

package com.gibby.dungeon.gen;

import net.minecraft.world.gen.feature.*;
import net.minecraft.world.*;
import java.util.*;
import net.minecraft.init.*;
import net.minecraft.block.*;
import com.gibby.dungeon.*;

public class archruins extends WorldGenerator
{
    public boolean generate(final World world, final Random rand, final int i, final int j, final int k) {
        if (world.getBlock(i, j, k) != Blocks.grass || world.getBlock(i + 19, j, k + 18) != Blocks.grass || world.getBlock(i, j, k + 18) != Blocks.grass || world.getBlock(i + 19, j, k) != Blocks.grass || world.getBlock(i, j + 1, k) != Blocks.air || world.getBlock(i + 19, j + 1, k + 18) != Blocks.air || world.getBlock(i, j + 1, k + 18) != Blocks.air || world.getBlock(i + 19, j + 1, k) != Blocks.air) {
            return false;
        }
        world.setBlock(i, j + 0, k + 0, (Block)Blocks.grass);
        world.setBlock(i, j + 0, k + 1, (Block)Blocks.grass);
        world.setBlock(i, j + 0, k + 2, (Block)Blocks.grass);
        world.setBlock(i, j + 0, k + 3, (Block)Blocks.grass);
        world.setBlock(i, j + 0, k + 4, (Block)Blocks.grass);
        world.setBlock(i, j + 0, k + 5, (Block)Blocks.grass);
        world.setBlock(i, j + 0, k + 6, (Block)Blocks.grass);
        world.setBlock(i, j + 0, k + 7, (Block)Blocks.grass);
        world.setBlock(i, j + 0, k + 8, (Block)Blocks.grass);
        world.setBlock(i, j + 0, k + 9, (Block)Blocks.grass);
        world.setBlock(i, j + 0, k + 10, (Block)Blocks.grass);
        world.setBlock(i, j + 0, k + 11, (Block)Blocks.grass);
        world.setBlock(i, j + 0, k + 12, (Block)Blocks.grass);
        world.setBlock(i, j + 0, k + 13, (Block)Blocks.grass);
        world.setBlock(i, j + 0, k + 14, (Block)Blocks.grass);
        world.setBlock(i, j + 0, k + 15, (Block)Blocks.grass);
        world.setBlock(i, j + 0, k + 16, (Block)Blocks.grass);
        world.setBlock(i, j + 0, k + 17, (Block)Blocks.grass);
        world.setBlock(i, j + 0, k + 18, (Block)Blocks.grass);
        world.setBlock(i, j + 0, k + 19, (Block)Blocks.grass);
        world.setBlock(i, j + 0, k + 20, (Block)Blocks.grass);
        world.setBlock(i, j + 0, k + 21, (Block)Blocks.grass);
        world.setBlock(i, j + 0, k + 22, (Block)Blocks.grass);
        world.setBlock(i, j + 0, k + 23, (Block)Blocks.grass);
        world.setBlock(i, j + 0, k + 24, (Block)Blocks.grass);
        world.setBlock(i, j + 0, k + 25, (Block)Blocks.grass);
        world.setBlock(i + 1, j + 0, k + 0, (Block)Blocks.grass);
        world.setBlock(i + 1, j + 0, k + 1, (Block)Blocks.grass);
        world.setBlock(i + 1, j + 0, k + 2, (Block)Blocks.grass);
        world.setBlock(i + 1, j + 0, k + 3, (Block)Blocks.grass);
        world.setBlock(i + 1, j + 0, k + 4, (Block)Blocks.grass);
        world.setBlock(i + 1, j + 0, k + 5, (Block)Blocks.grass);
        world.setBlock(i + 1, j + 0, k + 6, (Block)Blocks.grass);
        world.setBlock(i + 1, j + 0, k + 7, (Block)Blocks.grass);
        world.setBlock(i + 1, j + 0, k + 8, (Block)Blocks.grass);
        world.setBlock(i + 1, j + 0, k + 9, (Block)Blocks.grass);
        world.setBlock(i + 1, j + 0, k + 10, (Block)Blocks.grass);
        world.setBlock(i + 1, j + 0, k + 11, (Block)Blocks.grass);
        world.setBlock(i + 1, j + 0, k + 12, (Block)Blocks.grass);
        world.setBlock(i + 1, j + 0, k + 13, (Block)Blocks.grass);
        world.setBlock(i + 1, j + 0, k + 14, (Block)Blocks.grass);
        world.setBlock(i + 1, j + 0, k + 15, (Block)Blocks.grass);
        world.setBlock(i + 1, j + 0, k + 16, (Block)Blocks.grass);
        world.setBlock(i + 1, j + 0, k + 17, (Block)Blocks.grass);
        world.setBlock(i + 1, j + 0, k + 18, (Block)Blocks.grass);
        world.setBlock(i + 1, j + 0, k + 19, (Block)Blocks.grass);
        world.setBlock(i + 1, j + 0, k + 20, (Block)Blocks.grass);
        world.setBlock(i + 1, j + 0, k + 21, (Block)Blocks.grass);
        world.setBlock(i + 1, j + 0, k + 22, (Block)Blocks.grass);
        world.setBlock(i + 1, j + 0, k + 23, (Block)Blocks.grass);
        world.setBlock(i + 1, j + 0, k + 24, (Block)Blocks.grass);
        world.setBlock(i + 1, j + 0, k + 25, (Block)Blocks.grass);
        world.setBlock(i + 2, j + 0, k + 0, (Block)Blocks.grass);
        world.setBlock(i + 2, j + 0, k + 1, (Block)Blocks.grass);
        world.setBlock(i + 2, j + 0, k + 2, (Block)Blocks.grass);
        world.setBlock(i + 2, j + 0, k + 3, (Block)Blocks.grass);
        world.setBlock(i + 2, j + 0, k + 4, (Block)Blocks.grass);
        world.setBlock(i + 2, j + 0, k + 5, (Block)Blocks.grass);
        world.setBlock(i + 2, j + 0, k + 6, (Block)Blocks.grass);
        world.setBlock(i + 2, j + 0, k + 7, (Block)Blocks.grass);
        world.setBlock(i + 2, j + 0, k + 8, (Block)Blocks.grass);
        world.setBlock(i + 2, j + 0, k + 9, (Block)Blocks.grass);
        world.setBlock(i + 2, j + 0, k + 10, (Block)Blocks.grass);
        world.setBlock(i + 2, j + 0, k + 11, (Block)Blocks.grass);
        world.setBlock(i + 2, j + 0, k + 12, Blocks.dirt);
        world.setBlock(i + 2, j + 0, k + 13, (Block)Blocks.grass);
        world.setBlock(i + 2, j + 0, k + 14, (Block)Blocks.grass);
        world.setBlock(i + 2, j + 0, k + 15, (Block)Blocks.grass);
        world.setBlock(i + 2, j + 0, k + 16, (Block)Blocks.grass);
        world.setBlock(i + 2, j + 0, k + 17, (Block)Blocks.grass);
        world.setBlock(i + 2, j + 0, k + 18, (Block)Blocks.grass);
        world.setBlock(i + 2, j + 0, k + 19, (Block)Blocks.grass);
        world.setBlock(i + 2, j + 0, k + 20, (Block)Blocks.grass);
        world.setBlock(i + 2, j + 0, k + 21, (Block)Blocks.grass);
        world.setBlock(i + 2, j + 0, k + 22, (Block)Blocks.grass);
        world.setBlock(i + 2, j + 0, k + 23, (Block)Blocks.grass);
        world.setBlock(i + 2, j + 0, k + 24, (Block)Blocks.grass);
        world.setBlock(i + 2, j + 0, k + 25, (Block)Blocks.grass);
        world.setBlock(i + 2, j + 1, k + 12, Blocks.stonebrick, 2, 0);
        world.setBlock(i + 3, j + 0, k + 0, (Block)Blocks.grass);
        world.setBlock(i + 3, j + 0, k + 1, (Block)Blocks.grass);
        world.setBlock(i + 3, j + 0, k + 2, (Block)Blocks.grass);
        world.setBlock(i + 3, j + 0, k + 3, (Block)Blocks.grass);
        world.setBlock(i + 3, j + 0, k + 4, Blocks.stonebrick, 2, 0);
        world.setBlock(i + 3, j + 0, k + 5, Blocks.dirt);
        world.setBlock(i + 3, j + 0, k + 6, Blocks.stonebrick, 2, 0);
        world.setBlock(i + 3, j + 0, k + 7, Blocks.dirt);
        world.setBlock(i + 3, j + 0, k + 8, (Block)Blocks.stone_slab, 3, 0);
        world.setBlock(i + 3, j + 0, k + 9, (Block)Blocks.grass);
        world.setBlock(i + 3, j + 0, k + 10, Blocks.mossy_cobblestone);
        world.setBlock(i + 3, j + 0, k + 11, (Block)Blocks.grass);
        world.setBlock(i + 3, j + 0, k + 12, Blocks.cobblestone);
        world.setBlock(i + 3, j + 0, k + 13, Blocks.cobblestone);
        world.setBlock(i + 3, j + 0, k + 14, (Block)Blocks.grass);
        world.setBlock(i + 3, j + 0, k + 15, Blocks.cobblestone);
        world.setBlock(i + 3, j + 0, k + 16, (Block)Blocks.grass);
        world.setBlock(i + 3, j + 0, k + 17, Blocks.dirt);
        world.setBlock(i + 3, j + 0, k + 18, (Block)Blocks.grass);
        world.setBlock(i + 3, j + 0, k + 19, Blocks.dirt);
        world.setBlock(i + 3, j + 0, k + 20, (Block)Blocks.grass);
        world.setBlock(i + 3, j + 0, k + 21, (Block)Blocks.grass);
        world.setBlock(i + 3, j + 0, k + 22, Blocks.dirt);
        world.setBlock(i + 3, j + 0, k + 23, Blocks.stonebrick, 2, 0);
        world.setBlock(i + 3, j + 0, k + 24, (Block)Blocks.grass);
        world.setBlock(i + 3, j + 0, k + 25, (Block)Blocks.grass);
        world.setBlock(i + 3, j + 1, k + 5, Blocks.stonebrick, 2, 0);
        world.setBlock(i + 3, j + 1, k + 7, Blocks.stonebrick, 2, 0);
        world.setBlock(i + 3, j + 1, k + 10, (Block)Blocks.stone_slab, 3, 0);
        world.setBlock(i + 3, j + 1, k + 17, Blocks.stonebrick, 2, 0);
        world.setBlock(i + 3, j + 1, k + 19, Blocks.stonebrick, 2, 0);
        world.setBlock(i + 3, j + 1, k + 22, Blocks.stonebrick, 2, 0);
        world.setBlock(i + 4, j + 0, k + 0, (Block)Blocks.grass);
        world.setBlock(i + 4, j + 0, k + 1, (Block)Blocks.grass);
        world.setBlock(i + 4, j + 0, k + 2, (Block)Blocks.grass);
        world.setBlock(i + 4, j + 0, k + 3, Blocks.dirt);
        world.setBlock(i + 4, j + 0, k + 4, (Block)Blocks.grass);
        world.setBlock(i + 4, j + 0, k + 5, (Block)Blocks.grass);
        world.setBlock(i + 4, j + 0, k + 6, Blocks.cobblestone);
        world.setBlock(i + 4, j + 0, k + 7, (Block)Blocks.grass);
        world.setBlock(i + 4, j + 0, k + 8, (Block)Blocks.grass);
        world.setBlock(i + 4, j + 0, k + 9, Blocks.dirt);
        world.setBlock(i + 4, j + 0, k + 10, Blocks.mossy_cobblestone);
        world.setBlock(i + 4, j + 0, k + 11, (Block)Blocks.grass);
        world.setBlock(i + 4, j + 0, k + 12, Blocks.mossy_cobblestone);
        world.setBlock(i + 4, j + 0, k + 13, (Block)Blocks.grass);
        world.setBlock(i + 4, j + 0, k + 14, Blocks.dirt);
        world.setBlock(i + 4, j + 0, k + 15, Blocks.dirt);
        world.setBlock(i + 4, j + 0, k + 16, Blocks.cobblestone);
        world.setBlock(i + 4, j + 0, k + 17, (Block)Blocks.grass);
        world.setBlock(i + 4, j + 0, k + 18, (Block)Blocks.stone_slab, 3, 0);
        world.setBlock(i + 4, j + 0, k + 19, (Block)Blocks.grass);
        world.setBlock(i + 4, j + 0, k + 20, Blocks.stonebrick, 2, 0);
        world.setBlock(i + 4, j + 0, k + 21, (Block)Blocks.grass);
        world.setBlock(i + 4, j + 0, k + 22, (Block)Blocks.grass);
        world.setBlock(i + 4, j + 0, k + 23, (Block)Blocks.grass);
        world.setBlock(i + 4, j + 0, k + 24, Blocks.dirt);
        world.setBlock(i + 4, j + 0, k + 25, (Block)Blocks.grass);
        world.setBlock(i + 4, j + 1, k + 3, Blocks.stonebrick, 2, 0);
        world.setBlock(i + 4, j + 1, k + 9, Blocks.stonebrick, 2, 0);
        world.setBlock(i + 4, j + 1, k + 14, Blocks.stonebrick, 2, 0);
        world.setBlock(i + 4, j + 1, k + 15, Blocks.stonebrick, 2, 0);
        world.setBlock(i + 4, j + 1, k + 21, (Block)Blocks.stone_slab, 3, 0);
        world.setBlock(i + 4, j + 1, k + 24, Blocks.stonebrick, 2, 0);
        world.setBlock(i + 5, j + 0, k + 0, (Block)Blocks.grass);
        world.setBlock(i + 5, j + 0, k + 1, (Block)Blocks.grass);
        world.setBlock(i + 5, j + 0, k + 2, (Block)Blocks.grass);
        world.setBlock(i + 5, j + 0, k + 3, (Block)Blocks.grass);
        world.setBlock(i + 5, j + 0, k + 4, Blocks.cobblestone);
        world.setBlock(i + 5, j + 0, k + 5, Blocks.dirt);
        world.setBlock(i + 5, j + 0, k + 6, Blocks.dirt);
        world.setBlock(i + 5, j + 0, k + 7, Blocks.dirt);
        world.setBlock(i + 5, j + 0, k + 8, Blocks.dirt);
        world.setBlock(i + 5, j + 0, k + 9, Blocks.cobblestone);
        world.setBlock(i + 5, j + 0, k + 10, Blocks.cobblestone);
        world.setBlock(i + 5, j + 0, k + 11, Blocks.dirt);
        world.setBlock(i + 5, j + 0, k + 12, Blocks.cobblestone);
        world.setBlock(i + 5, j + 0, k + 13, Blocks.mossy_cobblestone);
        world.setBlock(i + 5, j + 0, k + 14, Blocks.cobblestone);
        world.setBlock(i + 5, j + 0, k + 15, Blocks.dirt);
        world.setBlock(i + 5, j + 0, k + 16, Blocks.dirt);
        world.setBlock(i + 5, j + 0, k + 17, Blocks.dirt);
        world.setBlock(i + 5, j + 0, k + 18, (Block)Blocks.grass);
        world.setBlock(i + 5, j + 0, k + 19, Blocks.dirt);
        world.setBlock(i + 5, j + 0, k + 20, Blocks.dirt);
        world.setBlock(i + 5, j + 0, k + 21, Blocks.dirt);
        world.setBlock(i + 5, j + 0, k + 22, Blocks.dirt);
        world.setBlock(i + 5, j + 0, k + 23, Blocks.dirt);
        world.setBlock(i + 5, j + 0, k + 24, Blocks.cobblestone);
        world.setBlock(i + 5, j + 0, k + 25, (Block)Blocks.grass);
        world.setBlock(i + 5, j + 1, k + 4, Blocks.stonebrick, 2, 0);
        world.setBlock(i + 5, j + 1, k + 5, Blocks.stonebrick, 2, 0);
        world.setBlock(i + 5, j + 1, k + 6, Blocks.stonebrick, 2, 0);
        world.setBlock(i + 5, j + 1, k + 7, Blocks.stonebrick, 2, 0);
        world.setBlock(i + 5, j + 1, k + 8, Blocks.stonebrick, 2, 0);
        world.setBlock(i + 5, j + 1, k + 11, Blocks.stonebrick, 2, 0);
        world.setBlock(i + 5, j + 1, k + 13, Blocks.stonebrick, 1, 0);
        world.setBlock(i + 5, j + 1, k + 14, (Block)Blocks.stone_slab, 3, 0);
        world.setBlock(i + 5, j + 1, k + 15, Blocks.stonebrick, 2, 0);
        world.setBlock(i + 5, j + 1, k + 16, Blocks.stonebrick, 2, 0);
        world.setBlock(i + 5, j + 1, k + 17, Blocks.stonebrick, 2, 0);
        world.setBlock(i + 5, j + 1, k + 19, Blocks.stonebrick, 2, 0);
        world.setBlock(i + 5, j + 1, k + 20, Blocks.stonebrick, 2, 0);
        world.setBlock(i + 5, j + 1, k + 21, Blocks.stonebrick, 2, 0);
        world.setBlock(i + 5, j + 1, k + 22, Blocks.stonebrick, 2, 0);
        world.setBlock(i + 5, j + 1, k + 23, Blocks.stonebrick, 2, 0);
        world.setBlock(i + 5, j + 2, k + 4, Blocks.stonebrick, 2, 0);
        world.setBlock(i + 5, j + 2, k + 5, Blocks.stonebrick, 2, 0);
        world.setBlock(i + 5, j + 2, k + 21, Blocks.stonebrick, 2, 0);
        world.setBlock(i + 5, j + 2, k + 22, Blocks.stonebrick, 2, 0);
        world.setBlock(i + 5, j + 3, k + 4, Blocks.stonebrick, 1, 0);
        world.setBlock(i + 5, j + 3, k + 5, Blocks.stonebrick, 2, 0);
        world.setBlock(i + 5, j + 3, k + 21, Blocks.stonebrick, 1, 0);
        world.setBlock(i + 5, j + 3, k + 22, Blocks.stonebrick, 2, 0);
        world.setBlock(i + 5, j + 4, k + 4, Blocks.stonebrick, 1, 0);
        world.setBlock(i + 5, j + 4, k + 5, Blocks.stonebrick, 1, 0);
        world.setBlock(i + 5, j + 4, k + 21, Blocks.stonebrick, 1, 0);
        world.setBlock(i + 5, j + 4, k + 22, Blocks.stonebrick, 1, 0);
        world.setBlock(i + 5, j + 5, k + 4, Blocks.stonebrick, 2, 0);
        world.setBlock(i + 5, j + 5, k + 5, Blocks.stonebrick, 2, 0);
        world.setBlock(i + 5, j + 5, k + 21, Blocks.stonebrick, 1, 0);
        world.setBlock(i + 5, j + 5, k + 22, Blocks.stonebrick, 1, 0);
        world.setBlock(i + 5, j + 6, k + 4, Blocks.stonebrick, 2, 0);
        world.setBlock(i + 5, j + 6, k + 5, Blocks.stonebrick, 1, 0);
        world.setBlock(i + 5, j + 6, k + 21, Blocks.stonebrick, 2, 0);
        world.setBlock(i + 5, j + 6, k + 22, Blocks.stonebrick, 2, 0);
        world.setBlock(i + 5, j + 7, k + 4, Blocks.stonebrick, 2, 0);
        world.setBlock(i + 5, j + 7, k + 21, Blocks.stonebrick, 2, 0);
        world.setBlock(i + 5, j + 7, k + 22, Blocks.stonebrick, 1, 0);
        world.setBlock(i + 5, j + 8, k + 4, Blocks.stonebrick, 2, 0);
        world.setBlock(i + 5, j + 8, k + 20, Blocks.stonebrick, 2, 0);
        world.setBlock(i + 5, j + 8, k + 21, Blocks.stonebrick, 1, 0);
        world.setBlock(i + 5, j + 8, k + 22, Blocks.stonebrick, 2, 0);
        world.setBlock(i + 5, j + 9, k + 4, Blocks.stonebrick, 2, 0);
        world.setBlock(i + 5, j + 9, k + 19, Blocks.stonebrick, 2, 0);
        world.setBlock(i + 5, j + 9, k + 20, Blocks.stonebrick, 2, 0);
        world.setBlock(i + 5, j + 9, k + 21, Blocks.stonebrick, 1, 0);
        world.setBlock(i + 5, j + 9, k + 22, Blocks.stonebrick, 1, 0);
        world.setBlock(i + 5, j + 10, k + 4, Blocks.stonebrick, 2, 0);
        world.setBlock(i + 5, j + 10, k + 18, Blocks.stonebrick, 2, 0);
        world.setBlock(i + 5, j + 10, k + 19, Blocks.stonebrick, 2, 0);
        world.setBlock(i + 5, j + 10, k + 20, Blocks.stonebrick, 2, 0);
        world.setBlock(i + 5, j + 10, k + 22, Blocks.stonebrick, 2, 0);
        world.setBlock(i + 5, j + 11, k + 21, Blocks.stonebrick, 2, 0);
        world.setBlock(i + 5, j + 11, k + 22, Blocks.stonebrick, 2, 0);
        world.setBlock(i + 5, j + 12, k + 22, Blocks.stonebrick, 2, 0);
        world.setBlock(i + 5, j + 13, k + 22, Blocks.stonebrick, 2, 0);
        world.setBlock(i + 6, j + 0, k + 0, (Block)Blocks.grass);
        world.setBlock(i + 6, j + 0, k + 1, (Block)Blocks.grass);
        world.setBlock(i + 6, j + 0, k + 2, (Block)Blocks.grass);
        world.setBlock(i + 6, j + 0, k + 3, Blocks.dirt);
        world.setBlock(i + 6, j + 0, k + 4, Blocks.dirt);
        world.setBlock(i + 6, j + 0, k + 5, Blocks.cobblestone);
        world.setBlock(i + 6, j + 0, k + 6, Blocks.stonebrick, 2, 0);
        world.setBlock(i + 6, j + 0, k + 7, Blocks.dirt);
        world.setBlock(i + 6, j + 0, k + 8, Blocks.mossy_cobblestone);
        world.setBlock(i + 6, j + 0, k + 9, Blocks.dirt);
        world.setBlock(i + 6, j + 0, k + 10, Blocks.mossy_cobblestone);
        world.setBlock(i + 6, j + 0, k + 11, Blocks.dirt);
        world.setBlock(i + 6, j + 0, k + 12, Blocks.mossy_cobblestone);
        world.setBlock(i + 6, j + 0, k + 13, (Block)Blocks.grass);
        world.setBlock(i + 6, j + 0, k + 14, (Block)Blocks.grass);
        world.setBlock(i + 6, j + 0, k + 15, Blocks.mossy_cobblestone);
        world.setBlock(i + 6, j + 0, k + 16, Blocks.dirt);
        world.setBlock(i + 6, j + 0, k + 17, Blocks.mossy_cobblestone);
        world.setBlock(i + 6, j + 0, k + 18, Blocks.cobblestone);
        world.setBlock(i + 6, j + 0, k + 19, Blocks.dirt);
        world.setBlock(i + 6, j + 0, k + 20, Blocks.mossy_cobblestone);
        world.setBlock(i + 6, j + 0, k + 21, Blocks.dirt);
        world.setBlock(i + 6, j + 0, k + 22, Blocks.dirt);
        world.setBlock(i + 6, j + 0, k + 23, (Block)Blocks.grass);
        world.setBlock(i + 6, j + 0, k + 24, Blocks.dirt);
        world.setBlock(i + 6, j + 0, k + 25, (Block)Blocks.grass);
        world.setBlock(i + 6, j + 1, k + 3, Blocks.stonebrick, 2, 0);
        world.setBlock(i + 6, j + 1, k + 4, Blocks.stonebrick, 2, 0);
        world.setBlock(i + 6, j + 1, k + 5, Blocks.stonebrick, 2, 0);
        world.setBlock(i + 6, j + 1, k + 6, (Block)Blocks.stone_slab, 3, 0);
        world.setBlock(i + 6, j + 1, k + 7, Blocks.stonebrick, 2, 0);
        world.setBlock(i + 6, j + 1, k + 9, Blocks.stonebrick, 2, 0);
        world.setBlock(i + 6, j + 1, k + 10, (Block)Blocks.stone_slab, 3, 0);
        world.setBlock(i + 6, j + 1, k + 11, Blocks.stonebrick, 2, 0);
        world.setBlock(i + 6, j + 1, k + 12, (Block)Blocks.stone_slab, 3, 0);
        world.setBlock(i + 6, j + 1, k + 16, Blocks.stonebrick, 2, 0);
        world.setBlock(i + 6, j + 1, k + 19, Blocks.stonebrick, 2, 0);
        world.setBlock(i + 6, j + 1, k + 21, Blocks.stonebrick, 2, 0);
        world.setBlock(i + 6, j + 1, k + 22, Blocks.stonebrick, 2, 0);
        world.setBlock(i + 6, j + 1, k + 24, Blocks.stonebrick, 2, 0);
        world.setBlock(i + 6, j + 2, k + 4, Blocks.stonebrick, 2, 0);
        world.setBlock(i + 6, j + 2, k + 5, Blocks.stonebrick, 1, 0);
        world.setBlock(i + 6, j + 2, k + 21, Blocks.stonebrick, 1, 0);
        world.setBlock(i + 6, j + 2, k + 22, Blocks.stonebrick, 2, 0);
        world.setBlock(i + 6, j + 3, k + 4, Blocks.stonebrick, 2, 0);
        world.setBlock(i + 6, j + 3, k + 5, Blocks.stonebrick, 1, 0);
        world.setBlock(i + 6, j + 3, k + 21, Blocks.stonebrick, 1, 0);
        world.setBlock(i + 6, j + 3, k + 22, Blocks.stonebrick, 1, 0);
        world.setBlock(i + 6, j + 4, k + 4, Blocks.stonebrick, 1, 0);
        world.setBlock(i + 6, j + 4, k + 21, Blocks.stonebrick, 2, 0);
        world.setBlock(i + 6, j + 4, k + 22, Blocks.stonebrick, 1, 0);
        world.setBlock(i + 6, j + 5, k + 4, Blocks.stonebrick, 1, 0);
        world.setBlock(i + 6, j + 5, k + 21, Blocks.stonebrick, 2, 0);
        world.setBlock(i + 6, j + 5, k + 22, Blocks.stonebrick, 1, 0);
        world.setBlock(i + 6, j + 6, k + 4, Blocks.stonebrick, 2, 0);
        world.setBlock(i + 6, j + 6, k + 21, Blocks.stonebrick, 2, 0);
        world.setBlock(i + 6, j + 6, k + 22, Blocks.stonebrick, 1, 0);
        world.setBlock(i + 6, j + 7, k + 4, Blocks.stonebrick, 2, 0);
        world.setBlock(i + 6, j + 7, k + 21, Blocks.stonebrick, 2, 0);
        world.setBlock(i + 6, j + 7, k + 22, Blocks.stonebrick, 2, 0);
        world.setBlock(i + 6, j + 8, k + 4, Blocks.stonebrick, 2, 0);
        world.setBlock(i + 6, j + 8, k + 20, Blocks.stonebrick, 2, 0);
        world.setBlock(i + 6, j + 8, k + 21, Blocks.stonebrick, 2, 0);
        world.setBlock(i + 6, j + 8, k + 22, Blocks.stonebrick, 2, 0);
        world.setBlock(i + 6, j + 9, k + 19, Blocks.stonebrick, 2, 0);
        world.setBlock(i + 6, j + 9, k + 20, Blocks.stonebrick, 1, 0);
        world.setBlock(i + 6, j + 9, k + 21, Blocks.stonebrick, 2, 0);
        world.setBlock(i + 6, j + 9, k + 22, Blocks.stonebrick, 2, 0);
        world.setBlock(i + 6, j + 10, k + 20, Blocks.stonebrick, 2, 0);
        world.setBlock(i + 6, j + 10, k + 21, Blocks.stonebrick, 2, 0);
        world.setBlock(i + 6, j + 10, k + 22, Blocks.stonebrick, 1, 0);
        world.setBlock(i + 6, j + 11, k + 21, (Block)Blocks.stone_slab, 3, 0);
        world.setBlock(i + 6, j + 11, k + 22, Blocks.stonebrick, 2, 0);
        world.setBlock(i + 6, j + 12, k + 22, Blocks.stonebrick, 2, 0);
        world.setBlock(i + 7, j + 0, k + 0, (Block)Blocks.grass);
        world.setBlock(i + 7, j + 0, k + 1, (Block)Blocks.grass);
        world.setBlock(i + 7, j + 0, k + 2, Blocks.stonebrick, 2, 0);
        world.setBlock(i + 7, j + 0, k + 3, Blocks.stonebrick, 2, 0);
        world.setBlock(i + 7, j + 0, k + 4, Blocks.dirt);
        world.setBlock(i + 7, j + 0, k + 5, (Block)Blocks.grass);
        world.setBlock(i + 7, j + 0, k + 6, Blocks.mossy_cobblestone);
        world.setBlock(i + 7, j + 0, k + 7, Blocks.dirt);
        world.setBlock(i + 7, j + 0, k + 8, Blocks.stonebrick, 2, 0);
        world.setBlock(i + 7, j + 0, k + 9, (Block)Blocks.grass);
        world.setBlock(i + 7, j + 0, k + 10, Blocks.mossy_cobblestone);
        world.setBlock(i + 7, j + 0, k + 11, Blocks.dirt);
        world.setBlock(i + 7, j + 0, k + 12, Blocks.stonebrick, 2, 0);
        world.setBlock(i + 7, j + 0, k + 13, Blocks.cobblestone);
        world.setBlock(i + 7, j + 0, k + 14, Blocks.dirt);
        world.setBlock(i + 7, j + 0, k + 15, Blocks.cobblestone);
        world.setBlock(i + 7, j + 0, k + 16, Blocks.mossy_cobblestone);
        world.setBlock(i + 7, j + 0, k + 17, (Block)Blocks.grass);
        world.setBlock(i + 7, j + 0, k + 18, Blocks.stonebrick, 2, 0);
        world.setBlock(i + 7, j + 0, k + 19, Blocks.dirt);
        world.setBlock(i + 7, j + 0, k + 20, Blocks.stonebrick, 2, 0);
        world.setBlock(i + 7, j + 0, k + 21, Blocks.mossy_cobblestone);
        world.setBlock(i + 7, j + 0, k + 22, Blocks.cobblestone);
        world.setBlock(i + 7, j + 0, k + 23, (Block)Blocks.grass);
        world.setBlock(i + 7, j + 0, k + 24, Blocks.dirt);
        world.setBlock(i + 7, j + 0, k + 25, Blocks.cobblestone);
        world.setBlock(i + 7, j + 1, k + 4, Blocks.stonebrick, 2, 0);
        world.setBlock(i + 7, j + 1, k + 7, Blocks.stonebrick, 2, 0);
        world.setBlock(i + 7, j + 1, k + 11, Blocks.stonebrick, 2, 0);
        world.setBlock(i + 7, j + 1, k + 13, Blocks.stonebrick, 2, 0);
        world.setBlock(i + 7, j + 1, k + 14, Blocks.stonebrick, 1, 0);
        world.setBlock(i + 7, j + 1, k + 15, Blocks.stonebrick, 2, 0);
        world.setBlock(i + 7, j + 1, k + 16, Blocks.stonebrick, 2, 0);
        world.setBlock(i + 7, j + 1, k + 19, Blocks.stonebrick, 2, 0);
        world.setBlock(i + 7, j + 1, k + 24, Blocks.stonebrick, 2, 0);
        world.setBlock(i + 7, j + 2, k + 4, Blocks.stonebrick, 2, 0);
        world.setBlock(i + 7, j + 8, k + 21, Blocks.stonebrick, 2, 0);
        world.setBlock(i + 7, j + 8, k + 22, Blocks.stonebrick, 2, 0);
        world.setBlock(i + 7, j + 9, k + 21, Blocks.stonebrick, 2, 0);
        world.setBlock(i + 7, j + 9, k + 22, Blocks.stonebrick, 1, 0);
        world.setBlock(i + 7, j + 10, k + 21, (Block)Blocks.stone_slab, 3, 0);
        world.setBlock(i + 7, j + 10, k + 22, Blocks.stonebrick, 2, 0);
        world.setBlock(i + 7, j + 11, k + 22, Blocks.stonebrick, 2, 0);
        world.setBlock(i + 8, j + 0, k + 0, (Block)Blocks.grass);
        world.setBlock(i + 8, j + 0, k + 1, (Block)Blocks.grass);
        world.setBlock(i + 8, j + 0, k + 2, Blocks.dirt);
        world.setBlock(i + 8, j + 0, k + 3, (Block)Blocks.grass);
        world.setBlock(i + 8, j + 0, k + 4, Blocks.dirt);
        world.setBlock(i + 8, j + 0, k + 5, Blocks.dirt);
        world.setBlock(i + 8, j + 0, k + 6, Blocks.stonebrick, 2, 0);
        world.setBlock(i + 8, j + 0, k + 7, Blocks.dirt);
        world.setBlock(i + 8, j + 0, k + 8, Blocks.cobblestone);
        world.setBlock(i + 8, j + 0, k + 9, Blocks.dirt);
        world.setBlock(i + 8, j + 0, k + 10, (Block)Blocks.grass);
        world.setBlock(i + 8, j + 0, k + 11, Blocks.cobblestone);
        world.setBlock(i + 8, j + 0, k + 12, (Block)Blocks.grass);
        world.setBlock(i + 8, j + 0, k + 13, Blocks.cobblestone);
        world.setBlock(i + 8, j + 0, k + 14, (Block)Blocks.grass);
        world.setBlock(i + 8, j + 0, k + 15, Blocks.cobblestone);
        world.setBlock(i + 8, j + 0, k + 16, Blocks.cobblestone);
        world.setBlock(i + 8, j + 0, k + 17, Blocks.dirt);
        world.setBlock(i + 8, j + 0, k + 18, (Block)Blocks.grass);
        world.setBlock(i + 8, j + 0, k + 19, Blocks.dirt);
        world.setBlock(i + 8, j + 0, k + 20, Blocks.mossy_cobblestone);
        world.setBlock(i + 8, j + 0, k + 21, Blocks.cobblestone);
        world.setBlock(i + 8, j + 0, k + 22, Blocks.dirt);
        world.setBlock(i + 8, j + 0, k + 23, (Block)Blocks.grass);
        world.setBlock(i + 8, j + 0, k + 24, Blocks.dirt);
        world.setBlock(i + 8, j + 0, k + 25, (Block)Blocks.grass);
        world.setBlock(i + 8, j + 1, k + 2, Blocks.stonebrick, 2, 0);
        world.setBlock(i + 8, j + 1, k + 4, Blocks.stonebrick, 2, 0);
        world.setBlock(i + 8, j + 1, k + 5, Blocks.stonebrick, 2, 0);
        world.setBlock(i + 8, j + 1, k + 7, Blocks.stonebrick, 1, 0);
        world.setBlock(i + 8, j + 1, k + 9, Blocks.stonebrick, 1, 0);
        world.setBlock(i + 8, j + 1, k + 13, Blocks.stonebrick, 2, 0);
        world.setBlock(i + 8, j + 1, k + 17, Blocks.stonebrick, 2, 0);
        world.setBlock(i + 8, j + 1, k + 19, Blocks.stonebrick, 2, 0);
        world.setBlock(i + 8, j + 1, k + 22, Blocks.stonebrick, 2, 0);
        world.setBlock(i + 8, j + 1, k + 24, Blocks.stonebrick, 2, 0);
        world.setBlock(i + 8, j + 2, k + 5, Blocks.stonebrick, 2, 0);
        world.setBlock(i + 8, j + 2, k + 19, Blocks.stonebrick, 1, 0);
        world.setBlock(i + 8, j + 9, k + 21, Blocks.stonebrick, 1, 0);
        world.setBlock(i + 8, j + 9, k + 22, Blocks.stonebrick, 2, 0);
        world.setBlock(i + 8, j + 10, k + 21, Blocks.stonebrick, 2, 0);
        world.setBlock(i + 8, j + 10, k + 22, Blocks.stonebrick, 2, 0);
        world.setBlock(i + 9, j + 0, k + 0, (Block)Blocks.grass);
        world.setBlock(i + 9, j + 0, k + 1, (Block)Blocks.grass);
        world.setBlock(i + 9, j + 0, k + 2, (Block)Blocks.grass);
        world.setBlock(i + 9, j + 0, k + 3, (Block)Blocks.grass);
        world.setBlock(i + 9, j + 0, k + 4, Blocks.dirt);
        world.setBlock(i + 9, j + 0, k + 5, Blocks.cobblestone);
        world.setBlock(i + 9, j + 0, k + 6, Blocks.mossy_cobblestone);
        world.setBlock(i + 9, j + 0, k + 7, (Block)Blocks.grass);
        world.setBlock(i + 9, j + 0, k + 8, Blocks.dirt);
        world.setBlock(i + 9, j + 0, k + 9, (Block)Blocks.grass);
        world.setBlock(i + 9, j + 0, k + 10, Blocks.cobblestone);
        world.setBlock(i + 9, j + 0, k + 11, Blocks.stonebrick, 2, 0);
        world.setBlock(i + 9, j + 0, k + 12, (Block)Blocks.grass);
        world.setBlock(i + 9, j + 0, k + 13, Blocks.dirt);
        world.setBlock(i + 9, j + 0, k + 14, Blocks.cobblestone);
        world.setBlock(i + 9, j + 0, k + 15, (Block)Blocks.grass);
        world.setBlock(i + 9, j + 0, k + 16, (Block)Blocks.grass);
        world.setBlock(i + 9, j + 0, k + 17, Blocks.mossy_cobblestone);
        world.setBlock(i + 9, j + 0, k + 18, Blocks.cobblestone);
        world.setBlock(i + 9, j + 0, k + 19, Blocks.cobblestone);
        world.setBlock(i + 9, j + 0, k + 20, Blocks.dirt);
        world.setBlock(i + 9, j + 0, k + 21, Blocks.cobblestone);
        world.setBlock(i + 9, j + 0, k + 22, (Block)Blocks.grass);
        world.setBlock(i + 9, j + 0, k + 23, Blocks.cobblestone);
        world.setBlock(i + 9, j + 0, k + 24, (Block)Blocks.grass);
        world.setBlock(i + 9, j + 0, k + 25, Blocks.cobblestone);
        world.setBlock(i + 9, j + 1, k + 2, (Block)Blocks.stone_slab, 3, 0);
        world.setBlock(i + 9, j + 1, k + 4, Blocks.stonebrick, 2, 0);
        world.setBlock(i + 9, j + 1, k + 5, Blocks.stonebrick, 1, 0);
        world.setBlock(i + 9, j + 1, k + 8, Blocks.stonebrick, 2, 0);
        world.setBlock(i + 9, j + 1, k + 9, (Block)Blocks.stone_slab, 3, 0);
        world.setBlock(i + 9, j + 1, k + 11, Blocks.stonebrick, 2, 0);
        world.setBlock(i + 9, j + 1, k + 13, Blocks.stonebrick, 2, 0);
        world.setBlock(i + 9, j + 1, k + 14, Blocks.stonebrick, 2, 0);
        WorldGenWarlordDungeon.chest(world, rand, i + 9, j + 1, k + 17, "dungeonChest", rand.nextInt(5) + 1);
        world.setBlock(i + 9, j + 1, k + 18, Blocks.stonebrick, 2, 0);
        world.setBlock(i + 9, j + 1, k + 20, Blocks.stonebrick, 2, 0);
        world.setBlock(i + 9, j + 2, k + 4, Blocks.stonebrick, 2, 0);
        world.setBlock(i + 9, j + 2, k + 11, Blocks.stonebrick, 2, 0);
        world.setBlock(i + 9, j + 2, k + 14, Blocks.stonebrick, 1, 0);
        world.setBlock(i + 9, j + 10, k + 21, Blocks.stonebrick, 2, 0);
        world.setBlock(i + 9, j + 10, k + 22, Blocks.stonebrick, 2, 0);
        world.setBlock(i + 9, j + 11, k + 21, Blocks.stonebrick, 2, 0);
        world.setBlock(i + 9, j + 11, k + 22, (Block)Blocks.stone_slab, 3, 0);
        world.setBlock(i + 10, j + 0, k + 0, (Block)Blocks.grass);
        world.setBlock(i + 10, j + 0, k + 1, (Block)Blocks.grass);
        world.setBlock(i + 10, j + 0, k + 2, Blocks.dirt);
        world.setBlock(i + 10, j + 0, k + 3, (Block)Blocks.grass);
        world.setBlock(i + 10, j + 0, k + 4, Blocks.cobblestone);
        world.setBlock(i + 10, j + 0, k + 5, Blocks.mossy_cobblestone);
        world.setBlock(i + 10, j + 0, k + 6, Blocks.dirt);
        world.setBlock(i + 10, j + 0, k + 7, (Block)Blocks.grass);
        world.setBlock(i + 10, j + 0, k + 8, Blocks.dirt);
        world.setBlock(i + 10, j + 0, k + 9, Blocks.cobblestone);
        world.setBlock(i + 10, j + 0, k + 10, (Block)Blocks.grass);
        world.setBlock(i + 10, j + 0, k + 11, Blocks.cobblestone);
        world.setBlock(i + 10, j + 0, k + 12, Blocks.stonebrick, 2, 0);
        world.setBlock(i + 10, j + 0, k + 13, Blocks.dirt);
        world.setBlock(i + 10, j + 0, k + 14, Blocks.cobblestone);
        world.setBlock(i + 10, j + 0, k + 15, Blocks.mossy_cobblestone);
        world.setBlock(i + 10, j + 0, k + 16, Blocks.stonebrick, 2, 0);
        world.setBlock(i + 10, j + 0, k + 17, Blocks.cobblestone);
        world.setBlock(i + 10, j + 0, k + 18, Blocks.mossy_cobblestone);
        world.setBlock(i + 10, j + 0, k + 19, Blocks.mossy_cobblestone);
        world.setBlock(i + 10, j + 0, k + 20, Blocks.dirt);
        world.setBlock(i + 10, j + 0, k + 21, Blocks.stonebrick, 2, 0);
        world.setBlock(i + 10, j + 0, k + 22, Blocks.dirt);
        world.setBlock(i + 10, j + 0, k + 23, Blocks.stonebrick, 2, 0);
        world.setBlock(i + 10, j + 0, k + 24, Blocks.dirt);
        world.setBlock(i + 10, j + 0, k + 25, Blocks.dirt);
        world.setBlock(i + 10, j + 1, k + 2, Blocks.stonebrick, 2, 0);
        world.setBlock(i + 10, j + 1, k + 4, (Block)Blocks.stone_slab, 3, 0);
        world.setBlock(i + 10, j + 1, k + 6, Blocks.stonebrick, 1, 0);
        world.setBlock(i + 10, j + 1, k + 8, Blocks.stonebrick, 1, 0);
        world.setBlock(i + 10, j + 1, k + 9, Blocks.stonebrick, 2, 0);
        world.setBlock(i + 10, j + 1, k + 12, Blocks.stonebrick, 2, 0);
        world.setBlock(i + 10, j + 1, k + 13, Blocks.stonebrick, 2, 0);
        world.setBlock(i + 10, j + 1, k + 16, Blocks.stonebrick, 2, 0);
        world.setBlock(i + 10, j + 1, k + 20, Blocks.stonebrick, 2, 0);
        world.setBlock(i + 10, j + 1, k + 22, Blocks.stonebrick, 2, 0);
        world.setBlock(i + 10, j + 1, k + 24, Blocks.stonebrick, 2, 0);
        world.setBlock(i + 10, j + 1, k + 25, Blocks.stonebrick, 2, 0);
        world.setBlock(i + 10, j + 10, k + 21, Blocks.stonebrick, 2, 0);
        world.setBlock(i + 10, j + 10, k + 22, Blocks.stonebrick, 2, 0);
        world.setBlock(i + 11, j + 0, k + 0, (Block)Blocks.grass);
        world.setBlock(i + 11, j + 0, k + 1, (Block)Blocks.grass);
        world.setBlock(i + 11, j + 0, k + 2, (Block)Blocks.grass);
        world.setBlock(i + 11, j + 0, k + 3, (Block)Blocks.grass);
        world.setBlock(i + 11, j + 0, k + 4, Blocks.dirt);
        world.setBlock(i + 11, j + 0, k + 5, Blocks.stonebrick, 2, 0);
        world.setBlock(i + 11, j + 0, k + 6, Blocks.stonebrick, 2, 0);
        world.setBlock(i + 11, j + 0, k + 7, (Block)Blocks.grass);
        world.setBlock(i + 11, j + 0, k + 8, Blocks.cobblestone);
        world.setBlock(i + 11, j + 0, k + 9, (Block)Blocks.grass);
        world.setBlock(i + 11, j + 0, k + 10, Blocks.cobblestone);
        world.setBlock(i + 11, j + 0, k + 11, (Block)Blocks.grass);
        world.setBlock(i + 11, j + 0, k + 12, Blocks.cobblestone);
        world.setBlock(i + 11, j + 0, k + 13, Blocks.dirt);
        world.setBlock(i + 11, j + 0, k + 14, (Block)Blocks.grass);
        world.setBlock(i + 11, j + 0, k + 15, Blocks.mossy_cobblestone);
        world.setBlock(i + 11, j + 0, k + 16, Blocks.cobblestone);
        world.setBlock(i + 11, j + 0, k + 17, Blocks.dirt);
        world.setBlock(i + 11, j + 0, k + 18, Blocks.cobblestone);
        world.setBlock(i + 11, j + 0, k + 19, Blocks.mossy_cobblestone);
        world.setBlock(i + 11, j + 0, k + 20, (Block)Blocks.grass);
        world.setBlock(i + 11, j + 0, k + 21, Blocks.dirt);
        world.setBlock(i + 11, j + 0, k + 22, Blocks.dirt);
        world.setBlock(i + 11, j + 0, k + 23, (Block)Blocks.grass);
        world.setBlock(i + 11, j + 0, k + 24, (Block)Blocks.grass);
        world.setBlock(i + 11, j + 0, k + 25, Blocks.stonebrick, 2, 0);
        world.setBlock(i + 11, j + 1, k + 4, Blocks.stonebrick, 2, 0);
        world.setBlock(i + 11, j + 1, k + 8, (Block)Blocks.stone_slab, 3, 0);
        Dungeons.spawner(world, i + 11, j + 1, k + 9, 4, 2);
        world.setBlock(i + 11, j + 1, k + 10, Blocks.stonebrick, 2, 0);
        world.setBlock(i + 11, j + 1, k + 13, Blocks.stonebrick, 2, 0);
        world.setBlock(i + 11, j + 1, k + 15, Blocks.stonebrick, 2, 0);
        world.setBlock(i + 11, j + 1, k + 17, Blocks.stonebrick, 2, 0);
        world.setBlock(i + 11, j + 1, k + 21, Blocks.stonebrick, 2, 0);
        world.setBlock(i + 11, j + 1, k + 22, Blocks.stonebrick, 2, 0);
        world.setBlock(i + 11, j + 2, k + 4, Blocks.stonebrick, 2, 0);
        world.setBlock(i + 11, j + 2, k + 17, Blocks.stonebrick, 1, 0);
        world.setBlock(i + 11, j + 10, k + 21, Blocks.stonebrick, 2, 0);
        world.setBlock(i + 12, j + 0, k + 0, Blocks.dirt);
        world.setBlock(i + 12, j + 0, k + 1, Blocks.dirt);
        world.setBlock(i + 12, j + 0, k + 2, Blocks.cobblestone);
        world.setBlock(i + 12, j + 0, k + 3, (Block)Blocks.grass);
        world.setBlock(i + 12, j + 0, k + 4, (Block)Blocks.grass);
        world.setBlock(i + 12, j + 0, k + 5, Blocks.cobblestone);
        world.setBlock(i + 12, j + 0, k + 6, (Block)Blocks.grass);
        world.setBlock(i + 12, j + 0, k + 7, Blocks.dirt);
        world.setBlock(i + 12, j + 0, k + 8, Blocks.cobblestone);
        world.setBlock(i + 12, j + 0, k + 9, Blocks.cobblestone);
        world.setBlock(i + 12, j + 0, k + 10, (Block)Blocks.grass);
        world.setBlock(i + 12, j + 0, k + 11, Blocks.dirt);
        world.setBlock(i + 12, j + 0, k + 12, (Block)Blocks.grass);
        world.setBlock(i + 12, j + 0, k + 13, Blocks.cobblestone);
        world.setBlock(i + 12, j + 0, k + 14, Blocks.dirt);
        world.setBlock(i + 12, j + 0, k + 15, Blocks.cobblestone);
        world.setBlock(i + 12, j + 0, k + 16, Blocks.mossy_cobblestone);
        world.setBlock(i + 12, j + 0, k + 17, Blocks.cobblestone);
        world.setBlock(i + 12, j + 0, k + 18, (Block)Blocks.grass);
        world.setBlock(i + 12, j + 0, k + 19, Blocks.stonebrick, 2, 0);
        world.setBlock(i + 12, j + 0, k + 20, Blocks.cobblestone);
        world.setBlock(i + 12, j + 0, k + 21, Blocks.dirt);
        world.setBlock(i + 12, j + 0, k + 22, Blocks.dirt);
        world.setBlock(i + 12, j + 0, k + 23, Blocks.dirt);
        world.setBlock(i + 12, j + 0, k + 24, (Block)Blocks.grass);
        world.setBlock(i + 12, j + 0, k + 25, (Block)Blocks.grass);
        world.setBlock(i + 12, j + 1, k + 0, Blocks.stonebrick, 2, 0);
        world.setBlock(i + 12, j + 1, k + 1, Blocks.stonebrick, 2, 0);
        world.setBlock(i + 12, j + 1, k + 5, (Block)Blocks.stone_slab, 3, 0);
        world.setBlock(i + 12, j + 1, k + 7, Blocks.stonebrick, 2, 0);
        world.setBlock(i + 12, j + 1, k + 8, (Block)Blocks.stone_slab, 3, 0);
        world.setBlock(i + 12, j + 1, k + 11, Blocks.stonebrick, 2, 0);
        world.setBlock(i + 12, j + 1, k + 14, Blocks.stonebrick, 2, 0);
        world.setBlock(i + 12, j + 1, k + 20, Blocks.stonebrick, 1, 0);
        world.setBlock(i + 12, j + 1, k + 21, Blocks.stonebrick, 2, 0);
        world.setBlock(i + 12, j + 1, k + 22, Blocks.stonebrick, 2, 0);
        world.setBlock(i + 12, j + 1, k + 23, Blocks.stonebrick, 2, 0);
        world.setBlock(i + 12, j + 2, k + 11, Blocks.stonebrick, 2, 0);
        world.setBlock(i + 12, j + 2, k + 14, Blocks.stonebrick, 1, 0);
        world.setBlock(i + 12, j + 2, k + 21, Blocks.stonebrick, 2, 0);
        world.setBlock(i + 12, j + 3, k + 21, Blocks.stonebrick, 2, 0);
        world.setBlock(i + 13, j + 0, k + 0, (Block)Blocks.grass);
        world.setBlock(i + 13, j + 0, k + 1, (Block)Blocks.grass);
        world.setBlock(i + 13, j + 0, k + 2, Blocks.cobblestone);
        world.setBlock(i + 13, j + 0, k + 3, (Block)Blocks.grass);
        world.setBlock(i + 13, j + 0, k + 4, Blocks.cobblestone);
        world.setBlock(i + 13, j + 0, k + 5, Blocks.dirt);
        world.setBlock(i + 13, j + 0, k + 6, Blocks.stonebrick, 2, 0);
        world.setBlock(i + 13, j + 0, k + 7, Blocks.mossy_cobblestone);
        world.setBlock(i + 13, j + 0, k + 8, Blocks.cobblestone);
        world.setBlock(i + 13, j + 0, k + 9, (Block)Blocks.grass);
        world.setBlock(i + 13, j + 0, k + 10, Blocks.cobblestone);
        world.setBlock(i + 13, j + 0, k + 11, Blocks.dirt);
        world.setBlock(i + 13, j + 0, k + 12, Blocks.cobblestone);
        world.setBlock(i + 13, j + 0, k + 13, Blocks.cobblestone);
        world.setBlock(i + 13, j + 0, k + 14, (Block)Blocks.grass);
        world.setBlock(i + 13, j + 0, k + 15, Blocks.stonebrick, 2, 0);
        world.setBlock(i + 13, j + 0, k + 16, Blocks.stonebrick, 2, 0);
        world.setBlock(i + 13, j + 0, k + 17, Blocks.stonebrick, 2, 0);
        world.setBlock(i + 13, j + 0, k + 18, (Block)Blocks.grass);
        world.setBlock(i + 13, j + 0, k + 19, (Block)Blocks.grass);
        world.setBlock(i + 13, j + 0, k + 20, (Block)Blocks.grass);
        world.setBlock(i + 13, j + 0, k + 21, Blocks.cobblestone);
        world.setBlock(i + 13, j + 0, k + 22, Blocks.dirt);
        world.setBlock(i + 13, j + 0, k + 23, (Block)Blocks.grass);
        world.setBlock(i + 13, j + 0, k + 24, Blocks.dirt);
        world.setBlock(i + 13, j + 0, k + 25, (Block)Blocks.grass);
        world.setBlock(i + 13, j + 1, k + 5, Blocks.stonebrick, 2, 0);
        world.setBlock(i + 13, j + 1, k + 6, Blocks.stonebrick, 2, 0);
        world.setBlock(i + 13, j + 1, k + 8, (Block)Blocks.stone_slab, 3, 0);
        world.setBlock(i + 13, j + 1, k + 10, (Block)Blocks.stone_slab, 3, 0);
        world.setBlock(i + 13, j + 1, k + 11, Blocks.stonebrick, 2, 0);
        world.setBlock(i + 13, j + 1, k + 13, Blocks.stonebrick, 2, 0);
        world.setBlock(i + 13, j + 1, k + 22, Blocks.stonebrick, 2, 0);
        world.setBlock(i + 13, j + 1, k + 24, Blocks.stonebrick, 2, 0);
        world.setBlock(i + 13, j + 2, k + 5, Blocks.stonebrick, 2, 0);
        world.setBlock(i + 13, j + 2, k + 6, Blocks.stonebrick, 1, 0);
        world.setBlock(i + 13, j + 2, k + 22, Blocks.stonebrick, 2, 0);
        world.setBlock(i + 14, j + 0, k + 0, (Block)Blocks.grass);
        world.setBlock(i + 14, j + 0, k + 1, (Block)Blocks.grass);
        world.setBlock(i + 14, j + 0, k + 2, (Block)Blocks.grass);
        world.setBlock(i + 14, j + 0, k + 3, Blocks.dirt);
        world.setBlock(i + 14, j + 0, k + 4, Blocks.dirt);
        world.setBlock(i + 14, j + 0, k + 5, Blocks.dirt);
        world.setBlock(i + 14, j + 0, k + 6, Blocks.mossy_cobblestone);
        world.setBlock(i + 14, j + 0, k + 7, Blocks.cobblestone);
        world.setBlock(i + 14, j + 0, k + 8, Blocks.cobblestone);
        world.setBlock(i + 14, j + 0, k + 9, Blocks.cobblestone);
        world.setBlock(i + 14, j + 0, k + 10, (Block)Blocks.grass);
        world.setBlock(i + 14, j + 0, k + 11, Blocks.cobblestone);
        world.setBlock(i + 14, j + 0, k + 12, Blocks.mossy_cobblestone);
        world.setBlock(i + 14, j + 0, k + 13, Blocks.stonebrick, 2, 0);
        world.setBlock(i + 14, j + 0, k + 14, Blocks.dirt);
        world.setBlock(i + 14, j + 0, k + 15, Blocks.cobblestone);
        world.setBlock(i + 14, j + 0, k + 16, Blocks.cobblestone);
        world.setBlock(i + 14, j + 0, k + 17, Blocks.dirt);
        world.setBlock(i + 14, j + 0, k + 18, Blocks.mossy_cobblestone);
        world.setBlock(i + 14, j + 0, k + 19, Blocks.cobblestone);
        world.setBlock(i + 14, j + 0, k + 20, (Block)Blocks.grass);
        world.setBlock(i + 14, j + 0, k + 21, Blocks.dirt);
        world.setBlock(i + 14, j + 0, k + 22, Blocks.dirt);
        world.setBlock(i + 14, j + 0, k + 23, (Block)Blocks.grass);
        world.setBlock(i + 14, j + 0, k + 24, Blocks.stonebrick, 2, 0);
        world.setBlock(i + 14, j + 0, k + 25, (Block)Blocks.grass);
        world.setBlock(i + 14, j + 1, k + 3, Blocks.stonebrick, 2, 0);
        world.setBlock(i + 14, j + 1, k + 4, Blocks.stonebrick, 2, 0);
        world.setBlock(i + 14, j + 1, k + 5, Blocks.stonebrick, 2, 0);
        world.setBlock(i + 14, j + 1, k + 6, Blocks.stonebrick, 2, 0);
        world.setBlock(i + 14, j + 1, k + 8, Blocks.stonebrick, 2, 0);
        world.setBlock(i + 14, j + 1, k + 14, Blocks.stonebrick, 2, 0);
        world.setBlock(i + 14, j + 1, k + 17, Blocks.stonebrick, 2, 0);
        world.setBlock(i + 14, j + 1, k + 21, Blocks.stonebrick, 2, 0);
        world.setBlock(i + 14, j + 1, k + 22, Blocks.stonebrick, 2, 0);
        world.setBlock(i + 14, j + 2, k + 4, Blocks.stonebrick, 2, 0);
        world.setBlock(i + 14, j + 12, k + 22, Blocks.stonebrick, 2, 0);
        world.setBlock(i + 15, j + 0, k + 0, (Block)Blocks.grass);
        world.setBlock(i + 15, j + 0, k + 1, (Block)Blocks.grass);
        world.setBlock(i + 15, j + 0, k + 2, Blocks.dirt);
        world.setBlock(i + 15, j + 0, k + 3, (Block)Blocks.grass);
        world.setBlock(i + 15, j + 0, k + 4, Blocks.dirt);
        world.setBlock(i + 15, j + 0, k + 5, Blocks.cobblestone);
        world.setBlock(i + 15, j + 0, k + 6, (Block)Blocks.grass);
        world.setBlock(i + 15, j + 0, k + 7, Blocks.dirt);
        world.setBlock(i + 15, j + 0, k + 8, Blocks.stonebrick, 2, 0);
        world.setBlock(i + 15, j + 0, k + 9, Blocks.dirt);
        world.setBlock(i + 15, j + 0, k + 10, Blocks.cobblestone);
        world.setBlock(i + 15, j + 0, k + 11, Blocks.dirt);
        world.setBlock(i + 15, j + 0, k + 12, Blocks.cobblestone);
        world.setBlock(i + 15, j + 0, k + 13, Blocks.stonebrick, 2, 0);
        world.setBlock(i + 15, j + 0, k + 14, (Block)Blocks.grass);
        world.setBlock(i + 15, j + 0, k + 15, Blocks.cobblestone);
        world.setBlock(i + 15, j + 0, k + 16, (Block)Blocks.grass);
        world.setBlock(i + 15, j + 0, k + 17, Blocks.cobblestone);
        world.setBlock(i + 15, j + 0, k + 18, Blocks.cobblestone);
        world.setBlock(i + 15, j + 0, k + 19, Blocks.stonebrick, 2, 0);
        world.setBlock(i + 15, j + 0, k + 20, Blocks.dirt);
        world.setBlock(i + 15, j + 0, k + 21, (Block)Blocks.grass);
        world.setBlock(i + 15, j + 0, k + 22, Blocks.stonebrick, 2, 0);
        world.setBlock(i + 15, j + 0, k + 23, (Block)Blocks.grass);
        world.setBlock(i + 15, j + 0, k + 24, Blocks.cobblestone);
        world.setBlock(i + 15, j + 0, k + 25, Blocks.stonebrick, 2, 0);
        world.setBlock(i + 15, j + 1, k + 2, Blocks.stonebrick, 2, 0);
        world.setBlock(i + 15, j + 1, k + 4, Blocks.stonebrick, 2, 0);
        world.setBlock(i + 15, j + 1, k + 5, (Block)Blocks.stone_slab, 3, 0);
        world.setBlock(i + 15, j + 1, k + 7, Blocks.stonebrick, 2, 0);
        world.setBlock(i + 15, j + 1, k + 8, Blocks.stonebrick, 1, 0);
        world.setBlock(i + 15, j + 1, k + 9, Blocks.stonebrick, 2, 0);
        world.setBlock(i + 15, j + 1, k + 11, Blocks.stonebrick, 2, 0);
        world.setBlock(i + 15, j + 1, k + 12, (Block)Blocks.stone_slab, 3, 0);
        world.setBlock(i + 15, j + 1, k + 13, Blocks.stonebrick, 2, 0);
        world.setBlock(i + 15, j + 1, k + 17, Blocks.stonebrick, 2, 0);
        world.setBlock(i + 15, j + 1, k + 18, Blocks.stonebrick, 2, 0);
        world.setBlock(i + 15, j + 1, k + 20, Blocks.stonebrick, 2, 0);
        world.setBlock(i + 15, j + 2, k + 4, Blocks.stonebrick, 2, 0);
        world.setBlock(i + 15, j + 2, k + 13, Blocks.stonebrick, 2, 0);
        world.setBlock(i + 15, j + 12, k + 21, Blocks.stonebrick, 2, 0);
        world.setBlock(i + 15, j + 12, k + 22, Blocks.stonebrick, 2, 0);
        world.setBlock(i + 16, j + 0, k + 0, (Block)Blocks.grass);
        world.setBlock(i + 16, j + 0, k + 1, Blocks.cobblestone);
        world.setBlock(i + 16, j + 0, k + 2, Blocks.cobblestone);
        world.setBlock(i + 16, j + 0, k + 3, (Block)Blocks.grass);
        world.setBlock(i + 16, j + 0, k + 4, Blocks.dirt);
        world.setBlock(i + 16, j + 0, k + 5, Blocks.cobblestone);
        world.setBlock(i + 16, j + 0, k + 6, Blocks.mossy_cobblestone);
        world.setBlock(i + 16, j + 0, k + 7, Blocks.dirt);
        world.setBlock(i + 16, j + 0, k + 8, Blocks.stonebrick, 2, 0);
        world.setBlock(i + 16, j + 0, k + 9, Blocks.dirt);
        world.setBlock(i + 16, j + 0, k + 10, Blocks.stonebrick, 2, 0);
        world.setBlock(i + 16, j + 0, k + 11, Blocks.mossy_cobblestone);
        world.setBlock(i + 16, j + 0, k + 12, Blocks.cobblestone);
        world.setBlock(i + 16, j + 0, k + 13, Blocks.stonebrick, 2, 0);
        world.setBlock(i + 16, j + 0, k + 14, Blocks.cobblestone);
        world.setBlock(i + 16, j + 0, k + 15, Blocks.dirt);
        world.setBlock(i + 16, j + 0, k + 16, (Block)Blocks.grass);
        world.setBlock(i + 16, j + 0, k + 17, Blocks.cobblestone);
        world.setBlock(i + 16, j + 0, k + 18, (Block)Blocks.grass);
        world.setBlock(i + 16, j + 0, k + 19, Blocks.mossy_cobblestone);
        world.setBlock(i + 16, j + 0, k + 20, Blocks.cobblestone);
        world.setBlock(i + 16, j + 0, k + 21, (Block)Blocks.grass);
        world.setBlock(i + 16, j + 0, k + 22, Blocks.cobblestone);
        world.setBlock(i + 16, j + 0, k + 23, (Block)Blocks.grass);
        world.setBlock(i + 16, j + 0, k + 24, (Block)Blocks.grass);
        world.setBlock(i + 16, j + 0, k + 25, (Block)Blocks.grass);
        world.setBlock(i + 16, j + 1, k + 4, Blocks.stonebrick, 2, 0);
        world.setBlock(i + 16, j + 1, k + 5, Blocks.stonebrick, 1, 0);
        world.setBlock(i + 16, j + 1, k + 6, Blocks.stonebrick, 1, 0);
        world.setBlock(i + 16, j + 1, k + 7, Blocks.stonebrick, 2, 0);
        WorldGenWarlordDungeon.chest(world, rand, i + 16, j + 1, k + 8, "dungeonChest", rand.nextInt(5) + 1);
        world.setBlock(i + 16, j + 1, k + 9, Blocks.stonebrick, 2, 0);
        world.setBlock(i + 16, j + 1, k + 10, Blocks.stonebrick, 2, 0);
        world.setBlock(i + 16, j + 1, k + 12, Blocks.stonebrick, 2, 0);
        world.setBlock(i + 16, j + 1, k + 14, Blocks.stonebrick, 2, 0);
        world.setBlock(i + 16, j + 1, k + 15, Blocks.stonebrick, 2, 0);
        world.setBlock(i + 16, j + 1, k + 17, Blocks.stonebrick, 2, 0);
        world.setBlock(i + 16, j + 1, k + 20, Blocks.stonebrick, 2, 0);
        world.setBlock(i + 16, j + 2, k + 4, Blocks.stonebrick, 2, 0);
        world.setBlock(i + 16, j + 2, k + 7, Blocks.stonebrick, 2, 0);
        world.setBlock(i + 16, j + 2, k + 14, Blocks.stonebrick, 2, 0);
        world.setBlock(i + 16, j + 2, k + 15, Blocks.stonebrick, 2, 0);
        world.setBlock(i + 16, j + 12, k + 21, Blocks.stonebrick, 2, 0);
        world.setBlock(i + 16, j + 12, k + 22, Blocks.stonebrick, 2, 0);
        world.setBlock(i + 16, j + 13, k + 21, (Block)Blocks.stone_slab, 3, 0);
        world.setBlock(i + 17, j + 0, k + 0, (Block)Blocks.grass);
        world.setBlock(i + 17, j + 0, k + 1, (Block)Blocks.grass);
        world.setBlock(i + 17, j + 0, k + 2, Blocks.dirt);
        world.setBlock(i + 17, j + 0, k + 3, (Block)Blocks.grass);
        world.setBlock(i + 17, j + 0, k + 4, Blocks.mossy_cobblestone);
        world.setBlock(i + 17, j + 0, k + 5, Blocks.dirt);
        world.setBlock(i + 17, j + 0, k + 6, (Block)Blocks.grass);
        world.setBlock(i + 17, j + 0, k + 7, Blocks.cobblestone);
        world.setBlock(i + 17, j + 0, k + 8, (Block)Blocks.grass);
        world.setBlock(i + 17, j + 0, k + 9, Blocks.mossy_cobblestone);
        world.setBlock(i + 17, j + 0, k + 10, (Block)Blocks.grass);
        world.setBlock(i + 17, j + 0, k + 11, Blocks.mossy_cobblestone);
        world.setBlock(i + 17, j + 0, k + 12, (Block)Blocks.grass);
        world.setBlock(i + 17, j + 0, k + 13, Blocks.cobblestone);
        world.setBlock(i + 17, j + 0, k + 14, Blocks.dirt);
        world.setBlock(i + 17, j + 0, k + 15, Blocks.cobblestone);
        world.setBlock(i + 17, j + 0, k + 16, (Block)Blocks.grass);
        world.setBlock(i + 17, j + 0, k + 17, (Block)Blocks.grass);
        world.setBlock(i + 17, j + 0, k + 18, Blocks.mossy_cobblestone);
        world.setBlock(i + 17, j + 0, k + 19, Blocks.dirt);
        world.setBlock(i + 17, j + 0, k + 20, (Block)Blocks.grass);
        world.setBlock(i + 17, j + 0, k + 21, Blocks.cobblestone);
        world.setBlock(i + 17, j + 0, k + 22, Blocks.dirt);
        world.setBlock(i + 17, j + 0, k + 23, (Block)Blocks.grass);
        world.setBlock(i + 17, j + 0, k + 24, Blocks.cobblestone);
        world.setBlock(i + 17, j + 0, k + 25, (Block)Blocks.grass);
        world.setBlock(i + 17, j + 1, k + 2, Blocks.stonebrick, 2, 0);
        world.setBlock(i + 17, j + 1, k + 4, Blocks.stonebrick, 1, 0);
        world.setBlock(i + 17, j + 1, k + 5, Blocks.stonebrick, 2, 0);
        world.setBlock(i + 17, j + 1, k + 11, Blocks.stonebrick, 1, 0);
        world.setBlock(i + 17, j + 1, k + 14, Blocks.stonebrick, 2, 0);
        world.setBlock(i + 17, j + 1, k + 15, Blocks.stonebrick, 2, 0);
        world.setBlock(i + 17, j + 1, k + 19, Blocks.stonebrick, 2, 0);
        world.setBlock(i + 17, j + 1, k + 22, Blocks.stonebrick, 1, 0);
        world.setBlock(i + 17, j + 1, k + 24, (Block)Blocks.stone_slab, 3, 0);
        world.setBlock(i + 17, j + 11, k + 21, Blocks.stonebrick, 2, 0);
        world.setBlock(i + 17, j + 11, k + 22, Blocks.stonebrick, 2, 0);
        world.setBlock(i + 17, j + 12, k + 21, Blocks.stonebrick, 1, 0);
        world.setBlock(i + 17, j + 12, k + 22, Blocks.stonebrick, 1, 0);
        world.setBlock(i + 18, j + 0, k + 0, (Block)Blocks.grass);
        world.setBlock(i + 18, j + 0, k + 1, Blocks.cobblestone);
        world.setBlock(i + 18, j + 0, k + 2, (Block)Blocks.grass);
        world.setBlock(i + 18, j + 0, k + 3, (Block)Blocks.grass);
        world.setBlock(i + 18, j + 0, k + 4, Blocks.mossy_cobblestone);
        world.setBlock(i + 18, j + 0, k + 5, Blocks.cobblestone);
        world.setBlock(i + 18, j + 0, k + 6, (Block)Blocks.grass);
        world.setBlock(i + 18, j + 0, k + 7, (Block)Blocks.grass);
        world.setBlock(i + 18, j + 0, k + 8, Blocks.dirt);
        world.setBlock(i + 18, j + 0, k + 9, Blocks.cobblestone);
        world.setBlock(i + 18, j + 0, k + 10, (Block)Blocks.grass);
        world.setBlock(i + 18, j + 0, k + 11, Blocks.cobblestone);
        world.setBlock(i + 18, j + 0, k + 12, (Block)Blocks.grass);
        world.setBlock(i + 18, j + 0, k + 13, Blocks.cobblestone);
        world.setBlock(i + 18, j + 0, k + 14, (Block)Blocks.grass);
        world.setBlock(i + 18, j + 0, k + 15, (Block)Blocks.grass);
        world.setBlock(i + 18, j + 0, k + 16, (Block)Blocks.grass);
        world.setBlock(i + 18, j + 0, k + 17, Blocks.cobblestone);
        world.setBlock(i + 18, j + 0, k + 18, Blocks.cobblestone);
        world.setBlock(i + 18, j + 0, k + 19, Blocks.cobblestone);
        world.setBlock(i + 18, j + 0, k + 20, Blocks.dirt);
        world.setBlock(i + 18, j + 0, k + 21, Blocks.cobblestone);
        world.setBlock(i + 18, j + 0, k + 22, Blocks.cobblestone);
        world.setBlock(i + 18, j + 0, k + 23, (Block)Blocks.grass);
        world.setBlock(i + 18, j + 0, k + 24, Blocks.stonebrick, 2, 0);
        world.setBlock(i + 18, j + 0, k + 25, (Block)Blocks.grass);
        world.setBlock(i + 18, j + 1, k + 4, Blocks.stonebrick, 2, 0);
        world.setBlock(i + 18, j + 1, k + 6, (Block)Blocks.stone_slab, 3, 0);
        world.setBlock(i + 18, j + 1, k + 8, Blocks.stonebrick, 2, 0);
        world.setBlock(i + 18, j + 1, k + 10, (Block)Blocks.stone_slab, 3, 0);
        world.setBlock(i + 18, j + 1, k + 11, (Block)Blocks.stone_slab, 3, 0);
        world.setBlock(i + 18, j + 1, k + 13, (Block)Blocks.stone_slab, 3, 0);
        Dungeons.spawner(world, i + 18, j + 1, k + 16, 4, 2);
        world.setBlock(i + 18, j + 1, k + 17, Blocks.stonebrick, 2, 0);
        world.setBlock(i + 18, j + 1, k + 18, (Block)Blocks.stone_slab, 3, 0);
        world.setBlock(i + 18, j + 1, k + 20, Blocks.stonebrick, 2, 0);
        world.setBlock(i + 18, j + 2, k + 4, Blocks.stonebrick, 1, 0);
        world.setBlock(i + 18, j + 11, k + 21, Blocks.stonebrick, 2, 0);
        world.setBlock(i + 18, j + 11, k + 22, Blocks.stonebrick, 1, 0);
        world.setBlock(i + 18, j + 12, k + 21, Blocks.stonebrick, 2, 0);
        world.setBlock(i + 18, j + 12, k + 22, Blocks.stonebrick, 2, 0);
        world.setBlock(i + 18, j + 13, k + 22, Blocks.stonebrick, 2, 0);
        world.setBlock(i + 19, j + 0, k + 0, (Block)Blocks.grass);
        world.setBlock(i + 19, j + 0, k + 1, Blocks.stonebrick, 2, 0);
        world.setBlock(i + 19, j + 0, k + 2, Blocks.dirt);
        world.setBlock(i + 19, j + 0, k + 3, (Block)Blocks.grass);
        world.setBlock(i + 19, j + 0, k + 4, Blocks.dirt);
        world.setBlock(i + 19, j + 0, k + 5, Blocks.dirt);
        world.setBlock(i + 19, j + 0, k + 6, (Block)Blocks.grass);
        world.setBlock(i + 19, j + 0, k + 7, Blocks.cobblestone);
        world.setBlock(i + 19, j + 0, k + 8, Blocks.dirt);
        world.setBlock(i + 19, j + 0, k + 9, Blocks.cobblestone);
        world.setBlock(i + 19, j + 0, k + 10, (Block)Blocks.grass);
        world.setBlock(i + 19, j + 0, k + 11, Blocks.dirt);
        world.setBlock(i + 19, j + 0, k + 12, Blocks.stonebrick, 2, 0);
        world.setBlock(i + 19, j + 0, k + 13, (Block)Blocks.grass);
        world.setBlock(i + 19, j + 0, k + 14, (Block)Blocks.grass);
        world.setBlock(i + 19, j + 0, k + 15, Blocks.cobblestone);
        world.setBlock(i + 19, j + 0, k + 16, Blocks.cobblestone);
        world.setBlock(i + 19, j + 0, k + 17, Blocks.mossy_cobblestone);
        world.setBlock(i + 19, j + 0, k + 18, Blocks.mossy_cobblestone);
        world.setBlock(i + 19, j + 0, k + 19, (Block)Blocks.grass);
        world.setBlock(i + 19, j + 0, k + 20, Blocks.stonebrick, 2, 0);
        world.setBlock(i + 19, j + 0, k + 21, Blocks.cobblestone);
        world.setBlock(i + 19, j + 0, k + 22, Blocks.cobblestone);
        world.setBlock(i + 19, j + 0, k + 23, (Block)Blocks.grass);
        world.setBlock(i + 19, j + 0, k + 24, (Block)Blocks.grass);
        world.setBlock(i + 19, j + 0, k + 25, (Block)Blocks.grass);
        world.setBlock(i + 19, j + 1, k + 2, Blocks.stonebrick, 2, 0);
        world.setBlock(i + 19, j + 1, k + 4, Blocks.stonebrick, 2, 0);
        world.setBlock(i + 19, j + 1, k + 5, Blocks.stonebrick, 2, 0);
        world.setBlock(i + 19, j + 1, k + 7, Blocks.stonebrick, 2, 0);
        world.setBlock(i + 19, j + 1, k + 8, Blocks.stonebrick, 2, 0);
        world.setBlock(i + 19, j + 1, k + 11, Blocks.stonebrick, 2, 0);
        world.setBlock(i + 19, j + 1, k + 15, (Block)Blocks.stone_slab, 3, 0);
        world.setBlock(i + 19, j + 1, k + 16, (Block)Blocks.stone_slab, 3, 0);
        world.setBlock(i + 19, j + 1, k + 18, Blocks.stonebrick, 2, 0);
        world.setBlock(i + 19, j + 1, k + 22, (Block)Blocks.stone_slab, 3, 0);
        world.setBlock(i + 19, j + 2, k + 4, Blocks.stonebrick, 2, 0);
        world.setBlock(i + 19, j + 2, k + 5, Blocks.stonebrick, 2, 0);
        world.setBlock(i + 19, j + 2, k + 7, Blocks.stonebrick, 2, 0);
        world.setBlock(i + 19, j + 2, k + 11, Blocks.stonebrick, 1, 0);
        world.setBlock(i + 19, j + 10, k + 21, Blocks.stonebrick, 2, 0);
        world.setBlock(i + 19, j + 10, k + 22, Blocks.stonebrick, 2, 0);
        world.setBlock(i + 19, j + 11, k + 22, Blocks.stonebrick, 2, 0);
        world.setBlock(i + 19, j + 12, k + 21, Blocks.stonebrick, 2, 0);
        world.setBlock(i + 19, j + 12, k + 22, Blocks.stonebrick, 1, 0);
        world.setBlock(i + 20, j + 0, k + 0, (Block)Blocks.grass);
        world.setBlock(i + 20, j + 0, k + 1, (Block)Blocks.grass);
        world.setBlock(i + 20, j + 0, k + 2, Blocks.stonebrick, 2, 0);
        world.setBlock(i + 20, j + 0, k + 3, (Block)Blocks.grass);
        world.setBlock(i + 20, j + 0, k + 4, Blocks.stonebrick, 2, 0);
        world.setBlock(i + 20, j + 0, k + 5, Blocks.dirt);
        world.setBlock(i + 20, j + 0, k + 6, Blocks.cobblestone);
        world.setBlock(i + 20, j + 0, k + 7, Blocks.cobblestone);
        world.setBlock(i + 20, j + 0, k + 8, (Block)Blocks.grass);
        world.setBlock(i + 20, j + 0, k + 9, (Block)Blocks.grass);
        world.setBlock(i + 20, j + 0, k + 10, Blocks.cobblestone);
        world.setBlock(i + 20, j + 0, k + 11, Blocks.dirt);
        world.setBlock(i + 20, j + 0, k + 12, Blocks.mossy_cobblestone);
        world.setBlock(i + 20, j + 0, k + 13, Blocks.dirt);
        world.setBlock(i + 20, j + 0, k + 14, (Block)Blocks.grass);
        world.setBlock(i + 20, j + 0, k + 15, Blocks.cobblestone);
        world.setBlock(i + 20, j + 0, k + 16, Blocks.mossy_cobblestone);
        world.setBlock(i + 20, j + 0, k + 17, Blocks.cobblestone);
        world.setBlock(i + 20, j + 0, k + 18, (Block)Blocks.grass);
        world.setBlock(i + 20, j + 0, k + 19, Blocks.stonebrick, 2, 0);
        world.setBlock(i + 20, j + 0, k + 20, (Block)Blocks.grass);
        world.setBlock(i + 20, j + 0, k + 21, Blocks.stonebrick, 2, 0);
        world.setBlock(i + 20, j + 0, k + 22, Blocks.cobblestone);
        world.setBlock(i + 20, j + 0, k + 23, Blocks.stonebrick, 2, 0);
        world.setBlock(i + 20, j + 0, k + 24, Blocks.cobblestone);
        world.setBlock(i + 20, j + 0, k + 25, Blocks.cobblestone);
        world.setBlock(i + 20, j + 1, k + 5, Blocks.stonebrick, 1, 0);
        world.setBlock(i + 20, j + 1, k + 8, (Block)Blocks.stone_slab, 3, 0);
        world.setBlock(i + 20, j + 1, k + 11, Blocks.stonebrick, 2, 0);
        world.setBlock(i + 20, j + 1, k + 13, Blocks.stonebrick, 2, 0);
        world.setBlock(i + 20, j + 10, k + 21, Blocks.stonebrick, 2, 0);
        world.setBlock(i + 20, j + 10, k + 22, Blocks.stonebrick, 2, 0);
        world.setBlock(i + 20, j + 11, k + 21, Blocks.stonebrick, 2, 0);
        world.setBlock(i + 20, j + 11, k + 22, Blocks.stonebrick, 1, 0);
        world.setBlock(i + 20, j + 12, k + 21, Blocks.stonebrick, 1, 0);
        world.setBlock(i + 20, j + 12, k + 22, Blocks.stonebrick, 2, 0);
        world.setBlock(i + 20, j + 13, k + 21, (Block)Blocks.stone_slab, 3, 0);
        world.setBlock(i + 21, j + 0, k + 0, (Block)Blocks.grass);
        world.setBlock(i + 21, j + 0, k + 1, Blocks.dirt);
        world.setBlock(i + 21, j + 0, k + 2, (Block)Blocks.grass);
        world.setBlock(i + 21, j + 0, k + 3, (Block)Blocks.grass);
        world.setBlock(i + 21, j + 0, k + 4, Blocks.dirt);
        world.setBlock(i + 21, j + 0, k + 5, Blocks.cobblestone);
        world.setBlock(i + 21, j + 0, k + 6, Blocks.stonebrick, 2, 0);
        world.setBlock(i + 21, j + 0, k + 7, Blocks.dirt);
        world.setBlock(i + 21, j + 0, k + 8, Blocks.cobblestone);
        world.setBlock(i + 21, j + 0, k + 9, Blocks.dirt);
        world.setBlock(i + 21, j + 0, k + 10, Blocks.dirt);
        world.setBlock(i + 21, j + 0, k + 11, Blocks.cobblestone);
        world.setBlock(i + 21, j + 0, k + 12, Blocks.mossy_cobblestone);
        world.setBlock(i + 21, j + 0, k + 13, Blocks.mossy_cobblestone);
        world.setBlock(i + 21, j + 0, k + 14, Blocks.cobblestone);
        world.setBlock(i + 21, j + 0, k + 15, Blocks.dirt);
        world.setBlock(i + 21, j + 0, k + 16, Blocks.cobblestone);
        world.setBlock(i + 21, j + 0, k + 17, (Block)Blocks.grass);
        world.setBlock(i + 21, j + 0, k + 18, (Block)Blocks.grass);
        world.setBlock(i + 21, j + 0, k + 19, Blocks.cobblestone);
        world.setBlock(i + 21, j + 0, k + 20, (Block)Blocks.grass);
        world.setBlock(i + 21, j + 0, k + 21, Blocks.cobblestone);
        world.setBlock(i + 21, j + 0, k + 22, Blocks.cobblestone);
        world.setBlock(i + 21, j + 0, k + 23, Blocks.cobblestone);
        world.setBlock(i + 21, j + 0, k + 24, (Block)Blocks.grass);
        world.setBlock(i + 21, j + 0, k + 25, (Block)Blocks.grass);
        world.setBlock(i + 21, j + 1, k + 1, Blocks.stonebrick, 2, 0);
        world.setBlock(i + 21, j + 1, k + 4, Blocks.stonebrick, 2, 0);
        world.setBlock(i + 21, j + 1, k + 6, Blocks.stonebrick, 2, 0);
        world.setBlock(i + 21, j + 1, k + 7, Blocks.stonebrick, 2, 0);
        world.setBlock(i + 21, j + 1, k + 9, Blocks.stonebrick, 1, 0);
        world.setBlock(i + 21, j + 1, k + 10, Blocks.stonebrick, 2, 0);
        world.setBlock(i + 21, j + 1, k + 11, Blocks.stonebrick, 1, 0);
        world.setBlock(i + 21, j + 1, k + 13, Blocks.stonebrick, 2, 0);
        world.setBlock(i + 21, j + 1, k + 15, Blocks.stonebrick, 2, 0);
        world.setBlock(i + 21, j + 1, k + 17, (Block)Blocks.stone_slab, 3, 0);
        world.setBlock(i + 21, j + 1, k + 19, Blocks.stonebrick, 2, 0);
        world.setBlock(i + 21, j + 1, k + 21, (Block)Blocks.stone_slab, 3, 0);
        world.setBlock(i + 21, j + 1, k + 25, (Block)Blocks.stone_slab, 3, 0);
        world.setBlock(i + 21, j + 9, k + 21, Blocks.stonebrick, 2, 0);
        world.setBlock(i + 21, j + 9, k + 22, Blocks.stonebrick, 2, 0);
        world.setBlock(i + 21, j + 10, k + 21, Blocks.stonebrick, 2, 0);
        world.setBlock(i + 21, j + 10, k + 22, Blocks.stonebrick, 2, 0);
        world.setBlock(i + 21, j + 11, k + 21, Blocks.stonebrick, 1, 0);
        world.setBlock(i + 21, j + 11, k + 22, Blocks.stonebrick, 1, 0);
        world.setBlock(i + 21, j + 12, k + 21, Blocks.stonebrick, 1, 0);
        world.setBlock(i + 21, j + 12, k + 22, Blocks.stonebrick, 2, 0);
        world.setBlock(i + 22, j + 0, k + 0, (Block)Blocks.grass);
        world.setBlock(i + 22, j + 0, k + 1, (Block)Blocks.grass);
        world.setBlock(i + 22, j + 0, k + 2, Blocks.stonebrick, 2, 0);
        world.setBlock(i + 22, j + 0, k + 3, (Block)Blocks.grass);
        world.setBlock(i + 22, j + 0, k + 4, Blocks.mossy_cobblestone);
        world.setBlock(i + 22, j + 0, k + 5, (Block)Blocks.grass);
        world.setBlock(i + 22, j + 0, k + 6, Blocks.mossy_cobblestone);
        world.setBlock(i + 22, j + 0, k + 7, Blocks.cobblestone);
        world.setBlock(i + 22, j + 0, k + 8, Blocks.dirt);
        world.setBlock(i + 22, j + 0, k + 9, Blocks.cobblestone);
        world.setBlock(i + 22, j + 0, k + 10, Blocks.mossy_cobblestone);
        world.setBlock(i + 22, j + 0, k + 11, Blocks.dirt);
        world.setBlock(i + 22, j + 0, k + 12, Blocks.stonebrick, 2, 0);
        world.setBlock(i + 22, j + 0, k + 13, Blocks.dirt);
        world.setBlock(i + 22, j + 0, k + 14, Blocks.cobblestone);
        world.setBlock(i + 22, j + 0, k + 15, Blocks.dirt);
        world.setBlock(i + 22, j + 0, k + 16, Blocks.cobblestone);
        world.setBlock(i + 22, j + 0, k + 17, Blocks.cobblestone);
        world.setBlock(i + 22, j + 0, k + 18, Blocks.dirt);
        world.setBlock(i + 22, j + 0, k + 19, Blocks.dirt);
        world.setBlock(i + 22, j + 0, k + 20, Blocks.cobblestone);
        world.setBlock(i + 22, j + 0, k + 21, Blocks.cobblestone);
        world.setBlock(i + 22, j + 0, k + 22, Blocks.cobblestone);
        world.setBlock(i + 22, j + 0, k + 23, (Block)Blocks.grass);
        world.setBlock(i + 22, j + 0, k + 24, Blocks.stonebrick, 2, 0);
        world.setBlock(i + 22, j + 0, k + 25, Blocks.cobblestone);
        world.setBlock(i + 22, j + 1, k + 5, (Block)Blocks.stone_slab, 3, 0);
        world.setBlock(i + 22, j + 1, k + 8, Blocks.stonebrick, 2, 0);
        world.setBlock(i + 22, j + 1, k + 11, Blocks.stonebrick, 2, 0);
        world.setBlock(i + 22, j + 1, k + 13, Blocks.stonebrick, 2, 0);
        world.setBlock(i + 22, j + 1, k + 15, Blocks.stonebrick, 2, 0);
        world.setBlock(i + 22, j + 1, k + 16, Blocks.stonebrick, 2, 0);
        world.setBlock(i + 22, j + 1, k + 18, Blocks.stonebrick, 2, 0);
        world.setBlock(i + 22, j + 1, k + 19, Blocks.stonebrick, 2, 0);
        world.setBlock(i + 22, j + 2, k + 8, Blocks.stonebrick, 1, 0);
        world.setBlock(i + 22, j + 2, k + 16, Blocks.stonebrick, 2, 0);
        world.setBlock(i + 22, j + 8, k + 21, Blocks.stonebrick, 2, 0);
        world.setBlock(i + 22, j + 8, k + 22, Blocks.stonebrick, 1, 0);
        world.setBlock(i + 22, j + 9, k + 21, Blocks.stonebrick, 2, 0);
        world.setBlock(i + 22, j + 9, k + 22, Blocks.stonebrick, 2, 0);
        world.setBlock(i + 22, j + 10, k + 21, Blocks.stonebrick, 2, 0);
        world.setBlock(i + 22, j + 10, k + 22, Blocks.stonebrick, 1, 0);
        world.setBlock(i + 22, j + 11, k + 21, Blocks.stonebrick, 2, 0);
        world.setBlock(i + 22, j + 11, k + 22, Blocks.stonebrick, 2, 0);
        world.setBlock(i + 22, j + 12, k + 21, Blocks.stonebrick, 2, 0);
        world.setBlock(i + 22, j + 12, k + 22, Blocks.stonebrick, 2, 0);
        world.setBlock(i + 22, j + 14, k + 22, Blocks.stonebrick, 2, 0);
        world.setBlock(i + 23, j + 0, k + 0, (Block)Blocks.grass);
        world.setBlock(i + 23, j + 0, k + 1, Blocks.cobblestone);
        world.setBlock(i + 23, j + 0, k + 2, (Block)Blocks.grass);
        world.setBlock(i + 23, j + 0, k + 3, Blocks.dirt);
        world.setBlock(i + 23, j + 0, k + 4, Blocks.stonebrick, 2, 0);
        world.setBlock(i + 23, j + 0, k + 5, Blocks.dirt);
        world.setBlock(i + 23, j + 0, k + 6, Blocks.mossy_cobblestone);
        world.setBlock(i + 23, j + 0, k + 7, (Block)Blocks.grass);
        world.setBlock(i + 23, j + 0, k + 8, Blocks.dirt);
        world.setBlock(i + 23, j + 0, k + 9, Blocks.stonebrick, 2, 0);
        world.setBlock(i + 23, j + 0, k + 10, Blocks.dirt);
        world.setBlock(i + 23, j + 0, k + 11, Blocks.dirt);
        world.setBlock(i + 23, j + 0, k + 12, Blocks.dirt);
        world.setBlock(i + 23, j + 0, k + 13, Blocks.stonebrick, 2, 0);
        world.setBlock(i + 23, j + 0, k + 14, Blocks.dirt);
        world.setBlock(i + 23, j + 0, k + 15, Blocks.cobblestone);
        world.setBlock(i + 23, j + 0, k + 16, Blocks.dirt);
        world.setBlock(i + 23, j + 0, k + 17, Blocks.cobblestone);
        world.setBlock(i + 23, j + 0, k + 18, (Block)Blocks.grass);
        world.setBlock(i + 23, j + 0, k + 19, Blocks.cobblestone);
        world.setBlock(i + 23, j + 0, k + 20, Blocks.dirt);
        world.setBlock(i + 23, j + 0, k + 21, Blocks.cobblestone);
        world.setBlock(i + 23, j + 0, k + 22, Blocks.cobblestone);
        world.setBlock(i + 23, j + 0, k + 23, Blocks.dirt);
        world.setBlock(i + 23, j + 0, k + 24, Blocks.dirt);
        world.setBlock(i + 23, j + 0, k + 25, (Block)Blocks.grass);
        world.setBlock(i + 23, j + 1, k + 3, Blocks.stonebrick, 2, 0);
        world.setBlock(i + 23, j + 1, k + 4, Blocks.stonebrick, 2, 0);
        world.setBlock(i + 23, j + 1, k + 5, Blocks.stonebrick, 2, 0);
        world.setBlock(i + 23, j + 1, k + 8, Blocks.stonebrick, 2, 0);
        world.setBlock(i + 23, j + 1, k + 10, Blocks.stonebrick, 2, 0);
        world.setBlock(i + 23, j + 1, k + 11, Blocks.stonebrick, 2, 0);
        world.setBlock(i + 23, j + 1, k + 12, Blocks.stonebrick, 2, 0);
        world.setBlock(i + 23, j + 1, k + 13, Blocks.stonebrick, 1, 0);
        world.setBlock(i + 23, j + 1, k + 14, Blocks.stonebrick, 2, 0);
        world.setBlock(i + 23, j + 1, k + 15, Blocks.stonebrick, 2, 0);
        world.setBlock(i + 23, j + 1, k + 16, Blocks.stonebrick, 1, 0);
        world.setBlock(i + 23, j + 1, k + 19, Blocks.stonebrick, 2, 0);
        world.setBlock(i + 23, j + 1, k + 20, Blocks.stonebrick, 2, 0);
        world.setBlock(i + 23, j + 1, k + 21, Blocks.stonebrick, 2, 0);
        world.setBlock(i + 23, j + 1, k + 22, Blocks.stonebrick, 1, 0);
        world.setBlock(i + 23, j + 1, k + 23, Blocks.stonebrick, 2, 0);
        world.setBlock(i + 23, j + 1, k + 24, Blocks.stonebrick, 2, 0);
        world.setBlock(i + 23, j + 2, k + 4, Blocks.stonebrick, 2, 0);
        world.setBlock(i + 23, j + 2, k + 5, Blocks.stonebrick, 2, 0);
        world.setBlock(i + 23, j + 2, k + 8, Blocks.stonebrick, 2, 0);
        world.setBlock(i + 23, j + 2, k + 9, Blocks.stonebrick, 1, 0);
        world.setBlock(i + 23, j + 2, k + 12, Blocks.stonebrick, 2, 0);
        world.setBlock(i + 23, j + 2, k + 14, Blocks.stonebrick, 1, 0);
        world.setBlock(i + 23, j + 2, k + 21, Blocks.stonebrick, 2, 0);
        world.setBlock(i + 23, j + 2, k + 22, Blocks.stonebrick, 1, 0);
        world.setBlock(i + 23, j + 3, k + 4, Blocks.stonebrick, 2, 0);
        world.setBlock(i + 23, j + 3, k + 5, Blocks.stonebrick, 2, 0);
        world.setBlock(i + 23, j + 3, k + 21, Blocks.stonebrick, 1, 0);
        world.setBlock(i + 23, j + 3, k + 22, Blocks.stonebrick, 1, 0);
        world.setBlock(i + 23, j + 4, k + 4, Blocks.stonebrick, 1, 0);
        world.setBlock(i + 23, j + 4, k + 5, Blocks.stonebrick, 2, 0);
        world.setBlock(i + 23, j + 4, k + 21, Blocks.stonebrick, 1, 0);
        world.setBlock(i + 23, j + 4, k + 22, Blocks.stonebrick, 1, 0);
        world.setBlock(i + 23, j + 5, k + 4, Blocks.stonebrick, 1, 0);
        world.setBlock(i + 23, j + 5, k + 21, Blocks.stonebrick, 2, 0);
        world.setBlock(i + 23, j + 5, k + 22, Blocks.stonebrick, 2, 0);
        world.setBlock(i + 23, j + 6, k + 4, Blocks.stonebrick, 2, 0);
        world.setBlock(i + 23, j + 6, k + 21, Blocks.stonebrick, 2, 0);
        world.setBlock(i + 23, j + 6, k + 22, Blocks.stonebrick, 2, 0);
        world.setBlock(i + 23, j + 7, k + 21, Blocks.stonebrick, 2, 0);
        world.setBlock(i + 23, j + 7, k + 22, Blocks.stonebrick, 2, 0);
        world.setBlock(i + 23, j + 8, k + 20, Blocks.stonebrick, 1, 0);
        world.setBlock(i + 23, j + 8, k + 21, Blocks.stonebrick, 2, 0);
        world.setBlock(i + 23, j + 8, k + 22, Blocks.stonebrick, 2, 0);
        world.setBlock(i + 23, j + 9, k + 19, Blocks.stonebrick, 2, 0);
        world.setBlock(i + 23, j + 9, k + 20, Blocks.stonebrick, 2, 0);
        world.setBlock(i + 23, j + 9, k + 21, Blocks.stonebrick, 2, 0);
        world.setBlock(i + 23, j + 9, k + 22, Blocks.stonebrick, 1, 0);
        world.setBlock(i + 23, j + 10, k + 16, Blocks.stonebrick, 2, 0);
        world.setBlock(i + 23, j + 10, k + 17, Blocks.stonebrick, 2, 0);
        world.setBlock(i + 23, j + 10, k + 18, Blocks.stonebrick, 2, 0);
        world.setBlock(i + 23, j + 10, k + 19, Blocks.stonebrick, 2, 0);
        world.setBlock(i + 23, j + 10, k + 20, Blocks.stonebrick, 1, 0);
        world.setBlock(i + 23, j + 10, k + 21, Blocks.stonebrick, 2, 0);
        world.setBlock(i + 23, j + 10, k + 22, Blocks.stonebrick, 2, 0);
        world.setBlock(i + 23, j + 11, k + 18, Blocks.stonebrick, 2, 0);
        world.setBlock(i + 23, j + 11, k + 19, (Block)Blocks.stone_slab, 3, 0);
        world.setBlock(i + 23, j + 11, k + 20, Blocks.stonebrick, 2, 0);
        world.setBlock(i + 23, j + 11, k + 21, Blocks.stonebrick, 2, 0);
        world.setBlock(i + 23, j + 11, k + 22, Blocks.stonebrick, 2, 0);
        world.setBlock(i + 23, j + 12, k + 21, Blocks.stonebrick, 2, 0);
        world.setBlock(i + 23, j + 12, k + 22, Blocks.stonebrick, 1, 0);
        world.setBlock(i + 23, j + 13, k + 21, (Block)Blocks.stone_slab, 3, 0);
        world.setBlock(i + 23, j + 13, k + 22, Blocks.stonebrick, 2, 0);
        world.setBlock(i + 23, j + 14, k + 22, Blocks.stonebrick, 2, 0);
        world.setBlock(i + 23, j + 15, k + 22, Blocks.stonebrick, 2, 0);
        world.setBlock(i + 24, j + 0, k + 0, (Block)Blocks.grass);
        world.setBlock(i + 24, j + 0, k + 1, Blocks.dirt);
        world.setBlock(i + 24, j + 0, k + 2, (Block)Blocks.grass);
        world.setBlock(i + 24, j + 0, k + 3, Blocks.cobblestone);
        world.setBlock(i + 24, j + 0, k + 4, Blocks.dirt);
        world.setBlock(i + 24, j + 0, k + 5, Blocks.cobblestone);
        world.setBlock(i + 24, j + 0, k + 6, Blocks.dirt);
        world.setBlock(i + 24, j + 0, k + 7, Blocks.cobblestone);
        world.setBlock(i + 24, j + 0, k + 8, Blocks.mossy_cobblestone);
        world.setBlock(i + 24, j + 0, k + 9, Blocks.dirt);
        world.setBlock(i + 24, j + 0, k + 10, (Block)Blocks.grass);
        world.setBlock(i + 24, j + 0, k + 11, Blocks.mossy_cobblestone);
        world.setBlock(i + 24, j + 0, k + 12, Blocks.cobblestone);
        world.setBlock(i + 24, j + 0, k + 13, Blocks.mossy_cobblestone);
        world.setBlock(i + 24, j + 0, k + 14, Blocks.dirt);
        world.setBlock(i + 24, j + 0, k + 15, Blocks.cobblestone);
        world.setBlock(i + 24, j + 0, k + 16, Blocks.dirt);
        world.setBlock(i + 24, j + 0, k + 17, Blocks.cobblestone);
        world.setBlock(i + 24, j + 0, k + 18, Blocks.cobblestone);
        world.setBlock(i + 24, j + 0, k + 19, Blocks.cobblestone);
        world.setBlock(i + 24, j + 0, k + 20, Blocks.dirt);
        world.setBlock(i + 24, j + 0, k + 21, Blocks.dirt);
        world.setBlock(i + 24, j + 0, k + 22, Blocks.dirt);
        world.setBlock(i + 24, j + 0, k + 23, (Block)Blocks.grass);
        world.setBlock(i + 24, j + 0, k + 24, (Block)Blocks.grass);
        world.setBlock(i + 24, j + 0, k + 25, (Block)Blocks.grass);
        world.setBlock(i + 24, j + 1, k + 1, Blocks.stonebrick, 2, 0);
        world.setBlock(i + 24, j + 1, k + 4, Blocks.stonebrick, 2, 0);
        world.setBlock(i + 24, j + 1, k + 5, Blocks.stonebrick, 1, 0);
        world.setBlock(i + 24, j + 1, k + 6, Blocks.stonebrick, 2, 0);
        world.setBlock(i + 24, j + 1, k + 7, Blocks.stonebrick, 2, 0);
        world.setBlock(i + 24, j + 1, k + 9, Blocks.stonebrick, 2, 0);
        world.setBlock(i + 24, j + 1, k + 14, Blocks.stonebrick, 2, 0);
        world.setBlock(i + 24, j + 1, k + 16, Blocks.stonebrick, 2, 0);
        world.setBlock(i + 24, j + 1, k + 20, Blocks.stonebrick, 2, 0);
        world.setBlock(i + 24, j + 1, k + 21, Blocks.stonebrick, 2, 0);
        world.setBlock(i + 24, j + 1, k + 22, Blocks.stonebrick, 2, 0);
        world.setBlock(i + 24, j + 1, k + 23, (Block)Blocks.stone_slab, 3, 0);
        world.setBlock(i + 24, j + 2, k + 4, Blocks.stonebrick, 2, 0);
        world.setBlock(i + 24, j + 2, k + 5, Blocks.stonebrick, 1, 0);
        world.setBlock(i + 24, j + 2, k + 6, Blocks.stonebrick, 2, 0);
        world.setBlock(i + 24, j + 2, k + 9, Blocks.stonebrick, 2, 0);
        world.setBlock(i + 24, j + 2, k + 21, Blocks.stonebrick, 1, 0);
        world.setBlock(i + 24, j + 2, k + 22, Blocks.stonebrick, 1, 0);
        world.setBlock(i + 24, j + 3, k + 4, Blocks.stonebrick, 1, 0);
        world.setBlock(i + 24, j + 3, k + 5, Blocks.stonebrick, 1, 0);
        world.setBlock(i + 24, j + 3, k + 21, Blocks.stonebrick, 1, 0);
        world.setBlock(i + 24, j + 3, k + 22, Blocks.stonebrick, 2, 0);
        world.setBlock(i + 24, j + 4, k + 4, Blocks.stonebrick, 2, 0);
        world.setBlock(i + 24, j + 4, k + 5, Blocks.stonebrick, 2, 0);
        world.setBlock(i + 24, j + 4, k + 21, Blocks.stonebrick, 1, 0);
        world.setBlock(i + 24, j + 4, k + 22, Blocks.stonebrick, 1, 0);
        world.setBlock(i + 24, j + 5, k + 4, Blocks.stonebrick, 1, 0);
        world.setBlock(i + 24, j + 5, k + 5, Blocks.stonebrick, 2, 0);
        world.setBlock(i + 24, j + 5, k + 21, Blocks.stonebrick, 2, 0);
        world.setBlock(i + 24, j + 5, k + 22, Blocks.stonebrick, 2, 0);
        world.setBlock(i + 24, j + 6, k + 4, Blocks.stonebrick, 2, 0);
        world.setBlock(i + 24, j + 6, k + 5, Blocks.stonebrick, 2, 0);
        world.setBlock(i + 24, j + 6, k + 21, Blocks.stonebrick, 1, 0);
        world.setBlock(i + 24, j + 6, k + 22, Blocks.stonebrick, 2, 0);
        world.setBlock(i + 24, j + 7, k + 4, Blocks.stonebrick, 2, 0);
        world.setBlock(i + 24, j + 7, k + 21, Blocks.stonebrick, 2, 0);
        world.setBlock(i + 24, j + 7, k + 22, Blocks.stonebrick, 2, 0);
        world.setBlock(i + 24, j + 8, k + 4, Blocks.stonebrick, 2, 0);
        world.setBlock(i + 24, j + 8, k + 5, Blocks.stonebrick, 2, 0);
        world.setBlock(i + 24, j + 8, k + 20, Blocks.stonebrick, 2, 0);
        world.setBlock(i + 24, j + 8, k + 21, Blocks.stonebrick, 2, 0);
        world.setBlock(i + 24, j + 8, k + 22, Blocks.stonebrick, 2, 0);
        world.setBlock(i + 24, j + 9, k + 4, Blocks.stonebrick, 2, 0);
        world.setBlock(i + 24, j + 9, k + 19, Blocks.stonebrick, 2, 0);
        world.setBlock(i + 24, j + 9, k + 20, Blocks.stonebrick, 2, 0);
        world.setBlock(i + 24, j + 9, k + 21, Blocks.stonebrick, 1, 0);
        world.setBlock(i + 24, j + 9, k + 22, Blocks.stonebrick, 2, 0);
        world.setBlock(i + 24, j + 10, k + 18, Blocks.stonebrick, 2, 0);
        world.setBlock(i + 24, j + 10, k + 19, Blocks.stonebrick, 2, 0);
        world.setBlock(i + 24, j + 10, k + 20, Blocks.stonebrick, 2, 0);
        world.setBlock(i + 24, j + 10, k + 21, Blocks.stonebrick, 2, 0);
        world.setBlock(i + 24, j + 10, k + 22, Blocks.stonebrick, 1, 0);
        world.setBlock(i + 24, j + 11, k + 20, (Block)Blocks.stone_slab, 3, 0);
        world.setBlock(i + 24, j + 11, k + 21, Blocks.stonebrick, 2, 0);
        world.setBlock(i + 24, j + 11, k + 22, Blocks.stonebrick, 2, 0);
        world.setBlock(i + 24, j + 12, k + 21, Blocks.stonebrick, 2, 0);
        world.setBlock(i + 24, j + 12, k + 22, Blocks.stonebrick, 2, 0);
        world.setBlock(i + 24, j + 13, k + 21, Blocks.stonebrick, 2, 0);
        world.setBlock(i + 24, j + 13, k + 22, Blocks.stonebrick, 1, 0);
        world.setBlock(i + 24, j + 14, k + 21, Blocks.stonebrick, 2, 0);
        world.setBlock(i + 24, j + 14, k + 22, Blocks.stonebrick, 2, 0);
        world.setBlock(i + 24, j + 15, k + 22, Blocks.stonebrick, 1, 0);
        world.setBlock(i + 24, j + 16, k + 22, Blocks.stonebrick, 2, 0);
        world.setBlock(i + 25, j + 0, k + 0, (Block)Blocks.grass);
        world.setBlock(i + 25, j + 0, k + 1, (Block)Blocks.grass);
        world.setBlock(i + 25, j + 0, k + 2, Blocks.dirt);
        world.setBlock(i + 25, j + 0, k + 3, (Block)Blocks.grass);
        world.setBlock(i + 25, j + 0, k + 4, (Block)Blocks.grass);
        world.setBlock(i + 25, j + 0, k + 5, (Block)Blocks.grass);
        world.setBlock(i + 25, j + 0, k + 6, Blocks.stonebrick, 2, 0);
        world.setBlock(i + 25, j + 0, k + 7, (Block)Blocks.grass);
        world.setBlock(i + 25, j + 0, k + 8, Blocks.stonebrick, 2, 0);
        world.setBlock(i + 25, j + 0, k + 9, (Block)Blocks.grass);
        world.setBlock(i + 25, j + 0, k + 10, (Block)Blocks.grass);
        world.setBlock(i + 25, j + 0, k + 11, Blocks.stonebrick, 2, 0);
        world.setBlock(i + 25, j + 0, k + 12, (Block)Blocks.grass);
        world.setBlock(i + 25, j + 0, k + 13, (Block)Blocks.grass);
        world.setBlock(i + 25, j + 0, k + 14, (Block)Blocks.grass);
        world.setBlock(i + 25, j + 0, k + 15, Blocks.dirt);
        world.setBlock(i + 25, j + 0, k + 16, (Block)Blocks.grass);
        world.setBlock(i + 25, j + 0, k + 17, (Block)Blocks.grass);
        world.setBlock(i + 25, j + 0, k + 18, (Block)Blocks.grass);
        world.setBlock(i + 25, j + 0, k + 19, (Block)Blocks.grass);
        world.setBlock(i + 25, j + 0, k + 20, (Block)Blocks.grass);
        world.setBlock(i + 25, j + 0, k + 21, (Block)Blocks.grass);
        world.setBlock(i + 25, j + 0, k + 22, (Block)Blocks.grass);
        world.setBlock(i + 25, j + 0, k + 23, (Block)Blocks.grass);
        world.setBlock(i + 25, j + 0, k + 24, (Block)Blocks.grass);
        world.setBlock(i + 25, j + 0, k + 25, (Block)Blocks.grass);
        world.setBlock(i + 25, j + 1, k + 2, Blocks.stonebrick, 2, 0);
        world.setBlock(i + 25, j + 1, k + 15, Blocks.stonebrick, 2, 0);
        world.setBlock(i + 25, j + 1, k + 21, (Block)Blocks.stone_slab, 3, 0);
        world.setBlock(i + 26, j + 0, k + 0, (Block)Blocks.grass);
        world.setBlock(i + 26, j + 0, k + 1, (Block)Blocks.grass);
        world.setBlock(i + 26, j + 0, k + 2, (Block)Blocks.grass);
        world.setBlock(i + 26, j + 0, k + 3, (Block)Blocks.grass);
        world.setBlock(i + 26, j + 0, k + 4, (Block)Blocks.grass);
        world.setBlock(i + 26, j + 0, k + 5, Blocks.dirt);
        world.setBlock(i + 26, j + 0, k + 6, Blocks.stonebrick, 2, 0);
        world.setBlock(i + 26, j + 0, k + 7, Blocks.dirt);
        world.setBlock(i + 26, j + 0, k + 8, Blocks.dirt);
        world.setBlock(i + 26, j + 0, k + 9, (Block)Blocks.grass);
        world.setBlock(i + 26, j + 0, k + 10, Blocks.dirt);
        world.setBlock(i + 26, j + 0, k + 11, (Block)Blocks.grass);
        world.setBlock(i + 26, j + 0, k + 12, Blocks.dirt);
        world.setBlock(i + 26, j + 0, k + 13, Blocks.cobblestone);
        world.setBlock(i + 26, j + 0, k + 14, Blocks.dirt);
        world.setBlock(i + 26, j + 0, k + 15, (Block)Blocks.grass);
        world.setBlock(i + 26, j + 0, k + 16, Blocks.dirt);
        world.setBlock(i + 26, j + 0, k + 17, Blocks.dirt);
        world.setBlock(i + 26, j + 0, k + 18, (Block)Blocks.grass);
        world.setBlock(i + 26, j + 0, k + 19, Blocks.dirt);
        world.setBlock(i + 26, j + 0, k + 20, (Block)Blocks.grass);
        world.setBlock(i + 26, j + 0, k + 21, Blocks.dirt);
        world.setBlock(i + 26, j + 0, k + 22, (Block)Blocks.grass);
        world.setBlock(i + 26, j + 0, k + 23, (Block)Blocks.grass);
        world.setBlock(i + 26, j + 0, k + 24, (Block)Blocks.grass);
        world.setBlock(i + 26, j + 0, k + 25, (Block)Blocks.grass);
        world.setBlock(i + 26, j + 1, k + 2, (Block)Blocks.stone_slab, 3, 0);
        world.setBlock(i + 26, j + 1, k + 4, (Block)Blocks.stone_slab, 3, 0);
        world.setBlock(i + 26, j + 1, k + 5, Blocks.stonebrick, 2, 0);
        world.setBlock(i + 26, j + 1, k + 7, Blocks.stonebrick, 2, 0);
        world.setBlock(i + 26, j + 1, k + 8, Blocks.stonebrick, 2, 0);
        world.setBlock(i + 26, j + 1, k + 10, Blocks.stonebrick, 2, 0);
        world.setBlock(i + 26, j + 1, k + 12, Blocks.stonebrick, 2, 0);
        world.setBlock(i + 26, j + 1, k + 14, Blocks.stonebrick, 2, 0);
        world.setBlock(i + 26, j + 1, k + 16, Blocks.stonebrick, 2, 0);
        world.setBlock(i + 26, j + 1, k + 17, Blocks.stonebrick, 2, 0);
        world.setBlock(i + 26, j + 1, k + 18, (Block)Blocks.stone_slab, 3, 0);
        world.setBlock(i + 26, j + 1, k + 19, Blocks.stonebrick, 2, 0);
        world.setBlock(i + 26, j + 1, k + 20, (Block)Blocks.stone_slab, 3, 0);
        world.setBlock(i + 26, j + 1, k + 21, Blocks.stonebrick, 2, 0);
        world.setBlock(i + 26, j + 2, k + 8, Blocks.stonebrick, 2, 0);
        world.setBlock(i + 26, j + 2, k + 16, Blocks.stonebrick, 2, 0);
        world.setBlock(i + 27, j + 0, k + 0, (Block)Blocks.grass);
        world.setBlock(i + 27, j + 0, k + 1, (Block)Blocks.grass);
        world.setBlock(i + 27, j + 0, k + 2, (Block)Blocks.grass);
        world.setBlock(i + 27, j + 0, k + 3, (Block)Blocks.grass);
        world.setBlock(i + 27, j + 0, k + 4, (Block)Blocks.grass);
        world.setBlock(i + 27, j + 0, k + 5, (Block)Blocks.grass);
        world.setBlock(i + 27, j + 0, k + 6, Blocks.dirt);
        world.setBlock(i + 27, j + 0, k + 7, (Block)Blocks.grass);
        world.setBlock(i + 27, j + 0, k + 8, (Block)Blocks.grass);
        world.setBlock(i + 27, j + 0, k + 9, (Block)Blocks.grass);
        world.setBlock(i + 27, j + 0, k + 10, Blocks.stonebrick, 2, 0);
        world.setBlock(i + 27, j + 0, k + 11, (Block)Blocks.grass);
        world.setBlock(i + 27, j + 0, k + 12, (Block)Blocks.grass);
        world.setBlock(i + 27, j + 0, k + 13, (Block)Blocks.grass);
        world.setBlock(i + 27, j + 0, k + 14, (Block)Blocks.grass);
        world.setBlock(i + 27, j + 0, k + 15, (Block)Blocks.grass);
        world.setBlock(i + 27, j + 0, k + 16, (Block)Blocks.grass);
        world.setBlock(i + 27, j + 0, k + 17, (Block)Blocks.grass);
        world.setBlock(i + 27, j + 0, k + 18, (Block)Blocks.grass);
        world.setBlock(i + 27, j + 0, k + 19, (Block)Blocks.grass);
        world.setBlock(i + 27, j + 0, k + 20, (Block)Blocks.grass);
        world.setBlock(i + 27, j + 0, k + 21, (Block)Blocks.grass);
        world.setBlock(i + 27, j + 0, k + 22, (Block)Blocks.grass);
        world.setBlock(i + 27, j + 0, k + 23, (Block)Blocks.grass);
        world.setBlock(i + 27, j + 0, k + 24, (Block)Blocks.grass);
        world.setBlock(i + 27, j + 0, k + 25, (Block)Blocks.grass);
        world.setBlock(i + 27, j + 1, k + 6, Blocks.stonebrick, 2, 0);
        world.setBlock(i + 4, j + 9, k + 20, Blocks.vine, 8, 0);
        world.setBlock(i + 5, j + 4, k + 6, Blocks.vine, 4, 0);
        world.setBlock(i + 5, j + 5, k + 6, Blocks.vine, 4, 0);
        world.setBlock(i + 5, j + 6, k + 6, Blocks.vine, 4, 0);
        world.setBlock(i + 5, j + 7, k + 3, Blocks.vine, 1, 0);
        world.setBlock(i + 6, j + 7, k + 23, Blocks.vine, 4, 0);
        world.setBlock(i + 6, j + 8, k + 23, Blocks.vine, 4, 0);
        world.setBlock(i + 6, j + 9, k + 23, Blocks.vine, 4, 0);
        world.setBlock(i + 7, j + 8, k + 20, Blocks.vine, 2, 0);
        world.setBlock(i + 7, j + 9, k + 20, Blocks.vine, 2, 0);
        world.setBlock(i + 8, j + 9, k + 23, Blocks.vine, 4, 0);
        world.setBlock(i + 8, j + 10, k + 23, Blocks.vine, 4, 0);
        world.setBlock(i + 10, j + 10, k + 20, Blocks.vine, 1, 0);
        world.setBlock(i + 19, j + 11, k + 23, Blocks.vine, 4, 0);
        world.setBlock(i + 20, j + 11, k + 23, Blocks.vine, 4, 0);
        world.setBlock(i + 21, j + 9, k + 20, Blocks.vine, 1, 0);
        world.setBlock(i + 21, j + 10, k + 20, Blocks.vine, 1, 0);
        world.setBlock(i + 21, j + 11, k + 20, Blocks.vine, 1, 0);
        world.setBlock(i + 22, j + 8, k + 23, Blocks.vine, 4, 0);
        world.setBlock(i + 22, j + 9, k + 23, Blocks.vine, 4, 0);
        world.setBlock(i + 22, j + 10, k + 23, Blocks.vine, 4, 0);
        world.setBlock(i + 23, j + 6, k + 3, Blocks.vine, 1, 0);
        world.setBlock(i + 24, j + 6, k + 3, Blocks.vine, 1, 0);
        world.setBlock(i + 25, j + 4, k + 4, Blocks.vine, 2, 0);
        world.setBlock(i + 25, j + 7, k + 4, Blocks.vine, 2, 0);
        world.setBlock(i + 25, j + 10, k + 19, Blocks.vine, 2, 0);
        return true;
    }
}
