package com.gibby.dungeon.gen;

import com.gibby.dungeon.Dungeons;
import cpw.mods.fml.common.IWorldGenerator;
import net.minecraft.block.Block;
import net.minecraft.world.IBlockAccess;
import net.minecraft.world.World;
import net.minecraft.world.chunk.IChunkProvider;
import net.minecraft.world.gen.feature.WorldGenerator;

import java.util.Random;

public class FireflyTreeLarge extends WorldGenerator implements IWorldGenerator
{
    public void generate(final Random random, final int chunkX, final int chunkZ, final World world, final IChunkProvider chunkGenerator, final IChunkProvider chunkProvider) {
    }

    public void setBlock(final World world, final int x, final int y, final int z, final Block block, final int metadata) {
        final Block b1 = world.getBlock(x, y, z);
        if (b1.isAir(world, x, y, z) || b1.isLeaves(world, x, y, z)) {
            world.setBlock(x, y, z, block, metadata, 2);
        }
    }

    public boolean generate(final World world, final Random rand, final int i, final int j, final int k) {
        if (world.getBlock(i + 19, j - 1, k + 15) != Dungeons.midnightGrass || world.getBlock(i + 20, j - 1, k + 16) != Dungeons.midnightGrass) {
            return false;
        }
        for (int c = 4; c < 30; ++c) {
            if (!world.isAirBlock(i + 19, j + c, k + 15)) {
                return false;
            }
        }
        this.setBlock(world, i + 0, j + 16, k + 16, Dungeons.fireflyLeaves, 0);
        this.setBlock(world, i + 0, j + 16, k + 22, Dungeons.fireflyLeaves, 0);
        this.setBlock(world, i + 0, j + 16, k + 23, Dungeons.fireflyLeaves, 0);
        this.setBlock(world, i + 1, j + 10, k + 24, Dungeons.fireflyLeaves, 0);
        this.setBlock(world, i + 1, j + 16, k + 15, Dungeons.fireflyLeaves, 0);
        this.setBlock(world, i + 1, j + 16, k + 16, Dungeons.fireflyLeaves, 0);
        this.setBlock(world, i + 1, j + 16, k + 17, Dungeons.fireflyLeaves, 0);
        this.setBlock(world, i + 1, j + 16, k + 18, Dungeons.fireflyLeaves, 0);
        this.setBlock(world, i + 1, j + 16, k + 21, Dungeons.fireflyLeaves, 0);
        this.setBlock(world, i + 1, j + 16, k + 22, Dungeons.fireflyLeaves, 0);
        this.setBlock(world, i + 1, j + 16, k + 23, Dungeons.fireflyLeaves, 0);
        this.setBlock(world, i + 1, j + 16, k + 24, Dungeons.fireflyLeaves, 0);
        this.setBlock(world, i + 2, j + 10, k + 24, Dungeons.fireflyLeaves, 0);
        this.setBlock(world, i + 2, j + 10, k + 25, Dungeons.fireflyLeaves, 0);
        this.setBlock(world, i + 2, j + 16, k + 14, Dungeons.fireflyLeaves, 0);
        this.setBlock(world, i + 2, j + 16, k + 15, Dungeons.fireflyLeaves, 0);
        this.setBlock(world, i + 2, j + 16, k + 16, Dungeons.fireflyLeaves, 0);
        this.setBlock(world, i + 2, j + 16, k + 17, Dungeons.fireflyLeaves, 0);
        this.setBlock(world, i + 2, j + 16, k + 18, Dungeons.fireflyLeaves, 0);
        this.setBlock(world, i + 2, j + 16, k + 19, Dungeons.fireflyLeaves, 0);
        this.setBlock(world, i + 2, j + 16, k + 20, Dungeons.fireflyLeaves, 0);
        this.setBlock(world, i + 2, j + 16, k + 21, Dungeons.fireflyLeaves, 0);
        this.setBlock(world, i + 2, j + 16, k + 22, Dungeons.fireflyLeaves, 0);
        this.setBlock(world, i + 2, j + 16, k + 23, Dungeons.fireflyLeaves, 0);
        this.setBlock(world, i + 2, j + 16, k + 24, Dungeons.fireflyLeaves, 0);
        this.setBlock(world, i + 2, j + 16, k + 25, Dungeons.fireflyLeaves, 0);
        this.setBlock(world, i + 2, j + 17, k + 17, Dungeons.fireflyLeaves, 0);
        this.setBlock(world, i + 2, j + 17, k + 22, Dungeons.fireflyLeaves, 0);
        this.setBlock(world, i + 2, j + 17, k + 23, Dungeons.fireflyLeaves, 0);
        this.setBlock(world, i + 2, j + 18, k + 11, Dungeons.fireflyLeaves, 0);
        this.setBlock(world, i + 3, j + 10, k + 23, Dungeons.fireflyLeaves, 0);
        this.setBlock(world, i + 3, j + 10, k + 24, Dungeons.fireflyLeaves, 0);
        this.setBlock(world, i + 3, j + 10, k + 25, Dungeons.fireflyLeaves, 0);
        this.setBlock(world, i + 3, j + 15, k + 16, Dungeons.fireflyLeaves, 0);
        this.setBlock(world, i + 3, j + 16, k + 13, Dungeons.fireflyLeaves, 0);
        this.setBlock(world, i + 3, j + 16, k + 14, Dungeons.fireflyLeaves, 0);
        this.setBlock(world, i + 3, j + 16, k + 15, Dungeons.fireflyLeaves, 0);
        this.setBlock(world, i + 3, j + 16, k + 16, Dungeons.fireflyLeaves, 0);
        this.setBlock(world, i + 3, j + 16, k + 17, Dungeons.fireflyLeaves, 0);
        this.setBlock(world, i + 3, j + 16, k + 18, Dungeons.fireflyLeaves, 0);
        this.setBlock(world, i + 3, j + 16, k + 19, Dungeons.fireflyLeaves, 0);
        this.setBlock(world, i + 3, j + 16, k + 20, Dungeons.fireflyLeaves, 0);
        this.setBlock(world, i + 3, j + 16, k + 21, Dungeons.fireflyLeaves, 0);
        this.setBlock(world, i + 3, j + 16, k + 22, Dungeons.fireflyLeaves, 0);
        this.setBlock(world, i + 3, j + 16, k + 23, Dungeons.fireflyLeaves, 0);
        this.setBlock(world, i + 3, j + 16, k + 24, Dungeons.fireflyLeaves, 0);
        this.setBlock(world, i + 3, j + 16, k + 25, Dungeons.fireflyLeaves, 0);
        this.setBlock(world, i + 3, j + 17, k + 16, Dungeons.fireflyLeaves, 0);
        this.setBlock(world, i + 3, j + 17, k + 17, Dungeons.fireflyLeaves, 0);
        this.setBlock(world, i + 3, j + 17, k + 18, Dungeons.fireflyLeaves, 0);
        this.setBlock(world, i + 3, j + 17, k + 21, Dungeons.fireflyLeaves, 0);
        this.setBlock(world, i + 3, j + 17, k + 22, Dungeons.fireflyLeaves, 0);
        this.setBlock(world, i + 3, j + 17, k + 23, Dungeons.fireflyLeaves, 0);
        this.setBlock(world, i + 3, j + 17, k + 24, Dungeons.fireflyLeaves, 0);
        this.setBlock(world, i + 3, j + 18, k + 10, Dungeons.fireflyLeaves, 0);
        this.setBlock(world, i + 3, j + 18, k + 11, Dungeons.fireflyLeaves, 0);
        this.setBlock(world, i + 4, j + 10, k + 22, Dungeons.fireflyLeaves, 0);
        this.setBlock(world, i + 4, j + 10, k + 23, Dungeons.fireflyLeaves, 0);
        this.setBlock(world, i + 4, j + 10, k + 24, Dungeons.fireflyLeaves, 0);
        this.setBlock(world, i + 4, j + 10, k + 25, Dungeons.fireflyLeaves, 0);
        this.setBlock(world, i + 4, j + 10, k + 26, Dungeons.fireflyLeaves, 0);
        this.setBlock(world, i + 4, j + 15, k + 16, Dungeons.fireflyLeaves, 0);
        this.setBlock(world, i + 4, j + 15, k + 17, Dungeons.fireflyLeaves, 0);
        this.setBlock(world, i + 4, j + 15, k + 22, Dungeons.fireflyLeaves, 0);
        this.setBlock(world, i + 4, j + 15, k + 23, Dungeons.fireflyLeaves, 0);
        this.setBlock(world, i + 4, j + 16, k + 13, Dungeons.fireflyLeaves, 0);
        this.setBlock(world, i + 4, j + 16, k + 14, Dungeons.fireflyLeaves, 0);
        this.setBlock(world, i + 4, j + 16, k + 15, Dungeons.fireflyLeaves, 0);
        this.setBlock(world, i + 4, j + 16, k + 16, Dungeons.fireflyLeaves, 0);
        this.setBlock(world, i + 4, j + 16, k + 17, Dungeons.fireflyLeaves, 0);
        this.setBlock(world, i + 4, j + 16, k + 18, Dungeons.fireflyLeaves, 0);
        this.setBlock(world, i + 4, j + 16, k + 19, Dungeons.fireflyLeaves, 0);
        this.setBlock(world, i + 4, j + 16, k + 20, Dungeons.fireflyLeaves, 0);
        this.setBlock(world, i + 4, j + 16, k + 21, Dungeons.fireflyLeaves, 0);
        this.setBlock(world, i + 4, j + 16, k + 22, Dungeons.fireflyLeaves, 0);
        this.setBlock(world, i + 4, j + 16, k + 23, Dungeons.fireflyLeaves, 0);
        this.setBlock(world, i + 4, j + 16, k + 24, Dungeons.fireflyLeaves, 0);
        this.setBlock(world, i + 4, j + 16, k + 25, Dungeons.fireflyLeaves, 0);
        this.setBlock(world, i + 4, j + 16, k + 26, Dungeons.fireflyLeaves, 0);
        this.setBlock(world, i + 4, j + 17, k + 16, Dungeons.fireflyLeaves, 0);
        this.setBlock(world, i + 4, j + 17, k + 17, Dungeons.fireflyLeaves, 0);
        this.setBlock(world, i + 4, j + 17, k + 18, Dungeons.fireflyLeaves, 0);
        this.setBlock(world, i + 4, j + 17, k + 19, Dungeons.fireflyLeaves, 0);
        this.setBlock(world, i + 4, j + 17, k + 21, Dungeons.fireflyLeaves, 0);
        this.setBlock(world, i + 4, j + 17, k + 22, Dungeons.fireflyLeaves, 0);
        this.setBlock(world, i + 4, j + 17, k + 23, Dungeons.fireflyLeaves, 0);
        this.setBlock(world, i + 4, j + 17, k + 24, Dungeons.fireflyLeaves, 0);
        this.setBlock(world, i + 4, j + 18, k + 8, Dungeons.fireflyLeaves, 0);
        this.setBlock(world, i + 4, j + 18, k + 9, Dungeons.fireflyLeaves, 0);
        this.setBlock(world, i + 4, j + 18, k + 10, Dungeons.fireflyLeaves, 0);
        this.setBlock(world, i + 4, j + 18, k + 11, Dungeons.fireflyLeaves, 0);
        this.setBlock(world, i + 4, j + 18, k + 12, Dungeons.fireflyLeaves, 0);
        this.setBlock(world, i + 4, j + 18, k + 17, Dungeons.fireflyLeaves, 0);
        this.setBlock(world, i + 4, j + 18, k + 18, Dungeons.fireflyLeaves, 0);
        this.setBlock(world, i + 4, j + 18, k + 22, Dungeons.fireflyLeaves, 0);
        this.setBlock(world, i + 5, j + 9, k + 24, Dungeons.fireflyLeaves, 0);
        this.setBlock(world, i + 5, j + 9, k + 25, Dungeons.fireflyLeaves, 0);
        this.setBlock(world, i + 5, j + 10, k + 22, Dungeons.fireflyLeaves, 0);
        this.setBlock(world, i + 5, j + 10, k + 23, Dungeons.fireflyLeaves, 0);
        this.setBlock(world, i + 5, j + 10, k + 24, Dungeons.fireflyLeaves, 0);
        this.setBlock(world, i + 5, j + 10, k + 25, Dungeons.fireflyLeaves, 0);
        this.setBlock(world, i + 5, j + 10, k + 26, Dungeons.fireflyLeaves, 0);
        this.setBlock(world, i + 5, j + 11, k + 23, Dungeons.fireflyLeaves, 0);
        this.setBlock(world, i + 5, j + 11, k + 24, Dungeons.fireflyLeaves, 0);
        this.setBlock(world, i + 5, j + 11, k + 25, Dungeons.fireflyLeaves, 0);
        this.setBlock(world, i + 5, j + 15, k + 15, Dungeons.fireflyLeaves, 0);
        this.setBlock(world, i + 5, j + 15, k + 16, Dungeons.fireflyLeaves, 0);
        this.setBlock(world, i + 5, j + 15, k + 17, Dungeons.fireflyLog, 0);
        this.setBlock(world, i + 5, j + 15, k + 18, Dungeons.fireflyLeaves, 0);
        this.setBlock(world, i + 5, j + 15, k + 21, Dungeons.fireflyLeaves, 0);
        this.setBlock(world, i + 5, j + 15, k + 22, Dungeons.fireflyLog, 0);
        this.setBlock(world, i + 5, j + 15, k + 23, Dungeons.fireflyLeaves, 0);
        this.setBlock(world, i + 5, j + 16, k + 13, Dungeons.fireflyLeaves, 0);
        this.setBlock(world, i + 5, j + 16, k + 14, Dungeons.fireflyLeaves, 0);
        this.setBlock(world, i + 5, j + 16, k + 15, Dungeons.fireflyLeaves, 0);
        this.setBlock(world, i + 5, j + 16, k + 16, Dungeons.fireflyLeaves, 0);
        this.setBlock(world, i + 5, j + 16, k + 17, Dungeons.fireflyLeaves, 0);
        this.setBlock(world, i + 5, j + 16, k + 18, Dungeons.fireflyLeaves, 0);
        this.setBlock(world, i + 5, j + 16, k + 19, Dungeons.fireflyLeaves, 0);
        this.setBlock(world, i + 5, j + 16, k + 20, Dungeons.fireflyLeaves, 0);
        this.setBlock(world, i + 5, j + 16, k + 21, Dungeons.fireflyLeaves, 0);
        this.setBlock(world, i + 5, j + 16, k + 22, Dungeons.fireflyLeaves, 0);
        this.setBlock(world, i + 5, j + 16, k + 23, Dungeons.fireflyLeaves, 0);
        this.setBlock(world, i + 5, j + 16, k + 24, Dungeons.fireflyLeaves, 0);
        this.setBlock(world, i + 5, j + 16, k + 25, Dungeons.fireflyLeaves, 0);
        this.setBlock(world, i + 5, j + 16, k + 26, Dungeons.fireflyLeaves, 0);
        this.setBlock(world, i + 5, j + 17, k + 16, Dungeons.fireflyLeaves, 0);
        this.setBlock(world, i + 5, j + 17, k + 17, Dungeons.fireflyLeaves, 0);
        this.setBlock(world, i + 5, j + 17, k + 18, Dungeons.fireflyLeaves, 0);
        this.setBlock(world, i + 5, j + 17, k + 19, Dungeons.fireflyLeaves, 0);
        this.setBlock(world, i + 5, j + 17, k + 21, Dungeons.fireflyLeaves, 0);
        this.setBlock(world, i + 5, j + 17, k + 22, Dungeons.fireflyLeaves, 0);
        this.setBlock(world, i + 5, j + 17, k + 23, Dungeons.fireflyLeaves, 0);
        this.setBlock(world, i + 5, j + 18, k + 8, Dungeons.fireflyLeaves, 0);
        this.setBlock(world, i + 5, j + 18, k + 9, Dungeons.fireflyLeaves, 0);
        this.setBlock(world, i + 5, j + 18, k + 10, Dungeons.fireflyLeaves, 0);
        this.setBlock(world, i + 5, j + 18, k + 11, Dungeons.fireflyLeaves, 0);
        this.setBlock(world, i + 5, j + 18, k + 12, Dungeons.fireflyLeaves, 0);
        this.setBlock(world, i + 5, j + 18, k + 13, Dungeons.fireflyLeaves, 0);
        this.setBlock(world, i + 5, j + 19, k + 10, Dungeons.fireflyLeaves, 0);
        this.setBlock(world, i + 5, j + 19, k + 11, Dungeons.fireflyLeaves, 0);
        this.setBlock(world, i + 6, j + 9, k + 23, Dungeons.fireflyLeaves, 0);
        this.setBlock(world, i + 6, j + 9, k + 24, Dungeons.fireflyLeaves, 0);
        this.setBlock(world, i + 6, j + 9, k + 25, Dungeons.fireflyLeaves, 0);
        this.setBlock(world, i + 6, j + 10, k + 21, Dungeons.fireflyLeaves, 0);
        this.setBlock(world, i + 6, j + 10, k + 22, Dungeons.fireflyLeaves, 0);
        this.setBlock(world, i + 6, j + 10, k + 23, Dungeons.fireflyLeaves, 0);
        this.setBlock(world, i + 6, j + 10, k + 24, Dungeons.fireflyLeaves, 0);
        this.setBlock(world, i + 6, j + 10, k + 25, Dungeons.fireflyLeaves, 0);
        this.setBlock(world, i + 6, j + 10, k + 26, Dungeons.fireflyLeaves, 0);
        this.setBlock(world, i + 6, j + 10, k + 27, Dungeons.fireflyLeaves, 0);
        this.setBlock(world, i + 6, j + 11, k + 23, Dungeons.fireflyLeaves, 0);
        this.setBlock(world, i + 6, j + 11, k + 24, Dungeons.fireflyLeaves, 0);
        this.setBlock(world, i + 6, j + 11, k + 25, Dungeons.fireflyLeaves, 0);
        this.setBlock(world, i + 6, j + 12, k + 24, Dungeons.fireflyLeaves, 0);
        this.setBlock(world, i + 6, j + 14, k + 17, Dungeons.fireflyLog, 0);
        this.setBlock(world, i + 6, j + 14, k + 18, Dungeons.fireflyLog, 0);
        this.setBlock(world, i + 6, j + 14, k + 19, Dungeons.fireflyLog, 0);
        this.setBlock(world, i + 6, j + 14, k + 21, Dungeons.fireflyLog, 0);
        this.setBlock(world, i + 6, j + 14, k + 22, Dungeons.fireflyLog, 0);
        this.setBlock(world, i + 6, j + 15, k + 16, Dungeons.fireflyLeaves, 0);
        this.setBlock(world, i + 6, j + 15, k + 17, Dungeons.fireflyLeaves, 0);
        this.setBlock(world, i + 6, j + 15, k + 18, Dungeons.fireflyLeaves, 0);
        this.setBlock(world, i + 6, j + 15, k + 21, Dungeons.fireflyLeaves, 0);
        this.setBlock(world, i + 6, j + 15, k + 22, Dungeons.fireflyLeaves, 0);
        this.setBlock(world, i + 6, j + 15, k + 23, Dungeons.fireflyLeaves, 0);
        this.setBlock(world, i + 6, j + 16, k + 14, Dungeons.fireflyLeaves, 0);
        this.setBlock(world, i + 6, j + 16, k + 15, Dungeons.fireflyLeaves, 0);
        this.setBlock(world, i + 6, j + 16, k + 16, Dungeons.fireflyLeaves, 0);
        this.setBlock(world, i + 6, j + 16, k + 17, Dungeons.fireflyLeaves, 0);
        this.setBlock(world, i + 6, j + 16, k + 18, Dungeons.fireflyLeaves, 0);
        this.setBlock(world, i + 6, j + 16, k + 19, Dungeons.fireflyLeaves, 0);
        this.setBlock(world, i + 6, j + 16, k + 20, Dungeons.fireflyLeaves, 0);
        this.setBlock(world, i + 6, j + 16, k + 21, Dungeons.fireflyLeaves, 0);
        this.setBlock(world, i + 6, j + 16, k + 22, Dungeons.fireflyLeaves, 0);
        this.setBlock(world, i + 6, j + 16, k + 23, Dungeons.fireflyLeaves, 0);
        this.setBlock(world, i + 6, j + 16, k + 24, Dungeons.fireflyLeaves, 0);
        this.setBlock(world, i + 6, j + 16, k + 25, Dungeons.fireflyLeaves, 0);
        this.setBlock(world, i + 6, j + 17, k + 11, Dungeons.fireflyLeaves, 0);
        this.setBlock(world, i + 6, j + 17, k + 16, Dungeons.fireflyLeaves, 0);
        this.setBlock(world, i + 6, j + 18, k + 5, Dungeons.fireflyLeaves, 0);
        this.setBlock(world, i + 6, j + 18, k + 6, Dungeons.fireflyLeaves, 0);
        this.setBlock(world, i + 6, j + 18, k + 7, Dungeons.fireflyLeaves, 0);
        this.setBlock(world, i + 6, j + 18, k + 8, Dungeons.fireflyLeaves, 0);
        this.setBlock(world, i + 6, j + 18, k + 9, Dungeons.fireflyLeaves, 0);
        this.setBlock(world, i + 6, j + 18, k + 10, Dungeons.fireflyLeaves, 0);
        this.setBlock(world, i + 6, j + 18, k + 11, Dungeons.fireflyLeaves, 0);
        this.setBlock(world, i + 6, j + 18, k + 12, Dungeons.fireflyLeaves, 0);
        this.setBlock(world, i + 6, j + 18, k + 13, Dungeons.fireflyLeaves, 0);
        this.setBlock(world, i + 6, j + 19, k + 9, Dungeons.fireflyLeaves, 0);
        this.setBlock(world, i + 6, j + 19, k + 10, Dungeons.fireflyLeaves, 0);
        this.setBlock(world, i + 6, j + 19, k + 11, Dungeons.fireflyLeaves, 0);
        this.setBlock(world, i + 6, j + 19, k + 12, Dungeons.fireflyLeaves, 0);
        this.setBlock(world, i + 6, j + 20, k + 11, Dungeons.fireflyLeaves, 0);
        this.setBlock(world, i + 6, j + 25, k + 23, Dungeons.fireflyLeaves, 0);
        this.setBlock(world, i + 7, j + 9, k + 23, Dungeons.fireflyLeaves, 0);
        this.setBlock(world, i + 7, j + 9, k + 24, Dungeons.fireflyLeaves, 0);
        this.setBlock(world, i + 7, j + 9, k + 25, Dungeons.fireflyLeaves, 0);
        this.setBlock(world, i + 7, j + 10, k + 21, Dungeons.fireflyLeaves, 0);
        this.setBlock(world, i + 7, j + 10, k + 22, Dungeons.fireflyLeaves, 0);
        this.setBlock(world, i + 7, j + 10, k + 23, Dungeons.fireflyLeaves, 0);
        this.setBlock(world, i + 7, j + 10, k + 24, Dungeons.fireflyLeaves, 0);
        this.setBlock(world, i + 7, j + 10, k + 25, Dungeons.fireflyLeaves, 0);
        this.setBlock(world, i + 7, j + 10, k + 26, Dungeons.fireflyLeaves, 0);
        this.setBlock(world, i + 7, j + 10, k + 27, Dungeons.fireflyLeaves, 0);
        this.setBlock(world, i + 7, j + 11, k + 23, Dungeons.fireflyLeaves, 0);
        this.setBlock(world, i + 7, j + 11, k + 24, Dungeons.fireflyLeaves, 0);
        this.setBlock(world, i + 7, j + 11, k + 25, Dungeons.fireflyLeaves, 0);
        this.setBlock(world, i + 7, j + 12, k + 24, Dungeons.fireflyLeaves, 0);
        this.setBlock(world, i + 7, j + 14, k + 20, Dungeons.fireflyLog, 0);
        this.setBlock(world, i + 7, j + 14, k + 21, Dungeons.fireflyLog, 0);
        this.setBlock(world, i + 7, j + 16, k + 15, Dungeons.fireflyLeaves, 0);
        this.setBlock(world, i + 7, j + 16, k + 16, Dungeons.fireflyLeaves, 0);
        this.setBlock(world, i + 7, j + 16, k + 17, Dungeons.fireflyLeaves, 0);
        this.setBlock(world, i + 7, j + 16, k + 18, Dungeons.fireflyLeaves, 0);
        this.setBlock(world, i + 7, j + 16, k + 19, Dungeons.fireflyLeaves, 0);
        this.setBlock(world, i + 7, j + 16, k + 20, Dungeons.fireflyLeaves, 0);
        this.setBlock(world, i + 7, j + 16, k + 21, Dungeons.fireflyLeaves, 0);
        this.setBlock(world, i + 7, j + 16, k + 22, Dungeons.fireflyLeaves, 0);
        this.setBlock(world, i + 7, j + 16, k + 23, Dungeons.fireflyLeaves, 0);
        this.setBlock(world, i + 7, j + 16, k + 24, Dungeons.fireflyLeaves, 0);
        this.setBlock(world, i + 7, j + 17, k + 10, Dungeons.fireflyLeaves, 0);
        this.setBlock(world, i + 7, j + 17, k + 11, Dungeons.fireflyLeaves, 0);
        this.setBlock(world, i + 7, j + 17, k + 12, Dungeons.fireflyLeaves, 0);
        this.setBlock(world, i + 7, j + 18, k + 4, Dungeons.fireflyLeaves, 0);
        this.setBlock(world, i + 7, j + 18, k + 5, Dungeons.fireflyLeaves, 0);
        this.setBlock(world, i + 7, j + 18, k + 6, Dungeons.fireflyLeaves, 0);
        this.setBlock(world, i + 7, j + 18, k + 7, Dungeons.fireflyLeaves, 0);
        this.setBlock(world, i + 7, j + 18, k + 8, Dungeons.fireflyLeaves, 0);
        this.setBlock(world, i + 7, j + 18, k + 9, Dungeons.fireflyLeaves, 0);
        this.setBlock(world, i + 7, j + 18, k + 10, Dungeons.fireflyLeaves, 0);
        this.setBlock(world, i + 7, j + 18, k + 11, Dungeons.fireflyLeaves, 0);
        this.setBlock(world, i + 7, j + 18, k + 12, Dungeons.fireflyLeaves, 0);
        this.setBlock(world, i + 7, j + 18, k + 13, Dungeons.fireflyLeaves, 0);
        this.setBlock(world, i + 7, j + 18, k + 14, Dungeons.fireflyLeaves, 0);
        this.setBlock(world, i + 7, j + 19, k + 10, Dungeons.fireflyLeaves, 0);
        this.setBlock(world, i + 7, j + 19, k + 11, Dungeons.fireflyLeaves, 0);
        this.setBlock(world, i + 7, j + 19, k + 12, Dungeons.fireflyLeaves, 0);
        this.setBlock(world, i + 7, j + 20, k + 11, Dungeons.fireflyLeaves, 0);
        this.setBlock(world, i + 7, j + 24, k + 12, Dungeons.fireflyLeaves, 0);
        this.setBlock(world, i + 7, j + 24, k + 13, Dungeons.fireflyLeaves, 0);
        this.setBlock(world, i + 7, j + 24, k + 14, Dungeons.fireflyLeaves, 0);
        this.setBlock(world, i + 7, j + 24, k + 15, Dungeons.fireflyLeaves, 0);
        this.setBlock(world, i + 7, j + 24, k + 16, Dungeons.fireflyLeaves, 0);
        this.setBlock(world, i + 7, j + 25, k + 22, Dungeons.fireflyLeaves, 0);
        this.setBlock(world, i + 7, j + 25, k + 23, Dungeons.fireflyLeaves, 0);
        this.setBlock(world, i + 7, j + 25, k + 24, Dungeons.fireflyLeaves, 0);
        this.setBlock(world, i + 7, j + 25, k + 25, Dungeons.fireflyLeaves, 0);
        this.setBlock(world, i + 8, j + 9, k + 24, Dungeons.fireflyLeaves, 0);
        this.setBlock(world, i + 8, j + 9, k + 25, Dungeons.fireflyLeaves, 0);
        this.setBlock(world, i + 8, j + 10, k + 21, Dungeons.fireflyLeaves, 0);
        this.setBlock(world, i + 8, j + 10, k + 22, Dungeons.fireflyLeaves, 0);
        this.setBlock(world, i + 8, j + 10, k + 23, Dungeons.fireflyLeaves, 0);
        this.setBlock(world, i + 8, j + 10, k + 24, Dungeons.fireflyLog, 0);
        this.setBlock(world, i + 8, j + 10, k + 25, Dungeons.fireflyLeaves, 0);
        this.setBlock(world, i + 8, j + 10, k + 26, Dungeons.fireflyLeaves, 0);
        this.setBlock(world, i + 8, j + 10, k + 27, Dungeons.fireflyLeaves, 0);
        this.setBlock(world, i + 8, j + 10, k + 28, Dungeons.fireflyLeaves, 0);
        this.setBlock(world, i + 8, j + 11, k + 23, Dungeons.fireflyLeaves, 0);
        this.setBlock(world, i + 8, j + 11, k + 24, Dungeons.fireflyLeaves, 0);
        this.setBlock(world, i + 8, j + 13, k + 20, Dungeons.fireflyLog, 0);
        this.setBlock(world, i + 8, j + 16, k + 11, Dungeons.fireflyLeaves, 0);
        this.setBlock(world, i + 8, j + 16, k + 16, Dungeons.fireflyLeaves, 0);
        this.setBlock(world, i + 8, j + 16, k + 17, Dungeons.fireflyLeaves, 0);
        this.setBlock(world, i + 8, j + 16, k + 18, Dungeons.fireflyLeaves, 0);
        this.setBlock(world, i + 8, j + 16, k + 21, Dungeons.fireflyLeaves, 0);
        this.setBlock(world, i + 8, j + 16, k + 22, Dungeons.fireflyLeaves, 0);
        this.setBlock(world, i + 8, j + 16, k + 23, Dungeons.fireflyLeaves, 0);
        this.setBlock(world, i + 8, j + 17, k + 6, Dungeons.fireflyLeaves, 0);
        this.setBlock(world, i + 8, j + 17, k + 9, Dungeons.fireflyLeaves, 0);
        this.setBlock(world, i + 8, j + 17, k + 10, Dungeons.fireflyLeaves, 0);
        this.setBlock(world, i + 8, j + 17, k + 11, Dungeons.fireflyLog, 0);
        this.setBlock(world, i + 8, j + 17, k + 12, Dungeons.fireflyLeaves, 0);
        this.setBlock(world, i + 8, j + 18, k + 3, Dungeons.fireflyLeaves, 0);
        this.setBlock(world, i + 8, j + 18, k + 4, Dungeons.fireflyLeaves, 0);
        this.setBlock(world, i + 8, j + 18, k + 5, Dungeons.fireflyLeaves, 0);
        this.setBlock(world, i + 8, j + 18, k + 6, Dungeons.fireflyLeaves, 0);
        this.setBlock(world, i + 8, j + 18, k + 7, Dungeons.fireflyLeaves, 0);
        this.setBlock(world, i + 8, j + 18, k + 8, Dungeons.fireflyLeaves, 0);
        this.setBlock(world, i + 8, j + 18, k + 9, Dungeons.fireflyLeaves, 0);
        this.setBlock(world, i + 8, j + 18, k + 10, Dungeons.fireflyLeaves, 0);
        this.setBlock(world, i + 8, j + 18, k + 11, Dungeons.fireflyLeaves, 0);
        this.setBlock(world, i + 8, j + 18, k + 12, Dungeons.fireflyLeaves, 0);
        this.setBlock(world, i + 8, j + 18, k + 13, Dungeons.fireflyLeaves, 0);
        this.setBlock(world, i + 8, j + 18, k + 14, Dungeons.fireflyLeaves, 0);
        this.setBlock(world, i + 8, j + 18, k + 15, Dungeons.fireflyLeaves, 0);
        this.setBlock(world, i + 8, j + 19, k + 6, Dungeons.fireflyLeaves, 0);
        this.setBlock(world, i + 8, j + 19, k + 10, Dungeons.fireflyLeaves, 0);
        this.setBlock(world, i + 8, j + 19, k + 11, Dungeons.fireflyLeaves, 0);
        this.setBlock(world, i + 8, j + 19, k + 12, Dungeons.fireflyLeaves, 0);
        this.setBlock(world, i + 8, j + 20, k + 11, Dungeons.fireflyLeaves, 0);
        this.setBlock(world, i + 8, j + 24, k + 11, Dungeons.fireflyLeaves, 0);
        this.setBlock(world, i + 8, j + 24, k + 12, Dungeons.fireflyLeaves, 0);
        this.setBlock(world, i + 8, j + 24, k + 13, Dungeons.fireflyLeaves, 0);
        this.setBlock(world, i + 8, j + 24, k + 14, Dungeons.fireflyLeaves, 0);
        this.setBlock(world, i + 8, j + 24, k + 15, Dungeons.fireflyLeaves, 0);
        this.setBlock(world, i + 8, j + 24, k + 16, Dungeons.fireflyLeaves, 0);
        this.setBlock(world, i + 8, j + 24, k + 17, Dungeons.fireflyLeaves, 0);
        this.setBlock(world, i + 8, j + 25, k + 14, Dungeons.fireflyLeaves, 0);
        this.setBlock(world, i + 8, j + 25, k + 21, Dungeons.fireflyLeaves, 0);
        this.setBlock(world, i + 8, j + 25, k + 22, Dungeons.fireflyLeaves, 0);
        this.setBlock(world, i + 8, j + 25, k + 23, Dungeons.fireflyLeaves, 0);
        this.setBlock(world, i + 8, j + 25, k + 24, Dungeons.fireflyLeaves, 0);
        this.setBlock(world, i + 8, j + 25, k + 25, Dungeons.fireflyLeaves, 0);
        this.setBlock(world, i + 8, j + 25, k + 26, Dungeons.fireflyLeaves, 0);
        this.setBlock(world, i + 8, j + 26, k + 23, Dungeons.fireflyLeaves, 0);
        this.setBlock(world, i + 9, j + 10, k + 22, Dungeons.fireflyLeaves, 0);
        this.setBlock(world, i + 9, j + 10, k + 23, Dungeons.fireflyLeaves, 0);
        this.setBlock(world, i + 9, j + 10, k + 24, Dungeons.fireflyLeaves, 0);
        this.setBlock(world, i + 9, j + 10, k + 25, Dungeons.fireflyLeaves, 0);
        this.setBlock(world, i + 9, j + 10, k + 26, Dungeons.fireflyLeaves, 0);
        this.setBlock(world, i + 9, j + 10, k + 27, Dungeons.fireflyLeaves, 0);
        this.setBlock(world, i + 9, j + 10, k + 28, Dungeons.fireflyLeaves, 0);
        this.setBlock(world, i + 9, j + 10, k + 29, Dungeons.fireflyLeaves, 0);
        this.setBlock(world, i + 9, j + 10, k + 30, Dungeons.fireflyLeaves, 0);
        this.setBlock(world, i + 9, j + 11, k + 24, Dungeons.fireflyLog, 0);
        this.setBlock(world, i + 9, j + 12, k + 13, Dungeons.fireflyLeaves, 0);
        this.setBlock(world, i + 9, j + 12, k + 14, Dungeons.fireflyLeaves, 0);
        this.setBlock(world, i + 9, j + 12, k + 15, Dungeons.fireflyLeaves, 0);
        this.setBlock(world, i + 9, j + 13, k + 20, Dungeons.fireflyLog, 0);
        this.setBlock(world, i + 9, j + 16, k + 11, Dungeons.fireflyLog, 0);
        this.setBlock(world, i + 9, j + 16, k + 17, Dungeons.fireflyLeaves, 0);
        this.setBlock(world, i + 9, j + 16, k + 22, Dungeons.fireflyLeaves, 0);
        this.setBlock(world, i + 9, j + 17, k + 5, Dungeons.fireflyLeaves, 0);
        this.setBlock(world, i + 9, j + 17, k + 6, Dungeons.fireflyLeaves, 0);
        this.setBlock(world, i + 9, j + 17, k + 7, Dungeons.fireflyLeaves, 0);
        this.setBlock(world, i + 9, j + 17, k + 10, Dungeons.fireflyLeaves, 0);
        this.setBlock(world, i + 9, j + 17, k + 11, Dungeons.fireflyLeaves, 0);
        this.setBlock(world, i + 9, j + 17, k + 12, Dungeons.fireflyLeaves, 0);
        this.setBlock(world, i + 9, j + 18, k + 3, Dungeons.fireflyLeaves, 0);
        this.setBlock(world, i + 9, j + 18, k + 4, Dungeons.fireflyLeaves, 0);
        this.setBlock(world, i + 9, j + 18, k + 5, Dungeons.fireflyLeaves, 0);
        this.setBlock(world, i + 9, j + 18, k + 6, Dungeons.fireflyLeaves, 0);
        this.setBlock(world, i + 9, j + 18, k + 7, Dungeons.fireflyLeaves, 0);
        this.setBlock(world, i + 9, j + 18, k + 8, Dungeons.fireflyLeaves, 0);
        this.setBlock(world, i + 9, j + 18, k + 9, Dungeons.fireflyLeaves, 0);
        this.setBlock(world, i + 9, j + 18, k + 10, Dungeons.fireflyLeaves, 0);
        this.setBlock(world, i + 9, j + 18, k + 11, Dungeons.fireflyLeaves, 0);
        this.setBlock(world, i + 9, j + 18, k + 12, Dungeons.fireflyLeaves, 0);
        this.setBlock(world, i + 9, j + 18, k + 13, Dungeons.fireflyLeaves, 0);
        this.setBlock(world, i + 9, j + 18, k + 14, Dungeons.fireflyLeaves, 0);
        this.setBlock(world, i + 9, j + 18, k + 17, Dungeons.fireflyLeaves, 0);
        this.setBlock(world, i + 9, j + 18, k + 18, Dungeons.fireflyLeaves, 0);
        this.setBlock(world, i + 9, j + 19, k + 5, Dungeons.fireflyLeaves, 0);
        this.setBlock(world, i + 9, j + 19, k + 6, Dungeons.fireflyLeaves, 0);
        this.setBlock(world, i + 9, j + 19, k + 7, Dungeons.fireflyLeaves, 0);
        this.setBlock(world, i + 9, j + 19, k + 10, Dungeons.fireflyLeaves, 0);
        this.setBlock(world, i + 9, j + 19, k + 11, Dungeons.fireflyLeaves, 0);
        this.setBlock(world, i + 9, j + 20, k + 6, Dungeons.fireflyLeaves, 0);
        this.setBlock(world, i + 9, j + 20, k + 11, Dungeons.fireflyLeaves, 0);
        this.setBlock(world, i + 9, j + 23, k + 14, Dungeons.fireflyLeaves, 0);
        this.setBlock(world, i + 9, j + 24, k + 11, Dungeons.fireflyLeaves, 0);
        this.setBlock(world, i + 9, j + 24, k + 12, Dungeons.fireflyLeaves, 0);
        this.setBlock(world, i + 9, j + 24, k + 13, Dungeons.fireflyLeaves, 0);
        this.setBlock(world, i + 9, j + 24, k + 14, Dungeons.fireflyLeaves, 0);
        this.setBlock(world, i + 9, j + 24, k + 15, Dungeons.fireflyLeaves, 0);
        this.setBlock(world, i + 9, j + 24, k + 16, Dungeons.fireflyLeaves, 0);
        this.setBlock(world, i + 9, j + 24, k + 17, Dungeons.fireflyLeaves, 0);
        this.setBlock(world, i + 9, j + 24, k + 18, Dungeons.fireflyLeaves, 0);
        this.setBlock(world, i + 9, j + 24, k + 22, Dungeons.fireflyLeaves, 0);
        this.setBlock(world, i + 9, j + 24, k + 23, Dungeons.fireflyLeaves, 0);
        this.setBlock(world, i + 9, j + 24, k + 24, Dungeons.fireflyLeaves, 0);
        this.setBlock(world, i + 9, j + 25, k + 13, Dungeons.fireflyLeaves, 0);
        this.setBlock(world, i + 9, j + 25, k + 14, Dungeons.fireflyLeaves, 0);
        this.setBlock(world, i + 9, j + 25, k + 15, Dungeons.fireflyLeaves, 0);
        this.setBlock(world, i + 9, j + 25, k + 21, Dungeons.fireflyLeaves, 0);
        this.setBlock(world, i + 9, j + 25, k + 22, Dungeons.fireflyLeaves, 0);
        this.setBlock(world, i + 9, j + 25, k + 23, Dungeons.fireflyLeaves, 0);
        this.setBlock(world, i + 9, j + 25, k + 24, Dungeons.fireflyLeaves, 0);
        this.setBlock(world, i + 9, j + 25, k + 25, Dungeons.fireflyLeaves, 0);
        this.setBlock(world, i + 9, j + 25, k + 26, Dungeons.fireflyLeaves, 0);
        this.setBlock(world, i + 9, j + 25, k + 27, Dungeons.fireflyLeaves, 0);
        this.setBlock(world, i + 9, j + 26, k + 23, Dungeons.fireflyLeaves, 0);
        this.setBlock(world, i + 9, j + 26, k + 24, Dungeons.fireflyLeaves, 0);
        this.setBlock(world, i + 10, j + 9, k + 25, Dungeons.fireflyLeaves, 0);
        this.setBlock(world, i + 10, j + 9, k + 26, Dungeons.fireflyLeaves, 0);
        this.setBlock(world, i + 10, j + 9, k + 27, Dungeons.fireflyLeaves, 0);
        this.setBlock(world, i + 10, j + 10, k + 22, Dungeons.fireflyLeaves, 0);
        this.setBlock(world, i + 10, j + 10, k + 23, Dungeons.fireflyLeaves, 0);
        this.setBlock(world, i + 10, j + 10, k + 24, Dungeons.fireflyLeaves, 0);
        this.setBlock(world, i + 10, j + 10, k + 25, Dungeons.fireflyLeaves, 0);
        this.setBlock(world, i + 10, j + 10, k + 26, Dungeons.fireflyLeaves, 0);
        this.setBlock(world, i + 10, j + 10, k + 27, Dungeons.fireflyLeaves, 0);
        this.setBlock(world, i + 10, j + 10, k + 28, Dungeons.fireflyLeaves, 0);
        this.setBlock(world, i + 10, j + 10, k + 29, Dungeons.fireflyLeaves, 0);
        this.setBlock(world, i + 10, j + 10, k + 30, Dungeons.fireflyLeaves, 0);
        this.setBlock(world, i + 10, j + 10, k + 31, Dungeons.fireflyLeaves, 0);
        this.setBlock(world, i + 10, j + 11, k + 14, Dungeons.fireflyLeaves, 0);
        this.setBlock(world, i + 10, j + 11, k + 24, Dungeons.fireflyLog, 0);
        this.setBlock(world, i + 10, j + 11, k + 25, Dungeons.fireflyLeaves, 0);
        this.setBlock(world, i + 10, j + 11, k + 26, Dungeons.fireflyLeaves, 0);
        this.setBlock(world, i + 10, j + 11, k + 27, Dungeons.fireflyLeaves, 0);
        this.setBlock(world, i + 10, j + 11, k + 28, Dungeons.fireflyLeaves, 0);
        this.setBlock(world, i + 10, j + 12, k + 12, Dungeons.fireflyLeaves, 0);
        this.setBlock(world, i + 10, j + 12, k + 13, Dungeons.fireflyLeaves, 0);
        this.setBlock(world, i + 10, j + 12, k + 14, Dungeons.fireflyLeaves, 0);
        this.setBlock(world, i + 10, j + 12, k + 15, Dungeons.fireflyLeaves, 0);
        this.setBlock(world, i + 10, j + 12, k + 16, Dungeons.fireflyLeaves, 0);
        this.setBlock(world, i + 10, j + 13, k + 13, Dungeons.fireflyLeaves, 0);
        this.setBlock(world, i + 10, j + 13, k + 14, Dungeons.fireflyLeaves, 0);
        this.setBlock(world, i + 10, j + 13, k + 20, Dungeons.fireflyLog, 0);
        this.setBlock(world, i + 10, j + 16, k + 7, Dungeons.fireflyLeaves, 0);
        this.setBlock(world, i + 10, j + 16, k + 11, Dungeons.fireflyLog, 0);
        this.setBlock(world, i + 10, j + 17, k + 4, Dungeons.fireflyLeaves, 0);
        this.setBlock(world, i + 10, j + 17, k + 5, Dungeons.fireflyLeaves, 0);
        this.setBlock(world, i + 10, j + 17, k + 6, Dungeons.fireflyLeaves, 0);
        this.setBlock(world, i + 10, j + 17, k + 7, Dungeons.fireflyLog, 0);
        this.setBlock(world, i + 10, j + 17, k + 8, Dungeons.fireflyLeaves, 0);
        this.setBlock(world, i + 10, j + 17, k + 11, Dungeons.fireflyLeaves, 0);
        this.setBlock(world, i + 10, j + 17, k + 12, Dungeons.fireflyLeaves, 0);
        this.setBlock(world, i + 10, j + 18, k + 3, Dungeons.fireflyLeaves, 0);
        this.setBlock(world, i + 10, j + 18, k + 4, Dungeons.fireflyLeaves, 0);
        this.setBlock(world, i + 10, j + 18, k + 5, Dungeons.fireflyLeaves, 0);
        this.setBlock(world, i + 10, j + 18, k + 6, Dungeons.fireflyLog, 0);
        this.setBlock(world, i + 10, j + 18, k + 7, Dungeons.fireflyLeaves, 0);
        this.setBlock(world, i + 10, j + 18, k + 8, Dungeons.fireflyLeaves, 0);
        this.setBlock(world, i + 10, j + 18, k + 9, Dungeons.fireflyLeaves, 0);
        this.setBlock(world, i + 10, j + 18, k + 10, Dungeons.fireflyLeaves, 0);
        this.setBlock(world, i + 10, j + 18, k + 11, Dungeons.fireflyLeaves, 0);
        this.setBlock(world, i + 10, j + 18, k + 12, Dungeons.fireflyLeaves, 0);
        this.setBlock(world, i + 10, j + 18, k + 13, Dungeons.fireflyLeaves, 0);
        this.setBlock(world, i + 10, j + 18, k + 16, Dungeons.fireflyLeaves, 0);
        this.setBlock(world, i + 10, j + 18, k + 17, Dungeons.fireflyLeaves, 0);
        this.setBlock(world, i + 10, j + 18, k + 18, Dungeons.fireflyLeaves, 0);
        this.setBlock(world, i + 10, j + 18, k + 19, Dungeons.fireflyLeaves, 0);
        this.setBlock(world, i + 10, j + 18, k + 20, Dungeons.fireflyLeaves, 0);
        this.setBlock(world, i + 10, j + 19, k + 5, Dungeons.fireflyLeaves, 0);
        this.setBlock(world, i + 10, j + 19, k + 6, Dungeons.fireflyLeaves, 0);
        this.setBlock(world, i + 10, j + 19, k + 7, Dungeons.fireflyLeaves, 0);
        this.setBlock(world, i + 10, j + 19, k + 10, Dungeons.fireflyLeaves, 0);
        this.setBlock(world, i + 10, j + 19, k + 11, Dungeons.fireflyLeaves, 0);
        this.setBlock(world, i + 10, j + 20, k + 6, Dungeons.fireflyLeaves, 0);
        this.setBlock(world, i + 10, j + 23, k + 14, Dungeons.fireflyLeaves, 0);
        this.setBlock(world, i + 10, j + 23, k + 15, Dungeons.fireflyLeaves, 0);
        this.setBlock(world, i + 10, j + 23, k + 20, Dungeons.fireflyLog, 0);
        this.setBlock(world, i + 10, j + 23, k + 22, Dungeons.fireflyLeaves, 0);
        this.setBlock(world, i + 10, j + 23, k + 23, Dungeons.fireflyLeaves, 0);
        this.setBlock(world, i + 10, j + 24, k + 11, Dungeons.fireflyLeaves, 0);
        this.setBlock(world, i + 10, j + 24, k + 12, Dungeons.fireflyLeaves, 0);
        this.setBlock(world, i + 10, j + 24, k + 13, Dungeons.fireflyLeaves, 0);
        this.setBlock(world, i + 10, j + 24, k + 14, Dungeons.fireflyLog, 0);
        this.setBlock(world, i + 10, j + 24, k + 15, Dungeons.fireflyLeaves, 0);
        this.setBlock(world, i + 10, j + 24, k + 16, Dungeons.fireflyLeaves, 0);
        this.setBlock(world, i + 10, j + 24, k + 17, Dungeons.fireflyLeaves, 0);
        this.setBlock(world, i + 10, j + 24, k + 18, Dungeons.fireflyLeaves, 0);
        this.setBlock(world, i + 10, j + 24, k + 21, Dungeons.fireflyLog, 0);
        this.setBlock(world, i + 10, j + 24, k + 22, Dungeons.fireflyLog, 0);
        this.setBlock(world, i + 10, j + 24, k + 23, Dungeons.fireflyLog, 0);
        this.setBlock(world, i + 10, j + 24, k + 24, Dungeons.fireflyLeaves, 0);
        this.setBlock(world, i + 10, j + 24, k + 25, Dungeons.fireflyLeaves, 0);
        this.setBlock(world, i + 10, j + 25, k + 12, Dungeons.fireflyLeaves, 0);
        this.setBlock(world, i + 10, j + 25, k + 13, Dungeons.fireflyLeaves, 0);
        this.setBlock(world, i + 10, j + 25, k + 14, Dungeons.fireflyLeaves, 0);
        this.setBlock(world, i + 10, j + 25, k + 15, Dungeons.fireflyLeaves, 0);
        this.setBlock(world, i + 10, j + 25, k + 16, Dungeons.fireflyLeaves, 0);
        this.setBlock(world, i + 10, j + 25, k + 20, Dungeons.fireflyLeaves, 0);
        this.setBlock(world, i + 10, j + 25, k + 21, Dungeons.fireflyLeaves, 0);
        this.setBlock(world, i + 10, j + 25, k + 22, Dungeons.fireflyLeaves, 0);
        this.setBlock(world, i + 10, j + 25, k + 23, Dungeons.fireflyLeaves, 0);
        this.setBlock(world, i + 10, j + 25, k + 24, Dungeons.fireflyLeaves, 0);
        this.setBlock(world, i + 10, j + 25, k + 25, Dungeons.fireflyLeaves, 0);
        this.setBlock(world, i + 10, j + 25, k + 26, Dungeons.fireflyLeaves, 0);
        this.setBlock(world, i + 10, j + 25, k + 27, Dungeons.fireflyLeaves, 0);
        this.setBlock(world, i + 10, j + 26, k + 14, Dungeons.fireflyLeaves, 0);
        this.setBlock(world, i + 10, j + 26, k + 22, Dungeons.fireflyLeaves, 0);
        this.setBlock(world, i + 10, j + 26, k + 23, Dungeons.fireflyLeaves, 0);
        this.setBlock(world, i + 10, j + 26, k + 24, Dungeons.fireflyLeaves, 0);
        this.setBlock(world, i + 10, j + 26, k + 25, Dungeons.fireflyLeaves, 0);
        this.setBlock(world, i + 10, j + 27, k + 23, Dungeons.fireflyLeaves, 0);
        this.setBlock(world, i + 11, j + 9, k + 24, Dungeons.fireflyLeaves, 0);
        this.setBlock(world, i + 11, j + 9, k + 25, Dungeons.fireflyLeaves, 0);
        this.setBlock(world, i + 11, j + 9, k + 26, Dungeons.fireflyLeaves, 0);
        this.setBlock(world, i + 11, j + 9, k + 27, Dungeons.fireflyLeaves, 0);
        this.setBlock(world, i + 11, j + 9, k + 28, Dungeons.fireflyLeaves, 0);
        this.setBlock(world, i + 11, j + 9, k + 29, Dungeons.fireflyLeaves, 0);
        this.setBlock(world, i + 11, j + 10, k + 23, Dungeons.fireflyLeaves, 0);
        this.setBlock(world, i + 11, j + 10, k + 24, Dungeons.fireflyLeaves, 0);
        this.setBlock(world, i + 11, j + 10, k + 25, Dungeons.fireflyLog, 0);
        this.setBlock(world, i + 11, j + 10, k + 26, Dungeons.fireflyLog, 0);
        this.setBlock(world, i + 11, j + 10, k + 27, Dungeons.fireflyLeaves, 0);
        this.setBlock(world, i + 11, j + 10, k + 28, Dungeons.fireflyLeaves, 0);
        this.setBlock(world, i + 11, j + 10, k + 29, Dungeons.fireflyLeaves, 0);
        this.setBlock(world, i + 11, j + 10, k + 30, Dungeons.fireflyLeaves, 0);
        this.setBlock(world, i + 11, j + 10, k + 31, Dungeons.fireflyLeaves, 0);
        this.setBlock(world, i + 11, j + 10, k + 32, Dungeons.fireflyLeaves, 0);
        this.setBlock(world, i + 11, j + 11, k + 13, Dungeons.fireflyLeaves, 0);
        this.setBlock(world, i + 11, j + 11, k + 14, Dungeons.fireflyLeaves, 0);
        this.setBlock(world, i + 11, j + 11, k + 15, Dungeons.fireflyLeaves, 0);
        this.setBlock(world, i + 11, j + 11, k + 24, Dungeons.fireflyLog, 0);
        this.setBlock(world, i + 11, j + 11, k + 25, Dungeons.fireflyLeaves, 0);
        this.setBlock(world, i + 11, j + 11, k + 26, Dungeons.fireflyLeaves, 0);
        this.setBlock(world, i + 11, j + 11, k + 27, Dungeons.fireflyLeaves, 0);
        this.setBlock(world, i + 11, j + 11, k + 28, Dungeons.fireflyLeaves, 0);
        this.setBlock(world, i + 11, j + 11, k + 29, Dungeons.fireflyLeaves, 0);
        this.setBlock(world, i + 11, j + 12, k + 12, Dungeons.fireflyLeaves, 0);
        this.setBlock(world, i + 11, j + 12, k + 13, Dungeons.fireflyLeaves, 0);
        this.setBlock(world, i + 11, j + 12, k + 14, Dungeons.fireflyLeaves, 0);
        this.setBlock(world, i + 11, j + 12, k + 15, Dungeons.fireflyLeaves, 0);
        this.setBlock(world, i + 11, j + 12, k + 16, Dungeons.fireflyLeaves, 0);
        this.setBlock(world, i + 11, j + 12, k + 17, Dungeons.fireflyLeaves, 0);
        this.setBlock(world, i + 11, j + 12, k + 27, Dungeons.fireflyLeaves, 0);
        this.setBlock(world, i + 11, j + 13, k + 14, Dungeons.fireflyLeaves, 0);
        this.setBlock(world, i + 11, j + 13, k + 15, Dungeons.fireflyLeaves, 0);
        this.setBlock(world, i + 11, j + 13, k + 20, Dungeons.fireflyLog, 0);
        this.setBlock(world, i + 11, j + 15, k + 23, Dungeons.fireflyLeaves, 0);
        this.setBlock(world, i + 11, j + 16, k + 11, Dungeons.fireflyLog, 0);
        this.setBlock(world, i + 11, j + 16, k + 12, Dungeons.fireflyLog, 0);
        this.setBlock(world, i + 11, j + 17, k + 6, Dungeons.fireflyLeaves, 0);
        this.setBlock(world, i + 11, j + 17, k + 7, Dungeons.fireflyLeaves, 0);
        this.setBlock(world, i + 11, j + 17, k + 8, Dungeons.fireflyLeaves, 0);
        this.setBlock(world, i + 11, j + 18, k + 3, Dungeons.fireflyLeaves, 0);
        this.setBlock(world, i + 11, j + 18, k + 4, Dungeons.fireflyLeaves, 0);
        this.setBlock(world, i + 11, j + 18, k + 5, Dungeons.fireflyLeaves, 0);
        this.setBlock(world, i + 11, j + 18, k + 6, Dungeons.fireflyLog, 0);
        this.setBlock(world, i + 11, j + 18, k + 7, Dungeons.fireflyLeaves, 0);
        this.setBlock(world, i + 11, j + 18, k + 8, Dungeons.fireflyLeaves, 0);
        this.setBlock(world, i + 11, j + 18, k + 9, Dungeons.fireflyLeaves, 0);
        this.setBlock(world, i + 11, j + 18, k + 10, Dungeons.fireflyLeaves, 0);
        this.setBlock(world, i + 11, j + 18, k + 11, Dungeons.fireflyLeaves, 0);
        this.setBlock(world, i + 11, j + 18, k + 12, Dungeons.fireflyLeaves, 0);
        this.setBlock(world, i + 11, j + 18, k + 13, Dungeons.fireflyLeaves, 0);
        this.setBlock(world, i + 11, j + 18, k + 15, Dungeons.fireflyLeaves, 0);
        this.setBlock(world, i + 11, j + 18, k + 16, Dungeons.fireflyLeaves, 0);
        this.setBlock(world, i + 11, j + 18, k + 17, Dungeons.fireflyLeaves, 0);
        this.setBlock(world, i + 11, j + 18, k + 18, Dungeons.fireflyLeaves, 0);
        this.setBlock(world, i + 11, j + 18, k + 19, Dungeons.fireflyLeaves, 0);
        this.setBlock(world, i + 11, j + 18, k + 20, Dungeons.fireflyLeaves, 0);
        this.setBlock(world, i + 11, j + 18, k + 21, Dungeons.fireflyLeaves, 0);
        this.setBlock(world, i + 11, j + 19, k + 6, Dungeons.fireflyLeaves, 0);
        this.setBlock(world, i + 11, j + 19, k + 7, Dungeons.fireflyLeaves, 0);
        this.setBlock(world, i + 11, j + 19, k + 11, Dungeons.fireflyLeaves, 0);
        this.setBlock(world, i + 11, j + 19, k + 17, Dungeons.fireflyLeaves, 0);
        this.setBlock(world, i + 11, j + 21, k + 24, Dungeons.fireflyLeaves, 0);
        this.setBlock(world, i + 11, j + 22, k + 19, Dungeons.fireflyLog, 0);
        this.setBlock(world, i + 11, j + 23, k + 14, Dungeons.fireflyLog, 0);
        this.setBlock(world, i + 11, j + 23, k + 20, Dungeons.fireflyLog, 0);
        this.setBlock(world, i + 11, j + 24, k + 11, Dungeons.fireflyLeaves, 0);
        this.setBlock(world, i + 11, j + 24, k + 12, Dungeons.fireflyLeaves, 0);
        this.setBlock(world, i + 11, j + 24, k + 13, Dungeons.fireflyLeaves, 0);
        this.setBlock(world, i + 11, j + 24, k + 14, Dungeons.fireflyLeaves, 0);
        this.setBlock(world, i + 11, j + 24, k + 15, Dungeons.fireflyLeaves, 0);
        this.setBlock(world, i + 11, j + 24, k + 16, Dungeons.fireflyLeaves, 0);
        this.setBlock(world, i + 11, j + 24, k + 17, Dungeons.fireflyLeaves, 0);
        this.setBlock(world, i + 11, j + 24, k + 18, Dungeons.fireflyLeaves, 0);
        this.setBlock(world, i + 11, j + 24, k + 22, Dungeons.fireflyLeaves, 0);
        this.setBlock(world, i + 11, j + 24, k + 23, Dungeons.fireflyLeaves, 0);
        this.setBlock(world, i + 11, j + 24, k + 24, Dungeons.fireflyLeaves, 0);
        this.setBlock(world, i + 11, j + 25, k + 13, Dungeons.fireflyLeaves, 0);
        this.setBlock(world, i + 11, j + 25, k + 14, Dungeons.fireflyLeaves, 0);
        this.setBlock(world, i + 11, j + 25, k + 15, Dungeons.fireflyLeaves, 0);
        this.setBlock(world, i + 11, j + 25, k + 16, Dungeons.fireflyLeaves, 0);
        this.setBlock(world, i + 11, j + 25, k + 21, Dungeons.fireflyLeaves, 0);
        this.setBlock(world, i + 11, j + 25, k + 22, Dungeons.fireflyLeaves, 0);
        this.setBlock(world, i + 11, j + 25, k + 23, Dungeons.fireflyLeaves, 0);
        this.setBlock(world, i + 11, j + 25, k + 24, Dungeons.fireflyLeaves, 0);
        this.setBlock(world, i + 11, j + 25, k + 25, Dungeons.fireflyLeaves, 0);
        this.setBlock(world, i + 11, j + 25, k + 26, Dungeons.fireflyLeaves, 0);
        this.setBlock(world, i + 11, j + 25, k + 27, Dungeons.fireflyLeaves, 0);
        this.setBlock(world, i + 11, j + 26, k + 14, Dungeons.fireflyLeaves, 0);
        this.setBlock(world, i + 11, j + 26, k + 22, Dungeons.fireflyLeaves, 0);
        this.setBlock(world, i + 11, j + 26, k + 23, Dungeons.fireflyLeaves, 0);
        this.setBlock(world, i + 11, j + 26, k + 24, Dungeons.fireflyLeaves, 0);
        this.setBlock(world, i + 11, j + 26, k + 25, Dungeons.fireflyLeaves, 0);
        this.setBlock(world, i + 11, j + 27, k + 24, Dungeons.fireflyLeaves, 0);
        this.setBlock(world, i + 12, j + 9, k + 25, Dungeons.fireflyLeaves, 0);
        this.setBlock(world, i + 12, j + 9, k + 26, Dungeons.fireflyLeaves, 0);
        this.setBlock(world, i + 12, j + 9, k + 27, Dungeons.fireflyLeaves, 0);
        this.setBlock(world, i + 12, j + 9, k + 28, Dungeons.fireflyLeaves, 0);
        this.setBlock(world, i + 12, j + 10, k + 23, Dungeons.fireflyLeaves, 0);
        this.setBlock(world, i + 12, j + 10, k + 24, Dungeons.fireflyLeaves, 0);
        this.setBlock(world, i + 12, j + 10, k + 25, Dungeons.fireflyLeaves, 0);
        this.setBlock(world, i + 12, j + 10, k + 26, Dungeons.fireflyLeaves, 0);
        this.setBlock(world, i + 12, j + 10, k + 27, Dungeons.fireflyLeaves, 0);
        this.setBlock(world, i + 12, j + 10, k + 28, Dungeons.fireflyLeaves, 0);
        this.setBlock(world, i + 12, j + 10, k + 29, Dungeons.fireflyLeaves, 0);
        this.setBlock(world, i + 12, j + 10, k + 30, Dungeons.fireflyLeaves, 0);
        this.setBlock(world, i + 12, j + 10, k + 31, Dungeons.fireflyLeaves, 0);
        this.setBlock(world, i + 12, j + 11, k + 14, Dungeons.fireflyLeaves, 0);
        this.setBlock(world, i + 12, j + 11, k + 15, Dungeons.fireflyLeaves, 0);
        this.setBlock(world, i + 12, j + 11, k + 23, Dungeons.fireflyLog, 0);
        this.setBlock(world, i + 12, j + 11, k + 24, Dungeons.fireflyLeaves, 0);
        this.setBlock(world, i + 12, j + 11, k + 25, Dungeons.fireflyLeaves, 0);
        this.setBlock(world, i + 12, j + 11, k + 26, Dungeons.fireflyLeaves, 0);
        this.setBlock(world, i + 12, j + 11, k + 27, Dungeons.fireflyLeaves, 0);
        this.setBlock(world, i + 12, j + 11, k + 28, Dungeons.fireflyLeaves, 0);
        this.setBlock(world, i + 12, j + 12, k + 13, Dungeons.fireflyLeaves, 0);
        this.setBlock(world, i + 12, j + 12, k + 14, Dungeons.fireflyLeaves, 0);
        this.setBlock(world, i + 12, j + 12, k + 15, Dungeons.fireflyLeaves, 0);
        this.setBlock(world, i + 12, j + 12, k + 16, Dungeons.fireflyLeaves, 0);
        this.setBlock(world, i + 12, j + 12, k + 17, Dungeons.fireflyLeaves, 0);
        this.setBlock(world, i + 12, j + 12, k + 18, Dungeons.fireflyLeaves, 0);
        this.setBlock(world, i + 12, j + 12, k + 22, Dungeons.fireflyLog, 0);
        this.setBlock(world, i + 12, j + 12, k + 23, Dungeons.fireflyLog, 0);
        this.setBlock(world, i + 12, j + 13, k + 14, Dungeons.fireflyLeaves, 0);
        this.setBlock(world, i + 12, j + 13, k + 15, Dungeons.fireflyLeaves, 0);
        this.setBlock(world, i + 12, j + 13, k + 19, Dungeons.fireflyLog, 0);
        this.setBlock(world, i + 12, j + 13, k + 20, Dungeons.fireflyLog, 0);
        this.setBlock(world, i + 12, j + 13, k + 21, Dungeons.fireflyLog, 0);
        this.setBlock(world, i + 12, j + 13, k + 22, Dungeons.fireflyLog, 0);
        this.setBlock(world, i + 12, j + 15, k + 23, Dungeons.fireflyLeaves, 0);
        this.setBlock(world, i + 12, j + 15, k + 24, Dungeons.fireflyLeaves, 0);
        this.setBlock(world, i + 12, j + 16, k + 12, Dungeons.fireflyLog, 0);
        this.setBlock(world, i + 12, j + 17, k + 6, Dungeons.fireflyLeaves, 0);
        this.setBlock(world, i + 12, j + 17, k + 7, Dungeons.fireflyLeaves, 0);
        this.setBlock(world, i + 12, j + 17, k + 8, Dungeons.fireflyLeaves, 0);
        this.setBlock(world, i + 12, j + 17, k + 18, Dungeons.fireflyLog, 0);
        this.setBlock(world, i + 12, j + 18, k + 4, Dungeons.fireflyLeaves, 0);
        this.setBlock(world, i + 12, j + 18, k + 5, Dungeons.fireflyLeaves, 0);
        this.setBlock(world, i + 12, j + 18, k + 6, Dungeons.fireflyLeaves, 0);
        this.setBlock(world, i + 12, j + 18, k + 7, Dungeons.fireflyLog, 0);
        this.setBlock(world, i + 12, j + 18, k + 8, Dungeons.fireflyLeaves, 0);
        this.setBlock(world, i + 12, j + 18, k + 9, Dungeons.fireflyLeaves, 0);
        this.setBlock(world, i + 12, j + 18, k + 10, Dungeons.fireflyLeaves, 0);
        this.setBlock(world, i + 12, j + 18, k + 11, Dungeons.fireflyLeaves, 0);
        this.setBlock(world, i + 12, j + 18, k + 12, Dungeons.fireflyLeaves, 0);
        this.setBlock(world, i + 12, j + 18, k + 15, Dungeons.fireflyLeaves, 0);
        this.setBlock(world, i + 12, j + 18, k + 16, Dungeons.fireflyLeaves, 0);
        this.setBlock(world, i + 12, j + 18, k + 17, Dungeons.fireflyLeaves, 0);
        this.setBlock(world, i + 12, j + 18, k + 18, Dungeons.fireflyLog, 0);
        this.setBlock(world, i + 12, j + 18, k + 19, Dungeons.fireflyLeaves, 0);
        this.setBlock(world, i + 12, j + 18, k + 20, Dungeons.fireflyLeaves, 0);
        this.setBlock(world, i + 12, j + 18, k + 21, Dungeons.fireflyLeaves, 0);
        this.setBlock(world, i + 12, j + 19, k + 7, Dungeons.fireflyLeaves, 0);
        this.setBlock(world, i + 12, j + 19, k + 16, Dungeons.fireflyLeaves, 0);
        this.setBlock(world, i + 12, j + 19, k + 17, Dungeons.fireflyLeaves, 0);
        this.setBlock(world, i + 12, j + 19, k + 18, Dungeons.fireflyLeaves, 0);
        this.setBlock(world, i + 12, j + 19, k + 19, Dungeons.fireflyLeaves, 0);
        this.setBlock(world, i + 12, j + 21, k + 14, Dungeons.fireflyLog, 0);
        this.setBlock(world, i + 12, j + 21, k + 21, Dungeons.fireflyLeaves, 0);
        this.setBlock(world, i + 12, j + 21, k + 22, Dungeons.fireflyLeaves, 0);
        this.setBlock(world, i + 12, j + 21, k + 23, Dungeons.fireflyLeaves, 0);
        this.setBlock(world, i + 12, j + 21, k + 24, Dungeons.fireflyLeaves, 0);
        this.setBlock(world, i + 12, j + 21, k + 25, Dungeons.fireflyLeaves, 0);
        this.setBlock(world, i + 12, j + 22, k + 14, Dungeons.fireflyLog, 0);
        this.setBlock(world, i + 12, j + 22, k + 19, Dungeons.fireflyLog, 0);
        this.setBlock(world, i + 12, j + 24, k + 11, Dungeons.fireflyLeaves, 0);
        this.setBlock(world, i + 12, j + 24, k + 12, Dungeons.fireflyLeaves, 0);
        this.setBlock(world, i + 12, j + 24, k + 13, Dungeons.fireflyLeaves, 0);
        this.setBlock(world, i + 12, j + 24, k + 14, Dungeons.fireflyLeaves, 0);
        this.setBlock(world, i + 12, j + 24, k + 15, Dungeons.fireflyLeaves, 0);
        this.setBlock(world, i + 12, j + 24, k + 16, Dungeons.fireflyLeaves, 0);
        this.setBlock(world, i + 12, j + 24, k + 17, Dungeons.fireflyLeaves, 0);
        this.setBlock(world, i + 12, j + 25, k + 13, Dungeons.fireflyLeaves, 0);
        this.setBlock(world, i + 12, j + 25, k + 14, Dungeons.fireflyLeaves, 0);
        this.setBlock(world, i + 12, j + 25, k + 15, Dungeons.fireflyLeaves, 0);
        this.setBlock(world, i + 12, j + 25, k + 22, Dungeons.fireflyLeaves, 0);
        this.setBlock(world, i + 12, j + 25, k + 23, Dungeons.fireflyLeaves, 0);
        this.setBlock(world, i + 12, j + 25, k + 24, Dungeons.fireflyLeaves, 0);
        this.setBlock(world, i + 12, j + 25, k + 25, Dungeons.fireflyLeaves, 0);
        this.setBlock(world, i + 12, j + 25, k + 26, Dungeons.fireflyLeaves, 0);
        this.setBlock(world, i + 12, j + 26, k + 23, Dungeons.fireflyLeaves, 0);
        this.setBlock(world, i + 12, j + 26, k + 24, Dungeons.fireflyLeaves, 0);
        this.setBlock(world, i + 13, j + 9, k + 26, Dungeons.fireflyLeaves, 0);
        this.setBlock(world, i + 13, j + 9, k + 27, Dungeons.fireflyLeaves, 0);
        this.setBlock(world, i + 13, j + 10, k + 23, Dungeons.fireflyLeaves, 0);
        this.setBlock(world, i + 13, j + 10, k + 24, Dungeons.fireflyLeaves, 0);
        this.setBlock(world, i + 13, j + 10, k + 25, Dungeons.fireflyLeaves, 0);
        this.setBlock(world, i + 13, j + 10, k + 26, Dungeons.fireflyLeaves, 0);
        this.setBlock(world, i + 13, j + 10, k + 27, Dungeons.fireflyLeaves, 0);
        this.setBlock(world, i + 13, j + 10, k + 28, Dungeons.fireflyLeaves, 0);
        this.setBlock(world, i + 13, j + 10, k + 29, Dungeons.fireflyLeaves, 0);
        this.setBlock(world, i + 13, j + 10, k + 30, Dungeons.fireflyLeaves, 0);
        this.setBlock(world, i + 13, j + 11, k + 15, Dungeons.fireflyLeaves, 0);
        this.setBlock(world, i + 13, j + 11, k + 28, Dungeons.fireflyLeaves, 0);
        this.setBlock(world, i + 13, j + 12, k + 13, Dungeons.fireflyLeaves, 0);
        this.setBlock(world, i + 13, j + 12, k + 14, Dungeons.fireflyLeaves, 0);
        this.setBlock(world, i + 13, j + 12, k + 15, Dungeons.fireflyLog, 0);
        this.setBlock(world, i + 13, j + 12, k + 16, Dungeons.fireflyLeaves, 0);
        this.setBlock(world, i + 13, j + 12, k + 17, Dungeons.fireflyLeaves, 0);
        this.setBlock(world, i + 13, j + 13, k + 15, Dungeons.fireflyLeaves, 0);
        this.setBlock(world, i + 13, j + 13, k + 16, Dungeons.fireflyLog, 0);
        this.setBlock(world, i + 13, j + 13, k + 17, Dungeons.fireflyLog, 0);
        this.setBlock(world, i + 13, j + 13, k + 19, Dungeons.fireflyLog, 0);
        this.setBlock(world, i + 13, j + 15, k + 22, Dungeons.fireflyLeaves, 0);
        this.setBlock(world, i + 13, j + 15, k + 23, Dungeons.fireflyLeaves, 0);
        this.setBlock(world, i + 13, j + 15, k + 24, Dungeons.fireflyLeaves, 0);
        this.setBlock(world, i + 13, j + 15, k + 25, Dungeons.fireflyLeaves, 0);
        this.setBlock(world, i + 13, j + 16, k + 12, Dungeons.fireflyLog, 0);
        this.setBlock(world, i + 13, j + 16, k + 18, Dungeons.fireflyLog, 0);
        this.setBlock(world, i + 13, j + 17, k + 6, Dungeons.fireflyLeaves, 0);
        this.setBlock(world, i + 13, j + 17, k + 7, Dungeons.fireflyLeaves, 0);
        this.setBlock(world, i + 13, j + 17, k + 17, Dungeons.fireflyLog, 0);
        this.setBlock(world, i + 13, j + 18, k + 7, Dungeons.fireflyLeaves, 0);
        this.setBlock(world, i + 13, j + 18, k + 8, Dungeons.fireflyLog, 0);
        this.setBlock(world, i + 13, j + 18, k + 9, Dungeons.fireflyLeaves, 0);
        this.setBlock(world, i + 13, j + 18, k + 11, Dungeons.fireflyLeaves, 0);
        this.setBlock(world, i + 13, j + 18, k + 16, Dungeons.fireflyLeaves, 0);
        this.setBlock(world, i + 13, j + 18, k + 17, Dungeons.fireflyLog, 0);
        this.setBlock(world, i + 13, j + 18, k + 18, Dungeons.fireflyLog, 0);
        this.setBlock(world, i + 13, j + 18, k + 19, Dungeons.fireflyLeaves, 0);
        this.setBlock(world, i + 13, j + 18, k + 20, Dungeons.fireflyLeaves, 0);
        this.setBlock(world, i + 13, j + 18, k + 21, Dungeons.fireflyLeaves, 0);
        this.setBlock(world, i + 13, j + 18, k + 22, Dungeons.fireflyLeaves, 0);
        this.setBlock(world, i + 13, j + 19, k + 8, Dungeons.fireflyLeaves, 0);
        this.setBlock(world, i + 13, j + 19, k + 17, Dungeons.fireflyLeaves, 0);
        this.setBlock(world, i + 13, j + 19, k + 18, Dungeons.fireflyLeaves, 0);
        this.setBlock(world, i + 13, j + 19, k + 19, Dungeons.fireflyLeaves, 0);
        this.setBlock(world, i + 13, j + 19, k + 20, Dungeons.fireflyLeaves, 0);
        this.setBlock(world, i + 13, j + 20, k + 14, Dungeons.fireflyLog, 0);
        this.setBlock(world, i + 13, j + 20, k + 18, Dungeons.fireflyLeaves, 0);
        this.setBlock(world, i + 13, j + 20, k + 22, Dungeons.fireflyLeaves, 0);
        this.setBlock(world, i + 13, j + 20, k + 23, Dungeons.fireflyLeaves, 0);
        this.setBlock(world, i + 13, j + 21, k + 20, Dungeons.fireflyLeaves, 0);
        this.setBlock(world, i + 13, j + 21, k + 21, Dungeons.fireflyLeaves, 0);
        this.setBlock(world, i + 13, j + 21, k + 22, Dungeons.fireflyLeaves, 0);
        this.setBlock(world, i + 13, j + 21, k + 23, Dungeons.fireflyLeaves, 0);
        this.setBlock(world, i + 13, j + 21, k + 24, Dungeons.fireflyLeaves, 0);
        this.setBlock(world, i + 13, j + 21, k + 25, Dungeons.fireflyLeaves, 0);
        this.setBlock(world, i + 13, j + 22, k + 19, Dungeons.fireflyLog, 0);
        this.setBlock(world, i + 13, j + 22, k + 20, Dungeons.fireflyLeaves, 0);
        this.setBlock(world, i + 13, j + 22, k + 21, Dungeons.fireflyLeaves, 0);
        this.setBlock(world, i + 13, j + 22, k + 22, Dungeons.fireflyLeaves, 0);
        this.setBlock(world, i + 13, j + 22, k + 23, Dungeons.fireflyLeaves, 0);
        this.setBlock(world, i + 13, j + 24, k + 12, Dungeons.fireflyLeaves, 0);
        this.setBlock(world, i + 13, j + 24, k + 13, Dungeons.fireflyLeaves, 0);
        this.setBlock(world, i + 13, j + 24, k + 14, Dungeons.fireflyLeaves, 0);
        this.setBlock(world, i + 13, j + 24, k + 15, Dungeons.fireflyLeaves, 0);
        this.setBlock(world, i + 13, j + 24, k + 16, Dungeons.fireflyLeaves, 0);
        this.setBlock(world, i + 13, j + 24, k + 26, Dungeons.fireflyLeaves, 0);
        this.setBlock(world, i + 13, j + 24, k + 27, Dungeons.fireflyLeaves, 0);
        this.setBlock(world, i + 13, j + 24, k + 28, Dungeons.fireflyLeaves, 0);
        this.setBlock(world, i + 13, j + 24, k + 29, Dungeons.fireflyLeaves, 0);
        this.setBlock(world, i + 13, j + 25, k + 14, Dungeons.fireflyLeaves, 0);
        this.setBlock(world, i + 13, j + 25, k + 23, Dungeons.fireflyLeaves, 0);
        this.setBlock(world, i + 13, j + 25, k + 24, Dungeons.fireflyLeaves, 0);
        this.setBlock(world, i + 14, j + 10, k + 24, Dungeons.fireflyLeaves, 0);
        this.setBlock(world, i + 14, j + 10, k + 25, Dungeons.fireflyLeaves, 0);
        this.setBlock(world, i + 14, j + 10, k + 26, Dungeons.fireflyLeaves, 0);
        this.setBlock(world, i + 14, j + 10, k + 27, Dungeons.fireflyLeaves, 0);
        this.setBlock(world, i + 14, j + 10, k + 28, Dungeons.fireflyLeaves, 0);
        this.setBlock(world, i + 14, j + 10, k + 29, Dungeons.fireflyLeaves, 0);
        this.setBlock(world, i + 14, j + 12, k + 14, Dungeons.fireflyLeaves, 0);
        this.setBlock(world, i + 14, j + 12, k + 15, Dungeons.fireflyLeaves, 0);
        this.setBlock(world, i + 14, j + 12, k + 16, Dungeons.fireflyLeaves, 0);
        this.setBlock(world, i + 14, j + 13, k + 17, Dungeons.fireflyLog, 0);
        this.setBlock(world, i + 14, j + 13, k + 18, Dungeons.fireflyLog, 0);
        this.setBlock(world, i + 14, j + 13, k + 19, Dungeons.fireflyLog, 0);
        this.setBlock(world, i + 14, j + 14, k + 19, Dungeons.fireflyLog, 0);
        this.setBlock(world, i + 14, j + 15, k + 19, Dungeons.fireflyLog, 0);
        this.setBlock(world, i + 14, j + 15, k + 23, Dungeons.fireflyLeaves, 0);
        this.setBlock(world, i + 14, j + 15, k + 24, Dungeons.fireflyLeaves, 0);
        this.setBlock(world, i + 14, j + 15, k + 25, Dungeons.fireflyLeaves, 0);
        this.setBlock(world, i + 14, j + 15, k + 26, Dungeons.fireflyLeaves, 0);
        this.setBlock(world, i + 14, j + 16, k + 12, Dungeons.fireflyLog, 0);
        this.setBlock(world, i + 14, j + 16, k + 19, Dungeons.fireflyLog, 0);
        this.setBlock(world, i + 14, j + 16, k + 24, Dungeons.fireflyLeaves, 0);
        this.setBlock(world, i + 14, j + 17, k + 9, Dungeons.fireflyLog, 0);
        this.setBlock(world, i + 14, j + 18, k + 8, Dungeons.fireflyLeaves, 0);
        this.setBlock(world, i + 14, j + 18, k + 13, Dungeons.fireflyLog, 0);
        this.setBlock(world, i + 14, j + 18, k + 16, Dungeons.fireflyLeaves, 0);
        this.setBlock(world, i + 14, j + 18, k + 17, Dungeons.fireflyLeaves, 0);
        this.setBlock(world, i + 14, j + 18, k + 18, Dungeons.fireflyLeaves, 0);
        this.setBlock(world, i + 14, j + 18, k + 19, Dungeons.fireflyLeaves, 0);
        this.setBlock(world, i + 14, j + 18, k + 20, Dungeons.fireflyLeaves, 0);
        this.setBlock(world, i + 14, j + 18, k + 21, Dungeons.fireflyLeaves, 0);
        this.setBlock(world, i + 14, j + 19, k + 13, Dungeons.fireflyLog, 0);
        this.setBlock(world, i + 14, j + 19, k + 18, Dungeons.fireflyLeaves, 0);
        this.setBlock(world, i + 14, j + 20, k + 4, Dungeons.fireflyLeaves, 0);
        this.setBlock(world, i + 14, j + 20, k + 14, Dungeons.fireflyLog, 0);
        this.setBlock(world, i + 14, j + 20, k + 21, Dungeons.fireflyLeaves, 0);
        this.setBlock(world, i + 14, j + 20, k + 22, Dungeons.fireflyLeaves, 0);
        this.setBlock(world, i + 14, j + 20, k + 23, Dungeons.fireflyLeaves, 0);
        this.setBlock(world, i + 14, j + 21, k + 19, Dungeons.fireflyLeaves, 0);
        this.setBlock(world, i + 14, j + 21, k + 20, Dungeons.fireflyLeaves, 0);
        this.setBlock(world, i + 14, j + 21, k + 21, Dungeons.fireflyLeaves, 0);
        this.setBlock(world, i + 14, j + 21, k + 22, Dungeons.fireflyLog, 0);
        this.setBlock(world, i + 14, j + 21, k + 23, Dungeons.fireflyLeaves, 0);
        this.setBlock(world, i + 14, j + 21, k + 24, Dungeons.fireflyLeaves, 0);
        this.setBlock(world, i + 14, j + 22, k + 18, Dungeons.fireflyLog, 0);
        this.setBlock(world, i + 14, j + 22, k + 19, Dungeons.fireflyLog, 0);
        this.setBlock(world, i + 14, j + 22, k + 20, Dungeons.fireflyLog, 0);
        this.setBlock(world, i + 14, j + 22, k + 21, Dungeons.fireflyLog, 0);
        this.setBlock(world, i + 14, j + 22, k + 22, Dungeons.fireflyLeaves, 0);
        this.setBlock(world, i + 14, j + 22, k + 23, Dungeons.fireflyLeaves, 0);
        this.setBlock(world, i + 14, j + 23, k + 21, Dungeons.fireflyLeaves, 0);
        this.setBlock(world, i + 14, j + 23, k + 22, Dungeons.fireflyLeaves, 0);
        this.setBlock(world, i + 14, j + 24, k + 13, Dungeons.fireflyLeaves, 0);
        this.setBlock(world, i + 14, j + 24, k + 14, Dungeons.fireflyLeaves, 0);
        this.setBlock(world, i + 14, j + 24, k + 15, Dungeons.fireflyLeaves, 0);
        this.setBlock(world, i + 14, j + 24, k + 25, Dungeons.fireflyLeaves, 0);
        this.setBlock(world, i + 14, j + 24, k + 26, Dungeons.fireflyLeaves, 0);
        this.setBlock(world, i + 14, j + 24, k + 27, Dungeons.fireflyLeaves, 0);
        this.setBlock(world, i + 14, j + 24, k + 28, Dungeons.fireflyLeaves, 0);
        this.setBlock(world, i + 14, j + 24, k + 29, Dungeons.fireflyLeaves, 0);
        this.setBlock(world, i + 14, j + 25, k + 16, Dungeons.fireflyLeaves, 0);
        this.setBlock(world, i + 14, j + 25, k + 17, Dungeons.fireflyLeaves, 0);
        this.setBlock(world, i + 14, j + 25, k + 18, Dungeons.fireflyLeaves, 0);
        this.setBlock(world, i + 14, j + 25, k + 19, Dungeons.fireflyLeaves, 0);
        this.setBlock(world, i + 14, j + 25, k + 27, Dungeons.fireflyLeaves, 0);
        this.setBlock(world, i + 15, j + 10, k + 25, Dungeons.fireflyLeaves, 0);
        this.setBlock(world, i + 15, j + 10, k + 26, Dungeons.fireflyLeaves, 0);
        this.setBlock(world, i + 15, j + 10, k + 27, Dungeons.fireflyLeaves, 0);
        this.setBlock(world, i + 15, j + 10, k + 28, Dungeons.fireflyLeaves, 0);
        this.setBlock(world, i + 15, j + 12, k + 15, Dungeons.fireflyLeaves, 0);
        this.setBlock(world, i + 15, j + 13, k + 18, Dungeons.fireflyLog, 0);
        this.setBlock(world, i + 15, j + 14, k + 23, Dungeons.fireflyLeaves, 0);
        this.setBlock(world, i + 15, j + 15, k + 22, Dungeons.fireflyLeaves, 0);
        this.setBlock(world, i + 15, j + 15, k + 23, Dungeons.fireflyLeaves, 0);
        this.setBlock(world, i + 15, j + 15, k + 24, Dungeons.fireflyLeaves, 0);
        this.setBlock(world, i + 15, j + 15, k + 25, Dungeons.fireflyLeaves, 0);
        this.setBlock(world, i + 15, j + 15, k + 26, Dungeons.fireflyLeaves, 0);
        this.setBlock(world, i + 15, j + 16, k + 10, Dungeons.fireflyLog, 0);
        this.setBlock(world, i + 15, j + 16, k + 11, Dungeons.fireflyLog, 0);
        this.setBlock(world, i + 15, j + 16, k + 12, Dungeons.fireflyLog, 0);
        this.setBlock(world, i + 15, j + 16, k + 23, Dungeons.fireflyLeaves, 0);
        this.setBlock(world, i + 15, j + 16, k + 24, Dungeons.fireflyLeaves, 0);
        this.setBlock(world, i + 15, j + 16, k + 25, Dungeons.fireflyLeaves, 0);
        this.setBlock(world, i + 15, j + 17, k + 7, Dungeons.fireflyLog, 0);
        this.setBlock(world, i + 15, j + 17, k + 8, Dungeons.fireflyLog, 0);
        this.setBlock(world, i + 15, j + 17, k + 9, Dungeons.fireflyLog, 0);
        this.setBlock(world, i + 15, j + 17, k + 10, Dungeons.fireflyLog, 0);
        this.setBlock(world, i + 15, j + 17, k + 12, Dungeons.fireflyLog, 0);
        this.setBlock(world, i + 15, j + 17, k + 13, Dungeons.fireflyLog, 0);
        this.setBlock(world, i + 15, j + 18, k + 17, Dungeons.fireflyLeaves, 0);
        this.setBlock(world, i + 15, j + 18, k + 18, Dungeons.fireflyLeaves, 0);
        this.setBlock(world, i + 15, j + 18, k + 19, Dungeons.fireflyLeaves, 0);
        this.setBlock(world, i + 15, j + 18, k + 20, Dungeons.fireflyLeaves, 0);
        this.setBlock(world, i + 15, j + 20, k + 3, Dungeons.fireflyLeaves, 0);
        this.setBlock(world, i + 15, j + 20, k + 4, Dungeons.fireflyLeaves, 0);
        this.setBlock(world, i + 15, j + 20, k + 5, Dungeons.fireflyLeaves, 0);
        this.setBlock(world, i + 15, j + 20, k + 6, Dungeons.fireflyLeaves, 0);
        this.setBlock(world, i + 15, j + 20, k + 7, Dungeons.fireflyLeaves, 0);
        this.setBlock(world, i + 15, j + 20, k + 22, Dungeons.fireflyLeaves, 0);
        this.setBlock(world, i + 15, j + 21, k + 19, Dungeons.fireflyLeaves, 0);
        this.setBlock(world, i + 15, j + 21, k + 20, Dungeons.fireflyLeaves, 0);
        this.setBlock(world, i + 15, j + 21, k + 21, Dungeons.fireflyLeaves, 0);
        this.setBlock(world, i + 15, j + 21, k + 22, Dungeons.fireflyLeaves, 0);
        this.setBlock(world, i + 15, j + 21, k + 23, Dungeons.fireflyLeaves, 0);
        this.setBlock(world, i + 15, j + 22, k + 18, Dungeons.fireflyLog, 0);
        this.setBlock(world, i + 15, j + 22, k + 20, Dungeons.fireflyLeaves, 0);
        this.setBlock(world, i + 15, j + 22, k + 21, Dungeons.fireflyLeaves, 0);
        this.setBlock(world, i + 15, j + 22, k + 22, Dungeons.fireflyLeaves, 0);
        this.setBlock(world, i + 15, j + 23, k + 27, Dungeons.fireflyLeaves, 0);
        this.setBlock(world, i + 15, j + 24, k + 24, Dungeons.fireflyLeaves, 0);
        this.setBlock(world, i + 15, j + 24, k + 25, Dungeons.fireflyLeaves, 0);
        this.setBlock(world, i + 15, j + 24, k + 26, Dungeons.fireflyLeaves, 0);
        this.setBlock(world, i + 15, j + 24, k + 27, Dungeons.fireflyLeaves, 0);
        this.setBlock(world, i + 15, j + 24, k + 28, Dungeons.fireflyLeaves, 0);
        this.setBlock(world, i + 15, j + 24, k + 29, Dungeons.fireflyLeaves, 0);
        this.setBlock(world, i + 15, j + 24, k + 30, Dungeons.fireflyLeaves, 0);
        this.setBlock(world, i + 15, j + 25, k + 16, Dungeons.fireflyLeaves, 0);
        this.setBlock(world, i + 15, j + 25, k + 17, Dungeons.fireflyLeaves, 0);
        this.setBlock(world, i + 15, j + 25, k + 18, Dungeons.fireflyLeaves, 0);
        this.setBlock(world, i + 15, j + 25, k + 19, Dungeons.fireflyLeaves, 0);
        this.setBlock(world, i + 15, j + 25, k + 20, Dungeons.fireflyLeaves, 0);
        this.setBlock(world, i + 15, j + 25, k + 26, Dungeons.fireflyLeaves, 0);
        this.setBlock(world, i + 15, j + 25, k + 27, Dungeons.fireflyLeaves, 0);
        this.setBlock(world, i + 15, j + 28, k + 8, Dungeons.fireflyLeaves, 0);
        this.setBlock(world, i + 15, j + 28, k + 9, Dungeons.fireflyLeaves, 0);
        this.setBlock(world, i + 15, j + 28, k + 10, Dungeons.fireflyLeaves, 0);
        this.setBlock(world, i + 15, j + 28, k + 11, Dungeons.fireflyLeaves, 0);
        this.setBlock(world, i + 16, j + 13, k + 17, Dungeons.fireflyLog, 0);
        this.setBlock(world, i + 16, j + 13, k + 18, Dungeons.fireflyLog, 0);
        this.setBlock(world, i + 16, j + 14, k + 22, Dungeons.fireflyLog, 0);
        this.setBlock(world, i + 16, j + 14, k + 23, Dungeons.fireflyLog, 0);
        this.setBlock(world, i + 16, j + 14, k + 24, Dungeons.fireflyLeaves, 0);
        this.setBlock(world, i + 16, j + 15, k + 21, Dungeons.fireflyLeaves, 0);
        this.setBlock(world, i + 16, j + 15, k + 22, Dungeons.fireflyLeaves, 0);
        this.setBlock(world, i + 16, j + 15, k + 23, Dungeons.fireflyLeaves, 0);
        this.setBlock(world, i + 16, j + 15, k + 24, Dungeons.fireflyLeaves, 0);
        this.setBlock(world, i + 16, j + 15, k + 25, Dungeons.fireflyLeaves, 0);
        this.setBlock(world, i + 16, j + 15, k + 26, Dungeons.fireflyLeaves, 0);
        this.setBlock(world, i + 16, j + 15, k + 27, Dungeons.fireflyLeaves, 0);
        this.setBlock(world, i + 16, j + 16, k + 11, Dungeons.fireflyLog, 0);
        this.setBlock(world, i + 16, j + 16, k + 12, Dungeons.fireflyLog, 0);
        this.setBlock(world, i + 16, j + 16, k + 23, Dungeons.fireflyLeaves, 0);
        this.setBlock(world, i + 16, j + 16, k + 24, Dungeons.fireflyLeaves, 0);
        this.setBlock(world, i + 16, j + 16, k + 25, Dungeons.fireflyLeaves, 0);
        this.setBlock(world, i + 16, j + 17, k + 7, Dungeons.fireflyLog, 0);
        this.setBlock(world, i + 16, j + 17, k + 8, Dungeons.fireflyLog, 0);
        this.setBlock(world, i + 16, j + 17, k + 23, Dungeons.fireflyLeaves, 0);
        this.setBlock(world, i + 16, j + 18, k + 7, Dungeons.fireflyLog, 0);
        this.setBlock(world, i + 16, j + 18, k + 8, Dungeons.fireflyLog, 0);
        this.setBlock(world, i + 16, j + 18, k + 17, Dungeons.fireflyLeaves, 0);
        this.setBlock(world, i + 16, j + 18, k + 18, Dungeons.fireflyLeaves, 0);
        this.setBlock(world, i + 16, j + 18, k + 19, Dungeons.fireflyLeaves, 0);
        this.setBlock(world, i + 16, j + 19, k + 5, Dungeons.fireflyLeaves, 0);
        this.setBlock(world, i + 16, j + 20, k + 2, Dungeons.fireflyLeaves, 0);
        this.setBlock(world, i + 16, j + 20, k + 3, Dungeons.fireflyLeaves, 0);
        this.setBlock(world, i + 16, j + 20, k + 4, Dungeons.fireflyLeaves, 0);
        this.setBlock(world, i + 16, j + 20, k + 5, Dungeons.fireflyLeaves, 0);
        this.setBlock(world, i + 16, j + 20, k + 6, Dungeons.fireflyLeaves, 0);
        this.setBlock(world, i + 16, j + 20, k + 7, Dungeons.fireflyLeaves, 0);
        this.setBlock(world, i + 16, j + 20, k + 8, Dungeons.fireflyLeaves, 0);
        this.setBlock(world, i + 16, j + 20, k + 9, Dungeons.fireflyLeaves, 0);
        this.setBlock(world, i + 16, j + 21, k + 18, Dungeons.fireflyLog, 0);
        this.setBlock(world, i + 16, j + 21, k + 19, Dungeons.fireflyLeaves, 0);
        this.setBlock(world, i + 16, j + 21, k + 20, Dungeons.fireflyLeaves, 0);
        this.setBlock(world, i + 16, j + 21, k + 21, Dungeons.fireflyLeaves, 0);
        this.setBlock(world, i + 16, j + 21, k + 22, Dungeons.fireflyLeaves, 0);
        this.setBlock(world, i + 16, j + 22, k + 21, Dungeons.fireflyLeaves, 0);
        this.setBlock(world, i + 16, j + 22, k + 22, Dungeons.fireflyLeaves, 0);
        this.setBlock(world, i + 16, j + 22, k + 27, Dungeons.fireflyLeaves, 0);
        this.setBlock(world, i + 16, j + 23, k + 26, Dungeons.fireflyLeaves, 0);
        this.setBlock(world, i + 16, j + 23, k + 27, Dungeons.fireflyLog, 0);
        this.setBlock(world, i + 16, j + 23, k + 28, Dungeons.fireflyLeaves, 0);
        this.setBlock(world, i + 16, j + 24, k + 17, Dungeons.fireflyLeaves, 0);
        this.setBlock(world, i + 16, j + 24, k + 18, Dungeons.fireflyLeaves, 0);
        this.setBlock(world, i + 16, j + 24, k + 19, Dungeons.fireflyLeaves, 0);
        this.setBlock(world, i + 16, j + 24, k + 24, Dungeons.fireflyLeaves, 0);
        this.setBlock(world, i + 16, j + 24, k + 25, Dungeons.fireflyLeaves, 0);
        this.setBlock(world, i + 16, j + 24, k + 26, Dungeons.fireflyLeaves, 0);
        this.setBlock(world, i + 16, j + 24, k + 27, Dungeons.fireflyLeaves, 0);
        this.setBlock(world, i + 16, j + 24, k + 28, Dungeons.fireflyLeaves, 0);
        this.setBlock(world, i + 16, j + 24, k + 29, Dungeons.fireflyLeaves, 0);
        this.setBlock(world, i + 16, j + 24, k + 30, Dungeons.fireflyLeaves, 0);
        this.setBlock(world, i + 16, j + 25, k + 15, Dungeons.fireflyLeaves, 0);
        this.setBlock(world, i + 16, j + 25, k + 16, Dungeons.fireflyLeaves, 0);
        this.setBlock(world, i + 16, j + 25, k + 17, Dungeons.fireflyLeaves, 0);
        this.setBlock(world, i + 16, j + 25, k + 18, Dungeons.fireflyLeaves, 0);
        this.setBlock(world, i + 16, j + 25, k + 19, Dungeons.fireflyLeaves, 0);
        this.setBlock(world, i + 16, j + 25, k + 20, Dungeons.fireflyLeaves, 0);
        this.setBlock(world, i + 16, j + 25, k + 21, Dungeons.fireflyLeaves, 0);
        this.setBlock(world, i + 16, j + 25, k + 25, Dungeons.fireflyLeaves, 0);
        this.setBlock(world, i + 16, j + 25, k + 26, Dungeons.fireflyLeaves, 0);
        this.setBlock(world, i + 16, j + 25, k + 27, Dungeons.fireflyLeaves, 0);
        this.setBlock(world, i + 16, j + 25, k + 28, Dungeons.fireflyLeaves, 0);
        this.setBlock(world, i + 16, j + 26, k + 17, Dungeons.fireflyLeaves, 0);
        this.setBlock(world, i + 16, j + 26, k + 18, Dungeons.fireflyLeaves, 0);
        this.setBlock(world, i + 16, j + 26, k + 19, Dungeons.fireflyLeaves, 0);
        this.setBlock(world, i + 16, j + 26, k + 26, Dungeons.fireflyLeaves, 0);
        this.setBlock(world, i + 16, j + 28, k + 7, Dungeons.fireflyLeaves, 0);
        this.setBlock(world, i + 16, j + 28, k + 8, Dungeons.fireflyLeaves, 0);
        this.setBlock(world, i + 16, j + 28, k + 9, Dungeons.fireflyLeaves, 0);
        this.setBlock(world, i + 16, j + 28, k + 10, Dungeons.fireflyLeaves, 0);
        this.setBlock(world, i + 16, j + 28, k + 11, Dungeons.fireflyLeaves, 0);
        this.setBlock(world, i + 16, j + 28, k + 12, Dungeons.fireflyLeaves, 0);
        this.setBlock(world, i + 17, j + 13, k + 17, Dungeons.fireflyLog, 0);
        this.setBlock(world, i + 17, j + 14, k + 13, Dungeons.fireflyLog, 0);
        this.setBlock(world, i + 17, j + 14, k + 21, Dungeons.fireflyLog, 0);
        this.setBlock(world, i + 17, j + 14, k + 23, Dungeons.fireflyLeaves, 0);
        this.setBlock(world, i + 17, j + 15, k + 12, Dungeons.fireflyLog, 0);
        this.setBlock(world, i + 17, j + 15, k + 13, Dungeons.fireflyLog, 0);
        this.setBlock(world, i + 17, j + 15, k + 21, Dungeons.fireflyLeaves, 0);
        this.setBlock(world, i + 17, j + 15, k + 22, Dungeons.fireflyLeaves, 0);
        this.setBlock(world, i + 17, j + 15, k + 23, Dungeons.fireflyLeaves, 0);
        this.setBlock(world, i + 17, j + 15, k + 24, Dungeons.fireflyLeaves, 0);
        this.setBlock(world, i + 17, j + 15, k + 25, Dungeons.fireflyLeaves, 0);
        this.setBlock(world, i + 17, j + 15, k + 26, Dungeons.fireflyLeaves, 0);
        this.setBlock(world, i + 17, j + 15, k + 27, Dungeons.fireflyLeaves, 0);
        this.setBlock(world, i + 17, j + 16, k + 12, Dungeons.fireflyLog, 0);
        this.setBlock(world, i + 17, j + 16, k + 23, Dungeons.fireflyLeaves, 0);
        this.setBlock(world, i + 17, j + 16, k + 24, Dungeons.fireflyLeaves, 0);
        this.setBlock(world, i + 17, j + 16, k + 25, Dungeons.fireflyLeaves, 0);
        this.setBlock(world, i + 17, j + 16, k + 26, Dungeons.fireflyLeaves, 0);
        this.setBlock(world, i + 17, j + 18, k + 6, Dungeons.fireflyLog, 0);
        this.setBlock(world, i + 17, j + 18, k + 7, Dungeons.fireflyLog, 0);
        this.setBlock(world, i + 17, j + 19, k + 4, Dungeons.fireflyLeaves, 0);
        this.setBlock(world, i + 17, j + 19, k + 5, Dungeons.fireflyLog, 0);
        this.setBlock(world, i + 17, j + 19, k + 6, Dungeons.fireflyLog, 0);
        this.setBlock(world, i + 17, j + 20, k + 1, Dungeons.fireflyLeaves, 0);
        this.setBlock(world, i + 17, j + 20, k + 2, Dungeons.fireflyLeaves, 0);
        this.setBlock(world, i + 17, j + 20, k + 3, Dungeons.fireflyLeaves, 0);
        this.setBlock(world, i + 17, j + 20, k + 4, Dungeons.fireflyLeaves, 0);
        this.setBlock(world, i + 17, j + 20, k + 5, Dungeons.fireflyLeaves, 0);
        this.setBlock(world, i + 17, j + 20, k + 6, Dungeons.fireflyLeaves, 0);
        this.setBlock(world, i + 17, j + 20, k + 7, Dungeons.fireflyLeaves, 0);
        this.setBlock(world, i + 17, j + 20, k + 8, Dungeons.fireflyLeaves, 0);
        this.setBlock(world, i + 17, j + 20, k + 9, Dungeons.fireflyLeaves, 0);
        this.setBlock(world, i + 17, j + 20, k + 10, Dungeons.fireflyLeaves, 0);
        this.setBlock(world, i + 17, j + 20, k + 11, Dungeons.fireflyLeaves, 0);
        this.setBlock(world, i + 17, j + 21, k + 3, Dungeons.fireflyLeaves, 0);
        this.setBlock(world, i + 17, j + 21, k + 4, Dungeons.fireflyLeaves, 0);
        this.setBlock(world, i + 17, j + 21, k + 5, Dungeons.fireflyLeaves, 0);
        this.setBlock(world, i + 17, j + 21, k + 6, Dungeons.fireflyLeaves, 0);
        this.setBlock(world, i + 17, j + 21, k + 7, Dungeons.fireflyLeaves, 0);
        this.setBlock(world, i + 17, j + 21, k + 8, Dungeons.fireflyLeaves, 0);
        this.setBlock(world, i + 17, j + 21, k + 17, Dungeons.fireflyLog, 0);
        this.setBlock(world, i + 17, j + 21, k + 18, Dungeons.fireflyLog, 0);
        this.setBlock(world, i + 17, j + 21, k + 20, Dungeons.fireflyLeaves, 0);
        this.setBlock(world, i + 17, j + 21, k + 21, Dungeons.fireflyLeaves, 0);
        this.setBlock(world, i + 17, j + 22, k + 4, Dungeons.fireflyLeaves, 0);
        this.setBlock(world, i + 17, j + 22, k + 17, Dungeons.fireflyLog, 0);
        this.setBlock(world, i + 17, j + 22, k + 24, Dungeons.fireflyLog, 0);
        this.setBlock(world, i + 17, j + 23, k + 17, Dungeons.fireflyLog, 0);
        this.setBlock(world, i + 17, j + 23, k + 25, Dungeons.fireflyLog, 0);
        this.setBlock(world, i + 17, j + 23, k + 26, Dungeons.fireflyLog, 0);
        this.setBlock(world, i + 17, j + 23, k + 27, Dungeons.fireflyLeaves, 0);
        this.setBlock(world, i + 17, j + 24, k + 17, Dungeons.fireflyLog, 0);
        this.setBlock(world, i + 17, j + 24, k + 18, Dungeons.fireflyLeaves, 0);
        this.setBlock(world, i + 17, j + 24, k + 19, Dungeons.fireflyLeaves, 0);
        this.setBlock(world, i + 17, j + 24, k + 24, Dungeons.fireflyLeaves, 0);
        this.setBlock(world, i + 17, j + 24, k + 25, Dungeons.fireflyLeaves, 0);
        this.setBlock(world, i + 17, j + 24, k + 26, Dungeons.fireflyLeaves, 0);
        this.setBlock(world, i + 17, j + 24, k + 27, Dungeons.fireflyLeaves, 0);
        this.setBlock(world, i + 17, j + 24, k + 28, Dungeons.fireflyLeaves, 0);
        this.setBlock(world, i + 17, j + 24, k + 29, Dungeons.fireflyLeaves, 0);
        this.setBlock(world, i + 17, j + 24, k + 30, Dungeons.fireflyLeaves, 0);
        this.setBlock(world, i + 17, j + 25, k + 12, Dungeons.fireflyLeaves, 0);
        this.setBlock(world, i + 17, j + 25, k + 13, Dungeons.fireflyLeaves, 0);
        this.setBlock(world, i + 17, j + 25, k + 14, Dungeons.fireflyLeaves, 0);
        this.setBlock(world, i + 17, j + 25, k + 15, Dungeons.fireflyLeaves, 0);
        this.setBlock(world, i + 17, j + 25, k + 16, Dungeons.fireflyLeaves, 0);
        this.setBlock(world, i + 17, j + 25, k + 17, Dungeons.fireflyLeaves, 0);
        this.setBlock(world, i + 17, j + 25, k + 18, Dungeons.fireflyLeaves, 0);
        this.setBlock(world, i + 17, j + 25, k + 19, Dungeons.fireflyLeaves, 0);
        this.setBlock(world, i + 17, j + 25, k + 20, Dungeons.fireflyLeaves, 0);
        this.setBlock(world, i + 17, j + 25, k + 21, Dungeons.fireflyLeaves, 0);
        this.setBlock(world, i + 17, j + 25, k + 26, Dungeons.fireflyLeaves, 0);
        this.setBlock(world, i + 17, j + 25, k + 27, Dungeons.fireflyLeaves, 0);
        this.setBlock(world, i + 17, j + 25, k + 28, Dungeons.fireflyLeaves, 0);
        this.setBlock(world, i + 17, j + 26, k + 17, Dungeons.fireflyLeaves, 0);
        this.setBlock(world, i + 17, j + 26, k + 18, Dungeons.fireflyLeaves, 0);
        this.setBlock(world, i + 17, j + 26, k + 19, Dungeons.fireflyLeaves, 0);
        this.setBlock(world, i + 17, j + 26, k + 20, Dungeons.fireflyLeaves, 0);
        this.setBlock(world, i + 17, j + 27, k + 10, Dungeons.fireflyLeaves, 0);
        this.setBlock(world, i + 17, j + 27, k + 18, Dungeons.fireflyLeaves, 0);
        this.setBlock(world, i + 17, j + 28, k + 7, Dungeons.fireflyLeaves, 0);
        this.setBlock(world, i + 17, j + 28, k + 8, Dungeons.fireflyLeaves, 0);
        this.setBlock(world, i + 17, j + 28, k + 9, Dungeons.fireflyLeaves, 0);
        this.setBlock(world, i + 17, j + 28, k + 10, Dungeons.fireflyLeaves, 0);
        this.setBlock(world, i + 17, j + 28, k + 11, Dungeons.fireflyLeaves, 0);
        this.setBlock(world, i + 17, j + 28, k + 12, Dungeons.fireflyLeaves, 0);
        this.setBlock(world, i + 17, j + 28, k + 13, Dungeons.fireflyLeaves, 0);
        this.setBlock(world, i + 17, j + 29, k + 9, Dungeons.fireflyLeaves, 0);
        this.setBlock(world, i + 17, j + 29, k + 10, Dungeons.fireflyLeaves, 0);
        this.setBlock(world, i + 17, j + 29, k + 11, Dungeons.fireflyLeaves, 0);
        this.setBlock(world, i + 18, j + 12, k + 15, Dungeons.fireflyLeaves, 0);
        this.setBlock(world, i + 18, j + 12, k + 16, Dungeons.fireflyLeaves, 0);
        this.setBlock(world, i + 18, j + 12, k + 17, Dungeons.fireflyLeaves, 0);
        this.setBlock(world, i + 18, j + 12, k + 18, Dungeons.fireflyLeaves, 0);
        this.setBlock(world, i + 18, j + 13, k + 14, Dungeons.fireflyLog, 0);
        this.setBlock(world, i + 18, j + 13, k + 16, Dungeons.fireflyLog, 0);
        this.setBlock(world, i + 18, j + 14, k + 13, Dungeons.fireflyLog, 0);
        this.setBlock(world, i + 18, j + 14, k + 14, Dungeons.fireflyLog, 0);
        this.setBlock(world, i + 18, j + 14, k + 16, Dungeons.fireflyLog, 0);
        this.setBlock(world, i + 18, j + 14, k + 17, Dungeons.fireflyLog, 0);
        this.setBlock(world, i + 18, j + 14, k + 20, Dungeons.fireflyLog, 0);
        this.setBlock(world, i + 18, j + 14, k + 21, Dungeons.fireflyLog, 0);
        this.setBlock(world, i + 18, j + 15, k + 22, Dungeons.fireflyLeaves, 0);
        this.setBlock(world, i + 18, j + 15, k + 23, Dungeons.fireflyLeaves, 0);
        this.setBlock(world, i + 18, j + 15, k + 24, Dungeons.fireflyLeaves, 0);
        this.setBlock(world, i + 18, j + 15, k + 25, Dungeons.fireflyLeaves, 0);
        this.setBlock(world, i + 18, j + 15, k + 26, Dungeons.fireflyLeaves, 0);
        this.setBlock(world, i + 18, j + 16, k + 23, Dungeons.fireflyLeaves, 0);
        this.setBlock(world, i + 18, j + 16, k + 24, Dungeons.fireflyLeaves, 0);
        this.setBlock(world, i + 18, j + 16, k + 25, Dungeons.fireflyLeaves, 0);
        this.setBlock(world, i + 18, j + 19, k + 4, Dungeons.fireflyLeaves, 0);
        this.setBlock(world, i + 18, j + 19, k + 5, Dungeons.fireflyLeaves, 0);
        this.setBlock(world, i + 18, j + 19, k + 6, Dungeons.fireflyLeaves, 0);
        this.setBlock(world, i + 18, j + 19, k + 7, Dungeons.fireflyLeaves, 0);
        this.setBlock(world, i + 18, j + 20, k + 2, Dungeons.fireflyLeaves, 0);
        this.setBlock(world, i + 18, j + 20, k + 3, Dungeons.fireflyLeaves, 0);
        this.setBlock(world, i + 18, j + 20, k + 4, Dungeons.fireflyLeaves, 0);
        this.setBlock(world, i + 18, j + 20, k + 5, Dungeons.fireflyLeaves, 0);
        this.setBlock(world, i + 18, j + 20, k + 6, Dungeons.fireflyLeaves, 0);
        this.setBlock(world, i + 18, j + 20, k + 7, Dungeons.fireflyLeaves, 0);
        this.setBlock(world, i + 18, j + 20, k + 8, Dungeons.fireflyLeaves, 0);
        this.setBlock(world, i + 18, j + 20, k + 9, Dungeons.fireflyLeaves, 0);
        this.setBlock(world, i + 18, j + 20, k + 10, Dungeons.fireflyLeaves, 0);
        this.setBlock(world, i + 18, j + 20, k + 17, Dungeons.fireflyLog, 0);
        this.setBlock(world, i + 18, j + 21, k + 3, Dungeons.fireflyLeaves, 0);
        this.setBlock(world, i + 18, j + 21, k + 4, Dungeons.fireflyLeaves, 0);
        this.setBlock(world, i + 18, j + 21, k + 5, Dungeons.fireflyLeaves, 0);
        this.setBlock(world, i + 18, j + 21, k + 6, Dungeons.fireflyLeaves, 0);
        this.setBlock(world, i + 18, j + 21, k + 7, Dungeons.fireflyLeaves, 0);
        this.setBlock(world, i + 18, j + 21, k + 21, Dungeons.fireflyLog, 0);
        this.setBlock(world, i + 18, j + 21, k + 22, Dungeons.fireflyLog, 0);
        this.setBlock(world, i + 18, j + 21, k + 23, Dungeons.fireflyLog, 0);
        this.setBlock(world, i + 18, j + 22, k + 5, Dungeons.fireflyLeaves, 0);
        this.setBlock(world, i + 18, j + 22, k + 24, Dungeons.fireflyLog, 0);
        this.setBlock(world, i + 18, j + 23, k + 27, Dungeons.fireflyLeaves, 0);
        this.setBlock(world, i + 18, j + 24, k + 15, Dungeons.fireflyLeaves, 0);
        this.setBlock(world, i + 18, j + 24, k + 17, Dungeons.fireflyLeaves, 0);
        this.setBlock(world, i + 18, j + 24, k + 18, Dungeons.fireflyLeaves, 0);
        this.setBlock(world, i + 18, j + 24, k + 25, Dungeons.fireflyLeaves, 0);
        this.setBlock(world, i + 18, j + 24, k + 26, Dungeons.fireflyLeaves, 0);
        this.setBlock(world, i + 18, j + 24, k + 27, Dungeons.fireflyLeaves, 0);
        this.setBlock(world, i + 18, j + 24, k + 28, Dungeons.fireflyLeaves, 0);
        this.setBlock(world, i + 18, j + 24, k + 29, Dungeons.fireflyLeaves, 0);
        this.setBlock(world, i + 18, j + 25, k + 11, Dungeons.fireflyLeaves, 0);
        this.setBlock(world, i + 18, j + 25, k + 12, Dungeons.fireflyLeaves, 0);
        this.setBlock(world, i + 18, j + 25, k + 13, Dungeons.fireflyLeaves, 0);
        this.setBlock(world, i + 18, j + 25, k + 14, Dungeons.fireflyLeaves, 0);
        this.setBlock(world, i + 18, j + 25, k + 15, Dungeons.fireflyLeaves, 0);
        this.setBlock(world, i + 18, j + 25, k + 16, Dungeons.fireflyLeaves, 0);
        this.setBlock(world, i + 18, j + 25, k + 17, Dungeons.fireflyLeaves, 0);
        this.setBlock(world, i + 18, j + 25, k + 18, Dungeons.fireflyLeaves, 0);
        this.setBlock(world, i + 18, j + 25, k + 19, Dungeons.fireflyLeaves, 0);
        this.setBlock(world, i + 18, j + 25, k + 20, Dungeons.fireflyLeaves, 0);
        this.setBlock(world, i + 18, j + 25, k + 21, Dungeons.fireflyLeaves, 0);
        this.setBlock(world, i + 18, j + 25, k + 27, Dungeons.fireflyLeaves, 0);
        this.setBlock(world, i + 18, j + 26, k + 10, Dungeons.fireflyLog, 0);
        this.setBlock(world, i + 18, j + 26, k + 14, Dungeons.fireflyLeaves, 0);
        this.setBlock(world, i + 18, j + 26, k + 15, Dungeons.fireflyLeaves, 0);
        this.setBlock(world, i + 18, j + 26, k + 18, Dungeons.fireflyLeaves, 0);
        this.setBlock(world, i + 18, j + 26, k + 19, Dungeons.fireflyLeaves, 0);
        this.setBlock(world, i + 18, j + 27, k + 9, Dungeons.fireflyLeaves, 0);
        this.setBlock(world, i + 18, j + 27, k + 10, Dungeons.fireflyLog, 0);
        this.setBlock(world, i + 18, j + 27, k + 11, Dungeons.fireflyLeaves, 0);
        this.setBlock(world, i + 18, j + 28, k + 7, Dungeons.fireflyLeaves, 0);
        this.setBlock(world, i + 18, j + 28, k + 8, Dungeons.fireflyLeaves, 0);
        this.setBlock(world, i + 18, j + 28, k + 9, Dungeons.fireflyLeaves, 0);
        this.setBlock(world, i + 18, j + 28, k + 10, Dungeons.fireflyLeaves, 0);
        this.setBlock(world, i + 18, j + 28, k + 11, Dungeons.fireflyLeaves, 0);
        this.setBlock(world, i + 18, j + 28, k + 12, Dungeons.fireflyLeaves, 0);
        this.setBlock(world, i + 18, j + 28, k + 13, Dungeons.fireflyLeaves, 0);
        this.setBlock(world, i + 18, j + 29, k + 8, Dungeons.fireflyLeaves, 0);
        this.setBlock(world, i + 18, j + 29, k + 9, Dungeons.fireflyLeaves, 0);
        this.setBlock(world, i + 18, j + 29, k + 10, Dungeons.fireflyLeaves, 0);
        this.setBlock(world, i + 18, j + 29, k + 11, Dungeons.fireflyLeaves, 0);
        this.setBlock(world, i + 18, j + 29, k + 20, Dungeons.fireflyLeaves, 0);
        this.setBlock(world, i + 18, j + 29, k + 21, Dungeons.fireflyLeaves, 0);
        this.setBlock(world, i + 18, j + 30, k + 10, Dungeons.fireflyLeaves, 0);
        this.setBlock(world, i + 19, j + 0, k + 15, Dungeons.fireflyLog, 0);
        this.setBlock(world, i + 19, j + 0, k + 16, Dungeons.fireflyLog, 0);
        this.setBlock(world, i + 19, j + 1, k + 15, Dungeons.fireflyLog, 0);
        this.setBlock(world, i + 19, j + 1, k + 16, Dungeons.fireflyLog, 0);
        this.setBlock(world, i + 19, j + 2, k + 15, Dungeons.fireflyLog, 0);
        this.setBlock(world, i + 19, j + 2, k + 16, Dungeons.fireflyLog, 0);
        this.setBlock(world, i + 19, j + 3, k + 15, Dungeons.fireflyLog, 0);
        this.setBlock(world, i + 19, j + 3, k + 16, Dungeons.fireflyLog, 0);
        this.setBlock(world, i + 19, j + 4, k + 15, Dungeons.fireflyLog, 0);
        this.setBlock(world, i + 19, j + 4, k + 16, Dungeons.fireflyLog, 0);
        this.setBlock(world, i + 19, j + 5, k + 15, Dungeons.fireflyLog, 0);
        this.setBlock(world, i + 19, j + 5, k + 16, Dungeons.fireflyLog, 0);
        this.setBlock(world, i + 19, j + 6, k + 15, Dungeons.fireflyLog, 0);
        this.setBlock(world, i + 19, j + 6, k + 16, Dungeons.fireflyLog, 0);
        this.setBlock(world, i + 19, j + 7, k + 15, Dungeons.fireflyLog, 0);
        this.setBlock(world, i + 19, j + 7, k + 16, Dungeons.fireflyLog, 0);
        this.setBlock(world, i + 19, j + 8, k + 15, Dungeons.fireflyLog, 0);
        this.setBlock(world, i + 19, j + 8, k + 16, Dungeons.fireflyLog, 0);
        this.setBlock(world, i + 19, j + 9, k + 15, Dungeons.fireflyLog, 0);
        this.setBlock(world, i + 19, j + 9, k + 16, Dungeons.fireflyLog, 0);
        this.setBlock(world, i + 19, j + 10, k + 15, Dungeons.fireflyLog, 0);
        this.setBlock(world, i + 19, j + 10, k + 16, Dungeons.fireflyLog, 0);
        this.setBlock(world, i + 19, j + 11, k + 15, Dungeons.fireflyLog, 0);
        this.setBlock(world, i + 19, j + 11, k + 16, Dungeons.fireflyLog, 0);
        this.setBlock(world, i + 19, j + 12, k + 15, Dungeons.fireflyLog, 0);
        this.setBlock(world, i + 19, j + 12, k + 16, Dungeons.fireflyLog, 0);
        this.setBlock(world, i + 19, j + 12, k + 17, Dungeons.fireflyLeaves, 0);
        this.setBlock(world, i + 19, j + 12, k + 18, Dungeons.fireflyLeaves, 0);
        this.setBlock(world, i + 19, j + 12, k + 19, Dungeons.fireflyLeaves, 0);
        this.setBlock(world, i + 19, j + 13, k + 14, Dungeons.fireflyLog, 0);
        this.setBlock(world, i + 19, j + 13, k + 15, Dungeons.fireflyLog, 0);
        this.setBlock(world, i + 19, j + 13, k + 16, Dungeons.fireflyLog, 0);
        this.setBlock(world, i + 19, j + 14, k + 15, Dungeons.fireflyLog, 0);
        this.setBlock(world, i + 19, j + 14, k + 16, Dungeons.fireflyLog, 0);
        this.setBlock(world, i + 19, j + 14, k + 17, Dungeons.fireflyLog, 0);
        this.setBlock(world, i + 19, j + 14, k + 18, Dungeons.fireflyLog, 0);
        this.setBlock(world, i + 19, j + 14, k + 19, Dungeons.fireflyLog, 0);
        this.setBlock(world, i + 19, j + 14, k + 20, Dungeons.fireflyLog, 0);
        this.setBlock(world, i + 19, j + 14, k + 21, Dungeons.fireflyLog, 0);
        this.setBlock(world, i + 19, j + 14, k + 24, Dungeons.fireflyLeaves, 0);
        this.setBlock(world, i + 19, j + 15, k + 23, Dungeons.fireflyLeaves, 0);
        this.setBlock(world, i + 19, j + 15, k + 24, Dungeons.fireflyLeaves, 0);
        this.setBlock(world, i + 19, j + 15, k + 25, Dungeons.fireflyLeaves, 0);
        this.setBlock(world, i + 19, j + 15, k + 26, Dungeons.fireflyLeaves, 0);
        this.setBlock(world, i + 19, j + 15, k + 27, Dungeons.fireflyLeaves, 0);
        this.setBlock(world, i + 19, j + 19, k + 5, Dungeons.fireflyLeaves, 0);
        this.setBlock(world, i + 19, j + 19, k + 6, Dungeons.fireflyLeaves, 0);
        this.setBlock(world, i + 19, j + 20, k + 2, Dungeons.fireflyLeaves, 0);
        this.setBlock(world, i + 19, j + 20, k + 3, Dungeons.fireflyLeaves, 0);
        this.setBlock(world, i + 19, j + 20, k + 4, Dungeons.fireflyLeaves, 0);
        this.setBlock(world, i + 19, j + 20, k + 5, Dungeons.fireflyLeaves, 0);
        this.setBlock(world, i + 19, j + 20, k + 6, Dungeons.fireflyLeaves, 0);
        this.setBlock(world, i + 19, j + 20, k + 7, Dungeons.fireflyLeaves, 0);
        this.setBlock(world, i + 19, j + 20, k + 8, Dungeons.fireflyLeaves, 0);
        this.setBlock(world, i + 19, j + 20, k + 9, Dungeons.fireflyLeaves, 0);
        this.setBlock(world, i + 19, j + 20, k + 16, Dungeons.fireflyLog, 0);
        this.setBlock(world, i + 19, j + 20, k + 17, Dungeons.fireflyLog, 0);
        this.setBlock(world, i + 19, j + 20, k + 18, Dungeons.fireflyLog, 0);
        this.setBlock(world, i + 19, j + 20, k + 19, Dungeons.fireflyLog, 0);
        this.setBlock(world, i + 19, j + 21, k + 4, Dungeons.fireflyLeaves, 0);
        this.setBlock(world, i + 19, j + 21, k + 5, Dungeons.fireflyLeaves, 0);
        this.setBlock(world, i + 19, j + 21, k + 6, Dungeons.fireflyLeaves, 0);
        this.setBlock(world, i + 19, j + 21, k + 7, Dungeons.fireflyLeaves, 0);
        this.setBlock(world, i + 19, j + 21, k + 15, Dungeons.fireflyLog, 0);
        this.setBlock(world, i + 19, j + 21, k + 16, Dungeons.fireflyLog, 0);
        this.setBlock(world, i + 19, j + 21, k + 19, Dungeons.fireflyLog, 0);
        this.setBlock(world, i + 19, j + 21, k + 20, Dungeons.fireflyLog, 0);
        this.setBlock(world, i + 19, j + 22, k + 15, Dungeons.fireflyLog, 0);
        this.setBlock(world, i + 19, j + 22, k + 22, Dungeons.fireflyLeaves, 0);
        this.setBlock(world, i + 19, j + 23, k + 15, Dungeons.fireflyLog, 0);
        this.setBlock(world, i + 19, j + 24, k + 14, Dungeons.fireflyLeaves, 0);
        this.setBlock(world, i + 19, j + 24, k + 15, Dungeons.fireflyLog, 0);
        this.setBlock(world, i + 19, j + 24, k + 16, Dungeons.fireflyLeaves, 0);
        this.setBlock(world, i + 19, j + 24, k + 26, Dungeons.fireflyLeaves, 0);
        this.setBlock(world, i + 19, j + 24, k + 27, Dungeons.fireflyLeaves, 0);
        this.setBlock(world, i + 19, j + 24, k + 28, Dungeons.fireflyLeaves, 0);
        this.setBlock(world, i + 19, j + 25, k + 10, Dungeons.fireflyLog, 0);
        this.setBlock(world, i + 19, j + 25, k + 11, Dungeons.fireflyLeaves, 0);
        this.setBlock(world, i + 19, j + 25, k + 12, Dungeons.fireflyLeaves, 0);
        this.setBlock(world, i + 19, j + 25, k + 13, Dungeons.fireflyLeaves, 0);
        this.setBlock(world, i + 19, j + 25, k + 14, Dungeons.fireflyLog, 0);
        this.setBlock(world, i + 19, j + 25, k + 15, Dungeons.fireflyLeaves, 0);
        this.setBlock(world, i + 19, j + 25, k + 16, Dungeons.fireflyLeaves, 0);
        this.setBlock(world, i + 19, j + 25, k + 17, Dungeons.fireflyLeaves, 0);
        this.setBlock(world, i + 19, j + 25, k + 18, Dungeons.fireflyLeaves, 0);
        this.setBlock(world, i + 19, j + 25, k + 19, Dungeons.fireflyLeaves, 0);
        this.setBlock(world, i + 19, j + 25, k + 20, Dungeons.fireflyLeaves, 0);
        this.setBlock(world, i + 19, j + 26, k + 13, Dungeons.fireflyLeaves, 0);
        this.setBlock(world, i + 19, j + 26, k + 14, Dungeons.fireflyLeaves, 0);
        this.setBlock(world, i + 19, j + 26, k + 15, Dungeons.fireflyLeaves, 0);
        this.setBlock(world, i + 19, j + 27, k + 5, Dungeons.fireflyLeaves, 0);
        this.setBlock(world, i + 19, j + 27, k + 6, Dungeons.fireflyLeaves, 0);
        this.setBlock(world, i + 19, j + 27, k + 7, Dungeons.fireflyLeaves, 0);
        this.setBlock(world, i + 19, j + 27, k + 8, Dungeons.fireflyLeaves, 0);
        this.setBlock(world, i + 19, j + 27, k + 10, Dungeons.fireflyLeaves, 0);
        this.setBlock(world, i + 19, j + 27, k + 14, Dungeons.fireflyLeaves, 0);
        this.setBlock(world, i + 19, j + 28, k + 7, Dungeons.fireflyLeaves, 0);
        this.setBlock(world, i + 19, j + 28, k + 8, Dungeons.fireflyLeaves, 0);
        this.setBlock(world, i + 19, j + 28, k + 9, Dungeons.fireflyLeaves, 0);
        this.setBlock(world, i + 19, j + 28, k + 10, Dungeons.fireflyLeaves, 0);
        this.setBlock(world, i + 19, j + 28, k + 11, Dungeons.fireflyLeaves, 0);
        this.setBlock(world, i + 19, j + 28, k + 12, Dungeons.fireflyLeaves, 0);
        this.setBlock(world, i + 19, j + 29, k + 9, Dungeons.fireflyLeaves, 0);
        this.setBlock(world, i + 19, j + 29, k + 10, Dungeons.fireflyLeaves, 0);
        this.setBlock(world, i + 19, j + 29, k + 11, Dungeons.fireflyLeaves, 0);
        this.setBlock(world, i + 19, j + 29, k + 18, Dungeons.fireflyLeaves, 0);
        this.setBlock(world, i + 19, j + 29, k + 19, Dungeons.fireflyLeaves, 0);
        this.setBlock(world, i + 19, j + 29, k + 20, Dungeons.fireflyLeaves, 0);
        this.setBlock(world, i + 19, j + 29, k + 21, Dungeons.fireflyLeaves, 0);
        this.setBlock(world, i + 19, j + 29, k + 22, Dungeons.fireflyLeaves, 0);
        this.setBlock(world, i + 20, j + 0, k + 15, Dungeons.fireflyLog, 0);
        this.setBlock(world, i + 20, j + 0, k + 16, Dungeons.fireflyLog, 0);
        this.setBlock(world, i + 20, j + 1, k + 15, Dungeons.fireflyLog, 0);
        this.setBlock(world, i + 20, j + 1, k + 16, Dungeons.fireflyLog, 0);
        this.setBlock(world, i + 20, j + 2, k + 15, Dungeons.fireflyLog, 0);
        this.setBlock(world, i + 20, j + 2, k + 16, Dungeons.fireflyLog, 0);
        this.setBlock(world, i + 20, j + 3, k + 15, Dungeons.fireflyLog, 0);
        this.setBlock(world, i + 20, j + 3, k + 16, Dungeons.fireflyLog, 0);
        this.setBlock(world, i + 20, j + 4, k + 15, Dungeons.fireflyLog, 0);
        this.setBlock(world, i + 20, j + 4, k + 16, Dungeons.fireflyLog, 0);
        this.setBlock(world, i + 20, j + 5, k + 15, Dungeons.fireflyLog, 0);
        this.setBlock(world, i + 20, j + 5, k + 16, Dungeons.fireflyLog, 0);
        this.setBlock(world, i + 20, j + 6, k + 15, Dungeons.fireflyLog, 0);
        this.setBlock(world, i + 20, j + 6, k + 16, Dungeons.fireflyLog, 0);
        this.setBlock(world, i + 20, j + 7, k + 15, Dungeons.fireflyLog, 0);
        this.setBlock(world, i + 20, j + 7, k + 16, Dungeons.fireflyLog, 0);
        this.setBlock(world, i + 20, j + 8, k + 15, Dungeons.fireflyLog, 0);
        this.setBlock(world, i + 20, j + 8, k + 16, Dungeons.fireflyLog, 0);
