package com.gibby.dungeon.gen;

import com.gibby.dungeon.Dungeons;
import cpw.mods.fml.common.IWorldGenerator;
import net.minecraft.block.Block;
import net.minecraft.world.IBlockAccess;
import net.minecraft.world.World;
import net.minecraft.world.chunk.IChunkProvider;
import net.minecraft.world.gen.feature.WorldGenerator;

import java.util.Random;

public class FireflyTreeMedium extends WorldGenerator implements IWorldGenerator
{
    public void generate(final Random random, final int chunkX, final int chunkZ, final World world, final IChunkProvider chunkGenerator, final IChunkProvider chunkProvider) {
    }

    public void setBlock(final World world, final int x, final int y, final int z, final Block block, final int metadata) {
        final Block b1 = world.getBlock(x, y, z);
        if (b1.isAir(world, x, y, z) || b1.isLeaves(world, x, y, z)) {
            world.setBlock(x, y, z, block, metadata, 2);
        }
    }

    public boolean generate(final World world, final Random rand, final int i, final int j, final int k) {
        if (world.getBlock(i + 8, j - 1, k + 9) != Dungeons.midnightGrass) {
            return false;
        }
        for (int c = 4; c < 12; ++c) {
            if (!world.isAirBlock(i + 8, j + c, k + 9)) {
                return false;
            }
        }
        this.setBlock(world, i + 1, j + 7, k + 11, Dungeons.fireflyLeaves, 0);
        this.setBlock(world, i + 2, j + 7, k + 3, Dungeons.fireflyLeaves, 0);
        this.setBlock(world, i + 2, j + 7, k + 4, Dungeons.fireflyLeaves, 0);
        this.setBlock(world, i + 2, j + 7, k + 10, Dungeons.fireflyLeaves, 0);
        this.setBlock(world, i + 2, j + 7, k + 11, Dungeons.fireflyLeaves, 0);
        this.setBlock(world, i + 2, j + 7, k + 12, Dungeons.fireflyLeaves, 0);
        this.setBlock(world, i + 2, j + 7, k + 13, Dungeons.fireflyLeaves, 0);
        this.setBlock(world, i + 2, j + 11, k + 6, Dungeons.fireflyLeaves, 0);
        this.setBlock(world, i + 2, j + 11, k + 7, Dungeons.fireflyLeaves, 0);
        this.setBlock(world, i + 2, j + 11, k + 8, Dungeons.fireflyLeaves, 0);
        this.setBlock(world, i + 2, j + 11, k + 9, Dungeons.fireflyLeaves, 0);
        this.setBlock(world, i + 3, j + 6, k + 11, Dungeons.fireflyLeaves, 0);
        this.setBlock(world, i + 3, j + 7, k + 2, Dungeons.fireflyLeaves, 0);
        this.setBlock(world, i + 3, j + 7, k + 3, Dungeons.fireflyLeaves, 0);
        this.setBlock(world, i + 3, j + 7, k + 4, Dungeons.fireflyLeaves, 0);
        this.setBlock(world, i + 3, j + 7, k + 5, Dungeons.fireflyLeaves, 0);
        this.setBlock(world, i + 3, j + 7, k + 9, Dungeons.fireflyLeaves, 0);
        this.setBlock(world, i + 3, j + 7, k + 10, Dungeons.fireflyLeaves, 0);
        this.setBlock(world, i + 3, j + 7, k + 11, Dungeons.fireflyLeaves, 0);
        this.setBlock(world, i + 3, j + 7, k + 12, Dungeons.fireflyLeaves, 0);
        this.setBlock(world, i + 3, j + 7, k + 13, Dungeons.fireflyLeaves, 0);
        this.setBlock(world, i + 3, j + 7, k + 14, Dungeons.fireflyLeaves, 0);
        this.setBlock(world, i + 3, j + 8, k + 4, Dungeons.fireflyLeaves, 0);
        this.setBlock(world, i + 3, j + 8, k + 11, Dungeons.fireflyLeaves, 0);
        this.setBlock(world, i + 3, j + 8, k + 12, Dungeons.fireflyLeaves, 0);
        this.setBlock(world, i + 3, j + 11, k + 5, Dungeons.fireflyLeaves, 0);
        this.setBlock(world, i + 3, j + 11, k + 6, Dungeons.fireflyLeaves, 0);
        this.setBlock(world, i + 3, j + 11, k + 7, Dungeons.fireflyLeaves, 0);
        this.setBlock(world, i + 3, j + 11, k + 8, Dungeons.fireflyLeaves, 0);
        this.setBlock(world, i + 3, j + 11, k + 9, Dungeons.fireflyLeaves, 0);
        this.setBlock(world, i + 3, j + 11, k + 10, Dungeons.fireflyLeaves, 0);
        this.setBlock(world, i + 4, j + 6, k + 4, Dungeons.fireflyLeaves, 0);
        this.setBlock(world, i + 4, j + 6, k + 5, Dungeons.fireflyLog, 0);
        this.setBlock(world, i + 4, j + 6, k + 11, Dungeons.fireflyLog, 0);
        this.setBlock(world, i + 4, j + 6, k + 12, Dungeons.fireflyLeaves, 0);
        this.setBlock(world, i + 4, j + 7, k + 1, Dungeons.fireflyLeaves, 0);
        this.setBlock(world, i + 4, j + 7, k + 2, Dungeons.fireflyLeaves, 0);
        this.setBlock(world, i + 4, j + 7, k + 3, Dungeons.fireflyLeaves, 0);
        this.setBlock(world, i + 4, j + 7, k + 4, Dungeons.fireflyLog, 0);
        this.setBlock(world, i + 4, j + 7, k + 5, Dungeons.fireflyLeaves, 0);
        this.setBlock(world, i + 4, j + 7, k + 6, Dungeons.fireflyLeaves, 0);
        this.setBlock(world, i + 4, j + 7, k + 9, Dungeons.fireflyLeaves, 0);
        this.setBlock(world, i + 4, j + 7, k + 10, Dungeons.fireflyLeaves, 0);
        this.setBlock(world, i + 4, j + 7, k + 11, Dungeons.fireflyLog, 0);
        this.setBlock(world, i + 4, j + 7, k + 12, Dungeons.fireflyLeaves, 0);
        this.setBlock(world, i + 4, j + 7, k + 13, Dungeons.fireflyLeaves, 0);
        this.setBlock(world, i + 4, j + 7, k + 14, Dungeons.fireflyLeaves, 0);
        this.setBlock(world, i + 4, j + 8, k + 3, Dungeons.fireflyLeaves, 0);
        this.setBlock(world, i + 4, j + 8, k + 4, Dungeons.fireflyLeaves, 0);
        this.setBlock(world, i + 4, j + 8, k + 5, Dungeons.fireflyLeaves, 0);
        this.setBlock(world, i + 4, j + 8, k + 11, Dungeons.fireflyLeaves, 0);
        this.setBlock(world, i + 4, j + 8, k + 12, Dungeons.fireflyLeaves, 0);
        this.setBlock(world, i + 4, j + 8, k + 13, Dungeons.fireflyLeaves, 0);
        this.setBlock(world, i + 4, j + 10, k + 6, Dungeons.fireflyLeaves, 0);
        this.setBlock(world, i + 4, j + 10, k + 7, Dungeons.fireflyLeaves, 0);
        this.setBlock(world, i + 4, j + 10, k + 8, Dungeons.fireflyLeaves, 0);
        this.setBlock(world, i + 4, j + 11, k + 4, Dungeons.fireflyLeaves, 0);
        this.setBlock(world, i + 4, j + 11, k + 5, Dungeons.fireflyLeaves, 0);
        this.setBlock(world, i + 4, j + 11, k + 6, Dungeons.fireflyLeaves, 0);
        this.setBlock(world, i + 4, j + 11, k + 7, Dungeons.fireflyLeaves, 0);
        this.setBlock(world, i + 4, j + 11, k + 8, Dungeons.fireflyLeaves, 0);
        this.setBlock(world, i + 4, j + 11, k + 9, Dungeons.fireflyLeaves, 0);
        this.setBlock(world, i + 4, j + 11, k + 10, Dungeons.fireflyLeaves, 0);
        this.setBlock(world, i + 4, j + 12, k + 7, Dungeons.fireflyLeaves, 0);
        this.setBlock(world, i + 4, j + 12, k + 8, Dungeons.fireflyLeaves, 0);
        this.setBlock(world, i + 5, j + 5, k + 10, Dungeons.fireflyLog, 0);
        this.setBlock(world, i + 5, j + 6, k + 6, Dungeons.fireflyLog, 0);
        this.setBlock(world, i + 5, j + 6, k + 7, Dungeons.fireflyLog, 0);
        this.setBlock(world, i + 5, j + 7, k + 2, Dungeons.fireflyLeaves, 0);
        this.setBlock(world, i + 5, j + 7, k + 3, Dungeons.fireflyLeaves, 0);
        this.setBlock(world, i + 5, j + 7, k + 4, Dungeons.fireflyLeaves, 0);
        this.setBlock(world, i + 5, j + 7, k + 5, Dungeons.fireflyLeaves, 0);
        this.setBlock(world, i + 5, j + 7, k + 7, Dungeons.fireflyLog, 0);
        this.setBlock(world, i + 5, j + 7, k + 10, Dungeons.fireflyLeaves, 0);
        this.setBlock(world, i + 5, j + 7, k + 11, Dungeons.fireflyLeaves, 0);
        this.setBlock(world, i + 5, j + 7, k + 12, Dungeons.fireflyLeaves, 0);
        this.setBlock(world, i + 5, j + 7, k + 13, Dungeons.fireflyLeaves, 0);
        this.setBlock(world, i + 5, j + 8, k + 3, Dungeons.fireflyLeaves, 0);
        this.setBlock(world, i + 5, j + 8, k + 7, Dungeons.fireflyLog, 0);
        this.setBlock(world, i + 5, j + 9, k + 7, Dungeons.fireflyLog, 0);
        this.setBlock(world, i + 5, j + 10, k + 6, Dungeons.fireflyLeaves, 0);
        this.setBlock(world, i + 5, j + 10, k + 7, Dungeons.fireflyLeaves, 0);
        this.setBlock(world, i + 5, j + 10, k + 8, Dungeons.fireflyLeaves, 0);
        this.setBlock(world, i + 5, j + 11, k + 4, Dungeons.fireflyLeaves, 0);
        this.setBlock(world, i + 5, j + 11, k + 5, Dungeons.fireflyLeaves, 0);
        this.setBlock(world, i + 5, j + 11, k + 6, Dungeons.fireflyLeaves, 0);
        this.setBlock(world, i + 5, j + 11, k + 7, Dungeons.fireflyLeaves, 0);
        this.setBlock(world, i + 5, j + 11, k + 8, Dungeons.fireflyLeaves, 0);
        this.setBlock(world, i + 5, j + 11, k + 9, Dungeons.fireflyLeaves, 0);
        this.setBlock(world, i + 5, j + 11, k + 10, Dungeons.fireflyLeaves, 0);
        this.setBlock(world, i + 5, j + 11, k + 11, Dungeons.fireflyLeaves, 0);
        this.setBlock(world, i + 5, j + 12, k + 6, Dungeons.fireflyLeaves, 0);
        this.setBlock(world, i + 5, j + 12, k + 7, Dungeons.fireflyLeaves, 0);
        this.setBlock(world, i + 5, j + 12, k + 8, Dungeons.fireflyLeaves, 0);
        this.setBlock(world, i + 5, j + 12, k + 9, Dungeons.fireflyLeaves, 0);
        this.setBlock(world, i + 6, j + 5, k + 8, Dungeons.fireflyLog, 0);
        this.setBlock(world, i + 6, j + 5, k + 9, Dungeons.fireflyLog, 0);
        this.setBlock(world, i + 6, j + 6, k + 8, Dungeons.fireflyLog, 0);
        this.setBlock(world, i + 6, j + 7, k + 3, Dungeons.fireflyLeaves, 0);
        this.setBlock(world, i + 6, j + 7, k + 4, Dungeons.fireflyLeaves, 0);
        this.setBlock(world, i + 6, j + 7, k + 12, Dungeons.fireflyLeaves, 0);
        this.setBlock(world, i + 6, j + 10, k + 7, Dungeons.fireflyLeaves, 0);
        this.setBlock(world, i + 6, j + 10, k + 8, Dungeons.fireflyLeaves, 0);
        this.setBlock(world, i + 6, j + 11, k + 5, Dungeons.fireflyLeaves, 0);
        this.setBlock(world, i + 6, j + 11, k + 6, Dungeons.fireflyLeaves, 0);
        this.setBlock(world, i + 6, j + 11, k + 7, Dungeons.fireflyLeaves, 0);
        this.setBlock(world, i + 6, j + 11, k + 8, Dungeons.fireflyLeaves, 0);
        this.setBlock(world, i + 6, j + 11, k + 9, Dungeons.fireflyLeaves, 0);
        this.setBlock(world, i + 6, j + 11, k + 10, Dungeons.fireflyLeaves, 0);
        this.setBlock(world, i + 6, j + 11, k + 11, Dungeons.fireflyLeaves, 0);
        this.setBlock(world, i + 6, j + 11, k + 12, Dungeons.fireflyLeaves, 0);
        this.setBlock(world, i + 6, j + 12, k + 7, Dungeons.fireflyLeaves, 0);
        this.setBlock(world, i + 6, j + 12, k + 8, Dungeons.fireflyLeaves, 0);
        this.setBlock(world, i + 6, j + 12, k + 9, Dungeons.fireflyLeaves, 0);
        this.setBlock(world, i + 7, j + 5, k + 9, Dungeons.fireflyLog, 0);
        this.setBlock(world, i + 7, j + 6, k + 3, Dungeons.fireflyLeaves, 0);
        this.setBlock(world, i + 7, j + 6, k + 4, Dungeons.fireflyLeaves, 0);
        this.setBlock(world, i + 7, j + 6, k + 5, Dungeons.fireflyLeaves, 0);
        this.setBlock(world, i + 7, j + 6, k + 6, Dungeons.fireflyLeaves, 0);
        this.setBlock(world, i + 7, j + 10, k + 11, Dungeons.fireflyLeaves, 0);
        this.setBlock(world, i + 7, j + 11, k + 4, Dungeons.fireflyLeaves, 0);
        this.setBlock(world, i + 7, j + 11, k + 5, Dungeons.fireflyLeaves, 0);
        this.setBlock(world, i + 7, j + 11, k + 6, Dungeons.fireflyLeaves, 0);
        this.setBlock(world, i + 7, j + 11, k + 7, Dungeons.fireflyLeaves, 0);
        this.setBlock(world, i + 7, j + 11, k + 8, Dungeons.fireflyLeaves, 0);
        this.setBlock(world, i + 7, j + 11, k + 9, Dungeons.fireflyLeaves, 0);
        this.setBlock(world, i + 7, j + 11, k + 10, Dungeons.fireflyLeaves, 0);
        this.setBlock(world, i + 7, j + 11, k + 11, Dungeons.fireflyLeaves, 0);
        this.setBlock(world, i + 7, j + 11, k + 12, Dungeons.fireflyLeaves, 0);
        this.setBlock(world, i + 7, j + 11, k + 13, Dungeons.fireflyLeaves, 0);
        this.setBlock(world, i + 7, j + 12, k + 11, Dungeons.fireflyLeaves, 0);
        this.setBlock(world, i + 8, j + 0, k + 9, Dungeons.fireflyLog, 0);
        this.setBlock(world, i + 8, j + 1, k + 9, Dungeons.fireflyLog, 0);
        this.setBlock(world, i + 8, j + 2, k + 9, Dungeons.fireflyLog, 0);
        this.setBlock(world, i + 8, j + 3, k + 9, Dungeons.fireflyLog, 0);
        this.setBlock(world, i + 8, j + 4, k + 9, Dungeons.fireflyLog, 0);
        this.setBlock(world, i + 8, j + 5, k + 5, Dungeons.fireflyLeaves, 0);
        this.setBlock(world, i + 8, j + 5, k + 8, Dungeons.fireflyLog, 0);
        this.setBlock(world, i + 8, j + 5, k + 9, Dungeons.fireflyLog, 0);
        this.setBlock(world, i + 8, j + 5, k + 10, Dungeons.fireflyLog, 0);
        this.setBlock(world, i + 8, j + 6, k + 2, Dungeons.fireflyLeaves, 0);
        this.setBlock(world, i + 8, j + 6, k + 3, Dungeons.fireflyLeaves, 0);
        this.setBlock(world, i + 8, j + 6, k + 4, Dungeons.fireflyLeaves, 0);
        this.setBlock(world, i + 8, j + 6, k + 5, Dungeons.fireflyLeaves, 0);
        this.setBlock(world, i + 8, j + 6, k + 6, Dungeons.fireflyLeaves, 0);
        this.setBlock(world, i + 8, j + 6, k + 10, Dungeons.fireflyLog, 0);
        this.setBlock(world, i + 8, j + 7, k + 5, Dungeons.fireflyLeaves, 0);
        this.setBlock(world, i + 8, j + 7, k + 6, Dungeons.fireflyLeaves, 0);
        this.setBlock(world, i + 8, j + 9, k + 11, Dungeons.fireflyLeaves, 0);
        this.setBlock(world, i + 8, j + 10, k + 6, Dungeons.fireflyLeaves, 0);
        this.setBlock(world, i + 8, j + 10, k + 10, Dungeons.fireflyLeaves, 0);
        this.setBlock(world, i + 8, j + 10, k + 11, Dungeons.fireflyLeaves, 0);
        this.setBlock(world, i + 8, j + 10, k + 12, Dungeons.fireflyLeaves, 0);
        this.setBlock(world, i + 8, j + 11, k + 3, Dungeons.fireflyLeaves, 0);
        this.setBlock(world, i + 8, j + 11, k + 4, Dungeons.fireflyLeaves, 0);
        this.setBlock(world, i + 8, j + 11, k + 5, Dungeons.fireflyLeaves, 0);
        this.setBlock(world, i + 8, j + 11, k + 6, Dungeons.fireflyLeaves, 0);
        this.setBlock(world, i + 8, j + 11, k + 7, Dungeons.fireflyLeaves, 0);
        this.setBlock(world, i + 8, j + 11, k + 8, Dungeons.fireflyLeaves, 0);
        this.setBlock(world, i + 8, j + 11, k + 9, Dungeons.fireflyLeaves, 0);
        this.setBlock(world, i + 8, j + 11, k + 10, Dungeons.fireflyLeaves, 0);
        this.setBlock(world, i + 8, j + 11, k + 11, Dungeons.fireflyLeaves, 0);
        this.setBlock(world, i + 8, j + 11, k + 12, Dungeons.fireflyLeaves, 0);
        this.setBlock(world, i + 8, j + 11, k + 13, Dungeons.fireflyLeaves, 0);
        this.setBlock(world, i + 8, j + 11, k + 14, Dungeons.fireflyLeaves, 0);
        this.setBlock(world, i + 8, j + 12, k + 5, Dungeons.fireflyLeaves, 0);
        this.setBlock(world, i + 8, j + 12, k + 6, Dungeons.fireflyLeaves, 0);
        this.setBlock(world, i + 8, j + 12, k + 10, Dungeons.fireflyLeaves, 0);
        this.setBlock(world, i + 8, j + 12, k + 11, Dungeons.fireflyLeaves, 0);
        this.setBlock(world, i + 8, j + 12, k + 12, Dungeons.fireflyLeaves, 0);
        this.setBlock(world, i + 9, j + 5, k + 4, Dungeons.fireflyLeaves, 0);
        this.setBlock(world, i + 9, j + 5, k + 5, Dungeons.fireflyLeaves, 0);
        this.setBlock(world, i + 9, j + 5, k + 7, Dungeons.fireflyLog, 0);
        this.setBlock(world, i + 9, j + 6, k + 2, Dungeons.fireflyLeaves, 0);
        this.setBlock(world, i + 9, j + 6, k + 3, Dungeons.fireflyLeaves, 0);
        this.setBlock(world, i + 9, j + 6, k + 4, Dungeons.fireflyLeaves, 0);
        this.setBlock(world, i + 9, j + 6, k + 5, Dungeons.fireflyLog, 0);
        this.setBlock(world, i + 9, j + 6, k + 6, Dungeons.fireflyLog, 0);
        this.setBlock(world, i + 9, j + 6, k + 7, Dungeons.fireflyLog, 0);
        this.setBlock(world, i + 9, j + 6, k + 11, Dungeons.fireflyLog, 0);
        this.setBlock(world, i + 9, j + 7, k + 4, Dungeons.fireflyLeaves, 0);
        this.setBlock(world, i + 9, j + 7, k + 5, Dungeons.fireflyLeaves, 0);
        this.setBlock(world, i + 9, j + 7, k + 6, Dungeons.fireflyLeaves, 0);
        this.setBlock(world, i + 9, j + 7, k + 11, Dungeons.fireflyLog, 0);
        this.setBlock(world, i + 9, j + 8, k + 11, Dungeons.fireflyLog, 0);
        this.setBlock(world, i + 9, j + 9, k + 10, Dungeons.fireflyLeaves, 0);
        this.setBlock(world, i + 9, j + 9, k + 11, Dungeons.fireflyLog, 0);
        this.setBlock(world, i + 9, j + 10, k + 5, Dungeons.fireflyLeaves, 0);
        this.setBlock(world, i + 9, j + 10, k + 6, Dungeons.fireflyLeaves, 0);
        this.setBlock(world, i + 9, j + 10, k + 7, Dungeons.fireflyLeaves, 0);
        this.setBlock(world, i + 9, j + 10, k + 9, Dungeons.fireflyLeaves, 0);
        this.setBlock(world, i + 9, j + 10, k + 10, Dungeons.fireflyLeaves, 0);
        this.setBlock(world, i + 9, j + 10, k + 11, Dungeons.fireflyLeaves, 0);
        this.setBlock(world, i + 9, j + 10, k + 12, Dungeons.fireflyLeaves, 0);
        this.setBlock(world, i + 9, j + 10, k + 13, Dungeons.fireflyLeaves, 0);
        this.setBlock(world, i + 9, j + 11, k + 3, Dungeons.fireflyLeaves, 0);
        this.setBlock(world, i + 9, j + 11, k + 4, Dungeons.fireflyLeaves, 0);
        this.setBlock(world, i + 9, j + 11, k + 5, Dungeons.fireflyLeaves, 0);
        this.setBlock(world, i + 9, j + 11, k + 6, Dungeons.fireflyLeaves, 0);
        this.setBlock(world, i + 9, j + 11, k + 7, Dungeons.fireflyLeaves, 0);
        this.setBlock(world, i + 9, j + 11, k + 8, Dungeons.fireflyLeaves, 0);
        this.setBlock(world, i + 9, j + 11, k + 9, Dungeons.fireflyLeaves, 0);
        this.setBlock(world, i + 9, j + 11, k + 10, Dungeons.fireflyLeaves, 0);
        this.setBlock(world, i + 9, j + 11, k + 11, Dungeons.fireflyLeaves, 0);
        this.setBlock(world, i + 9, j + 11, k + 12, Dungeons.fireflyLeaves, 0);
        this.setBlock(world, i + 9, j + 11, k + 13, Dungeons.fireflyLeaves, 0);
        this.setBlock(world, i + 9, j + 11, k + 14, Dungeons.fireflyLeaves, 0);
        this.setBlock(world, i + 9, j + 11, k + 15, Dungeons.fireflyLeaves, 0);
        this.setBlock(world, i + 9, j + 12, k + 4, Dungeons.fireflyLeaves, 0);
        this.setBlock(world, i + 9, j + 12, k + 5, Dungeons.fireflyLeaves, 0);
        this.setBlock(world, i + 9, j + 12, k + 6, Dungeons.fireflyLeaves, 0);
        this.setBlock(world, i + 9, j + 12, k + 7, Dungeons.fireflyLeaves, 0);
        this.setBlock(world, i + 9, j + 12, k + 10, Dungeons.fireflyLeaves, 0);
        this.setBlock(world, i + 9, j + 12, k + 11, Dungeons.fireflyLeaves, 0);
        this.setBlock(world, i + 9, j + 12, k + 12, Dungeons.fireflyLeaves, 0);
        this.setBlock(world, i + 9, j + 12, k + 13, Dungeons.fireflyLeaves, 0);
        this.setBlock(world, i + 9, j + 13, k + 11, Dungeons.fireflyLeaves, 0);
        this.setBlock(world, i + 10, j + 5, k + 5, Dungeons.fireflyLeaves, 0);
        this.setBlock(world, i + 10, j + 6, k + 2, Dungeons.fireflyLeaves, 0);
        this.setBlock(world, i + 10, j + 6, k + 3, Dungeons.fireflyLeaves, 0);
        this.setBlock(world, i + 10, j + 6, k + 4, Dungeons.fireflyLeaves, 0);
        this.setBlock(world, i + 10, j + 6, k + 5, Dungeons.fireflyLeaves, 0);
        this.setBlock(world, i + 10, j + 6, k + 6, Dungeons.fireflyLeaves, 0);
        this.setBlock(world, i + 10, j + 6, k + 7, Dungeons.fireflyLeaves, 0);
        this.setBlock(world, i + 10, j + 6, k + 11, Dungeons.fireflyLog, 0);
        this.setBlock(world, i + 10, j + 6, k + 12, Dungeons.fireflyLeaves, 0);
        this.setBlock(world, i + 10, j + 6, k + 13, Dungeons.fireflyLeaves, 0);
        this.setBlock(world, i + 10, j + 7, k + 5, Dungeons.fireflyLeaves, 0);
        this.setBlock(world, i + 10, j + 7, k + 7, Dungeons.fireflyLog, 0);
        this.setBlock(world, i + 10, j + 8, k + 7, Dungeons.fireflyLog, 0);
        this.setBlock(world, i + 10, j + 9, k + 6, Dungeons.fireflyLog, 0);
        this.setBlock(world, i + 10, j + 9, k + 11, Dungeons.fireflyLeaves, 0);
        this.setBlock(world, i + 10, j + 9, k + 12, Dungeons.fireflyLeaves, 0);
        this.setBlock(world, i + 10, j + 10, k + 5, Dungeons.fireflyLeaves, 0);
        this.setBlock(world, i + 10, j + 10, k + 6, Dungeons.fireflyLog, 0);
        this.setBlock(world, i + 10, j + 10, k + 7, Dungeons.fireflyLeaves, 0);
        this.setBlock(world, i + 10, j + 10, k + 10, Dungeons.fireflyLeaves, 0);
        this.setBlock(world, i + 10, j + 10, k + 11, Dungeons.fireflyLeaves, 0);
        this.setBlock(world, i + 10, j + 10, k + 12, Dungeons.fireflyLeaves, 0);
        this.setBlock(world, i + 10, j + 11, k + 3, Dungeons.fireflyLeaves, 0);
        this.setBlock(world, i + 10, j + 11, k + 4, Dungeons.fireflyLeaves, 0);
        this.setBlock(world, i + 10, j + 11, k + 5, Dungeons.fireflyLeaves, 0);
        this.setBlock(world, i + 10, j + 11, k + 6, Dungeons.fireflyLeaves, 0);
        this.setBlock(world, i + 10, j + 11, k + 7, Dungeons.fireflyLeaves, 0);
        this.setBlock(world, i + 10, j + 11, k + 8, Dungeons.fireflyLeaves, 0);
        this.setBlock(world, i + 10, j + 11, k + 9, Dungeons.fireflyLeaves, 0);
        this.setBlock(world, i + 10, j + 11, k + 10, Dungeons.fireflyLeaves, 0);
        this.setBlock(world, i + 10, j + 11, k + 11, Dungeons.fireflyLeaves, 0);
        this.setBlock(world, i + 10, j + 11, k + 12, Dungeons.fireflyLeaves, 0);
        this.setBlock(world, i + 10, j + 11, k + 13, Dungeons.fireflyLeaves, 0);
        this.setBlock(world, i + 10, j + 11, k + 14, Dungeons.fireflyLeaves, 0);
        this.setBlock(world, i + 10, j + 11, k + 15, Dungeons.fireflyLeaves, 0);
        this.setBlock(world, i + 10, j + 12, k + 4, Dungeons.fireflyLeaves, 0);
        this.setBlock(world, i + 10, j + 12, k + 5, Dungeons.fireflyLeaves, 0);
        this.setBlock(world, i + 10, j + 12, k + 6, Dungeons.fireflyLeaves, 0);
        this.setBlock(world, i + 10, j + 12, k + 7, Dungeons.fireflyLeaves, 0);
        this.setBlock(world, i + 10, j + 12, k + 10, Dungeons.fireflyLeaves, 0);
        this.setBlock(world, i + 10, j + 12, k + 11, Dungeons.fireflyLeaves, 0);
        this.setBlock(world, i + 10, j + 12, k + 12, Dungeons.fireflyLeaves, 0);
        this.setBlock(world, i + 11, j + 5, k + 12, Dungeons.fireflyLeaves, 0);
        this.setBlock(world, i + 11, j + 6, k + 3, Dungeons.fireflyLeaves, 0);
        this.setBlock(world, i + 11, j + 6, k + 4, Dungeons.fireflyLeaves, 0);
        this.setBlock(world, i + 11, j + 6, k + 5, Dungeons.fireflyLeaves, 0);
        this.setBlock(world, i + 11, j + 6, k + 6, Dungeons.fireflyLeaves, 0);
        this.setBlock(world, i + 11, j + 6, k + 11, Dungeons.fireflyLeaves, 0);
        this.setBlock(world, i + 11, j + 6, k + 12, Dungeons.fireflyLog, 0);
        this.setBlock(world, i + 11, j + 6, k + 13, Dungeons.fireflyLeaves, 0);
        this.setBlock(world, i + 11, j + 6, k + 14, Dungeons.fireflyLeaves, 0);
        this.setBlock(world, i + 11, j + 7, k + 7, Dungeons.fireflyLog, 0);
        this.setBlock(world, i + 11, j + 7, k + 12, Dungeons.fireflyLeaves, 0);
        this.setBlock(world, i + 11, j + 7, k + 13, Dungeons.fireflyLeaves, 0);
        this.setBlock(world, i + 11, j + 9, k + 6, Dungeons.fireflyLeaves, 0);
        this.setBlock(world, i + 11, j + 9, k + 7, Dungeons.fireflyLeaves, 0);
        this.setBlock(world, i + 11, j + 10, k + 5, Dungeons.fireflyLeaves, 0);
        this.setBlock(world, i + 11, j + 10, k + 6, Dungeons.fireflyLeaves, 0);
        this.setBlock(world, i + 11, j + 10, k + 12, Dungeons.fireflyLeaves, 0);
        this.setBlock(world, i + 11, j + 11, k + 3, Dungeons.fireflyLeaves, 0);
        this.setBlock(world, i + 11, j + 11, k + 4, Dungeons.fireflyLeaves, 0);
        this.setBlock(world, i + 11, j + 11, k + 5, Dungeons.fireflyLeaves, 0);
        this.setBlock(world, i + 11, j + 11, k + 6, Dungeons.fireflyLeaves, 0);
        this.setBlock(world, i + 11, j + 11, k + 7, Dungeons.fireflyLeaves, 0);
        this.setBlock(world, i + 11, j + 11, k + 8, Dungeons.fireflyLeaves, 0);
        this.setBlock(world, i + 11, j + 11, k + 9, Dungeons.fireflyLeaves, 0);
        this.setBlock(world, i + 11, j + 11, k + 10, Dungeons.fireflyLeaves, 0);
        this.setBlock(world, i + 11, j + 11, k + 11, Dungeons.fireflyLeaves, 0);
        this.setBlock(world, i + 11, j + 11, k + 12, Dungeons.fireflyLeaves, 0);
        this.setBlock(world, i + 11, j + 11, k + 13, Dungeons.fireflyLeaves, 0);
        this.setBlock(world, i + 11, j + 11, k + 14, Dungeons.fireflyLeaves, 0);
        this.setBlock(world, i + 11, j + 12, k + 5, Dungeons.fireflyLeaves, 0);
        this.setBlock(world, i + 11, j + 12, k + 6, Dungeons.fireflyLeaves, 0);
        this.setBlock(world, i + 11, j + 12, k + 11, Dungeons.fireflyLeaves, 0);
        this.setBlock(world, i + 12, j + 5, k + 13, Dungeons.fireflyLeaves, 0);
        this.setBlock(world, i + 12, j + 6, k + 4, Dungeons.fireflyLeaves, 0);
        this.setBlock(world, i + 12, j + 6, k + 5, Dungeons.fireflyLeaves, 0);
        this.setBlock(world, i + 12, j + 6, k + 11, Dungeons.fireflyLeaves, 0);
        this.setBlock(world, i + 12, j + 6, k + 12, Dungeons.fireflyLeaves, 0);
        this.setBlock(world, i + 12, j + 6, k + 13, Dungeons.fireflyLeaves, 0);
        this.setBlock(world, i + 12, j + 6, k + 14, Dungeons.fireflyLeaves, 0);
        this.setBlock(world, i + 12, j + 7, k + 7, Dungeons.fireflyLog, 0);
        this.setBlock(world, i + 12, j + 7, k + 13, Dungeons.fireflyLeaves, 0);
        this.setBlock(world, i + 12, j + 9, k + 5, Dungeons.fireflyLeaves, 0);
        this.setBlock(world, i + 12, j + 9, k + 6, Dungeons.fireflyLeaves, 0);
        this.setBlock(world, i + 12, j + 9, k + 7, Dungeons.fireflyLeaves, 0);
        this.setBlock(world, i + 12, j + 9, k + 8, Dungeons.fireflyLeaves, 0);
        this.setBlock(world, i + 12, j + 11, k + 4, Dungeons.fireflyLeaves, 0);
        this.setBlock(world, i + 12, j + 11, k + 5, Dungeons.fireflyLeaves, 0);
        this.setBlock(world, i + 12, j + 11, k + 6, Dungeons.fireflyLeaves, 0);
        this.setBlock(world, i + 12, j + 11, k + 7, Dungeons.fireflyLeaves, 0);
        this.setBlock(world, i + 12, j + 11, k + 9, Dungeons.fireflyLeaves, 0);
        this.setBlock(world, i + 12, j + 11, k + 10, Dungeons.fireflyLeaves, 0);
        this.setBlock(world, i + 12, j + 11, k + 11, Dungeons.fireflyLeaves, 0);
        this.setBlock(world, i + 12, j + 11, k + 12, Dungeons.fireflyLeaves, 0);
        this.setBlock(world, i + 12, j + 11, k + 13, Dungeons.fireflyLeaves, 0);
        this.setBlock(world, i + 13, j + 6, k + 12, Dungeons.fireflyLeaves, 0);
        this.setBlock(world, i + 13, j + 6, k + 13, Dungeons.fireflyLeaves, 0);
        this.setBlock(world, i + 13, j + 6, k + 14, Dungeons.fireflyLeaves, 0);
        this.setBlock(world, i + 13, j + 8, k + 7, Dungeons.fireflyLog, 0);
        this.setBlock(world, i + 13, j + 9, k + 4, Dungeons.fireflyLeaves, 0);
        this.setBlock(world, i + 13, j + 9, k + 5, Dungeons.fireflyLeaves, 0);
        this.setBlock(world, i + 13, j + 9, k + 6, Dungeons.fireflyLeaves, 0);
        this.setBlock(world, i + 13, j + 9, k + 7, Dungeons.fireflyLeaves, 0);
        this.setBlock(world, i + 13, j + 9, k + 8, Dungeons.fireflyLeaves, 0);
        this.setBlock(world, i + 13, j + 9, k + 9, Dungeons.fireflyLeaves, 0);
        this.setBlock(world, i + 13, j + 10, k + 6, Dungeons.fireflyLeaves, 0);
        this.setBlock(world, i + 13, j + 10, k + 7, Dungeons.fireflyLeaves, 0);
        this.setBlock(world, i + 13, j + 11, k + 5, Dungeons.fireflyLeaves, 0);
        this.setBlock(world, i + 13, j + 11, k + 6, Dungeons.fireflyLeaves, 0);
        this.setBlock(world, i + 13, j + 11, k + 10, Dungeons.fireflyLeaves, 0);
        this.setBlock(world, i + 13, j + 11, k + 11, Dungeons.fireflyLeaves, 0);
        this.setBlock(world, i + 13, j + 11, k + 12, Dungeons.fireflyLeaves, 0);
        this.setBlock(world, i + 14, j + 7, k + 7, Dungeons.fireflyLeaves, 0);
        this.setBlock(world, i + 14, j + 8, k + 6, Dungeons.fireflyLeaves, 0);
        this.setBlock(world, i + 14, j + 8, k + 7, Dungeons.fireflyLog, 0);
        this.setBlock(world, i + 14, j + 8, k + 8, Dungeons.fireflyLeaves, 0);
        this.setBlock(world, i + 14, j + 9, k + 4, Dungeons.fireflyLeaves, 0);
        this.setBlock(world, i + 14, j + 9, k + 5, Dungeons.fireflyLeaves, 0);
        this.setBlock(world, i + 14, j + 9, k + 6, Dungeons.fireflyLeaves, 0);
        this.setBlock(world, i + 14, j + 9, k + 7, Dungeons.fireflyLeaves, 0);
        this.setBlock(world, i + 14, j + 9, k + 8, Dungeons.fireflyLeaves, 0);
        this.setBlock(world, i + 14, j + 9, k + 9, Dungeons.fireflyLeaves, 0);
        this.setBlock(world, i + 14, j + 10, k + 6, Dungeons.fireflyLeaves, 0);
        this.setBlock(world, i + 14, j + 10, k + 7, Dungeons.fireflyLeaves, 0);
        this.setBlock(world, i + 14, j + 10, k + 8, Dungeons.fireflyLeaves, 0);
        this.setBlock(world, i + 15, j + 8, k + 7, Dungeons.fireflyLeaves, 0);
        this.setBlock(world, i + 15, j + 9, k + 5, Dungeons.fireflyLeaves, 0);
        this.setBlock(world, i + 15, j + 9, k + 6, Dungeons.fireflyLeaves, 0);
        this.setBlock(world, i + 15, j + 9, k + 7, Dungeons.fireflyLeaves, 0);
        this.setBlock(world, i + 15, j + 9, k + 8, Dungeons.fireflyLeaves, 0);
        this.setBlock(world, i + 15, j + 9, k + 9, Dungeons.fireflyLeaves, 0);
        this.setBlock(world, i + 15, j + 10, k + 6, Dungeons.fireflyLeaves, 0);
        this.setBlock(world, i + 15, j + 10, k + 7, Dungeons.fireflyLeaves, 0);
        this.setBlock(world, i + 16, j + 9, k + 5, Dungeons.fireflyLeaves, 0);
        this.setBlock(world, i + 16, j + 9, k + 6, Dungeons.fireflyLeaves, 0);
        this.setBlock(world, i + 16, j + 9, k + 7, Dungeons.fireflyLeaves, 0);
        this.setBlock(world, i + 16, j + 9, k + 8, Dungeons.fireflyLeaves, 0);
        this.setBlock(world, i + 17, j + 9, k + 6, Dungeons.fireflyLeaves, 0);
        this.setBlock(world, i + 17, j + 9, k + 7, Dungeons.fireflyLeaves, 0);
        return true;
    }
}
