package com.gibby.dungeon.gen;

import com.gibby.dungeon.Dungeons;
import cpw.mods.fml.common.IWorldGenerator;
import net.minecraft.block.Block;
import net.minecraft.world.IBlockAccess;
import net.minecraft.world.World;
import net.minecraft.world.chunk.IChunkProvider;
import net.minecraft.world.gen.feature.WorldGenerator;

import java.util.Random;

public class JadeTreeLarge extends WorldGenerator implements IWorldGenerator
{
    public void generate(final Random random, final int chunkX, final int chunkZ, final World world, final IChunkProvider chunkGenerator, final IChunkProvider chunkProvider) {
    }

    public void setBlock(final World world, final int x, final int y, final int z, final Block block, final int metadata) {
        final Block b1 = world.getBlock(x, y, z);
        if (b1.isAir(world, x, y, z) || b1.isLeaves(world, x, y, z)) {
            world.setBlock(x, y, z, block, metadata, 2);
        }
    }

    private boolean isRightBlock(final World world, final int i, final int j, final int k) {
        for (int c = 2; c < 12; ++c) {
            if (!world.isAirBlock(i, j + c, k) && world.getBlock(i, j + c, k) != Dungeons.jadeLeaves && world.getBlock(i, j + c, k) != Dungeons.jadeLog) {
                return false;
            }
        }
        return true;
    }

    private Block jadeLeaves(final World world) {
        if (world.rand.nextInt(20) == 0) {
            return Dungeons.jadePeaches;
        }
        return Dungeons.jadeLeaves;
    }

    public boolean generate(final World world, final Random rand, final int i, final int j, final int k) {
        if (world.getBlock(i + 20, j - 1, k + 20) != Dungeons.midnightGrass || world.getBlock(i + 20, j - 1, k + 18) != Dungeons.midnightGrass) {
            return false;
        }
        if (!this.isRightBlock(world, i + 0, j + 1, k + 36)) {
            return false;
        }
        if (!this.isRightBlock(world, i + 36, j + 1, k + 0)) {
            return false;
        }
        if (!this.isRightBlock(world, i + 0, j + 1, k + 0)) {
            return false;
        }
        if (!this.isRightBlock(world, i + 36, j + 1, k + 36)) {
            return false;
        }
        if (!this.isRightBlock(world, i + 25, j + 1, k + 25)) {
            return false;
        }
        if (!this.isRightBlock(world, i + 15, j + 1, k + 15)) {
            return false;
        }
        this.setBlock(world, i + 1, j + 7, k + 20, this.jadeLeaves(world), 0);
        this.setBlock(world, i + 1, j + 7, k + 21, this.jadeLeaves(world), 0);
        this.setBlock(world, i + 1, j + 7, k + 22, this.jadeLeaves(world), 0);
        this.setBlock(world, i + 1, j + 7, k + 23, this.jadeLeaves(world), 0);
        this.setBlock(world, i + 1, j + 7, k + 24, this.jadeLeaves(world), 0);
        this.setBlock(world, i + 2, j + 7, k + 19, this.jadeLeaves(world), 0);
        this.setBlock(world, i + 2, j + 7, k + 20, this.jadeLeaves(world), 0);
        this.setBlock(world, i + 2, j + 7, k + 21, this.jadeLeaves(world), 0);
        this.setBlock(world, i + 2, j + 7, k + 22, this.jadeLeaves(world), 0);
        this.setBlock(world, i + 2, j + 7, k + 23, this.jadeLeaves(world), 0);
        this.setBlock(world, i + 2, j + 7, k + 24, this.jadeLeaves(world), 0);
        this.setBlock(world, i + 2, j + 7, k + 25, this.jadeLeaves(world), 0);
        this.setBlock(world, i + 2, j + 7, k + 26, this.jadeLeaves(world), 0);
        this.setBlock(world, i + 3, j + 7, k + 18, this.jadeLeaves(world), 0);
        this.setBlock(world, i + 3, j + 7, k + 19, this.jadeLeaves(world), 0);
        this.setBlock(world, i + 3, j + 7, k + 20, this.jadeLeaves(world), 0);
        this.setBlock(world, i + 3, j + 7, k + 21, this.jadeLeaves(world), 0);
        this.setBlock(world, i + 3, j + 7, k + 22, this.jadeLeaves(world), 0);
        this.setBlock(world, i + 3, j + 7, k + 23, this.jadeLeaves(world), 0);
        this.setBlock(world, i + 3, j + 7, k + 24, this.jadeLeaves(world), 0);
        this.setBlock(world, i + 3, j + 7, k + 25, this.jadeLeaves(world), 0);
        this.setBlock(world, i + 3, j + 7, k + 26, this.jadeLeaves(world), 0);
        this.setBlock(world, i + 3, j + 8, k + 21, this.jadeLeaves(world), 0);
        this.setBlock(world, i + 3, j + 8, k + 22, this.jadeLeaves(world), 0);
        this.setBlock(world, i + 3, j + 8, k + 23, this.jadeLeaves(world), 0);
        this.setBlock(world, i + 4, j + 7, k + 16, this.jadeLeaves(world), 0);
        this.setBlock(world, i + 4, j + 7, k + 17, this.jadeLeaves(world), 0);
        this.setBlock(world, i + 4, j + 7, k + 18, this.jadeLeaves(world), 0);
        this.setBlock(world, i + 4, j + 7, k + 19, this.jadeLeaves(world), 0);
        this.setBlock(world, i + 4, j + 7, k + 20, this.jadeLeaves(world), 0);
        this.setBlock(world, i + 4, j + 7, k + 21, this.jadeLeaves(world), 0);
        this.setBlock(world, i + 4, j + 7, k + 22, this.jadeLeaves(world), 0);
        this.setBlock(world, i + 4, j + 7, k + 23, this.jadeLeaves(world), 0);
        this.setBlock(world, i + 4, j + 7, k + 24, this.jadeLeaves(world), 0);
        this.setBlock(world, i + 4, j + 7, k + 25, this.jadeLeaves(world), 0);
        this.setBlock(world, i + 4, j + 7, k + 26, this.jadeLeaves(world), 0);
        this.setBlock(world, i + 4, j + 7, k + 27, this.jadeLeaves(world), 0);
        this.setBlock(world, i + 4, j + 8, k + 20, this.jadeLeaves(world), 0);
        this.setBlock(world, i + 4, j + 8, k + 21, this.jadeLeaves(world), 0);
        this.setBlock(world, i + 4, j + 8, k + 22, this.jadeLeaves(world), 0);
        this.setBlock(world, i + 4, j + 8, k + 23, this.jadeLeaves(world), 0);
        this.setBlock(world, i + 4, j + 8, k + 24, this.jadeLeaves(world), 0);
        this.setBlock(world, i + 5, j + 6, k + 20, this.jadeLeaves(world), 0);
        this.setBlock(world, i + 5, j + 6, k + 21, this.jadeLeaves(world), 0);
        this.setBlock(world, i + 5, j + 6, k + 22, this.jadeLeaves(world), 0);
        this.setBlock(world, i + 5, j + 7, k + 13, this.jadeLeaves(world), 0);
        this.setBlock(world, i + 5, j + 7, k + 14, this.jadeLeaves(world), 0);
        this.setBlock(world, i + 5, j + 7, k + 15, this.jadeLeaves(world), 0);
        this.setBlock(world, i + 5, j + 7, k + 16, this.jadeLeaves(world), 0);
        this.setBlock(world, i + 5, j + 7, k + 17, this.jadeLeaves(world), 0);
        this.setBlock(world, i + 5, j + 7, k + 18, this.jadeLeaves(world), 0);
        this.setBlock(world, i + 5, j + 7, k + 19, this.jadeLeaves(world), 0);
        this.setBlock(world, i + 5, j + 7, k + 20, this.jadeLeaves(world), 0);
        this.setBlock(world, i + 5, j + 7, k + 21, this.jadeLeaves(world), 0);
        this.setBlock(world, i + 5, j + 7, k + 22, this.jadeLeaves(world), 0);
        this.setBlock(world, i + 5, j + 7, k + 23, this.jadeLeaves(world), 0);
        this.setBlock(world, i + 5, j + 7, k + 24, this.jadeLeaves(world), 0);
        this.setBlock(world, i + 5, j + 7, k + 25, this.jadeLeaves(world), 0);
        this.setBlock(world, i + 5, j + 7, k + 26, this.jadeLeaves(world), 0);
        this.setBlock(world, i + 5, j + 7, k + 27, this.jadeLeaves(world), 0);
        this.setBlock(world, i + 5, j + 7, k + 28, this.jadeLeaves(world), 0);
        this.setBlock(world, i + 5, j + 7, k + 29, this.jadeLeaves(world), 0);
        this.setBlock(world, i + 5, j + 8, k + 19, this.jadeLeaves(world), 0);
        this.setBlock(world, i + 5, j + 8, k + 20, this.jadeLeaves(world), 0);
        this.setBlock(world, i + 5, j + 8, k + 21, this.jadeLeaves(world), 0);
        this.setBlock(world, i + 5, j + 8, k + 22, this.jadeLeaves(world), 0);
        this.setBlock(world, i + 5, j + 8, k + 23, this.jadeLeaves(world), 0);
        this.setBlock(world, i + 5, j + 8, k + 24, this.jadeLeaves(world), 0);
        this.setBlock(world, i + 5, j + 8, k + 25, this.jadeLeaves(world), 0);
        this.setBlock(world, i + 5, j + 9, k + 22, this.jadeLeaves(world), 0);
        this.setBlock(world, i + 6, j + 6, k + 19, this.jadeLeaves(world), 0);
        this.setBlock(world, i + 6, j + 6, k + 20, this.jadeLeaves(world), 0);
        this.setBlock(world, i + 6, j + 6, k + 21, this.jadeLeaves(world), 0);
        this.setBlock(world, i + 6, j + 6, k + 22, this.jadeLeaves(world), 0);
        this.setBlock(world, i + 6, j + 6, k + 23, this.jadeLeaves(world), 0);
        this.setBlock(world, i + 6, j + 7, k + 11, this.jadeLeaves(world), 0);
        this.setBlock(world, i + 6, j + 7, k + 12, this.jadeLeaves(world), 0);
        this.setBlock(world, i + 6, j + 7, k + 13, this.jadeLeaves(world), 0);
        this.setBlock(world, i + 6, j + 7, k + 14, this.jadeLeaves(world), 0);
        this.setBlock(world, i + 6, j + 7, k + 15, this.jadeLeaves(world), 0);
        this.setBlock(world, i + 6, j + 7, k + 16, this.jadeLeaves(world), 0);
        this.setBlock(world, i + 6, j + 7, k + 17, this.jadeLeaves(world), 0);
        this.setBlock(world, i + 6, j + 7, k + 18, this.jadeLeaves(world), 0);
        this.setBlock(world, i + 6, j + 7, k + 19, this.jadeLeaves(world), 0);
        this.setBlock(world, i + 6, j + 7, k + 20, this.jadeLeaves(world), 0);
        this.setBlock(world, i + 6, j + 7, k + 21, this.jadeLeaves(world), 0);
        this.setBlock(world, i + 6, j + 7, k + 22, this.jadeLeaves(world), 0);
        this.setBlock(world, i + 6, j + 7, k + 23, this.jadeLeaves(world), 0);
        this.setBlock(world, i + 6, j + 7, k + 24, this.jadeLeaves(world), 0);
        this.setBlock(world, i + 6, j + 7, k + 25, this.jadeLeaves(world), 0);
        this.setBlock(world, i + 6, j + 7, k + 26, this.jadeLeaves(world), 0);
        this.setBlock(world, i + 6, j + 7, k + 27, this.jadeLeaves(world), 0);
        this.setBlock(world, i + 6, j + 7, k + 28, this.jadeLeaves(world), 0);
        this.setBlock(world, i + 6, j + 7, k + 29, this.jadeLeaves(world), 0);
        this.setBlock(world, i + 6, j + 8, k + 18, this.jadeLeaves(world), 0);
        this.setBlock(world, i + 6, j + 8, k + 19, this.jadeLeaves(world), 0);
        this.setBlock(world, i + 6, j + 8, k + 20, this.jadeLeaves(world), 0);
        this.setBlock(world, i + 6, j + 8, k + 21, this.jadeLeaves(world), 0);
        this.setBlock(world, i + 6, j + 8, k + 22, this.jadeLeaves(world), 0);
        this.setBlock(world, i + 6, j + 8, k + 23, this.jadeLeaves(world), 0);
        this.setBlock(world, i + 6, j + 8, k + 24, this.jadeLeaves(world), 0);
        this.setBlock(world, i + 6, j + 8, k + 25, this.jadeLeaves(world), 0);
        this.setBlock(world, i + 6, j + 9, k + 20, this.jadeLeaves(world), 0);
        this.setBlock(world, i + 6, j + 9, k + 21, this.jadeLeaves(world), 0);
        this.setBlock(world, i + 6, j + 9, k + 22, this.jadeLeaves(world), 0);
        this.setBlock(world, i + 6, j + 9, k + 23, this.jadeLeaves(world), 0);
        this.setBlock(world, i + 7, j + 6, k + 17, this.jadeLeaves(world), 0);
        this.setBlock(world, i + 7, j + 6, k + 18, this.jadeLeaves(world), 0);
        this.setBlock(world, i + 7, j + 6, k + 19, this.jadeLeaves(world), 0);
        this.setBlock(world, i + 7, j + 6, k + 20, this.jadeLeaves(world), 0);
        this.setBlock(world, i + 7, j + 6, k + 21, this.jadeLeaves(world), 0);
        this.setBlock(world, i + 7, j + 6, k + 22, this.jadeLeaves(world), 0);
        this.setBlock(world, i + 7, j + 6, k + 23, this.jadeLeaves(world), 0);
        this.setBlock(world, i + 7, j + 6, k + 24, this.jadeLeaves(world), 0);
        this.setBlock(world, i + 7, j + 6, k + 25, this.jadeLeaves(world), 0);
        this.setBlock(world, i + 7, j + 7, k + 10, this.jadeLeaves(world), 0);
        this.setBlock(world, i + 7, j + 7, k + 11, this.jadeLeaves(world), 0);
        this.setBlock(world, i + 7, j + 7, k + 12, this.jadeLeaves(world), 0);
        this.setBlock(world, i + 7, j + 7, k + 13, this.jadeLeaves(world), 0);
        this.setBlock(world, i + 7, j + 7, k + 14, this.jadeLeaves(world), 0);
        this.setBlock(world, i + 7, j + 7, k + 15, this.jadeLeaves(world), 0);
        this.setBlock(world, i + 7, j + 7, k + 16, this.jadeLeaves(world), 0);
        this.setBlock(world, i + 7, j + 7, k + 17, this.jadeLeaves(world), 0);
        this.setBlock(world, i + 7, j + 7, k + 18, this.jadeLeaves(world), 0);
        this.setBlock(world, i + 7, j + 7, k + 19, this.jadeLeaves(world), 0);
        this.setBlock(world, i + 7, j + 7, k + 20, this.jadeLeaves(world), 0);
        this.setBlock(world, i + 7, j + 7, k + 21, this.jadeLeaves(world), 0);
        this.setBlock(world, i + 7, j + 7, k + 22, this.jadeLeaves(world), 0);
        this.setBlock(world, i + 7, j + 7, k + 23, this.jadeLeaves(world), 0);
        this.setBlock(world, i + 7, j + 7, k + 24, this.jadeLeaves(world), 0);
        this.setBlock(world, i + 7, j + 7, k + 25, this.jadeLeaves(world), 0);
        this.setBlock(world, i + 7, j + 7, k + 26, this.jadeLeaves(world), 0);
        this.setBlock(world, i + 7, j + 7, k + 27, this.jadeLeaves(world), 0);
        this.setBlock(world, i + 7, j + 7, k + 28, this.jadeLeaves(world), 0);
        this.setBlock(world, i + 7, j + 7, k + 29, this.jadeLeaves(world), 0);
        this.setBlock(world, i + 7, j + 7, k + 30, this.jadeLeaves(world), 0);
        this.setBlock(world, i + 7, j + 8, k + 18, this.jadeLeaves(world), 0);
        this.setBlock(world, i + 7, j + 8, k + 19, this.jadeLeaves(world), 0);
        this.setBlock(world, i + 7, j + 8, k + 20, this.jadeLeaves(world), 0);
        this.setBlock(world, i + 7, j + 8, k + 21, this.jadeLeaves(world), 0);
        this.setBlock(world, i + 7, j + 8, k + 22, this.jadeLeaves(world), 0);
        this.setBlock(world, i + 7, j + 8, k + 23, this.jadeLeaves(world), 0);
        this.setBlock(world, i + 7, j + 8, k + 24, this.jadeLeaves(world), 0);
        this.setBlock(world, i + 7, j + 8, k + 25, this.jadeLeaves(world), 0);
        this.setBlock(world, i + 7, j + 8, k + 26, this.jadeLeaves(world), 0);
        this.setBlock(world, i + 7, j + 9, k + 20, this.jadeLeaves(world), 0);
        this.setBlock(world, i + 7, j + 9, k + 21, this.jadeLeaves(world), 0);
        this.setBlock(world, i + 7, j + 9, k + 22, this.jadeLeaves(world), 0);
        this.setBlock(world, i + 7, j + 9, k + 23, this.jadeLeaves(world), 0);
        this.setBlock(world, i + 7, j + 9, k + 24, this.jadeLeaves(world), 0);
        this.setBlock(world, i + 8, j + 6, k + 14, this.jadeLeaves(world), 0);
        this.setBlock(world, i + 8, j + 6, k + 15, this.jadeLeaves(world), 0);
        this.setBlock(world, i + 8, j + 6, k + 16, this.jadeLeaves(world), 0);
        this.setBlock(world, i + 8, j + 6, k + 17, this.jadeLeaves(world), 0);
        this.setBlock(world, i + 8, j + 6, k + 18, this.jadeLeaves(world), 0);
        this.setBlock(world, i + 8, j + 6, k + 19, this.jadeLeaves(world), 0);
        this.setBlock(world, i + 8, j + 6, k + 20, this.jadeLeaves(world), 0);
        this.setBlock(world, i + 8, j + 6, k + 21, this.jadeLeaves(world), 0);
        this.setBlock(world, i + 8, j + 6, k + 22, this.jadeLeaves(world), 0);
        this.setBlock(world, i + 8, j + 6, k + 23, this.jadeLeaves(world), 0);
        this.setBlock(world, i + 8, j + 6, k + 24, this.jadeLeaves(world), 0);
        this.setBlock(world, i + 8, j + 6, k + 25, this.jadeLeaves(world), 0);
        this.setBlock(world, i + 8, j + 6, k + 26, this.jadeLeaves(world), 0);
        this.setBlock(world, i + 8, j + 6, k + 27, this.jadeLeaves(world), 0);
        this.setBlock(world, i + 8, j + 7, k + 9, this.jadeLeaves(world), 0);
        this.setBlock(world, i + 8, j + 7, k + 10, this.jadeLeaves(world), 0);
        this.setBlock(world, i + 8, j + 7, k + 11, this.jadeLeaves(world), 0);
        this.setBlock(world, i + 8, j + 7, k + 12, this.jadeLeaves(world), 0);
        this.setBlock(world, i + 8, j + 7, k + 13, this.jadeLeaves(world), 0);
        this.setBlock(world, i + 8, j + 7, k + 14, this.jadeLeaves(world), 0);
        this.setBlock(world, i + 8, j + 7, k + 15, this.jadeLeaves(world), 0);
        this.setBlock(world, i + 8, j + 7, k + 16, this.jadeLeaves(world), 0);
        this.setBlock(world, i + 8, j + 7, k + 17, this.jadeLeaves(world), 0);
        this.setBlock(world, i + 8, j + 7, k + 18, this.jadeLeaves(world), 0);
        this.setBlock(world, i + 8, j + 7, k + 19, this.jadeLeaves(world), 0);
        this.setBlock(world, i + 8, j + 7, k + 20, this.jadeLeaves(world), 0);
        this.setBlock(world, i + 8, j + 7, k + 21, this.jadeLeaves(world), 0);
        this.setBlock(world, i + 8, j + 7, k + 22, this.jadeLeaves(world), 0);
        this.setBlock(world, i + 8, j + 7, k + 23, this.jadeLeaves(world), 0);
        this.setBlock(world, i + 8, j + 7, k + 24, this.jadeLeaves(world), 0);
        this.setBlock(world, i + 8, j + 7, k + 25, this.jadeLeaves(world), 0);
        this.setBlock(world, i + 8, j + 7, k + 26, this.jadeLeaves(world), 0);
        this.setBlock(world, i + 8, j + 7, k + 27, this.jadeLeaves(world), 0);
        this.setBlock(world, i + 8, j + 7, k + 28, this.jadeLeaves(world), 0);
        this.setBlock(world, i + 8, j + 7, k + 29, this.jadeLeaves(world), 0);
        this.setBlock(world, i + 8, j + 7, k + 30, this.jadeLeaves(world), 0);
        this.setBlock(world, i + 8, j + 7, k + 31, this.jadeLeaves(world), 0);
        this.setBlock(world, i + 8, j + 8, k + 15, this.jadeLeaves(world), 0);
        this.setBlock(world, i + 8, j + 8, k + 16, this.jadeLeaves(world), 0);
        this.setBlock(world, i + 8, j + 8, k + 17, this.jadeLeaves(world), 0);
        this.setBlock(world, i + 8, j + 8, k + 18, this.jadeLeaves(world), 0);
        this.setBlock(world, i + 8, j + 8, k + 19, this.jadeLeaves(world), 0);
        this.setBlock(world, i + 8, j + 8, k + 20, this.jadeLeaves(world), 0);
        this.setBlock(world, i + 8, j + 8, k + 21, this.jadeLeaves(world), 0);
        this.setBlock(world, i + 8, j + 8, k + 22, this.jadeLeaves(world), 0);
        this.setBlock(world, i + 8, j + 8, k + 23, this.jadeLeaves(world), 0);
        this.setBlock(world, i + 8, j + 8, k + 24, this.jadeLeaves(world), 0);
        this.setBlock(world, i + 8, j + 8, k + 25, this.jadeLeaves(world), 0);
        this.setBlock(world, i + 8, j + 8, k + 26, this.jadeLeaves(world), 0);
        this.setBlock(world, i + 8, j + 8, k + 27, this.jadeLeaves(world), 0);
        this.setBlock(world, i + 8, j + 9, k + 19, this.jadeLeaves(world), 0);
        this.setBlock(world, i + 8, j + 9, k + 20, this.jadeLeaves(world), 0);
        this.setBlock(world, i + 8, j + 9, k + 21, this.jadeLeaves(world), 0);
        this.setBlock(world, i + 8, j + 9, k + 22, this.jadeLeaves(world), 0);
        this.setBlock(world, i + 8, j + 9, k + 23, this.jadeLeaves(world), 0);
        this.setBlock(world, i + 8, j + 9, k + 24, this.jadeLeaves(world), 0);
        this.setBlock(world, i + 9, j + 5, k + 21, this.jadeLeaves(world), 0);
        this.setBlock(world, i + 9, j + 6, k + 12, this.jadeLeaves(world), 0);
        this.setBlock(world, i + 9, j + 6, k + 13, this.jadeLeaves(world), 0);
        this.setBlock(world, i + 9, j + 6, k + 14, this.jadeLeaves(world), 0);
        this.setBlock(world, i + 9, j + 6, k + 15, this.jadeLeaves(world), 0);
        this.setBlock(world, i + 9, j + 6, k + 16, this.jadeLeaves(world), 0);
        this.setBlock(world, i + 9, j + 6, k + 17, this.jadeLeaves(world), 0);
        this.setBlock(world, i + 9, j + 6, k + 18, this.jadeLeaves(world), 0);
        this.setBlock(world, i + 9, j + 6, k + 19, this.jadeLeaves(world), 0);
        this.setBlock(world, i + 9, j + 6, k + 20, this.jadeLeaves(world), 0);
        this.setBlock(world, i + 9, j + 6, k + 21, this.jadeLeaves(world), 0);
        this.setBlock(world, i + 9, j + 6, k + 22, this.jadeLeaves(world), 0);
        this.setBlock(world, i + 9, j + 6, k + 23, this.jadeLeaves(world), 0);
        this.setBlock(world, i + 9, j + 6, k + 24, this.jadeLeaves(world), 0);
        this.setBlock(world, i + 9, j + 6, k + 25, this.jadeLeaves(world), 0);
        this.setBlock(world, i + 9, j + 6, k + 26, this.jadeLeaves(world), 0);
        this.setBlock(world, i + 9, j + 6, k + 27, this.jadeLeaves(world), 0);
        this.setBlock(world, i + 9, j + 7, k + 8, this.jadeLeaves(world), 0);
        this.setBlock(world, i + 9, j + 7, k + 9, this.jadeLeaves(world), 0);
        this.setBlock(world, i + 9, j + 7, k + 10, this.jadeLeaves(world), 0);
        this.setBlock(world, i + 9, j + 7, k + 11, this.jadeLeaves(world), 0);
        this.setBlock(world, i + 9, j + 7, k + 12, this.jadeLeaves(world), 0);
        this.setBlock(world, i + 9, j + 7, k + 13, this.jadeLeaves(world), 0);
        this.setBlock(world, i + 9, j + 7, k + 14, this.jadeLeaves(world), 0);
        this.setBlock(world, i + 9, j + 7, k + 15, this.jadeLeaves(world), 0);
        this.setBlock(world, i + 9, j + 7, k + 16, this.jadeLeaves(world), 0);
        this.setBlock(world, i + 9, j + 7, k + 17, this.jadeLeaves(world), 0);
        this.setBlock(world, i + 9, j + 7, k + 18, this.jadeLeaves(world), 0);
        this.setBlock(world, i + 9, j + 7, k + 19, this.jadeLeaves(world), 0);
        this.setBlock(world, i + 9, j + 7, k + 20, this.jadeLeaves(world), 0);
        this.setBlock(world, i + 9, j + 7, k + 21, this.jadeLeaves(world), 0);
        this.setBlock(world, i + 9, j + 7, k + 22, this.jadeLeaves(world), 0);
        this.setBlock(world, i + 9, j + 7, k + 23, this.jadeLeaves(world), 0);
        this.setBlock(world, i + 9, j + 7, k + 24, this.jadeLeaves(world), 0);
        this.setBlock(world, i + 9, j + 7, k + 25, this.jadeLeaves(world), 0);
        this.setBlock(world, i + 9, j + 7, k + 26, this.jadeLeaves(world), 0);
        this.setBlock(world, i + 9, j + 7, k + 27, this.jadeLeaves(world), 0);
        this.setBlock(world, i + 9, j + 7, k + 28, this.jadeLeaves(world), 0);
        this.setBlock(world, i + 9, j + 7, k + 29, this.jadeLeaves(world), 0);
        this.setBlock(world, i + 9, j + 7, k + 30, this.jadeLeaves(world), 0);
        this.setBlock(world, i + 9, j + 7, k + 31, this.jadeLeaves(world), 0);
        this.setBlock(world, i + 9, j + 8, k + 13, this.jadeLeaves(world), 0);
        this.setBlock(world, i + 9, j + 8, k + 14, this.jadeLeaves(world), 0);
        this.setBlock(world, i + 9, j + 8, k + 15, this.jadeLeaves(world), 0);
        this.setBlock(world, i + 9, j + 8, k + 16, this.jadeLeaves(world), 0);
        this.setBlock(world, i + 9, j + 8, k + 17, this.jadeLeaves(world), 0);
        this.setBlock(world, i + 9, j + 8, k + 18, this.jadeLeaves(world), 0);
        this.setBlock(world, i + 9, j + 8, k + 19, this.jadeLeaves(world), 0);
        this.setBlock(world, i + 9, j + 8, k + 20, this.jadeLeaves(world), 0);
        this.setBlock(world, i + 9, j + 8, k + 21, this.jadeLeaves(world), 0);
        this.setBlock(world, i + 9, j + 8, k + 22, this.jadeLeaves(world), 0);
        this.setBlock(world, i + 9, j + 8, k + 23, this.jadeLeaves(world), 0);
        this.setBlock(world, i + 9, j + 8, k + 24, this.jadeLeaves(world), 0);
        this.setBlock(world, i + 9, j + 8, k + 25, this.jadeLeaves(world), 0);
        this.setBlock(world, i + 9, j + 8, k + 26, this.jadeLeaves(world), 0);
        this.setBlock(world, i + 9, j + 8, k + 27, this.jadeLeaves(world), 0);
        this.setBlock(world, i + 9, j + 8, k + 28, this.jadeLeaves(world), 0);
        this.setBlock(world, i + 9, j + 9, k + 18, this.jadeLeaves(world), 0);
        this.setBlock(world, i + 9, j + 9, k + 19, this.jadeLeaves(world), 0);
        this.setBlock(world, i + 9, j + 9, k + 20, this.jadeLeaves(world), 0);
        this.setBlock(world, i + 9, j + 9, k + 21, this.jadeLeaves(world), 0);
        this.setBlock(world, i + 9, j + 9, k + 22, this.jadeLeaves(world), 0);
        this.setBlock(world, i + 9, j + 9, k + 23, this.jadeLeaves(world), 0);
        this.setBlock(world, i + 9, j + 9, k + 24, this.jadeLeaves(world), 0);
        this.setBlock(world, i + 10, j + 5, k + 20, this.jadeLeaves(world), 0);
        this.setBlock(world, i + 10, j + 5, k + 21, this.jadeLeaves(world), 0);
        this.setBlock(world, i + 10, j + 5, k + 22, this.jadeLeaves(world), 0);
        this.setBlock(world, i + 10, j + 6, k + 11, this.jadeLeaves(world), 0);
        this.setBlock(world, i + 10, j + 6, k + 12, this.jadeLeaves(world), 0);
        this.setBlock(world, i + 10, j + 6, k + 13, this.jadeLeaves(world), 0);
        this.setBlock(world, i + 10, j + 6, k + 14, this.jadeLeaves(world), 0);
        this.setBlock(world, i + 10, j + 6, k + 15, this.jadeLeaves(world), 0);
        this.setBlock(world, i + 10, j + 6, k + 16, this.jadeLeaves(world), 0);
        this.setBlock(world, i + 10, j + 6, k + 17, this.jadeLeaves(world), 0);
        this.setBlock(world, i + 10, j + 6, k + 18, this.jadeLeaves(world), 0);
        this.setBlock(world, i + 10, j + 6, k + 19, this.jadeLeaves(world), 0);
        this.setBlock(world, i + 10, j + 6, k + 20, this.jadeLeaves(world), 0);
        this.setBlock(world, i + 10, j + 6, k + 21, this.jadeLeaves(world), 0);
        this.setBlock(world, i + 10, j + 6, k + 22, this.jadeLeaves(world), 0);
        this.setBlock(world, i + 10, j + 6, k + 23, this.jadeLeaves(world), 0);
        this.setBlock(world, i + 10, j + 6, k + 24, this.jadeLeaves(world), 0);
        this.setBlock(world, i + 10, j + 6, k + 25, this.jadeLeaves(world), 0);
        this.setBlock(world, i + 10, j + 6, k + 26, this.jadeLeaves(world), 0);
        this.setBlock(world, i + 10, j + 6, k + 27, this.jadeLeaves(world), 0);
        this.setBlock(world, i + 10, j + 7, k + 7, this.jadeLeaves(world), 0);
        this.setBlock(world, i + 10, j + 7, k + 8, this.jadeLeaves(world), 0);
        this.setBlock(world, i + 10, j + 7, k + 9, this.jadeLeaves(world), 0);
        this.setBlock(world, i + 10, j + 7, k + 10, this.jadeLeaves(world), 0);
        this.setBlock(world, i + 10, j + 7, k + 11, this.jadeLeaves(world), 0);
        this.setBlock(world, i + 10, j + 7, k + 12, this.jadeLeaves(world), 0);
        this.setBlock(world, i + 10, j + 7, k + 13, this.jadeLeaves(world), 0);
        this.setBlock(world, i + 10, j + 7, k + 14, this.jadeLeaves(world), 0);
        this.setBlock(world, i + 10, j + 7, k + 15, this.jadeLeaves(world), 0);
        this.setBlock(world, i + 10, j + 7, k + 16, this.jadeLeaves(world), 0);
        this.setBlock(world, i + 10, j + 7, k + 17, this.jadeLeaves(world), 0);
        this.setBlock(world, i + 10, j + 7, k + 18, this.jadeLeaves(world), 0);
        this.setBlock(world, i + 10, j + 7, k + 19, this.jadeLeaves(world), 0);
        this.setBlock(world, i + 10, j + 7, k + 20, this.jadeLeaves(world), 0);
        this.setBlock(world, i + 10, j + 7, k + 21, this.jadeLeaves(world), 0);
        this.setBlock(world, i + 10, j + 7, k + 22, this.jadeLeaves(world), 0);
        this.setBlock(world, i + 10, j + 7, k + 23, this.jadeLeaves(world), 0);
        this.setBlock(world, i + 10, j + 7, k + 24, this.jadeLeaves(world), 0);
        this.setBlock(world, i + 10, j + 7, k + 25, this.jadeLeaves(world), 0);
        this.setBlock(world, i + 10, j + 7, k + 26, this.jadeLeaves(world), 0);
        this.setBlock(world, i + 10, j + 7, k + 27, this.jadeLeaves(world), 0);
        this.setBlock(world, i + 10, j + 7, k + 28, this.jadeLeaves(world), 0);
        this.setBlock(world, i + 10, j + 7, k + 29, this.jadeLeaves(world), 0);
        this.setBlock(world, i + 10, j + 7, k + 30, this.jadeLeaves(world), 0);
        this.setBlock(world, i + 10, j + 7, k + 31, this.jadeLeaves(world), 0);
        this.setBlock(world, i + 10, j + 7, k + 32, this.jadeLeaves(world), 0);
        this.setBlock(world, i + 10, j + 8, k + 12, this.jadeLeaves(world), 0);
        this.setBlock(world, i + 10, j + 8, k + 13, this.jadeLeaves(world), 0);
        this.setBlock(world, i + 10, j + 8, k + 14, this.jadeLeaves(world), 0);
        this.setBlock(world, i + 10, j + 8, k + 15, this.jadeLeaves(world), 0);
        this.setBlock(world, i + 10, j + 8, k + 16, this.jadeLeaves(world), 0);
        this.setBlock(world, i + 10, j + 8, k + 17, this.jadeLeaves(world), 0);
        this.setBlock(world, i + 10, j + 8, k + 18, this.jadeLeaves(world), 0);
        this.setBlock(world, i + 10, j + 8, k + 19, this.jadeLeaves(world), 0);
        this.setBlock(world, i + 10, j + 8, k + 20, this.jadeLeaves(world), 0);
        this.setBlock(world, i + 10, j + 8, k + 21, this.jadeLeaves(world), 0);
        this.setBlock(world, i + 10, j + 8, k + 22, this.jadeLeaves(world), 0);
        this.setBlock(world, i + 10, j + 8, k + 23, this.jadeLeaves(world), 0);
        this.setBlock(world, i + 10, j + 8, k + 24, this.jadeLeaves(world), 0);
        this.setBlock(world, i + 10, j + 8, k + 25, this.jadeLeaves(world), 0);
        this.setBlock(world, i + 10, j + 8, k + 26, this.jadeLeaves(world), 0);
        this.setBlock(world, i + 10, j + 8, k + 27, this.jadeLeaves(world), 0);
        this.setBlock(world, i + 10, j + 8, k + 28, this.jadeLeaves(world), 0);
        this.setBlock(world, i + 10, j + 9, k + 18, this.jadeLeaves(world), 0);
        this.setBlock(world, i + 10, j + 9, k + 19, this.jadeLeaves(world), 0);
        this.setBlock(world, i + 10, j + 9, k + 20, this.jadeLeaves(world), 0);
        this.setBlock(world, i + 10, j + 9, k + 21, this.jadeLeaves(world), 0);
        this.setBlock(world, i + 10, j + 9, k + 22, this.jadeLeaves(world), 0);
        this.setBlock(world, i + 10, j + 9, k + 23, this.jadeLeaves(world), 0);
        this.setBlock(world, i + 10, j + 9, k + 24, this.jadeLeaves(world), 0);
        this.setBlock(world, i + 11, j + 5, k + 18, this.jadeLeaves(world), 0);
        this.setBlock(world, i + 11, j + 5, k + 19, this.jadeLeaves(world), 0);
        this.setBlock(world, i + 11, j + 5, k + 20, this.jadeLeaves(world), 0);
        this.setBlock(world, i + 11, j + 5, k + 21, this.jadeLeaves(world), 0);
        this.setBlock(world, i + 11, j + 5, k + 22, this.jadeLeaves(world), 0);
        this.setBlock(world, i + 11, j + 5, k + 23, this.jadeLeaves(world), 0);
        this.setBlock(world, i + 11, j + 6, k + 11, this.jadeLeaves(world), 0);
        this.setBlock(world, i + 11, j + 6, k + 12, this.jadeLeaves(world), 0);
        this.setBlock(world, i + 11, j + 6, k + 13, this.jadeLeaves(world), 0);
        this.setBlock(world, i + 11, j + 6, k + 14, this.jadeLeaves(world), 0);
        this.setBlock(world, i + 11, j + 6, k + 15, this.jadeLeaves(world), 0);
        this.setBlock(world, i + 11, j + 6, k + 16, this.jadeLeaves(world), 0);
        this.setBlock(world, i + 11, j + 6, k + 17, this.jadeLeaves(world), 0);
        this.setBlock(world, i + 11, j + 6, k + 18, this.jadeLeaves(world), 0);
        this.setBlock(world, i + 11, j + 6, k + 19, this.jadeLeaves(world), 0);
        this.setBlock(world, i + 11, j + 6, k + 20, this.jadeLeaves(world), 0);
        this.setBlock(world, i + 11, j + 6, k + 21, this.jadeLeaves(world), 0);
        this.setBlock(world, i + 11, j + 6, k + 22, this.jadeLeaves(world), 0);
        this.setBlock(world, i + 11, j + 6, k + 23, this.jadeLeaves(world), 0);
        this.setBlock(world, i + 11, j + 6, k + 24, this.jadeLeaves(world), 0);
        this.setBlock(world, i + 11, j + 6, k + 25, this.jadeLeaves(world), 0);
        this.setBlock(world, i + 11, j + 6, k + 26, this.jadeLeaves(world), 0);
        this.setBlock(world, i + 11, j + 6, k + 27, this.jadeLeaves(world), 0);
        this.setBlock(world, i + 11, j + 6, k + 28, this.jadeLeaves(world), 0);
        this.setBlock(world, i + 11, j + 7, k + 4, this.jadeLeaves(world), 0);
        this.setBlock(world, i + 11, j + 7, k + 5, this.jadeLeaves(world), 0);
        this.setBlock(world, i + 11, j + 7, k + 6, this.jadeLeaves(world), 0);
        this.setBlock(world, i + 11, j + 7, k + 7, this.jadeLeaves(world), 0);
        this.setBlock(world, i + 11, j + 7, k + 8, this.jadeLeaves(world), 0);
        this.setBlock(world, i + 11, j + 7, k + 9, this.jadeLeaves(world), 0);
        this.setBlock(world, i + 11, j + 7, k + 10, this.jadeLeaves(world), 0);
        this.setBlock(world, i + 11, j + 7, k + 11, this.jadeLeaves(world), 0);
        this.setBlock(world, i + 11, j + 7, k + 12, this.jadeLeaves(world), 0);
        this.setBlock(world, i + 11, j + 7, k + 13, this.jadeLeaves(world), 0);
        this.setBlock(world, i + 11, j + 7, k + 14, this.jadeLeaves(world), 0);
        this.setBlock(world, i + 11, j + 7, k + 15, this.jadeLeaves(world), 0);
        this.setBlock(world, i + 11, j + 7, k + 16, this.jadeLeaves(world), 0);
        this.setBlock(world, i + 11, j + 7, k + 17, this.jadeLeaves(world), 0);
        this.setBlock(world, i + 11, j + 7, k + 18, this.jadeLeaves(world), 0);
        this.setBlock(world, i + 11, j + 7, k + 19, this.jadeLeaves(world), 0);
        this.setBlock(world, i + 11, j + 7, k + 20, this.jadeLeaves(world), 0);
        this.setBlock(world, i + 11, j + 7, k + 21, this.jadeLeaves(world), 0);
        this.setBlock(world, i + 11, j + 7, k + 22, this.jadeLeaves(world), 0);
        this.setBlock(world, i + 11, j + 7, k + 23, this.jadeLeaves(world), 0);
        this.setBlock(world, i + 11, j + 7, k + 24, this.jadeLeaves(world), 0);
        this.setBlock(world, i + 11, j + 7, k + 25, this.jadeLeaves(world), 0);
        this.setBlock(world, i + 11, j + 7, k + 26, this.jadeLeaves(world), 0);
        this.setBlock(world, i + 11, j + 7, k + 27, this.jadeLeaves(world), 0);
        this.setBlock(world, i + 11, j + 7, k + 28, this.jadeLeaves(world), 0);
        this.setBlock(world, i + 11, j + 7, k + 29, this.jadeLeaves(world), 0);
        this.setBlock(world, i + 11, j + 7, k + 30, this.jadeLeaves(world), 0);
        this.setBlock(world, i + 11, j + 7, k + 31, this.jadeLeaves(world), 0);
        this.setBlock(world, i + 11, j + 7, k + 32, this.jadeLeaves(world), 0);
        this.setBlock(world, i + 11, j + 8, k + 10, this.jadeLeaves(world), 0);
        this.setBlock(world, i + 11, j + 8, k + 11, this.jadeLeaves(world), 0);
        this.setBlock(world, i + 11, j + 8, k + 12, this.jadeLeaves(world), 0);
        this.setBlock(world, i + 11, j + 8, k + 13, this.jadeLeaves(world), 0);
        this.setBlock(world, i + 11, j + 8, k + 14, this.jadeLeaves(world), 0);
        this.setBlock(world, i + 11, j + 8, k + 15, this.jadeLeaves(world), 0);
        this.setBlock(world, i + 11, j + 8, k + 16, this.jadeLeaves(world), 0);
        this.setBlock(world, i + 11, j + 8, k + 17, this.jadeLeaves(world), 0);
        this.setBlock(world, i + 11, j + 8, k + 18, this.jadeLeaves(world), 0);
        this.setBlock(world, i + 11, j + 8, k + 19, this.jadeLeaves(world), 0);
        this.setBlock(world, i + 11, j + 8, k + 20, this.jadeLeaves(world), 0);
        this.setBlock(world, i + 11, j + 8, k + 21, this.jadeLeaves(world), 0);
        this.setBlock(world, i + 11, j + 8, k + 22, this.jadeLeaves(world), 0);
        this.setBlock(world, i + 11, j + 8, k + 23, this.jadeLeaves(world), 0);
        this.setBlock(world, i + 11, j + 8, k + 24, this.jadeLeaves(world), 0);
        this.setBlock(world, i + 11, j + 8, k + 25, this.jadeLeaves(world), 0);
        this.setBlock(world, i + 11, j + 8, k + 26, this.jadeLeaves(world), 0);
        this.setBlock(world, i + 11, j + 8, k + 27, this.jadeLeaves(world), 0);
        this.setBlock(world, i + 11, j + 8, k + 28, this.jadeLeaves(world), 0);
        this.setBlock(world, i + 11, j + 9, k + 17, this.jadeLeaves(world), 0);
        this.setBlock(world, i + 11, j + 9, k + 18, this.jadeLeaves(world), 0);
        this.setBlock(world, i + 11, j + 9, k + 19, this.jadeLeaves(world), 0);
        this.setBlock(world, i + 11, j + 9, k + 20, this.jadeLeaves(world), 0);
        this.setBlock(world, i + 11, j + 9, k + 21, this.jadeLeaves(world), 0);
        this.setBlock(world, i + 11, j + 9, k + 22, this.jadeLeaves(world), 0);
        this.setBlock(world, i + 11, j + 9, k + 23, this.jadeLeaves(world), 0);
        this.setBlock(world, i + 11, j + 9, k + 24, this.jadeLeaves(world), 0);
        this.setBlock(world, i + 11, j + 9, k + 25, this.jadeLeaves(world), 0);
        this.setBlock(world, i + 12, j + 5, k + 17, this.jadeLeaves(world), 0);
        this.setBlock(world, i + 12, j + 5, k + 18, this.jadeLeaves(world), 0);
        this.setBlock(world, i + 12, j + 5, k + 19, this.jadeLeaves(world), 0);
        this.setBlock(world, i + 12, j + 5, k + 20, this.jadeLeaves(world), 0);
        this.setBlock(world, i + 12, j + 5, k + 21, this.jadeLeaves(world), 0);
        this.setBlock(world, i + 12, j + 5, k + 22, this.jadeLeaves(world), 0);
        this.setBlock(world, i + 12, j + 5, k + 23, this.jadeLeaves(world), 0);
        this.setBlock(world, i + 12, j + 5, k + 24, this.jadeLeaves(world), 0);
        this.setBlock(world, i + 12, j + 5, k + 25, this.jadeLeaves(world), 0);
        this.setBlock(world, i + 12, j + 6, k + 9, this.jadeLeaves(world), 0);
        this.setBlock(world, i + 12, j + 6, k + 10, this.jadeLeaves(world), 0);
        this.setBlock(world, i + 12, j + 6, k + 11, this.jadeLeaves(world), 0);
        this.setBlock(world, i + 12, j + 6, k + 12, this.jadeLeaves(world), 0);
        this.setBlock(world, i + 12, j + 6, k + 13, this.jadeLeaves(world), 0);
        this.setBlock(world, i + 12, j + 6, k + 14, this.jadeLeaves(world), 0);
        this.setBlock(world, i + 12, j + 6, k + 15, this.jadeLeaves(world), 0);
        this.setBlock(world, i + 12, j + 6, k + 16, this.jadeLeaves(world), 0);
        this.setBlock(world, i + 12, j + 6, k + 17, this.jadeLeaves(world), 0);
        this.setBlock(world, i + 12, j + 6, k + 18, this.jadeLeaves(world), 0);
        this.setBlock(world, i + 12, j + 6, k + 19, this.jadeLeaves(world), 0);
        this.setBlock(world, i + 12, j + 6, k + 20, this.jadeLeaves(world), 0);
        this.setBlock(world, i + 12, j + 6, k + 21, this.jadeLeaves(world), 0);
        this.setBlock(world, i + 12, j + 6, k + 22, this.jadeLeaves(world), 0);
        this.setBlock(world, i + 12, j + 6, k + 23, this.jadeLeaves(world), 0);
        this.setBlock(world, i + 12, j + 6, k + 24, this.jadeLeaves(world), 0);
        this.setBlock(world, i + 12, j + 6, k + 25, this.jadeLeaves(world), 0);
        this.setBlock(world, i + 12, j + 6, k + 26, this.jadeLeaves(world), 0);
        this.setBlock(world, i + 12, j + 6, k + 27, this.jadeLeaves(world), 0);
        this.setBlock(world, i + 12, j + 6, k + 28, this.jadeLeaves(world), 0);
        this.setBlock(world, i + 12, j + 6, k + 29, this.jadeLeaves(world), 0);
        this.setBlock(world, i + 12, j + 7, k + 4, this.jadeLeaves(world), 0);
        this.setBlock(world, i + 12, j + 7, k + 5, this.jadeLeaves(world), 0);
        this.setBlock(world, i + 12, j + 7, k + 6, this.jadeLeaves(world), 0);
        this.setBlock(world, i + 12, j + 7, k + 7, this.jadeLeaves(world), 0);
        this.setBlock(world, i + 12, j + 7, k + 8, this.jadeLeaves(world), 0);
        this.setBlock(world, i + 12, j + 7, k + 9, this.jadeLeaves(world), 0);
        this.setBlock(world, i + 12, j + 7, k + 10, this.jadeLeaves(world), 0);
        this.setBlock(world, i + 12, j + 7, k + 11, this.jadeLeaves(world), 0);
        this.setBlock(world, i + 12, j + 7, k + 12, this.jadeLeaves(world), 0);
        this.setBlock(world, i + 12, j + 7, k + 13, this.jadeLeaves(world), 0);
        this.setBlock(world, i + 12, j + 7, k + 14, this.jadeLeaves(world), 0);
        this.setBlock(world, i + 12, j + 7, k + 15, this.jadeLeaves(world), 0);
        this.setBlock(world, i + 12, j + 7, k + 16, this.jadeLeaves(world), 0);
        this.setBlock(world, i + 12, j + 7, k + 17, this.jadeLeaves(world), 0);
        this.setBlock(world, i + 12, j + 7, k + 18, this.jadeLeaves(world), 0);
        this.setBlock(world, i + 12, j + 7, k + 19, this.jadeLeaves(world), 0);
        this.setBlock(world, i + 12, j + 7, k + 20, this.jadeLeaves(world), 0);
        this.setBlock(world, i + 12, j + 7, k + 21, this.jadeLeaves(world), 0);
        this.setBlock(world, i + 12, j + 7, k + 22, this.jadeLeaves(world), 0);
        this.setBlock(world, i + 12, j + 7, k + 23, this.jadeLeaves(world), 0);
        this.setBlock(world, i + 12, j + 7, k + 24, this.jadeLeaves(world), 0);
        this.setBlock(world, i + 12, j + 7, k + 25, this.jadeLeaves(world), 0);
        this.setBlock(world, i + 12, j + 7, k + 26, this.jadeLeaves(world), 0);
        this.setBlock(world, i + 12, j + 7, k + 27, this.jadeLeaves(world), 0);
        this.setBlock(world, i + 12, j + 7, k + 28, this.jadeLeaves(world), 0);
        this.setBlock(world, i + 12, j + 7, k + 29, this.jadeLeaves(world), 0);
        this.setBlock(world, i + 12, j + 7, k + 30, this.jadeLeaves(world), 0);
        this.setBlock(world, i + 12, j + 7, k + 31, this.jadeLeaves(world), 0);
        this.setBlock(world, i + 12, j + 7, k + 32, this.jadeLeaves(world), 0);
        this.setBlock(world, i + 12, j + 7, k + 33, this.jadeLeaves(world), 0);
        this.setBlock(world, i + 12, j + 8, k + 9, this.jadeLeaves(world), 0);
        this.setBlock(world, i + 12, j + 8, k + 10, this.jadeLeaves(world), 0);
        this.setBlock(world, i + 12, j + 8, k + 11, this.jadeLeaves(world), 0);
        this.setBlock(world, i + 12, j + 8, k + 12, this.jadeLeaves(world), 0);
        this.setBlock(world, i + 12, j + 8, k + 13, this.jadeLeaves(world), 0);
        this.setBlock(world, i + 12, j + 8, k + 14, this.jadeLeaves(world), 0);
        this.setBlock(world, i + 12, j + 8, k + 15, this.jadeLeaves(world), 0);
        this.setBlock(world, i + 12, j + 8, k + 16, this.jadeLeaves(world), 0);
        this.setBlock(world, i + 12, j + 8, k + 17, this.jadeLeaves(world), 0);
        this.setBlock(world, i + 12, j + 8, k + 18, this.jadeLeaves(world), 0);
        this.setBlock(world, i + 12, j + 8, k + 19, this.jadeLeaves(world), 0);
        this.setBlock(world, i + 12, j + 8, k + 20, this.jadeLeaves(world), 0);
        this.setBlock(world, i + 12, j + 8, k + 21, this.jadeLeaves(world), 0);
        this.setBlock(world, i + 12, j + 8, k + 22, this.jadeLeaves(world), 0);
        this.setBlock(world, i + 12, j + 8, k + 23, this.jadeLeaves(world), 0);
        this.setBlock(world, i + 12, j + 8, k + 24, this.jadeLeaves(world), 0);
        this.setBlock(world, i + 12, j + 8, k + 25, this.jadeLeaves(world), 0);
        this.setBlock(world, i + 12, j + 8, k + 26, this.jadeLeaves(world), 0);
        this.setBlock(world, i + 12, j + 8, k + 27, this.jadeLeaves(world), 0);
        this.setBlock(world, i + 12, j + 8, k + 28, this.jadeLeaves(world), 0);
        this.setBlock(world, i + 12, j + 8, k + 29, this.jadeLeaves(world), 0);
        this.setBlock(world, i + 12, j + 9, k + 15, this.jadeLeaves(world), 0);
        this.setBlock(world, i + 12, j + 9, k + 16, this.jadeLeaves(world), 0);
        this.setBlock(world, i + 12, j + 9, k + 17, this.jadeLeaves(world), 0);
        this.setBlock(world, i + 12, j + 9, k + 18, this.jadeLeaves(world), 0);
        this.setBlock(world, i + 12, j + 9, k + 19, this.jadeLeaves(world), 0);
        this.setBlock(world, i + 12, j + 9, k + 20, this.jadeLeaves(world), 0);
        this.setBlock(world, i + 12, j + 9, k + 21, this.jadeLeaves(world), 0);
        this.setBlock(world, i + 12, j + 9, k + 22, this.jadeLeaves(world), 0);
        this.setBlock(world, i + 12, j + 9, k + 23, this.jadeLeaves(world), 0);
        this.setBlock(world, i + 12, j + 9, k + 24, this.jadeLeaves(world), 0);
        this.setBlock(world, i + 12, j + 9, k + 25, this.jadeLeaves(world), 0);
        this.setBlock(world, i + 13, j + 5, k + 15, this.jadeLeaves(world), 0);
        this.setBlock(world, i + 13, j + 5, k + 16, this.jadeLeaves(world), 0);
        this.setBlock(world, i + 13, j + 5, k + 17, this.jadeLeaves(world), 0);
        this.setBlock(world, i + 13, j + 5, k + 18, this.jadeLeaves(world), 0);
        this.setBlock(world, i + 13, j + 5, k + 19, this.jadeLeaves(world), 0);
        this.setBlock(world, i + 13, j + 5, k + 20, this.jadeLeaves(world), 0);
        this.setBlock(world, i + 13, j + 5, k + 21, this.jadeLeaves(world), 0);
        this.setBlock(world, i + 13, j + 5, k + 22, this.jadeLeaves(world), 0);
        this.setBlock(world, i + 13, j + 5, k + 23, this.jadeLeaves(world), 0);
        this.setBlock(world, i + 13, j + 5, k + 24, this.jadeLeaves(world), 0);
        this.setBlock(world, i + 13, j + 5, k + 25, this.jadeLeaves(world), 0);
        this.setBlock(world, i + 13, j + 5, k + 26, this.jadeLeaves(world), 0);
        this.setBlock(world, i + 13, j + 6, k + 9, this.jadeLeaves(world), 0);
        this.setBlock(world, i + 13, j + 6, k + 10, this.jadeLeaves(world), 0);
        this.setBlock(world, i + 13, j + 6, k + 11, this.jadeLeaves(world), 0);
        this.setBlock(world, i + 13, j + 6, k + 12, this.jadeLeaves(world), 0);
        this.setBlock(world, i + 13, j + 6, k + 13, this.jadeLeaves(world), 0);
        this.setBlock(world, i + 13, j + 6, k + 14, this.jadeLeaves(world), 0);
        this.setBlock(world, i + 13, j + 6, k + 15, this.jadeLeaves(world), 0);
        this.setBlock(world, i + 13, j + 6, k + 16, this.jadeLeaves(world), 0);
        this.setBlock(world, i + 13, j + 6, k + 17, this.jadeLeaves(world), 0);
        this.setBlock(world, i + 13, j + 6, k + 18, this.jadeLeaves(world), 0);
        this.setBlock(world, i + 13, j + 6, k + 19, this.jadeLeaves(world), 0);
        this.setBlock(world, i + 13, j + 6, k + 20, this.jadeLeaves(world), 0);
        this.setBlock(world, i + 13, j + 6, k + 21, this.jadeLeaves(world), 0);
        this.setBlock(world, i + 13, j + 6, k + 22, this.jadeLeaves(world), 0);
        this.setBlock(world, i + 13, j + 6, k + 23, this.jadeLeaves(world), 0);
        this.setBlock(world, i + 13, j + 6, k + 24, this.jadeLeaves(world), 0);
        this.setBlock(world, i + 13, j + 6, k + 25, this.jadeLeaves(world), 0);
        this.setBlock(world, i + 13, j + 6, k + 26, this.jadeLeaves(world), 0);
        this.setBlock(world, i + 13, j + 6, k + 27, this.jadeLeaves(world), 0);
        this.setBlock(world, i + 13, j + 6, k + 28, this.jadeLeaves(world), 0);
        this.setBlock(world, i + 13, j + 6, k + 29, this.jadeLeaves(world), 0);
        this.setBlock(world, i + 13, j + 6, k + 30, this.jadeLeaves(world), 0);
        this.setBlock(world, i + 13, j + 7, k + 3, this.jadeLeaves(world), 0);
        this.setBlock(world, i + 13, j + 7, k + 4, this.jadeLeaves(world), 0);
        this.setBlock(world, i + 13, j + 7, k + 5, this.jadeLeaves(world), 0);
        this.setBlock(world, i + 13, j + 7, k + 6, this.jadeLeaves(world), 0);
        this.setBlock(world, i + 13, j + 7, k + 7, this.jadeLeaves(world), 0);
        this.setBlock(world, i + 13, j + 7, k + 8, this.jadeLeaves(world), 0);
        this.setBlock(world, i + 13, j + 7, k + 9, this.jadeLeaves(world), 0);
        this.setBlock(world, i + 13, j + 7, k + 10, this.jadeLeaves(world), 0);
        this.setBlock(world, i + 13, j + 7, k + 11, this.jadeLeaves(world), 0);
        this.setBlock(world, i + 13, j + 7, k + 12, this.jadeLeaves(world), 0);
        this.setBlock(world, i + 13, j + 7, k + 13, this.jadeLeaves(world), 0);
        this.setBlock(world, i + 13, j + 7, k + 14, this.jadeLeaves(world), 0);
        this.setBlock(world, i + 13, j + 7, k + 15, this.jadeLeaves(world), 0);
        this.setBlock(world, i + 13, j + 7, k + 16, this.jadeLeaves(world), 0);
        this.setBlock(world, i + 13, j + 7, k + 17, this.jadeLeaves(world), 0);
        this.setBlock(world, i + 13, j + 7, k + 18, this.jadeLeaves(world), 0);
        this.setBlock(world, i + 13, j + 7, k + 19, this.jadeLeaves(world), 0);
        this.setBlock(world, i + 13, j + 7, k + 20, this.jadeLeaves(world), 0);
        this.setBlock(world, i + 13, j + 7, k + 21, this.jadeLeaves(world), 0);
        this.setBlock(world, i + 13, j + 7, k + 22, this.jadeLeaves(world), 0);
        this.setBlock(world, i + 13, j + 7, k + 23, this.jadeLeaves(world), 0);
        this.setBlock(world, i + 13, j + 7, k + 24, this.jadeLeaves(world), 0);
        this.setBlock(world, i + 13, j + 7, k + 25, this.jadeLeaves(world), 0);
        this.setBlock(world, i + 13, j + 7, k + 26, this.jadeLeaves(world), 0);
        this.setBlock(world, i + 13, j + 7, k + 27, this.jadeLeaves(world), 0);
        this.setBlock(world, i + 13, j + 7, k + 28, this.jadeLeaves(world), 0);
        this.setBlock(world, i + 13, j + 7, k + 29, this.jadeLeaves(world), 0);
        this.setBlock(world, i + 13, j + 7, k + 30, this.jadeLeaves(world), 0);
        this.setBlock(world, i + 13, j + 7, k + 31, this.jadeLeaves(world), 0);
        this.setBlock(world, i + 13, j + 7, k + 32, this.jadeLeaves(world), 0);
        this.setBlock(world, i + 13, j + 7, k + 33, this.jadeLeaves(world), 0);
        this.setBlock(world, i + 13, j + 8, k + 7, this.jadeLeaves(world), 0);
        this.setBlock(world, i + 13, j + 8, k + 8, this.jadeLeaves(world), 0);
        this.setBlock(world, i + 13, j + 8, k + 9, this.jadeLeaves(world), 0);
        this.setBlock(world, i + 13, j + 8, k + 10, this.jadeLeaves(world), 0);
        this.setBlock(world, i + 13, j + 8, k + 11, this.jadeLeaves(world), 0);
        this.setBlock(world, i + 13, j + 8, k + 12, this.jadeLeaves(world), 0);
        this.setBlock(world, i + 13, j + 8, k + 13, this.jadeLeaves(world), 0);
        this.setBlock(world, i + 13, j + 8, k + 14, this.jadeLeaves(world), 0);
        this.setBlock(world, i + 13, j + 8, k + 15, this.jadeLeaves(world), 0);
        this.setBlock(world, i + 13, j + 8, k + 16, this.jadeLeaves(world), 0);
        this.setBlock(world, i + 13, j + 8, k + 17, this.jadeLeaves(world), 0);
        this.setBlock(world, i + 13, j + 8, k + 18, this.jadeLeaves(world), 0);
        this.setBlock(world, i + 13, j + 8, k + 19, this.jadeLeaves(world), 0);
        this.setBlock(world, i + 13, j + 8, k + 20, this.jadeLeaves(world), 0);
        this.setBlock(world, i + 13, j + 8, k + 21, this.jadeLeaves(world), 0);
        this.setBlock(world, i + 13, j + 8, k + 22, this.jadeLeaves(world), 0);
        this.setBlock(world, i + 13, j + 8, k + 23, this.jadeLeaves(world), 0);
        this.setBlock(world, i + 13, j + 8, k + 24, this.jadeLeaves(world), 0);
        this.setBlock(world, i + 13, j + 8, k + 25, this.jadeLeaves(world), 0);
        this.setBlock(world, i + 13, j + 8, k + 26, this.jadeLeaves(world), 0);
        this.setBlock(world, i + 13, j + 8, k + 27, this.jadeLeaves(world), 0);
        this.setBlock(world, i + 13, j + 8, k + 28, this.jadeLeaves(world), 0);
        this.setBlock(world, i + 13, j + 8, k + 29, this.jadeLeaves(world), 0);
        this.setBlock(world, i + 13, j + 8, k + 30, this.jadeLeaves(world), 0);
        this.setBlock(world, i + 13, j + 9, k + 13, this.jadeLeaves(world), 0);
        this.setBlock(world, i + 13, j + 9, k + 14, this.jadeLeaves(world), 0);
        this.setBlock(world, i + 13, j + 9, k + 15, this.jadeLeaves(world), 0);
        this.setBlock(world, i + 13, j + 9, k + 16, this.jadeLeaves(world), 0);
        this.setBlock(world, i + 13, j + 9, k + 17, this.jadeLeaves(world), 0);
        this.setBlock(world, i + 13, j + 9, k + 18, this.jadeLeaves(world), 0);
        this.setBlock(world, i + 13, j + 9, k + 19, this.jadeLeaves(world), 0);
        this.setBlock(world, i + 13, j + 9, k + 20, this.jadeLeaves(world), 0);
        this.setBlock(world, i + 13, j + 9, k + 21, this.jadeLeaves(world), 0);
        this.setBlock(world, i + 13, j + 9, k + 22, this.jadeLeaves(world), 0);
        this.setBlock(world, i + 13, j + 9, k + 23, this.jadeLeaves(world), 0);
        this.setBlock(world, i + 13, j + 9, k + 24, this.jadeLeaves(world), 0);
        this.setBlock(world, i + 13, j + 9, k + 25, this.jadeLeaves(world), 0);
        this.setBlock(world, i + 13, j + 9, k + 26, this.jadeLeaves(world), 0);
        this.setBlock(world, i + 14, j + 5, k + 14, this.jadeLeaves(world), 0);
        this.setBlock(world, i + 14, j + 5, k + 15, this.jadeLeaves(world), 0);
        this.setBlock(world, i + 14, j + 5, k + 16, this.jadeLeaves(world), 0);
        this.setBlock(world, i + 14, j + 5, k + 17, this.jadeLeaves(world), 0);
        this.setBlock(world, i + 14, j + 5, k + 18, this.jadeLeaves(world), 0);
        this.setBlock(world, i + 14, j + 5, k + 19, this.jadeLeaves(world), 0);
        this.setBlock(world, i + 14, j + 5, k + 20, this.jadeLeaves(world), 0);
        this.setBlock(world, i + 14, j + 5, k + 21, this.jadeLeaves(world), 0);
        this.setBlock(world, i + 14, j + 5, k + 22, this.jadeLeaves(world), 0);
        this.setBlock(world, i + 14, j + 5, k + 23, this.jadeLeaves(world), 0);
        this.setBlock(world, i + 14, j + 5, k + 24, this.jadeLeaves(world), 0);
        this.setBlock(world, i + 14, j + 5, k + 25, this.jadeLeaves(world), 0);
        this.setBlock(world, i + 14, j + 5, k + 26, this.jadeLeaves(world), 0);
        this.setBlock(world, i + 14, j + 6, k + 9, this.jadeLeaves(world), 0);
        this.setBlock(world, i + 14, j + 6, k + 10, this.jadeLeaves(world), 0);
        this.setBlock(world, i + 14, j + 6, k + 11, this.jadeLeaves(world), 0);
        this.setBlock(world, i + 14, j + 6, k + 12, this.jadeLeaves(world), 0);
        this.setBlock(world, i + 14, j + 6, k + 13, this.jadeLeaves(world), 0);
        this.setBlock(world, i + 14, j + 6, k + 14, this.jadeLeaves(world), 0);
        this.setBlock(world, i + 14, j + 6, k + 15, this.jadeLeaves(world), 0);
        this.setBlock(world, i + 14, j + 6, k + 16, this.jadeLeaves(world), 0);
        this.setBlock(world, i + 14, j + 6, k + 17, this.jadeLeaves(world), 0);
        this.setBlock(world, i + 14, j + 6, k + 18, this.jadeLeaves(world), 0);
        this.setBlock(world, i + 14, j + 6, k + 19, this.jadeLeaves(world), 0);
        this.setBlock(world, i + 14, j + 6, k + 20, this.jadeLeaves(world), 0);
        this.setBlock(world, i + 14, j + 6, k + 21, this.jadeLeaves(world), 0);
        this.setBlock(world, i + 14, j + 6, k + 22, this.jadeLeaves(world), 0);
        this.setBlock(world, i + 14, j + 6, k + 23, this.jadeLeaves(world), 0);
        this.setBlock(world, i + 14, j + 6, k + 24, this.jadeLeaves(world), 0);
        this.setBlock(world, i + 14, j + 6, k + 25, this.jadeLeaves(world), 0);
        this.setBlock(world, i + 14, j + 6, k + 26, this.jadeLeaves(world), 0);
        this.setBlock(world, i + 14, j + 6, k + 27, this.jadeLeaves(world), 0);
        this.setBlock(world, i + 14, j + 6, k + 28, this.jadeLeaves(world), 0);
        this.setBlock(world, i + 14, j + 6, k + 29, this.jadeLeaves(world), 0);
        this.setBlock(world, i + 14, j + 6, k + 30, this.jadeLeaves(world), 0);
        this.setBlock(world, i + 14, j + 7, k + 2, this.jadeLeaves(world), 0);
        this.setBlock(world, i + 14, j + 7, k + 3, this.jadeLeaves(world), 0);
        this.setBlock(world, i + 14, j + 7, k + 4, this.jadeLeaves(world), 0);
        this.setBlock(world, i + 14, j + 7, k + 5, this.jadeLeaves(world), 0);
        this.setBlock(world, i + 14, j + 7, k + 6, this.jadeLeaves(world), 0);
        this.setBlock(world, i + 14, j + 7, k + 7, this.jadeLeaves(world), 0);
        this.setBlock(world, i + 14, j + 7, k + 8, this.jadeLeaves(world), 0);
        this.setBlock(world, i + 14, j + 7, k + 9, this.jadeLeaves(world), 0);
        this.setBlock(world, i + 14, j + 7, k + 10, this.jadeLeaves(world), 0);
        this.setBlock(world, i + 14, j + 7, k + 11, this.jadeLeaves(world), 0);
        this.setBlock(world, i + 14, j + 7, k + 12, this.jadeLeaves(world), 0);
        this.setBlock(world, i + 14, j + 7, k + 13, this.jadeLeaves(world), 0);
        this.setBlock(world, i + 14, j + 7, k + 14, this.jadeLeaves(world), 0);
        this.setBlock(world, i + 14, j + 7, k + 15, this.jadeLeaves(world), 0);
        this.setBlock(world, i + 14, j + 7, k + 16, this.jadeLeaves(world), 0);
        this.setBlock(world, i + 14, j + 7, k + 17, this.jadeLeaves(world), 0);
        this.setBlock(world, i + 14, j + 7, k + 18, this.jadeLeaves(world), 0);
        this.setBlock(world, i + 14, j + 7, k + 19, this.jadeLeaves(world), 0);
        this.setBlock(world, i + 14, j + 7, k + 20, this.jadeLeaves(world), 0);
        this.setBlock(world, i + 14, j + 7, k + 21, this.jadeLeaves(world), 0);
        this.setBlock(world, i + 14, j + 7, k + 22, this.jadeLeaves(world), 0);
        this.setBlock(world, i + 14, j + 7, k + 23, this.jadeLeaves(world), 0);
        this.setBlock(world, i + 14, j + 7, k + 24, this.jadeLeaves(world), 0);
        this.setBlock(world, i + 14, j + 7, k + 25, this.jadeLeaves(world), 0);
        this.setBlock(world, i + 14, j + 7, k + 26, this.jadeLeaves(world), 0);
        this.setBlock(world, i + 14, j + 7, k + 27, this.jadeLeaves(world), 0);
        this.setBlock(world, i + 14, j + 7, k + 28, this.jadeLeaves(world), 0);
        this.setBlock(world, i + 14, j + 7, k + 29, this.jadeLeaves(world), 0);
        this.setBlock(world, i + 14, j + 7, k + 30, this.jadeLeaves(world), 0);
        this.setBlock(world, i + 14, j + 7, k + 31, this.jadeLeaves(world), 0);
        this.setBlock(world, i + 14, j + 7, k + 32, this.jadeLeaves(world), 0);
        this.setBlock(world, i + 14, j + 7, k + 33, this.jadeLeaves(world), 0);
        this.setBlock(world, i + 14, j + 7, k + 34, this.jadeLeaves(world), 0);
        this.setBlock(world, i + 14, j + 8, k + 6, this.jadeLeaves(world), 0);
        this.setBlock(world, i + 14, j + 8, k + 7, this.jadeLeaves(world), 0);
        this.setBlock(world, i + 14, j + 8, k + 8, this.jadeLeaves(world), 0);
        this.setBlock(world, i + 14, j + 8, k + 9, this.jadeLeaves(world), 0);
        this.setBlock(world, i + 14, j + 8, k + 10, this.jadeLeaves(world), 0);
        this.setBlock(world, i + 14, j + 8, k + 11, this.jadeLeaves(world), 0);
        this.setBlock(world, i + 14, j + 8, k + 12, this.jadeLeaves(world), 0);
        this.setBlock(world, i + 14, j + 8, k + 13, this.jadeLeaves(world), 0);
        this.setBlock(world, i + 14, j + 8, k + 14, this.jadeLeaves(world), 0);
        this.setBlock(world, i + 14, j + 8, k + 15, this.jadeLeaves(world), 0);
        this.setBlock(world, i + 14, j + 8, k + 16, this.jadeLeaves(world), 0);
        this.setBlock(world, i + 14, j + 8, k + 17, this.jadeLeaves(world), 0);
        this.setBlock(world, i + 14, j + 8, k + 18, this.jadeLeaves(world), 0);
        this.setBlock(world, i + 14, j + 8, k + 19, this.jadeLeaves(world), 0);
        this.setBlock(world, i + 14, j + 8, k + 20, this.jadeLeaves(world), 0);
        this.setBlock(world, i + 14, j + 8, k + 21, this.jadeLeaves(world), 0);
        this.setBlock(world, i + 14, j + 8, k + 22, this.jadeLeaves(world), 0);
        this.setBlock(world, i + 14, j + 8, k + 23, this.jadeLeaves(world), 0);
        this.setBlock(world, i + 14, j + 8, k + 24, this.jadeLeaves(world), 0);
        this.setBlock(world, i + 14, j + 8, k + 25, this.jadeLeaves(world), 0);
        this.setBlock(world, i + 14, j + 8, k + 26, this.jadeLeaves(world), 0);
        this.setBlock(world, i + 14, j + 8, k + 27, this.jadeLeaves(world), 0);
        this.setBlock(world, i + 14, j + 8, k + 28, this.jadeLeaves(world), 0);
        this.setBlock(world, i + 14, j + 8, k + 29, this.jadeLeaves(world), 0);
        this.setBlock(world, i + 14, j + 8, k + 30, this.jadeLeaves(world), 0);
        this.setBlock(world, i + 14, j + 9, k + 13, this.jadeLeaves(world), 0);
        this.setBlock(world, i + 14, j + 9, k + 14, this.jadeLeaves(world), 0);
        this.setBlock(world, i + 14, j + 9, k + 15, this.jadeLeaves(world), 0);
        this.setBlock(world, i + 14, j + 9, k + 16, this.jadeLeaves(world), 0);
        this.setBlock(world, i + 14, j + 9, k + 17, this.jadeLeaves(world), 0);
        this.setBlock(world, i + 14, j + 9, k + 18, this.jadeLeaves(world), 0);
        this.setBlock(world, i + 14, j + 9, k + 19, this.jadeLeaves(world), 0);
        this.setBlock(world, i + 14, j + 9, k + 20, this.jadeLeaves(world), 0);
        this.setBlock(world, i + 14, j + 9, k + 21, this.jadeLeaves(world), 0);
        this.setBlock(world, i + 14, j + 9, k + 22, this.jadeLeaves(world), 0);
        this.setBlock(world, i + 14, j + 9, k + 23, this.jadeLeaves(world), 0);
        this.setBlock(world, i + 14, j + 9, k + 24, this.jadeLeaves(world), 0);
        this.setBlock(world, i + 14, j + 9, k + 25, this.jadeLeaves(world), 0);
        this.setBlock(world, i + 14, j + 9, k + 26, this.jadeLeaves(world), 0);
        this.setBlock(world, i + 14, j + 9, k + 27, this.jadeLeaves(world), 0);
        this.setBlock(world, i + 14, j + 10, k + 19, this.jadeLeaves(world), 0);
        this.setBlock(world, i + 15, j + 5, k + 11, this.jadeLeaves(world), 0);
        this.setBlock(world, i + 15, j + 5, k + 12, this.jadeLeaves(world), 0);
        this.setBlock(world, i + 15, j + 5, k + 13, this.jadeLeaves(world), 0);
        this.setBlock(world, i + 15, j + 5, k + 14, this.jadeLeaves(world), 0);
        this.setBlock(world, i + 15, j + 5, k + 15, this.jadeLeaves(world), 0);
        this.setBlock(world, i + 15, j + 5, k + 16, this.jadeLeaves(world), 0);
        this.setBlock(world, i + 15, j + 5, k + 17, this.jadeLeaves(world), 0);
        this.setBlock(world, i + 15, j + 5, k + 18, this.jadeLeaves(world), 0);
        this.setBlock(world, i + 15, j + 5, k + 19, this.jadeLeaves(world), 0);
        this.setBlock(world, i + 15, j + 5, k + 20, this.jadeLeaves(world), 0);
        this.setBlock(world, i + 15, j + 5, k + 21, this.jadeLeaves(world), 0);
        this.setBlock(world, i + 15, j + 5, k + 22, this.jadeLeaves(world), 0);
        this.setBlock(world, i + 15, j + 5, k + 23, this.jadeLeaves(world), 0);
        this.setBlock(world, i + 15, j + 5, k + 24, this.jadeLeaves(world), 0);
        this.setBlock(world, i + 15, j + 5, k + 25, this.jadeLeaves(world), 0);
        this.setBlock(world, i + 15, j + 5, k + 26, this.jadeLeaves(world), 0);
        this.setBlock(world, i + 15, j + 5, k + 27, this.jadeLeaves(world), 0);
        this.setBlock(world, i + 15, j + 6, k + 8, this.jadeLeaves(world), 0);
        this.setBlock(world, i + 15, j + 6, k + 9, this.jadeLeaves(world), 0);
        this.setBlock(world, i + 15, j + 6, k + 10, this.jadeLeaves(world), 0);
        this.setBlock(world, i + 15, j + 6, k + 11, this.jadeLeaves(world), 0);
        this.setBlock(world, i + 15, j + 6, k + 12, this.jadeLeaves(world), 0);
        this.setBlock(world, i + 15, j + 6, k + 13, this.jadeLeaves(world), 0);
        this.setBlock(world, i + 15, j + 6, k + 14, this.jadeLeaves(world), 0);
        this.setBlock(world, i + 15, j + 6, k + 15, this.jadeLeaves(world), 0);
        this.setBlock(world, i + 15, j + 6, k + 16, this.jadeLeaves(world), 0);
        this.setBlock(world, i + 15, j + 6, k + 17, this.jadeLeaves(world), 0);
        this.setBlock(world, i + 15, j + 6, k + 18, this.jadeLeaves(world), 0);
        this.setBlock(world, i + 15, j + 6, k + 19, this.jadeLeaves(world), 0);
        this.setBlock(world, i + 15, j + 6, k + 20, this.jadeLeaves(world), 0);
        this.setBlock(world, i + 15, j + 6, k + 21, this.jadeLeaves(world), 0);
        this.setBlock(world, i + 15, j + 6, k + 22, this.jadeLeaves(world), 0);
        this.setBlock(world, i + 15, j + 6, k + 23, this.jadeLeaves(world), 0);
        this.setBlock(world, i + 15, j + 6, k + 24, this.jadeLeaves(world), 0);
        this.setBlock(world, i + 15, j + 6, k + 25, this.jadeLeaves(world), 0);
        this.setBlock(world, i + 15, j + 6, k + 26, this.jadeLeaves(world), 0);
        this.setBlock(world, i + 15, j + 6, k + 27, this.jadeLeaves(world), 0);
        this.setBlock(world, i + 15, j + 6, k + 28, this.jadeLeaves(world), 0);
        this.setBlock(world, i + 15, j + 6, k + 29, this.jadeLeaves(world), 0);
        this.setBlock(world, i + 15, j + 6, k + 30, this.jadeLeaves(world), 0);
        this.setBlock(world, i + 15, j + 6, k + 31, this.jadeLeaves(world), 0);
        this.setBlock(world, i + 15, j + 7, k + 2, this.jadeLeaves(world), 0);
        this.setBlock(world, i + 15, j + 7, k + 3, this.jadeLeaves(world), 0);
        this.setBlock(world, i + 15, j + 7, k + 4, this.jadeLeaves(world), 0);
        this.setBlock(world, i + 15, j + 7, k + 5, this.jadeLeaves(world), 0);
        this.setBlock(world, i + 15, j + 7, k + 6, this.jadeLeaves(world), 0);
        this.setBlock(world, i + 15, j + 7, k + 7, this.jadeLeaves(world), 0);
        this.setBlock(world, i + 15, j + 7, k + 8, this.jadeLeaves(world), 0);
        this.setBlock(world, i + 15, j + 7, k + 9, this.jadeLeaves(world), 0);
        this.setBlock(world, i + 15, j + 7, k + 10, this.jadeLeaves(world), 0);
        this.setBlock(world, i + 15, j + 7, k + 11, this.jadeLeaves(world), 0);
        this.setBlock(world, i + 15, j + 7, k + 12, this.jadeLeaves(world), 0);
        this.setBlock(world, i + 15, j + 7, k + 13, this.jadeLeaves(world), 0);
        this.setBlock(world, i + 15, j + 7, k + 14, this.jadeLeaves(world), 0);
        this.setBlock(world, i + 15, j + 7, k + 15, this.jadeLeaves(world), 0);
        this.setBlock(world, i + 15, j + 7, k + 16, this.jadeLeaves(world), 0);
        this.setBlock(world, i + 15, j + 7, k + 17, this.jadeLeaves(world), 0);
        this.setBlock(world, i + 15, j + 7, k + 18, this.jadeLeaves(world), 0);
        this.setBlock(world, i + 15, j + 7, k + 19, this.jadeLeaves(world), 0);
        this.setBlock(world, i + 15, j + 7, k + 20, this.jadeLeaves(world), 0);
        this.setBlock(world, i + 15, j + 7, k + 21, this.jadeLeaves(world), 0);
        this.setBlock(world, i + 15, j + 7, k + 22, this.jadeLeaves(world), 0);
        this.setBlock(world, i + 15, j + 7, k + 23, this.jadeLeaves(world), 0);
        this.setBlock(world, i + 15, j + 7, k + 24, this.jadeLeaves(world), 0);
        this.setBlock(world, i + 15, j + 7, k + 25, this.jadeLeaves(world), 0);
        this.setBlock(world, i + 15, j + 7, k + 26, this.jadeLeaves(world), 0);
        this.setBlock(world, i + 15, j + 7, k + 27, this.jadeLeaves(world), 0);
        this.setBlock(world, i + 15, j + 7, k + 28, this.jadeLeaves(world), 0);
        this.setBlock(world, i + 15, j + 7, k + 29, this.jadeLeaves(world), 0);
        this.setBlock(world, i + 15, j + 7, k + 30, this.jadeLeaves(world), 0);
        this.setBlock(world, i + 15, j + 7, k + 31, this.jadeLeaves(world), 0);
        this.setBlock(world, i + 15, j + 7, k + 32, this.jadeLeaves(world), 0);
        this.setBlock(world, i + 15, j + 7, k + 33, this.jadeLeaves(world), 0);
        this.setBlock(world, i + 15, j + 7, k + 34, this.jadeLeaves(world), 0);
        this.setBlock(world, i + 15, j + 8, k + 5, this.jadeLeaves(world), 0);
        this.setBlock(world, i + 15, j + 8, k + 6, this.jadeLeaves(world), 0);
        this.setBlock(world, i + 15, j + 8, k + 7, this.jadeLeaves(world), 0);
        this.setBlock(world, i + 15, j + 8, k + 8, this.jadeLeaves(world), 0);
        this.setBlock(world, i + 15, j + 8, k + 9, this.jadeLeaves(world), 0);
        this.setBlock(world, i + 15, j + 8, k + 10, this.jadeLeaves(world), 0);
        this.setBlock(world, i + 15, j + 8, k + 11, this.jadeLeaves(world), 0);
        this.setBlock(world, i + 15, j + 8, k + 12, this.jadeLeaves(world), 0);
        this.setBlock(world, i + 15, j + 8, k + 13, this.jadeLeaves(world), 0);
        this.setBlock(world, i + 15, j + 8, k + 14, this.jadeLeaves(world), 0);
        this.setBlock(world, i + 15, j + 8, k + 15, this.jadeLeaves(world), 0);
        this.setBlock(world, i + 15, j + 8, k + 16, this.jadeLeaves(world), 0);
        this.setBlock(world, i + 15, j + 8, k + 17, this.jadeLeaves(world), 0);
        this.setBlock(world, i + 15, j + 8, k + 18, this.jadeLeaves(world), 0);
        this.setBlock(world, i + 15, j + 8, k + 19, this.jadeLeaves(world), 0);
        this.setBlock(world, i + 15, j + 8, k + 20, this.jadeLeaves(world), 0);
        this.setBlock(world, i + 15, j + 8, k + 21, this.jadeLeaves(world), 0);
        this.setBlock(world, i + 15, j + 8, k + 22, this.jadeLeaves(world), 0);
        this.setBlock(world, i + 15, j + 8, k + 23, this.jadeLeaves(world), 0);
        this.setBlock(world, i + 15, j + 8, k + 24, this.jadeLeaves(world), 0);
        this.setBlock(world, i + 15, j + 8, k + 25, this.jadeLeaves(world), 0);
        this.setBlock(world, i + 15, j + 8, k + 26, this.jadeLeaves(world), 0);
        this.setBlock(world, i + 15, j + 8, k + 27, this.jadeLeaves(world), 0);
        this.setBlock(world, i + 15, j + 8, k + 28, this.jadeLeaves(world), 0);
        this.setBlock(world, i + 15, j + 8, k + 29, this.jadeLeaves(world), 0);
        this.setBlock(world, i + 15, j + 8, k + 30, this.jadeLeaves(world), 0);
        this.setBlock(world, i + 15, j + 8, k + 31, this.jadeLeaves(world), 0);
        this.setBlock(world, i + 15, j + 9, k + 11, this.jadeLeaves(world), 0);
        this.setBlock(world, i + 15, j + 9, k + 12, this.jadeLeaves(world), 0);
        this.setBlock(world, i + 15, j + 9, k + 13, this.jadeLeaves(world), 0);
        this.setBlock(world, i + 15, j + 9, k + 14, this.jadeLeaves(world), 0);
        this.setBlock(world, i + 15, j + 9, k + 15, this.jadeLeaves(world), 0);
        this.setBlock(world, i + 15, j + 9, k + 16, this.jadeLeaves(world), 0);
        this.setBlock(world, i + 15, j + 9, k + 17, this.jadeLeaves(world), 0);
        this.setBlock(world, i + 15, j + 9, k + 18, this.jadeLeaves(world), 0);
        this.setBlock(world, i + 15, j + 9, k + 19, this.jadeLeaves(world), 0);
        this.setBlock(world, i + 15, j + 9, k + 20, this.jadeLeaves(world), 0);
        this.setBlock(world, i + 15, j + 9, k + 21, this.jadeLeaves(world), 0);
        this.setBlock(world, i + 15, j + 9, k + 22, this.jadeLeaves(world), 0);
        this.setBlock(world, i + 15, j + 9, k + 23, this.jadeLeaves(world), 0);
        this.setBlock(world, i + 15, j + 9, k + 24, this.jadeLeaves(world), 0);
        this.setBlock(world, i + 15, j + 9, k + 25, this.jadeLeaves(world), 0);
        this.setBlock(world, i + 15, j + 9, k + 26, this.jadeLeaves(world), 0);
        this.setBlock(world, i + 15, j + 9, k + 27, this.jadeLeaves(world), 0);
        this.setBlock(world, i + 15, j + 9, k + 28, this.jadeLeaves(world), 0);
        this.setBlock(world, i + 15, j + 10, k + 19, this.jadeLeaves(world), 0);
        this.setBlock(world, i + 15, j + 10, k + 20, this.jadeLeaves(world), 0);
        this.setBlock(world, i + 15, j + 10, k + 21, this.jadeLeaves(world), 0);
        this.setBlock(world, i + 16, j + 0, k + 19, Dungeons.jadeLog, 0);
        this.setBlock(world, i + 16, j + 4, k + 17, this.jadeLeaves(world), 0);
        this.setBlock(world, i + 16, j + 4, k + 18, this.jadeLeaves(world), 0);
        this.setBlock(world, i + 16, j + 4, k + 19, this.jadeLeaves(world), 0);
        this.setBlock(world, i + 16, j + 5, k + 11, this.jadeLeaves(world), 0);
        this.setBlock(world, i + 16, j + 5, k + 12, this.jadeLeaves(world), 0);
        this.setBlock(world, i + 16, j + 5, k + 13, this.jadeLeaves(world), 0);
        this.setBlock(world, i + 16, j + 5, k + 14, this.jadeLeaves(world), 0);
        this.setBlock(world, i + 16, j + 5, k + 15, this.jadeLeaves(world), 0);
        this.setBlock(world, i + 16, j + 5, k + 16, this.jadeLeaves(world), 0);
        this.setBlock(world, i + 16, j + 5, k + 17, this.jadeLeaves(world), 0);
        this.setBlock(world, i + 16, j + 5, k + 18, this.jadeLeaves(world), 0);
        this.setBlock(world, i + 16, j + 5, k + 19, this.jadeLeaves(world), 0);
        this.setBlock(world, i + 16, j + 5, k + 20, this.jadeLeaves(world), 0);
        this.setBlock(world, i + 16, j + 5, k + 21, this.jadeLeaves(world), 0);
        this.setBlock(world, i + 16, j + 5, k + 22, this.jadeLeaves(world), 0);
        this.setBlock(world, i + 16, j + 5, k + 23, this.jadeLeaves(world), 0);
        this.setBlock(world, i + 16, j + 5, k + 24, this.jadeLeaves(world), 0);
        this.setBlock(world, i + 16, j + 5, k + 25, this.jadeLeaves(world), 0);
        this.setBlock(world, i + 16, j + 5, k + 26, this.jadeLeaves(world), 0);
        this.setBlock(world, i + 16, j + 5, k + 27, this.jadeLeaves(world), 0);
        this.setBlock(world, i + 16, j + 6, k + 7, this.jadeLeaves(world), 0);
        this.setBlock(world, i + 16, j + 6, k + 8, this.jadeLeaves(world), 0);
        this.setBlock(world, i + 16, j + 6, k + 9, this.jadeLeaves(world), 0);
        this.setBlock(world, i + 16, j + 6, k + 10, this.jadeLeaves(world), 0);
        this.setBlock(world, i + 16, j + 6, k + 11, this.jadeLeaves(world), 0);
        this.setBlock(world, i + 16, j + 6, k + 12, this.jadeLeaves(world), 0);
        this.setBlock(world, i + 16, j + 6, k + 13, this.jadeLeaves(world), 0);
        this.setBlock(world, i + 16, j + 6, k + 14, this.jadeLeaves(world), 0);
        this.setBlock(world, i + 16, j + 6, k + 15, this.jadeLeaves(world), 0);
        this.setBlock(world, i + 16, j + 6, k + 16, this.jadeLeaves(world), 0);
        this.setBlock(world, i + 16, j + 6, k + 17, this.jadeLeaves(world), 0);
        this.setBlock(world, i + 16, j + 6, k + 18, this.jadeLeaves(world), 0);
        this.setBlock(world, i + 16, j + 6, k + 19, this.jadeLeaves(world), 0);
        this.setBlock(world, i + 16, j + 6, k + 20, this.jadeLeaves(world), 0);
        this.setBlock(world, i + 16, j + 6, k + 21, this.jadeLeaves(world), 0);
        this.setBlock(world, i + 16, j + 6, k + 22, this.jadeLeaves(world), 0);
        this.setBlock(world, i + 16, j + 6, k + 23, this.jadeLeaves(world), 0);
        this.setBlock(world, i + 16, j + 6, k + 24, this.jadeLeaves(world), 0);
        this.setBlock(world, i + 16, j + 6, k + 25, this.jadeLeaves(world), 0);
        this.setBlock(world, i + 16, j + 6, k + 26, this.jadeLeaves(world), 0);
        this.setBlock(world, i + 16, j + 6, k + 27, this.jadeLeaves(world), 0);
        this.setBlock(world, i + 16, j + 6, k + 28, this.jadeLeaves(world), 0);
        this.setBlock(world, i + 16, j + 6, k + 29, this.jadeLeaves(world), 0);
        this.setBlock(world, i + 16, j + 6, k + 30, this.jadeLeaves(world), 0);
        this.setBlock(world, i + 16, j + 6, k + 31, this.jadeLeaves(world), 0);
        this.setBlock(world, i + 16, j + 7, k + 1, this.jadeLeaves(world), 0);
        this.setBlock(world, i + 16, j + 7, k + 2, this.jadeLeaves(world), 0);
        this.setBlock(world, i + 16, j + 7, k + 3, this.jadeLeaves(world), 0);
        this.setBlock(world, i + 16, j + 7, k + 4, this.jadeLeaves(world), 0);
        this.setBlock(world, i + 16, j + 7, k + 5, this.jadeLeaves(world), 0);
        this.setBlock(world, i + 16, j + 7, k + 6, this.jadeLeaves(world), 0);
        this.setBlock(world, i + 16, j + 7, k + 7, this.jadeLeaves(world), 0);
        this.setBlock(world, i + 16, j + 7, k + 8, this.jadeLeaves(world), 0);
        this.setBlock(world, i + 16, j + 7, k + 9, this.jadeLeaves(world), 0);
        this.setBlock(world, i + 16, j + 7, k + 10, this.jadeLeaves(world), 0);
        this.setBlock(world, i + 16, j + 7, k + 11, this.jadeLeaves(world), 0);
        this.setBlock(world, i + 16, j + 7, k + 12, this.jadeLeaves(world), 0);
        this.setBlock(world, i + 16, j + 7, k + 13, this.jadeLeaves(world), 0);
        this.setBlock(world, i + 16, j + 7, k + 14, this.jadeLeaves(world), 0);
        this.setBlock(world, i + 16, j + 7, k + 15, this.jadeLeaves(world), 0);
        this.setBlock(world, i + 16, j + 7, k + 16, this.jadeLeaves(world), 0);
        this.setBlock(world, i + 16, j + 7, k + 17, this.jadeLeaves(world), 0);
        this.setBlock(world, i + 16, j + 7, k + 18, this.jadeLeaves(world), 0);
        this.setBlock(world, i + 16, j + 7, k + 19, this.jadeLeaves(world), 0);
        this.setBlock(world, i + 16, j + 7, k + 20, this.jadeLeaves(world), 0);
        this.setBlock(world, i + 16, j + 7, k + 21, this.jadeLeaves(world), 0);
        this.setBlock(world, i + 16, j + 7, k + 22, this.jadeLeaves(world), 0);
        this.setBlock(world, i + 16, j + 7, k + 23, this.jadeLeaves(world), 0);
        this.setBlock(world, i + 16, j + 7, k + 24, this.jadeLeaves(world), 0);
        this.setBlock(world, i + 16, j + 7, k + 25, this.jadeLeaves(world), 0);
        this.setBlock(world, i + 16, j + 7, k + 26, this.jadeLeaves(world), 0);
        this.setBlock(world, i + 16, j + 7, k + 27, this.jadeLeaves(world), 0);
        this.setBlock(world, i + 16, j + 7, k + 28, this.jadeLeaves(world), 0);
        this.setBlock(world, i + 16, j + 7, k + 29, this.jadeLeaves(world), 0);
        this.setBlock(world, i + 16, j + 7, k + 30, this.jadeLeaves(world), 0);
        this.setBlock(world, i + 16, j + 7, k + 31, this.jadeLeaves(world), 0);
        this.setBlock(world, i + 16, j + 7, k + 32, this.jadeLeaves(world), 0);
        this.setBlock(world, i + 16, j + 7, k + 33, this.jadeLeaves(world), 0);
        this.setBlock(world, i + 16, j + 7, k + 34, this.jadeLeaves(world), 0);
        this.setBlock(world, i + 16, j + 7, k + 35, this.jadeLeaves(world), 0);
        this.setBlock(world, i + 16, j + 8, k + 5, this.jadeLeaves(world), 0);
        this.setBlock(world, i + 16, j + 8, k + 6, this.jadeLeaves(world), 0);
        this.setBlock(world, i + 16, j + 8, k + 7, this.jadeLeaves(world), 0);
        this.setBlock(world, i + 16, j + 8, k + 8, this.jadeLeaves(world), 0);
        this.setBlock(world, i + 16, j + 8, k + 9, this.jadeLeaves(world), 0);
        this.setBlock(world, i + 16, j + 8, k + 10, this.jadeLeaves(world), 0);
        this.setBlock(world, i + 16, j + 8, k + 11, this.jadeLeaves(world), 0);
        this.setBlock(world, i + 16, j + 8, k + 12, this.jadeLeaves(world), 0);
        this.setBlock(world, i + 16, j + 8, k + 13, this.jadeLeaves(world), 0);
        this.setBlock(world, i + 16, j + 8, k + 14, this.jadeLeaves(world), 0);
        this.setBlock(world, i + 16, j + 8, k + 15, this.jadeLeaves(world), 0);
        this.setBlock(world, i + 16, j + 8, k + 16, this.jadeLeaves(world), 0);
        this.setBlock(world, i + 16, j + 8, k + 17, this.jadeLeaves(world), 0);
        this.setBlock(world, i + 16, j + 8, k + 18, this.jadeLeaves(world), 0);
        this.setBlock(world, i + 16, j + 8, k + 19, this.jadeLeaves(world), 0);
        this.setBlock(world, i + 16, j + 8, k + 20, this.jadeLeaves(world), 0);
        this.setBlock(world, i + 16, j + 8, k + 21, this.jadeLeaves(world), 0);
        this.setBlock(world, i + 16, j + 8, k + 22, this.jadeLeaves(world), 0);
        this.setBlock(world, i + 16, j + 8, k + 23, this.jadeLeaves(world), 0);
        this.setBlock(world, i + 16, j + 8, k + 24, this.jadeLeaves(world), 0);
        this.setBlock(world, i + 16, j + 8, k + 25, this.jadeLeaves(world), 0);
        this.setBlock(world, i + 16, j + 8, k + 26, this.jadeLeaves(world), 0);
        this.setBlock(world, i + 16, j + 8, k + 27, this.jadeLeaves(world), 0);
        this.setBlock(world, i + 16, j + 8, k + 28, this.jadeLeaves(world), 0);
        this.setBlock(world, i + 16, j + 8, k + 29, this.jadeLeaves(world), 0);
        this.setBlock(world, i + 16, j + 8, k + 30, this.jadeLeaves(world), 0);
        this.setBlock(world, i + 16, j + 8, k + 31, this.jadeLeaves(world), 0);
        this.setBlock(world, i + 16, j + 9, k + 8, this.jadeLeaves(world), 0);
        this.setBlock(world, i + 16, j + 9, k + 9, this.jadeLeaves(world), 0);
        this.setBlock(world, i + 16, j + 9, k + 10, this.jadeLeaves(world), 0);
        this.setBlock(world, i + 16, j + 9, k + 11, this.jadeLeaves(world), 0);
        this.setBlock(world, i + 16, j + 9, k + 12, this.jadeLeaves(world), 0);
        this.setBlock(world, i + 16, j + 9, k + 13, this.jadeLeaves(world), 0);
        this.setBlock(world, i + 16, j + 9, k + 14, this.jadeLeaves(world), 0);
        this.setBlock(world, i + 16, j + 9, k + 15, this.jadeLeaves(world), 0);
        this.setBlock(world, i + 16, j + 9, k + 16, this.jadeLeaves(world), 0);
        this.setBlock(world, i + 16, j + 9, k + 17, this.jadeLeaves(world), 0);
        this.setBlock(world, i + 16, j + 9, k + 18, this.jadeLeaves(world), 0);
        this.setBlock(world, i + 16, j + 9, k + 19, this.jadeLeaves(world), 0);
        this.setBlock(world, i + 16, j + 9, k + 20, this.jadeLeaves(world), 0);
        this.setBlock(world, i + 16, j + 9, k + 21, this.jadeLeaves(world), 0);
        this.setBlock(world, i + 16, j + 9, k + 22, this.jadeLeaves(world), 0);
        this.setBlock(world, i + 16, j + 9, k + 23, this.jadeLeaves(world), 0);
        this.setBlock(world, i + 16, j + 9, k + 24, this.jadeLeaves(world), 0);
        this.setBlock(world, i + 16, j + 9, k + 25, this.jadeLeaves(world), 0);
        this.setBlock(world, i + 16, j + 9, k + 26, this.jadeLeaves(world), 0);
        this.setBlock(world, i + 16, j + 9, k + 27, this.jadeLeaves(world), 0);
        this.setBlock(world, i + 16, j + 9, k + 28, this.jadeLeaves(world), 0);
        this.setBlock(world, i + 16, j + 9, k + 29, this.jadeLeaves(world), 0);
        this.setBlock(world, i + 16, j + 10, k + 18, this.jadeLeaves(world), 0);
        this.setBlock(world, i + 16, j + 10, k + 19, this.jadeLeaves(world), 0);
        this.setBlock(world, i + 16, j + 10, k + 20, this.jadeLeaves(world), 0);
        this.setBlock(world, i + 16, j + 10, k + 21, this.jadeLeaves(world), 0);
        this.setBlock(world, i + 17, j + 0, k + 18, Dungeons.jadeLog, 0);
        this.setBlock(world, i + 17, j + 0, k + 19, Dungeons.jadeLog, 0);
        this.setBlock(world, i + 17, j + 0, k + 20, Dungeons.jadeLog, 0);
        this.setBlock(world, i + 17, j + 1, k + 19, Dungeons.jadeLog, 0);
        this.setBlock(world, i + 17, j + 4, k + 17, this.jadeLeaves(world), 0);
        this.setBlock(world, i + 17, j + 4, k + 18, this.jadeLeaves(world), 0);
        this.setBlock(world, i + 17, j + 4, k + 19, this.jadeLeaves(world), 0);
        this.setBlock(world, i + 17, j + 4, k + 20, this.jadeLeaves(world), 0);
        this.setBlock(world, i + 17, j + 4, k + 21, this.jadeLeaves(world), 0);
        this.setBlock(world, i + 17, j + 5, k + 10, this.jadeLeaves(world), 0);
        this.setBlock(world, i + 17, j + 5, k + 11, this.jadeLeaves(world), 0);
        this.setBlock(world, i + 17, j + 5, k + 12, this.jadeLeaves(world), 0);
        this.setBlock(world, i + 17, j + 5, k + 13, this.jadeLeaves(world), 0);
        this.setBlock(world, i + 17, j + 5, k + 14, this.jadeLeaves(world), 0);
        this.setBlock(world, i + 17, j + 5, k + 15, this.jadeLeaves(world), 0);
        this.setBlock(world, i + 17, j + 5, k + 16, this.jadeLeaves(world), 0);
        this.setBlock(world, i + 17, j + 5, k + 17, this.jadeLeaves(world), 0);
        this.setBlock(world, i + 17, j + 5, k + 18, this.jadeLeaves(world), 0);
        this.setBlock(world, i + 17, j + 5, k + 19, this.jadeLeaves(world), 0);
        this.setBlock(world, i + 17, j + 5, k + 20, this.jadeLeaves(world), 0);
        this.setBlock(world, i + 17, j + 5, k + 21, this.jadeLeaves(world), 0);
        this.setBlock(world, i + 17, j + 5, k + 22, this.jadeLeaves(world), 0);
        this.setBlock(world, i + 17, j + 5, k + 23, this.jadeLeaves(world), 0);
        this.setBlock(world, i + 17, j + 5, k + 24, this.jadeLeaves(world), 0);
        this.setBlock(world, i + 17, j + 5, k + 25, this.jadeLeaves(world), 0);
        this.setBlock(world, i + 17, j + 5, k + 26, this.jadeLeaves(world), 0);
        this.setBlock(world, i + 17, j + 5, k + 27, this.jadeLeaves(world), 0);
        this.setBlock(world, i + 17, j + 5, k + 28, this.jadeLeaves(world), 0);
        this.setBlock(world, i + 17, j + 6, k + 6, this.jadeLeaves(world), 0);
        this.setBlock(world, i + 17, j + 6, k + 7, this.jadeLeaves(world), 0);
        this.setBlock(world, i + 17, j + 6, k + 8, this.jadeLeaves(world), 0);
        this.setBlock(world, i + 17, j + 6, k + 9, this.jadeLeaves(world), 0);
        this.setBlock(world, i + 17, j + 6, k + 10, this.jadeLeaves(world), 0);
        this.setBlock(world, i + 17, j + 6, k + 11, this.jadeLeaves(world), 0);
        this.setBlock(world, i + 17, j + 6, k + 12, this.jadeLeaves(world), 0);
        this.setBlock(world, i + 17, j + 6, k + 13, this.jadeLeaves(world), 0);
        this.setBlock(world, i + 17, j + 6, k + 14, this.jadeLeaves(world), 0);
        this.setBlock(world, i + 17, j + 6, k + 15, this.jadeLeaves(world), 0);
        this.setBlock(world, i + 17, j + 6, k + 16, this.jadeLeaves(world), 0);
        this.setBlock(world, i + 17, j + 6, k + 17, this.jadeLeaves(world), 0);
        this.setBlock(world, i + 17, j + 6, k + 18, this.jadeLeaves(world), 0);
        this.setBlock(world, i + 17, j + 6, k + 19, this.jadeLeaves(world), 0);
        this.setBlock(world, i + 17, j + 6, k + 20, this.jadeLeaves(world), 0);
        this.setBlock(world, i + 17, j + 6, k + 21, this.jadeLeaves(world), 0);
        this.setBlock(world, i + 17, j + 6, k + 22, this.jadeLeaves(world), 0);
        this.setBlock(world, i + 17, j + 6, k + 23, this.jadeLeaves(world), 0);
        this.setBlock(world, i + 17, j + 6, k + 24, this.jadeLeaves(world), 0);
        this.setBlock(world, i + 17, j + 6, k + 25, this.jadeLeaves(world), 0);
        this.setBlock(world, i + 17, j + 6, k + 26, this.jadeLeaves(world), 0);
        this.setBlock(world, i + 17, j + 6, k + 27, this.jadeLeaves(world), 0);
        this.setBlock(world, i + 17, j + 6, k + 28, this.jadeLeaves(world), 0);
        this.setBlock(world, i + 17, j + 6, k + 29, this.jadeLeaves(world), 0);
        this.setBlock(world, i + 17, j + 6, k + 30, this.jadeLeaves(world), 0);
        this.setBlock(world, i + 17, j + 6, k + 31, this.jadeLeaves(world), 0);
        this.setBlock(world, i + 17, j + 6, k + 32, this.jadeLeaves(world), 0);
        this.setBlock(world, i + 17, j + 7, k + 1, this.jadeLeaves(world), 0);
        this.setBlock(world, i + 17, j + 7, k + 2, this.jadeLeaves(world), 0);
        this.setBlock(world, i + 17, j + 7, k + 3, this.jadeLeaves(world), 0);
        this.setBlock(world, i + 17, j + 7, k + 4, this.jadeLeaves(world), 0);
        this.setBlock(world, i + 17, j + 7, k + 5, this.jadeLeaves(world), 0);
        this.setBlock(world, i + 17, j + 7, k + 6, this.jadeLeaves(world), 0);
        this.setBlock(world, i + 17, j + 7, k + 7, this.jadeLeaves(world), 0);
        this.setBlock(world, i + 17, j + 7, k + 8, this.jadeLeaves(world), 0);
        this.setBlock(world, i + 17, j + 7, k + 9, this.jadeLeaves(world), 0);
        this.setBlock(world, i + 17, j + 7, k + 10, this.jadeLeaves(world), 0);
        this.setBlock(world, i + 17, j + 7, k + 11, this.jadeLeaves(world), 0);
        this.setBlock(world, i + 17, j + 7, k + 12, this.jadeLeaves(world), 0);
        this.setBlock(world, i + 17, j + 7, k + 13, this.jadeLeaves(world), 0);
        this.setBlock(world, i + 17, j + 7, k + 14, this.jadeLeaves(world), 0);
        this.setBlock(world, i + 17, j + 7, k + 15, this.jadeLeaves(world), 0);
        this.setBlock(world, i + 17, j + 7, k + 16, this.jadeLeaves(world), 0);
        this.setBlock(world, i + 17, j + 7, k + 17, this.jadeLeaves(world), 0);
        this.setBlock(world, i + 17, j + 7, k + 18, this.jadeLeaves(world), 0);
        this.setBlock(world, i + 17, j + 7, k + 19, this.jadeLeaves(world), 0);
        this.setBlock(world, i + 17, j + 7, k + 20, this.jadeLeaves(world), 0);
        this.setBlock(world, i + 17, j + 7, k + 21, this.jadeLeaves(world), 0);
        this.setBlock(world, i + 17, j + 7, k + 22, this.jadeLeaves(world), 0);
        this.setBlock(world, i + 17, j + 7, k + 23, this.jadeLeaves(world), 0);
        this.setBlock(world, i + 17, j + 7, k + 24, this.jadeLeaves(world), 0);
        this.setBlock(world, i + 17, j + 7, k + 25, this.jadeLeaves(world), 0);
        this.setBlock(world, i + 17, j + 7, k + 26, this.jadeLeaves(world), 0);
        this.setBlock(world, i + 17, j + 7, k + 27, this.jadeLeaves(world), 0);
        this.setBlock(world, i + 17, j + 7, k + 28, this.jadeLeaves(world), 0);
        this.setBlock(world, i + 17, j + 7, k + 29, this.jadeLeaves(world), 0);
        this.setBlock(world, i + 17, j + 7, k + 30, this.jadeLeaves(world), 0);
        this.setBlock(world, i + 17, j + 7, k + 31, this.jadeLeaves(world), 0);
        this.setBlock(world, i + 17, j + 7, k + 32, this.jadeLeaves(world), 0);
        this.setBlock(world, i + 17, j + 7, k + 33, this.jadeLeaves(world), 0);
        this.setBlock(world, i + 17, j + 7, k + 34, this.jadeLeaves(world), 0);
        this.setBlock(world, i + 17, j + 7, k + 35, this.jadeLeaves(world), 0);
        this.setBlock(world, i + 17, j + 8, k + 5, this.jadeLeaves(world), 0);
        this.setBlock(world, i + 17, j + 8, k + 6, this.jadeLeaves(world), 0);
        this.setBlock(world, i + 17, j + 8, k + 7, this.jadeLeaves(world), 0);
        this.setBlock(world, i + 17, j + 8, k + 8, this.jadeLeaves(world), 0);
        this.setBlock(world, i + 17, j + 8, k + 9, this.jadeLeaves(world), 0);
        this.setBlock(world, i + 17, j + 8, k + 10, this.jadeLeaves(world), 0);
        this.setBlock(world, i + 17, j + 8, k + 11, this.jadeLeaves(world), 0);
        this.setBlock(world, i + 17, j + 8, k + 12, this.jadeLeaves(world), 0);
        this.setBlock(world, i + 17, j + 8, k + 13, this.jadeLeaves(world), 0);
        this.setBlock(world, i + 17, j + 8, k + 14, this.jadeLeaves(world), 0);
        this.setBlock(world, i + 17, j + 8, k + 15, this.jadeLeaves(world), 0);
        this.setBlock(world, i + 17, j + 8, k + 16, this.jadeLeaves(world), 0);
        this.setBlock(world, i + 17, j + 8, k + 17, this.jadeLeaves(world), 0);
        this.setBlock(world, i + 17, j + 8, k + 18, this.jadeLeaves(world), 0);
        this.setBlock(world, i + 17, j + 8, k + 19, this.jadeLeaves(world), 0);
        this.setBlock(world, i + 17, j + 8, k + 20, this.jadeLeaves(world), 0);
        this.setBlock(world, i + 17, j + 8, k + 21, this.jadeLeaves(world), 0);
        this.setBlock(world, i + 17, j + 8, k + 22, this.jadeLeaves(world), 0);
        this.setBlock(world, i + 17, j + 8, k + 23, this.jadeLeaves(world), 0);
        this.setBlock(world, i + 17, j + 8, k + 24, this.jadeLeaves(world), 0);
        this.setBlock(world, i + 17, j + 8, k + 25, this.jadeLeaves(world), 0);
        this.setBlock(world, i + 17, j + 8, k + 26, this.jadeLeaves(world), 0);
        this.setBlock(world, i + 17, j + 8, k + 27, this.jadeLeaves(world), 0);
        this.setBlock(world, i + 17, j + 8, k + 28, this.jadeLeaves(world), 0);
        this.setBlock(world, i + 17, j + 8, k + 29, this.jadeLeaves(world), 0);
        this.setBlock(world, i + 17, j + 8, k + 30, this.jadeLeaves(world), 0);
        this.setBlock(world, i + 17, j + 8, k + 31, this.jadeLeaves(world), 0);
        this.setBlock(world, i + 17, j + 8, k + 32, this.jadeLeaves(world), 0);
        this.setBlock(world, i + 17, j + 9, k + 6, this.jadeLeaves(world), 0);
        this.setBlock(world, i + 17, j + 9, k + 7, this.jadeLeaves(world), 0);
        this.setBlock(world, i + 17, j + 9, k + 8, this.jadeLeaves(world), 0);
        this.setBlock(world, i + 17, j + 9, k + 9, this.jadeLeaves(world), 0);
        this.setBlock(world, i + 17, j + 9, k + 10, this.jadeLeaves(world), 0);
        this.setBlock(world, i + 17, j + 9, k + 11, this.jadeLeaves(world), 0);
        this.setBlock(world, i + 17, j + 9, k + 12, this.jadeLeaves(world), 0);
        this.setBlock(world, i + 17, j + 9, k + 13, this.jadeLeaves(world), 0);
        this.setBlock(world, i + 17, j + 9, k + 14, this.jadeLeaves(world), 0);
        this.setBlock(world, i + 17, j + 9, k + 15, this.jadeLeaves(world), 0);
        this.setBlock(world, i + 17, j + 9, k + 16, this.jadeLeaves(world), 0);
        this.setBlock(world, i + 17, j + 9, k + 17, this.jadeLeaves(world), 0);
        this.setBlock(world, i + 17, j + 9, k + 18, this.jadeLeaves(world), 0);
        this.setBlock(world, i + 17, j + 9, k + 19, this.jadeLeaves(world), 0);
        this.setBlock(world, i + 17, j + 9, k + 20, this.jadeLeaves(world), 0);
        this.setBlock(world, i + 17, j + 9, k + 21, this.jadeLeaves(world), 0);
        this.setBlock(world, i + 17, j + 9, k + 22, this.jadeLeaves(world), 0);
        this.setBlock(world, i + 17, j + 9, k + 23, this.jadeLeaves(world), 0);
        this.setBlock(world, i + 17, j + 9, k + 24, this.jadeLeaves(world), 0);
        this.setBlock(world, i + 17, j + 9, k + 25, this.jadeLeaves(world), 0);
        this.setBlock(world, i + 17, j + 9, k + 26, this.jadeLeaves(world), 0);
        this.setBlock(world, i + 17, j + 9, k + 27, this.jadeLeaves(world), 0);
        this.setBlock(world, i + 17, j + 9, k + 28, this.jadeLeaves(world), 0);
        this.setBlock(world, i + 17, j + 9, k + 29, this.jadeLeaves(world), 0);
        this.setBlock(world, i + 17, j + 9, k + 30, this.jadeLeaves(world), 0);
        this.setBlock(world, i + 17, j + 10, k + 16, this.jadeLeaves(world), 0);
        this.setBlock(world, i + 17, j + 10, k + 17, this.jadeLeaves(world), 0);
        this.setBlock(world, i + 17, j + 10, k + 18, this.jadeLeaves(world), 0);
        this.setBlock(world, i + 17, j + 10, k + 19, this.jadeLeaves(world), 0);
        this.setBlock(world, i + 17, j + 10, k + 20, this.jadeLeaves(world), 0);
        this.setBlock(world, i + 17, j + 10, k + 21, this.jadeLeaves(world), 0);
        this.setBlock(world, i + 17, j + 10, k + 22, this.jadeLeaves(world), 0);
        this.setBlock(world, i + 18, j + 0, k + 17, Dungeons.jadeLog, 0);
        this.setBlock(world, i + 18, j + 0, k + 18, Dungeons.jadeLog, 0);
        this.setBlock(world, i + 18, j + 0, k + 19, Dungeons.jadeLog, 0);
        this.setBlock(world, i + 18, j + 0, k + 20, Dungeons.jadeLog, 0);
        this.setBlock(world, i + 18, j + 0, k + 21, Dungeons.jadeLog, 0);
        this.setBlock(world, i + 18, j + 1, k + 18, Dungeons.jadeLog, 0);
        this.setBlock(world, i + 18, j + 1, k + 19, Dungeons.jadeLog, 0);
        this.setBlock(world, i + 18, j + 1, k + 20, Dungeons.jadeLog, 0);
        this.setBlock(world, i + 18, j + 2, k + 18, Dungeons.jadeLog, 0);
        this.setBlock(world, i + 18, j + 2, k + 19, Dungeons.jadeLog, 0);
        this.setBlock(world, i + 18, j + 2, k + 20, Dungeons.jadeLog, 0);
        this.setBlock(world, i + 18, j + 3, k + 18, Dungeons.jadeLog, 0);
        this.setBlock(world, i + 18, j + 3, k + 19, Dungeons.jadeLog, 0);
        this.setBlock(world, i + 18, j + 3, k + 20, Dungeons.jadeLog, 0);
        this.setBlock(world, i + 18, j + 4, k + 17, this.jadeLeaves(world), 0);
        this.setBlock(world, i + 18, j + 4, k + 18, this.jadeLeaves(world), 0);
        this.setBlock(world, i + 18, j + 4, k + 19, this.jadeLeaves(world), 0);
        this.setBlock(world, i + 18, j + 4, k + 20, this.jadeLeaves(world), 0);
        this.setBlock(world, i + 18, j + 4, k + 21, this.jadeLeaves(world), 0);
        this.setBlock(world, i + 18, j + 4, k + 22, this.jadeLeaves(world), 0);
        this.setBlock(world, i + 18, j + 5, k + 10, this.jadeLeaves(world), 0);
        this.setBlock(world, i + 18, j + 5, k + 11, this.jadeLeaves(world), 0);
        this.setBlock(world, i + 18, j + 5, k + 12, this.jadeLeaves(world), 0);
        this.setBlock(world, i + 18, j + 5, k + 13, this.jadeLeaves(world), 0);
        this.setBlock(world, i + 18, j + 5, k + 14, this.jadeLeaves(world), 0);
        this.setBlock(world, i + 18, j + 5, k + 15, this.jadeLeaves(world), 0);
        this.setBlock(world, i + 18, j + 5, k + 16, this.jadeLeaves(world), 0);
        this.setBlock(world, i + 18, j + 5, k + 17, this.jadeLeaves(world), 0);
        this.setBlock(world, i + 18, j + 5, k + 18, this.jadeLeaves(world), 0);
        this.setBlock(world, i + 18, j + 5, k + 19, this.jadeLeaves(world), 0);
        this.setBlock(world, i + 18, j + 5, k + 20, this.jadeLeaves(world), 0);
        this.setBlock(world, i + 18, j + 5, k + 21, this.jadeLeaves(world), 0);
        this.setBlock(world, i + 18, j + 5, k + 22, this.jadeLeaves(world), 0);
        this.setBlock(world, i + 18, j + 5, k + 23, this.jadeLeaves(world), 0);
        this.setBlock(world, i + 18, j + 5, k + 24, this.jadeLeaves(world), 0);
        this.setBlock(world, i + 18, j + 5, k + 25, this.jadeLeaves(world), 0);
        this.setBlock(world, i + 18, j + 5, k + 26, this.jadeLeaves(world), 0);
        this.setBlock(world, i + 18, j + 5, k + 27, this.jadeLeaves(world), 0);
        this.setBlock(world, i + 18, j + 5, k + 28, this.jadeLeaves(world), 0);
        this.setBlock(world, i + 18, j + 5, k + 29, this.jadeLeaves(world), 0);
        this.setBlock(world, i + 18, j + 6, k + 5, this.jadeLeaves(world), 0);
        this.setBlock(world, i + 18, j + 6, k + 6, this.jadeLeaves(world), 0);
        this.setBlock(world, i + 18, j + 6, k + 7, this.jadeLeaves(world), 0);
        this.setBlock(world, i + 18, j + 6, k + 8, this.jadeLeaves(world), 0);
        this.setBlock(world, i + 18, j + 6, k + 9, this.jadeLeaves(world), 0);
        this.setBlock(world, i + 18, j + 6, k + 10, this.jadeLeaves(world), 0);
        this.setBlock(world, i + 18, j + 6, k + 11, this.jadeLeaves(world), 0);
        this.setBlock(world, i + 18, j + 6, k + 12, this.jadeLeaves(world), 0);
        this.setBlock(world, i + 18, j + 6, k + 13, this.jadeLeaves(world), 0);
        this.setBlock(world, i + 18, j + 6, k + 14, this.jadeLeaves(world), 0);
        this.setBlock(world, i + 18, j + 6, k + 15, this.jadeLeaves(world), 0);
        this.setBlock(world, i + 18, j + 6, k + 16, this.jadeLeaves(world), 0);
        this.setBlock(world, i + 18, j + 6, k + 17, this.jadeLeaves(world), 0);
        this.setBlock(world, i + 18, j + 6, k + 18, this.jadeLeaves(world), 0);
        this.setBlock(world, i + 18, j + 6, k + 19, this.jadeLeaves(world), 0);
        this.setBlock(world, i + 18, j + 6, k + 20, this.jadeLeaves(world), 0);
        this.setBlock(world, i + 18, j + 6, k + 21, this.jadeLeaves(world), 0);
        this.setBlock(world, i + 18, j + 6, k + 22, this.jadeLeaves(world), 0);
        this.setBlock(world, i + 18, j + 6, k + 23, this.jadeLeaves(world), 0);
        this.setBlock(world, i + 18, j + 6, k + 24, this.jadeLeaves(world), 0);
        this.setBlock(world, i + 18, j + 6, k + 25, this.jadeLeaves(world), 0);
        this.setBlock(world, i + 18, j + 6, k + 26, this.jadeLeaves(world), 0);
        this.setBlock(world, i + 18, j + 6, k + 27, this.jadeLeaves(world), 0);
        this.setBlock(world, i + 18, j + 6, k + 28, this.jadeLeaves(world), 0);
        this.setBlock(world, i + 18, j + 6, k + 29, this.jadeLeaves(world), 0);
        this.setBlock(world, i + 18, j + 6, k + 30, this.jadeLeaves(world), 0);
        this.setBlock(world, i + 18, j + 6, k + 31, this.jadeLeaves(world), 0);
        this.setBlock(world, i + 18, j + 6, k + 32, this.jadeLeaves(world), 0);
        this.setBlock(world, i + 18, j + 6, k + 33, this.jadeLeaves(world), 0);
        this.setBlock(world, i + 18, j + 7, k + 1, this.jadeLeaves(world), 0);
        this.setBlock(world, i + 18, j + 7, k + 2, this.jadeLeaves(world), 0);
        this.setBlock(world, i + 18, j + 7, k + 3, this.jadeLeaves(world), 0);
        this.setBlock(world, i + 18, j + 7, k + 4, this.jadeLeaves(world), 0);
        this.setBlock(world, i + 18, j + 7, k + 5, this.jadeLeaves(world), 0);
        this.setBlock(world, i + 18, j + 7, k + 6, this.jadeLeaves(world), 0);
        this.setBlock(world, i + 18, j + 7, k + 7, this.jadeLeaves(world), 0);
        this.setBlock(world, i + 18, j + 7, k + 8, this.jadeLeaves(world), 0);
        this.setBlock(world, i + 18, j + 7, k + 9, this.jadeLeaves(world), 0);
        this.setBlock(world, i + 18, j + 7, k + 10, this.jadeLeaves(world), 0);
        this.setBlock(world, i + 18, j + 7, k + 11, this.jadeLeaves(world), 0);
        this.setBlock(world, i + 18, j + 7, k + 12, this.jadeLeaves(world), 0);
        this.setBlock(world, i + 18, j + 7, k + 13, this.jadeLeaves(world), 0);
        this.setBlock(world, i + 18, j + 7, k + 14, this.jadeLeaves(world), 0);
        this.setBlock(world, i + 18, j + 7, k + 15, this.jadeLeaves(world), 0);
        this.setBlock(world, i + 18, j + 7, k + 16, this.jadeLeaves(world), 0);
        this.setBlock(world, i + 18, j + 7, k + 17, this.jadeLeaves(world), 0);
        this.setBlock(world, i + 18, j + 7, k + 18, this.jadeLeaves(world), 0);
        this.setBlock(world, i + 18, j + 7, k + 19, this.jadeLeaves(world), 0);
        this.setBlock(world, i + 18, j + 7, k + 20, this.jadeLeaves(world), 0);
        this.setBlock(world, i + 18, j + 7, k + 21, this.jadeLeaves(world), 0);
        this.setBlock(world, i + 18, j + 7, k + 22, this.jadeLeaves(world), 0);
        this.setBlock(world, i + 18, j + 7, k + 23, this.jadeLeaves(world), 0);
        this.setBlock(world, i + 18, j + 7, k + 24, this.jadeLeaves(world), 0);
        this.setBlock(world, i + 18, j + 7, k + 25, this.jadeLeaves(world), 0);
        this.setBlock(world, i + 18, j + 7, k + 26, this.jadeLeaves(world), 0);
