

package com.gibby.dungeon.gen;

import net.minecraft.world.gen.feature.*;
import net.minecraft.world.*;
import java.util.*;
import net.minecraft.init.*;
import net.minecraft.block.*;
import com.gibby.dungeon.*;

public class LargeCastle3 extends WorldGenerator
{
    public boolean generate(final World world, final Random rand, final int i, final int j, final int k) {
        if (world.getBlock(i, j - 1, k) != Blocks.grass || world.getBlock(i + 42, j - 1, k) != Blocks.grass || world.getBlock(i + 42, j - 1, k + 30) != Blocks.grass || world.getBlock(i, j - 1, k + 30) != Blocks.grass || world.getBlock(i, j, k) != Blocks.air || world.getBlock(i + 42, j, k) != Blocks.air || world.getBlock(i + 42, j, k + 30) != Blocks.air || world.getBlock(i, j, k + 30) != Blocks.air) {
            return false;
        }
        world.setBlock(i + 0, j, k, Blocks.grass);
        world.setBlock(i + 0, j, k + 1, Blocks.grass);
        world.setBlock(i + 0, j, k + 2, Blocks.grass);
        world.setBlock(i + 0, j, k + 3, Blocks.grass);
        world.setBlock(i + 0, j, k + 4, Blocks.grass);
        world.setBlock(i + 0, j, k + 5, Blocks.grass);
        world.setBlock(i + 0, j, k + 6, Blocks.grass);
        world.setBlock(i + 0, j, k + 7, Blocks.grass);
        world.setBlock(i + 0, j, k + 8, Blocks.grass);
        world.setBlock(i + 0, j, k + 9, Blocks.grass);
        world.setBlock(i + 0, j, k + 10, Blocks.grass);
        world.setBlock(i + 0, j, k + 11, Blocks.grass);
        world.setBlock(i + 0, j, k + 12, Blocks.grass);
        world.setBlock(i + 0, j, k + 13, Blocks.grass);
        world.setBlock(i + 0, j, k + 14, Blocks.grass);
        world.setBlock(i + 0, j, k + 15, Blocks.grass);
        world.setBlock(i + 0, j, k + 16, Blocks.grass);
        world.setBlock(i + 0, j, k + 17, Blocks.grass);
        world.setBlock(i + 0, j, k + 18, Blocks.grass);
        world.setBlock(i + 0, j, k + 19, Blocks.grass);
        world.setBlock(i + 0, j, k + 20, Blocks.grass);
        world.setBlock(i + 0, j, k + 21, Blocks.grass);
        world.setBlock(i + 0, j, k + 22, Blocks.grass);
        world.setBlock(i + 0, j, k + 23, Blocks.grass);
        world.setBlock(i + 0, j, k + 24, Blocks.grass);
        world.setBlock(i + 0, j, k + 25, Blocks.grass);
        world.setBlock(i + 0, j, k + 26, Blocks.grass);
        world.setBlock(i + 0, j, k + 27, Blocks.grass);
        world.setBlock(i + 0, j, k + 28, Blocks.grass);
        world.setBlock(i + 0, j, k + 29, Blocks.grass);
        world.setBlock(i + 0, j, k + 30, Blocks.grass);
        world.setBlock(i + 0, j + 53, k + 11, Blocks.wool, 14, 0);
        world.setBlock(i + 0, j + 53, k + 12, Blocks.wool, 14, 0);
        world.setBlock(i + 1, j, k, Blocks.grass);
        world.setBlock(i + 1, j, k + 1, Blocks.grass);
        world.setBlock(i + 1, j, k + 2, Blocks.grass);
        world.setBlock(i + 1, j, k + 3, Blocks.grass);
        world.setBlock(i + 1, j, k + 4, Blocks.grass);
        world.setBlock(i + 1, j, k + 5, Blocks.grass);
        world.setBlock(i + 1, j, k + 6, Blocks.grass);
        world.setBlock(i + 1, j, k + 7, Blocks.grass);
        world.setBlock(i + 1, j, k + 8, Blocks.grass);
        world.setBlock(i + 1, j, k + 9, Blocks.grass);
        world.setBlock(i + 1, j, k + 10, Blocks.grass);
        world.setBlock(i + 1, j, k + 11, Blocks.grass);
        world.setBlock(i + 1, j, k + 12, Blocks.grass);
        world.setBlock(i + 1, j, k + 13, Blocks.grass);
        world.setBlock(i + 1, j, k + 14, Blocks.grass);
        world.setBlock(i + 1, j, k + 15, Blocks.grass);
        world.setBlock(i + 1, j, k + 16, Blocks.grass);
        world.setBlock(i + 1, j, k + 17, Blocks.grass);
        world.setBlock(i + 1, j, k + 18, Blocks.grass);
        world.setBlock(i + 1, j, k + 19, Blocks.grass);
        world.setBlock(i + 1, j, k + 20, Blocks.grass);
        world.setBlock(i + 1, j, k + 21, Blocks.grass);
        world.setBlock(i + 1, j, k + 22, Blocks.grass);
        world.setBlock(i + 1, j, k + 23, Blocks.grass);
        world.setBlock(i + 1, j, k + 24, Blocks.grass);
        world.setBlock(i + 1, j, k + 25, Blocks.grass);
        world.setBlock(i + 1, j, k + 26, Blocks.grass);
        world.setBlock(i + 1, j, k + 27, Blocks.grass);
        world.setBlock(i + 1, j, k + 28, Blocks.grass);
        world.setBlock(i + 1, j, k + 29, Blocks.grass);
        world.setBlock(i + 1, j, k + 30, Blocks.grass);
        world.setBlock(i + 1, j + 30, k + 14, Blocks.stonebrick);
        world.setBlock(i + 1, j + 30, k + 15, Blocks.stonebrick);
        world.setBlock(i + 1, j + 30, k + 16, Blocks.stonebrick);
        world.setBlock(i + 1, j + 30, k + 17, Blocks.stonebrick);
        world.setBlock(i + 1, j + 30, k + 18, Blocks.stonebrick);
        world.setBlock(i + 1, j + 30, k + 19, Blocks.stonebrick);
        world.setBlock(i + 1, j + 31, k + 14, Blocks.stonebrick);
        world.setBlock(i + 1, j + 31, k + 15, Blocks.stonebrick);
        world.setBlock(i + 1, j + 31, k + 16, Blocks.stonebrick);
        world.setBlock(i + 1, j + 31, k + 17, Blocks.stonebrick);
        world.setBlock(i + 1, j + 31, k + 18, Blocks.stonebrick);
        world.setBlock(i + 1, j + 31, k + 19, Blocks.stonebrick);
        world.setBlock(i + 1, j + 32, k + 14, Blocks.stonebrick);
        world.setBlock(i + 1, j + 32, k + 15, Blocks.stonebrick);
        world.setBlock(i + 1, j + 32, k + 16, Blocks.stonebrick);
        world.setBlock(i + 1, j + 32, k + 17, Blocks.stonebrick);
        world.setBlock(i + 1, j + 32, k + 18, Blocks.stonebrick);
        world.setBlock(i + 1, j + 32, k + 19, Blocks.stonebrick);
        world.setBlock(i + 1, j + 33, k + 14, Blocks.stonebrick);
        world.setBlock(i + 1, j + 33, k + 15, Blocks.stonebrick);
        world.setBlock(i + 1, j + 33, k + 16, Blocks.stonebrick);
        world.setBlock(i + 1, j + 33, k + 17, Blocks.stonebrick);
        world.setBlock(i + 1, j + 33, k + 18, Blocks.stonebrick);
        world.setBlock(i + 1, j + 33, k + 19, Blocks.stonebrick);
        world.setBlock(i + 1, j + 34, k + 14, Blocks.stonebrick);
        world.setBlock(i + 1, j + 34, k + 15, Blocks.stonebrick);
        world.setBlock(i + 1, j + 34, k + 16, Blocks.stonebrick);
        world.setBlock(i + 1, j + 34, k + 17, Blocks.stonebrick);
        world.setBlock(i + 1, j + 34, k + 18, Blocks.stonebrick);
        world.setBlock(i + 1, j + 34, k + 19, Blocks.stonebrick);
        world.setBlock(i + 1, j + 35, k + 14, Blocks.stonebrick);
        world.setBlock(i + 1, j + 35, k + 15, Blocks.stonebrick);
        world.setBlock(i + 1, j + 35, k + 16, Blocks.stonebrick);
        world.setBlock(i + 1, j + 35, k + 17, Blocks.stonebrick);
        world.setBlock(i + 1, j + 35, k + 18, Blocks.stonebrick);
        world.setBlock(i + 1, j + 35, k + 19, Blocks.stonebrick);
        world.setBlock(i + 1, j + 36, k + 14, Blocks.stonebrick);
        world.setBlock(i + 1, j + 36, k + 15, Blocks.stonebrick);
        world.setBlock(i + 1, j + 36, k + 16, Blocks.stonebrick);
        world.setBlock(i + 1, j + 36, k + 17, Blocks.stonebrick);
        world.setBlock(i + 1, j + 36, k + 18, Blocks.stonebrick);
        world.setBlock(i + 1, j + 36, k + 19, Blocks.stonebrick);
        world.setBlock(i + 1, j + 37, k + 14, Blocks.stonebrick);
        world.setBlock(i + 1, j + 37, k + 15, Blocks.stonebrick);
        world.setBlock(i + 1, j + 37, k + 16, Blocks.stonebrick);
        world.setBlock(i + 1, j + 37, k + 17, Blocks.stonebrick);
        world.setBlock(i + 1, j + 37, k + 18, Blocks.stonebrick);
        world.setBlock(i + 1, j + 37, k + 19, Blocks.stonebrick);
        world.setBlock(i + 1, j + 38, k + 14, Blocks.stonebrick);
        world.setBlock(i + 1, j + 38, k + 16, Blocks.stonebrick);
        world.setBlock(i + 1, j + 38, k + 17, Blocks.stonebrick);
        world.setBlock(i + 1, j + 38, k + 19, Blocks.stonebrick);
        world.setBlock(i + 1, j + 52, k + 13, Blocks.wool);
        world.setBlock(i + 1, j + 53, k + 12, Blocks.wool, 14, 0);
        world.setBlock(i + 1, j + 53, k + 13, Blocks.wool, 14, 0);
        world.setBlock(i + 1, j + 54, k + 13, Blocks.wool);
        world.setBlock(i + 2, j, k, Blocks.grass);
        world.setBlock(i + 2, j, k + 1, Blocks.grass);
        world.setBlock(i + 2, j, k + 2, Blocks.grass);
        world.setBlock(i + 2, j, k + 3, Blocks.grass);
        world.setBlock(i + 2, j, k + 4, Blocks.grass);
        world.setBlock(i + 2, j, k + 5, Blocks.grass);
        world.setBlock(i + 2, j, k + 6, Blocks.grass);
        world.setBlock(i + 2, j, k + 7, Blocks.grass);
        world.setBlock(i + 2, j, k + 8, Blocks.grass);
        world.setBlock(i + 2, j, k + 9, Blocks.grass);
        world.setBlock(i + 2, j, k + 10, Blocks.grass);
        world.setBlock(i + 2, j, k + 11, Blocks.grass);
        world.setBlock(i + 2, j, k + 12, Blocks.grass);
        world.setBlock(i + 2, j, k + 13, Blocks.grass);
        world.setBlock(i + 2, j, k + 14, Blocks.dirt);
        world.setBlock(i + 2, j, k + 15, Blocks.dirt);
        world.setBlock(i + 2, j, k + 16, Blocks.dirt);
        world.setBlock(i + 2, j, k + 17, Blocks.dirt);
        world.setBlock(i + 2, j, k + 18, Blocks.dirt);
        world.setBlock(i + 2, j, k + 19, Blocks.dirt);
        world.setBlock(i + 2, j, k + 20, Blocks.grass);
        world.setBlock(i + 2, j, k + 21, Blocks.grass);
        world.setBlock(i + 2, j, k + 22, Blocks.grass);
        world.setBlock(i + 2, j, k + 23, Blocks.grass);
        world.setBlock(i + 2, j, k + 24, Blocks.grass);
        world.setBlock(i + 2, j, k + 25, Blocks.grass);
        world.setBlock(i + 2, j, k + 26, Blocks.grass);
        world.setBlock(i + 2, j, k + 27, Blocks.grass);
        world.setBlock(i + 2, j, k + 28, Blocks.grass);
        world.setBlock(i + 2, j, k + 29, Blocks.grass);
        world.setBlock(i + 2, j, k + 30, Blocks.grass);
        world.setBlock(i + 2, j + 1, k + 14, Blocks.cobblestone);
        world.setBlock(i + 2, j + 1, k + 15, Blocks.cobblestone);
        world.setBlock(i + 2, j + 1, k + 16, Blocks.cobblestone);
        world.setBlock(i + 2, j + 1, k + 17, Blocks.cobblestone);
        world.setBlock(i + 2, j + 1, k + 18, Blocks.cobblestone);
        world.setBlock(i + 2, j + 1, k + 19, Blocks.cobblestone);
        world.setBlock(i + 2, j + 2, k + 14, Blocks.cobblestone);
        world.setBlock(i + 2, j + 2, k + 15, Blocks.cobblestone);
        world.setBlock(i + 2, j + 2, k + 16, Blocks.cobblestone);
        world.setBlock(i + 2, j + 2, k + 17, Blocks.cobblestone);
        world.setBlock(i + 2, j + 2, k + 18, Blocks.cobblestone);
        world.setBlock(i + 2, j + 2, k + 19, Blocks.cobblestone);
        world.setBlock(i + 2, j + 3, k + 14, Blocks.cobblestone);
        world.setBlock(i + 2, j + 3, k + 15, Blocks.cobblestone);
        world.setBlock(i + 2, j + 3, k + 16, Blocks.cobblestone);
        world.setBlock(i + 2, j + 3, k + 17, Blocks.cobblestone);
        world.setBlock(i + 2, j + 3, k + 18, Blocks.cobblestone);
        world.setBlock(i + 2, j + 3, k + 19, Blocks.cobblestone);
        world.setBlock(i + 2, j + 4, k + 14, Blocks.cobblestone);
        world.setBlock(i + 2, j + 4, k + 15, Blocks.cobblestone);
        world.setBlock(i + 2, j + 4, k + 16, Blocks.cobblestone);
        world.setBlock(i + 2, j + 4, k + 17, Blocks.cobblestone);
        world.setBlock(i + 2, j + 4, k + 18, Blocks.cobblestone);
        world.setBlock(i + 2, j + 4, k + 19, Blocks.cobblestone);
        world.setBlock(i + 2, j + 5, k + 14, Blocks.stonebrick);
        world.setBlock(i + 2, j + 5, k + 15, Blocks.stonebrick);
        world.setBlock(i + 2, j + 5, k + 16, Blocks.stonebrick);
        world.setBlock(i + 2, j + 5, k + 17, Blocks.stonebrick);
        world.setBlock(i + 2, j + 5, k + 18, Blocks.stonebrick);
        world.setBlock(i + 2, j + 5, k + 19, Blocks.stonebrick);
        world.setBlock(i + 2, j + 6, k + 14, Blocks.stonebrick);
        world.setBlock(i + 2, j + 6, k + 15, Blocks.stonebrick);
        world.setBlock(i + 2, j + 6, k + 16, Blocks.stonebrick);
        world.setBlock(i + 2, j + 6, k + 17, Blocks.stonebrick);
        world.setBlock(i + 2, j + 6, k + 18, Blocks.stonebrick);
        world.setBlock(i + 2, j + 6, k + 19, Blocks.stonebrick);
        world.setBlock(i + 2, j + 7, k + 14, Blocks.stonebrick);
        world.setBlock(i + 2, j + 7, k + 15, Blocks.stonebrick);
        world.setBlock(i + 2, j + 7, k + 16, Blocks.stonebrick);
        world.setBlock(i + 2, j + 7, k + 17, Blocks.stonebrick);
        world.setBlock(i + 2, j + 7, k + 18, Blocks.stonebrick);
        world.setBlock(i + 2, j + 7, k + 19, Blocks.stonebrick);
        world.setBlock(i + 2, j + 8, k + 14, Blocks.stonebrick);
        world.setBlock(i + 2, j + 8, k + 15, Blocks.stonebrick);
        world.setBlock(i + 2, j + 8, k + 16, Blocks.stonebrick);
        world.setBlock(i + 2, j + 8, k + 17, Blocks.stonebrick);
        world.setBlock(i + 2, j + 8, k + 18, Blocks.stonebrick);
        world.setBlock(i + 2, j + 8, k + 19, Blocks.stonebrick);
        world.setBlock(i + 2, j + 9, k + 14, Blocks.stonebrick);
        world.setBlock(i + 2, j + 9, k + 15, Blocks.stonebrick);
        world.setBlock(i + 2, j + 9, k + 16, Blocks.stonebrick);
        world.setBlock(i + 2, j + 9, k + 17, Blocks.stonebrick);
        world.setBlock(i + 2, j + 9, k + 18, Blocks.stonebrick);
        world.setBlock(i + 2, j + 9, k + 19, Blocks.stonebrick);
        world.setBlock(i + 2, j + 10, k + 14, Blocks.stonebrick);
        world.setBlock(i + 2, j + 10, k + 15, Blocks.stonebrick);
        world.setBlock(i + 2, j + 10, k + 16, Blocks.stonebrick);
        world.setBlock(i + 2, j + 10, k + 17, Blocks.stonebrick);
        world.setBlock(i + 2, j + 10, k + 18, Blocks.stonebrick);
        world.setBlock(i + 2, j + 10, k + 19, Blocks.stonebrick);
        world.setBlock(i + 2, j + 11, k + 14, Blocks.stonebrick);
        world.setBlock(i + 2, j + 11, k + 15, Blocks.stonebrick);
        world.setBlock(i + 2, j + 11, k + 16, Blocks.stonebrick);
        world.setBlock(i + 2, j + 11, k + 17, Blocks.stonebrick);
        world.setBlock(i + 2, j + 11, k + 18, Blocks.stonebrick);
        world.setBlock(i + 2, j + 11, k + 19, Blocks.stonebrick);
        world.setBlock(i + 2, j + 12, k + 14, Blocks.stonebrick);
        world.setBlock(i + 2, j + 12, k + 15, Blocks.stonebrick);
        world.setBlock(i + 2, j + 12, k + 16, Blocks.stonebrick);
        world.setBlock(i + 2, j + 12, k + 17, Blocks.stonebrick);
        world.setBlock(i + 2, j + 12, k + 18, Blocks.stonebrick);
        world.setBlock(i + 2, j + 12, k + 19, Blocks.stonebrick);
        world.setBlock(i + 2, j + 13, k + 14, Blocks.stonebrick);
        world.setBlock(i + 2, j + 13, k + 15, Blocks.stonebrick);
        world.setBlock(i + 2, j + 13, k + 16, Blocks.stonebrick);
        world.setBlock(i + 2, j + 13, k + 17, Blocks.stonebrick);
        world.setBlock(i + 2, j + 13, k + 18, Blocks.stonebrick);
        world.setBlock(i + 2, j + 13, k + 19, Blocks.stonebrick);
        world.setBlock(i + 2, j + 14, k + 14, Blocks.stonebrick);
        world.setBlock(i + 2, j + 14, k + 15, Blocks.stonebrick);
        world.setBlock(i + 2, j + 14, k + 16, Blocks.stonebrick);
        world.setBlock(i + 2, j + 14, k + 17, Blocks.stonebrick);
        world.setBlock(i + 2, j + 14, k + 18, Blocks.stonebrick);
        world.setBlock(i + 2, j + 14, k + 19, Blocks.stonebrick);
        world.setBlock(i + 2, j + 15, k + 14, Blocks.stonebrick);
        world.setBlock(i + 2, j + 15, k + 15, Blocks.stonebrick);
        world.setBlock(i + 2, j + 15, k + 16, Blocks.stonebrick);
        world.setBlock(i + 2, j + 15, k + 17, Blocks.stonebrick);
        world.setBlock(i + 2, j + 15, k + 18, Blocks.stonebrick);
        world.setBlock(i + 2, j + 15, k + 19, Blocks.stonebrick);
        world.setBlock(i + 2, j + 16, k + 14, Blocks.stonebrick);
        world.setBlock(i + 2, j + 16, k + 15, Blocks.stonebrick);
        world.setBlock(i + 2, j + 16, k + 16, Blocks.stonebrick);
        world.setBlock(i + 2, j + 16, k + 17, Blocks.stonebrick);
        world.setBlock(i + 2, j + 16, k + 18, Blocks.stonebrick);
        world.setBlock(i + 2, j + 16, k + 19, Blocks.stonebrick);
        world.setBlock(i + 2, j + 17, k + 14, Blocks.stonebrick);
        world.setBlock(i + 2, j + 17, k + 15, Blocks.stonebrick);
        world.setBlock(i + 2, j + 17, k + 16, Blocks.stonebrick);
        world.setBlock(i + 2, j + 17, k + 17, Blocks.stonebrick);
        world.setBlock(i + 2, j + 17, k + 18, Blocks.stonebrick);
        world.setBlock(i + 2, j + 17, k + 19, Blocks.stonebrick);
        world.setBlock(i + 2, j + 18, k + 14, Blocks.stonebrick);
        world.setBlock(i + 2, j + 18, k + 15, Blocks.stonebrick);
        world.setBlock(i + 2, j + 18, k + 16, Blocks.stonebrick);
        world.setBlock(i + 2, j + 18, k + 17, Blocks.stonebrick);
        world.setBlock(i + 2, j + 18, k + 18, Blocks.stonebrick);
        world.setBlock(i + 2, j + 18, k + 19, Blocks.stonebrick);
        world.setBlock(i + 2, j + 19, k + 14, Blocks.stonebrick);
        world.setBlock(i + 2, j + 19, k + 15, Blocks.stonebrick);
        world.setBlock(i + 2, j + 19, k + 16, Blocks.stonebrick);
        world.setBlock(i + 2, j + 19, k + 17, Blocks.stonebrick);
        world.setBlock(i + 2, j + 19, k + 18, Blocks.stonebrick);
        world.setBlock(i + 2, j + 19, k + 19, Blocks.stonebrick);
        world.setBlock(i + 2, j + 20, k + 14, Blocks.stonebrick);
        world.setBlock(i + 2, j + 20, k + 15, Blocks.stonebrick);
        world.setBlock(i + 2, j + 20, k + 16, Blocks.stonebrick);
        world.setBlock(i + 2, j + 20, k + 17, Blocks.stonebrick);
        world.setBlock(i + 2, j + 20, k + 18, Blocks.stonebrick);
        world.setBlock(i + 2, j + 20, k + 19, Blocks.stonebrick);
        world.setBlock(i + 2, j + 21, k + 14, Blocks.stonebrick);
        world.setBlock(i + 2, j + 21, k + 15, Blocks.stonebrick);
        world.setBlock(i + 2, j + 21, k + 16, Blocks.stonebrick);
        world.setBlock(i + 2, j + 21, k + 17, Blocks.stonebrick);
        world.setBlock(i + 2, j + 21, k + 18, Blocks.stonebrick);
        world.setBlock(i + 2, j + 21, k + 19, Blocks.stonebrick);
        world.setBlock(i + 2, j + 22, k + 14, Blocks.stonebrick);
        world.setBlock(i + 2, j + 22, k + 15, Blocks.stonebrick);
        world.setBlock(i + 2, j + 22, k + 16, Blocks.stonebrick);
        world.setBlock(i + 2, j + 22, k + 17, Blocks.stonebrick);
        world.setBlock(i + 2, j + 22, k + 18, Blocks.stonebrick);
        world.setBlock(i + 2, j + 22, k + 19, Blocks.stonebrick);
        world.setBlock(i + 2, j + 23, k + 14, Blocks.stonebrick);
        world.setBlock(i + 2, j + 23, k + 15, Blocks.stonebrick);
        world.setBlock(i + 2, j + 23, k + 16, Blocks.stonebrick);
        world.setBlock(i + 2, j + 23, k + 17, Blocks.stonebrick);
        world.setBlock(i + 2, j + 23, k + 18, Blocks.stonebrick);
        world.setBlock(i + 2, j + 23, k + 19, Blocks.stonebrick);
        world.setBlock(i + 2, j + 24, k + 14, Blocks.stonebrick);
        world.setBlock(i + 2, j + 24, k + 15, Blocks.stonebrick);
        world.setBlock(i + 2, j + 24, k + 16, Blocks.stonebrick);
        world.setBlock(i + 2, j + 24, k + 17, Blocks.stonebrick);
        world.setBlock(i + 2, j + 24, k + 18, Blocks.stonebrick);
        world.setBlock(i + 2, j + 24, k + 19, Blocks.stonebrick);
        world.setBlock(i + 2, j + 25, k + 14, Blocks.stonebrick);
        world.setBlock(i + 2, j + 25, k + 15, Blocks.stonebrick);
        world.setBlock(i + 2, j + 25, k + 16, Blocks.stonebrick);
        world.setBlock(i + 2, j + 25, k + 17, Blocks.stonebrick);
        world.setBlock(i + 2, j + 25, k + 18, Blocks.stonebrick);
        world.setBlock(i + 2, j + 25, k + 19, Blocks.stonebrick);
        world.setBlock(i + 2, j + 26, k + 14, Blocks.stonebrick);
        world.setBlock(i + 2, j + 26, k + 15, Blocks.stonebrick);
        world.setBlock(i + 2, j + 26, k + 16, Blocks.stonebrick);
        world.setBlock(i + 2, j + 26, k + 17, Blocks.stonebrick);
        world.setBlock(i + 2, j + 26, k + 18, Blocks.stonebrick);
        world.setBlock(i + 2, j + 26, k + 19, Blocks.stonebrick);
        world.setBlock(i + 2, j + 27, k + 14, Blocks.stonebrick);
        world.setBlock(i + 2, j + 27, k + 15, Blocks.stonebrick);
        world.setBlock(i + 2, j + 27, k + 16, Blocks.stonebrick);
        world.setBlock(i + 2, j + 27, k + 17, Blocks.stonebrick);
        world.setBlock(i + 2, j + 27, k + 18, Blocks.stonebrick);
        world.setBlock(i + 2, j + 27, k + 19, Blocks.stonebrick);
        world.setBlock(i + 2, j + 28, k + 14, Blocks.stonebrick);
        world.setBlock(i + 2, j + 28, k + 15, Blocks.stonebrick);
        world.setBlock(i + 2, j + 28, k + 16, Blocks.stonebrick);
        world.setBlock(i + 2, j + 28, k + 17, Blocks.stonebrick);
        world.setBlock(i + 2, j + 28, k + 18, Blocks.stonebrick);
        world.setBlock(i + 2, j + 28, k + 19, Blocks.stonebrick);
        world.setBlock(i + 2, j + 29, k + 14, Blocks.stonebrick);
        world.setBlock(i + 2, j + 29, k + 15, Blocks.stonebrick);
        world.setBlock(i + 2, j + 29, k + 16, Blocks.stonebrick);
        world.setBlock(i + 2, j + 29, k + 17, Blocks.stonebrick);
        world.setBlock(i + 2, j + 29, k + 18, Blocks.stonebrick);
        world.setBlock(i + 2, j + 29, k + 19, Blocks.stonebrick);
        world.setBlock(i + 2, j + 30, k + 13, Blocks.stonebrick);
        world.setBlock(i + 2, j + 30, k + 14, Blocks.stonebrick);
        world.setBlock(i + 2, j + 30, k + 15, Blocks.stonebrick);
        world.setBlock(i + 2, j + 30, k + 16, Blocks.stonebrick);
        world.setBlock(i + 2, j + 30, k + 17, Blocks.stonebrick);
        world.setBlock(i + 2, j + 30, k + 18, Blocks.stonebrick);
        world.setBlock(i + 2, j + 30, k + 19, Blocks.stonebrick);
        world.setBlock(i + 2, j + 30, k + 20, Blocks.stonebrick);
        world.setBlock(i + 2, j + 31, k + 13, Blocks.stonebrick);
        world.setBlock(i + 2, j + 31, k + 14, Blocks.stonebrick);
        world.setBlock(i + 2, j + 31, k + 15, Blocks.stonebrick);
        world.setBlock(i + 2, j + 31, k + 16, Blocks.stonebrick);
        world.setBlock(i + 2, j + 31, k + 17, Blocks.stonebrick);
        world.setBlock(i + 2, j + 31, k + 18, Blocks.stonebrick);
        world.setBlock(i + 2, j + 31, k + 19, Blocks.stonebrick);
        world.setBlock(i + 2, j + 31, k + 20, Blocks.stonebrick);
        world.setBlock(i + 2, j + 32, k + 13, Blocks.stonebrick);
        world.setBlock(i + 2, j + 32, k + 14, Blocks.stonebrick);
        world.setBlock(i + 2, j + 32, k + 15, Blocks.stonebrick);
        world.setBlock(i + 2, j + 32, k + 16, Blocks.stonebrick);
        world.setBlock(i + 2, j + 32, k + 17, Blocks.stonebrick);
        world.setBlock(i + 2, j + 32, k + 18, Blocks.stonebrick);
        world.setBlock(i + 2, j + 32, k + 19, Blocks.stonebrick);
        world.setBlock(i + 2, j + 32, k + 20, Blocks.stonebrick);
        world.setBlock(i + 2, j + 33, k + 13, Blocks.stonebrick);
        world.setBlock(i + 2, j + 33, k + 20, Blocks.stonebrick);
        world.setBlock(i + 2, j + 34, k + 13, Blocks.stonebrick);
        world.setBlock(i + 2, j + 34, k + 20, Blocks.stonebrick);
        world.setBlock(i + 2, j + 35, k + 13, Blocks.stonebrick);
        world.setBlock(i + 2, j + 35, k + 20, Blocks.stonebrick);
        world.setBlock(i + 2, j + 36, k + 13, Blocks.stonebrick);
        world.setBlock(i + 2, j + 36, k + 14, Blocks.stonebrick);
        world.setBlock(i + 2, j + 36, k + 15, Blocks.stonebrick);
        world.setBlock(i + 2, j + 36, k + 16, Blocks.stonebrick);
        world.setBlock(i + 2, j + 36, k + 17, Blocks.stonebrick);
        world.setBlock(i + 2, j + 36, k + 18, Blocks.stonebrick);
        world.setBlock(i + 2, j + 36, k + 19, Blocks.stonebrick);
        world.setBlock(i + 2, j + 36, k + 20, Blocks.stonebrick);
        world.setBlock(i + 2, j + 37, k + 13, Blocks.stonebrick);
        world.setBlock(i + 2, j + 37, k + 20, Blocks.stonebrick);
        world.setBlock(i + 2, j + 38, k + 13, Blocks.stonebrick);
        world.setBlock(i + 2, j + 38, k + 20, Blocks.stonebrick);
        world.setBlock(i + 2, j + 39, k + 13, Blocks.stonebrick);
        world.setBlock(i + 2, j + 39, k + 20, Blocks.stonebrick);
        world.setBlock(i + 2, j + 52, k + 13, Blocks.wool);
        world.setBlock(i + 2, j + 52, k + 14, Blocks.wool);
        world.setBlock(i + 2, j + 53, k + 13, Blocks.wool, 14, 0);
        world.setBlock(i + 2, j + 53, k + 14, Blocks.wool, 14, 0);
        world.setBlock(i + 2, j + 54, k + 13, Blocks.wool);
        world.setBlock(i + 2, j + 54, k + 14, Blocks.wool);
        world.setBlock(i + 3, j, k, Blocks.grass);
        world.setBlock(i + 3, j, k + 1, Blocks.grass);
        world.setBlock(i + 3, j, k + 2, Blocks.grass);
        world.setBlock(i + 3, j, k + 3, Blocks.grass);
        world.setBlock(i + 3, j, k + 4, Blocks.grass);
        world.setBlock(i + 3, j, k + 5, Blocks.grass);
        world.setBlock(i + 3, j, k + 6, Blocks.grass);
        world.setBlock(i + 3, j, k + 7, Blocks.grass);
        world.setBlock(i + 3, j, k + 8, Blocks.grass);
        world.setBlock(i + 3, j, k + 9, Blocks.grass);
        world.setBlock(i + 3, j, k + 10, Blocks.grass);
        world.setBlock(i + 3, j, k + 11, Blocks.grass);
        world.setBlock(i + 3, j, k + 12, Blocks.grass);
        world.setBlock(i + 3, j, k + 13, Blocks.dirt);
        world.setBlock(i + 3, j, k + 14, Blocks.cobblestone);
        world.setBlock(i + 3, j, k + 15, Blocks.cobblestone);
        world.setBlock(i + 3, j, k + 16, Blocks.cobblestone);
        world.setBlock(i + 3, j, k + 17, Blocks.cobblestone);
        world.setBlock(i + 3, j, k + 18, Blocks.cobblestone);
        world.setBlock(i + 3, j, k + 19, Blocks.cobblestone);
        world.setBlock(i + 3, j, k + 20, Blocks.dirt);
        world.setBlock(i + 3, j, k + 21, Blocks.grass);
        world.setBlock(i + 3, j, k + 22, Blocks.grass);
        world.setBlock(i + 3, j, k + 23, Blocks.grass);
        world.setBlock(i + 3, j, k + 24, Blocks.grass);
        world.setBlock(i + 3, j, k + 25, Blocks.grass);
        world.setBlock(i + 3, j, k + 26, Blocks.grass);
        world.setBlock(i + 3, j, k + 27, Blocks.grass);
        world.setBlock(i + 3, j, k + 28, Blocks.grass);
        world.setBlock(i + 3, j, k + 29, Blocks.grass);
        world.setBlock(i + 3, j, k + 30, Blocks.grass);
        world.setBlock(i + 3, j + 1, k + 13, Blocks.cobblestone);
        world.setBlock(i + 3, j + 1, k + 20, Blocks.cobblestone);
        world.setBlock(i + 3, j + 2, k + 13, Blocks.cobblestone);
        world.setBlock(i + 3, j + 2, k + 20, Blocks.cobblestone);
        world.setBlock(i + 3, j + 3, k + 13, Blocks.cobblestone);
        world.setBlock(i + 3, j + 3, k + 20, Blocks.cobblestone);
        world.setBlock(i + 3, j + 4, k + 13, Blocks.cobblestone);
        world.setBlock(i + 3, j + 4, k + 14, Blocks.wool, 9, 0);
        world.setBlock(i + 3, j + 4, k + 15, Blocks.wool, 9, 0);
        world.setBlock(i + 3, j + 4, k + 16, Blocks.wool, 9, 0);
        world.setBlock(i + 3, j + 4, k + 17, Blocks.wool, 9, 0);
        world.setBlock(i + 3, j + 4, k + 18, Blocks.wool, 9, 0);
        world.setBlock(i + 3, j + 4, k + 19, Blocks.wool, 9, 0);
        world.setBlock(i + 3, j + 4, k + 20, Blocks.cobblestone);
        world.setBlock(i + 3, j + 5, k + 13, Blocks.stonebrick);
        Dungeons.spawner(world, i + 3, j + 5, k + 16, 12, 2);
        world.setBlock(i + 3, j + 5, k + 18, Blocks.stone_slab, 13, 0);
        world.setBlock(i + 3, j + 5, k + 19, Blocks.stone_slab, 5, 0);
        world.setBlock(i + 3, j + 5, k + 20, Blocks.stonebrick);
        world.setBlock(i + 3, j + 6, k + 13, Blocks.stonebrick);
        world.setBlock(i + 3, j + 6, k + 16, Blocks.stone_slab, 13, 0);
        world.setBlock(i + 3, j + 6, k + 17, Blocks.stone_slab, 5, 0);
        world.setBlock(i + 3, j + 6, k + 20, Blocks.stonebrick);
        world.setBlock(i + 3, j + 7, k + 13, Blocks.stonebrick);
        world.setBlock(i + 3, j + 7, k + 14, Blocks.stone_slab, 13, 0);
        world.setBlock(i + 3, j + 7, k + 15, Blocks.stone_slab, 5, 0);
        world.setBlock(i + 3, j + 7, k + 20, Blocks.stonebrick);
        world.setBlock(i + 3, j + 8, k + 13, Blocks.stonebrick);
        world.setBlock(i + 3, j + 8, k + 20, Blocks.stonebrick);
        world.setBlock(i + 3, j + 9, k + 13, Blocks.stonebrick);
        world.setBlock(i + 3, j + 9, k + 20, Blocks.stonebrick);
        world.setBlock(i + 3, j + 10, k + 13, Blocks.stonebrick);
        world.setBlock(i + 3, j + 10, k + 20, Blocks.stonebrick);
        world.setBlock(i + 3, j + 11, k + 13, Blocks.stonebrick);
        world.setBlock(i + 3, j + 11, k + 20, Blocks.stonebrick);
        world.setBlock(i + 3, j + 12, k + 13, Blocks.stonebrick);
        world.setBlock(i + 3, j + 12, k + 14, Blocks.stonebrick);
        world.setBlock(i + 3, j + 12, k + 15, Blocks.stonebrick);
        world.setBlock(i + 3, j + 12, k + 16, Blocks.stonebrick);
        world.setBlock(i + 3, j + 12, k + 17, Blocks.stonebrick);
        world.setBlock(i + 3, j + 12, k + 18, Blocks.stonebrick);
        world.setBlock(i + 3, j + 12, k + 19, Blocks.stonebrick);
        world.setBlock(i + 3, j + 12, k + 20, Blocks.stonebrick);
        world.setBlock(i + 3, j + 13, k + 13, Blocks.stonebrick);
        world.setBlock(i + 3, j + 13, k + 14, Blocks.bookshelf);
        Dungeons.spawner(world, i + 3, j + 13, k + 16, 12, 3);
        world.setBlock(i + 3, j + 13, k + 18, Blocks.stone_slab, 13, 0);
        world.setBlock(i + 3, j + 13, k + 19, Blocks.stone_slab, 5, 0);
        world.setBlock(i + 3, j + 13, k + 20, Blocks.stonebrick);
        world.setBlock(i + 3, j + 14, k + 13, Blocks.stonebrick);
        world.setBlock(i + 3, j + 14, k + 14, Blocks.bookshelf);
        world.setBlock(i + 3, j + 14, k + 16, Blocks.stone_slab, 13, 0);
        world.setBlock(i + 3, j + 14, k + 17, Blocks.stone_slab, 5, 0);
        world.setBlock(i + 3, j + 14, k + 20, Blocks.stonebrick);
        world.setBlock(i + 3, j + 15, k + 13, Blocks.stonebrick);
        world.setBlock(i + 3, j + 15, k + 14, Blocks.stone_slab, 13, 0);
        world.setBlock(i + 3, j + 15, k + 15, Blocks.stone_slab, 5, 0);
        world.setBlock(i + 3, j + 15, k + 20, Blocks.stonebrick);
        world.setBlock(i + 3, j + 16, k + 13, Blocks.stonebrick);
        world.setBlock(i + 3, j + 16, k + 20, Blocks.stonebrick);
        world.setBlock(i + 3, j + 17, k + 13, Blocks.stonebrick);
        world.setBlock(i + 3, j + 17, k + 20, Blocks.stonebrick);
        world.setBlock(i + 3, j + 18, k + 13, Blocks.stonebrick);
        world.setBlock(i + 3, j + 18, k + 20, Blocks.stonebrick);
        world.setBlock(i + 3, j + 19, k + 13, Blocks.stonebrick);
        world.setBlock(i + 3, j + 19, k + 20, Blocks.stonebrick);
        world.setBlock(i + 3, j + 20, k + 13, Blocks.stonebrick);
        world.setBlock(i + 3, j + 20, k + 14, Blocks.stonebrick);
        world.setBlock(i + 3, j + 20, k + 15, Blocks.stonebrick);
        world.setBlock(i + 3, j + 20, k + 16, Blocks.stonebrick);
        world.setBlock(i + 3, j + 20, k + 17, Blocks.stonebrick);
        world.setBlock(i + 3, j + 20, k + 18, Blocks.stonebrick);
        world.setBlock(i + 3, j + 20, k + 19, Blocks.stonebrick);
        world.setBlock(i + 3, j + 20, k + 20, Blocks.stonebrick);
        world.setBlock(i + 3, j + 21, k + 13, Blocks.stonebrick);
        Dungeons.spawner(world, i + 3, j + 21, k + 16, 12, 3);
        world.setBlock(i + 3, j + 21, k + 18, Blocks.stone_slab, 13, 0);
        world.setBlock(i + 3, j + 21, k + 19, Blocks.stone_slab, 5, 0);
        world.setBlock(i + 3, j + 21, k + 20, Blocks.stonebrick);
        world.setBlock(i + 3, j + 22, k + 13, Blocks.stonebrick);
        world.setBlock(i + 3, j + 22, k + 16, Blocks.stone_slab, 13, 0);
        world.setBlock(i + 3, j + 22, k + 17, Blocks.stone_slab, 5, 0);
        world.setBlock(i + 3, j + 22, k + 20, Blocks.stonebrick);
        world.setBlock(i + 3, j + 23, k + 13, Blocks.stonebrick);
        world.setBlock(i + 3, j + 23, k + 14, Blocks.stone_slab, 13, 0);
        world.setBlock(i + 3, j + 23, k + 15, Blocks.stone_slab, 5, 0);
        world.setBlock(i + 3, j + 23, k + 20, Blocks.stonebrick);
        world.setBlock(i + 3, j + 24, k + 13, Blocks.stonebrick);
        world.setBlock(i + 3, j + 24, k + 20, Blocks.stonebrick);
        world.setBlock(i + 3, j + 25, k + 13, Blocks.stonebrick);
        world.setBlock(i + 3, j + 25, k + 20, Blocks.stonebrick);
        world.setBlock(i + 3, j + 26, k + 13, Blocks.stonebrick);
        world.setBlock(i + 3, j + 26, k + 20, Blocks.stonebrick);
        world.setBlock(i + 3, j + 27, k + 13, Blocks.stonebrick);
        world.setBlock(i + 3, j + 27, k + 20, Blocks.stonebrick);
        world.setBlock(i + 3, j + 28, k + 13, Blocks.stonebrick);
        world.setBlock(i + 3, j + 28, k + 14, Blocks.stonebrick);
        world.setBlock(i + 3, j + 28, k + 15, Blocks.stonebrick);
        world.setBlock(i + 3, j + 28, k + 16, Blocks.stonebrick);
        world.setBlock(i + 3, j + 28, k + 17, Blocks.stonebrick);
        world.setBlock(i + 3, j + 28, k + 18, Blocks.stonebrick);
        world.setBlock(i + 3, j + 28, k + 19, Blocks.stonebrick);
        world.setBlock(i + 3, j + 28, k + 20, Blocks.stonebrick);
        world.setBlock(i + 3, j + 29, k + 13, Blocks.stonebrick);
        world.setBlock(i + 3, j + 29, k + 14, Blocks.stone_slab, 5, 0);
        world.setBlock(i + 3, j + 29, k + 15, Blocks.stone_slab, 13, 0);
        Dungeons.spawner(world, i + 3, j + 29, k + 17, 12, 2);
        world.setBlock(i + 3, j + 29, k + 20, Blocks.stonebrick);
        world.setBlock(i + 3, j + 30, k + 12, Blocks.stonebrick);
        world.setBlock(i + 3, j + 30, k + 13, Blocks.stonebrick);
        world.setBlock(i + 3, j + 30, k + 16, Blocks.stone_slab, 5, 0);
        world.setBlock(i + 3, j + 30, k + 17, Blocks.stone_slab, 13, 0);
        world.setBlock(i + 3, j + 30, k + 20, Blocks.stonebrick);
        world.setBlock(i + 3, j + 30, k + 21, Blocks.stonebrick);
        world.setBlock(i + 3, j + 31, k + 12, Blocks.stonebrick);
        world.setBlock(i + 3, j + 31, k + 13, Blocks.stonebrick);
        world.setBlock(i + 3, j + 31, k + 18, Blocks.stone_slab, 5, 0);
        world.setBlock(i + 3, j + 31, k + 19, Blocks.stone_slab, 13, 0);
        world.setBlock(i + 3, j + 31, k + 20, Blocks.stonebrick);
        world.setBlock(i + 3, j + 31, k + 21, Blocks.stonebrick);
        world.setBlock(i + 3, j + 32, k + 12, Blocks.stonebrick);
        world.setBlock(i + 3, j + 32, k + 13, Blocks.stonebrick);
        world.setBlock(i + 3, j + 32, k + 20, Blocks.stonebrick);
        world.setBlock(i + 3, j + 32, k + 21, Blocks.stonebrick);
        world.setBlock(i + 3, j + 33, k + 12, Blocks.stonebrick);
        world.setBlock(i + 3, j + 33, k + 21, Blocks.stonebrick);
        world.setBlock(i + 3, j + 34, k + 12, Blocks.stonebrick);
        world.setBlock(i + 3, j + 34, k + 21, Blocks.stonebrick);
        world.setBlock(i + 3, j + 35, k + 12, Blocks.stonebrick);
        world.setBlock(i + 3, j + 35, k + 21, Blocks.stonebrick);
        world.setBlock(i + 3, j + 36, k + 12, Blocks.stonebrick);
        world.setBlock(i + 3, j + 36, k + 13, Blocks.stonebrick);
        world.setBlock(i + 3, j + 36, k + 14, Blocks.stonebrick);
        world.setBlock(i + 3, j + 36, k + 15, Blocks.stonebrick);
        world.setBlock(i + 3, j + 36, k + 16, Blocks.stonebrick);
        world.setBlock(i + 3, j + 36, k + 17, Blocks.stonebrick);
        world.setBlock(i + 3, j + 36, k + 18, Blocks.stonebrick);
        world.setBlock(i + 3, j + 36, k + 19, Blocks.stonebrick);
        world.setBlock(i + 3, j + 36, k + 20, Blocks.stonebrick);
        world.setBlock(i + 3, j + 36, k + 21, Blocks.stonebrick);
        world.setBlock(i + 3, j + 37, k + 12, Blocks.stonebrick);
        world.setBlock(i + 3, j + 37, k + 21, Blocks.stonebrick);
        world.setBlock(i + 3, j + 52, k + 14, Blocks.wool);
        world.setBlock(i + 3, j + 52, k + 15, Blocks.wool);
        world.setBlock(i + 3, j + 53, k + 14, Blocks.wool, 14, 0);
        world.setBlock(i + 3, j + 53, k + 15, Blocks.wool, 14, 0);
        world.setBlock(i + 3, j + 54, k + 14, Blocks.wool);
        world.setBlock(i + 3, j + 54, k + 15, Blocks.wool);
        world.setBlock(i + 4, j, k, Blocks.grass);
        world.setBlock(i + 4, j, k + 1, Blocks.grass);
        world.setBlock(i + 4, j, k + 2, Blocks.grass);
        world.setBlock(i + 4, j, k + 3, Blocks.grass);
        world.setBlock(i + 4, j, k + 4, Blocks.grass);
        world.setBlock(i + 4, j, k + 5, Blocks.grass);
        world.setBlock(i + 4, j, k + 6, Blocks.grass);
        world.setBlock(i + 4, j, k + 7, Blocks.grass);
        world.setBlock(i + 4, j, k + 8, Blocks.grass);
        world.setBlock(i + 4, j, k + 9, Blocks.grass);
        world.setBlock(i + 4, j, k + 10, Blocks.grass);
        world.setBlock(i + 4, j, k + 11, Blocks.grass);
        world.setBlock(i + 4, j, k + 12, Blocks.dirt);
        world.setBlock(i + 4, j, k + 13, Blocks.cobblestone);
        world.setBlock(i + 4, j, k + 14, Blocks.cobblestone);
        world.setBlock(i + 4, j, k + 15, Blocks.cobblestone);
        world.setBlock(i + 4, j, k + 16, Blocks.cobblestone);
        world.setBlock(i + 4, j, k + 17, Blocks.cobblestone);
        world.setBlock(i + 4, j, k + 18, Blocks.cobblestone);
        world.setBlock(i + 4, j, k + 19, Blocks.cobblestone);
        world.setBlock(i + 4, j, k + 20, Blocks.cobblestone);
        world.setBlock(i + 4, j, k + 21, Blocks.dirt);
        world.setBlock(i + 4, j, k + 22, Blocks.grass);
        world.setBlock(i + 4, j, k + 23, Blocks.grass);
        world.setBlock(i + 4, j, k + 24, Blocks.grass);
        world.setBlock(i + 4, j, k + 25, Blocks.grass);
        world.setBlock(i + 4, j, k + 26, Blocks.grass);
        world.setBlock(i + 4, j, k + 27, Blocks.grass);
        world.setBlock(i + 4, j, k + 28, Blocks.grass);
        world.setBlock(i + 4, j, k + 29, Blocks.grass);
        world.setBlock(i + 4, j, k + 30, Blocks.grass);
        world.setBlock(i + 4, j + 1, k + 12, Blocks.cobblestone);
        world.setBlock(i + 4, j + 1, k + 21, Blocks.cobblestone);
        world.setBlock(i + 4, j + 2, k + 12, Blocks.cobblestone);
        world.setBlock(i + 4, j + 2, k + 21, Blocks.cobblestone);
        world.setBlock(i + 4, j + 3, k + 12, Blocks.cobblestone);
        world.setBlock(i + 4, j + 3, k + 21, Blocks.cobblestone);
        world.setBlock(i + 4, j + 4, k + 12, Blocks.cobblestone);
        world.setBlock(i + 4, j + 4, k + 13, Blocks.wool, 9, 0);
        world.setBlock(i + 4, j + 4, k + 14, Blocks.wool, 9, 0);
        world.setBlock(i + 4, j + 4, k + 15, Blocks.wool, 9, 0);
        world.setBlock(i + 4, j + 4, k + 16, Blocks.wool, 9, 0);
        world.setBlock(i + 4, j + 4, k + 17, Blocks.wool, 9, 0);
        world.setBlock(i + 4, j + 4, k + 18, Blocks.wool, 9, 0);
        world.setBlock(i + 4, j + 4, k + 19, Blocks.wool, 9, 0);
        world.setBlock(i + 4, j + 4, k + 20, Blocks.wool, 9, 0);
        world.setBlock(i + 4, j + 4, k + 21, Blocks.cobblestone);
        world.setBlock(i + 4, j + 5, k + 12, Blocks.stonebrick);
        world.setBlock(i + 4, j + 5, k + 21, Blocks.stonebrick);
        world.setBlock(i + 4, j + 6, k + 12, Blocks.stonebrick);
        world.setBlock(i + 4, j + 6, k + 21, Blocks.stonebrick);
        world.setBlock(i + 4, j + 7, k + 12, Blocks.stonebrick);
        world.setBlock(i + 4, j + 7, k + 21, Blocks.stonebrick);
        world.setBlock(i + 4, j + 8, k + 12, Blocks.stonebrick);
        world.setBlock(i + 4, j + 8, k + 13, Blocks.stonebrick);
        world.setBlock(i + 4, j + 8, k + 14, Blocks.stone_slab, 5, 0);
        world.setBlock(i + 4, j + 8, k + 15, Blocks.stonebrick);
        world.setBlock(i + 4, j + 8, k + 16, Blocks.stonebrick);
        world.setBlock(i + 4, j + 8, k + 17, Blocks.stonebrick);
        world.setBlock(i + 4, j + 8, k + 18, Blocks.stonebrick);
        world.setBlock(i + 4, j + 8, k + 19, Blocks.stonebrick);
        world.setBlock(i + 4, j + 8, k + 20, Blocks.stonebrick);
        world.setBlock(i + 4, j + 8, k + 21, Blocks.stonebrick);
        world.setBlock(i + 4, j + 9, k + 12, Blocks.stonebrick);
        world.setBlock(i + 4, j + 9, k + 21, Blocks.stonebrick);
        world.setBlock(i + 4, j + 10, k + 12, Blocks.stonebrick);
        world.setBlock(i + 4, j + 10, k + 21, Blocks.stonebrick);
        world.setBlock(i + 4, j + 11, k + 12, Blocks.stonebrick);
        world.setBlock(i + 4, j + 11, k + 21, Blocks.stonebrick);
        world.setBlock(i + 4, j + 12, k + 12, Blocks.stonebrick);
        world.setBlock(i + 4, j + 12, k + 13, Blocks.stonebrick);
        world.setBlock(i + 4, j + 12, k + 14, Blocks.stonebrick);
        world.setBlock(i + 4, j + 12, k + 15, Blocks.stonebrick);
        world.setBlock(i + 4, j + 12, k + 16, Blocks.stonebrick);
        world.setBlock(i + 4, j + 12, k + 17, Blocks.stonebrick);
        world.setBlock(i + 4, j + 12, k + 18, Blocks.stonebrick);
        world.setBlock(i + 4, j + 12, k + 19, Blocks.stonebrick);
        world.setBlock(i + 4, j + 12, k + 20, Blocks.stonebrick);
        world.setBlock(i + 4, j + 12, k + 21, Blocks.stonebrick);
        world.setBlock(i + 4, j + 13, k + 12, Blocks.stonebrick);
        world.setBlock(i + 4, j + 13, k + 13, Blocks.bookshelf);
        world.setBlock(i + 4, j + 13, k + 21, Blocks.stonebrick);
        world.setBlock(i + 4, j + 14, k + 12, Blocks.stonebrick);
        world.setBlock(i + 4, j + 14, k + 13, Blocks.bookshelf);
        world.setBlock(i + 4, j + 14, k + 21, Blocks.stonebrick);
        world.setBlock(i + 4, j + 15, k + 12, Blocks.stonebrick);
        world.setBlock(i + 4, j + 15, k + 21, Blocks.stonebrick);
        world.setBlock(i + 4, j + 16, k + 12, Blocks.stonebrick);
        world.setBlock(i + 4, j + 16, k + 13, Blocks.stonebrick);
        world.setBlock(i + 4, j + 16, k + 14, Blocks.stone_slab, 5, 0);
        world.setBlock(i + 4, j + 16, k + 15, Blocks.stonebrick);
        world.setBlock(i + 4, j + 16, k + 16, Blocks.stonebrick);
        world.setBlock(i + 4, j + 16, k + 17, Blocks.stonebrick);
        world.setBlock(i + 4, j + 16, k + 18, Blocks.stonebrick);
        world.setBlock(i + 4, j + 16, k + 19, Blocks.stonebrick);
        world.setBlock(i + 4, j + 16, k + 20, Blocks.stonebrick);
        world.setBlock(i + 4, j + 16, k + 21, Blocks.stonebrick);
        world.setBlock(i + 4, j + 17, k + 12, Blocks.stonebrick);
        world.setBlock(i + 4, j + 17, k + 21, Blocks.stonebrick);
        world.setBlock(i + 4, j + 18, k + 12, Blocks.stonebrick);
        world.setBlock(i + 4, j + 18, k + 21, Blocks.stonebrick);
        world.setBlock(i + 4, j + 19, k + 12, Blocks.stonebrick);
        world.setBlock(i + 4, j + 19, k + 21, Blocks.stonebrick);
        world.setBlock(i + 4, j + 20, k + 12, Blocks.stonebrick);
        world.setBlock(i + 4, j + 20, k + 13, Blocks.stonebrick);
        world.setBlock(i + 4, j + 20, k + 14, Blocks.stonebrick);
        world.setBlock(i + 4, j + 20, k + 15, Blocks.stonebrick);
        world.setBlock(i + 4, j + 20, k + 16, Blocks.stonebrick);
        world.setBlock(i + 4, j + 20, k + 17, Blocks.stonebrick);
        world.setBlock(i + 4, j + 20, k + 18, Blocks.stonebrick);
        world.setBlock(i + 4, j + 20, k + 19, Blocks.stonebrick);
        world.setBlock(i + 4, j + 20, k + 20, Blocks.stonebrick);
        world.setBlock(i + 4, j + 20, k + 21, Blocks.stonebrick);
        world.setBlock(i + 4, j + 21, k + 12, Blocks.stonebrick);
        world.setBlock(i + 4, j + 21, k + 21, Blocks.stonebrick);
        world.setBlock(i + 4, j + 22, k + 12, Blocks.stonebrick);
        world.setBlock(i + 4, j + 22, k + 21, Blocks.stonebrick);
        world.setBlock(i + 4, j + 23, k + 12, Blocks.stonebrick);
        world.setBlock(i + 4, j + 23, k + 21, Blocks.stonebrick);
        world.setBlock(i + 4, j + 24, k + 12, Blocks.stonebrick);
        world.setBlock(i + 4, j + 24, k + 13, Blocks.stonebrick);
        world.setBlock(i + 4, j + 24, k + 14, Blocks.stone_slab, 5, 0);
        world.setBlock(i + 4, j + 24, k + 15, Blocks.stonebrick);
        world.setBlock(i + 4, j + 24, k + 16, Blocks.stonebrick);
        world.setBlock(i + 4, j + 24, k + 17, Blocks.stonebrick);
        world.setBlock(i + 4, j + 24, k + 18, Blocks.stonebrick);
        world.setBlock(i + 4, j + 24, k + 19, Blocks.stonebrick);
        world.setBlock(i + 4, j + 24, k + 20, Blocks.stonebrick);
        world.setBlock(i + 4, j + 24, k + 21, Blocks.stonebrick);
        world.setBlock(i + 4, j + 25, k + 12, Blocks.stonebrick);
        world.setBlock(i + 4, j + 25, k + 21, Blocks.stonebrick);
        world.setBlock(i + 4, j + 26, k + 12, Blocks.stonebrick);
        world.setBlock(i + 4, j + 26, k + 21, Blocks.stonebrick);
        world.setBlock(i + 4, j + 27, k + 12, Blocks.stonebrick);
        world.setBlock(i + 4, j + 27, k + 21, Blocks.stonebrick);
        world.setBlock(i + 4, j + 28, k + 12, Blocks.stonebrick);
        world.setBlock(i + 4, j + 28, k + 13, Blocks.stonebrick);
        world.setBlock(i + 4, j + 28, k + 14, Blocks.stonebrick);
        world.setBlock(i + 4, j + 28, k + 15, Blocks.stonebrick);
        world.setBlock(i + 4, j + 28, k + 16, Blocks.stonebrick);
        world.setBlock(i + 4, j + 28, k + 17, Blocks.stonebrick);
        world.setBlock(i + 4, j + 28, k + 18, Blocks.stonebrick);
        world.setBlock(i + 4, j + 28, k + 19, Blocks.stonebrick);
        world.setBlock(i + 4, j + 28, k + 20, Blocks.stonebrick);
        world.setBlock(i + 4, j + 28, k + 21, Blocks.stonebrick);
        world.setBlock(i + 4, j + 29, k + 12, Blocks.stonebrick);
        world.setBlock(i + 4, j + 29, k + 21, Blocks.stonebrick);
        world.setBlock(i + 4, j + 30, k + 11, Blocks.stonebrick);
        world.setBlock(i + 4, j + 30, k + 12, Blocks.stonebrick);
        world.setBlock(i + 4, j + 30, k + 21, Blocks.stonebrick);
        world.setBlock(i + 4, j + 30, k + 22, Blocks.stonebrick);
        world.setBlock(i + 4, j + 31, k + 11, Blocks.stonebrick);
        world.setBlock(i + 4, j + 31, k + 12, Blocks.stonebrick);
        world.setBlock(i + 4, j + 31, k + 21, Blocks.stonebrick);
        world.setBlock(i + 4, j + 31, k + 22, Blocks.stonebrick);
        world.setBlock(i + 4, j + 32, k + 11, Blocks.stonebrick);
        world.setBlock(i + 4, j + 32, k + 12, Blocks.stonebrick);
        world.setBlock(i + 4, j + 32, k + 13, Blocks.stonebrick);
        world.setBlock(i + 4, j + 32, k + 14, Blocks.stonebrick);
        world.setBlock(i + 4, j + 32, k + 15, Blocks.stonebrick);
        world.setBlock(i + 4, j + 32, k + 16, Blocks.stonebrick);
        world.setBlock(i + 4, j + 32, k + 17, Blocks.stonebrick);
        world.setBlock(i + 4, j + 32, k + 18, Blocks.stonebrick);
        world.setBlock(i + 4, j + 32, k + 19, Blocks.stone_slab, 5, 0);
        world.setBlock(i + 4, j + 32, k + 20, Blocks.stonebrick);
        world.setBlock(i + 4, j + 32, k + 21, Blocks.stonebrick);
        world.setBlock(i + 4, j + 32, k + 22, Blocks.stonebrick);
        world.setBlock(i + 4, j + 33, k + 11, Blocks.stonebrick);
        world.setBlock(i + 4, j + 33, k + 22, Blocks.stonebrick);
        world.setBlock(i + 4, j + 34, k + 11, Blocks.stonebrick);
        world.setBlock(i + 4, j + 34, k + 22, Blocks.stonebrick);
        world.setBlock(i + 4, j + 35, k + 11, Blocks.stonebrick);
        world.setBlock(i + 4, j + 35, k + 22, Blocks.stonebrick);
        world.setBlock(i + 4, j + 36, k + 11, Blocks.stonebrick);
        world.setBlock(i + 4, j + 36, k + 12, Blocks.stonebrick);
        world.setBlock(i + 4, j + 36, k + 13, Blocks.stonebrick);
        world.setBlock(i + 4, j + 36, k + 14, Blocks.stonebrick);
        world.setBlock(i + 4, j + 36, k + 15, Blocks.stonebrick);
        world.setBlock(i + 4, j + 36, k + 16, Blocks.stonebrick);
        world.setBlock(i + 4, j + 36, k + 17, Blocks.stonebrick);
        world.setBlock(i + 4, j + 36, k + 18, Blocks.stonebrick);
        world.setBlock(i + 4, j + 36, k + 19, Blocks.stonebrick);
        world.setBlock(i + 4, j + 36, k + 20, Blocks.stonebrick);
        world.setBlock(i + 4, j + 36, k + 21, Blocks.stonebrick);
        world.setBlock(i + 4, j + 36, k + 22, Blocks.stonebrick);
        world.setBlock(i + 4, j + 37, k + 11, Blocks.stonebrick);
        world.setBlock(i + 4, j + 37, k + 22, Blocks.stonebrick);
        world.setBlock(i + 4, j + 38, k + 11, Blocks.stonebrick);
        world.setBlock(i + 4, j + 38, k + 22, Blocks.stonebrick);
        world.setBlock(i + 4, j + 39, k + 11, Blocks.stonebrick);
        world.setBlock(i + 4, j + 39, k + 22, Blocks.stonebrick);
        world.setBlock(i + 4, j + 52, k + 15, Blocks.wool);
        world.setBlock(i + 4, j + 52, k + 16, Blocks.wool);
        world.setBlock(i + 4, j + 53, k + 15, Blocks.wool, 14, 0);
        world.setBlock(i + 4, j + 53, k + 16, Blocks.wool, 14, 0);
        world.setBlock(i + 4, j + 54, k + 15, Blocks.wool);
        world.setBlock(i + 5, j, k, Blocks.grass);
        world.setBlock(i + 5, j, k + 1, Blocks.grass);
        world.setBlock(i + 5, j, k + 2, Blocks.grass);
        world.setBlock(i + 5, j, k + 3, Blocks.grass);
        world.setBlock(i + 5, j, k + 4, Blocks.grass);
        world.setBlock(i + 5, j, k + 5, Blocks.grass);
        world.setBlock(i + 5, j, k + 6, Blocks.grass);
        world.setBlock(i + 5, j, k + 7, Blocks.grass);
        world.setBlock(i + 5, j, k + 8, Blocks.grass);
        world.setBlock(i + 5, j, k + 9, Blocks.grass);
        world.setBlock(i + 5, j, k + 10, Blocks.grass);
        world.setBlock(i + 5, j, k + 11, Blocks.dirt);
        world.setBlock(i + 5, j, k + 12, Blocks.cobblestone);
        world.setBlock(i + 5, j, k + 13, Blocks.cobblestone);
        world.setBlock(i + 5, j, k + 14, Blocks.cobblestone);
        world.setBlock(i + 5, j, k + 15, Blocks.cobblestone);
        world.setBlock(i + 5, j, k + 16, Blocks.cobblestone);
        world.setBlock(i + 5, j, k + 17, Blocks.cobblestone);
        world.setBlock(i + 5, j, k + 18, Blocks.cobblestone);
        world.setBlock(i + 5, j, k + 19, Blocks.cobblestone);
        world.setBlock(i + 5, j, k + 20, Blocks.cobblestone);
        world.setBlock(i + 5, j, k + 21, Blocks.cobblestone);
        world.setBlock(i + 5, j, k + 22, Blocks.dirt);
        world.setBlock(i + 5, j, k + 23, Blocks.grass);
        world.setBlock(i + 5, j, k + 24, Blocks.grass);
        world.setBlock(i + 5, j, k + 25, Blocks.grass);
        world.setBlock(i + 5, j, k + 26, Blocks.grass);
        world.setBlock(i + 5, j, k + 27, Blocks.grass);
        world.setBlock(i + 5, j, k + 28, Blocks.grass);
        world.setBlock(i + 5, j, k + 29, Blocks.grass);
        world.setBlock(i + 5, j, k + 30, Blocks.grass);
        world.setBlock(i + 5, j + 1, k + 11, Blocks.cobblestone);
        world.setBlock(i + 5, j + 1, k + 22, Blocks.cobblestone);
        world.setBlock(i + 5, j + 2, k + 11, Blocks.cobblestone);
        world.setBlock(i + 5, j + 2, k + 22, Blocks.cobblestone);
        world.setBlock(i + 5, j + 3, k + 11, Blocks.cobblestone);
        world.setBlock(i + 5, j + 3, k + 22, Blocks.cobblestone);
        world.setBlock(i + 5, j + 4, k + 11, Blocks.cobblestone);
        world.setBlock(i + 5, j + 4, k + 12, Blocks.wool, 14, 0);
        world.setBlock(i + 5, j + 4, k + 13, Blocks.wool, 14, 0);
        world.setBlock(i + 5, j + 4, k + 14, Blocks.wool);
        world.setBlock(i + 5, j + 4, k + 15, Blocks.wool);
        world.setBlock(i + 5, j + 4, k + 16, Blocks.wool);
        world.setBlock(i + 5, j + 4, k + 17, Blocks.wool);
        world.setBlock(i + 5, j + 4, k + 18, Blocks.wool);
        world.setBlock(i + 5, j + 4, k + 19, Blocks.wool);
        world.setBlock(i + 5, j + 4, k + 20, Blocks.wool, 9, 0);
        world.setBlock(i + 5, j + 4, k + 21, Blocks.wool, 9, 0);
        world.setBlock(i + 5, j + 4, k + 22, Blocks.cobblestone);
        world.setBlock(i + 5, j + 5, k + 11, Blocks.stonebrick);
        world.setBlock(i + 5, j + 5, k + 22, Blocks.stonebrick);
        world.setBlock(i + 5, j + 6, k + 11, Blocks.stonebrick);
        world.setBlock(i + 5, j + 6, k + 22, Blocks.stonebrick);
        world.setBlock(i + 5, j + 7, k + 11, Blocks.stonebrick);
        world.setBlock(i + 5, j + 7, k + 22, Blocks.stonebrick);
        world.setBlock(i + 5, j + 8, k + 11, Blocks.stonebrick);
        world.setBlock(i + 5, j + 8, k + 12, Blocks.stonebrick);
        world.setBlock(i + 5, j + 8, k + 13, Blocks.stonebrick);
        world.setBlock(i + 5, j + 8, k + 14, Blocks.stonebrick);
        world.setBlock(i + 5, j + 8, k + 15, Blocks.stonebrick);
        world.setBlock(i + 5, j + 8, k + 16, Blocks.stonebrick);
        world.setBlock(i + 5, j + 8, k + 17, Blocks.stonebrick);
        world.setBlock(i + 5, j + 8, k + 18, Blocks.stonebrick);
        world.setBlock(i + 5, j + 8, k + 19, Blocks.stonebrick);
        world.setBlock(i + 5, j + 8, k + 20, Blocks.stonebrick);
        world.setBlock(i + 5, j + 8, k + 21, Blocks.stonebrick);
        world.setBlock(i + 5, j + 8, k + 22, Blocks.stonebrick);
        world.setBlock(i + 5, j + 9, k + 11, Blocks.stonebrick);
        world.setBlock(i + 5, j + 9, k + 22, Blocks.stonebrick);
        world.setBlock(i + 5, j + 10, k + 11, Blocks.stonebrick);
        world.setBlock(i + 5, j + 10, k + 22, Blocks.stonebrick);
        world.setBlock(i + 5, j + 11, k + 11, Blocks.stonebrick);
        world.setBlock(i + 5, j + 11, k + 22, Blocks.stonebrick);
        world.setBlock(i + 5, j + 12, k + 11, Blocks.stonebrick);
        world.setBlock(i + 5, j + 12, k + 12, Blocks.stonebrick);
        world.setBlock(i + 5, j + 12, k + 13, Blocks.stonebrick);
        world.setBlock(i + 5, j + 12, k + 14, Blocks.stonebrick);
        world.setBlock(i + 5, j + 12, k + 15, Blocks.stonebrick);
        world.setBlock(i + 5, j + 12, k + 16, Blocks.stonebrick);
        world.setBlock(i + 5, j + 12, k + 17, Blocks.stonebrick);
        world.setBlock(i + 5, j + 12, k + 18, Blocks.stonebrick);
        world.setBlock(i + 5, j + 12, k + 19, Blocks.stonebrick);
        world.setBlock(i + 5, j + 12, k + 20, Blocks.stonebrick);
        world.setBlock(i + 5, j + 12, k + 21, Blocks.stonebrick);
        world.setBlock(i + 5, j + 12, k + 22, Blocks.stonebrick);
        world.setBlock(i + 5, j + 13, k + 11, Blocks.stonebrick);
        world.setBlock(i + 5, j + 13, k + 12, Blocks.bookshelf);
        world.setBlock(i + 5, j + 13, k + 14, Blocks.enchanting_table);
        world.setBlock(i + 5, j + 13, k + 22, Blocks.stonebrick);
        world.setBlock(i + 5, j + 14, k + 11, Blocks.stonebrick);
        world.setBlock(i + 5, j + 14, k + 12, Blocks.bookshelf);
        world.setBlock(i + 5, j + 14, k + 22, Blocks.stonebrick);
        world.setBlock(i + 5, j + 15, k + 11, Blocks.stonebrick);
        world.setBlock(i + 5, j + 15, k + 22, Blocks.stonebrick);
        world.setBlock(i + 5, j + 16, k + 11, Blocks.stonebrick);
        world.setBlock(i + 5, j + 16, k + 12, Blocks.stonebrick);
        world.setBlock(i + 5, j + 16, k + 13, Blocks.stonebrick);
        world.setBlock(i + 5, j + 16, k + 14, Blocks.stonebrick);
        world.setBlock(i + 5, j + 16, k + 15, Blocks.stonebrick);
        world.setBlock(i + 5, j + 16, k + 16, Blocks.stonebrick);
        world.setBlock(i + 5, j + 16, k + 17, Blocks.stonebrick);
        world.setBlock(i + 5, j + 16, k + 18, Blocks.stonebrick);
        world.setBlock(i + 5, j + 16, k + 19, Blocks.stonebrick);
        world.setBlock(i + 5, j + 16, k + 20, Blocks.stonebrick);
        world.setBlock(i + 5, j + 16, k + 21, Blocks.stonebrick);
        world.setBlock(i + 5, j + 16, k + 22, Blocks.stonebrick);
        world.setBlock(i + 5, j + 17, k + 11, Blocks.stonebrick);
        world.setBlock(i + 5, j + 17, k + 22, Blocks.stonebrick);
        world.setBlock(i + 5, j + 18, k + 11, Blocks.stonebrick);
        world.setBlock(i + 5, j + 18, k + 22, Blocks.stonebrick);
        world.setBlock(i + 5, j + 19, k + 11, Blocks.stonebrick);
        world.setBlock(i + 5, j + 19, k + 22, Blocks.stonebrick);
        world.setBlock(i + 5, j + 20, k + 11, Blocks.stonebrick);
        world.setBlock(i + 5, j + 20, k + 12, Blocks.stonebrick);
        world.setBlock(i + 5, j + 20, k + 13, Blocks.stonebrick);
        world.setBlock(i + 5, j + 20, k + 14, Blocks.stonebrick);
        world.setBlock(i + 5, j + 20, k + 15, Blocks.stonebrick);
        world.setBlock(i + 5, j + 20, k + 16, Blocks.stonebrick);
        world.setBlock(i + 5, j + 20, k + 17, Blocks.stonebrick);
        world.setBlock(i + 5, j + 20, k + 18, Blocks.stonebrick);
        world.setBlock(i + 5, j + 20, k + 19, Blocks.stonebrick);
        world.setBlock(i + 5, j + 20, k + 20, Blocks.stonebrick);
        world.setBlock(i + 5, j + 20, k + 21, Blocks.stonebrick);
        world.setBlock(i + 5, j + 20, k + 22, Blocks.stonebrick);
        world.setBlock(i + 5, j + 21, k + 11, Blocks.stonebrick);
        world.setBlock(i + 5, j + 21, k + 12, Blocks.furnace, 3, 0);
        world.setBlock(i + 5, j + 21, k + 21, Blocks.furnace, 2, 0);
        world.setBlock(i + 5, j + 21, k + 22, Blocks.stonebrick);
        world.setBlock(i + 5, j + 22, k + 11, Blocks.stonebrick);
        world.setBlock(i + 5, j + 22, k + 12, Blocks.furnace, 3, 0);
        world.setBlock(i + 5, j + 22, k + 21, Blocks.furnace, 2, 0);
        world.setBlock(i + 5, j + 22, k + 22, Blocks.stonebrick);
        world.setBlock(i + 5, j + 23, k + 11, Blocks.stonebrick);
        world.setBlock(i + 5, j + 23, k + 12, Blocks.furnace, 3, 0);
        world.setBlock(i + 5, j + 23, k + 21, Blocks.furnace, 2, 0);
        world.setBlock(i + 5, j + 23, k + 22, Blocks.stonebrick);
        world.setBlock(i + 5, j + 24, k + 11, Blocks.stonebrick);
        world.setBlock(i + 5, j + 24, k + 12, Blocks.stonebrick);
        world.setBlock(i + 5, j + 24, k + 13, Blocks.stonebrick);
        world.setBlock(i + 5, j + 24, k + 14, Blocks.stonebrick);
        world.setBlock(i + 5, j + 24, k + 15, Blocks.stonebrick);
        world.setBlock(i + 5, j + 24, k + 16, Blocks.stonebrick);
        world.setBlock(i + 5, j + 24, k + 17, Blocks.stonebrick);
        world.setBlock(i + 5, j + 24, k + 18, Blocks.stonebrick);
        world.setBlock(i + 5, j + 24, k + 19, Blocks.stonebrick);
        world.setBlock(i + 5, j + 24, k + 20, Blocks.stonebrick);
        world.setBlock(i + 5, j + 24, k + 21, Blocks.stonebrick);
        world.setBlock(i + 5, j + 24, k + 22, Blocks.stonebrick);
        world.setBlock(i + 5, j + 25, k + 11, Blocks.stonebrick);
        world.setBlock(i + 5, j + 25, k + 21, Blocks.obsidian, 2, 0);
        world.setBlock(i + 5, j + 25, k + 22, Blocks.stonebrick);
        world.setBlock(i + 5, j + 26, k + 11, Blocks.stonebrick);
        world.setBlock(i + 5, j + 26, k + 22, Blocks.stonebrick);
        world.setBlock(i + 5, j + 27, k + 11, Blocks.stonebrick);
        world.setBlock(i + 5, j + 27, k + 22, Blocks.stonebrick);
        world.setBlock(i + 5, j + 28, k + 11, Blocks.stonebrick);
        world.setBlock(i + 5, j + 28, k + 12, Blocks.stonebrick);
        world.setBlock(i + 5, j + 28, k + 13, Blocks.stonebrick);
        world.setBlock(i + 5, j + 28, k + 14, Blocks.stonebrick);
        world.setBlock(i + 5, j + 28, k + 15, Blocks.stonebrick);
        world.setBlock(i + 5, j + 28, k + 16, Blocks.stonebrick);
        world.setBlock(i + 5, j + 28, k + 17, Blocks.stonebrick);
        world.setBlock(i + 5, j + 28, k + 18, Blocks.stonebrick);
        world.setBlock(i + 5, j + 28, k + 19, Blocks.stonebrick);
        world.setBlock(i + 5, j + 28, k + 20, Blocks.stonebrick);
        world.setBlock(i + 5, j + 28, k + 21, Blocks.stonebrick);
        world.setBlock(i + 5, j + 28, k + 22, Blocks.stonebrick);
        world.setBlock(i + 5, j + 29, k + 11, Blocks.stonebrick);
        world.setBlock(i + 5, j + 29, k + 22, Blocks.stonebrick);
        world.setBlock(i + 5, j + 30, k + 10, Blocks.stonebrick);
        world.setBlock(i + 5, j + 30, k + 11, Blocks.stonebrick);
        world.setBlock(i + 5, j + 30, k + 22, Blocks.stonebrick);
        world.setBlock(i + 5, j + 30, k + 23, Blocks.stonebrick);
        world.setBlock(i + 5, j + 31, k + 10, Blocks.stonebrick);
        world.setBlock(i + 5, j + 31, k + 11, Blocks.stonebrick);
        world.setBlock(i + 5, j + 31, k + 22, Blocks.stonebrick);
        world.setBlock(i + 5, j + 31, k + 23, Blocks.stonebrick);
        world.setBlock(i + 5, j + 32, k + 10, Blocks.stonebrick);
        world.setBlock(i + 5, j + 32, k + 11, Blocks.stonebrick);
        world.setBlock(i + 5, j + 32, k + 12, Blocks.stonebrick);
        world.setBlock(i + 5, j + 32, k + 13, Blocks.stonebrick);
        world.setBlock(i + 5, j + 32, k + 14, Blocks.stonebrick);
        world.setBlock(i + 5, j + 32, k + 15, Blocks.stonebrick);
        world.setBlock(i + 5, j + 32, k + 16, Blocks.stonebrick);
        world.setBlock(i + 5, j + 32, k + 17, Blocks.stonebrick);
        world.setBlock(i + 5, j + 32, k + 18, Blocks.stonebrick);
        world.setBlock(i + 5, j + 32, k + 19, Blocks.stonebrick);
        world.setBlock(i + 5, j + 32, k + 20, Blocks.stonebrick);
        world.setBlock(i + 5, j + 32, k + 21, Blocks.stonebrick);
        world.setBlock(i + 5, j + 32, k + 22, Blocks.stonebrick);
        world.setBlock(i + 5, j + 32, k + 23, Blocks.stonebrick);
        world.setBlock(i + 5, j + 33, k + 10, Blocks.stonebrick);
        world.setBlock(i + 5, j + 33, k + 11, Blocks.bookshelf);
        world.setBlock(i + 5, j + 33, k + 22, Blocks.bookshelf);
        world.setBlock(i + 5, j + 33, k + 23, Blocks.stonebrick);
        world.setBlock(i + 5, j + 34, k + 10, Blocks.stonebrick);
        world.setBlock(i + 5, j + 34, k + 11, Blocks.bookshelf);
        world.setBlock(i + 5, j + 34, k + 22, Blocks.bookshelf);
        world.setBlock(i + 5, j + 34, k + 23, Blocks.stonebrick);
        world.setBlock(i + 5, j + 35, k + 10, Blocks.stonebrick);
        world.setBlock(i + 5, j + 35, k + 11, Blocks.bookshelf);
        world.setBlock(i + 5, j + 35, k + 22, Blocks.bookshelf);
        world.setBlock(i + 5, j + 35, k + 23, Blocks.stonebrick);
        world.setBlock(i + 5, j + 36, k + 10, Blocks.stonebrick);
        world.setBlock(i + 5, j + 36, k + 11, Blocks.stonebrick);
        world.setBlock(i + 5, j + 36, k + 12, Blocks.stonebrick);
        world.setBlock(i + 5, j + 36, k + 13, Blocks.stonebrick);
        world.setBlock(i + 5, j + 36, k + 14, Blocks.stonebrick);
        world.setBlock(i + 5, j + 36, k + 15, Blocks.stonebrick);
        world.setBlock(i + 5, j + 36, k + 16, Blocks.stonebrick);
        world.setBlock(i + 5, j + 36, k + 17, Blocks.stonebrick);
        world.setBlock(i + 5, j + 36, k + 18, Blocks.stonebrick);
        world.setBlock(i + 5, j + 36, k + 19, Blocks.stonebrick);
        world.setBlock(i + 5, j + 36, k + 20, Blocks.stonebrick);
        world.setBlock(i + 5, j + 36, k + 21, Blocks.stonebrick);
        world.setBlock(i + 5, j + 36, k + 22, Blocks.stonebrick);
        world.setBlock(i + 5, j + 36, k + 23, Blocks.stonebrick);
        world.setBlock(i + 5, j + 37, k + 10, Blocks.stonebrick);
        world.setBlock(i + 5, j + 37, k + 16, Blocks.planks);
        Dungeons.spawner(world, i + 5, j + 37, k + 17, 12, 3);
        world.setBlock(i + 5, j + 37, k + 23, Blocks.stonebrick);
        world.setBlock(i + 5, j + 38, k + 10, Blocks.stonebrick);
        world.setBlock(i + 5, j + 38, k + 16, Blocks.planks);
        world.setBlock(i + 5, j + 38, k + 23, Blocks.stonebrick);
        world.setBlock(i + 5, j + 39, k + 16, Blocks.planks);
        world.setBlock(i + 5, j + 40, k + 16, Blocks.planks);
        world.setBlock(i + 5, j + 41, k + 16, Blocks.planks);
        world.setBlock(i + 5, j + 42, k + 16, Blocks.planks);
        world.setBlock(i + 5, j + 43, k + 16, Blocks.planks);
        world.setBlock(i + 5, j + 44, k + 16, Blocks.planks);
        world.setBlock(i + 5, j + 45, k + 16, Blocks.planks);
        world.setBlock(i + 5, j + 46, k + 16, Blocks.planks);
        world.setBlock(i + 5, j + 47, k + 16, Blocks.planks);
        world.setBlock(i + 5, j + 48, k + 16, Blocks.planks);
        world.setBlock(i + 5, j + 49, k + 16, Blocks.planks);
        world.setBlock(i + 5, j + 50, k + 16, Blocks.planks);
        world.setBlock(i + 5, j + 51, k + 16, Blocks.planks);
        world.setBlock(i + 5, j + 52, k + 16, Blocks.planks);
        world.setBlock(i + 5, j + 53, k + 16, Blocks.planks);
        world.setBlock(i + 5, j + 54, k + 15, Blocks.wool);
        world.setBlock(i + 5, j + 54, k + 16, Blocks.planks);
        world.setBlock(i + 6, j, k, Blocks.grass);
        world.setBlock(i + 6, j, k + 1, Blocks.grass);
        world.setBlock(i + 6, j, k + 2, Blocks.grass);
        world.setBlock(i + 6, j, k + 3, Blocks.grass);
        world.setBlock(i + 6, j, k + 4, Blocks.grass);
        world.setBlock(i + 6, j, k + 5, Blocks.grass);
        world.setBlock(i + 6, j, k + 6, Blocks.grass);
        world.setBlock(i + 6, j, k + 7, Blocks.grass);
        world.setBlock(i + 6, j, k + 8, Blocks.grass);
        world.setBlock(i + 6, j, k + 9, Blocks.grass);
        world.setBlock(i + 6, j, k + 10, Blocks.grass);
        world.setBlock(i + 6, j, k + 11, Blocks.dirt);
        world.setBlock(i + 6, j, k + 12, Blocks.cobblestone);
        world.setBlock(i + 6, j, k + 13, Blocks.cobblestone);
        world.setBlock(i + 6, j, k + 14, Blocks.cobblestone);
        world.setBlock(i + 6, j, k + 15, Blocks.cobblestone);
        world.setBlock(i + 6, j, k + 16, Blocks.cobblestone);
        world.setBlock(i + 6, j, k + 17, Blocks.cobblestone);
        world.setBlock(i + 6, j, k + 18, Blocks.cobblestone);
        world.setBlock(i + 6, j, k + 19, Blocks.cobblestone);
        world.setBlock(i + 6, j, k + 20, Blocks.cobblestone);
        world.setBlock(i + 6, j, k + 21, Blocks.cobblestone);
        world.setBlock(i + 6, j, k + 22, Blocks.dirt);
        world.setBlock(i + 6, j, k + 23, Blocks.grass);
        world.setBlock(i + 6, j, k + 24, Blocks.grass);
        world.setBlock(i + 6, j, k + 25, Blocks.grass);
        world.setBlock(i + 6, j, k + 26, Blocks.grass);
        world.setBlock(i + 6, j, k + 27, Blocks.grass);
        world.setBlock(i + 6, j, k + 28, Blocks.grass);
        world.setBlock(i + 6, j, k + 29, Blocks.grass);
        world.setBlock(i + 6, j, k + 30, Blocks.grass);
        world.setBlock(i + 6, j + 1, k + 11, Blocks.cobblestone);
        Dungeons.spawner(world, i + 6, j + 1, k + 16, 7, 1);
        world.setBlock(i + 6, j + 1, k + 22, Blocks.cobblestone);
        world.setBlock(i + 6, j + 2, k + 11, Blocks.cobblestone);
        world.setBlock(i + 6, j + 2, k + 22, Blocks.cobblestone);
        world.setBlock(i + 6, j + 3, k + 11, Blocks.cobblestone);
        world.setBlock(i + 6, j + 3, k + 22, Blocks.cobblestone);
        world.setBlock(i + 6, j + 4, k + 11, Blocks.cobblestone);
        world.setBlock(i + 6, j + 4, k + 12, Blocks.wool, 14, 0);
        world.setBlock(i + 6, j + 4, k + 13, Blocks.wool, 14, 0);
        world.setBlock(i + 6, j + 4, k + 14, Blocks.wool);
        world.setBlock(i + 6, j + 4, k + 15, Blocks.wool);
        world.setBlock(i + 6, j + 4, k + 16, Blocks.wool);
        world.setBlock(i + 6, j + 4, k + 17, Blocks.wool, 4, 0);
        world.setBlock(i + 6, j + 4, k + 18, Blocks.wool);
        world.setBlock(i + 6, j + 4, k + 19, Blocks.wool);
        world.setBlock(i + 6, j + 4, k + 20, Blocks.wool, 9, 0);
        world.setBlock(i + 6, j + 4, k + 21, Blocks.wool, 9, 0);
        world.setBlock(i + 6, j + 4, k + 22, Blocks.cobblestone);
        world.setBlock(i + 6, j + 5, k + 11, Blocks.stonebrick);
        world.setBlock(i + 6, j + 5, k + 22, Blocks.stonebrick);
        world.setBlock(i + 6, j + 6, k + 11, Blocks.stonebrick);
        world.setBlock(i + 6, j + 6, k + 22, Blocks.stonebrick);
        world.setBlock(i + 6, j + 7, k + 11, Blocks.stonebrick);
        world.setBlock(i + 6, j + 7, k + 22, Blocks.stonebrick);
        world.setBlock(i + 6, j + 8, k + 11, Blocks.stonebrick);
        world.setBlock(i + 6, j + 8, k + 12, Blocks.stonebrick);
        world.setBlock(i + 6, j + 8, k + 13, Blocks.stonebrick);
        world.setBlock(i + 6, j + 8, k + 14, Blocks.stonebrick);
        world.setBlock(i + 6, j + 8, k + 15, Blocks.stonebrick);
        world.setBlock(i + 6, j + 8, k + 16, Blocks.glass);
        world.setBlock(i + 6, j + 8, k + 17, Blocks.glass);
        world.setBlock(i + 6, j + 8, k + 18, Blocks.stonebrick);
        world.setBlock(i + 6, j + 8, k + 19, Blocks.stonebrick);
        world.setBlock(i + 6, j + 8, k + 20, Blocks.stonebrick);
        world.setBlock(i + 6, j + 8, k + 21, Blocks.stonebrick);
        world.setBlock(i + 6, j + 8, k + 22, Blocks.stonebrick);
        world.setBlock(i + 6, j + 9, k + 11, Blocks.stonebrick);
        world.setBlock(i + 6, j + 9, k + 22, Blocks.stonebrick);
        world.setBlock(i + 6, j + 10, k + 11, Blocks.stonebrick);
        world.setBlock(i + 6, j + 10, k + 22, Blocks.stonebrick);
        world.setBlock(i + 6, j + 11, k + 11, Blocks.stonebrick);
        world.setBlock(i + 6, j + 11, k + 22, Blocks.stonebrick);
        world.setBlock(i + 6, j + 12, k + 11, Blocks.stonebrick);
        world.setBlock(i + 6, j + 12, k + 12, Blocks.stonebrick);
        world.setBlock(i + 6, j + 12, k + 13, Blocks.stonebrick);
        world.setBlock(i + 6, j + 12, k + 14, Blocks.stonebrick);
        world.setBlock(i + 6, j + 12, k + 15, Blocks.stonebrick);
        world.setBlock(i + 6, j + 12, k + 16, Blocks.glass);
        world.setBlock(i + 6, j + 12, k + 17, Blocks.glass);
        world.setBlock(i + 6, j + 12, k + 18, Blocks.stonebrick);
        world.setBlock(i + 6, j + 12, k + 19, Blocks.stonebrick);
        world.setBlock(i + 6, j + 12, k + 20, Blocks.stonebrick);
        world.setBlock(i + 6, j + 12, k + 21, Blocks.stonebrick);
        world.setBlock(i + 6, j + 12, k + 22, Blocks.stonebrick);
        world.setBlock(i + 6, j + 13, k + 11, Blocks.stonebrick);
        world.setBlock(i + 6, j + 13, k + 22, Blocks.stonebrick);
        world.setBlock(i + 6, j + 14, k + 11, Blocks.stonebrick);
        world.setBlock(i + 6, j + 14, k + 22, Blocks.stonebrick);
        world.setBlock(i + 6, j + 15, k + 11, Blocks.stonebrick);
        world.setBlock(i + 6, j + 15, k + 22, Blocks.stonebrick);
        world.setBlock(i + 6, j + 16, k + 11, Blocks.stonebrick);
        world.setBlock(i + 6, j + 16, k + 12, Blocks.stonebrick);
        world.setBlock(i + 6, j + 16, k + 13, Blocks.stonebrick);
        world.setBlock(i + 6, j + 16, k + 14, Blocks.stonebrick);
        world.setBlock(i + 6, j + 16, k + 15, Blocks.stonebrick);
        world.setBlock(i + 6, j + 16, k + 16, Blocks.glass);
        world.setBlock(i + 6, j + 16, k + 17, Blocks.glass);
        world.setBlock(i + 6, j + 16, k + 18, Blocks.stonebrick);
        world.setBlock(i + 6, j + 16, k + 19, Blocks.stonebrick);
        world.setBlock(i + 6, j + 16, k + 20, Blocks.stonebrick);
        world.setBlock(i + 6, j + 16, k + 21, Blocks.stonebrick);
        world.setBlock(i + 6, j + 16, k + 22, Blocks.stonebrick);
        world.setBlock(i + 6, j + 17, k + 11, Blocks.stonebrick);
        world.setBlock(i + 6, j + 17, k + 22, Blocks.stonebrick);
        world.setBlock(i + 6, j + 18, k + 11, Blocks.stonebrick);
        world.setBlock(i + 6, j + 18, k + 22, Blocks.stonebrick);
        world.setBlock(i + 6, j + 19, k + 11, Blocks.stonebrick);
        world.setBlock(i + 6, j + 19, k + 22, Blocks.stonebrick);
        world.setBlock(i + 6, j + 20, k + 11, Blocks.stonebrick);
        world.setBlock(i + 6, j + 20, k + 12, Blocks.stonebrick);
        world.setBlock(i + 6, j + 20, k + 13, Blocks.stonebrick);
        world.setBlock(i + 6, j + 20, k + 14, Blocks.stonebrick);
        world.setBlock(i + 6, j + 20, k + 15, Blocks.stonebrick);
        world.setBlock(i + 6, j + 20, k + 16, Blocks.glass);
        world.setBlock(i + 6, j + 20, k + 17, Blocks.glass);
        world.setBlock(i + 6, j + 20, k + 18, Blocks.stonebrick);
        world.setBlock(i + 6, j + 20, k + 19, Blocks.stonebrick);
        world.setBlock(i + 6, j + 20, k + 20, Blocks.stonebrick);
        world.setBlock(i + 6, j + 20, k + 21, Blocks.stonebrick);
        world.setBlock(i + 6, j + 20, k + 22, Blocks.stonebrick);
        world.setBlock(i + 6, j + 21, k + 11, Blocks.stonebrick);
        world.setBlock(i + 6, j + 21, k + 12, Blocks.stonebrick);
        world.setBlock(i + 6, j + 21, k + 21, Blocks.stonebrick);
        world.setBlock(i + 6, j + 21, k + 22, Blocks.stonebrick);
        world.setBlock(i + 6, j + 22, k + 11, Blocks.stonebrick);
        world.setBlock(i + 6, j + 22, k + 12, Blocks.stonebrick);
        world.setBlock(i + 6, j + 22, k + 21, Blocks.stonebrick);
        world.setBlock(i + 6, j + 22, k + 22, Blocks.stonebrick);
        world.setBlock(i + 6, j + 23, k + 11, Blocks.stonebrick);
        world.setBlock(i + 6, j + 23, k + 12, Blocks.stonebrick);
        world.setBlock(i + 6, j + 23, k + 21, Blocks.stonebrick);
        world.setBlock(i + 6, j + 23, k + 22, Blocks.stonebrick);
        world.setBlock(i + 6, j + 24, k + 11, Blocks.stonebrick);
        world.setBlock(i + 6, j + 24, k + 12, Blocks.stonebrick);
        world.setBlock(i + 6, j + 24, k + 13, Blocks.stonebrick);
        world.setBlock(i + 6, j + 24, k + 14, Blocks.stonebrick);
        world.setBlock(i + 6, j + 24, k + 15, Blocks.stonebrick);
        world.setBlock(i + 6, j + 24, k + 16, Blocks.glass);
        world.setBlock(i + 6, j + 24, k + 17, Blocks.glass);
        world.setBlock(i + 6, j + 24, k + 18, Blocks.stonebrick);
        world.setBlock(i + 6, j + 24, k + 19, Blocks.stonebrick);
        world.setBlock(i + 6, j + 24, k + 20, Blocks.stonebrick);
        world.setBlock(i + 6, j + 24, k + 21, Blocks.stonebrick);
        world.setBlock(i + 6, j + 24, k + 22, Blocks.stonebrick);
        world.setBlock(i + 6, j + 25, k + 11, Blocks.stonebrick);
        WorldGenWarlordDungeon.chest(world, rand, i + 6, j + 25, k + 21, "dungeonChest", rand.nextInt(5) + 1);
        world.setBlock(i + 6, j + 25, k + 22, Blocks.stonebrick);
        world.setBlock(i + 6, j + 26, k + 11, Blocks.stonebrick);
        WorldGenWarlordDungeon.chest(world, rand, i + 6, j + 25, k + 21, "dungeonChest", rand.nextInt(5) + 1);
        world.setBlock(i + 6, j + 26, k + 22, Blocks.stonebrick);
        world.setBlock(i + 6, j + 27, k + 11, Blocks.stonebrick);
        world.setBlock(i + 6, j + 27, k + 22, Blocks.stonebrick);
        world.setBlock(i + 6, j + 28, k + 11, Blocks.stonebrick);
        world.setBlock(i + 6, j + 28, k + 12, Blocks.stonebrick);
        world.setBlock(i + 6, j + 28, k + 13, Blocks.stonebrick);
        world.setBlock(i + 6, j + 28, k + 14, Blocks.stonebrick);
        world.setBlock(i + 6, j + 28, k + 15, Blocks.stonebrick);
        world.setBlock(i + 6, j + 28, k + 16, Blocks.glass);
        world.setBlock(i + 6, j + 28, k + 17, Blocks.glass);
        world.setBlock(i + 6, j + 28, k + 18, Blocks.stonebrick);
        world.setBlock(i + 6, j + 28, k + 19, Blocks.stonebrick);
        world.setBlock(i + 6, j + 28, k + 20, Blocks.stonebrick);
        world.setBlock(i + 6, j + 28, k + 21, Blocks.stonebrick);
        world.setBlock(i + 6, j + 28, k + 22, Blocks.stonebrick);
        world.setBlock(i + 6, j + 29, k + 11, Blocks.stonebrick);
        world.setBlock(i + 6, j + 29, k + 22, Blocks.stonebrick);
        world.setBlock(i + 6, j + 30, k + 10, Blocks.stonebrick);
        world.setBlock(i + 6, j + 30, k + 11, Blocks.stonebrick);
        world.setBlock(i + 6, j + 30, k + 22, Blocks.stonebrick);
        world.setBlock(i + 6, j + 30, k + 23, Blocks.stonebrick);
        world.setBlock(i + 6, j + 31, k + 10, Blocks.stonebrick);
        world.setBlock(i + 6, j + 31, k + 11, Blocks.stonebrick);
        world.setBlock(i + 6, j + 31, k + 22, Blocks.stonebrick);
        world.setBlock(i + 6, j + 31, k + 23, Blocks.stonebrick);
        world.setBlock(i + 6, j + 32, k + 10, Blocks.stonebrick);
        world.setBlock(i + 6, j + 32, k + 11, Blocks.stonebrick);
        world.setBlock(i + 6, j + 32, k + 12, Blocks.stonebrick);
        world.setBlock(i + 6, j + 32, k + 13, Blocks.stonebrick);
        world.setBlock(i + 6, j + 32, k + 14, Blocks.stonebrick);
        world.setBlock(i + 6, j + 32, k + 15, Blocks.stonebrick);
        world.setBlock(i + 6, j + 32, k + 16, Blocks.glass);
        world.setBlock(i + 6, j + 32, k + 17, Blocks.glass);
        world.setBlock(i + 6, j + 32, k + 18, Blocks.stonebrick);
        world.setBlock(i + 6, j + 32, k + 19, Blocks.stonebrick);
        world.setBlock(i + 6, j + 32, k + 20, Blocks.stonebrick);
        world.setBlock(i + 6, j + 32, k + 21, Blocks.stonebrick);
        world.setBlock(i + 6, j + 32, k + 22, Blocks.stonebrick);
        world.setBlock(i + 6, j + 32, k + 23, Blocks.stonebrick);
        world.setBlock(i + 6, j + 33, k + 10, Blocks.stonebrick);
        world.setBlock(i + 6, j + 33, k + 23, Blocks.stonebrick);
        world.setBlock(i + 6, j + 34, k + 10, Blocks.stonebrick);
        world.setBlock(i + 6, j + 34, k + 23, Blocks.stonebrick);
        world.setBlock(i + 6, j + 35, k + 10, Blocks.stonebrick);
        world.setBlock(i + 6, j + 35, k + 23, Blocks.stonebrick);
        world.setBlock(i + 6, j + 36, k + 10, Blocks.stonebrick);
        world.setBlock(i + 6, j + 36, k + 11, Blocks.stonebrick);
        world.setBlock(i + 6, j + 36, k + 12, Blocks.stonebrick);
        world.setBlock(i + 6, j + 36, k + 13, Blocks.stonebrick);
        world.setBlock(i + 6, j + 36, k + 14, Blocks.stonebrick);
        world.setBlock(i + 6, j + 36, k + 15, Blocks.stonebrick);
        world.setBlock(i + 6, j + 36, k + 16, Blocks.stonebrick);
        world.setBlock(i + 6, j + 36, k + 17, Blocks.stonebrick);
        world.setBlock(i + 6, j + 36, k + 18, Blocks.stonebrick);
        world.setBlock(i + 6, j + 36, k + 19, Blocks.stonebrick);
        world.setBlock(i + 6, j + 36, k + 20, Blocks.stonebrick);
        world.setBlock(i + 6, j + 36, k + 21, Blocks.stonebrick);
        world.setBlock(i + 6, j + 36, k + 22, Blocks.stonebrick);
        world.setBlock(i + 6, j + 36, k + 23, Blocks.stonebrick);
        world.setBlock(i + 6, j + 37, k + 10, Blocks.stonebrick);
        world.setBlock(i + 6, j + 37, k + 17, Blocks.planks);
        world.setBlock(i + 6, j + 37, k + 23, Blocks.stonebrick);
        world.setBlock(i + 6, j + 38, k + 17, Blocks.planks);
        world.setBlock(i + 6, j + 39, k + 17, Blocks.planks);
        world.setBlock(i + 6, j + 40, k + 17, Blocks.planks);
        world.setBlock(i + 6, j + 41, k + 17, Blocks.planks);
        world.setBlock(i + 6, j + 42, k + 17, Blocks.planks);
        world.setBlock(i + 6, j + 43, k + 17, Blocks.planks);
        world.setBlock(i + 6, j + 44, k + 17, Blocks.planks);
        world.setBlock(i + 6, j + 45, k + 17, Blocks.planks);
        world.setBlock(i + 7, j, k, Blocks.grass);
        world.setBlock(i + 7, j, k + 1, Blocks.grass);
        world.setBlock(i + 7, j, k + 2, Blocks.grass);
        world.setBlock(i + 7, j, k + 3, Blocks.grass);
        world.setBlock(i + 7, j, k + 4, Blocks.grass);
        world.setBlock(i + 7, j, k + 5, Blocks.grass);
        world.setBlock(i + 7, j, k + 6, Blocks.grass);
        world.setBlock(i + 7, j, k + 7, Blocks.grass);
        world.setBlock(i + 7, j, k + 8, Blocks.grass);
        world.setBlock(i + 7, j, k + 9, Blocks.grass);
        world.setBlock(i + 7, j, k + 10, Blocks.grass);
        world.setBlock(i + 7, j, k + 11, Blocks.dirt);
        world.setBlock(i + 7, j, k + 12, Blocks.cobblestone);
        world.setBlock(i + 7, j, k + 13, Blocks.cobblestone);
        world.setBlock(i + 7, j, k + 14, Blocks.cobblestone);
        world.setBlock(i + 7, j, k + 15, Blocks.cobblestone);
        world.setBlock(i + 7, j, k + 16, Blocks.cobblestone);
        world.setBlock(i + 7, j, k + 17, Blocks.cobblestone);
        world.setBlock(i + 7, j, k + 18, Blocks.cobblestone);
        world.setBlock(i + 7, j, k + 19, Blocks.cobblestone);
        world.setBlock(i + 7, j, k + 20, Blocks.cobblestone);
        world.setBlock(i + 7, j, k + 21, Blocks.cobblestone);
        world.setBlock(i + 7, j, k + 22, Blocks.dirt);
        world.setBlock(i + 7, j, k + 23, Blocks.grass);
        world.setBlock(i + 7, j, k + 24, Blocks.grass);
        world.setBlock(i + 7, j, k + 25, Blocks.grass);
        world.setBlock(i + 7, j, k + 26, Blocks.grass);
        world.setBlock(i + 7, j, k + 27, Blocks.grass);
        world.setBlock(i + 7, j, k + 28, Blocks.grass);
        world.setBlock(i + 7, j, k + 29, Blocks.grass);
        world.setBlock(i + 7, j, k + 30, Blocks.grass);
        world.setBlock(i + 7, j + 1, k + 11, Blocks.cobblestone);
        world.setBlock(i + 7, j + 1, k + 22, Blocks.cobblestone);
        world.setBlock(i + 7, j + 2, k + 11, Blocks.cobblestone);
        world.setBlock(i + 7, j + 2, k + 22, Blocks.cobblestone);
        world.setBlock(i + 7, j + 3, k + 11, Blocks.cobblestone);
        world.setBlock(i + 7, j + 3, k + 22, Blocks.cobblestone);
        world.setBlock(i + 7, j + 4, k + 11, Blocks.cobblestone);
        world.setBlock(i + 7, j + 4, k + 12, Blocks.wool, 14, 0);
        world.setBlock(i + 7, j + 4, k + 13, Blocks.wool, 14, 0);
        world.setBlock(i + 7, j + 4, k + 14, Blocks.wool);
        world.setBlock(i + 7, j + 4, k + 15, Blocks.wool, 4, 0);
        world.setBlock(i + 7, j + 4, k + 16, Blocks.wool, 4, 0);
        world.setBlock(i + 7, j + 4, k + 17, Blocks.wool, 4, 0);
        world.setBlock(i + 7, j + 4, k + 18, Blocks.wool);
        world.setBlock(i + 7, j + 4, k + 19, Blocks.wool);
        world.setBlock(i + 7, j + 4, k + 20, Blocks.wool, 9, 0);
        world.setBlock(i + 7, j + 4, k + 21, Blocks.wool, 9, 0);
        world.setBlock(i + 7, j + 4, k + 22, Blocks.cobblestone);
        world.setBlock(i + 7, j + 5, k + 11, Blocks.stonebrick);
        world.setBlock(i + 7, j + 5, k + 22, Blocks.stonebrick);
        world.setBlock(i + 7, j + 6, k + 11, Blocks.stonebrick);
        world.setBlock(i + 7, j + 6, k + 22, Blocks.stonebrick);
        world.setBlock(i + 7, j + 7, k + 11, Blocks.stonebrick);
        world.setBlock(i + 7, j + 7, k + 22, Blocks.stonebrick);
        world.setBlock(i + 7, j + 8, k + 11, Blocks.stonebrick);
        world.setBlock(i + 7, j + 8, k + 12, Blocks.stonebrick);
        world.setBlock(i + 7, j + 8, k + 13, Blocks.stonebrick);
        world.setBlock(i + 7, j + 8, k + 14, Blocks.stonebrick);
        world.setBlock(i + 7, j + 8, k + 15, Blocks.glass);
        world.setBlock(i + 7, j + 8, k + 16, Blocks.glass);
        world.setBlock(i + 7, j + 8, k + 17, Blocks.glass);
        world.setBlock(i + 7, j + 8, k + 18, Blocks.glass);
        world.setBlock(i + 7, j + 8, k + 19, Blocks.stonebrick);
        world.setBlock(i + 7, j + 8, k + 20, Blocks.stonebrick);
        world.setBlock(i + 7, j + 8, k + 21, Blocks.stonebrick);
        world.setBlock(i + 7, j + 8, k + 22, Blocks.stonebrick);
        world.setBlock(i + 7, j + 9, k + 11, Blocks.stonebrick);
        world.setBlock(i + 7, j + 9, k + 12, Blocks.obsidian, 3, 0);
        WorldGenWarlordDungeon.chest(world, rand, i + 7, j + 9, k + 21, "dungeonChest", rand.nextInt(5) + 1);
        world.setBlock(i + 7, j + 9, k + 22, Blocks.stonebrick);
        world.setBlock(i + 7, j + 10, k + 11, Blocks.stonebrick);
        world.setBlock(i + 7, j + 10, k + 22, Blocks.stonebrick);
        world.setBlock(i + 7, j + 11, k + 11, Blocks.stonebrick);
        world.setBlock(i + 7, j + 11, k + 22, Blocks.stonebrick);
        world.setBlock(i + 7, j + 12, k + 11, Blocks.stonebrick);
        world.setBlock(i + 7, j + 12, k + 12, Blocks.stonebrick);
        world.setBlock(i + 7, j + 12, k + 13, Blocks.stonebrick);
        world.setBlock(i + 7, j + 12, k + 14, Blocks.stonebrick);
        world.setBlock(i + 7, j + 12, k + 15, Blocks.glass);
        world.setBlock(i + 7, j + 12, k + 16, Blocks.glass);
        world.setBlock(i + 7, j + 12, k + 17, Blocks.glass);
        world.setBlock(i + 7, j + 12, k + 18, Blocks.glass);
        world.setBlock(i + 7, j + 12, k + 19, Blocks.stonebrick);
        world.setBlock(i + 7, j + 12, k + 20, Blocks.stonebrick);
        world.setBlock(i + 7, j + 12, k + 21, Blocks.stonebrick);
        world.setBlock(i + 7, j + 12, k + 22, Blocks.stonebrick);
        world.setBlock(i + 7, j + 13, k + 11, Blocks.stonebrick);
        world.setBlock(i + 7, j + 13, k + 22, Blocks.stonebrick);
        world.setBlock(i + 7, j + 14, k + 11, Blocks.stonebrick);
        world.setBlock(i + 7, j + 14, k + 22, Blocks.stonebrick);
        world.setBlock(i + 7, j + 15, k + 11, Blocks.stonebrick);
        world.setBlock(i + 7, j + 15, k + 22, Blocks.stonebrick);
        world.setBlock(i + 7, j + 16, k + 11, Blocks.stonebrick);
        world.setBlock(i + 7, j + 16, k + 12, Blocks.stonebrick);
        world.setBlock(i + 7, j + 16, k + 13, Blocks.stonebrick);
        world.setBlock(i + 7, j + 16, k + 14, Blocks.stonebrick);
        world.setBlock(i + 7, j + 16, k + 15, Blocks.glass);
        world.setBlock(i + 7, j + 16, k + 16, Blocks.glass);
        world.setBlock(i + 7, j + 16, k + 17, Blocks.glass);
        world.setBlock(i + 7, j + 16, k + 18, Blocks.glass);
        world.setBlock(i + 7, j + 16, k + 19, Blocks.stonebrick);
        world.setBlock(i + 7, j + 16, k + 20, Blocks.stonebrick);
        world.setBlock(i + 7, j + 16, k + 21, Blocks.stonebrick);
        world.setBlock(i + 7, j + 16, k + 22, Blocks.stonebrick);
        world.setBlock(i + 7, j + 17, k + 11, Blocks.stonebrick);
        world.setBlock(i + 7, j + 17, k + 22, Blocks.stonebrick);
        world.setBlock(i + 7, j + 18, k + 11, Blocks.stonebrick);
        world.setBlock(i + 7, j + 18, k + 22, Blocks.stonebrick);
        world.setBlock(i + 7, j + 19, k + 11, Blocks.stonebrick);
        world.setBlock(i + 7, j + 19, k + 22, Blocks.stonebrick);
        world.setBlock(i + 7, j + 20, k + 11, Blocks.stonebrick);
        world.setBlock(i + 7, j + 20, k + 12, Blocks.stonebrick);
        world.setBlock(i + 7, j + 20, k + 13, Blocks.stonebrick);
        world.setBlock(i + 7, j + 20, k + 14, Blocks.stonebrick);
        world.setBlock(i + 7, j + 20, k + 15, Blocks.glass);
        world.setBlock(i + 7, j + 20, k + 16, Blocks.glass);
        world.setBlock(i + 7, j + 20, k + 17, Blocks.glass);
        world.setBlock(i + 7, j + 20, k + 18, Blocks.glass);
        world.setBlock(i + 7, j + 20, k + 19, Blocks.stonebrick);
        world.setBlock(i + 7, j + 20, k + 20, Blocks.stonebrick);
        world.setBlock(i + 7, j + 20, k + 21, Blocks.stonebrick);
        world.setBlock(i + 7, j + 20, k + 22, Blocks.stonebrick);
        world.setBlock(i + 7, j + 21, k + 11, Blocks.stonebrick);
        world.setBlock(i + 7, j + 21, k + 12, Blocks.netherrack, 1, 0);
        world.setBlock(i + 7, j + 21, k + 21, Blocks.netherrack, 3, 0);
        world.setBlock(i + 7, j + 21, k + 22, Blocks.stonebrick);
        world.setBlock(i + 7, j + 22, k + 11, Blocks.stonebrick);
        world.setBlock(i + 7, j + 22, k + 22, Blocks.stonebrick);
        world.setBlock(i + 7, j + 23, k + 11, Blocks.stonebrick);
        world.setBlock(i + 7, j + 23, k + 22, Blocks.stonebrick);
        world.setBlock(i + 7, j + 24, k + 11, Blocks.stonebrick);
        world.setBlock(i + 7, j + 24, k + 12, Blocks.stonebrick);
        world.setBlock(i + 7, j + 24, k + 13, Blocks.stonebrick);
        world.setBlock(i + 7, j + 24, k + 14, Blocks.stonebrick);
        world.setBlock(i + 7, j + 24, k + 15, Blocks.glass);
        world.setBlock(i + 7, j + 24, k + 16, Blocks.glass);
        world.setBlock(i + 7, j + 24, k + 17, Blocks.glass);
        world.setBlock(i + 7, j + 24, k + 18, Blocks.glass);
        world.setBlock(i + 7, j + 24, k + 19, Blocks.stonebrick);
        world.setBlock(i + 7, j + 24, k + 20, Blocks.stonebrick);
        world.setBlock(i + 7, j + 24, k + 21, Blocks.stonebrick);
        world.setBlock(i + 7, j + 24, k + 22, Blocks.stonebrick);
        world.setBlock(i + 7, j + 25, k + 11, Blocks.stonebrick);
        world.setBlock(i + 7, j + 25, k + 12, Blocks.obsidian, 3, 0);
        world.setBlock(i + 7, j + 25, k + 21, Blocks.obsidian, 2, 0);
        world.setBlock(i + 7, j + 25, k + 22, Blocks.stonebrick);
        world.setBlock(i + 7, j + 26, k + 11, Blocks.stonebrick);
        world.setBlock(i + 7, j + 26, k + 22, Blocks.stonebrick);
        world.setBlock(i + 7, j + 27, k + 11, Blocks.stonebrick);
        world.setBlock(i + 7, j + 27, k + 22, Blocks.stonebrick);
        world.setBlock(i + 7, j + 28, k + 11, Blocks.stonebrick);
        world.setBlock(i + 7, j + 28, k + 12, Blocks.stonebrick);
        world.setBlock(i + 7, j + 28, k + 13, Blocks.stonebrick);
        world.setBlock(i + 7, j + 28, k + 14, Blocks.stonebrick);
        world.setBlock(i + 7, j + 28, k + 15, Blocks.glass);
        world.setBlock(i + 7, j + 28, k + 16, Blocks.glass);
        world.setBlock(i + 7, j + 28, k + 17, Blocks.glass);
        world.setBlock(i + 7, j + 28, k + 18, Blocks.glass);
        world.setBlock(i + 7, j + 28, k + 19, Blocks.stonebrick);
        world.setBlock(i + 7, j + 28, k + 20, Blocks.stonebrick);
        world.setBlock(i + 7, j + 28, k + 21, Blocks.stonebrick);
        world.setBlock(i + 7, j + 28, k + 22, Blocks.stonebrick);
        world.setBlock(i + 7, j + 29, k + 11, Blocks.stonebrick);
        world.setBlock(i + 7, j + 29, k + 22, Blocks.stonebrick);
        world.setBlock(i + 7, j + 30, k + 10, Blocks.stonebrick);
        world.setBlock(i + 7, j + 30, k + 11, Blocks.stonebrick);
        world.setBlock(i + 7, j + 30, k + 22, Blocks.stonebrick);
        world.setBlock(i + 7, j + 30, k + 23, Blocks.stonebrick);
        world.setBlock(i + 7, j + 31, k + 10, Blocks.stonebrick);
        world.setBlock(i + 7, j + 31, k + 11, Blocks.stonebrick);
        world.setBlock(i + 7, j + 31, k + 22, Blocks.stonebrick);
        world.setBlock(i + 7, j + 31, k + 23, Blocks.stonebrick);
        world.setBlock(i + 7, j + 32, k + 10, Blocks.stonebrick);
        world.setBlock(i + 7, j + 32, k + 11, Blocks.stonebrick);
        world.setBlock(i + 7, j + 32, k + 12, Blocks.stonebrick);
        world.setBlock(i + 7, j + 32, k + 13, Blocks.stonebrick);
        world.setBlock(i + 7, j + 32, k + 14, Blocks.stonebrick);
        world.setBlock(i + 7, j + 32, k + 15, Blocks.glass);
        world.setBlock(i + 7, j + 32, k + 16, Blocks.glass);
        world.setBlock(i + 7, j + 32, k + 17, Blocks.glass);
        world.setBlock(i + 7, j + 32, k + 18, Blocks.glass);
        world.setBlock(i + 7, j + 32, k + 19, Blocks.stonebrick);
        world.setBlock(i + 7, j + 32, k + 20, Blocks.stonebrick);
        world.setBlock(i + 7, j + 32, k + 21, Blocks.stonebrick);
        world.setBlock(i + 7, j + 32, k + 22, Blocks.stonebrick);
        world.setBlock(i + 7, j + 32, k + 23, Blocks.stonebrick);
        world.setBlock(i + 7, j + 33, k + 10, Blocks.stonebrick);
        world.setBlock(i + 7, j + 33, k + 23, Blocks.stonebrick);
        world.setBlock(i + 7, j + 34, k + 10, Blocks.stonebrick);
        world.setBlock(i + 7, j + 34, k + 23, Blocks.stonebrick);
        world.setBlock(i + 7, j + 35, k + 10, Blocks.stonebrick);
        world.setBlock(i + 7, j + 35, k + 23, Blocks.stonebrick);
        world.setBlock(i + 7, j + 36, k + 10, Blocks.stonebrick);
        world.setBlock(i + 7, j + 36, k + 11, Blocks.stonebrick);
        world.setBlock(i + 7, j + 36, k + 12, Blocks.stonebrick);
        world.setBlock(i + 7, j + 36, k + 13, Blocks.stonebrick);
        world.setBlock(i + 7, j + 36, k + 14, Blocks.stonebrick);
        world.setBlock(i + 7, j + 36, k + 15, Blocks.stonebrick);
        world.setBlock(i + 7, j + 36, k + 16, Blocks.glass);
        world.setBlock(i + 7, j + 36, k + 17, Blocks.glass);
        world.setBlock(i + 7, j + 36, k + 18, Blocks.stonebrick);
        world.setBlock(i + 7, j + 36, k + 19, Blocks.stonebrick);
        world.setBlock(i + 7, j + 36, k + 20, Blocks.stonebrick);
        world.setBlock(i + 7, j + 36, k + 21, Blocks.stonebrick);
        world.setBlock(i + 7, j + 36, k + 22, Blocks.stonebrick);
        world.setBlock(i + 7, j + 36, k + 23, Blocks.stonebrick);
        world.setBlock(i + 7, j + 37, k + 10, Blocks.stonebrick);
        world.setBlock(i + 7, j + 37, k + 23, Blocks.stonebrick);
        world.setBlock(i + 7, j + 38, k + 10, Blocks.stonebrick);
        world.setBlock(i + 7, j + 38, k + 23, Blocks.stonebrick);
        world.setBlock(i + 8, j, k, Blocks.grass);
        world.setBlock(i + 8, j, k + 1, Blocks.grass);
        world.setBlock(i + 8, j, k + 2, Blocks.grass);
        world.setBlock(i + 8, j, k + 3, Blocks.grass);
        world.setBlock(i + 8, j, k + 4, Blocks.grass);
        world.setBlock(i + 8, j, k + 5, Blocks.grass);
        world.setBlock(i + 8, j, k + 6, Blocks.grass);
        world.setBlock(i + 8, j, k + 7, Blocks.grass);
        world.setBlock(i + 8, j, k + 8, Blocks.grass);
        world.setBlock(i + 8, j, k + 9, Blocks.grass);
        world.setBlock(i + 8, j, k + 10, Blocks.grass);
        world.setBlock(i + 8, j, k + 11, Blocks.dirt);
        world.setBlock(i + 8, j, k + 12, Blocks.cobblestone);
        world.setBlock(i + 8, j, k + 13, Blocks.cobblestone);
        world.setBlock(i + 8, j, k + 14, Blocks.cobblestone);
        world.setBlock(i + 8, j, k + 15, Blocks.cobblestone);
        world.setBlock(i + 8, j, k + 16, Blocks.cobblestone);
        world.setBlock(i + 8, j, k + 17, Blocks.cobblestone);
        world.setBlock(i + 8, j, k + 18, Blocks.cobblestone);
        world.setBlock(i + 8, j, k + 19, Blocks.cobblestone);
        world.setBlock(i + 8, j, k + 20, Blocks.cobblestone);
        world.setBlock(i + 8, j, k + 21, Blocks.cobblestone);
        world.setBlock(i + 8, j, k + 22, Blocks.dirt);
        world.setBlock(i + 8, j, k + 23, Blocks.grass);
        world.setBlock(i + 8, j, k + 24, Blocks.grass);
        world.setBlock(i + 8, j, k + 25, Blocks.grass);
        world.setBlock(i + 8, j, k + 26, Blocks.grass);
        world.setBlock(i + 8, j, k + 27, Blocks.grass);
        world.setBlock(i + 8, j, k + 28, Blocks.grass);
        world.setBlock(i + 8, j, k + 29, Blocks.grass);
        world.setBlock(i + 8, j, k + 30, Blocks.grass);
        world.setBlock(i + 8, j + 1, k + 11, Blocks.cobblestone);
        world.setBlock(i + 8, j + 1, k + 22, Blocks.cobblestone);
        world.setBlock(i + 8, j + 2, k + 11, Blocks.cobblestone);
        world.setBlock(i + 8, j + 2, k + 22, Blocks.cobblestone);
        world.setBlock(i + 8, j + 3, k + 11, Blocks.cobblestone);
        world.setBlock(i + 8, j + 3, k + 22, Blocks.cobblestone);
        world.setBlock(i + 8, j + 4, k + 11, Blocks.cobblestone);
        world.setBlock(i + 8, j + 4, k + 12, Blocks.wool, 14, 0);
        world.setBlock(i + 8, j + 4, k + 13, Blocks.wool, 14, 0);
        world.setBlock(i + 8, j + 4, k + 14, Blocks.wool);
        world.setBlock(i + 8, j + 4, k + 15, Blocks.wool);
        world.setBlock(i + 8, j + 4, k + 16, Blocks.wool, 4, 0);
        world.setBlock(i + 8, j + 4, k + 17, Blocks.wool, 4, 0);
        world.setBlock(i + 8, j + 4, k + 18, Blocks.wool, 4, 0);
        world.setBlock(i + 8, j + 4, k + 19, Blocks.wool);
        world.setBlock(i + 8, j + 4, k + 20, Blocks.wool, 9, 0);
        world.setBlock(i + 8, j + 4, k + 21, Blocks.wool, 9, 0);
        world.setBlock(i + 8, j + 4, k + 22, Blocks.cobblestone);
        world.setBlock(i + 8, j + 5, k + 11, Blocks.stonebrick);
        world.setBlock(i + 8, j + 5, k + 22, Blocks.stonebrick);
        world.setBlock(i + 8, j + 6, k + 11, Blocks.stonebrick);
        world.setBlock(i + 8, j + 6, k + 22, Blocks.stonebrick);
        world.setBlock(i + 8, j + 7, k + 11, Blocks.stonebrick);
        world.setBlock(i + 8, j + 7, k + 22, Blocks.stonebrick);
        world.setBlock(i + 8, j + 8, k + 11, Blocks.stonebrick);
        world.setBlock(i + 8, j + 8, k + 12, Blocks.stonebrick);
        world.setBlock(i + 8, j + 8, k + 13, Blocks.stonebrick);
        world.setBlock(i + 8, j + 8, k + 14, Blocks.stonebrick);
        world.setBlock(i + 8, j + 8, k + 15, Blocks.glass);
        world.setBlock(i + 8, j + 8, k + 16, Blocks.glass);
        world.setBlock(i + 8, j + 8, k + 17, Blocks.glass);
        world.setBlock(i + 8, j + 8, k + 18, Blocks.glass);
        world.setBlock(i + 8, j + 8, k + 19, Blocks.stonebrick);
        world.setBlock(i + 8, j + 8, k + 20, Blocks.stonebrick);
        world.setBlock(i + 8, j + 8, k + 21, Blocks.stonebrick);
        world.setBlock(i + 8, j + 8, k + 22, Blocks.stonebrick);
        world.setBlock(i + 8, j + 9, k + 11, Blocks.stonebrick);
        world.setBlock(i + 8, j + 9, k + 12, Blocks.obsidian, 3, 0);
        WorldGenWarlordDungeon.chest(world, rand, i + 8, j + 9, k + 21, "dungeonChest", rand.nextInt(5) + 1);
        world.setBlock(i + 8, j + 9, k + 22, Blocks.stonebrick);
        world.setBlock(i + 8, j + 10, k + 11, Blocks.stonebrick);
        world.setBlock(i + 8, j + 10, k + 22, Blocks.stonebrick);
        world.setBlock(i + 8, j + 11, k + 11, Blocks.stonebrick);
        world.setBlock(i + 8, j + 11, k + 22, Blocks.stonebrick);
        world.setBlock(i + 8, j + 12, k + 11, Blocks.stonebrick);
        world.setBlock(i + 8, j + 12, k + 12, Blocks.stonebrick);
        this.generate2(world, rand, i, j, k);
        return true;
    }

    public boolean generate2(final World world, final Random rand, final int i, final int j, final int k) {
        world.setBlock(i + 8, j + 12, k + 13, Blocks.stonebrick);
        world.setBlock(i + 8, j + 12, k + 14, Blocks.stonebrick);
        world.setBlock(i + 8, j + 12, k + 15, Blocks.glass);
        world.setBlock(i + 8, j + 12, k + 16, Blocks.glass);
        world.setBlock(i + 8, j + 12, k + 17, Blocks.glass);
        world.setBlock(i + 8, j + 12, k + 18, Blocks.glass);
        world.setBlock(i + 8, j + 12, k + 19, Blocks.stonebrick);
        world.setBlock(i + 8, j + 12, k + 20, Blocks.stonebrick);
        world.setBlock(i + 8, j + 12, k + 21, Blocks.stonebrick);
        world.setBlock(i + 8, j + 12, k + 22, Blocks.stonebrick);
        world.setBlock(i + 8, j + 13, k + 11, Blocks.stonebrick);
        world.setBlock(i + 8, j + 13, k + 22, Blocks.stonebrick);
        world.setBlock(i + 8, j + 14, k + 11, Blocks.stonebrick);
        world.setBlock(i + 8, j + 14, k + 22, Blocks.stonebrick);
        world.setBlock(i + 8, j + 15, k + 11, Blocks.stonebrick);
        world.setBlock(i + 8, j + 15, k + 22, Blocks.stonebrick);
        world.setBlock(i + 8, j + 16, k + 11, Blocks.stonebrick);
        world.setBlock(i + 8, j + 16, k + 12, Blocks.stonebrick);
        world.setBlock(i + 8, j + 16, k + 13, Blocks.stonebrick);
        world.setBlock(i + 8, j + 16, k + 14, Blocks.stonebrick);
        world.setBlock(i + 8, j + 16, k + 15, Blocks.glass);
        world.setBlock(i + 8, j + 16, k + 16, Blocks.glass);
        world.setBlock(i + 8, j + 16, k + 17, Blocks.glass);
        world.setBlock(i + 8, j + 16, k + 18, Blocks.glass);
        world.setBlock(i + 8, j + 16, k + 19, Blocks.stonebrick);
        world.setBlock(i + 8, j + 16, k + 20, Blocks.stonebrick);
        world.setBlock(i + 8, j + 16, k + 21, Blocks.stonebrick);
        world.setBlock(i + 8, j + 16, k + 22, Blocks.stonebrick);
        world.setBlock(i + 8, j + 17, k + 11, Blocks.stonebrick);
        world.setBlock(i + 8, j + 17, k + 22, Blocks.stonebrick);
        world.setBlock(i + 8, j + 18, k + 11, Blocks.stonebrick);
        world.setBlock(i + 8, j + 18, k + 22, Blocks.stonebrick);
        world.setBlock(i + 8, j + 19, k + 11, Blocks.stonebrick);
        world.setBlock(i + 8, j + 19, k + 22, Blocks.stonebrick);
        world.setBlock(i + 8, j + 20, k + 11, Blocks.stonebrick);
        world.setBlock(i + 8, j + 20, k + 12, Blocks.stonebrick);
        world.setBlock(i + 8, j + 20, k + 13, Blocks.stonebrick);
        world.setBlock(i + 8, j + 20, k + 14, Blocks.stonebrick);
        world.setBlock(i + 8, j + 20, k + 15, Blocks.glass);
        world.setBlock(i + 8, j + 20, k + 16, Blocks.glass);
        world.setBlock(i + 8, j + 20, k + 17, Blocks.glass);
        world.setBlock(i + 8, j + 20, k + 18, Blocks.glass);
        world.setBlock(i + 8, j + 20, k + 19, Blocks.stonebrick);
        world.setBlock(i + 8, j + 20, k + 20, Blocks.stonebrick);
        world.setBlock(i + 8, j + 20, k + 21, Blocks.stonebrick);
