package com.gibby.dungeon.gen;

import com.gibby.dungeon.Dungeons;
import cpw.mods.fml.common.IWorldGenerator;
import net.minecraft.block.Block;
import net.minecraft.world.IBlockAccess;
import net.minecraft.world.World;
import net.minecraft.world.chunk.IChunkProvider;
import net.minecraft.world.gen.feature.WorldGenerator;

import java.util.Random;

public class MidnightWillowSmall extends WorldGenerator implements IWorldGenerator
{
    public void generate(final Random random, final int chunkX, final int chunkZ, final World world, final IChunkProvider chunkGenerator, final IChunkProvider chunkProvider) {
    }

    public void setBlock(final World world, final int x, final int y, final int z, final Block block, final int metadata) {
        final Block b1 = world.getBlock(x, y, z);
        if (b1.isAir(world, x, y, z) || b1.isLeaves(world, x, y, z)) {
            world.setBlock(x, y, z, block, metadata, 2);
        }
    }

    public boolean generate(final World world, final Random rand, final int i, final int j, final int k) {
        if (world.getBlock(i + 8, j, k + 8) != Dungeons.midnightGrass) {
            return false;
        }
        for (int c = 4; c < 12; ++c) {
            if (!world.isAirBlock(i + 0, j + c, k + 14)) {
                return false;
            }
            if (!world.isAirBlock(i + 14, j + c, k + 0)) {
                return false;
            }
            if (!world.isAirBlock(i + 0, j + c, k + 0)) {
                return false;
            }
            if (!world.isAirBlock(i + 14, j + c, k + 14)) {
                return false;
            }
            if (!world.isAirBlock(i + 5, j + c, k + 5)) {
                return false;
            }
            if (!world.isAirBlock(i + 9, j + c, k + 9)) {
                return false;
            }
        }
        this.setBlock(world, i + 0, j + 7, k + 6, Dungeons.midnightLeaves, 0);
        this.setBlock(world, i + 1, j + 3, k + 6, Dungeons.midnightLeaves, 0);
        this.setBlock(world, i + 1, j + 4, k + 6, Dungeons.midnightLeaves, 0);
        this.setBlock(world, i + 1, j + 4, k + 8, Dungeons.midnightLeaves, 0);
        this.setBlock(world, i + 1, j + 5, k + 6, Dungeons.midnightLeaves, 0);
        this.setBlock(world, i + 1, j + 5, k + 7, Dungeons.midnightLeaves, 0);
        this.setBlock(world, i + 1, j + 5, k + 8, Dungeons.midnightLeaves, 0);
        this.setBlock(world, i + 1, j + 6, k + 6, Dungeons.midnightLeaves, 0);
        this.setBlock(world, i + 1, j + 6, k + 7, Dungeons.midnightLeaves, 0);
        this.setBlock(world, i + 1, j + 6, k + 8, Dungeons.midnightLeaves, 0);
        this.setBlock(world, i + 1, j + 6, k + 10, Dungeons.midnightLeaves, 0);
        this.setBlock(world, i + 1, j + 6, k + 12, Dungeons.midnightLeaves, 0);
        this.setBlock(world, i + 1, j + 7, k + 6, Dungeons.midnightLeaves, 0);
        this.setBlock(world, i + 1, j + 7, k + 8, Dungeons.midnightLeaves, 0);
        this.setBlock(world, i + 1, j + 7, k + 9, Dungeons.midnightLeaves, 0);
        this.setBlock(world, i + 1, j + 7, k + 10, Dungeons.midnightLeaves, 0);
        this.setBlock(world, i + 1, j + 8, k + 6, Dungeons.midnightLeaves, 0);
        this.setBlock(world, i + 1, j + 8, k + 7, Dungeons.midnightLeaves, 0);
        this.setBlock(world, i + 1, j + 8, k + 8, Dungeons.midnightLeaves, 0);
        this.setBlock(world, i + 1, j + 8, k + 9, Dungeons.midnightLeaves, 0);
        this.setBlock(world, i + 1, j + 9, k + 6, Dungeons.midnightLeaves, 0);
        this.setBlock(world, i + 1, j + 9, k + 7, Dungeons.midnightLeaves, 0);
        this.setBlock(world, i + 1, j + 9, k + 8, Dungeons.midnightLeaves, 0);
        this.setBlock(world, i + 2, j + 2, k + 4, Dungeons.midnightLeaves, 0);
        this.setBlock(world, i + 2, j + 3, k + 4, Dungeons.midnightLeaves, 0);
        this.setBlock(world, i + 2, j + 3, k + 12, Dungeons.midnightLeaves, 0);
        this.setBlock(world, i + 2, j + 4, k + 4, Dungeons.midnightLeaves, 0);
        this.setBlock(world, i + 2, j + 4, k + 12, Dungeons.midnightLeaves, 0);
        this.setBlock(world, i + 2, j + 5, k + 4, Dungeons.midnightLeaves, 0);
        this.setBlock(world, i + 2, j + 5, k + 5, Dungeons.midnightLeaves, 0);
        this.setBlock(world, i + 2, j + 5, k + 12, Dungeons.midnightLeaves, 0);
        this.setBlock(world, i + 2, j + 6, k + 4, Dungeons.midnightLeaves, 0);
        this.setBlock(world, i + 2, j + 6, k + 5, Dungeons.midnightLeaves, 0);
        this.setBlock(world, i + 2, j + 6, k + 12, Dungeons.midnightLeaves, 0);
        this.setBlock(world, i + 2, j + 7, k + 4, Dungeons.midnightLeaves, 0);
        this.setBlock(world, i + 2, j + 7, k + 5, Dungeons.midnightLeaves, 0);
        this.setBlock(world, i + 2, j + 7, k + 11, Dungeons.midnightLeaves, 0);
        this.setBlock(world, i + 2, j + 7, k + 12, Dungeons.midnightLeaves, 0);
        this.setBlock(world, i + 2, j + 8, k + 5, Dungeons.midnightLeaves, 0);
        this.setBlock(world, i + 2, j + 8, k + 8, Dungeons.midnightLeaves, 0);
        this.setBlock(world, i + 2, j + 8, k + 9, Dungeons.midnightLeaves, 0);
        this.setBlock(world, i + 2, j + 8, k + 10, Dungeons.midnightLeaves, 0);
        this.setBlock(world, i + 2, j + 8, k + 11, Dungeons.midnightLeaves, 0);
        this.setBlock(world, i + 2, j + 8, k + 12, Dungeons.midnightLeaves, 0);
        this.setBlock(world, i + 2, j + 9, k + 5, Dungeons.midnightLeaves, 0);
        this.setBlock(world, i + 2, j + 9, k + 6, Dungeons.midnightLeaves, 0);
        this.setBlock(world, i + 2, j + 9, k + 7, Dungeons.midnightLeaves, 0);
        this.setBlock(world, i + 2, j + 9, k + 8, Dungeons.midnightLeaves, 0);
        this.setBlock(world, i + 2, j + 9, k + 9, Dungeons.midnightLeaves, 0);
        this.setBlock(world, i + 2, j + 10, k + 6, Dungeons.midnightLeaves, 0);
        this.setBlock(world, i + 2, j + 10, k + 8, Dungeons.midnightLeaves, 0);
        this.setBlock(world, i + 3, j + 4, k + 3, Dungeons.midnightLeaves, 0);
        this.setBlock(world, i + 3, j + 4, k + 4, Dungeons.midnightLeaves, 0);
        this.setBlock(world, i + 3, j + 4, k + 14, Dungeons.midnightLeaves, 0);
        this.setBlock(world, i + 3, j + 5, k + 2, Dungeons.midnightLeaves, 0);
        this.setBlock(world, i + 3, j + 5, k + 3, Dungeons.midnightLeaves, 0);
        this.setBlock(world, i + 3, j + 5, k + 4, Dungeons.midnightLeaves, 0);
        this.setBlock(world, i + 3, j + 5, k + 14, Dungeons.midnightLeaves, 0);
        this.setBlock(world, i + 3, j + 6, k + 3, Dungeons.midnightLeaves, 0);
        this.setBlock(world, i + 3, j + 6, k + 4, Dungeons.midnightLeaves, 0);
        this.setBlock(world, i + 3, j + 6, k + 14, Dungeons.midnightLeaves, 0);
        this.setBlock(world, i + 3, j + 7, k + 4, Dungeons.midnightLeaves, 0);
        this.setBlock(world, i + 3, j + 7, k + 13, Dungeons.midnightLeaves, 0);
        this.setBlock(world, i + 3, j + 7, k + 14, Dungeons.midnightLeaves, 0);
        this.setBlock(world, i + 3, j + 8, k + 4, Dungeons.midnightLeaves, 0);
        this.setBlock(world, i + 3, j + 8, k + 5, Dungeons.midnightLeaves, 0);
        this.setBlock(world, i + 3, j + 8, k + 9, Dungeons.midnightLeaves, 0);
        this.setBlock(world, i + 3, j + 8, k + 13, Dungeons.midnightLeaves, 0);
        this.setBlock(world, i + 3, j + 8, k + 14, Dungeons.midnightLeaves, 0);
        this.setBlock(world, i + 3, j + 9, k + 5, Dungeons.midnightLeaves, 0);
        this.setBlock(world, i + 3, j + 9, k + 6, Dungeons.midnightLeaves, 0);
        this.setBlock(world, i + 3, j + 9, k + 7, Dungeons.midnightLeaves, 0);
        this.setBlock(world, i + 3, j + 9, k + 8, Dungeons.midnightLeaves, 0);
        this.setBlock(world, i + 3, j + 9, k + 9, Dungeons.midnightLeaves, 0);
        this.setBlock(world, i + 3, j + 9, k + 10, Dungeons.midnightLeaves, 0);
        this.setBlock(world, i + 3, j + 9, k + 11, Dungeons.midnightLeaves, 0);
        this.setBlock(world, i + 3, j + 9, k + 12, Dungeons.midnightLeaves, 0);
        this.setBlock(world, i + 3, j + 9, k + 13, Dungeons.midnightLeaves, 0);
        this.setBlock(world, i + 3, j + 10, k + 6, Dungeons.midnightLeaves, 0);
        this.setBlock(world, i + 3, j + 10, k + 7, Dungeons.midnightLeaves, 0);
        this.setBlock(world, i + 3, j + 10, k + 8, Dungeons.midnightLeaves, 0);
        this.setBlock(world, i + 3, j + 10, k + 9, Dungeons.midnightLeaves, 0);
        this.setBlock(world, i + 3, j + 10, k + 10, Dungeons.midnightLeaves, 0);
        this.setBlock(world, i + 3, j + 10, k + 11, Dungeons.midnightLeaves, 0);
        this.setBlock(world, i + 3, j + 10, k + 12, Dungeons.midnightLeaves, 0);
        this.setBlock(world, i + 3, j + 11, k + 8, Dungeons.midnightLeaves, 0);
        this.setBlock(world, i + 4, j + 4, k + 2, Dungeons.midnightLeaves, 0);
        this.setBlock(world, i + 4, j + 5, k + 2, Dungeons.midnightLeaves, 0);
        this.setBlock(world, i + 4, j + 5, k + 5, Dungeons.midnightLeaves, 0);
        this.setBlock(world, i + 4, j + 5, k + 15, Dungeons.midnightLeaves, 0);
        this.setBlock(world, i + 4, j + 6, k + 2, Dungeons.midnightLeaves, 0);
        this.setBlock(world, i + 4, j + 6, k + 3, Dungeons.midnightLeaves, 0);
        this.setBlock(world, i + 4, j + 6, k + 5, Dungeons.midnightLeaves, 0);
        this.setBlock(world, i + 4, j + 6, k + 15, Dungeons.midnightLeaves, 0);
        this.setBlock(world, i + 4, j + 7, k + 3, Dungeons.midnightLeaves, 0);
        this.setBlock(world, i + 4, j + 7, k + 5, Dungeons.midnightLeaves, 0);
        this.setBlock(world, i + 4, j + 7, k + 11, Dungeons.midnightLeaves, 0);
        this.setBlock(world, i + 4, j + 7, k + 14, Dungeons.midnightLeaves, 0);
        this.setBlock(world, i + 4, j + 8, k + 3, Dungeons.midnightLeaves, 0);
        this.setBlock(world, i + 4, j + 8, k + 5, Dungeons.midnightLeaves, 0);
        this.setBlock(world, i + 4, j + 8, k + 6, Dungeons.midnightLeaves, 0);
        this.setBlock(world, i + 4, j + 8, k + 10, Dungeons.midnightLeaves, 0);
        this.setBlock(world, i + 4, j + 8, k + 11, Dungeons.midnightLeaves, 0);
        this.setBlock(world, i + 4, j + 8, k + 14, Dungeons.midnightLeaves, 0);
        this.setBlock(world, i + 4, j + 8, k + 15, Dungeons.midnightLeaves, 0);
        this.setBlock(world, i + 4, j + 9, k + 3, Dungeons.midnightLeaves, 0);
        this.setBlock(world, i + 4, j + 9, k + 4, Dungeons.midnightLeaves, 0);
        this.setBlock(world, i + 4, j + 9, k + 5, Dungeons.midnightLeaves, 0);
        this.setBlock(world, i + 4, j + 9, k + 6, Dungeons.midnightLeaves, 0);
        this.setBlock(world, i + 4, j + 9, k + 9, Dungeons.midnightLeaves, 0);
        this.setBlock(world, i + 4, j + 9, k + 10, Dungeons.midnightLeaves, 0);
        this.setBlock(world, i + 4, j + 9, k + 11, Dungeons.midnightLeaves, 0);
        this.setBlock(world, i + 4, j + 9, k + 12, Dungeons.midnightLeaves, 0);
        this.setBlock(world, i + 4, j + 9, k + 13, Dungeons.midnightLeaves, 0);
        this.setBlock(world, i + 4, j + 9, k + 15, Dungeons.midnightLeaves, 0);
        this.setBlock(world, i + 4, j + 10, k + 6, Dungeons.midnightLeaves, 0);
        this.setBlock(world, i + 4, j + 10, k + 9, Dungeons.midnightLeaves, 0);
        this.setBlock(world, i + 4, j + 10, k + 10, Dungeons.midnightLeaves, 0);
        this.setBlock(world, i + 4, j + 10, k + 11, Dungeons.midnightLeaves, 0);
        this.setBlock(world, i + 4, j + 10, k + 12, Dungeons.midnightLeaves, 0);
        this.setBlock(world, i + 4, j + 11, k + 7, Dungeons.midnightLeaves, 0);
        this.setBlock(world, i + 4, j + 11, k + 8, Dungeons.midnightLeaves, 0);
        this.setBlock(world, i + 4, j + 11, k + 9, Dungeons.midnightLeaves, 0);
        this.setBlock(world, i + 5, j + 2, k + 11, Dungeons.midnightLeaves, 0);
        this.setBlock(world, i + 5, j + 3, k + 2, Dungeons.midnightLeaves, 0);
        this.setBlock(world, i + 5, j + 3, k + 11, Dungeons.midnightLeaves, 0);
        this.setBlock(world, i + 5, j + 4, k + 1, Dungeons.midnightLeaves, 0);
        this.setBlock(world, i + 5, j + 4, k + 2, Dungeons.midnightLeaves, 0);
        this.setBlock(world, i + 5, j + 4, k + 11, Dungeons.midnightLeaves, 0);
        this.setBlock(world, i + 5, j + 5, k + 1, Dungeons.midnightLeaves, 0);
        this.setBlock(world, i + 5, j + 5, k + 2, Dungeons.midnightLeaves, 0);
        this.setBlock(world, i + 5, j + 5, k + 8, Dungeons.midnightLeaves, 0);
        this.setBlock(world, i + 5, j + 5, k + 11, Dungeons.midnightLeaves, 0);
        this.setBlock(world, i + 5, j + 5, k + 15, Dungeons.midnightLeaves, 0);
        this.setBlock(world, i + 5, j + 6, k + 2, Dungeons.midnightLeaves, 0);
        this.setBlock(world, i + 5, j + 6, k + 3, Dungeons.midnightLeaves, 0);
        this.setBlock(world, i + 5, j + 6, k + 8, Dungeons.midnightLeaves, 0);
        this.setBlock(world, i + 5, j + 6, k + 11, Dungeons.midnightLeaves, 0);
        this.setBlock(world, i + 5, j + 6, k + 15, Dungeons.midnightLeaves, 0);
        this.setBlock(world, i + 5, j + 7, k + 2, Dungeons.midnightLeaves, 0);
        this.setBlock(world, i + 5, j + 7, k + 3, Dungeons.midnightLeaves, 0);
        this.setBlock(world, i + 5, j + 7, k + 8, Dungeons.midnightLeaves, 0);
        this.setBlock(world, i + 5, j + 7, k + 11, Dungeons.midnightLeaves, 0);
        this.setBlock(world, i + 5, j + 7, k + 15, Dungeons.midnightLeaves, 0);
        this.setBlock(world, i + 5, j + 8, k + 3, Dungeons.midnightLeaves, 0);
        this.setBlock(world, i + 5, j + 8, k + 4, Dungeons.midnightLeaves, 0);
        this.setBlock(world, i + 5, j + 8, k + 8, Dungeons.midnightLeaves, 0);
        this.setBlock(world, i + 5, j + 8, k + 11, Dungeons.midnightLeaves, 0);
        this.setBlock(world, i + 5, j + 8, k + 13, Dungeons.midnightLeaves, 0);
        this.setBlock(world, i + 5, j + 8, k + 15, Dungeons.midnightLeaves, 0);
        this.setBlock(world, i + 5, j + 9, k + 3, Dungeons.midnightLeaves, 0);
        this.setBlock(world, i + 5, j + 9, k + 4, Dungeons.midnightLeaves, 0);
        this.setBlock(world, i + 5, j + 9, k + 5, Dungeons.midnightLeaves, 0);
        this.setBlock(world, i + 5, j + 9, k + 7, Dungeons.midnightLeaves, 0);
        this.setBlock(world, i + 5, j + 9, k + 8, Dungeons.midnightLeaves, 0);
        this.setBlock(world, i + 5, j + 9, k + 9, Dungeons.midnightLeaves, 0);
        this.setBlock(world, i + 5, j + 9, k + 11, Dungeons.midnightLeaves, 0);
        this.setBlock(world, i + 5, j + 9, k + 13, Dungeons.midnightLeaves, 0);
        this.setBlock(world, i + 5, j + 9, k + 14, Dungeons.midnightLeaves, 0);
        this.setBlock(world, i + 5, j + 9, k + 15, Dungeons.midnightLeaves, 0);
        this.setBlock(world, i + 5, j + 10, k + 4, Dungeons.midnightLeaves, 0);
        this.setBlock(world, i + 5, j + 10, k + 5, Dungeons.midnightLeaves, 0);
        this.setBlock(world, i + 5, j + 10, k + 6, Dungeons.midnightLeaves, 0);
        this.setBlock(world, i + 5, j + 10, k + 7, Dungeons.midnightLeaves, 0);
        this.setBlock(world, i + 5, j + 10, k + 8, Dungeons.midnightLeaves, 0);
        this.setBlock(world, i + 5, j + 10, k + 9, Dungeons.midnightLeaves, 0);
        this.setBlock(world, i + 5, j + 10, k + 10, Dungeons.midnightLeaves, 0);
        this.setBlock(world, i + 5, j + 10, k + 11, Dungeons.midnightLeaves, 0);
        this.setBlock(world, i + 5, j + 10, k + 12, Dungeons.midnightLeaves, 0);
        this.setBlock(world, i + 5, j + 10, k + 13, Dungeons.midnightLeaves, 0);
        this.setBlock(world, i + 5, j + 10, k + 14, Dungeons.midnightLeaves, 0);
        this.setBlock(world, i + 5, j + 10, k + 15, Dungeons.midnightLeaves, 0);
        this.setBlock(world, i + 5, j + 11, k + 7, Dungeons.midnightLeaves, 0);
        this.setBlock(world, i + 5, j + 11, k + 8, Dungeons.midnightLeaves, 0);
        this.setBlock(world, i + 5, j + 11, k + 9, Dungeons.midnightLeaves, 0);
        this.setBlock(world, i + 6, j + 5, k + 1, Dungeons.midnightLeaves, 0);
        this.setBlock(world, i + 6, j + 6, k + 1, Dungeons.midnightLeaves, 0);
        this.setBlock(world, i + 6, j + 6, k + 2, Dungeons.midnightLeaves, 0);
        this.setBlock(world, i + 6, j + 6, k + 10, Dungeons.midnightLeaves, 0);
        this.setBlock(world, i + 6, j + 7, k + 1, Dungeons.midnightLeaves, 0);
        this.setBlock(world, i + 6, j + 7, k + 2, Dungeons.midnightLeaves, 0);
        this.setBlock(world, i + 6, j + 7, k + 10, Dungeons.midnightLeaves, 0);
        this.setBlock(world, i + 6, j + 8, k + 1, Dungeons.midnightLeaves, 0);
        this.setBlock(world, i + 6, j + 8, k + 2, Dungeons.midnightLeaves, 0);
        this.setBlock(world, i + 6, j + 8, k + 3, Dungeons.midnightLeaves, 0);
        this.setBlock(world, i + 6, j + 8, k + 4, Dungeons.midnightLeaves, 0);
        this.setBlock(world, i + 6, j + 8, k + 6, Dungeons.midnightLeaves, 0);
        this.setBlock(world, i + 6, j + 8, k + 10, Dungeons.midnightLeaves, 0);
        this.setBlock(world, i + 6, j + 8, k + 13, Dungeons.midnightLeaves, 0);
        this.setBlock(world, i + 6, j + 9, k + 3, Dungeons.midnightLeaves, 0);
        this.setBlock(world, i + 6, j + 9, k + 4, Dungeons.midnightLeaves, 0);
        this.setBlock(world, i + 6, j + 9, k + 6, Dungeons.midnightLeaves, 0);
        this.setBlock(world, i + 6, j + 9, k + 13, Dungeons.midnightLeaves, 0);
        this.setBlock(world, i + 6, j + 9, k + 15, Dungeons.midnightLeaves, 0);
        this.setBlock(world, i + 6, j + 10, k + 4, Dungeons.midnightLeaves, 0);
        this.setBlock(world, i + 6, j + 10, k + 5, Dungeons.midnightLeaves, 0);
        this.setBlock(world, i + 6, j + 10, k + 6, Dungeons.midnightLeaves, 0);
        this.setBlock(world, i + 6, j + 10, k + 7, Dungeons.midnightLeaves, 0);
        this.setBlock(world, i + 6, j + 10, k + 8, Dungeons.midnightLeaves, 0);
        this.setBlock(world, i + 6, j + 10, k + 9, Dungeons.midnightLeaves, 0);
        this.setBlock(world, i + 6, j + 10, k + 10, Dungeons.midnightLeaves, 0);
        this.setBlock(world, i + 6, j + 10, k + 11, Dungeons.midnightLeaves, 0);
        this.setBlock(world, i + 6, j + 10, k + 13, Dungeons.midnightLeaves, 0);
        this.setBlock(world, i + 6, j + 10, k + 14, Dungeons.midnightLeaves, 0);
        this.setBlock(world, i + 6, j + 10, k + 15, Dungeons.midnightLeaves, 0);
        this.setBlock(world, i + 6, j + 11, k + 7, Dungeons.midnightLeaves, 0);
        this.setBlock(world, i + 6, j + 11, k + 8, Dungeons.midnightLeaves, 0);
        this.setBlock(world, i + 6, j + 11, k + 12, Dungeons.midnightLeaves, 0);
        this.setBlock(world, i + 6, j + 11, k + 13, Dungeons.midnightLeaves, 0);
        this.setBlock(world, i + 6, j + 11, k + 14, Dungeons.midnightLeaves, 0);
        this.setBlock(world, i + 7, j + 5, k + 0, Dungeons.midnightLeaves, 0);
        this.setBlock(world, i + 7, j + 5, k + 1, Dungeons.midnightLeaves, 0);
        this.setBlock(world, i + 7, j + 6, k + 1, Dungeons.midnightLeaves, 0);
        this.setBlock(world, i + 7, j + 6, k + 10, Dungeons.midnightLeaves, 0);
        this.setBlock(world, i + 7, j + 6, k + 16, Dungeons.midnightLeaves, 0);
        this.setBlock(world, i + 7, j + 7, k + 1, Dungeons.midnightLeaves, 0);
        this.setBlock(world, i + 7, j + 7, k + 10, Dungeons.midnightLeaves, 0);
        this.setBlock(world, i + 7, j + 7, k + 16, Dungeons.midnightLeaves, 0);
        this.setBlock(world, i + 7, j + 8, k + 1, Dungeons.midnightLeaves, 0);
        this.setBlock(world, i + 7, j + 8, k + 2, Dungeons.midnightLeaves, 0);
        this.setBlock(world, i + 7, j + 8, k + 3, Dungeons.midnightLeaves, 0);
        this.setBlock(world, i + 7, j + 8, k + 5, Dungeons.midnightLeaves, 0);
        this.setBlock(world, i + 7, j + 8, k + 8, Dungeons.midnightLeaves, 0);
        this.setBlock(world, i + 7, j + 8, k + 10, Dungeons.midnightLeaves, 0);
        this.setBlock(world, i + 7, j + 8, k + 13, Dungeons.midnightLeaves, 0);
        this.setBlock(world, i + 7, j + 8, k + 16, Dungeons.midnightLeaves, 0);
        this.setBlock(world, i + 7, j + 9, k + 3, Dungeons.midnightLeaves, 0);
        this.setBlock(world, i + 7, j + 9, k + 5, Dungeons.midnightLeaves, 0);
        this.setBlock(world, i + 7, j + 9, k + 8, Dungeons.midnightLeaves, 0);
        this.setBlock(world, i + 7, j + 9, k + 10, Dungeons.midnightLeaves, 0);
        this.setBlock(world, i + 7, j + 9, k + 11, Dungeons.midnightLeaves, 0);
        this.setBlock(world, i + 7, j + 9, k + 12, Dungeons.midnightLeaves, 0);
        this.setBlock(world, i + 7, j + 9, k + 15, Dungeons.midnightLeaves, 0);
        this.setBlock(world, i + 7, j + 9, k + 16, Dungeons.midnightLeaves, 0);
        this.setBlock(world, i + 7, j + 10, k + 3, Dungeons.midnightLeaves, 0);
        this.setBlock(world, i + 7, j + 10, k + 4, Dungeons.midnightLeaves, 0);
        this.setBlock(world, i + 7, j + 10, k + 5, Dungeons.midnightLeaves, 0);
        this.setBlock(world, i + 7, j + 10, k + 6, Dungeons.midnightLeaves, 0);
        this.setBlock(world, i + 7, j + 10, k + 7, Dungeons.midnightLeaves, 0);
        this.setBlock(world, i + 7, j + 10, k + 8, Dungeons.midnightLeaves, 0);
        this.setBlock(world, i + 7, j + 10, k + 9, Dungeons.midnightLeaves, 0);
        this.setBlock(world, i + 7, j + 10, k + 10, Dungeons.midnightLeaves, 0);
        this.setBlock(world, i + 7, j + 10, k + 11, Dungeons.midnightLeaves, 0);
        this.setBlock(world, i + 7, j + 10, k + 15, Dungeons.midnightLeaves, 0);
        this.setBlock(world, i + 7, j + 11, k + 8, Dungeons.midnightLeaves, 0);
        this.setBlock(world, i + 7, j + 11, k + 11, Dungeons.midnightLeaves, 0);
        this.setBlock(world, i + 7, j + 11, k + 12, Dungeons.midnightLeaves, 0);
        this.setBlock(world, i + 7, j + 11, k + 13, Dungeons.midnightLeaves, 0);
        this.setBlock(world, i + 7, j + 11, k + 15, Dungeons.midnightLeaves, 0);
        this.setBlock(world, i + 7, j + 12, k + 14, Dungeons.midnightLeaves, 0);
        this.setBlock(world, i + 8, j + 1, k + 8, Dungeons.midnightLog, 0);
        this.setBlock(world, i + 8, j + 2, k + 8, Dungeons.midnightLog, 0);
        this.setBlock(world, i + 8, j + 3, k + 8, Dungeons.midnightLog, 0);
        this.setBlock(world, i + 8, j + 4, k + 1, Dungeons.midnightLeaves, 0);
        this.setBlock(world, i + 8, j + 4, k + 8, Dungeons.midnightLog, 0);
        this.setBlock(world, i + 8, j + 5, k + 1, Dungeons.midnightLeaves, 0);
        this.setBlock(world, i + 8, j + 5, k + 8, Dungeons.midnightLog, 0);
        this.setBlock(world, i + 8, j + 5, k + 16, Dungeons.midnightLeaves, 0);
        this.setBlock(world, i + 8, j + 6, k + 1, Dungeons.midnightLeaves, 0);
        this.setBlock(world, i + 8, j + 6, k + 5, Dungeons.midnightLeaves, 0);
        this.setBlock(world, i + 8, j + 6, k + 8, Dungeons.midnightLog, 0);
        this.setBlock(world, i + 8, j + 6, k + 16, Dungeons.midnightLeaves, 0);
        this.setBlock(world, i + 8, j + 7, k + 1, Dungeons.midnightLeaves, 0);
        this.setBlock(world, i + 8, j + 7, k + 5, Dungeons.midnightLeaves, 0);
        this.setBlock(world, i + 8, j + 7, k + 6, Dungeons.midnightLeaves, 0);
        this.setBlock(world, i + 8, j + 7, k + 7, Dungeons.midnightLeaves, 0);
        this.setBlock(world, i + 8, j + 7, k + 8, Dungeons.midnightLog, 0);
        this.setBlock(world, i + 8, j + 7, k + 11, Dungeons.midnightLeaves, 0);
        this.setBlock(world, i + 8, j + 7, k + 12, Dungeons.midnightLeaves, 0);
        this.setBlock(world, i + 8, j + 7, k + 15, Dungeons.midnightLeaves, 0);
        this.setBlock(world, i + 8, j + 7, k + 16, Dungeons.midnightLeaves, 0);
        this.setBlock(world, i + 8, j + 8, k + 1, Dungeons.midnightLeaves, 0);
        this.setBlock(world, i + 8, j + 8, k + 2, Dungeons.midnightLeaves, 0);
        this.setBlock(world, i + 8, j + 8, k + 3, Dungeons.midnightLeaves, 0);
        this.setBlock(world, i + 8, j + 8, k + 5, Dungeons.midnightLeaves, 0);
        this.setBlock(world, i + 8, j + 8, k + 6, Dungeons.midnightLeaves, 0);
        this.setBlock(world, i + 8, j + 8, k + 7, Dungeons.midnightLeaves, 0);
        this.setBlock(world, i + 8, j + 8, k + 8, Dungeons.midnightLeaves, 0);
        this.setBlock(world, i + 8, j + 8, k + 9, Dungeons.midnightLeaves, 0);
        this.setBlock(world, i + 8, j + 8, k + 12, Dungeons.midnightLeaves, 0);
        this.setBlock(world, i + 8, j + 8, k + 15, Dungeons.midnightLeaves, 0);
        this.setBlock(world, i + 8, j + 8, k + 16, Dungeons.midnightLeaves, 0);
        this.setBlock(world, i + 8, j + 9, k + 2, Dungeons.midnightLeaves, 0);
        this.setBlock(world, i + 8, j + 9, k + 3, Dungeons.midnightLeaves, 0);
        this.setBlock(world, i + 8, j + 9, k + 5, Dungeons.midnightLeaves, 0);
        this.setBlock(world, i + 8, j + 9, k + 6, Dungeons.midnightLeaves, 0);
        this.setBlock(world, i + 8, j + 9, k + 7, Dungeons.midnightLeaves, 0);
        this.setBlock(world, i + 8, j + 9, k + 8, Dungeons.midnightLeaves, 0);
        this.setBlock(world, i + 8, j + 9, k + 9, Dungeons.midnightLeaves, 0);
        this.setBlock(world, i + 8, j + 9, k + 12, Dungeons.midnightLeaves, 0);
        this.setBlock(world, i + 8, j + 9, k + 13, Dungeons.midnightLeaves, 0);
        this.setBlock(world, i + 8, j + 9, k + 15, Dungeons.midnightLeaves, 0);
        this.setBlock(world, i + 8, j + 9, k + 16, Dungeons.midnightLeaves, 0);
        this.setBlock(world, i + 8, j + 10, k + 3, Dungeons.midnightLeaves, 0);
        this.setBlock(world, i + 8, j + 10, k + 4, Dungeons.midnightLeaves, 0);
        this.setBlock(world, i + 8, j + 10, k + 5, Dungeons.midnightLeaves, 0);
        this.setBlock(world, i + 8, j + 10, k + 6, Dungeons.midnightLeaves, 0);
        this.setBlock(world, i + 8, j + 10, k + 7, Dungeons.midnightLeaves, 0);
        this.setBlock(world, i + 8, j + 10, k + 8, Dungeons.midnightLeaves, 0);
        this.setBlock(world, i + 8, j + 10, k + 9, Dungeons.midnightLeaves, 0);
        this.setBlock(world, i + 8, j + 10, k + 10, Dungeons.midnightLeaves, 0);
        this.setBlock(world, i + 8, j + 10, k + 11, Dungeons.midnightLeaves, 0);
        this.setBlock(world, i + 8, j + 10, k + 12, Dungeons.midnightLeaves, 0);
        this.setBlock(world, i + 8, j + 10, k + 13, Dungeons.midnightLeaves, 0);
        this.setBlock(world, i + 8, j + 10, k + 15, Dungeons.midnightLeaves, 0);
        this.setBlock(world, i + 8, j + 10, k + 16, Dungeons.midnightLeaves, 0);
        this.setBlock(world, i + 8, j + 11, k + 4, Dungeons.midnightLeaves, 0);
        this.setBlock(world, i + 8, j + 11, k + 5, Dungeons.midnightLeaves, 0);
        this.setBlock(world, i + 8, j + 11, k + 8, Dungeons.midnightLeaves, 0);
        this.setBlock(world, i + 8, j + 11, k + 10, Dungeons.midnightLeaves, 0);
        this.setBlock(world, i + 8, j + 11, k + 11, Dungeons.midnightLeaves, 0);
        this.setBlock(world, i + 8, j + 11, k + 12, Dungeons.midnightLeaves, 0);
        this.setBlock(world, i + 8, j + 11, k + 13, Dungeons.midnightLeaves, 0);
        this.setBlock(world, i + 8, j + 11, k + 14, Dungeons.midnightLeaves, 0);
        this.setBlock(world, i + 8, j + 11, k + 15, Dungeons.midnightLeaves, 0);
        this.setBlock(world, i + 8, j + 12, k + 11, Dungeons.midnightLeaves, 0);
        this.setBlock(world, i + 8, j + 12, k + 12, Dungeons.midnightLeaves, 0);
        this.setBlock(world, i + 8, j + 12, k + 13, Dungeons.midnightLeaves, 0);
        this.setBlock(world, i + 8, j + 12, k + 14, Dungeons.midnightLeaves, 0);
        this.setBlock(world, i + 8, j + 12, k + 15, Dungeons.midnightLeaves, 0);
        this.setBlock(world, i + 9, j + 6, k + 7, Dungeons.midnightLeaves, 0);
        this.setBlock(world, i + 9, j + 6, k + 8, Dungeons.midnightLeaves, 0);
        this.setBlock(world, i + 9, j + 7, k + 1, Dungeons.midnightLeaves, 0);
        this.setBlock(world, i + 9, j + 7, k + 6, Dungeons.midnightLeaves, 0);
        this.setBlock(world, i + 9, j + 7, k + 7, Dungeons.midnightLeaves, 0);
        this.setBlock(world, i + 9, j + 7, k + 8, Dungeons.midnightLeaves, 0);
        this.setBlock(world, i + 9, j + 8, k + 1, Dungeons.midnightLeaves, 0);
        this.setBlock(world, i + 9, j + 8, k + 2, Dungeons.midnightLeaves, 0);
        this.setBlock(world, i + 9, j + 8, k + 3, Dungeons.midnightLeaves, 0);
        this.setBlock(world, i + 9, j + 8, k + 5, Dungeons.midnightLeaves, 0);
        this.setBlock(world, i + 9, j + 8, k + 6, Dungeons.midnightLeaves, 0);
        this.setBlock(world, i + 9, j + 8, k + 7, Dungeons.midnightLeaves, 0);
        this.setBlock(world, i + 9, j + 8, k + 8, Dungeons.midnightLeaves, 0);
        this.setBlock(world, i + 9, j + 8, k + 12, Dungeons.midnightLeaves, 0);
        this.setBlock(world, i + 9, j + 8, k + 15, Dungeons.midnightLeaves, 0);
        this.setBlock(world, i + 9, j + 8, k + 16, Dungeons.midnightLeaves, 0);
        this.setBlock(world, i + 9, j + 9, k + 3, Dungeons.midnightLeaves, 0);
        this.setBlock(world, i + 9, j + 9, k + 5, Dungeons.midnightLeaves, 0);
        this.setBlock(world, i + 9, j + 9, k + 6, Dungeons.midnightLeaves, 0);
        this.setBlock(world, i + 9, j + 9, k + 7, Dungeons.midnightLeaves, 0);
        this.setBlock(world, i + 9, j + 9, k + 8, Dungeons.midnightLeaves, 0);
        this.setBlock(world, i + 9, j + 9, k + 9, Dungeons.midnightLeaves, 0);
        this.setBlock(world, i + 9, j + 9, k + 12, Dungeons.midnightLeaves, 0);
        this.setBlock(world, i + 9, j + 9, k + 15, Dungeons.midnightLeaves, 0);
        this.setBlock(world, i + 9, j + 9, k + 16, Dungeons.midnightLeaves, 0);
        this.setBlock(world, i + 9, j + 10, k + 4, Dungeons.midnightLeaves, 0);
        this.setBlock(world, i + 9, j + 10, k + 5, Dungeons.midnightLeaves, 0);
        this.setBlock(world, i + 9, j + 10, k + 6, Dungeons.midnightLeaves, 0);
        this.setBlock(world, i + 9, j + 10, k + 7, Dungeons.midnightLeaves, 0);
        this.setBlock(world, i + 9, j + 10, k + 8, Dungeons.midnightLeaves, 0);
        this.setBlock(world, i + 9, j + 10, k + 9, Dungeons.midnightLeaves, 0);
        this.setBlock(world, i + 9, j + 10, k + 10, Dungeons.midnightLeaves, 0);
        this.setBlock(world, i + 9, j + 10, k + 11, Dungeons.midnightLeaves, 0);
        this.setBlock(world, i + 9, j + 10, k + 12, Dungeons.midnightLeaves, 0);
        this.setBlock(world, i + 9, j + 10, k + 13, Dungeons.midnightLeaves, 0);
        this.setBlock(world, i + 9, j + 10, k + 15, Dungeons.midnightLeaves, 0);
        this.setBlock(world, i + 9, j + 11, k + 8, Dungeons.midnightLeaves, 0);
        this.setBlock(world, i + 9, j + 11, k + 11, Dungeons.midnightLeaves, 0);
        this.setBlock(world, i + 9, j + 11, k + 12, Dungeons.midnightLeaves, 0);
        this.setBlock(world, i + 9, j + 11, k + 13, Dungeons.midnightLeaves, 0);
        this.setBlock(world, i + 9, j + 11, k + 14, Dungeons.midnightLeaves, 0);
        this.setBlock(world, i + 9, j + 11, k + 15, Dungeons.midnightLeaves, 0);
        this.setBlock(world, i + 10, j + 3, k + 1, Dungeons.midnightLeaves, 0);
        this.setBlock(world, i + 10, j + 4, k + 1, Dungeons.midnightLeaves, 0);
        this.setBlock(world, i + 10, j + 5, k + 1, Dungeons.midnightLeaves, 0);
        this.setBlock(world, i + 10, j + 5, k + 7, Dungeons.midnightLeaves, 0);
        this.setBlock(world, i + 10, j + 5, k + 13, Dungeons.midnightLeaves, 0);
        this.setBlock(world, i + 10, j + 6, k + 1, Dungeons.midnightLeaves, 0);
        this.setBlock(world, i + 10, j + 6, k + 3, Dungeons.midnightLeaves, 0);
        this.setBlock(world, i + 10, j + 6, k + 7, Dungeons.midnightLeaves, 0);
        this.setBlock(world, i + 10, j + 6, k + 13, Dungeons.midnightLeaves, 0);
        this.setBlock(world, i + 10, j + 6, k + 16, Dungeons.midnightLeaves, 0);
        this.setBlock(world, i + 10, j + 7, k + 0, Dungeons.midnightLeaves, 0);
        this.setBlock(world, i + 10, j + 7, k + 1, Dungeons.midnightLeaves, 0);
        this.setBlock(world, i + 10, j + 7, k + 3, Dungeons.midnightLeaves, 0);
        this.setBlock(world, i + 10, j + 7, k + 7, Dungeons.midnightLeaves, 0);
        this.setBlock(world, i + 10, j + 7, k + 10, Dungeons.midnightLeaves, 0);
        this.setBlock(world, i + 10, j + 7, k + 13, Dungeons.midnightLeaves, 0);
        this.setBlock(world, i + 10, j + 7, k + 16, Dungeons.midnightLeaves, 0);
        this.setBlock(world, i + 10, j + 8, k + 1, Dungeons.midnightLeaves, 0);
        this.setBlock(world, i + 10, j + 8, k + 2, Dungeons.midnightLeaves, 0);
        this.setBlock(world, i + 10, j + 8, k + 3, Dungeons.midnightLeaves, 0);
        this.setBlock(world, i + 10, j + 8, k + 5, Dungeons.midnightLeaves, 0);
        this.setBlock(world, i + 10, j + 8, k + 6, Dungeons.midnightLeaves, 0);
        this.setBlock(world, i + 10, j + 8, k + 7, Dungeons.midnightLeaves, 0);
        this.setBlock(world, i + 10, j + 8, k + 8, Dungeons.midnightLeaves, 0);
        this.setBlock(world, i + 10, j + 8, k + 9, Dungeons.midnightLeaves, 0);
        this.setBlock(world, i + 10, j + 8, k + 10, Dungeons.midnightLeaves, 0);
        this.setBlock(world, i + 10, j + 8, k + 13, Dungeons.midnightLeaves, 0);
        this.setBlock(world, i + 10, j + 8, k + 16, Dungeons.midnightLeaves, 0);
        this.setBlock(world, i + 10, j + 9, k + 3, Dungeons.midnightLeaves, 0);
        this.setBlock(world, i + 10, j + 9, k + 4, Dungeons.midnightLeaves, 0);
        this.setBlock(world, i + 10, j + 9, k + 5, Dungeons.midnightLeaves, 0);
        this.setBlock(world, i + 10, j + 9, k + 6, Dungeons.midnightLeaves, 0);
        this.setBlock(world, i + 10, j + 9, k + 7, Dungeons.midnightLeaves, 0);
        this.setBlock(world, i + 10, j + 9, k + 8, Dungeons.midnightLeaves, 0);
        this.setBlock(world, i + 10, j + 9, k + 9, Dungeons.midnightLeaves, 0);
        this.setBlock(world, i + 10, j + 9, k + 10, Dungeons.midnightLeaves, 0);
        this.setBlock(world, i + 10, j + 9, k + 11, Dungeons.midnightLeaves, 0);
        this.setBlock(world, i + 10, j + 9, k + 13, Dungeons.midnightLeaves, 0);
        this.setBlock(world, i + 10, j + 9, k + 15, Dungeons.midnightLeaves, 0);
        this.setBlock(world, i + 10, j + 9, k + 16, Dungeons.midnightLeaves, 0);
        this.setBlock(world, i + 10, j + 10, k + 4, Dungeons.midnightLeaves, 0);
        this.setBlock(world, i + 10, j + 10, k + 5, Dungeons.midnightLeaves, 0);
        this.setBlock(world, i + 10, j + 10, k + 6, Dungeons.midnightLeaves, 0);
        this.setBlock(world, i + 10, j + 10, k + 7, Dungeons.midnightLeaves, 0);
        this.setBlock(world, i + 10, j + 10, k + 8, Dungeons.midnightLeaves, 0);
        this.setBlock(world, i + 10, j + 10, k + 9, Dungeons.midnightLeaves, 0);
        this.setBlock(world, i + 10, j + 10, k + 10, Dungeons.midnightLeaves, 0);
        this.setBlock(world, i + 10, j + 10, k + 11, Dungeons.midnightLeaves, 0);
        this.setBlock(world, i + 10, j + 10, k + 12, Dungeons.midnightLeaves, 0);
        this.setBlock(world, i + 10, j + 10, k + 13, Dungeons.midnightLeaves, 0);
        this.setBlock(world, i + 10, j + 10, k + 14, Dungeons.midnightLeaves, 0);
        this.setBlock(world, i + 10, j + 10, k + 15, Dungeons.midnightLeaves, 0);
        this.setBlock(world, i + 10, j + 11, k + 8, Dungeons.midnightLeaves, 0);
        this.setBlock(world, i + 10, j + 11, k + 13, Dungeons.midnightLeaves, 0);
        this.setBlock(world, i + 10, j + 11, k + 14, Dungeons.midnightLeaves, 0);
        this.setBlock(world, i + 11, j + 5, k + 2, Dungeons.midnightLeaves, 0);
        this.setBlock(world, i + 11, j + 5, k + 7, Dungeons.midnightLeaves, 0);
        this.setBlock(world, i + 11, j + 5, k + 10, Dungeons.midnightLeaves, 0);
        this.setBlock(world, i + 11, j + 6, k + 2, Dungeons.midnightLeaves, 0);
        this.setBlock(world, i + 11, j + 6, k + 3, Dungeons.midnightLeaves, 0);
        this.setBlock(world, i + 11, j + 6, k + 4, Dungeons.midnightLeaves, 0);
        this.setBlock(world, i + 11, j + 6, k + 7, Dungeons.midnightLeaves, 0);
        this.setBlock(world, i + 11, j + 6, k + 10, Dungeons.midnightLeaves, 0);
        this.setBlock(world, i + 11, j + 6, k + 17, Dungeons.midnightLeaves, 0);
        this.setBlock(world, i + 11, j + 7, k + 2, Dungeons.midnightLeaves, 0);
        this.setBlock(world, i + 11, j + 7, k + 3, Dungeons.midnightLeaves, 0);
        this.setBlock(world, i + 11, j + 7, k + 4, Dungeons.midnightLeaves, 0);
        this.setBlock(world, i + 11, j + 7, k + 7, Dungeons.midnightLeaves, 0);
        this.setBlock(world, i + 11, j + 7, k + 9, Dungeons.midnightLeaves, 0);
        this.setBlock(world, i + 11, j + 7, k + 10, Dungeons.midnightLeaves, 0);
        this.setBlock(world, i + 11, j + 7, k + 11, Dungeons.midnightLeaves, 0);
        this.setBlock(world, i + 11, j + 7, k + 16, Dungeons.midnightLeaves, 0);
        this.setBlock(world, i + 11, j + 7, k + 17, Dungeons.midnightLeaves, 0);
        this.setBlock(world, i + 11, j + 8, k + 3, Dungeons.midnightLeaves, 0);
        this.setBlock(world, i + 11, j + 8, k + 4, Dungeons.midnightLeaves, 0);
        this.setBlock(world, i + 11, j + 8, k + 6, Dungeons.midnightLeaves, 0);
        this.setBlock(world, i + 11, j + 8, k + 7, Dungeons.midnightLeaves, 0);
        this.setBlock(world, i + 11, j + 8, k + 9, Dungeons.midnightLeaves, 0);
        this.setBlock(world, i + 11, j + 8, k + 10, Dungeons.midnightLeaves, 0);
        this.setBlock(world, i + 11, j + 8, k + 11, Dungeons.midnightLeaves, 0);
        this.setBlock(world, i + 11, j + 8, k + 15, Dungeons.midnightLeaves, 0);
        this.setBlock(world, i + 11, j + 8, k + 16, Dungeons.midnightLeaves, 0);
        this.setBlock(world, i + 11, j + 9, k + 3, Dungeons.midnightLeaves, 0);
        this.setBlock(world, i + 11, j + 9, k + 4, Dungeons.midnightLeaves, 0);
        this.setBlock(world, i + 11, j + 9, k + 5, Dungeons.midnightLeaves, 0);
        this.setBlock(world, i + 11, j + 9, k + 6, Dungeons.midnightLeaves, 0);
        this.setBlock(world, i + 11, j + 9, k + 7, Dungeons.midnightLeaves, 0);
        this.setBlock(world, i + 11, j + 9, k + 8, Dungeons.midnightLeaves, 0);
        this.setBlock(world, i + 11, j + 9, k + 9, Dungeons.midnightLeaves, 0);
        this.setBlock(world, i + 11, j + 9, k + 10, Dungeons.midnightLeaves, 0);
        this.setBlock(world, i + 11, j + 9, k + 11, Dungeons.midnightLeaves, 0);
        this.setBlock(world, i + 11, j + 9, k + 12, Dungeons.midnightLeaves, 0);
        this.setBlock(world, i + 11, j + 9, k + 13, Dungeons.midnightLeaves, 0);
        this.setBlock(world, i + 11, j + 9, k + 14, Dungeons.midnightLeaves, 0);
        this.setBlock(world, i + 11, j + 9, k + 15, Dungeons.midnightLeaves, 0);
        this.setBlock(world, i + 11, j + 9, k + 16, Dungeons.midnightLeaves, 0);
        this.setBlock(world, i + 11, j + 10, k + 5, Dungeons.midnightLeaves, 0);
        this.setBlock(world, i + 11, j + 10, k + 7, Dungeons.midnightLeaves, 0);
        this.setBlock(world, i + 11, j + 10, k + 8, Dungeons.midnightLeaves, 0);
        this.setBlock(world, i + 11, j + 10, k + 9, Dungeons.midnightLeaves, 0);
        this.setBlock(world, i + 11, j + 10, k + 10, Dungeons.midnightLeaves, 0);
        this.setBlock(world, i + 11, j + 10, k + 11, Dungeons.midnightLeaves, 0);
        this.setBlock(world, i + 11, j + 10, k + 12, Dungeons.midnightLeaves, 0);
        this.setBlock(world, i + 11, j + 10, k + 13, Dungeons.midnightLeaves, 0);
        this.setBlock(world, i + 11, j + 10, k + 14, Dungeons.midnightLeaves, 0);
        this.setBlock(world, i + 11, j + 10, k + 15, Dungeons.midnightLeaves, 0);
        this.setBlock(world, i + 12, j + 2, k + 2, Dungeons.midnightLeaves, 0);
        this.setBlock(world, i + 12, j + 3, k + 2, Dungeons.midnightLeaves, 0);
        this.setBlock(world, i + 12, j + 3, k + 8, Dungeons.midnightLeaves, 0);
        this.setBlock(world, i + 12, j + 4, k + 2, Dungeons.midnightLeaves, 0);
        this.setBlock(world, i + 12, j + 4, k + 8, Dungeons.midnightLeaves, 0);
        this.setBlock(world, i + 12, j + 4, k + 17, Dungeons.midnightLeaves, 0);
        this.setBlock(world, i + 12, j + 5, k + 2, Dungeons.midnightLeaves, 0);
        this.setBlock(world, i + 12, j + 5, k + 8, Dungeons.midnightLeaves, 0);
        this.setBlock(world, i + 12, j + 5, k + 10, Dungeons.midnightLeaves, 0);
        this.setBlock(world, i + 12, j + 5, k + 17, Dungeons.midnightLeaves, 0);
        this.setBlock(world, i + 12, j + 6, k + 2, Dungeons.midnightLeaves, 0);
        this.setBlock(world, i + 12, j + 6, k + 3, Dungeons.midnightLeaves, 0);
        this.setBlock(world, i + 12, j + 6, k + 7, Dungeons.midnightLeaves, 0);
        this.setBlock(world, i + 12, j + 6, k + 8, Dungeons.midnightLeaves, 0);
        this.setBlock(world, i + 12, j + 6, k + 10, Dungeons.midnightLeaves, 0);
        this.setBlock(world, i + 12, j + 6, k + 17, Dungeons.midnightLeaves, 0);
        this.setBlock(world, i + 12, j + 7, k + 3, Dungeons.midnightLeaves, 0);
        this.setBlock(world, i + 12, j + 7, k + 8, Dungeons.midnightLeaves, 0);
        this.setBlock(world, i + 12, j + 7, k + 10, Dungeons.midnightLeaves, 0);
        this.setBlock(world, i + 12, j + 7, k + 16, Dungeons.midnightLeaves, 0);
        this.setBlock(world, i + 12, j + 8, k + 3, Dungeons.midnightLeaves, 0);
        this.setBlock(world, i + 12, j + 8, k + 6, Dungeons.midnightLeaves, 0);
        this.setBlock(world, i + 12, j + 8, k + 8, Dungeons.midnightLeaves, 0);
        this.setBlock(world, i + 12, j + 8, k + 10, Dungeons.midnightLeaves, 0);
        this.setBlock(world, i + 12, j + 8, k + 15, Dungeons.midnightLeaves, 0);
        this.setBlock(world, i + 12, j + 8, k + 16, Dungeons.midnightLeaves, 0);
        this.setBlock(world, i + 12, j + 9, k + 3, Dungeons.midnightLeaves, 0);
        this.setBlock(world, i + 12, j + 9, k + 4, Dungeons.midnightLeaves, 0);
        this.setBlock(world, i + 12, j + 9, k + 5, Dungeons.midnightLeaves, 0);
        this.setBlock(world, i + 12, j + 9, k + 6, Dungeons.midnightLeaves, 0);
        this.setBlock(world, i + 12, j + 9, k + 7, Dungeons.midnightLeaves, 0);
        this.setBlock(world, i + 12, j + 9, k + 8, Dungeons.midnightLeaves, 0);
        this.setBlock(world, i + 12, j + 9, k + 9, Dungeons.midnightLeaves, 0);
        this.setBlock(world, i + 12, j + 9, k + 10, Dungeons.midnightLeaves, 0);
        this.setBlock(world, i + 12, j + 9, k + 11, Dungeons.midnightLeaves, 0);
        this.setBlock(world, i + 12, j + 9, k + 12, Dungeons.midnightLeaves, 0);
        this.setBlock(world, i + 12, j + 9, k + 13, Dungeons.midnightLeaves, 0);
        this.setBlock(world, i + 12, j + 9, k + 14, Dungeons.midnightLeaves, 0);
        this.setBlock(world, i + 12, j + 9, k + 15, Dungeons.midnightLeaves, 0);
        this.setBlock(world, i + 12, j + 10, k + 8, Dungeons.midnightLeaves, 0);
        this.setBlock(world, i + 12, j + 10, k + 9, Dungeons.midnightLeaves, 0);
        this.setBlock(world, i + 12, j + 10, k + 10, Dungeons.midnightLeaves, 0);
        this.setBlock(world, i + 12, j + 10, k + 13, Dungeons.midnightLeaves, 0);
        this.setBlock(world, i + 12, j + 10, k + 14, Dungeons.midnightLeaves, 0);
        this.setBlock(world, i + 13, j + 5, k + 3, Dungeons.midnightLeaves, 0);
        this.setBlock(world, i + 13, j + 5, k + 16, Dungeons.midnightLeaves, 0);
        this.setBlock(world, i + 13, j + 6, k + 3, Dungeons.midnightLeaves, 0);
        this.setBlock(world, i + 13, j + 6, k + 16, Dungeons.midnightLeaves, 0);
        this.setBlock(world, i + 13, j + 7, k + 3, Dungeons.midnightLeaves, 0);
        this.setBlock(world, i + 13, j + 7, k + 5, Dungeons.midnightLeaves, 0);
        this.setBlock(world, i + 13, j + 7, k + 15, Dungeons.midnightLeaves, 0);
        this.setBlock(world, i + 13, j + 7, k + 16, Dungeons.midnightLeaves, 0);
        this.setBlock(world, i + 13, j + 8, k + 3, Dungeons.midnightLeaves, 0);
        this.setBlock(world, i + 13, j + 8, k + 4, Dungeons.midnightLeaves, 0);
        this.setBlock(world, i + 13, j + 8, k + 5, Dungeons.midnightLeaves, 0);
        this.setBlock(world, i + 13, j + 8, k + 6, Dungeons.midnightLeaves, 0);
        this.setBlock(world, i + 13, j + 8, k + 14, Dungeons.midnightLeaves, 0);
        this.setBlock(world, i + 13, j + 8, k + 15, Dungeons.midnightLeaves, 0);
        this.setBlock(world, i + 13, j + 8, k + 16, Dungeons.midnightLeaves, 0);
        this.setBlock(world, i + 13, j + 9, k + 4, Dungeons.midnightLeaves, 0);
        this.setBlock(world, i + 13, j + 9, k + 5, Dungeons.midnightLeaves, 0);
        this.setBlock(world, i + 13, j + 9, k + 6, Dungeons.midnightLeaves, 0);
        this.setBlock(world, i + 13, j + 9, k + 9, Dungeons.midnightLeaves, 0);
        this.setBlock(world, i + 13, j + 9, k + 10, Dungeons.midnightLeaves, 0);
        this.setBlock(world, i + 13, j + 9, k + 11, Dungeons.midnightLeaves, 0);
        this.setBlock(world, i + 13, j + 9, k + 12, Dungeons.midnightLeaves, 0);
        this.setBlock(world, i + 13, j + 9, k + 13, Dungeons.midnightLeaves, 0);
        this.setBlock(world, i + 13, j + 9, k + 14, Dungeons.midnightLeaves, 0);
        this.setBlock(world, i + 13, j + 9, k + 15, Dungeons.midnightLeaves, 0);
        this.setBlock(world, i + 13, j + 10, k + 7, Dungeons.midnightLeaves, 0);
        this.setBlock(world, i + 13, j + 10, k + 8, Dungeons.midnightLeaves, 0);
        this.setBlock(world, i + 13, j + 10, k + 9, Dungeons.midnightLeaves, 0);
        this.setBlock(world, i + 14, j + 2, k + 15, Dungeons.midnightLeaves, 0);
        this.setBlock(world, i + 14, j + 3, k + 15, Dungeons.midnightLeaves, 0);
        this.setBlock(world, i + 14, j + 4, k + 4, Dungeons.midnightLeaves, 0);
        this.setBlock(world, i + 14, j + 4, k + 15, Dungeons.midnightLeaves, 0);
        this.setBlock(world, i + 14, j + 5, k + 4, Dungeons.midnightLeaves, 0);
        this.setBlock(world, i + 14, j + 5, k + 5, Dungeons.midnightLeaves, 0);
        this.setBlock(world, i + 14, j + 5, k + 14, Dungeons.midnightLeaves, 0);
        this.setBlock(world, i + 14, j + 5, k + 15, Dungeons.midnightLeaves, 0);
        this.setBlock(world, i + 14, j + 6, k + 4, Dungeons.midnightLeaves, 0);
        this.setBlock(world, i + 14, j + 6, k + 5, Dungeons.midnightLeaves, 0);
        this.setBlock(world, i + 14, j + 6, k + 14, Dungeons.midnightLeaves, 0);
        this.setBlock(world, i + 14, j + 6, k + 15, Dungeons.midnightLeaves, 0);
        this.setBlock(world, i + 14, j + 7, k + 4, Dungeons.midnightLeaves, 0);
        this.setBlock(world, i + 14, j + 7, k + 5, Dungeons.midnightLeaves, 0);
        this.setBlock(world, i + 14, j + 7, k + 6, Dungeons.midnightLeaves, 0);
        this.setBlock(world, i + 14, j + 7, k + 14, Dungeons.midnightLeaves, 0);
        this.setBlock(world, i + 14, j + 7, k + 15, Dungeons.midnightLeaves, 0);
        this.setBlock(world, i + 14, j + 8, k + 6, Dungeons.midnightLeaves, 0);
        this.setBlock(world, i + 14, j + 8, k + 8, Dungeons.midnightLeaves, 0);
        this.setBlock(world, i + 14, j + 8, k + 11, Dungeons.midnightLeaves, 0);
        this.setBlock(world, i + 14, j + 8, k + 12, Dungeons.midnightLeaves, 0);
        this.setBlock(world, i + 14, j + 8, k + 13, Dungeons.midnightLeaves, 0);
        this.setBlock(world, i + 14, j + 8, k + 14, Dungeons.midnightLeaves, 0);
        this.setBlock(world, i + 14, j + 9, k + 6, Dungeons.midnightLeaves, 0);
        this.setBlock(world, i + 14, j + 9, k + 7, Dungeons.midnightLeaves, 0);
        this.setBlock(world, i + 14, j + 9, k + 8, Dungeons.midnightLeaves, 0);
        this.setBlock(world, i + 14, j + 9, k + 9, Dungeons.midnightLeaves, 0);
        this.setBlock(world, i + 14, j + 9, k + 10, Dungeons.midnightLeaves, 0);
        this.setBlock(world, i + 14, j + 9, k + 11, Dungeons.midnightLeaves, 0);
        this.setBlock(world, i + 14, j + 10, k + 7, Dungeons.midnightLeaves, 0);
        this.setBlock(world, i + 14, j + 10, k + 8, Dungeons.midnightLeaves, 0);
        this.setBlock(world, i + 14, j + 10, k + 9, Dungeons.midnightLeaves, 0);
        this.setBlock(world, i + 14, j + 10, k + 10, Dungeons.midnightLeaves, 0);
        this.setBlock(world, i + 15, j + 4, k + 11, Dungeons.midnightLeaves, 0);
        this.setBlock(world, i + 15, j + 4, k + 13, Dungeons.midnightLeaves, 0);
        this.setBlock(world, i + 15, j + 5, k + 11, Dungeons.midnightLeaves, 0);
        this.setBlock(world, i + 15, j + 5, k + 13, Dungeons.midnightLeaves, 0);
        this.setBlock(world, i + 15, j + 6, k + 6, Dungeons.midnightLeaves, 0);
        this.setBlock(world, i + 15, j + 6, k + 7, Dungeons.midnightLeaves, 0);
        this.setBlock(world, i + 15, j + 6, k + 8, Dungeons.midnightLeaves, 0);
        this.setBlock(world, i + 15, j + 6, k + 11, Dungeons.midnightLeaves, 0);
        this.setBlock(world, i + 15, j + 6, k + 12, Dungeons.midnightLeaves, 0);
        this.setBlock(world, i + 15, j + 6, k + 13, Dungeons.midnightLeaves, 0);
        this.setBlock(world, i + 15, j + 7, k + 6, Dungeons.midnightLeaves, 0);
        this.setBlock(world, i + 15, j + 7, k + 7, Dungeons.midnightLeaves, 0);
        this.setBlock(world, i + 15, j + 7, k + 8, Dungeons.midnightLeaves, 0);
        this.setBlock(world, i + 15, j + 7, k + 10, Dungeons.midnightLeaves, 0);
        this.setBlock(world, i + 15, j + 7, k + 11, Dungeons.midnightLeaves, 0);
        this.setBlock(world, i + 15, j + 7, k + 12, Dungeons.midnightLeaves, 0);
        this.setBlock(world, i + 15, j + 7, k + 13, Dungeons.midnightLeaves, 0);
        this.setBlock(world, i + 15, j + 8, k + 6, Dungeons.midnightLeaves, 0);
        this.setBlock(world, i + 15, j + 8, k + 8, Dungeons.midnightLeaves, 0);
        this.setBlock(world, i + 15, j + 8, k + 9, Dungeons.midnightLeaves, 0);
        this.setBlock(world, i + 15, j + 8, k + 10, Dungeons.midnightLeaves, 0);
        this.setBlock(world, i + 15, j + 9, k + 8, Dungeons.midnightLeaves, 0);
        this.setBlock(world, i + 15, j + 9, k + 9, Dungeons.midnightLeaves, 0);
        this.setBlock(world, i + 16, j + 2, k + 8, Dungeons.midnightLeaves, 0);
        this.setBlock(world, i + 16, j + 3, k + 8, Dungeons.midnightLeaves, 0);
        this.setBlock(world, i + 16, j + 3, k + 9, Dungeons.midnightLeaves, 0);
        this.setBlock(world, i + 16, j + 3, k + 11, Dungeons.midnightLeaves, 0);
        this.setBlock(world, i + 16, j + 4, k + 7, Dungeons.midnightLeaves, 0);
        this.setBlock(world, i + 16, j + 4, k + 8, Dungeons.midnightLeaves, 0);
        this.setBlock(world, i + 16, j + 4, k + 9, Dungeons.midnightLeaves, 0);
        this.setBlock(world, i + 16, j + 4, k + 11, Dungeons.midnightLeaves, 0);
        this.setBlock(world, i + 16, j + 5, k + 5, Dungeons.midnightLeaves, 0);
        this.setBlock(world, i + 16, j + 5, k + 6, Dungeons.midnightLeaves, 0);
        this.setBlock(world, i + 16, j + 5, k + 7, Dungeons.midnightLeaves, 0);
        this.setBlock(world, i + 16, j + 5, k + 8, Dungeons.midnightLeaves, 0);
        this.setBlock(world, i + 16, j + 5, k + 9, Dungeons.midnightLeaves, 0);
        this.setBlock(world, i + 16, j + 5, k + 11, Dungeons.midnightLeaves, 0);
        this.setBlock(world, i + 16, j + 6, k + 7, Dungeons.midnightLeaves, 0);
        this.setBlock(world, i + 16, j + 6, k + 8, Dungeons.midnightLeaves, 0);
        this.setBlock(world, i + 16, j + 6, k + 9, Dungeons.midnightLeaves, 0);
        this.setBlock(world, i + 16, j + 6, k + 10, Dungeons.midnightLeaves, 0);
        this.setBlock(world, i + 16, j + 6, k + 11, Dungeons.midnightLeaves, 0);
        this.setBlock(world, i + 16, j + 7, k + 8, Dungeons.midnightLeaves, 0);
        this.setBlock(world, i + 16, j + 7, k + 9, Dungeons.midnightLeaves, 0);
        this.setBlock(world, i + 16, j + 7, k + 10, Dungeons.midnightLeaves, 0);
        this.setBlock(world, i + 16, j + 8, k + 8, Dungeons.midnightLeaves, 0);
        this.setBlock(world, i + 17, j + 5, k + 11, Dungeons.midnightLeaves, 0);
        return true;
    }
}
