package com.gibby.dungeon.gen;

import com.gibby.dungeon.Dungeons;
import cpw.mods.fml.common.IWorldGenerator;
import net.minecraft.block.Block;
import net.minecraft.world.World;
import net.minecraft.world.chunk.IChunkProvider;
import net.minecraft.world.gen.feature.WorldGenerator;

import java.util.Random;

public class MidnightWillowLarge extends WorldGenerator implements IWorldGenerator
{
    public void generate(final Random random, final int chunkX, final int chunkZ, final World world, final IChunkProvider chunkGenerator, final IChunkProvider chunkProvider) {
    }

    public void setBlock(final World world, final int x, final int y, final int z, final Block block, final int metadata) {
        final Block b1 = world.getBlock(x, y, z);
        if (b1.isAir(world, x, y, z) || b1.isLeaves(world, x, y, z)) {
            world.setBlock(x, y, z, block, metadata, 2);
        }
    }

    public boolean generate(final World world, final Random rand, final int i, final int j, final int k) {
        if (world.getBlock(i + 17, j - 1, k + 16) != Dungeons.midnightGrass || world.getBlock(i + 18, j - 1, k + 17) != Dungeons.midnightGrass) {
            return false;
        }
        for (int c = 4; c < 20; ++c) {
            if (!world.isAirBlock(i, j + c, k + 28)) {
                return false;
            }
            if (!world.isAirBlock(i + 28, j + c, k)) {
                return false;
            }
            if (!world.isAirBlock(i, j + c, k)) {
                return false;
            }
            if (!world.isAirBlock(i + 28, j + c, k + 28)) {
                return false;
            }
            if (!world.isAirBlock(i + 10, j + c, k + 10)) {
                return false;
            }
            if (!world.isAirBlock(i + 17, j + c, k + 17)) {
                return false;
            }
        }
        this.setBlock(world, i + 1, j + 4, k + 17, Dungeons.midnightLeaves, 0);
        this.setBlock(world, i + 1, j + 5, k + 15, Dungeons.midnightLeaves, 0);
        this.setBlock(world, i + 1, j + 5, k + 17, Dungeons.midnightLeaves, 0);
        this.setBlock(world, i + 1, j + 6, k + 14, Dungeons.midnightLeaves, 0);
        this.setBlock(world, i + 1, j + 6, k + 15, Dungeons.midnightLeaves, 0);
        this.setBlock(world, i + 1, j + 6, k + 16, Dungeons.midnightLeaves, 0);
        this.setBlock(world, i + 1, j + 6, k + 17, Dungeons.midnightLeaves, 0);
        this.setBlock(world, i + 1, j + 7, k + 12, Dungeons.midnightLeaves, 0);
        this.setBlock(world, i + 1, j + 7, k + 13, Dungeons.midnightLeaves, 0);
        this.setBlock(world, i + 1, j + 7, k + 14, Dungeons.midnightLeaves, 0);
        this.setBlock(world, i + 1, j + 7, k + 15, Dungeons.midnightLeaves, 0);
        this.setBlock(world, i + 1, j + 7, k + 16, Dungeons.midnightLeaves, 0);
        this.setBlock(world, i + 1, j + 7, k + 17, Dungeons.midnightLeaves, 0);
        this.setBlock(world, i + 1, j + 7, k + 18, Dungeons.midnightLeaves, 0);
        this.setBlock(world, i + 1, j + 8, k + 13, Dungeons.midnightLeaves, 0);
        this.setBlock(world, i + 1, j + 8, k + 14, Dungeons.midnightLeaves, 0);
        this.setBlock(world, i + 1, j + 8, k + 15, Dungeons.midnightLeaves, 0);
        this.setBlock(world, i + 1, j + 8, k + 16, Dungeons.midnightLeaves, 0);
        this.setBlock(world, i + 1, j + 8, k + 17, Dungeons.midnightLeaves, 0);
        this.setBlock(world, i + 1, j + 9, k + 13, Dungeons.midnightLeaves, 0);
        this.setBlock(world, i + 1, j + 9, k + 14, Dungeons.midnightLeaves, 0);
        this.setBlock(world, i + 1, j + 9, k + 15, Dungeons.midnightLeaves, 0);
        this.setBlock(world, i + 1, j + 9, k + 16, Dungeons.midnightLeaves, 0);
        this.setBlock(world, i + 1, j + 9, k + 17, Dungeons.midnightLeaves, 0);
        this.setBlock(world, i + 1, j + 10, k + 13, Dungeons.midnightLeaves, 0);
        this.setBlock(world, i + 1, j + 10, k + 14, Dungeons.midnightLeaves, 0);
        this.setBlock(world, i + 1, j + 10, k + 15, Dungeons.midnightLeaves, 0);
        this.setBlock(world, i + 1, j + 10, k + 16, Dungeons.midnightLeaves, 0);
        this.setBlock(world, i + 1, j + 10, k + 17, Dungeons.midnightLeaves, 0);
        this.setBlock(world, i + 1, j + 11, k + 15, Dungeons.midnightLeaves, 0);
        this.setBlock(world, i + 1, j + 11, k + 16, Dungeons.midnightLeaves, 0);
        this.setBlock(world, i + 1, j + 11, k + 17, Dungeons.midnightLeaves, 0);
        this.setBlock(world, i + 1, j + 12, k + 15, Dungeons.midnightLeaves, 0);
        this.setBlock(world, i + 1, j + 12, k + 17, Dungeons.midnightLeaves, 0);
        this.setBlock(world, i + 2, j + 4, k + 18, Dungeons.midnightLeaves, 0);
        this.setBlock(world, i + 2, j + 4, k + 19, Dungeons.midnightLeaves, 0);
        this.setBlock(world, i + 2, j + 5, k + 11, Dungeons.midnightLeaves, 0);
        this.setBlock(world, i + 2, j + 5, k + 18, Dungeons.midnightLeaves, 0);
        this.setBlock(world, i + 2, j + 5, k + 19, Dungeons.midnightLeaves, 0);
        this.setBlock(world, i + 2, j + 6, k + 11, Dungeons.midnightLeaves, 0);
        this.setBlock(world, i + 2, j + 6, k + 12, Dungeons.midnightLeaves, 0);
        this.setBlock(world, i + 2, j + 6, k + 18, Dungeons.midnightLeaves, 0);
        this.setBlock(world, i + 2, j + 6, k + 19, Dungeons.midnightLeaves, 0);
        this.setBlock(world, i + 2, j + 7, k + 10, Dungeons.midnightLeaves, 0);
        this.setBlock(world, i + 2, j + 7, k + 11, Dungeons.midnightLeaves, 0);
        this.setBlock(world, i + 2, j + 7, k + 12, Dungeons.midnightLeaves, 0);
        this.setBlock(world, i + 2, j + 7, k + 18, Dungeons.midnightLeaves, 0);
        this.setBlock(world, i + 2, j + 7, k + 19, Dungeons.midnightLeaves, 0);
        this.setBlock(world, i + 2, j + 8, k + 10, Dungeons.midnightLeaves, 0);
        this.setBlock(world, i + 2, j + 8, k + 11, Dungeons.midnightLeaves, 0);
        this.setBlock(world, i + 2, j + 8, k + 12, Dungeons.midnightLeaves, 0);
        this.setBlock(world, i + 2, j + 8, k + 18, Dungeons.midnightLeaves, 0);
        this.setBlock(world, i + 2, j + 8, k + 19, Dungeons.midnightLeaves, 0);
        this.setBlock(world, i + 2, j + 9, k + 10, Dungeons.midnightLeaves, 0);
        this.setBlock(world, i + 2, j + 9, k + 11, Dungeons.midnightLeaves, 0);
        this.setBlock(world, i + 2, j + 9, k + 12, Dungeons.midnightLeaves, 0);
        this.setBlock(world, i + 2, j + 9, k + 18, Dungeons.midnightLeaves, 0);
        this.setBlock(world, i + 2, j + 9, k + 19, Dungeons.midnightLeaves, 0);
        this.setBlock(world, i + 2, j + 10, k + 10, Dungeons.midnightLeaves, 0);
        this.setBlock(world, i + 2, j + 10, k + 11, Dungeons.midnightLeaves, 0);
        this.setBlock(world, i + 2, j + 10, k + 12, Dungeons.midnightLeaves, 0);
        this.setBlock(world, i + 2, j + 10, k + 13, Dungeons.midnightLeaves, 0);
        this.setBlock(world, i + 2, j + 10, k + 14, Dungeons.midnightLeaves, 0);
        this.setBlock(world, i + 2, j + 10, k + 15, Dungeons.midnightLeaves, 0);
        this.setBlock(world, i + 2, j + 10, k + 18, Dungeons.midnightLeaves, 0);
        this.setBlock(world, i + 2, j + 10, k + 19, Dungeons.midnightLeaves, 0);
        this.setBlock(world, i + 2, j + 11, k + 10, Dungeons.midnightLeaves, 0);
        this.setBlock(world, i + 2, j + 11, k + 11, Dungeons.midnightLeaves, 0);
        this.setBlock(world, i + 2, j + 11, k + 12, Dungeons.midnightLeaves, 0);
        this.setBlock(world, i + 2, j + 11, k + 13, Dungeons.midnightLeaves, 0);
        this.setBlock(world, i + 2, j + 11, k + 14, Dungeons.midnightLeaves, 0);
        this.setBlock(world, i + 2, j + 11, k + 15, Dungeons.midnightLeaves, 0);
        this.setBlock(world, i + 2, j + 11, k + 17, Dungeons.midnightLeaves, 0);
        this.setBlock(world, i + 2, j + 12, k + 12, Dungeons.midnightLeaves, 0);
        this.setBlock(world, i + 2, j + 12, k + 13, Dungeons.midnightLeaves, 0);
        this.setBlock(world, i + 2, j + 12, k + 14, Dungeons.midnightLeaves, 0);
        this.setBlock(world, i + 2, j + 12, k + 15, Dungeons.midnightLeaves, 0);
        this.setBlock(world, i + 2, j + 12, k + 16, Dungeons.midnightLeaves, 0);
        this.setBlock(world, i + 2, j + 12, k + 17, Dungeons.midnightLeaves, 0);
        this.setBlock(world, i + 2, j + 13, k + 13, Dungeons.midnightLeaves, 0);
        this.setBlock(world, i + 2, j + 13, k + 14, Dungeons.midnightLeaves, 0);
        this.setBlock(world, i + 2, j + 13, k + 15, Dungeons.midnightLeaves, 0);
        this.setBlock(world, i + 2, j + 13, k + 16, Dungeons.midnightLeaves, 0);
        this.setBlock(world, i + 2, j + 13, k + 17, Dungeons.midnightLeaves, 0);
        this.setBlock(world, i + 2, j + 14, k + 14, Dungeons.midnightLeaves, 0);
        this.setBlock(world, i + 2, j + 14, k + 15, Dungeons.midnightLeaves, 0);
        this.setBlock(world, i + 2, j + 14, k + 16, Dungeons.midnightLeaves, 0);
        this.setBlock(world, i + 2, j + 15, k + 15, Dungeons.midnightLeaves, 0);
        this.setBlock(world, i + 3, j + 5, k + 8, Dungeons.midnightLeaves, 0);
        this.setBlock(world, i + 3, j + 6, k + 8, Dungeons.midnightLeaves, 0);
        this.setBlock(world, i + 3, j + 6, k + 19, Dungeons.midnightLeaves, 0);
        this.setBlock(world, i + 3, j + 7, k + 8, Dungeons.midnightLeaves, 0);
        this.setBlock(world, i + 3, j + 7, k + 9, Dungeons.midnightLeaves, 0);
        this.setBlock(world, i + 3, j + 7, k + 19, Dungeons.midnightLeaves, 0);
        this.setBlock(world, i + 3, j + 8, k + 8, Dungeons.midnightLeaves, 0);
        this.setBlock(world, i + 3, j + 8, k + 9, Dungeons.midnightLeaves, 0);
        this.setBlock(world, i + 3, j + 8, k + 19, Dungeons.midnightLeaves, 0);
        this.setBlock(world, i + 3, j + 9, k + 8, Dungeons.midnightLeaves, 0);
        this.setBlock(world, i + 3, j + 9, k + 9, Dungeons.midnightLeaves, 0);
        this.setBlock(world, i + 3, j + 9, k + 19, Dungeons.midnightLeaves, 0);
        this.setBlock(world, i + 3, j + 10, k + 8, Dungeons.midnightLeaves, 0);
        this.setBlock(world, i + 3, j + 10, k + 9, Dungeons.midnightLeaves, 0);
        this.setBlock(world, i + 3, j + 10, k + 18, Dungeons.midnightLeaves, 0);
        this.setBlock(world, i + 3, j + 10, k + 19, Dungeons.midnightLeaves, 0);
        this.setBlock(world, i + 3, j + 11, k + 8, Dungeons.midnightLeaves, 0);
        this.setBlock(world, i + 3, j + 11, k + 9, Dungeons.midnightLeaves, 0);
        this.setBlock(world, i + 3, j + 11, k + 18, Dungeons.midnightLeaves, 0);
        this.setBlock(world, i + 3, j + 11, k + 19, Dungeons.midnightLeaves, 0);
        this.setBlock(world, i + 3, j + 12, k + 9, Dungeons.midnightLeaves, 0);
        this.setBlock(world, i + 3, j + 12, k + 10, Dungeons.midnightLeaves, 0);
        this.setBlock(world, i + 3, j + 12, k + 11, Dungeons.midnightLeaves, 0);
        this.setBlock(world, i + 3, j + 12, k + 12, Dungeons.midnightLeaves, 0);
        this.setBlock(world, i + 3, j + 12, k + 14, Dungeons.midnightLeaves, 0);
        this.setBlock(world, i + 3, j + 12, k + 18, Dungeons.midnightLeaves, 0);
        this.setBlock(world, i + 3, j + 12, k + 19, Dungeons.midnightLeaves, 0);
        this.setBlock(world, i + 3, j + 13, k + 9, Dungeons.midnightLeaves, 0);
        this.setBlock(world, i + 3, j + 13, k + 10, Dungeons.midnightLeaves, 0);
        this.setBlock(world, i + 3, j + 13, k + 11, Dungeons.midnightLeaves, 0);
        this.setBlock(world, i + 3, j + 13, k + 12, Dungeons.midnightLeaves, 0);
        this.setBlock(world, i + 3, j + 13, k + 13, Dungeons.midnightLeaves, 0);
        this.setBlock(world, i + 3, j + 13, k + 14, Dungeons.midnightLeaves, 0);
        this.setBlock(world, i + 3, j + 13, k + 17, Dungeons.midnightLeaves, 0);
        this.setBlock(world, i + 3, j + 14, k + 12, Dungeons.midnightLeaves, 0);
        this.setBlock(world, i + 3, j + 14, k + 13, Dungeons.midnightLeaves, 0);
        this.setBlock(world, i + 3, j + 14, k + 14, Dungeons.midnightLeaves, 0);
        this.setBlock(world, i + 3, j + 14, k + 15, Dungeons.midnightLeaves, 0);
        this.setBlock(world, i + 3, j + 14, k + 16, Dungeons.midnightLeaves, 0);
        this.setBlock(world, i + 3, j + 14, k + 17, Dungeons.midnightLeaves, 0);
        this.setBlock(world, i + 3, j + 15, k + 11, Dungeons.midnightLeaves, 0);
        this.setBlock(world, i + 3, j + 15, k + 13, Dungeons.midnightLeaves, 0);
        this.setBlock(world, i + 3, j + 15, k + 15, Dungeons.midnightLeaves, 0);
        this.setBlock(world, i + 3, j + 15, k + 16, Dungeons.midnightLeaves, 0);
        this.setBlock(world, i + 4, j + 5, k + 20, Dungeons.midnightLeaves, 0);
        this.setBlock(world, i + 4, j + 6, k + 7, Dungeons.midnightLeaves, 0);
        this.setBlock(world, i + 4, j + 6, k + 20, Dungeons.midnightLeaves, 0);
        this.setBlock(world, i + 4, j + 7, k + 7, Dungeons.midnightLeaves, 0);
        this.setBlock(world, i + 4, j + 7, k + 20, Dungeons.midnightLeaves, 0);
        this.setBlock(world, i + 4, j + 8, k + 7, Dungeons.midnightLeaves, 0);
        this.setBlock(world, i + 4, j + 8, k + 20, Dungeons.midnightLeaves, 0);
        this.setBlock(world, i + 4, j + 9, k + 7, Dungeons.midnightLeaves, 0);
        this.setBlock(world, i + 4, j + 9, k + 20, Dungeons.midnightLeaves, 0);
        this.setBlock(world, i + 4, j + 10, k + 7, Dungeons.midnightLeaves, 0);
        this.setBlock(world, i + 4, j + 10, k + 20, Dungeons.midnightLeaves, 0);
        this.setBlock(world, i + 4, j + 10, k + 21, Dungeons.midnightLeaves, 0);
        this.setBlock(world, i + 4, j + 11, k + 7, Dungeons.midnightLeaves, 0);
        this.setBlock(world, i + 4, j + 11, k + 8, Dungeons.midnightLeaves, 0);
        this.setBlock(world, i + 4, j + 11, k + 18, Dungeons.midnightLeaves, 0);
        this.setBlock(world, i + 4, j + 11, k + 19, Dungeons.midnightLeaves, 0);
        this.setBlock(world, i + 4, j + 11, k + 20, Dungeons.midnightLeaves, 0);
        this.setBlock(world, i + 4, j + 12, k + 8, Dungeons.midnightLeaves, 0);
        this.setBlock(world, i + 4, j + 12, k + 18, Dungeons.midnightLeaves, 0);
        this.setBlock(world, i + 4, j + 12, k + 19, Dungeons.midnightLeaves, 0);
        this.setBlock(world, i + 4, j + 12, k + 20, Dungeons.midnightLeaves, 0);
        this.setBlock(world, i + 4, j + 13, k + 9, Dungeons.midnightLeaves, 0);
        this.setBlock(world, i + 4, j + 13, k + 11, Dungeons.midnightLeaves, 0);
        this.setBlock(world, i + 4, j + 13, k + 17, Dungeons.midnightLeaves, 0);
        this.setBlock(world, i + 4, j + 13, k + 18, Dungeons.midnightLeaves, 0);
        this.setBlock(world, i + 4, j + 13, k + 19, Dungeons.midnightLeaves, 0);
        this.setBlock(world, i + 4, j + 14, k + 9, Dungeons.midnightLeaves, 0);
        this.setBlock(world, i + 4, j + 14, k + 10, Dungeons.midnightLeaves, 0);
        this.setBlock(world, i + 4, j + 14, k + 17, Dungeons.midnightLeaves, 0);
        this.setBlock(world, i + 4, j + 15, k + 10, Dungeons.midnightLeaves, 0);
        this.setBlock(world, i + 4, j + 15, k + 11, Dungeons.midnightLeaves, 0);
        this.setBlock(world, i + 4, j + 15, k + 12, Dungeons.midnightLeaves, 0);
        this.setBlock(world, i + 4, j + 15, k + 13, Dungeons.midnightLeaves, 0);
        this.setBlock(world, i + 4, j + 15, k + 14, Dungeons.midnightLeaves, 0);
        this.setBlock(world, i + 4, j + 15, k + 15, Dungeons.midnightLeaves, 0);
        this.setBlock(world, i + 4, j + 15, k + 16, Dungeons.midnightLeaves, 0);
        this.setBlock(world, i + 4, j + 16, k + 12, Dungeons.midnightLeaves, 0);
        this.setBlock(world, i + 4, j + 16, k + 13, Dungeons.midnightLeaves, 0);
        this.setBlock(world, i + 4, j + 16, k + 15, Dungeons.midnightLeaves, 0);
        this.setBlock(world, i + 4, j + 16, k + 16, Dungeons.midnightLeaves, 0);
        this.setBlock(world, i + 4, j + 17, k + 15, Dungeons.midnightLeaves, 0);
        this.setBlock(world, i + 4, j + 18, k + 15, Dungeons.midnightLeaves, 0);
        this.setBlock(world, i + 5, j + 4, k + 21, Dungeons.midnightLeaves, 0);
        this.setBlock(world, i + 5, j + 5, k + 21, Dungeons.midnightLeaves, 0);
        this.setBlock(world, i + 5, j + 6, k + 21, Dungeons.midnightLeaves, 0);
        this.setBlock(world, i + 5, j + 6, k + 22, Dungeons.midnightLeaves, 0);
        this.setBlock(world, i + 5, j + 6, k + 23, Dungeons.midnightLeaves, 0);
        this.setBlock(world, i + 5, j + 6, k + 24, Dungeons.midnightLeaves, 0);
        this.setBlock(world, i + 5, j + 7, k + 21, Dungeons.midnightLeaves, 0);
        this.setBlock(world, i + 5, j + 7, k + 22, Dungeons.midnightLeaves, 0);
        this.setBlock(world, i + 5, j + 7, k + 23, Dungeons.midnightLeaves, 0);
        this.setBlock(world, i + 5, j + 7, k + 24, Dungeons.midnightLeaves, 0);
        this.setBlock(world, i + 5, j + 8, k + 6, Dungeons.midnightLeaves, 0);
        this.setBlock(world, i + 5, j + 8, k + 21, Dungeons.midnightLeaves, 0);
        this.setBlock(world, i + 5, j + 8, k + 22, Dungeons.midnightLeaves, 0);
        this.setBlock(world, i + 5, j + 8, k + 23, Dungeons.midnightLeaves, 0);
        this.setBlock(world, i + 5, j + 8, k + 24, Dungeons.midnightLeaves, 0);
        this.setBlock(world, i + 5, j + 8, k + 25, Dungeons.midnightLeaves, 0);
        this.setBlock(world, i + 5, j + 9, k + 6, Dungeons.midnightLeaves, 0);
        this.setBlock(world, i + 5, j + 9, k + 21, Dungeons.midnightLeaves, 0);
        this.setBlock(world, i + 5, j + 9, k + 22, Dungeons.midnightLeaves, 0);
        this.setBlock(world, i + 5, j + 9, k + 23, Dungeons.midnightLeaves, 0);
        this.setBlock(world, i + 5, j + 9, k + 24, Dungeons.midnightLeaves, 0);
        this.setBlock(world, i + 5, j + 9, k + 25, Dungeons.midnightLeaves, 0);
        this.setBlock(world, i + 5, j + 9, k + 26, Dungeons.midnightLeaves, 0);
        this.setBlock(world, i + 5, j + 10, k + 6, Dungeons.midnightLeaves, 0);
        this.setBlock(world, i + 5, j + 10, k + 20, Dungeons.midnightLeaves, 0);
        this.setBlock(world, i + 5, j + 10, k + 21, Dungeons.midnightLeaves, 0);
        this.setBlock(world, i + 5, j + 10, k + 22, Dungeons.midnightLeaves, 0);
        this.setBlock(world, i + 5, j + 10, k + 23, Dungeons.midnightLeaves, 0);
        this.setBlock(world, i + 5, j + 10, k + 24, Dungeons.midnightLeaves, 0);
        this.setBlock(world, i + 5, j + 10, k + 25, Dungeons.midnightLeaves, 0);
        this.setBlock(world, i + 5, j + 10, k + 26, Dungeons.midnightLeaves, 0);
        this.setBlock(world, i + 5, j + 11, k + 7, Dungeons.midnightLeaves, 0);
        this.setBlock(world, i + 5, j + 11, k + 20, Dungeons.midnightLeaves, 0);
        this.setBlock(world, i + 5, j + 11, k + 21, Dungeons.midnightLeaves, 0);
        this.setBlock(world, i + 5, j + 11, k + 22, Dungeons.midnightLeaves, 0);
        this.setBlock(world, i + 5, j + 11, k + 23, Dungeons.midnightLeaves, 0);
        this.setBlock(world, i + 5, j + 11, k + 24, Dungeons.midnightLeaves, 0);
        this.setBlock(world, i + 5, j + 11, k + 25, Dungeons.midnightLeaves, 0);
        this.setBlock(world, i + 5, j + 11, k + 26, Dungeons.midnightLeaves, 0);
        this.setBlock(world, i + 5, j + 12, k + 7, Dungeons.midnightLeaves, 0);
        this.setBlock(world, i + 5, j + 12, k + 8, Dungeons.midnightLeaves, 0);
        this.setBlock(world, i + 5, j + 12, k + 13, Dungeons.midnightLeaves, 0);
        this.setBlock(world, i + 5, j + 12, k + 20, Dungeons.midnightLeaves, 0);
        this.setBlock(world, i + 5, j + 12, k + 21, Dungeons.midnightLeaves, 0);
        this.setBlock(world, i + 5, j + 12, k + 22, Dungeons.midnightLeaves, 0);
        this.setBlock(world, i + 5, j + 12, k + 23, Dungeons.midnightLeaves, 0);
        this.setBlock(world, i + 5, j + 12, k + 24, Dungeons.midnightLeaves, 0);
        this.setBlock(world, i + 5, j + 12, k + 25, Dungeons.midnightLeaves, 0);
        this.setBlock(world, i + 5, j + 12, k + 26, Dungeons.midnightLeaves, 0);
        this.setBlock(world, i + 5, j + 13, k + 8, Dungeons.midnightLeaves, 0);
        this.setBlock(world, i + 5, j + 13, k + 11, Dungeons.midnightLeaves, 0);
        this.setBlock(world, i + 5, j + 13, k + 12, Dungeons.midnightLeaves, 0);
        this.setBlock(world, i + 5, j + 13, k + 13, Dungeons.midnightLeaves, 0);
        this.setBlock(world, i + 5, j + 13, k + 18, Dungeons.midnightLeaves, 0);
        this.setBlock(world, i + 5, j + 13, k + 19, Dungeons.midnightLeaves, 0);
        this.setBlock(world, i + 5, j + 13, k + 20, Dungeons.midnightLeaves, 0);
        this.setBlock(world, i + 5, j + 13, k + 21, Dungeons.midnightLeaves, 0);
        this.setBlock(world, i + 5, j + 13, k + 22, Dungeons.midnightLeaves, 0);
        this.setBlock(world, i + 5, j + 13, k + 23, Dungeons.midnightLeaves, 0);
        this.setBlock(world, i + 5, j + 13, k + 24, Dungeons.midnightLeaves, 0);
        this.setBlock(world, i + 5, j + 13, k + 25, Dungeons.midnightLeaves, 0);
        this.setBlock(world, i + 5, j + 14, k + 9, Dungeons.midnightLeaves, 0);
        this.setBlock(world, i + 5, j + 14, k + 10, Dungeons.midnightLeaves, 0);
        this.setBlock(world, i + 5, j + 14, k + 11, Dungeons.midnightLeaves, 0);
        this.setBlock(world, i + 5, j + 14, k + 12, Dungeons.midnightLeaves, 0);
        this.setBlock(world, i + 5, j + 14, k + 13, Dungeons.midnightLeaves, 0);
        this.setBlock(world, i + 5, j + 14, k + 17, Dungeons.midnightLeaves, 0);
        this.setBlock(world, i + 5, j + 14, k + 18, Dungeons.midnightLeaves, 0);
        this.setBlock(world, i + 5, j + 14, k + 19, Dungeons.midnightLeaves, 0);
        this.setBlock(world, i + 5, j + 14, k + 21, Dungeons.midnightLeaves, 0);
        this.setBlock(world, i + 5, j + 14, k + 22, Dungeons.midnightLeaves, 0);
        this.setBlock(world, i + 5, j + 14, k + 23, Dungeons.midnightLeaves, 0);
        this.setBlock(world, i + 5, j + 14, k + 24, Dungeons.midnightLeaves, 0);
        this.setBlock(world, i + 5, j + 14, k + 25, Dungeons.midnightLeaves, 0);
        this.setBlock(world, i + 5, j + 15, k + 9, Dungeons.midnightLeaves, 0);
        this.setBlock(world, i + 5, j + 15, k + 10, Dungeons.midnightLeaves, 0);
        this.setBlock(world, i + 5, j + 15, k + 11, Dungeons.midnightLeaves, 0);
        this.setBlock(world, i + 5, j + 15, k + 12, Dungeons.midnightLeaves, 0);
        this.setBlock(world, i + 5, j + 15, k + 13, Dungeons.midnightLeaves, 0);
        this.setBlock(world, i + 5, j + 15, k + 16, Dungeons.midnightLeaves, 0);
        this.setBlock(world, i + 5, j + 15, k + 17, Dungeons.midnightLeaves, 0);
        this.setBlock(world, i + 5, j + 15, k + 18, Dungeons.midnightLeaves, 0);
        this.setBlock(world, i + 5, j + 15, k + 20, Dungeons.midnightLeaves, 0);
        this.setBlock(world, i + 5, j + 15, k + 22, Dungeons.midnightLeaves, 0);
        this.setBlock(world, i + 5, j + 15, k + 23, Dungeons.midnightLeaves, 0);
        this.setBlock(world, i + 5, j + 15, k + 24, Dungeons.midnightLeaves, 0);
        this.setBlock(world, i + 5, j + 15, k + 25, Dungeons.midnightLeaves, 0);
        this.setBlock(world, i + 5, j + 16, k + 11, Dungeons.midnightLeaves, 0);
        this.setBlock(world, i + 5, j + 16, k + 12, Dungeons.midnightLeaves, 0);
        this.setBlock(world, i + 5, j + 16, k + 13, Dungeons.midnightLeaves, 0);
        this.setBlock(world, i + 5, j + 16, k + 16, Dungeons.midnightLeaves, 0);
        this.setBlock(world, i + 5, j + 16, k + 18, Dungeons.midnightLeaves, 0);
        this.setBlock(world, i + 5, j + 16, k + 23, Dungeons.midnightLeaves, 0);
        this.setBlock(world, i + 5, j + 16, k + 24, Dungeons.midnightLeaves, 0);
        this.setBlock(world, i + 5, j + 17, k + 13, Dungeons.midnightLeaves, 0);
        this.setBlock(world, i + 5, j + 17, k + 14, Dungeons.midnightLeaves, 0);
        this.setBlock(world, i + 5, j + 17, k + 15, Dungeons.midnightLeaves, 0);
        this.setBlock(world, i + 5, j + 17, k + 16, Dungeons.midnightLeaves, 0);
        this.setBlock(world, i + 5, j + 17, k + 17, Dungeons.midnightLeaves, 0);
        this.setBlock(world, i + 5, j + 18, k + 14, Dungeons.midnightLeaves, 0);
        this.setBlock(world, i + 5, j + 18, k + 15, Dungeons.midnightLeaves, 0);
        this.setBlock(world, i + 6, j + 4, k + 6, Dungeons.midnightLeaves, 0);
        this.setBlock(world, i + 6, j + 5, k + 6, Dungeons.midnightLeaves, 0);
        this.setBlock(world, i + 6, j + 6, k + 6, Dungeons.midnightLeaves, 0);
        this.setBlock(world, i + 6, j + 7, k + 6, Dungeons.midnightLeaves, 0);
        this.setBlock(world, i + 6, j + 8, k + 6, Dungeons.midnightLeaves, 0);
        this.setBlock(world, i + 6, j + 9, k + 6, Dungeons.midnightLeaves, 0);
        this.setBlock(world, i + 6, j + 9, k + 28, Dungeons.midnightLeaves, 0);
        this.setBlock(world, i + 6, j + 10, k + 6, Dungeons.midnightLeaves, 0);
        this.setBlock(world, i + 6, j + 10, k + 28, Dungeons.midnightLeaves, 0);
        this.setBlock(world, i + 6, j + 11, k + 7, Dungeons.midnightLeaves, 0);
        this.setBlock(world, i + 6, j + 11, k + 27, Dungeons.midnightLeaves, 0);
        this.setBlock(world, i + 6, j + 11, k + 28, Dungeons.midnightLeaves, 0);
        this.setBlock(world, i + 6, j + 12, k + 7, Dungeons.midnightLeaves, 0);
        this.setBlock(world, i + 6, j + 12, k + 15, Dungeons.midnightLeaves, 0);
        this.setBlock(world, i + 6, j + 12, k + 20, Dungeons.midnightLeaves, 0);
        this.setBlock(world, i + 6, j + 12, k + 25, Dungeons.midnightLeaves, 0);
        this.setBlock(world, i + 6, j + 12, k + 26, Dungeons.midnightLeaves, 0);
        this.setBlock(world, i + 6, j + 12, k + 27, Dungeons.midnightLeaves, 0);
        this.setBlock(world, i + 6, j + 13, k + 8, Dungeons.midnightLeaves, 0);
        this.setBlock(world, i + 6, j + 13, k + 15, Dungeons.midnightLeaves, 0);
        this.setBlock(world, i + 6, j + 13, k + 20, Dungeons.midnightLeaves, 0);
        this.setBlock(world, i + 6, j + 13, k + 25, Dungeons.midnightLeaves, 0);
        this.setBlock(world, i + 6, j + 13, k + 26, Dungeons.midnightLeaves, 0);
        this.setBlock(world, i + 6, j + 14, k + 8, Dungeons.midnightLeaves, 0);
        this.setBlock(world, i + 6, j + 14, k + 11, Dungeons.midnightLeaves, 0);
        this.setBlock(world, i + 6, j + 14, k + 15, Dungeons.midnightLeaves, 0);
        this.setBlock(world, i + 6, j + 14, k + 19, Dungeons.midnightLeaves, 0);
        this.setBlock(world, i + 6, j + 14, k + 20, Dungeons.midnightLeaves, 0);
        this.setBlock(world, i + 6, j + 14, k + 22, Dungeons.midnightLeaves, 0);
        this.setBlock(world, i + 6, j + 14, k + 23, Dungeons.midnightLeaves, 0);
        this.setBlock(world, i + 6, j + 14, k + 25, Dungeons.midnightLeaves, 0);
        this.setBlock(world, i + 6, j + 14, k + 26, Dungeons.midnightLeaves, 0);
        this.setBlock(world, i + 6, j + 15, k + 9, Dungeons.midnightLeaves, 0);
        this.setBlock(world, i + 6, j + 15, k + 11, Dungeons.midnightLeaves, 0);
        this.setBlock(world, i + 6, j + 15, k + 13, Dungeons.midnightLeaves, 0);
        this.setBlock(world, i + 6, j + 15, k + 15, Dungeons.midnightLeaves, 0);
        this.setBlock(world, i + 6, j + 15, k + 17, Dungeons.midnightLeaves, 0);
        this.setBlock(world, i + 6, j + 15, k + 19, Dungeons.midnightLeaves, 0);
        this.setBlock(world, i + 6, j + 15, k + 20, Dungeons.midnightLeaves, 0);
        this.setBlock(world, i + 6, j + 15, k + 21, Dungeons.midnightLeaves, 0);
        this.setBlock(world, i + 6, j + 15, k + 22, Dungeons.midnightLeaves, 0);
        this.setBlock(world, i + 6, j + 15, k + 23, Dungeons.midnightLeaves, 0);
        this.setBlock(world, i + 6, j + 15, k + 25, Dungeons.midnightLeaves, 0);
        this.setBlock(world, i + 6, j + 15, k + 26, Dungeons.midnightLeaves, 0);
        this.setBlock(world, i + 6, j + 16, k + 9, Dungeons.midnightLeaves, 0);
        this.setBlock(world, i + 6, j + 16, k + 10, Dungeons.midnightLeaves, 0);
        this.setBlock(world, i + 6, j + 16, k + 11, Dungeons.midnightLeaves, 0);
        this.setBlock(world, i + 6, j + 16, k + 13, Dungeons.midnightLeaves, 0);
        this.setBlock(world, i + 6, j + 16, k + 15, Dungeons.midnightLeaves, 0);
        this.setBlock(world, i + 6, j + 16, k + 17, Dungeons.midnightLeaves, 0);
        this.setBlock(world, i + 6, j + 16, k + 18, Dungeons.midnightLeaves, 0);
        this.setBlock(world, i + 6, j + 16, k + 19, Dungeons.midnightLeaves, 0);
        this.setBlock(world, i + 6, j + 16, k + 20, Dungeons.midnightLeaves, 0);
        this.setBlock(world, i + 6, j + 16, k + 21, Dungeons.midnightLeaves, 0);
        this.setBlock(world, i + 6, j + 16, k + 22, Dungeons.midnightLeaves, 0);
        this.setBlock(world, i + 6, j + 16, k + 23, Dungeons.midnightLeaves, 0);
        this.setBlock(world, i + 6, j + 16, k + 24, Dungeons.midnightLeaves, 0);
        this.setBlock(world, i + 6, j + 16, k + 25, Dungeons.midnightLeaves, 0);
        this.setBlock(world, i + 6, j + 17, k + 9, Dungeons.midnightLeaves, 0);
        this.setBlock(world, i + 6, j + 17, k + 10, Dungeons.midnightLeaves, 0);
        this.setBlock(world, i + 6, j + 17, k + 11, Dungeons.midnightLeaves, 0);
        this.setBlock(world, i + 6, j + 17, k + 12, Dungeons.midnightLeaves, 0);
        this.setBlock(world, i + 6, j + 17, k + 13, Dungeons.midnightLeaves, 0);
        this.setBlock(world, i + 6, j + 17, k + 15, Dungeons.midnightLeaves, 0);
        this.setBlock(world, i + 6, j + 17, k + 16, Dungeons.midnightLeaves, 0);
        this.setBlock(world, i + 6, j + 17, k + 17, Dungeons.midnightLeaves, 0);
        this.setBlock(world, i + 6, j + 17, k + 21, Dungeons.midnightLeaves, 0);
        this.setBlock(world, i + 6, j + 17, k + 22, Dungeons.midnightLeaves, 0);
        this.setBlock(world, i + 6, j + 17, k + 23, Dungeons.midnightLeaves, 0);
        this.setBlock(world, i + 6, j + 17, k + 24, Dungeons.midnightLeaves, 0);
        this.setBlock(world, i + 6, j + 18, k + 11, Dungeons.midnightLeaves, 0);
        this.setBlock(world, i + 6, j + 18, k + 12, Dungeons.midnightLeaves, 0);
        this.setBlock(world, i + 6, j + 18, k + 13, Dungeons.midnightLeaves, 0);
        this.setBlock(world, i + 6, j + 18, k + 14, Dungeons.midnightLeaves, 0);
        this.setBlock(world, i + 6, j + 18, k + 15, Dungeons.midnightLeaves, 0);
        this.setBlock(world, i + 6, j + 18, k + 16, Dungeons.midnightLeaves, 0);
        this.setBlock(world, i + 6, j + 18, k + 17, Dungeons.midnightLeaves, 0);
        this.setBlock(world, i + 6, j + 18, k + 22, Dungeons.midnightLeaves, 0);
        this.setBlock(world, i + 6, j + 19, k + 15, Dungeons.midnightLeaves, 0);
        this.setBlock(world, i + 7, j + 8, k + 5, Dungeons.midnightLeaves, 0);
        this.setBlock(world, i + 7, j + 8, k + 28, Dungeons.midnightLeaves, 0);
        this.setBlock(world, i + 7, j + 9, k + 5, Dungeons.midnightLeaves, 0);
        this.setBlock(world, i + 7, j + 9, k + 28, Dungeons.midnightLeaves, 0);
        this.setBlock(world, i + 7, j + 10, k + 6, Dungeons.midnightLeaves, 0);
        this.setBlock(world, i + 7, j + 10, k + 28, Dungeons.midnightLeaves, 0);
        this.setBlock(world, i + 7, j + 11, k + 6, Dungeons.midnightLeaves, 0);
        this.setBlock(world, i + 7, j + 11, k + 24, Dungeons.midnightLeaves, 0);
        this.setBlock(world, i + 7, j + 11, k + 28, Dungeons.midnightLeaves, 0);
        this.setBlock(world, i + 7, j + 12, k + 6, Dungeons.midnightLeaves, 0);
        this.setBlock(world, i + 7, j + 12, k + 7, Dungeons.midnightLeaves, 0);
        this.setBlock(world, i + 7, j + 12, k + 8, Dungeons.midnightLeaves, 0);
        this.setBlock(world, i + 7, j + 12, k + 24, Dungeons.midnightLeaves, 0);
        this.setBlock(world, i + 7, j + 12, k + 28, Dungeons.midnightLeaves, 0);
        this.setBlock(world, i + 7, j + 13, k + 7, Dungeons.midnightLeaves, 0);
        this.setBlock(world, i + 7, j + 13, k + 8, Dungeons.midnightLeaves, 0);
        this.setBlock(world, i + 7, j + 13, k + 24, Dungeons.midnightLeaves, 0);
        this.setBlock(world, i + 7, j + 13, k + 27, Dungeons.midnightLeaves, 0);
        this.setBlock(world, i + 7, j + 13, k + 28, Dungeons.midnightLeaves, 0);
        this.setBlock(world, i + 7, j + 14, k + 8, Dungeons.midnightLeaves, 0);
        this.setBlock(world, i + 7, j + 14, k + 19, Dungeons.midnightLeaves, 0);
        this.setBlock(world, i + 7, j + 14, k + 24, Dungeons.midnightLeaves, 0);
        this.setBlock(world, i + 7, j + 14, k + 27, Dungeons.midnightLeaves, 0);
        this.setBlock(world, i + 7, j + 15, k + 9, Dungeons.midnightLeaves, 0);
        this.setBlock(world, i + 7, j + 15, k + 18, Dungeons.midnightLeaves, 0);
        this.setBlock(world, i + 7, j + 15, k + 19, Dungeons.midnightLeaves, 0);
        this.setBlock(world, i + 7, j + 15, k + 20, Dungeons.midnightLeaves, 0);
        this.setBlock(world, i + 7, j + 15, k + 21, Dungeons.midnightLeaves, 0);
        this.setBlock(world, i + 7, j + 15, k + 24, Dungeons.midnightLeaves, 0);
        this.setBlock(world, i + 7, j + 15, k + 26, Dungeons.midnightLeaves, 0);
        this.setBlock(world, i + 7, j + 16, k + 9, Dungeons.midnightLeaves, 0);
        this.setBlock(world, i + 7, j + 16, k + 18, Dungeons.midnightLeaves, 0);
        this.setBlock(world, i + 7, j + 16, k + 19, Dungeons.midnightLeaves, 0);
        this.setBlock(world, i + 7, j + 16, k + 20, Dungeons.midnightLeaves, 0);
        this.setBlock(world, i + 7, j + 16, k + 21, Dungeons.midnightLeaves, 0);
        this.setBlock(world, i + 7, j + 16, k + 24, Dungeons.midnightLeaves, 0);
        this.setBlock(world, i + 7, j + 16, k + 25, Dungeons.midnightLeaves, 0);
        this.setBlock(world, i + 7, j + 16, k + 26, Dungeons.midnightLeaves, 0);
        this.setBlock(world, i + 7, j + 17, k + 9, Dungeons.midnightLeaves, 0);
        this.setBlock(world, i + 7, j + 17, k + 10, Dungeons.midnightLeaves, 0);
        this.setBlock(world, i + 7, j + 17, k + 18, Dungeons.midnightLeaves, 0);
        this.setBlock(world, i + 7, j + 17, k + 19, Dungeons.midnightLeaves, 0);
        this.setBlock(world, i + 7, j + 17, k + 20, Dungeons.midnightLeaves, 0);
        this.setBlock(world, i + 7, j + 17, k + 21, Dungeons.midnightLeaves, 0);
        this.setBlock(world, i + 7, j + 17, k + 22, Dungeons.midnightLeaves, 0);
        this.setBlock(world, i + 7, j + 17, k + 23, Dungeons.midnightLeaves, 0);
        this.setBlock(world, i + 7, j + 17, k + 24, Dungeons.midnightLeaves, 0);
        this.setBlock(world, i + 7, j + 17, k + 25, Dungeons.midnightLeaves, 0);
        this.setBlock(world, i + 7, j + 18, k + 11, Dungeons.midnightLeaves, 0);
        this.setBlock(world, i + 7, j + 18, k + 12, Dungeons.midnightLeaves, 0);
        this.setBlock(world, i + 7, j + 18, k + 13, Dungeons.midnightLeaves, 0);
        this.setBlock(world, i + 7, j + 18, k + 14, Dungeons.midnightLeaves, 0);
        this.setBlock(world, i + 7, j + 18, k + 16, Dungeons.midnightLeaves, 0);
        this.setBlock(world, i + 7, j + 18, k + 17, Dungeons.midnightLeaves, 0);
        this.setBlock(world, i + 7, j + 18, k + 20, Dungeons.midnightLeaves, 0);
        this.setBlock(world, i + 7, j + 18, k + 21, Dungeons.midnightLeaves, 0);
        this.setBlock(world, i + 7, j + 18, k + 22, Dungeons.midnightLeaves, 0);
        this.setBlock(world, i + 7, j + 18, k + 23, Dungeons.midnightLeaves, 0);
        this.setBlock(world, i + 7, j + 19, k + 15, Dungeons.midnightLeaves, 0);
        this.setBlock(world, i + 7, j + 19, k + 16, Dungeons.midnightLeaves, 0);
        this.setBlock(world, i + 7, j + 19, k + 17, Dungeons.midnightLeaves, 0);
        this.setBlock(world, i + 8, j + 6, k + 4, Dungeons.midnightLeaves, 0);
        this.setBlock(world, i + 8, j + 7, k + 4, Dungeons.midnightLeaves, 0);
        this.setBlock(world, i + 8, j + 7, k + 5, Dungeons.midnightLeaves, 0);
        this.setBlock(world, i + 8, j + 8, k + 5, Dungeons.midnightLeaves, 0);
        this.setBlock(world, i + 8, j + 9, k + 5, Dungeons.midnightLeaves, 0);
        this.setBlock(world, i + 8, j + 9, k + 6, Dungeons.midnightLeaves, 0);
        this.setBlock(world, i + 8, j + 9, k + 29, Dungeons.midnightLeaves, 0);
        this.setBlock(world, i + 8, j + 10, k + 6, Dungeons.midnightLeaves, 0);
        this.setBlock(world, i + 8, j + 10, k + 29, Dungeons.midnightLeaves, 0);
        this.setBlock(world, i + 8, j + 11, k + 6, Dungeons.midnightLeaves, 0);
        this.setBlock(world, i + 8, j + 11, k + 7, Dungeons.midnightLeaves, 0);
        this.setBlock(world, i + 8, j + 11, k + 28, Dungeons.midnightLeaves, 0);
        this.setBlock(world, i + 8, j + 11, k + 29, Dungeons.midnightLeaves, 0);
        this.setBlock(world, i + 8, j + 12, k + 6, Dungeons.midnightLeaves, 0);
        this.setBlock(world, i + 8, j + 12, k + 7, Dungeons.midnightLeaves, 0);
        this.setBlock(world, i + 8, j + 12, k + 28, Dungeons.midnightLeaves, 0);
        this.setBlock(world, i + 8, j + 12, k + 29, Dungeons.midnightLeaves, 0);
        this.setBlock(world, i + 8, j + 13, k + 7, Dungeons.midnightLeaves, 0);
        this.setBlock(world, i + 8, j + 13, k + 12, Dungeons.midnightLeaves, 0);
        this.setBlock(world, i + 8, j + 13, k + 27, Dungeons.midnightLeaves, 0);
        this.setBlock(world, i + 8, j + 13, k + 28, Dungeons.midnightLeaves, 0);
        this.setBlock(world, i + 8, j + 13, k + 29, Dungeons.midnightLeaves, 0);
        this.setBlock(world, i + 8, j + 14, k + 7, Dungeons.midnightLeaves, 0);
        this.setBlock(world, i + 8, j + 14, k + 8, Dungeons.midnightLeaves, 0);
        this.setBlock(world, i + 8, j + 14, k + 9, Dungeons.midnightLeaves, 0);
        this.setBlock(world, i + 8, j + 14, k + 12, Dungeons.midnightLeaves, 0);
        this.setBlock(world, i + 8, j + 14, k + 27, Dungeons.midnightLeaves, 0);
        this.setBlock(world, i + 8, j + 14, k + 28, Dungeons.midnightLeaves, 0);
        this.setBlock(world, i + 8, j + 15, k + 8, Dungeons.midnightLeaves, 0);
        this.setBlock(world, i + 8, j + 15, k + 9, Dungeons.midnightLeaves, 0);
        this.setBlock(world, i + 8, j + 15, k + 12, Dungeons.midnightLeaves, 0);
        this.setBlock(world, i + 8, j + 15, k + 25, Dungeons.midnightLeaves, 0);
        this.setBlock(world, i + 8, j + 15, k + 26, Dungeons.midnightLeaves, 0);
        this.setBlock(world, i + 8, j + 15, k + 27, Dungeons.midnightLeaves, 0);
        this.setBlock(world, i + 8, j + 16, k + 8, Dungeons.midnightLeaves, 0);
        this.setBlock(world, i + 8, j + 16, k + 9, Dungeons.midnightLeaves, 0);
        this.setBlock(world, i + 8, j + 16, k + 12, Dungeons.midnightLeaves, 0);
        this.setBlock(world, i + 8, j + 16, k + 24, Dungeons.midnightLeaves, 0);
        this.setBlock(world, i + 8, j + 16, k + 25, Dungeons.midnightLeaves, 0);
        this.setBlock(world, i + 8, j + 16, k + 26, Dungeons.midnightLeaves, 0);
        this.setBlock(world, i + 8, j + 16, k + 27, Dungeons.midnightLeaves, 0);
        this.setBlock(world, i + 8, j + 17, k + 9, Dungeons.midnightLeaves, 0);
        this.setBlock(world, i + 8, j + 17, k + 10, Dungeons.midnightLeaves, 0);
        this.setBlock(world, i + 8, j + 17, k + 12, Dungeons.midnightLeaves, 0);
        this.setBlock(world, i + 8, j + 17, k + 13, Dungeons.midnightLeaves, 0);
        this.setBlock(world, i + 8, j + 17, k + 18, Dungeons.midnightLeaves, 0);
        this.setBlock(world, i + 8, j + 17, k + 19, Dungeons.midnightLeaves, 0);
        this.setBlock(world, i + 8, j + 17, k + 23, Dungeons.midnightLeaves, 0);
        this.setBlock(world, i + 8, j + 17, k + 24, Dungeons.midnightLeaves, 0);
        this.setBlock(world, i + 8, j + 17, k + 25, Dungeons.midnightLeaves, 0);
        this.setBlock(world, i + 8, j + 18, k + 11, Dungeons.midnightLeaves, 0);
        this.setBlock(world, i + 8, j + 18, k + 12, Dungeons.midnightLeaves, 0);
        this.setBlock(world, i + 8, j + 18, k + 13, Dungeons.midnightLeaves, 0);
        this.setBlock(world, i + 8, j + 18, k + 14, Dungeons.midnightLeaves, 0);
        this.setBlock(world, i + 8, j + 18, k + 15, Dungeons.midnightLeaves, 0);
        this.setBlock(world, i + 8, j + 18, k + 16, Dungeons.midnightLeaves, 0);
        this.setBlock(world, i + 8, j + 18, k + 18, Dungeons.midnightLeaves, 0);
        this.setBlock(world, i + 8, j + 18, k + 20, Dungeons.midnightLeaves, 0);
        this.setBlock(world, i + 8, j + 18, k + 21, Dungeons.midnightLeaves, 0);
        this.setBlock(world, i + 8, j + 18, k + 22, Dungeons.midnightLeaves, 0);
        this.setBlock(world, i + 8, j + 18, k + 23, Dungeons.midnightLeaves, 0);
        this.setBlock(world, i + 8, j + 18, k + 24, Dungeons.midnightLeaves, 0);
        this.setBlock(world, i + 8, j + 19, k + 15, Dungeons.midnightLeaves, 0);
        this.setBlock(world, i + 8, j + 19, k + 16, Dungeons.midnightLeaves, 0);
        this.setBlock(world, i + 8, j + 19, k + 17, Dungeons.midnightLeaves, 0);
        this.setBlock(world, i + 9, j + 3, k + 4, Dungeons.midnightLeaves, 0);
        this.setBlock(world, i + 9, j + 4, k + 4, Dungeons.midnightLeaves, 0);
        this.setBlock(world, i + 9, j + 5, k + 4, Dungeons.midnightLeaves, 0);
        this.setBlock(world, i + 9, j + 6, k + 4, Dungeons.midnightLeaves, 0);
        this.setBlock(world, i + 9, j + 7, k + 4, Dungeons.midnightLeaves, 0);
        this.setBlock(world, i + 9, j + 7, k + 29, Dungeons.midnightLeaves, 0);
        this.setBlock(world, i + 9, j + 8, k + 4, Dungeons.midnightLeaves, 0);
        this.setBlock(world, i + 9, j + 8, k + 5, Dungeons.midnightLeaves, 0);
        this.setBlock(world, i + 9, j + 9, k + 4, Dungeons.midnightLeaves, 0);
        this.setBlock(world, i + 9, j + 9, k + 5, Dungeons.midnightLeaves, 0);
        this.setBlock(world, i + 9, j + 10, k + 5, Dungeons.midnightLeaves, 0);
        this.setBlock(world, i + 9, j + 10, k + 29, Dungeons.midnightLeaves, 0);
        this.setBlock(world, i + 9, j + 11, k + 5, Dungeons.midnightLeaves, 0);
        this.setBlock(world, i + 9, j + 11, k + 6, Dungeons.midnightLeaves, 0);
        this.setBlock(world, i + 9, j + 11, k + 29, Dungeons.midnightLeaves, 0);
        this.setBlock(world, i + 9, j + 12, k + 6, Dungeons.midnightLeaves, 0);
        this.setBlock(world, i + 9, j + 12, k + 25, Dungeons.midnightLeaves, 0);
        this.setBlock(world, i + 9, j + 12, k + 29, Dungeons.midnightLeaves, 0);
        this.setBlock(world, i + 9, j + 13, k + 6, Dungeons.midnightLeaves, 0);
        this.setBlock(world, i + 9, j + 13, k + 7, Dungeons.midnightLeaves, 0);
        this.setBlock(world, i + 9, j + 13, k + 15, Dungeons.midnightLeaves, 0);
        this.setBlock(world, i + 9, j + 13, k + 25, Dungeons.midnightLeaves, 0);
        this.setBlock(world, i + 9, j + 13, k + 27, Dungeons.midnightLeaves, 0);
        this.setBlock(world, i + 9, j + 13, k + 28, Dungeons.midnightLeaves, 0);
        this.setBlock(world, i + 9, j + 13, k + 29, Dungeons.midnightLeaves, 0);
        this.setBlock(world, i + 9, j + 14, k + 7, Dungeons.midnightLeaves, 0);
        this.setBlock(world, i + 9, j + 14, k + 9, Dungeons.midnightLeaves, 0);
        this.setBlock(world, i + 9, j + 14, k + 15, Dungeons.midnightLeaves, 0);
        this.setBlock(world, i + 9, j + 14, k + 19, Dungeons.midnightLeaves, 0);
        this.setBlock(world, i + 9, j + 14, k + 22, Dungeons.midnightLeaves, 0);
        this.setBlock(world, i + 9, j + 14, k + 25, Dungeons.midnightLeaves, 0);
        this.setBlock(world, i + 9, j + 14, k + 27, Dungeons.midnightLeaves, 0);
        this.setBlock(world, i + 9, j + 15, k + 8, Dungeons.midnightLeaves, 0);
        this.setBlock(world, i + 9, j + 15, k + 9, Dungeons.midnightLeaves, 0);
        this.setBlock(world, i + 9, j + 15, k + 15, Dungeons.midnightLeaves, 0);
        this.setBlock(world, i + 9, j + 15, k + 19, Dungeons.midnightLeaves, 0);
        this.setBlock(world, i + 9, j + 15, k + 22, Dungeons.midnightLeaves, 0);
        this.setBlock(world, i + 9, j + 15, k + 25, Dungeons.midnightLeaves, 0);
        this.setBlock(world, i + 9, j + 15, k + 26, Dungeons.midnightLeaves, 0);
        this.setBlock(world, i + 9, j + 15, k + 27, Dungeons.midnightLeaves, 0);
        this.setBlock(world, i + 9, j + 16, k + 8, Dungeons.midnightLeaves, 0);
        this.setBlock(world, i + 9, j + 16, k + 9, Dungeons.midnightLeaves, 0);
        this.setBlock(world, i + 9, j + 16, k + 10, Dungeons.midnightLeaves, 0);
        this.setBlock(world, i + 9, j + 16, k + 15, Dungeons.midnightLeaves, 0);
        this.setBlock(world, i + 9, j + 16, k + 19, Dungeons.midnightLeaves, 0);
        this.setBlock(world, i + 9, j + 16, k + 22, Dungeons.midnightLeaves, 0);
        this.setBlock(world, i + 9, j + 16, k + 25, Dungeons.midnightLeaves, 0);
        this.setBlock(world, i + 9, j + 16, k + 26, Dungeons.midnightLeaves, 0);
        this.setBlock(world, i + 9, j + 17, k + 9, Dungeons.midnightLeaves, 0);
        this.setBlock(world, i + 9, j + 17, k + 10, Dungeons.midnightLeaves, 0);
        this.setBlock(world, i + 9, j + 17, k + 11, Dungeons.midnightLeaves, 0);
        this.setBlock(world, i + 9, j + 17, k + 12, Dungeons.midnightLeaves, 0);
        this.setBlock(world, i + 9, j + 17, k + 13, Dungeons.midnightLeaves, 0);
        this.setBlock(world, i + 9, j + 17, k + 15, Dungeons.midnightLeaves, 0);
        this.setBlock(world, i + 9, j + 17, k + 18, Dungeons.midnightLeaves, 0);
        this.setBlock(world, i + 9, j + 17, k + 19, Dungeons.midnightLeaves, 0);
        this.setBlock(world, i + 9, j + 17, k + 25, Dungeons.midnightLeaves, 0);
        this.setBlock(world, i + 9, j + 18, k + 13, Dungeons.midnightLeaves, 0);
        this.setBlock(world, i + 9, j + 18, k + 14, Dungeons.midnightLeaves, 0);
        this.setBlock(world, i + 9, j + 18, k + 15, Dungeons.midnightLeaves, 0);
        this.setBlock(world, i + 9, j + 18, k + 16, Dungeons.midnightLeaves, 0);
        this.setBlock(world, i + 9, j + 18, k + 17, Dungeons.midnightLeaves, 0);
        this.setBlock(world, i + 9, j + 18, k + 20, Dungeons.midnightLeaves, 0);
        this.setBlock(world, i + 9, j + 18, k + 21, Dungeons.midnightLeaves, 0);
        this.setBlock(world, i + 9, j + 18, k + 22, Dungeons.midnightLeaves, 0);
        this.setBlock(world, i + 9, j + 18, k + 23, Dungeons.midnightLeaves, 0);
        this.setBlock(world, i + 9, j + 18, k + 24, Dungeons.midnightLeaves, 0);
        this.setBlock(world, i + 9, j + 19, k + 15, Dungeons.midnightLeaves, 0);
        this.setBlock(world, i + 10, j + 7, k + 3, Dungeons.midnightLeaves, 0);
        this.setBlock(world, i + 10, j + 7, k + 29, Dungeons.midnightLeaves, 0);
        this.setBlock(world, i + 10, j + 8, k + 3, Dungeons.midnightLeaves, 0);
        this.setBlock(world, i + 10, j + 8, k + 29, Dungeons.midnightLeaves, 0);
        this.setBlock(world, i + 10, j + 9, k + 3, Dungeons.midnightLeaves, 0);
        this.setBlock(world, i + 10, j + 9, k + 4, Dungeons.midnightLeaves, 0);
        this.setBlock(world, i + 10, j + 9, k + 29, Dungeons.midnightLeaves, 0);
        this.setBlock(world, i + 10, j + 10, k + 4, Dungeons.midnightLeaves, 0);
        this.setBlock(world, i + 10, j + 10, k + 29, Dungeons.midnightLeaves, 0);
        this.setBlock(world, i + 10, j + 11, k + 5, Dungeons.midnightLeaves, 0);
        this.setBlock(world, i + 10, j + 11, k + 10, Dungeons.midnightLeaves, 0);
        this.setBlock(world, i + 10, j + 11, k + 29, Dungeons.midnightLeaves, 0);
        this.setBlock(world, i + 10, j + 12, k + 5, Dungeons.midnightLeaves, 0);
        this.setBlock(world, i + 10, j + 12, k + 10, Dungeons.midnightLeaves, 0);
        this.setBlock(world, i + 10, j + 12, k + 28, Dungeons.midnightLeaves, 0);
        this.setBlock(world, i + 10, j + 13, k + 5, Dungeons.midnightLeaves, 0);
        this.setBlock(world, i + 10, j + 13, k + 6, Dungeons.midnightLeaves, 0);
        this.setBlock(world, i + 10, j + 13, k + 10, Dungeons.midnightLeaves, 0);
        this.setBlock(world, i + 10, j + 13, k + 28, Dungeons.midnightLeaves, 0);
        this.setBlock(world, i + 10, j + 13, k + 29, Dungeons.midnightLeaves, 0);
        this.setBlock(world, i + 10, j + 14, k + 6, Dungeons.midnightLeaves, 0);
        this.setBlock(world, i + 10, j + 14, k + 7, Dungeons.midnightLeaves, 0);
        this.setBlock(world, i + 10, j + 14, k + 9, Dungeons.midnightLeaves, 0);
        this.setBlock(world, i + 10, j + 14, k + 10, Dungeons.midnightLeaves, 0);
        this.setBlock(world, i + 10, j + 14, k + 16, Dungeons.midnightLeaves, 0);
        this.setBlock(world, i + 10, j + 14, k + 18, Dungeons.midnightLeaves, 0);
        this.setBlock(world, i + 10, j + 14, k + 26, Dungeons.midnightLeaves, 0);
        this.setBlock(world, i + 10, j + 14, k + 27, Dungeons.midnightLeaves, 0);
        this.setBlock(world, i + 10, j + 14, k + 28, Dungeons.midnightLeaves, 0);
        this.setBlock(world, i + 10, j + 15, k + 6, Dungeons.midnightLeaves, 0);
        this.setBlock(world, i + 10, j + 15, k + 7, Dungeons.midnightLeaves, 0);
        this.setBlock(world, i + 10, j + 15, k + 8, Dungeons.midnightLeaves, 0);
        this.setBlock(world, i + 10, j + 15, k + 9, Dungeons.midnightLeaves, 0);
        this.setBlock(world, i + 10, j + 15, k + 10, Dungeons.midnightLeaves, 0);
        this.setBlock(world, i + 10, j + 15, k + 16, Dungeons.midnightLeaves, 0);
        this.setBlock(world, i + 10, j + 15, k + 18, Dungeons.midnightLeaves, 0);
        this.setBlock(world, i + 10, j + 15, k + 22, Dungeons.midnightLeaves, 0);
        this.setBlock(world, i + 10, j + 15, k + 26, Dungeons.midnightLeaves, 0);
        this.setBlock(world, i + 10, j + 15, k + 27, Dungeons.midnightLeaves, 0);
        this.setBlock(world, i + 10, j + 15, k + 28, Dungeons.midnightLeaves, 0);
        this.setBlock(world, i + 10, j + 16, k + 7, Dungeons.midnightLeaves, 0);
        this.setBlock(world, i + 10, j + 16, k + 8, Dungeons.midnightLeaves, 0);
        this.setBlock(world, i + 10, j + 16, k + 9, Dungeons.midnightLeaves, 0);
        this.setBlock(world, i + 10, j + 16, k + 10, Dungeons.midnightLeaves, 0);
        this.setBlock(world, i + 10, j + 16, k + 13, Dungeons.midnightLeaves, 0);
        this.setBlock(world, i + 10, j + 16, k + 16, Dungeons.midnightLeaves, 0);
        this.setBlock(world, i + 10, j + 16, k + 18, Dungeons.midnightLeaves, 0);
        this.setBlock(world, i + 10, j + 16, k + 22, Dungeons.midnightLeaves, 0);
        this.setBlock(world, i + 10, j + 16, k + 26, Dungeons.midnightLeaves, 0);
        this.setBlock(world, i + 10, j + 17, k + 9, Dungeons.midnightLeaves, 0);
        this.setBlock(world, i + 10, j + 17, k + 10, Dungeons.midnightLeaves, 0);
        this.setBlock(world, i + 10, j + 17, k + 11, Dungeons.midnightLeaves, 0);
        this.setBlock(world, i + 10, j + 17, k + 12, Dungeons.midnightLeaves, 0);
        this.setBlock(world, i + 10, j + 17, k + 13, Dungeons.midnightLeaves, 0);
        this.setBlock(world, i + 10, j + 17, k + 14, Dungeons.midnightLeaves, 0);
        this.setBlock(world, i + 10, j + 17, k + 15, Dungeons.midnightLeaves, 0);
        this.setBlock(world, i + 10, j + 17, k + 16, Dungeons.midnightLeaves, 0);
        this.setBlock(world, i + 10, j + 17, k + 17, Dungeons.midnightLeaves, 0);
        this.setBlock(world, i + 10, j + 17, k + 18, Dungeons.midnightLeaves, 0);
        this.setBlock(world, i + 10, j + 17, k + 19, Dungeons.midnightLeaves, 0);
        this.setBlock(world, i + 10, j + 17, k + 20, Dungeons.midnightLeaves, 0);
        this.setBlock(world, i + 10, j + 17, k + 22, Dungeons.midnightLeaves, 0);
        this.setBlock(world, i + 10, j + 17, k + 23, Dungeons.midnightLeaves, 0);
        this.setBlock(world, i + 10, j + 17, k + 24, Dungeons.midnightLeaves, 0);
        this.setBlock(world, i + 10, j + 17, k + 25, Dungeons.midnightLeaves, 0);
        this.setBlock(world, i + 10, j + 17, k + 26, Dungeons.midnightLeaves, 0);
        this.setBlock(world, i + 10, j + 18, k + 15, Dungeons.midnightLeaves, 0);
        this.setBlock(world, i + 10, j + 18, k + 16, Dungeons.midnightLeaves, 0);
        this.setBlock(world, i + 10, j + 18, k + 17, Dungeons.midnightLeaves, 0);
        this.setBlock(world, i + 10, j + 18, k + 20, Dungeons.midnightLeaves, 0);
        this.setBlock(world, i + 10, j + 18, k + 21, Dungeons.midnightLeaves, 0);
        this.setBlock(world, i + 10, j + 18, k + 22, Dungeons.midnightLeaves, 0);
        this.setBlock(world, i + 10, j + 18, k + 23, Dungeons.midnightLeaves, 0);
        this.setBlock(world, i + 10, j + 19, k + 15, Dungeons.midnightLeaves, 0);
        this.setBlock(world, i + 11, j + 6, k + 2, Dungeons.midnightLeaves, 0);
        this.setBlock(world, i + 11, j + 7, k + 2, Dungeons.midnightLeaves, 0);
        this.setBlock(world, i + 11, j + 7, k + 29, Dungeons.midnightLeaves, 0);
        this.setBlock(world, i + 11, j + 8, k + 2, Dungeons.midnightLeaves, 0);
        this.setBlock(world, i + 11, j + 8, k + 3, Dungeons.midnightLeaves, 0);
        this.setBlock(world, i + 11, j + 8, k + 29, Dungeons.midnightLeaves, 0);
        this.setBlock(world, i + 11, j + 9, k + 3, Dungeons.midnightLeaves, 0);
        this.setBlock(world, i + 11, j + 9, k + 4, Dungeons.midnightLeaves, 0);
        this.setBlock(world, i + 11, j + 9, k + 29, Dungeons.midnightLeaves, 0);
        this.setBlock(world, i + 11, j + 10, k + 4, Dungeons.midnightLeaves, 0);
        this.setBlock(world, i + 11, j + 10, k + 29, Dungeons.midnightLeaves, 0);
        this.setBlock(world, i + 11, j + 11, k + 4, Dungeons.midnightLeaves, 0);
        this.setBlock(world, i + 11, j + 11, k + 13, Dungeons.midnightLeaves, 0);
        this.setBlock(world, i + 11, j + 11, k + 22, Dungeons.midnightLeaves, 0);
        this.setBlock(world, i + 11, j + 11, k + 28, Dungeons.midnightLeaves, 0);
        this.setBlock(world, i + 11, j + 11, k + 29, Dungeons.midnightLeaves, 0);
        this.setBlock(world, i + 11, j + 12, k + 5, Dungeons.midnightLeaves, 0);
        this.setBlock(world, i + 11, j + 12, k + 13, Dungeons.midnightLeaves, 0);
        this.setBlock(world, i + 11, j + 12, k + 21, Dungeons.midnightLeaves, 0);
        this.setBlock(world, i + 11, j + 12, k + 22, Dungeons.midnightLeaves, 0);
        this.setBlock(world, i + 11, j + 12, k + 28, Dungeons.midnightLeaves, 0);
        this.setBlock(world, i + 11, j + 12, k + 29, Dungeons.midnightLeaves, 0);
        this.setBlock(world, i + 11, j + 13, k + 4, Dungeons.midnightLeaves, 0);
        this.setBlock(world, i + 11, j + 13, k + 5, Dungeons.midnightLeaves, 0);
        this.setBlock(world, i + 11, j + 13, k + 13, Dungeons.midnightLeaves, 0);
        this.setBlock(world, i + 11, j + 13, k + 15, Dungeons.midnightLeaves, 0);
        this.setBlock(world, i + 11, j + 13, k + 17, Dungeons.midnightLeaves, 0);
        this.setBlock(world, i + 11, j + 13, k + 21, Dungeons.midnightLeaves, 0);
        this.setBlock(world, i + 11, j + 13, k + 22, Dungeons.midnightLeaves, 0);
        this.setBlock(world, i + 11, j + 13, k + 27, Dungeons.midnightLeaves, 0);
        this.setBlock(world, i + 11, j + 13, k + 28, Dungeons.midnightLeaves, 0);
        this.setBlock(world, i + 11, j + 13, k + 29, Dungeons.midnightLeaves, 0);
        this.setBlock(world, i + 11, j + 14, k + 5, Dungeons.midnightLeaves, 0);
        this.setBlock(world, i + 11, j + 14, k + 6, Dungeons.midnightLeaves, 0);
        this.setBlock(world, i + 11, j + 14, k + 13, Dungeons.midnightLeaves, 0);
        this.setBlock(world, i + 11, j + 14, k + 15, Dungeons.midnightLeaves, 0);
        this.setBlock(world, i + 11, j + 14, k + 17, Dungeons.midnightLeaves, 0);
        this.setBlock(world, i + 11, j + 14, k + 21, Dungeons.midnightLeaves, 0);
        this.setBlock(world, i + 11, j + 14, k + 22, Dungeons.midnightLeaves, 0);
        this.setBlock(world, i + 11, j + 14, k + 27, Dungeons.midnightLeaves, 0);
        this.setBlock(world, i + 11, j + 14, k + 28, Dungeons.midnightLeaves, 0);
        this.setBlock(world, i + 11, j + 14, k + 29, Dungeons.midnightLeaves, 0);
        this.setBlock(world, i + 11, j + 15, k + 6, Dungeons.midnightLeaves, 0);
        this.setBlock(world, i + 11, j + 15, k + 8, Dungeons.midnightLeaves, 0);
        this.setBlock(world, i + 11, j + 15, k + 9, Dungeons.midnightLeaves, 0);
        this.setBlock(world, i + 11, j + 15, k + 13, Dungeons.midnightLeaves, 0);
        this.setBlock(world, i + 11, j + 15, k + 14, Dungeons.midnightLeaves, 0);
        this.setBlock(world, i + 11, j + 15, k + 15, Dungeons.midnightLeaves, 0);
        this.setBlock(world, i + 11, j + 15, k + 17, Dungeons.midnightLeaves, 0);
        this.setBlock(world, i + 11, j + 15, k + 18, Dungeons.midnightLeaves, 0);
        this.setBlock(world, i + 11, j + 15, k + 21, Dungeons.midnightLeaves, 0);
        this.setBlock(world, i + 11, j + 15, k + 22, Dungeons.midnightLeaves, 0);
        this.setBlock(world, i + 11, j + 15, k + 26, Dungeons.midnightLeaves, 0);
        this.setBlock(world, i + 11, j + 15, k + 27, Dungeons.midnightLeaves, 0);
        this.setBlock(world, i + 11, j + 15, k + 28, Dungeons.midnightLeaves, 0);
        this.setBlock(world, i + 11, j + 16, k + 6, Dungeons.midnightLeaves, 0);
        this.setBlock(world, i + 11, j + 16, k + 8, Dungeons.midnightLeaves, 0);
        this.setBlock(world, i + 11, j + 16, k + 9, Dungeons.midnightLeaves, 0);
        this.setBlock(world, i + 11, j + 16, k + 10, Dungeons.midnightLeaves, 0);
        this.setBlock(world, i + 11, j + 16, k + 11, Dungeons.midnightLeaves, 0);
        this.setBlock(world, i + 11, j + 16, k + 12, Dungeons.midnightLeaves, 0);
        this.setBlock(world, i + 11, j + 16, k + 13, Dungeons.midnightLeaves, 0);
        this.setBlock(world, i + 11, j + 16, k + 14, Dungeons.midnightLeaves, 0);
        this.setBlock(world, i + 11, j + 16, k + 15, Dungeons.midnightLeaves, 0);
        this.setBlock(world, i + 11, j + 16, k + 16, Dungeons.midnightLeaves, 0);
        this.setBlock(world, i + 11, j + 16, k + 17, Dungeons.midnightLeaves, 0);
        this.setBlock(world, i + 11, j + 16, k + 18, Dungeons.midnightLeaves, 0);
        this.setBlock(world, i + 11, j + 16, k + 21, Dungeons.midnightLeaves, 0);
        this.setBlock(world, i + 11, j + 16, k + 22, Dungeons.midnightLeaves, 0);
        this.setBlock(world, i + 11, j + 16, k + 25, Dungeons.midnightLeaves, 0);
        this.setBlock(world, i + 11, j + 16, k + 26, Dungeons.midnightLeaves, 0);
        this.setBlock(world, i + 11, j + 17, k + 7, Dungeons.midnightLeaves, 0);
        this.setBlock(world, i + 11, j + 17, k + 8, Dungeons.midnightLeaves, 0);
        this.setBlock(world, i + 11, j + 17, k + 9, Dungeons.midnightLeaves, 0);
        this.setBlock(world, i + 11, j + 17, k + 13, Dungeons.midnightLeaves, 0);
        this.setBlock(world, i + 11, j + 17, k + 15, Dungeons.midnightLeaves, 0);
        this.setBlock(world, i + 11, j + 17, k + 16, Dungeons.midnightLeaves, 0);
        this.setBlock(world, i + 11, j + 17, k + 17, Dungeons.midnightLeaves, 0);
        this.setBlock(world, i + 11, j + 17, k + 18, Dungeons.midnightLeaves, 0);
        this.setBlock(world, i + 11, j + 17, k + 19, Dungeons.midnightLeaves, 0);
        this.setBlock(world, i + 11, j + 17, k + 21, Dungeons.midnightLeaves, 0);
        this.setBlock(world, i + 11, j + 17, k + 22, Dungeons.midnightLeaves, 0);
        this.setBlock(world, i + 11, j + 17, k + 23, Dungeons.midnightLeaves, 0);
        this.setBlock(world, i + 11, j + 17, k + 24, Dungeons.midnightLeaves, 0);
        this.setBlock(world, i + 11, j + 17, k + 25, Dungeons.midnightLeaves, 0);
        this.setBlock(world, i + 11, j + 17, k + 26, Dungeons.midnightLeaves, 0);
        this.setBlock(world, i + 11, j + 18, k + 15, Dungeons.midnightLeaves, 0);
        this.setBlock(world, i + 11, j + 18, k + 20, Dungeons.midnightLeaves, 0);
        this.setBlock(world, i + 11, j + 18, k + 21, Dungeons.midnightLeaves, 0);
        this.setBlock(world, i + 11, j + 18, k + 22, Dungeons.midnightLeaves, 0);
        this.setBlock(world, i + 11, j + 18, k + 23, Dungeons.midnightLeaves, 0);
        this.setBlock(world, i + 12, j + 6, k + 2, Dungeons.midnightLeaves, 0);
        this.setBlock(world, i + 12, j + 6, k + 29, Dungeons.midnightLeaves, 0);
        this.setBlock(world, i + 12, j + 7, k + 2, Dungeons.midnightLeaves, 0);
        this.setBlock(world, i + 12, j + 7, k + 29, Dungeons.midnightLeaves, 0);
        this.setBlock(world, i + 12, j + 8, k + 2, Dungeons.midnightLeaves, 0);
        this.setBlock(world, i + 12, j + 8, k + 3, Dungeons.midnightLeaves, 0);
        this.setBlock(world, i + 12, j + 8, k + 29, Dungeons.midnightLeaves, 0);
        this.setBlock(world, i + 12, j + 9, k + 2, Dungeons.midnightLeaves, 0);
        this.setBlock(world, i + 12, j + 9, k + 3, Dungeons.midnightLeaves, 0);
        this.setBlock(world, i + 12, j + 9, k + 17, Dungeons.midnightLeaves, 0);
        this.setBlock(world, i + 12, j + 9, k + 29, Dungeons.midnightLeaves, 0);
        this.setBlock(world, i + 12, j + 10, k + 3, Dungeons.midnightLeaves, 0);
        this.setBlock(world, i + 12, j + 10, k + 4, Dungeons.midnightLeaves, 0);
        this.setBlock(world, i + 12, j + 10, k + 17, Dungeons.midnightLeaves, 0);
        this.setBlock(world, i + 12, j + 10, k + 29, Dungeons.midnightLeaves, 0);
        this.setBlock(world, i + 12, j + 11, k + 4, Dungeons.midnightLeaves, 0);
        this.setBlock(world, i + 12, j + 11, k + 17, Dungeons.midnightLeaves, 0);
        this.setBlock(world, i + 12, j + 11, k + 28, Dungeons.midnightLeaves, 0);
        this.setBlock(world, i + 12, j + 12, k + 4, Dungeons.midnightLeaves, 0);
        this.setBlock(world, i + 12, j + 12, k + 17, Dungeons.midnightLeaves, 0);
        this.setBlock(world, i + 12, j + 12, k + 27, Dungeons.midnightLeaves, 0);
        this.setBlock(world, i + 12, j + 13, k + 4, Dungeons.midnightLeaves, 0);
        this.setBlock(world, i + 12, j + 13, k + 12, Dungeons.midnightLeaves, 0);
        this.setBlock(world, i + 12, j + 13, k + 17, Dungeons.midnightLeaves, 0);
        this.setBlock(world, i + 12, j + 13, k + 26, Dungeons.midnightLeaves, 0);
        this.setBlock(world, i + 12, j + 13, k + 27, Dungeons.midnightLeaves, 0);
        this.setBlock(world, i + 12, j + 14, k + 5, Dungeons.midnightLeaves, 0);
        this.setBlock(world, i + 12, j + 14, k + 10, Dungeons.midnightLeaves, 0);
        this.setBlock(world, i + 12, j + 14, k + 12, Dungeons.midnightLeaves, 0);
        this.setBlock(world, i + 12, j + 14, k + 17, Dungeons.midnightLeaves, 0);
        this.setBlock(world, i + 12, j + 14, k + 26, Dungeons.midnightLeaves, 0);
        this.setBlock(world, i + 12, j + 14, k + 27, Dungeons.midnightLeaves, 0);
        this.setBlock(world, i + 12, j + 15, k + 5, Dungeons.midnightLeaves, 0);
        this.setBlock(world, i + 12, j + 15, k + 6, Dungeons.midnightLeaves, 0);
        this.setBlock(world, i + 12, j + 15, k + 10, Dungeons.midnightLeaves, 0);
        this.setBlock(world, i + 12, j + 15, k + 11, Dungeons.midnightLeaves, 0);
        this.setBlock(world, i + 12, j + 15, k + 12, Dungeons.midnightLeaves, 0);
        this.setBlock(world, i + 12, j + 15, k + 13, Dungeons.midnightLeaves, 0);
        this.setBlock(world, i + 12, j + 15, k + 14, Dungeons.midnightLeaves, 0);
        this.setBlock(world, i + 12, j + 15, k + 16, Dungeons.midnightLeaves, 0);
        this.setBlock(world, i + 12, j + 15, k + 17, Dungeons.midnightLeaves, 0);
        this.setBlock(world, i + 12, j + 15, k + 25, Dungeons.midnightLeaves, 0);
        this.setBlock(world, i + 12, j + 15, k + 26, Dungeons.midnightLeaves, 0);
        this.setBlock(world, i + 12, j + 15, k + 27, Dungeons.midnightLeaves, 0);
        this.setBlock(world, i + 12, j + 16, k + 6, Dungeons.midnightLeaves, 0);
        this.setBlock(world, i + 12, j + 16, k + 7, Dungeons.midnightLeaves, 0);
        this.setBlock(world, i + 12, j + 16, k + 10, Dungeons.midnightLeaves, 0);
        this.setBlock(world, i + 12, j + 16, k + 11, Dungeons.midnightLeaves, 0);
        this.setBlock(world, i + 12, j + 16, k + 12, Dungeons.midnightLeaves, 0);
        this.setBlock(world, i + 12, j + 16, k + 13, Dungeons.midnightLeaves, 0);
        this.setBlock(world, i + 12, j + 16, k + 14, Dungeons.midnightLeaves, 0);
        this.setBlock(world, i + 12, j + 16, k + 15, Dungeons.midnightLeaves, 0);
        this.setBlock(world, i + 12, j + 16, k + 16, Dungeons.midnightLeaves, 0);
        this.setBlock(world, i + 12, j + 16, k + 17, Dungeons.midnightLeaves, 0);
        this.setBlock(world, i + 12, j + 16, k + 18, Dungeons.midnightLeaves, 0);
        this.setBlock(world, i + 12, j + 16, k + 25, Dungeons.midnightLeaves, 0);
        this.setBlock(world, i + 12, j + 16, k + 26, Dungeons.midnightLeaves, 0);
        this.setBlock(world, i + 12, j + 17, k + 6, Dungeons.midnightLeaves, 0);
        this.setBlock(world, i + 12, j + 17, k + 7, Dungeons.midnightLeaves, 0);
        this.setBlock(world, i + 12, j + 17, k + 8, Dungeons.midnightLeaves, 0);
        this.setBlock(world, i + 12, j + 17, k + 9, Dungeons.midnightLeaves, 0);
        this.setBlock(world, i + 12, j + 17, k + 15, Dungeons.midnightLeaves, 0);
        this.setBlock(world, i + 12, j + 17, k + 19, Dungeons.midnightLeaves, 0);
        this.setBlock(world, i + 12, j + 17, k + 20, Dungeons.midnightLeaves, 0);
        this.setBlock(world, i + 12, j + 17, k + 21, Dungeons.midnightLeaves, 0);
        this.setBlock(world, i + 12, j + 17, k + 24, Dungeons.midnightLeaves, 0);
        this.setBlock(world, i + 12, j + 17, k + 25, Dungeons.midnightLeaves, 0);
        this.setBlock(world, i + 12, j + 18, k + 20, Dungeons.midnightLeaves, 0);
        this.setBlock(world, i + 12, j + 18, k + 21, Dungeons.midnightLeaves, 0);
        this.setBlock(world, i + 12, j + 18, k + 22, Dungeons.midnightLeaves, 0);
        this.setBlock(world, i + 12, j + 18, k + 23, Dungeons.midnightLeaves, 0);
        this.setBlock(world, i + 13, j + 6, k + 2, Dungeons.midnightLeaves, 0);
        this.setBlock(world, i + 13, j + 6, k + 29, Dungeons.midnightLeaves, 0);
        this.setBlock(world, i + 13, j + 7, k + 2, Dungeons.midnightLeaves, 0);
        this.setBlock(world, i + 13, j + 7, k + 29, Dungeons.midnightLeaves, 0);
        this.setBlock(world, i + 13, j + 8, k + 2, Dungeons.midnightLeaves, 0);
        this.setBlock(world, i + 13, j + 8, k + 29, Dungeons.midnightLeaves, 0);
        this.setBlock(world, i + 13, j + 9, k + 2, Dungeons.midnightLeaves, 0);
        this.setBlock(world, i + 13, j + 9, k + 3, Dungeons.midnightLeaves, 0);
        this.setBlock(world, i + 13, j + 9, k + 29, Dungeons.midnightLeaves, 0);
        this.setBlock(world, i + 13, j + 10, k + 3, Dungeons.midnightLeaves, 0);
        this.setBlock(world, i + 13, j + 10, k + 11, Dungeons.midnightLeaves, 0);
        this.setBlock(world, i + 13, j + 10, k + 17, Dungeons.midnightLeaves, 0);
        this.setBlock(world, i + 13, j + 10, k + 29, Dungeons.midnightLeaves, 0);
        this.setBlock(world, i + 13, j + 11, k + 4, Dungeons.midnightLeaves, 0);
        this.setBlock(world, i + 13, j + 11, k + 11, Dungeons.midnightLeaves, 0);
        this.setBlock(world, i + 13, j + 11, k + 17, Dungeons.midnightLeaves, 0);
        this.setBlock(world, i + 13, j + 11, k + 18, Dungeons.midnightLeaves, 0);
        this.setBlock(world, i + 13, j + 11, k + 27, Dungeons.midnightLeaves, 0);
        this.setBlock(world, i + 13, j + 11, k + 28, Dungeons.midnightLeaves, 0);
        this.setBlock(world, i + 13, j + 11, k + 29, Dungeons.midnightLeaves, 0);
        this.setBlock(world, i + 13, j + 12, k + 4, Dungeons.midnightLeaves, 0);
        this.setBlock(world, i + 13, j + 12, k + 10, Dungeons.midnightLeaves, 0);
        this.setBlock(world, i + 13, j + 12, k + 11, Dungeons.midnightLeaves, 0);
        this.setBlock(world, i + 13, j + 12, k + 17, Dungeons.midnightLeaves, 0);
        this.setBlock(world, i + 13, j + 12, k + 23, Dungeons.midnightLeaves, 0);
        this.setBlock(world, i + 13, j + 12, k + 27, Dungeons.midnightLeaves, 0);
        this.setBlock(world, i + 13, j + 12, k + 28, Dungeons.midnightLeaves, 0);
        this.setBlock(world, i + 13, j + 13, k + 4, Dungeons.midnightLeaves, 0);
        this.setBlock(world, i + 13, j + 13, k + 5, Dungeons.midnightLeaves, 0);
        this.setBlock(world, i + 13, j + 13, k + 10, Dungeons.midnightLeaves, 0);
        this.setBlock(world, i + 13, j + 13, k + 11, Dungeons.midnightLeaves, 0);
        this.setBlock(world, i + 13, j + 13, k + 17, Dungeons.midnightLeaves, 0);
        this.setBlock(world, i + 13, j + 13, k + 23, Dungeons.midnightLeaves, 0);
        this.setBlock(world, i + 13, j + 13, k + 27, Dungeons.midnightLeaves, 0);
        this.setBlock(world, i + 13, j + 14, k + 4, Dungeons.midnightLeaves, 0);
        this.setBlock(world, i + 13, j + 14, k + 5, Dungeons.midnightLeaves, 0);
        this.setBlock(world, i + 13, j + 14, k + 10, Dungeons.midnightLeaves, 0);
        this.setBlock(world, i + 13, j + 14, k + 11, Dungeons.midnightLeaves, 0);
        this.setBlock(world, i + 13, j + 14, k + 12, Dungeons.midnightLeaves, 0);
        this.setBlock(world, i + 13, j + 14, k + 13, Dungeons.midnightLeaves, 0);
        this.setBlock(world, i + 13, j + 14, k + 14, Dungeons.midnightLeaves, 0);
        this.setBlock(world, i + 13, j + 14, k + 15, Dungeons.midnightLeaves, 0);
        this.setBlock(world, i + 13, j + 14, k + 16, Dungeons.midnightLeaves, 0);
        this.setBlock(world, i + 13, j + 14, k + 17, Dungeons.midnightLeaves, 0);
        this.setBlock(world, i + 13, j + 14, k + 23, Dungeons.midnightLeaves, 0);
        this.setBlock(world, i + 13, j + 14, k + 24, Dungeons.midnightLeaves, 0);
        this.setBlock(world, i + 13, j + 14, k + 25, Dungeons.midnightLeaves, 0);
        this.setBlock(world, i + 13, j + 14, k + 26, Dungeons.midnightLeaves, 0);
        this.setBlock(world, i + 13, j + 14, k + 27, Dungeons.midnightLeaves, 0);
        this.setBlock(world, i + 13, j + 15, k + 4, Dungeons.midnightLeaves, 0);
        this.setBlock(world, i + 13, j + 15, k + 5, Dungeons.midnightLeaves, 0);
        this.setBlock(world, i + 13, j + 15, k + 6, Dungeons.midnightLeaves, 0);
        this.setBlock(world, i + 13, j + 15, k + 10, Dungeons.midnightLeaves, 0);
        this.setBlock(world, i + 13, j + 15, k + 11, Dungeons.midnightLeaves, 0);
        this.setBlock(world, i + 13, j + 15, k + 12, Dungeons.midnightLeaves, 0);
        this.setBlock(world, i + 13, j + 15, k + 13, Dungeons.midnightLeaves, 0);
        this.setBlock(world, i + 13, j + 15, k + 14, Dungeons.midnightLeaves, 0);
        this.setBlock(world, i + 13, j + 15, k + 15, Dungeons.midnightLeaves, 0);
        this.setBlock(world, i + 13, j + 15, k + 16, Dungeons.midnightLeaves, 0);
        this.setBlock(world, i + 13, j + 15, k + 17, Dungeons.midnightLeaves, 0);
        this.setBlock(world, i + 13, j + 15, k + 18, Dungeons.midnightLeaves, 0);
        this.setBlock(world, i + 13, j + 15, k + 23, Dungeons.midnightLeaves, 0);
        this.setBlock(world, i + 13, j + 15, k + 24, Dungeons.midnightLeaves, 0);
        this.setBlock(world, i + 13, j + 15, k + 25, Dungeons.midnightLeaves, 0);
        this.setBlock(world, i + 13, j + 15, k + 26, Dungeons.midnightLeaves, 0);
        this.setBlock(world, i + 13, j + 16, k + 6, Dungeons.midnightLeaves, 0);
        this.setBlock(world, i + 13, j + 16, k + 9, Dungeons.midnightLeaves, 0);
        this.setBlock(world, i + 13, j + 16, k + 10, Dungeons.midnightLeaves, 0);
        this.setBlock(world, i + 13, j + 16, k + 11, Dungeons.midnightLeaves, 0);
        this.setBlock(world, i + 13, j + 16, k + 14, Dungeons.midnightLeaves, 0);
        this.setBlock(world, i + 13, j + 16, k + 15, Dungeons.midnightLeaves, 0);
        this.setBlock(world, i + 13, j + 16, k + 18, Dungeons.midnightLeaves, 0);
        this.setBlock(world, i + 13, j + 16, k + 19, Dungeons.midnightLeaves, 0);
        this.setBlock(world, i + 13, j + 16, k + 20, Dungeons.midnightLeaves, 0);
        this.setBlock(world, i + 13, j + 16, k + 23, Dungeons.midnightLeaves, 0);
        this.setBlock(world, i + 13, j + 16, k + 24, Dungeons.midnightLeaves, 0);
        this.setBlock(world, i + 13, j + 16, k + 25, Dungeons.midnightLeaves, 0);
        this.setBlock(world, i + 13, j + 17, k + 6, Dungeons.midnightLeaves, 0);
        this.setBlock(world, i + 13, j + 17, k + 7, Dungeons.midnightLeaves, 0);
        this.setBlock(world, i + 13, j + 17, k + 8, Dungeons.midnightLeaves, 0);
        this.setBlock(world, i + 13, j + 17, k + 9, Dungeons.midnightLeaves, 0);
        this.setBlock(world, i + 13, j + 17, k + 10, Dungeons.midnightLeaves, 0);
        this.setBlock(world, i + 13, j + 17, k + 15, Dungeons.midnightLeaves, 0);
        this.setBlock(world, i + 13, j + 17, k + 19, Dungeons.midnightLeaves, 0);
        this.setBlock(world, i + 13, j + 17, k + 20, Dungeons.midnightLeaves, 0);
        this.setBlock(world, i + 13, j + 17, k + 21, Dungeons.midnightLeaves, 0);
        this.setBlock(world, i + 13, j + 17, k + 22, Dungeons.midnightLeaves, 0);
        this.setBlock(world, i + 13, j + 17, k + 23, Dungeons.midnightLeaves, 0);
        this.setBlock(world, i + 13, j + 17, k + 24, Dungeons.midnightLeaves, 0);
        this.setBlock(world, i + 13, j + 17, k + 25, Dungeons.midnightLeaves, 0);
        this.setBlock(world, i + 13, j + 18, k + 20, Dungeons.midnightLeaves, 0);
        this.setBlock(world, i + 13, j + 18, k + 21, Dungeons.midnightLeaves, 0);
        this.setBlock(world, i + 14, j + 4, k + 1, Dungeons.midnightLeaves, 0);
        this.setBlock(world, i + 14, j + 5, k + 1, Dungeons.midnightLeaves, 0);
        this.setBlock(world, i + 14, j + 5, k + 29, Dungeons.midnightLeaves, 0);
        this.setBlock(world, i + 14, j + 6, k + 1, Dungeons.midnightLeaves, 0);
        this.setBlock(world, i + 14, j + 6, k + 29, Dungeons.midnightLeaves, 0);
        this.setBlock(world, i + 14, j + 7, k + 1, Dungeons.midnightLeaves, 0);
        this.setBlock(world, i + 14, j + 7, k + 29, Dungeons.midnightLeaves, 0);
        this.setBlock(world, i + 14, j + 8, k + 1, Dungeons.midnightLeaves, 0);
        this.setBlock(world, i + 14, j + 8, k + 29, Dungeons.midnightLeaves, 0);
        this.setBlock(world, i + 14, j + 9, k + 2, Dungeons.midnightLeaves, 0);
        this.setBlock(world, i + 14, j + 9, k + 3, Dungeons.midnightLeaves, 0);
        this.setBlock(world, i + 14, j + 9, k + 29, Dungeons.midnightLeaves, 0);
        this.setBlock(world, i + 14, j + 10, k + 3, Dungeons.midnightLeaves, 0);
        this.setBlock(world, i + 14, j + 10, k + 14, Dungeons.midnightLeaves, 0);
        this.setBlock(world, i + 14, j + 10, k + 29, Dungeons.midnightLeaves, 0);
        this.setBlock(world, i + 14, j + 11, k + 3, Dungeons.midnightLeaves, 0);
        this.setBlock(world, i + 14, j + 11, k + 13, Dungeons.midnightLeaves, 0);
        this.setBlock(world, i + 14, j + 11, k + 14, Dungeons.midnightLeaves, 0);
        this.setBlock(world, i + 14, j + 11, k + 28, Dungeons.midnightLeaves, 0);
        this.setBlock(world, i + 14, j + 11, k + 29, Dungeons.midnightLeaves, 0);
        this.setBlock(world, i + 14, j + 12, k + 3, Dungeons.midnightLeaves, 0);
        this.setBlock(world, i + 14, j + 12, k + 4, Dungeons.midnightLeaves, 0);
        this.setBlock(world, i + 14, j + 12, k + 8, Dungeons.midnightLeaves, 0);
        this.setBlock(world, i + 14, j + 12, k + 13, Dungeons.midnightLeaves, 0);
        this.setBlock(world, i + 14, j + 12, k + 14, Dungeons.midnightLeaves, 0);
        this.setBlock(world, i + 14, j + 12, k + 25, Dungeons.midnightLeaves, 0);
        this.setBlock(world, i + 14, j + 12, k + 27, Dungeons.midnightLeaves, 0);
        this.setBlock(world, i + 14, j + 12, k + 28, Dungeons.midnightLeaves, 0);
        this.setBlock(world, i + 14, j + 13, k + 3, Dungeons.midnightLeaves, 0);
        this.setBlock(world, i + 14, j + 13, k + 4, Dungeons.midnightLeaves, 0);
        this.setBlock(world, i + 14, j + 13, k + 8, Dungeons.midnightLeaves, 0);
        this.setBlock(world, i + 14, j + 13, k + 13, Dungeons.midnightLeaves, 0);
        this.setBlock(world, i + 14, j + 13, k + 14, Dungeons.midnightLeaves, 0);
        this.setBlock(world, i + 14, j + 13, k + 25, Dungeons.midnightLeaves, 0);
        this.setBlock(world, i + 14, j + 13, k + 27, Dungeons.midnightLeaves, 0);
        this.setBlock(world, i + 14, j + 14, k + 4, Dungeons.midnightLeaves, 0);
        this.setBlock(world, i + 14, j + 14, k + 8, Dungeons.midnightLeaves, 0);
        this.setBlock(world, i + 14, j + 14, k + 12, Dungeons.midnightLeaves, 0);
        this.setBlock(world, i + 14, j + 14, k + 13, Dungeons.midnightLeaves, 0);
        this.setBlock(world, i + 14, j + 14, k + 14, Dungeons.midnightLeaves, 0);
        this.setBlock(world, i + 14, j + 14, k + 15, Dungeons.midnightLeaves, 0);
        this.setBlock(world, i + 14, j + 14, k + 16, Dungeons.midnightLeaves, 0);
        this.setBlock(world, i + 14, j + 14, k + 17, Dungeons.midnightLeaves, 0);
        this.setBlock(world, i + 14, j + 14, k + 18, Dungeons.midnightLeaves, 0);
        this.setBlock(world, i + 14, j + 14, k + 19, Dungeons.midnightLeaves, 0);
        this.setBlock(world, i + 14, j + 14, k + 24, Dungeons.midnightLeaves, 0);
        this.setBlock(world, i + 14, j + 14, k + 25, Dungeons.midnightLeaves, 0);
        this.setBlock(world, i + 14, j + 14, k + 26, Dungeons.midnightLeaves, 0);
        this.setBlock(world, i + 14, j + 15, k + 4, Dungeons.midnightLeaves, 0);
        this.setBlock(world, i + 14, j + 15, k + 5, Dungeons.midnightLeaves, 0);
        this.setBlock(world, i + 14, j + 15, k + 8, Dungeons.midnightLeaves, 0);
        this.setBlock(world, i + 14, j + 15, k + 12, Dungeons.midnightLeaves, 0);
        this.setBlock(world, i + 14, j + 15, k + 13, Dungeons.midnightLeaves, 0);
        this.setBlock(world, i + 14, j + 15, k + 14, Dungeons.midnightLeaves, 0);
        this.setBlock(world, i + 14, j + 15, k + 15, Dungeons.midnightLeaves, 0);
        this.setBlock(world, i + 14, j + 15, k + 16, Dungeons.midnightLeaves, 0);
        this.setBlock(world, i + 14, j + 15, k + 17, Dungeons.midnightLeaves, 0);
        this.setBlock(world, i + 14, j + 15, k + 18, Dungeons.midnightLeaves, 0);
        this.setBlock(world, i + 14, j + 15, k + 19, Dungeons.midnightLeaves, 0);
        this.setBlock(world, i + 14, j + 15, k + 24, Dungeons.midnightLeaves, 0);
        this.setBlock(world, i + 14, j + 15, k + 25, Dungeons.midnightLeaves, 0);
        this.setBlock(world, i + 14, j + 15, k + 26, Dungeons.midnightLeaves, 0);
        this.setBlock(world, i + 14, j + 16, k + 4, Dungeons.midnightLeaves, 0);
        this.setBlock(world, i + 14, j + 16, k + 5, Dungeons.midnightLeaves, 0);
        this.setBlock(world, i + 14, j + 16, k + 6, Dungeons.midnightLeaves, 0);
        this.setBlock(world, i + 14, j + 16, k + 8, Dungeons.midnightLeaves, 0);
        this.setBlock(world, i + 14, j + 16, k + 10, Dungeons.midnightLeaves, 0);
        this.setBlock(world, i + 14, j + 16, k + 11, Dungeons.midnightLeaves, 0);
        this.setBlock(world, i + 14, j + 16, k + 18, Dungeons.midnightLeaves, 0);
        this.setBlock(world, i + 14, j + 16, k + 19, Dungeons.midnightLeaves, 0);
        this.setBlock(world, i + 14, j + 16, k + 20, Dungeons.midnightLeaves, 0);
        this.setBlock(world, i + 14, j + 16, k + 21, Dungeons.midnightLeaves, 0);
        this.setBlock(world, i + 14, j + 16, k + 24, Dungeons.midnightLeaves, 0);
        this.setBlock(world, i + 14, j + 16, k + 25, Dungeons.midnightLeaves, 0);
        this.setBlock(world, i + 14, j + 17, k + 5, Dungeons.midnightLeaves, 0);
        this.setBlock(world, i + 14, j + 17, k + 6, Dungeons.midnightLeaves, 0);
        this.setBlock(world, i + 14, j + 17, k + 7, Dungeons.midnightLeaves, 0);
        this.setBlock(world, i + 14, j + 17, k + 8, Dungeons.midnightLeaves, 0);
        this.setBlock(world, i + 14, j + 17, k + 9, Dungeons.midnightLeaves, 0);
        this.setBlock(world, i + 14, j + 17, k + 10, Dungeons.midnightLeaves, 0);
        this.setBlock(world, i + 14, j + 17, k + 19, Dungeons.midnightLeaves, 0);
        this.setBlock(world, i + 14, j + 17, k + 20, Dungeons.midnightLeaves, 0);
        this.setBlock(world, i + 14, j + 17, k + 21, Dungeons.midnightLeaves, 0);
        this.setBlock(world, i + 14, j + 17, k + 22, Dungeons.midnightLeaves, 0);
        this.setBlock(world, i + 14, j + 17, k + 23, Dungeons.midnightLeaves, 0);
        this.setBlock(world, i + 14, j + 17, k + 24, Dungeons.midnightLeaves, 0);
        this.setBlock(world, i + 14, j + 17, k + 25, Dungeons.midnightLeaves, 0);
        this.setBlock(world, i + 15, j + 5, k + 1, Dungeons.midnightLeaves, 0);
        this.setBlock(world, i + 15, j + 6, k + 1, Dungeons.midnightLeaves, 0);
        this.setBlock(world, i + 15, j + 7, k + 1, Dungeons.midnightLeaves, 0);
        this.setBlock(world, i + 15, j + 7, k + 29, Dungeons.midnightLeaves, 0);
        this.setBlock(world, i + 15, j + 8, k + 1, Dungeons.midnightLeaves, 0);
        this.setBlock(world, i + 15, j + 8, k + 29, Dungeons.midnightLeaves, 0);
        this.setBlock(world, i + 15, j + 9, k + 1, Dungeons.midnightLeaves, 0);
        this.setBlock(world, i + 15, j + 9, k + 2, Dungeons.midnightLeaves, 0);
        this.setBlock(world, i + 15, j + 9, k + 29, Dungeons.midnightLeaves, 0);
        this.setBlock(world, i + 15, j + 10, k + 2, Dungeons.midnightLeaves, 0);
        this.setBlock(world, i + 15, j + 10, k + 3, Dungeons.midnightLeaves, 0);
        this.setBlock(world, i + 15, j + 10, k + 28, Dungeons.midnightLeaves, 0);
        this.setBlock(world, i + 15, j + 10, k + 29, Dungeons.midnightLeaves, 0);
        this.setBlock(world, i + 15, j + 11, k + 2, Dungeons.midnightLeaves, 0);
        this.setBlock(world, i + 15, j + 11, k + 3, Dungeons.midnightLeaves, 0);
        this.setBlock(world, i + 15, j + 11, k + 28, Dungeons.midnightLeaves, 0);
        this.setBlock(world, i + 15, j + 11, k + 29, Dungeons.midnightLeaves, 0);
        this.setBlock(world, i + 15, j + 12, k + 2, Dungeons.midnightLeaves, 0);
        this.setBlock(world, i + 15, j + 12, k + 3, Dungeons.midnightLeaves, 0);
        this.setBlock(world, i + 15, j + 12, k + 18, Dungeons.midnightLeaves, 0);
        this.setBlock(world, i + 15, j + 12, k + 19, Dungeons.midnightLeaves, 0);
        this.setBlock(world, i + 15, j + 12, k + 28, Dungeons.midnightLeaves, 0);
        this.setBlock(world, i + 15, j + 13, k + 3, Dungeons.midnightLeaves, 0);
        this.setBlock(world, i + 15, j + 13, k + 15, Dungeons.midnightLeaves, 0);
        this.setBlock(world, i + 15, j + 13, k + 17, Dungeons.midnightLeaves, 0);
        this.setBlock(world, i + 15, j + 13, k + 18, Dungeons.midnightLeaves, 0);
        this.setBlock(world, i + 15, j + 13, k + 19, Dungeons.midnightLeaves, 0);
        this.setBlock(world, i + 15, j + 13, k + 27, Dungeons.midnightLeaves, 0);
        this.setBlock(world, i + 15, j + 13, k + 28, Dungeons.midnightLeaves, 0);
        this.setBlock(world, i + 15, j + 14, k + 3, Dungeons.midnightLeaves, 0);
        this.setBlock(world, i + 15, j + 14, k + 12, Dungeons.midnightLeaves, 0);
        this.setBlock(world, i + 15, j + 14, k + 13, Dungeons.midnightLeaves, 0);
        this.setBlock(world, i + 15, j + 14, k + 14, Dungeons.midnightLeaves, 0);
        this.setBlock(world, i + 15, j + 14, k + 15, Dungeons.midnightLeaves, 0);
        this.setBlock(world, i + 15, j + 14, k + 16, Dungeons.midnightLeaves, 0);
        this.setBlock(world, i + 15, j + 14, k + 17, Dungeons.midnightLeaves, 0);
        this.setBlock(world, i + 15, j + 14, k + 18, Dungeons.midnightLeaves, 0);
        this.setBlock(world, i + 15, j + 14, k + 19, Dungeons.midnightLeaves, 0);
        this.setBlock(world, i + 15, j + 14, k + 20, Dungeons.midnightLeaves, 0);
        this.setBlock(world, i + 15, j + 14, k + 26, Dungeons.midnightLeaves, 0);
        this.setBlock(world, i + 15, j + 14, k + 27, Dungeons.midnightLeaves, 0);
        this.generate2(world, rand, i, j, k);
        return true;
    }

    public boolean generate2(final World world, final Random rand, final int i, final int j, final int k) {
        this.setBlock(world, i + 15, j + 15, k + 4, Dungeons.midnightLeaves, 0);
        this.setBlock(world, i + 15, j + 15, k + 8, Dungeons.midnightLeaves, 0);
        this.setBlock(world, i + 15, j + 15, k + 12, Dungeons.midnightLeaves, 0);
        this.setBlock(world, i + 15, j + 15, k + 13, Dungeons.midnightLeaves, 0);
        this.setBlock(world, i + 15, j + 15, k + 14, Dungeons.midnightLeaves, 0);
        this.setBlock(world, i + 15, j + 15, k + 17, Dungeons.midnightLeaves, 0);
        this.setBlock(world, i + 15, j + 15, k + 18, Dungeons.midnightLeaves, 0);
        this.setBlock(world, i + 15, j + 15, k + 19, Dungeons.midnightLeaves, 0);
        this.setBlock(world, i + 15, j + 15, k + 20, Dungeons.midnightLeaves, 0);
        this.setBlock(world, i + 15, j + 15, k + 25, Dungeons.midnightLeaves, 0);
        this.setBlock(world, i + 15, j + 15, k + 26, Dungeons.midnightLeaves, 0);
        this.setBlock(world, i + 15, j + 16, k + 4, Dungeons.midnightLeaves, 0);
        this.setBlock(world, i + 15, j + 16, k + 5, Dungeons.midnightLeaves, 0);
        this.setBlock(world, i + 15, j + 16, k + 11, Dungeons.midnightLeaves, 0);
        this.setBlock(world, i + 15, j + 16, k + 19, Dungeons.midnightLeaves, 0);
        this.setBlock(world, i + 15, j + 16, k + 20, Dungeons.midnightLeaves, 0);
        this.setBlock(world, i + 15, j + 16, k + 21, Dungeons.midnightLeaves, 0);
        this.setBlock(world, i + 15, j + 16, k + 24, Dungeons.midnightLeaves, 0);
        this.setBlock(world, i + 15, j + 17, k + 5, Dungeons.midnightLeaves, 0);
        this.setBlock(world, i + 15, j + 17, k + 7, Dungeons.midnightLeaves, 0);
        this.setBlock(world, i + 15, j + 17, k + 8, Dungeons.midnightLeaves, 0);
        this.setBlock(world, i + 15, j + 17, k + 9, Dungeons.midnightLeaves, 0);
        this.setBlock(world, i + 15, j + 17, k + 10, Dungeons.midnightLeaves, 0);
        this.setBlock(world, i + 15, j + 17, k + 11, Dungeons.midnightLeaves, 0);
        this.setBlock(world, i + 15, j + 17, k + 21, Dungeons.midnightLeaves, 0);
        this.setBlock(world, i + 15, j + 17, k + 22, Dungeons.midnightLeaves, 0);
        this.setBlock(world, i + 15, j + 17, k + 23, Dungeons.midnightLeaves, 0);
        this.setBlock(world, i + 15, j + 17, k + 24, Dungeons.midnightLeaves, 0);
        this.setBlock(world, i + 15, j + 18, k + 5, Dungeons.midnightLeaves, 0);
        this.setBlock(world, i + 15, j + 18, k + 6, Dungeons.midnightLeaves, 0);
        this.setBlock(world, i + 15, j + 18, k + 7, Dungeons.midnightLeaves, 0);
        this.setBlock(world, i + 16, j + 4, k + 1, Dungeons.midnightLeaves, 0);
        this.setBlock(world, i + 16, j + 5, k + 1, Dungeons.midnightLeaves, 0);
        this.setBlock(world, i + 16, j + 6, k + 1, Dungeons.midnightLeaves, 0);
        this.setBlock(world, i + 16, j + 7, k + 1, Dungeons.midnightLeaves, 0);
        this.setBlock(world, i + 16, j + 7, k + 29, Dungeons.midnightLeaves, 0);
        this.setBlock(world, i + 16, j + 8, k + 1, Dungeons.midnightLeaves, 0);
        this.setBlock(world, i + 16, j + 8, k + 15, Dungeons.midnightLeaves, 0);
        this.setBlock(world, i + 16, j + 8, k + 28, Dungeons.midnightLeaves, 0);
        this.setBlock(world, i + 16, j + 8, k + 29, Dungeons.midnightLeaves, 0);
        this.setBlock(world, i + 16, j + 9, k + 1, Dungeons.midnightLeaves, 0);
        this.setBlock(world, i + 16, j + 9, k + 15, Dungeons.midnightLeaves, 0);
        this.setBlock(world, i + 16, j + 9, k + 28, Dungeons.midnightLeaves, 0);
        this.setBlock(world, i + 16, j + 9, k + 29, Dungeons.midnightLeaves, 0);
        this.setBlock(world, i + 16, j + 10, k + 1, Dungeons.midnightLeaves, 0);
        this.setBlock(world, i + 16, j + 10, k + 2, Dungeons.midnightLeaves, 0);
        this.setBlock(world, i + 16, j + 10, k + 15, Dungeons.midnightLeaves, 0);
        this.setBlock(world, i + 16, j + 10, k + 18, Dungeons.midnightLeaves, 0);
        this.setBlock(world, i + 16, j + 10, k + 28, Dungeons.midnightLeaves, 0);
        this.setBlock(world, i + 16, j + 11, k + 2, Dungeons.midnightLeaves, 0);
        this.setBlock(world, i + 16, j + 11, k + 15, Dungeons.midnightLeaves, 0);
        this.setBlock(world, i + 16, j + 11, k + 18, Dungeons.midnightLeaves, 0);
        this.setBlock(world, i + 16, j + 11, k + 28, Dungeons.midnightLeaves, 0);
        this.setBlock(world, i + 16, j + 11, k + 29, Dungeons.midnightLeaves, 0);
        this.setBlock(world, i + 16, j + 12, k + 2, Dungeons.midnightLeaves, 0);
        this.setBlock(world, i + 16, j + 12, k + 8, Dungeons.midnightLeaves, 0);
        this.setBlock(world, i + 16, j + 12, k + 12, Dungeons.midnightLeaves, 0);
        this.setBlock(world, i + 16, j + 12, k + 15, Dungeons.midnightLeaves, 0);
        this.setBlock(world, i + 16, j + 12, k + 18, Dungeons.midnightLeaves, 0);
        this.setBlock(world, i + 16, j + 12, k + 19, Dungeons.midnightLeaves, 0);
        this.setBlock(world, i + 16, j + 12, k + 28, Dungeons.midnightLeaves, 0);
        this.setBlock(world, i + 16, j + 12, k + 29, Dungeons.midnightLeaves, 0);
        this.setBlock(world, i + 16, j + 13, k + 2, Dungeons.midnightLeaves, 0);
        this.setBlock(world, i + 16, j + 13, k + 8, Dungeons.midnightLeaves, 0);
        this.setBlock(world, i + 16, j + 13, k + 12, Dungeons.midnightLeaves, 0);
        this.setBlock(world, i + 16, j + 13, k + 15, Dungeons.midnightLeaves, 0);
        this.setBlock(world, i + 16, j + 13, k + 16, Dungeons.midnightLeaves, 0);
        this.setBlock(world, i + 16, j + 13, k + 17, Dungeons.midnightLeaves, 0);
        this.setBlock(world, i + 16, j + 13, k + 18, Dungeons.midnightLeaves, 0);
        this.setBlock(world, i + 16, j + 13, k + 19, Dungeons.midnightLeaves, 0);
        this.setBlock(world, i + 16, j + 13, k + 27, Dungeons.midnightLeaves, 0);
        this.setBlock(world, i + 16, j + 13, k + 28, Dungeons.midnightLeaves, 0);
        this.setBlock(world, i + 16, j + 14, k + 2, Dungeons.midnightLeaves, 0);
        this.setBlock(world, i + 16, j + 14, k + 3, Dungeons.midnightLeaves, 0);
        this.setBlock(world, i + 16, j + 14, k + 8, Dungeons.midnightLeaves, 0);
        this.setBlock(world, i + 16, j + 14, k + 12, Dungeons.midnightLeaves, 0);
        this.setBlock(world, i + 16, j + 14, k + 13, Dungeons.midnightLeaves, 0);
        this.setBlock(world, i + 16, j + 14, k + 14, Dungeons.midnightLeaves, 0);
        this.setBlock(world, i + 16, j + 14, k + 15, Dungeons.midnightLeaves, 0);
        this.setBlock(world, i + 16, j + 14, k + 16, Dungeons.midnightLeaves, 0);
        this.setBlock(world, i + 16, j + 14, k + 17, Dungeons.midnightLeaves, 0);
        this.setBlock(world, i + 16, j + 14, k + 18, Dungeons.midnightLeaves, 0);
        this.setBlock(world, i + 16, j + 14, k + 19, Dungeons.midnightLeaves, 0);
        this.setBlock(world, i + 16, j + 14, k + 20, Dungeons.midnightLeaves, 0);
        this.setBlock(world, i + 16, j + 14, k + 23, Dungeons.midnightLeaves, 0);
        this.setBlock(world, i + 16, j + 14, k + 27, Dungeons.midnightLeaves, 0);
        this.setBlock(world, i + 16, j + 14, k + 28, Dungeons.midnightLeaves, 0);
        this.setBlock(world, i + 16, j + 15, k + 3, Dungeons.midnightLeaves, 0);
        this.setBlock(world, i + 16, j + 15, k + 8, Dungeons.midnightLeaves, 0);
        this.setBlock(world, i + 16, j + 15, k + 12, Dungeons.midnightLeaves, 0);
        this.setBlock(world, i + 16, j + 15, k + 13, Dungeons.midnightLeaves, 0);
        this.setBlock(world, i + 16, j + 15, k + 14, Dungeons.midnightLeaves, 0);
        this.setBlock(world, i + 16, j + 15, k + 18, Dungeons.midnightLeaves, 0);
        this.setBlock(world, i + 16, j + 15, k + 19, Dungeons.midnightLeaves, 0);
        this.setBlock(world, i + 16, j + 15, k + 20, Dungeons.midnightLeaves, 0);
        this.setBlock(world, i + 16, j + 15, k + 21, Dungeons.midnightLeaves, 0);
        this.setBlock(world, i + 16, j + 15, k + 23, Dungeons.midnightLeaves, 0);
        this.setBlock(world, i + 16, j + 15, k + 24, Dungeons.midnightLeaves, 0);
        this.setBlock(world, i + 16, j + 15, k + 25, Dungeons.midnightLeaves, 0);
        this.setBlock(world, i + 16, j + 15, k + 26, Dungeons.midnightLeaves, 0);
        this.setBlock(world, i + 16, j + 15, k + 27, Dungeons.midnightLeaves, 0);
        this.setBlock(world, i + 16, j + 16, k + 4, Dungeons.midnightLeaves, 0);
        this.setBlock(world, i + 16, j + 16, k + 8, Dungeons.midnightLeaves, 0);
        this.setBlock(world, i + 16, j + 16, k + 11, Dungeons.midnightLeaves, 0);
        this.setBlock(world, i + 16, j + 16, k + 21, Dungeons.midnightLeaves, 0);
        this.setBlock(world, i + 16, j + 16, k + 23, Dungeons.midnightLeaves, 0);
        this.setBlock(world, i + 16, j + 16, k + 24, Dungeons.midnightLeaves, 0);
        this.setBlock(world, i + 16, j + 17, k + 5, Dungeons.midnightLeaves, 0);
        this.setBlock(world, i + 16, j + 17, k + 8, Dungeons.midnightLeaves, 0);
        this.setBlock(world, i + 16, j + 17, k + 9, Dungeons.midnightLeaves, 0);
        this.setBlock(world, i + 16, j + 17, k + 10, Dungeons.midnightLeaves, 0);
        this.setBlock(world, i + 16, j + 17, k + 11, Dungeons.midnightLeaves, 0);
        this.setBlock(world, i + 16, j + 17, k + 21, Dungeons.midnightLeaves, 0);
        this.setBlock(world, i + 16, j + 17, k + 22, Dungeons.midnightLeaves, 0);
        this.setBlock(world, i + 16, j + 18, k + 5, Dungeons.midnightLeaves, 0);
        this.setBlock(world, i + 16, j + 18, k + 6, Dungeons.midnightLeaves, 0);
        this.setBlock(world, i + 16, j + 18, k + 7, Dungeons.midnightLeaves, 0);
        this.setBlock(world, i + 17, j, k + 16, Dungeons.midnightLog, 0);
        this.setBlock(world, i + 17, j, k + 17, Dungeons.midnightLog, 0);
        this.setBlock(world, i + 17, j + 1, k + 16, Dungeons.midnightLog, 0);
        this.setBlock(world, i + 17, j + 1, k + 17, Dungeons.midnightLog, 0);
        this.setBlock(world, i + 17, j + 2, k + 16, Dungeons.midnightLog, 0);
        this.setBlock(world, i + 17, j + 2, k + 17, Dungeons.midnightLog, 0);
        this.setBlock(world, i + 17, j + 3, k + 1, Dungeons.midnightLeaves, 0);
        this.setBlock(world, i + 17, j + 3, k + 16, Dungeons.midnightLog, 0);
        this.setBlock(world, i + 17, j + 3, k + 17, Dungeons.midnightLog, 0);
        this.setBlock(world, i + 17, j + 4, k + 1, Dungeons.midnightLeaves, 0);
        this.setBlock(world, i + 17, j + 4, k + 16, Dungeons.midnightLog, 0);
        this.setBlock(world, i + 17, j + 4, k + 17, Dungeons.midnightLog, 0);
        this.setBlock(world, i + 17, j + 5, k + 1, Dungeons.midnightLeaves, 0);
        this.setBlock(world, i + 17, j + 5, k + 16, Dungeons.midnightLog, 0);
        this.setBlock(world, i + 17, j + 5, k + 17, Dungeons.midnightLog, 0);
        this.setBlock(world, i + 17, j + 6, k + 1, Dungeons.midnightLeaves, 0);
        this.setBlock(world, i + 17, j + 6, k + 16, Dungeons.midnightLog, 0);
        this.setBlock(world, i + 17, j + 6, k + 17, Dungeons.midnightLog, 0);
        this.setBlock(world, i + 17, j + 7, k + 1, Dungeons.midnightLeaves, 0);
        this.setBlock(world, i + 17, j + 7, k + 16, Dungeons.midnightLog, 0);
        this.setBlock(world, i + 17, j + 7, k + 17, Dungeons.midnightLog, 0);
        this.setBlock(world, i + 17, j + 8, k + 1, Dungeons.midnightLeaves, 0);
        this.setBlock(world, i + 17, j + 8, k + 16, Dungeons.midnightLog, 0);
        this.setBlock(world, i + 17, j + 8, k + 17, Dungeons.midnightLog, 0);
        this.setBlock(world, i + 17, j + 8, k + 27, Dungeons.midnightLeaves, 0);
        this.setBlock(world, i + 17, j + 8, k + 28, Dungeons.midnightLeaves, 0);
        this.setBlock(world, i + 17, j + 9, k + 1, Dungeons.midnightLeaves, 0);
        this.setBlock(world, i + 17, j + 9, k + 16, Dungeons.midnightLog, 0);
        this.setBlock(world, i + 17, j + 9, k + 17, Dungeons.midnightLog, 0);
        this.setBlock(world, i + 17, j + 9, k + 27, Dungeons.midnightLeaves, 0);
        this.setBlock(world, i + 17, j + 10, k + 1, Dungeons.midnightLeaves, 0);
        this.setBlock(world, i + 17, j + 10, k + 16, Dungeons.midnightLog, 0);
        this.setBlock(world, i + 17, j + 10, k + 17, Dungeons.midnightLog, 0);
        this.setBlock(world, i + 17, j + 10, k + 21, Dungeons.midnightLeaves, 0);
        this.setBlock(world, i + 17, j + 10, k + 22, Dungeons.midnightLeaves, 0);
        this.setBlock(world, i + 17, j + 10, k + 27, Dungeons.midnightLeaves, 0);
        this.setBlock(world, i + 17, j + 11, k + 1, Dungeons.midnightLeaves, 0);
        this.setBlock(world, i + 17, j + 11, k + 2, Dungeons.midnightLeaves, 0);
        this.setBlock(world, i + 17, j + 11, k + 16, Dungeons.midnightLog, 0);
        this.setBlock(world, i + 17, j + 11, k + 17, Dungeons.midnightLog, 0);
        this.setBlock(world, i + 17, j + 11, k + 21, Dungeons.midnightLeaves, 0);
        this.setBlock(world, i + 17, j + 11, k + 22, Dungeons.midnightLeaves, 0);
        this.setBlock(world, i + 17, j + 11, k + 27, Dungeons.midnightLeaves, 0);
        this.setBlock(world, i + 17, j + 11, k + 28, Dungeons.midnightLeaves, 0);
        this.setBlock(world, i + 17, j + 12, k + 1, Dungeons.midnightLeaves, 0);
        this.setBlock(world, i + 17, j + 12, k + 2, Dungeons.midnightLeaves, 0);
        this.setBlock(world, i + 17, j + 12, k + 16, Dungeons.midnightLeaves, 0);
        this.setBlock(world, i + 17, j + 12, k + 17, Dungeons.midnightLeaves, 0);
        this.setBlock(world, i + 17, j + 12, k + 18, Dungeons.midnightLeaves, 0);
        this.setBlock(world, i + 17, j + 12, k + 20, Dungeons.midnightLeaves, 0);
        this.setBlock(world, i + 17, j + 12, k + 21, Dungeons.midnightLeaves, 0);
        this.setBlock(world, i + 17, j + 12, k + 27, Dungeons.midnightLeaves, 0);
        this.setBlock(world, i + 17, j + 13, k + 1, Dungeons.midnightLeaves, 0);
        this.setBlock(world, i + 17, j + 13, k + 2, Dungeons.midnightLeaves, 0);
        this.setBlock(world, i + 17, j + 13, k + 14, Dungeons.midnightLeaves, 0);
        this.setBlock(world, i + 17, j + 13, k + 15, Dungeons.midnightLeaves, 0);
        this.setBlock(world, i + 17, j + 13, k + 16, Dungeons.midnightLeaves, 0);
        this.setBlock(world, i + 17, j + 13, k + 17, Dungeons.midnightLeaves, 0);
        this.setBlock(world, i + 17, j + 13, k + 18, Dungeons.midnightLeaves, 0);
        this.setBlock(world, i + 17, j + 13, k + 20, Dungeons.midnightLeaves, 0);
        this.setBlock(world, i + 17, j + 13, k + 21, Dungeons.midnightLeaves, 0);
        this.setBlock(world, i + 17, j + 13, k + 27, Dungeons.midnightLeaves, 0);
        this.setBlock(world, i + 17, j + 14, k + 2, Dungeons.midnightLeaves, 0);
        this.setBlock(world, i + 17, j + 14, k + 3, Dungeons.midnightLeaves, 0);
        this.setBlock(world, i + 17, j + 14, k + 12, Dungeons.midnightLeaves, 0);
        this.setBlock(world, i + 17, j + 14, k + 13, Dungeons.midnightLeaves, 0);
        this.setBlock(world, i + 17, j + 14, k + 14, Dungeons.midnightLeaves, 0);
        this.setBlock(world, i + 17, j + 14, k + 15, Dungeons.midnightLeaves, 0);
        this.setBlock(world, i + 17, j + 14, k + 16, Dungeons.midnightLeaves, 0);
        this.setBlock(world, i + 17, j + 14, k + 17, Dungeons.midnightLeaves, 0);
        this.setBlock(world, i + 17, j + 14, k + 18, Dungeons.midnightLeaves, 0);
        this.setBlock(world, i + 17, j + 14, k + 19, Dungeons.midnightLeaves, 0);
        this.setBlock(world, i + 17, j + 14, k + 20, Dungeons.midnightLeaves, 0);
        this.setBlock(world, i + 17, j + 14, k + 21, Dungeons.midnightLeaves, 0);
        this.setBlock(world, i + 17, j + 14, k + 25, Dungeons.midnightLeaves, 0);
        this.setBlock(world, i + 17, j + 14, k + 26, Dungeons.midnightLeaves, 0);
        this.setBlock(world, i + 17, j + 14, k + 27, Dungeons.midnightLeaves, 0);
        this.setBlock(world, i + 17, j + 15, k + 2, Dungeons.midnightLeaves, 0);
        this.setBlock(world, i + 17, j + 15, k + 3, Dungeons.midnightLeaves, 0);
        this.setBlock(world, i + 17, j + 15, k + 13, Dungeons.midnightLeaves, 0);
        this.setBlock(world, i + 17, j + 15, k + 14, Dungeons.midnightLeaves, 0);
        this.setBlock(world, i + 17, j + 15, k + 19, Dungeons.midnightLeaves, 0);
        this.setBlock(world, i + 17, j + 15, k + 20, Dungeons.midnightLeaves, 0);
        this.setBlock(world, i + 17, j + 15, k + 21, Dungeons.midnightLeaves, 0);
        this.setBlock(world, i + 17, j + 15, k + 23, Dungeons.midnightLeaves, 0);
        this.setBlock(world, i + 17, j + 15, k + 24, Dungeons.midnightLeaves, 0);
        this.setBlock(world, i + 17, j + 15, k + 25, Dungeons.midnightLeaves, 0);
