

package com.gibby.dungeon.gen;

import net.minecraft.world.gen.feature.*;
import net.minecraft.world.*;
import java.util.*;
import net.minecraft.init.*;
import net.minecraft.block.*;
import com.gibby.dungeon.*;

public class SmallCastle extends WorldGenerator
{
    public boolean generate(final World world, final Random rand, final int i, final int j, final int k) {
        if (world.getBlock(i, j, k) != Blocks.grass || world.getBlock(i + 19, j, k) != Blocks.grass || world.getBlock(i + 19, j, k + 19) != Blocks.grass || world.getBlock(i, j, k + 19) != Blocks.grass || world.getBlock(i, j + 1, k) != Blocks.air || world.getBlock(i + 19, j + 1, k) != Blocks.air || world.getBlock(i + 19, j + 1, k + 19) != Blocks.air || world.getBlock(i, j + 1, k + 19) != Blocks.air) {
            return false;
        }
        world.setBlock(i, j + 0, k + 0, Blocks.grass);
        world.setBlock(i, j + 0, k + 1, Blocks.grass);
        world.setBlock(i, j + 0, k + 2, Blocks.grass);
        world.setBlock(i, j + 0, k + 3, Blocks.grass);
        world.setBlock(i, j + 0, k + 4, Blocks.grass);
        world.setBlock(i, j + 0, k + 5, Blocks.grass);
        world.setBlock(i, j + 0, k + 6, Blocks.grass);
        world.setBlock(i, j + 0, k + 7, Blocks.grass);
        world.setBlock(i, j + 0, k + 8, Blocks.grass);
        world.setBlock(i, j + 0, k + 9, Blocks.grass);
        world.setBlock(i, j + 0, k + 10, Blocks.grass);
        world.setBlock(i, j + 0, k + 11, Blocks.grass);
        world.setBlock(i, j + 0, k + 12, Blocks.grass);
        world.setBlock(i, j + 0, k + 13, Blocks.grass);
        world.setBlock(i, j + 0, k + 14, Blocks.grass);
        world.setBlock(i, j + 0, k + 15, Blocks.grass);
        world.setBlock(i, j + 0, k + 16, Blocks.grass);
        world.setBlock(i, j + 0, k + 17, Blocks.grass);
        world.setBlock(i, j + 0, k + 18, Blocks.grass);
        world.setBlock(i, j + 0, k + 19, Blocks.grass);
        world.setBlock(i + 1, j + 0, k + 0, Blocks.grass);
        world.setBlock(i + 1, j + 0, k + 1, Blocks.dirt);
        world.setBlock(i + 1, j + 0, k + 2, Blocks.dirt);
        world.setBlock(i + 1, j + 0, k + 3, Blocks.dirt);
        world.setBlock(i + 1, j + 0, k + 4, Blocks.dirt);
        world.setBlock(i + 1, j + 0, k + 5, Blocks.dirt);
        world.setBlock(i + 1, j + 0, k + 6, Blocks.dirt);
        world.setBlock(i + 1, j + 0, k + 7, Blocks.dirt);
        world.setBlock(i + 1, j + 0, k + 8, Blocks.dirt);
        world.setBlock(i + 1, j + 0, k + 9, Blocks.dirt);
        world.setBlock(i + 1, j + 0, k + 10, Blocks.dirt);
        world.setBlock(i + 1, j + 0, k + 11, Blocks.dirt);
        world.setBlock(i + 1, j + 0, k + 12, Blocks.dirt);
        world.setBlock(i + 1, j + 0, k + 13, Blocks.dirt);
        world.setBlock(i + 1, j + 0, k + 14, Blocks.dirt);
        world.setBlock(i + 1, j + 0, k + 15, Blocks.dirt);
        world.setBlock(i + 1, j + 0, k + 16, Blocks.dirt);
        world.setBlock(i + 1, j + 0, k + 17, Blocks.dirt);
        world.setBlock(i + 1, j + 0, k + 18, Blocks.dirt);
        world.setBlock(i + 1, j + 0, k + 19, Blocks.grass);
        world.setBlock(i + 1, j + 1, k + 1, Blocks.cobblestone);
        world.setBlock(i + 1, j + 1, k + 2, Blocks.cobblestone);
        world.setBlock(i + 1, j + 1, k + 3, Blocks.cobblestone);
        world.setBlock(i + 1, j + 1, k + 4, Blocks.cobblestone);
        world.setBlock(i + 1, j + 1, k + 5, Blocks.cobblestone);
        world.setBlock(i + 1, j + 1, k + 6, Blocks.cobblestone);
        world.setBlock(i + 1, j + 1, k + 7, Blocks.cobblestone);
        world.setBlock(i + 1, j + 1, k + 8, Blocks.cobblestone);
        world.setBlock(i + 1, j + 1, k + 9, Blocks.cobblestone);
        world.setBlock(i + 1, j + 1, k + 10, Blocks.cobblestone);
        world.setBlock(i + 1, j + 1, k + 11, Blocks.cobblestone);
        world.setBlock(i + 1, j + 1, k + 12, Blocks.cobblestone);
        world.setBlock(i + 1, j + 1, k + 13, Blocks.cobblestone);
        world.setBlock(i + 1, j + 1, k + 14, Blocks.cobblestone);
        world.setBlock(i + 1, j + 1, k + 15, Blocks.cobblestone);
        world.setBlock(i + 1, j + 1, k + 16, Blocks.cobblestone);
        world.setBlock(i + 1, j + 1, k + 17, Blocks.cobblestone);
        world.setBlock(i + 1, j + 1, k + 18, Blocks.cobblestone);
        world.setBlock(i + 1, j + 2, k + 1, Blocks.cobblestone);
        world.setBlock(i + 1, j + 2, k + 2, Blocks.cobblestone);
        world.setBlock(i + 1, j + 2, k + 3, Blocks.cobblestone);
        world.setBlock(i + 1, j + 2, k + 4, Blocks.cobblestone);
        world.setBlock(i + 1, j + 2, k + 5, Blocks.cobblestone);
        world.setBlock(i + 1, j + 2, k + 6, Blocks.cobblestone);
        world.setBlock(i + 1, j + 2, k + 7, Blocks.cobblestone);
        world.setBlock(i + 1, j + 2, k + 8, Blocks.cobblestone);
        world.setBlock(i + 1, j + 2, k + 9, Blocks.cobblestone);
        world.setBlock(i + 1, j + 2, k + 10, Blocks.cobblestone);
        world.setBlock(i + 1, j + 2, k + 11, Blocks.cobblestone);
        world.setBlock(i + 1, j + 2, k + 12, Blocks.cobblestone);
        world.setBlock(i + 1, j + 2, k + 13, Blocks.cobblestone);
        world.setBlock(i + 1, j + 2, k + 14, Blocks.cobblestone);
        world.setBlock(i + 1, j + 2, k + 15, Blocks.cobblestone);
        world.setBlock(i + 1, j + 2, k + 16, Blocks.cobblestone);
        world.setBlock(i + 1, j + 2, k + 17, Blocks.cobblestone);
        world.setBlock(i + 1, j + 2, k + 18, Blocks.cobblestone);
        world.setBlock(i + 1, j + 3, k + 1, Blocks.cobblestone);
        world.setBlock(i + 1, j + 3, k + 3, Blocks.cobblestone);
        world.setBlock(i + 1, j + 3, k + 4, Blocks.cobblestone);
        world.setBlock(i + 1, j + 3, k + 6, Blocks.cobblestone);
        world.setBlock(i + 1, j + 3, k + 7, Blocks.cobblestone);
        world.setBlock(i + 1, j + 3, k + 9, Blocks.cobblestone);
        world.setBlock(i + 1, j + 3, k + 10, Blocks.cobblestone);
        world.setBlock(i + 1, j + 3, k + 12, Blocks.cobblestone);
        world.setBlock(i + 1, j + 3, k + 13, Blocks.cobblestone);
        world.setBlock(i + 1, j + 3, k + 15, Blocks.cobblestone);
        world.setBlock(i + 1, j + 3, k + 16, Blocks.cobblestone);
        world.setBlock(i + 1, j + 3, k + 18, Blocks.cobblestone);
        world.setBlock(i + 2, j + 0, k + 0, Blocks.grass);
        world.setBlock(i + 2, j + 0, k + 1, Blocks.dirt);
        world.setBlock(i + 2, j + 0, k + 2, Blocks.grass);
        world.setBlock(i + 2, j + 0, k + 3, Blocks.grass);
        world.setBlock(i + 2, j + 0, k + 4, Blocks.grass);
        world.setBlock(i + 2, j + 0, k + 5, Blocks.grass);
        world.setBlock(i + 2, j + 0, k + 6, Blocks.grass);
        world.setBlock(i + 2, j + 0, k + 7, Blocks.grass);
        world.setBlock(i + 2, j + 0, k + 8, Blocks.grass);
        world.setBlock(i + 2, j + 0, k + 9, Blocks.grass);
        world.setBlock(i + 2, j + 0, k + 10, Blocks.grass);
        world.setBlock(i + 2, j + 0, k + 11, Blocks.grass);
        world.setBlock(i + 2, j + 0, k + 12, Blocks.grass);
        world.setBlock(i + 2, j + 0, k + 13, Blocks.grass);
        world.setBlock(i + 2, j + 0, k + 14, Blocks.grass);
        world.setBlock(i + 2, j + 0, k + 15, Blocks.grass);
        world.setBlock(i + 2, j + 0, k + 16, Blocks.grass);
        world.setBlock(i + 2, j + 0, k + 17, Blocks.grass);
        world.setBlock(i + 2, j + 0, k + 18, Blocks.dirt);
        world.setBlock(i + 2, j + 0, k + 19, Blocks.grass);
        world.setBlock(i + 2, j + 1, k + 1, Blocks.cobblestone);
        world.setBlock(i + 2, j + 1, k + 18, Blocks.cobblestone);
        world.setBlock(i + 2, j + 2, k + 1, Blocks.cobblestone);
        world.setBlock(i + 2, j + 2, k + 18, Blocks.cobblestone);
        world.setBlock(i + 3, j + 0, k + 0, Blocks.grass);
        world.setBlock(i + 3, j + 0, k + 1, Blocks.dirt);
        world.setBlock(i + 3, j + 0, k + 2, Blocks.grass);
        world.setBlock(i + 3, j + 0, k + 3, Blocks.grass);
        world.setBlock(i + 3, j + 0, k + 4, Blocks.grass);
        world.setBlock(i + 3, j + 0, k + 5, Blocks.grass);
        world.setBlock(i + 3, j + 0, k + 6, Blocks.grass);
        world.setBlock(i + 3, j + 0, k + 7, Blocks.grass);
        world.setBlock(i + 3, j + 0, k + 8, Blocks.grass);
        world.setBlock(i + 3, j + 0, k + 9, Blocks.grass);
        world.setBlock(i + 3, j + 0, k + 10, Blocks.grass);
        world.setBlock(i + 3, j + 0, k + 11, Blocks.grass);
        world.setBlock(i + 3, j + 0, k + 12, Blocks.grass);
        world.setBlock(i + 3, j + 0, k + 13, Blocks.grass);
        world.setBlock(i + 3, j + 0, k + 14, Blocks.grass);
        world.setBlock(i + 3, j + 0, k + 15, Blocks.grass);
        world.setBlock(i + 3, j + 0, k + 16, Blocks.grass);
        world.setBlock(i + 3, j + 0, k + 17, Blocks.grass);
        world.setBlock(i + 3, j + 0, k + 18, Blocks.dirt);
        world.setBlock(i + 3, j + 0, k + 19, Blocks.grass);
        world.setBlock(i + 3, j + 1, k + 1, Blocks.cobblestone);
        world.setBlock(i + 3, j + 1, k + 18, Blocks.cobblestone);
        world.setBlock(i + 3, j + 2, k + 1, Blocks.cobblestone);
        world.setBlock(i + 3, j + 2, k + 18, Blocks.cobblestone);
        world.setBlock(i + 3, j + 3, k + 1, Blocks.cobblestone);
        world.setBlock(i + 3, j + 3, k + 18, Blocks.cobblestone);
        world.setBlock(i + 4, j + 0, k + 0, Blocks.grass);
        world.setBlock(i + 4, j + 0, k + 1, Blocks.dirt);
        world.setBlock(i + 4, j + 0, k + 2, Blocks.grass);
        world.setBlock(i + 4, j + 0, k + 3, Blocks.grass);
        world.setBlock(i + 4, j + 0, k + 4, Blocks.dirt);
        world.setBlock(i + 4, j + 0, k + 5, Blocks.dirt);
        world.setBlock(i + 4, j + 0, k + 6, Blocks.dirt);
        world.setBlock(i + 4, j + 0, k + 7, Blocks.dirt);
        world.setBlock(i + 4, j + 0, k + 8, Blocks.grass);
        world.setBlock(i + 4, j + 0, k + 9, Blocks.grass);
        world.setBlock(i + 4, j + 0, k + 10, Blocks.grass);
        world.setBlock(i + 4, j + 0, k + 11, Blocks.grass);
        world.setBlock(i + 4, j + 0, k + 12, Blocks.dirt);
        world.setBlock(i + 4, j + 0, k + 13, Blocks.dirt);
        world.setBlock(i + 4, j + 0, k + 14, Blocks.dirt);
        world.setBlock(i + 4, j + 0, k + 15, Blocks.dirt);
        world.setBlock(i + 4, j + 0, k + 16, Blocks.grass);
        world.setBlock(i + 4, j + 0, k + 17, Blocks.grass);
        world.setBlock(i + 4, j + 0, k + 18, Blocks.dirt);
        world.setBlock(i + 4, j + 0, k + 19, Blocks.grass);
        world.setBlock(i + 4, j + 1, k + 1, Blocks.cobblestone);
        world.setBlock(i + 4, j + 1, k + 4, Blocks.cobblestone);
        world.setBlock(i + 4, j + 1, k + 5, Blocks.cobblestone);
        world.setBlock(i + 4, j + 1, k + 6, Blocks.cobblestone);
        world.setBlock(i + 4, j + 1, k + 7, Blocks.cobblestone);
        world.setBlock(i + 4, j + 1, k + 12, Blocks.cobblestone);
        world.setBlock(i + 4, j + 1, k + 13, Blocks.cobblestone);
        world.setBlock(i + 4, j + 1, k + 14, Blocks.cobblestone);
        world.setBlock(i + 4, j + 1, k + 15, Blocks.cobblestone);
        world.setBlock(i + 4, j + 1, k + 18, Blocks.cobblestone);
        world.setBlock(i + 4, j + 2, k + 1, Blocks.cobblestone);
        world.setBlock(i + 4, j + 2, k + 4, Blocks.cobblestone);
        world.setBlock(i + 4, j + 2, k + 5, Blocks.cobblestone);
        world.setBlock(i + 4, j + 2, k + 6, Blocks.cobblestone);
        world.setBlock(i + 4, j + 2, k + 7, Blocks.cobblestone);
        world.setBlock(i + 4, j + 2, k + 12, Blocks.cobblestone);
        world.setBlock(i + 4, j + 2, k + 13, Blocks.cobblestone);
        world.setBlock(i + 4, j + 2, k + 14, Blocks.cobblestone);
        world.setBlock(i + 4, j + 2, k + 15, Blocks.cobblestone);
        world.setBlock(i + 4, j + 2, k + 18, Blocks.cobblestone);
        world.setBlock(i + 4, j + 3, k + 1, Blocks.cobblestone);
        world.setBlock(i + 4, j + 3, k + 4, Blocks.cobblestone);
        world.setBlock(i + 4, j + 3, k + 5, Blocks.cobblestone);
        world.setBlock(i + 4, j + 3, k + 6, Blocks.cobblestone);
        world.setBlock(i + 4, j + 3, k + 7, Blocks.cobblestone);
        world.setBlock(i + 4, j + 3, k + 12, Blocks.cobblestone);
        world.setBlock(i + 4, j + 3, k + 13, Blocks.cobblestone);
        world.setBlock(i + 4, j + 3, k + 14, Blocks.cobblestone);
        world.setBlock(i + 4, j + 3, k + 15, Blocks.cobblestone);
        world.setBlock(i + 4, j + 3, k + 18, Blocks.cobblestone);
        world.setBlock(i + 4, j + 4, k + 4, Blocks.cobblestone);
        world.setBlock(i + 4, j + 4, k + 5, Blocks.cobblestone);
        world.setBlock(i + 4, j + 4, k + 6, Blocks.cobblestone);
        world.setBlock(i + 4, j + 4, k + 7, Blocks.cobblestone);
        world.setBlock(i + 4, j + 4, k + 12, Blocks.cobblestone);
        world.setBlock(i + 4, j + 4, k + 13, Blocks.cobblestone);
        world.setBlock(i + 4, j + 4, k + 14, Blocks.cobblestone);
        world.setBlock(i + 4, j + 4, k + 15, Blocks.cobblestone);
        world.setBlock(i + 4, j + 5, k + 4, Blocks.stonebrick);
        world.setBlock(i + 4, j + 5, k + 5, Blocks.stonebrick);
        world.setBlock(i + 4, j + 5, k + 6, Blocks.stonebrick);
        world.setBlock(i + 4, j + 5, k + 7, Blocks.stonebrick);
        world.setBlock(i + 4, j + 5, k + 12, Blocks.stonebrick);
        world.setBlock(i + 4, j + 5, k + 13, Blocks.stonebrick);
        world.setBlock(i + 4, j + 5, k + 14, Blocks.stonebrick);
        world.setBlock(i + 4, j + 5, k + 15, Blocks.stonebrick);
        world.setBlock(i + 4, j + 6, k + 4, Blocks.stonebrick);
        world.setBlock(i + 4, j + 6, k + 5, Blocks.stonebrick);
        world.setBlock(i + 4, j + 6, k + 6, Blocks.stonebrick);
        world.setBlock(i + 4, j + 6, k + 7, Blocks.stonebrick);
        world.setBlock(i + 4, j + 6, k + 12, Blocks.stonebrick);
        world.setBlock(i + 4, j + 6, k + 13, Blocks.stonebrick);
        world.setBlock(i + 4, j + 6, k + 14, Blocks.stonebrick);
        world.setBlock(i + 4, j + 6, k + 15, Blocks.stonebrick);
        world.setBlock(i + 4, j + 7, k + 4, Blocks.stonebrick);
        world.setBlock(i + 4, j + 7, k + 7, Blocks.stonebrick);
        world.setBlock(i + 4, j + 7, k + 12, Blocks.stonebrick);
        world.setBlock(i + 4, j + 7, k + 15, Blocks.stonebrick);
        world.setBlock(i + 5, j + 0, k + 0, Blocks.grass);
        world.setBlock(i + 5, j + 0, k + 1, Blocks.dirt);
        world.setBlock(i + 5, j + 0, k + 2, Blocks.grass);
        world.setBlock(i + 5, j + 0, k + 3, Blocks.grass);
        world.setBlock(i + 5, j + 0, k + 4, Blocks.dirt);
        world.setBlock(i + 5, j + 0, k + 5, Blocks.grass);
        world.setBlock(i + 5, j + 0, k + 6, Blocks.grass);
        world.setBlock(i + 5, j + 0, k + 7, Blocks.dirt);
        world.setBlock(i + 5, j + 0, k + 8, Blocks.dirt);
        world.setBlock(i + 5, j + 0, k + 9, Blocks.dirt);
        world.setBlock(i + 5, j + 0, k + 10, Blocks.dirt);
        world.setBlock(i + 5, j + 0, k + 11, Blocks.dirt);
        world.setBlock(i + 5, j + 0, k + 12, Blocks.dirt);
        world.setBlock(i + 5, j + 0, k + 13, Blocks.grass);
        world.setBlock(i + 5, j + 0, k + 14, Blocks.grass);
        world.setBlock(i + 5, j + 0, k + 15, Blocks.dirt);
        world.setBlock(i + 5, j + 0, k + 16, Blocks.grass);
        world.setBlock(i + 5, j + 0, k + 17, Blocks.grass);
        world.setBlock(i + 5, j + 0, k + 18, Blocks.dirt);
        world.setBlock(i + 5, j + 0, k + 19, Blocks.grass);
        world.setBlock(i + 5, j + 1, k + 1, Blocks.cobblestone);
        world.setBlock(i + 5, j + 1, k + 4, Blocks.cobblestone);
        world.setBlock(i + 5, j + 1, k + 7, Blocks.cobblestone);
        world.setBlock(i + 5, j + 1, k + 8, Blocks.cobblestone);
        world.setBlock(i + 5, j + 1, k + 9, Blocks.cobblestone);
        world.setBlock(i + 5, j + 1, k + 10, Blocks.cobblestone);
        world.setBlock(i + 5, j + 1, k + 11, Blocks.cobblestone);
        world.setBlock(i + 5, j + 1, k + 12, Blocks.cobblestone);
        world.setBlock(i + 5, j + 1, k + 15, Blocks.cobblestone);
        world.setBlock(i + 5, j + 1, k + 18, Blocks.cobblestone);
        world.setBlock(i + 5, j + 2, k + 1, Blocks.cobblestone);
        world.setBlock(i + 5, j + 2, k + 4, Blocks.cobblestone);
        world.setBlock(i + 5, j + 2, k + 7, Blocks.cobblestone);
        world.setBlock(i + 5, j + 2, k + 8, Blocks.cobblestone);
        world.setBlock(i + 5, j + 2, k + 9, Blocks.cobblestone);
        world.setBlock(i + 5, j + 2, k + 10, Blocks.cobblestone);
        world.setBlock(i + 5, j + 2, k + 11, Blocks.cobblestone);
        world.setBlock(i + 5, j + 2, k + 12, Blocks.cobblestone);
        world.setBlock(i + 5, j + 2, k + 15, Blocks.cobblestone);
        world.setBlock(i + 5, j + 2, k + 18, Blocks.cobblestone);
        world.setBlock(i + 5, j + 3, k + 4, Blocks.cobblestone);
        world.setBlock(i + 5, j + 3, k + 7, Blocks.cobblestone);
        world.setBlock(i + 5, j + 3, k + 8, Blocks.cobblestone);
        world.setBlock(i + 5, j + 3, k + 9, Blocks.cobblestone);
        world.setBlock(i + 5, j + 3, k + 10, Blocks.cobblestone);
        world.setBlock(i + 5, j + 3, k + 11, Blocks.cobblestone);
        world.setBlock(i + 5, j + 3, k + 12, Blocks.cobblestone);
        world.setBlock(i + 5, j + 3, k + 15, Blocks.cobblestone);
        world.setBlock(i + 5, j + 4, k + 4, Blocks.cobblestone);
        world.setBlock(i + 5, j + 4, k + 7, Blocks.cobblestone);
        world.setBlock(i + 5, j + 4, k + 8, Blocks.cobblestone);
        world.setBlock(i + 5, j + 4, k + 9, Blocks.cobblestone);
        world.setBlock(i + 5, j + 4, k + 10, Blocks.cobblestone);
        world.setBlock(i + 5, j + 4, k + 11, Blocks.cobblestone);
        world.setBlock(i + 5, j + 4, k + 12, Blocks.cobblestone);
        world.setBlock(i + 5, j + 4, k + 15, Blocks.cobblestone);
        world.setBlock(i + 5, j + 5, k + 4, Blocks.stonebrick);
        world.setBlock(i + 5, j + 5, k + 5, Blocks.stonebrick);
        world.setBlock(i + 5, j + 5, k + 6, Blocks.stonebrick);
        world.setBlock(i + 5, j + 5, k + 7, Blocks.stonebrick);
        world.setBlock(i + 5, j + 5, k + 8, Blocks.cobblestone);
        world.setBlock(i + 5, j + 5, k + 11, Blocks.cobblestone);
        world.setBlock(i + 5, j + 5, k + 12, Blocks.stonebrick);
        world.setBlock(i + 5, j + 5, k + 13, Blocks.cobblestone);
        world.setBlock(i + 5, j + 5, k + 14, Blocks.cobblestone);
        world.setBlock(i + 5, j + 5, k + 15, Blocks.stonebrick);
        world.setBlock(i + 5, j + 6, k + 4, Blocks.stonebrick);
        Dungeons.spawner(world, i + 5, j + 6, k + 5, 12, 2);
        world.setBlock(i + 5, j + 6, k + 7, Blocks.stonebrick);
        world.setBlock(i + 5, j + 6, k + 12, Blocks.stonebrick);
        world.setBlock(i + 5, j + 6, k + 15, Blocks.stonebrick);
        world.setBlock(i + 6, j + 0, k + 0, Blocks.grass);
        world.setBlock(i + 6, j + 0, k + 1, Blocks.dirt);
        world.setBlock(i + 6, j + 0, k + 2, Blocks.grass);
        world.setBlock(i + 6, j + 0, k + 3, Blocks.grass);
        world.setBlock(i + 6, j + 0, k + 4, Blocks.dirt);
        world.setBlock(i + 6, j + 0, k + 5, Blocks.grass);
        world.setBlock(i + 6, j + 0, k + 6, Blocks.grass);
        world.setBlock(i + 6, j + 0, k + 7, Blocks.dirt);
        world.setBlock(i + 6, j + 0, k + 8, Blocks.grass);
        world.setBlock(i + 6, j + 0, k + 9, Blocks.grass);
        world.setBlock(i + 6, j + 0, k + 10, Blocks.grass);
        world.setBlock(i + 6, j + 0, k + 11, Blocks.grass);
        world.setBlock(i + 6, j + 0, k + 12, Blocks.dirt);
        world.setBlock(i + 6, j + 0, k + 13, Blocks.grass);
        world.setBlock(i + 6, j + 0, k + 14, Blocks.grass);
        world.setBlock(i + 6, j + 0, k + 15, Blocks.dirt);
        world.setBlock(i + 6, j + 0, k + 16, Blocks.grass);
        world.setBlock(i + 6, j + 0, k + 17, Blocks.grass);
        world.setBlock(i + 6, j + 0, k + 18, Blocks.dirt);
        world.setBlock(i + 6, j + 0, k + 19, Blocks.grass);
        world.setBlock(i + 6, j + 1, k + 1, Blocks.cobblestone);
        world.setBlock(i + 6, j + 1, k + 4, Blocks.cobblestone);
        world.setBlock(i + 6, j + 1, k + 7, Blocks.cobblestone);
        Dungeons.spawner(world, i + 6, j + 1, k + 8, 12, 2);
        WorldGenWarlordDungeon.chest(world, rand, i + 6, j + 1, k + 11, "dungeonChest", rand.nextInt(5) + 1);
        world.setBlock(i + 6, j + 1, k + 12, Blocks.cobblestone);
        world.setBlock(i + 6, j + 1, k + 15, Blocks.cobblestone);
        world.setBlock(i + 6, j + 1, k + 18, Blocks.cobblestone);
        world.setBlock(i + 6, j + 2, k + 1, Blocks.cobblestone);
        world.setBlock(i + 6, j + 2, k + 4, Blocks.cobblestone);
        world.setBlock(i + 6, j + 2, k + 7, Blocks.cobblestone);
        world.setBlock(i + 6, j + 2, k + 12, Blocks.cobblestone);
        world.setBlock(i + 6, j + 2, k + 15, Blocks.cobblestone);
        world.setBlock(i + 6, j + 2, k + 18, Blocks.cobblestone);
        world.setBlock(i + 6, j + 3, k + 1, Blocks.cobblestone);
        world.setBlock(i + 6, j + 3, k + 4, Blocks.cobblestone);
        world.setBlock(i + 6, j + 3, k + 7, Blocks.cobblestone);
        world.setBlock(i + 6, j + 3, k + 12, Blocks.cobblestone);
        world.setBlock(i + 6, j + 3, k + 15, Blocks.cobblestone);
        world.setBlock(i + 6, j + 3, k + 18, Blocks.cobblestone);
        world.setBlock(i + 6, j + 4, k + 4, Blocks.cobblestone);
        world.setBlock(i + 6, j + 4, k + 7, Blocks.cobblestone);
        world.setBlock(i + 6, j + 4, k + 8, Blocks.cobblestone);
        world.setBlock(i + 6, j + 4, k + 9, Blocks.cobblestone);
        world.setBlock(i + 6, j + 4, k + 10, Blocks.cobblestone);
        world.setBlock(i + 6, j + 4, k + 11, Blocks.cobblestone);
        world.setBlock(i + 6, j + 4, k + 12, Blocks.cobblestone);
        world.setBlock(i + 6, j + 4, k + 15, Blocks.cobblestone);
        world.setBlock(i + 6, j + 5, k + 4, Blocks.stonebrick);
        world.setBlock(i + 6, j + 5, k + 5, Blocks.stonebrick);
        world.setBlock(i + 6, j + 5, k + 6, Blocks.stonebrick);
        world.setBlock(i + 6, j + 5, k + 7, Blocks.stonebrick);
        world.setBlock(i + 6, j + 5, k + 8, Blocks.stone_stairs, 3, 0);
        world.setBlock(i + 6, j + 5, k + 11, Blocks.stone_stairs, 2, 0);
        world.setBlock(i + 6, j + 5, k + 12, Blocks.stonebrick);
        world.setBlock(i + 6, j + 5, k + 13, Blocks.cobblestone);
        world.setBlock(i + 6, j + 5, k + 14, Blocks.cobblestone);
        world.setBlock(i + 6, j + 5, k + 15, Blocks.stonebrick);
        world.setBlock(i + 6, j + 6, k + 4, Blocks.stonebrick);
        world.setBlock(i + 6, j + 6, k + 15, Blocks.stonebrick);
        world.setBlock(i + 6, j + 12, k + 6, Blocks.stonebrick);
        world.setBlock(i + 6, j + 12, k + 7, Blocks.stonebrick);
        world.setBlock(i + 6, j + 12, k + 8, Blocks.stonebrick);
        world.setBlock(i + 6, j + 12, k + 9, Blocks.stonebrick);
        world.setBlock(i + 6, j + 12, k + 10, Blocks.stonebrick);
        world.setBlock(i + 6, j + 12, k + 11, Blocks.stonebrick);
        world.setBlock(i + 6, j + 12, k + 12, Blocks.stonebrick);
        world.setBlock(i + 6, j + 12, k + 13, Blocks.stonebrick);
        world.setBlock(i + 6, j + 13, k + 6, Blocks.stonebrick);
        world.setBlock(i + 6, j + 13, k + 7, Blocks.stonebrick);
        world.setBlock(i + 6, j + 13, k + 8, Blocks.stonebrick);
        world.setBlock(i + 6, j + 13, k + 9, Blocks.stonebrick);
        world.setBlock(i + 6, j + 13, k + 10, Blocks.stonebrick);
        world.setBlock(i + 6, j + 13, k + 11, Blocks.stonebrick);
        world.setBlock(i + 6, j + 13, k + 12, Blocks.stonebrick);
        world.setBlock(i + 6, j + 13, k + 13, Blocks.stonebrick);
        world.setBlock(i + 6, j + 14, k + 6, Blocks.stonebrick);
        world.setBlock(i + 6, j + 14, k + 9, Blocks.stonebrick);
        world.setBlock(i + 6, j + 14, k + 10, Blocks.stonebrick);
        world.setBlock(i + 6, j + 14, k + 13, Blocks.stonebrick);
        world.setBlock(i + 7, j + 0, k + 0, Blocks.grass);
        world.setBlock(i + 7, j + 0, k + 1, Blocks.dirt);
        world.setBlock(i + 7, j + 0, k + 2, Blocks.grass);
        world.setBlock(i + 7, j + 0, k + 3, Blocks.grass);
        world.setBlock(i + 7, j + 0, k + 4, Blocks.dirt);
        world.setBlock(i + 7, j + 0, k + 5, Blocks.dirt);
        world.setBlock(i + 7, j + 0, k + 6, Blocks.dirt);
        world.setBlock(i + 7, j + 0, k + 7, Blocks.dirt);
        world.setBlock(i + 7, j + 0, k + 8, Blocks.dirt);
        world.setBlock(i + 7, j + 0, k + 9, Blocks.grass);
        world.setBlock(i + 7, j + 0, k + 10, Blocks.grass);
        world.setBlock(i + 7, j + 0, k + 11, Blocks.dirt);
        world.setBlock(i + 7, j + 0, k + 12, Blocks.dirt);
        world.setBlock(i + 7, j + 0, k + 13, Blocks.dirt);
        world.setBlock(i + 7, j + 0, k + 14, Blocks.dirt);
        world.setBlock(i + 7, j + 0, k + 15, Blocks.dirt);
        world.setBlock(i + 7, j + 0, k + 16, Blocks.grass);
        world.setBlock(i + 7, j + 0, k + 17, Blocks.grass);
        world.setBlock(i + 7, j + 0, k + 18, Blocks.dirt);
        world.setBlock(i + 7, j + 0, k + 19, Blocks.grass);
        world.setBlock(i + 7, j + 1, k + 1, Blocks.cobblestone);
        world.setBlock(i + 7, j + 1, k + 4, Blocks.cobblestone);
        world.setBlock(i + 7, j + 1, k + 5, Blocks.cobblestone);
        world.setBlock(i + 7, j + 1, k + 6, Blocks.cobblestone);
        world.setBlock(i + 7, j + 1, k + 7, Blocks.cobblestone);
        world.setBlock(i + 7, j + 1, k + 8, Blocks.cobblestone);
        world.setBlock(i + 7, j + 1, k + 11, Blocks.cobblestone);
        world.setBlock(i + 7, j + 1, k + 12, Blocks.cobblestone);
        world.setBlock(i + 7, j + 1, k + 13, Blocks.cobblestone);
        world.setBlock(i + 7, j + 1, k + 14, Blocks.cobblestone);
        world.setBlock(i + 7, j + 1, k + 15, Blocks.cobblestone);
        world.setBlock(i + 7, j + 1, k + 18, Blocks.cobblestone);
        world.setBlock(i + 7, j + 2, k + 1, Blocks.cobblestone);
        world.setBlock(i + 7, j + 2, k + 4, Blocks.cobblestone);
        world.setBlock(i + 7, j + 2, k + 5, Blocks.cobblestone);
        world.setBlock(i + 7, j + 2, k + 6, Blocks.cobblestone);
        world.setBlock(i + 7, j + 2, k + 7, Blocks.cobblestone);
        world.setBlock(i + 7, j + 2, k + 8, Blocks.cobblestone);
        world.setBlock(i + 7, j + 2, k + 11, Blocks.cobblestone);
        world.setBlock(i + 7, j + 2, k + 12, Blocks.cobblestone);
        world.setBlock(i + 7, j + 2, k + 13, Blocks.cobblestone);
        world.setBlock(i + 7, j + 2, k + 14, Blocks.cobblestone);
        world.setBlock(i + 7, j + 2, k + 15, Blocks.cobblestone);
        world.setBlock(i + 7, j + 2, k + 18, Blocks.cobblestone);
        world.setBlock(i + 7, j + 3, k + 1, Blocks.cobblestone);
        world.setBlock(i + 7, j + 3, k + 4, Blocks.cobblestone);
        world.setBlock(i + 7, j + 3, k + 5, Blocks.cobblestone);
        world.setBlock(i + 7, j + 3, k + 6, Blocks.cobblestone);
        world.setBlock(i + 7, j + 3, k + 7, Blocks.cobblestone);
        world.setBlock(i + 7, j + 3, k + 8, Blocks.cobblestone);
        world.setBlock(i + 7, j + 3, k + 11, Blocks.cobblestone);
        world.setBlock(i + 7, j + 3, k + 12, Blocks.cobblestone);
        world.setBlock(i + 7, j + 3, k + 13, Blocks.cobblestone);
        world.setBlock(i + 7, j + 3, k + 14, Blocks.cobblestone);
        world.setBlock(i + 7, j + 3, k + 15, Blocks.cobblestone);
        world.setBlock(i + 7, j + 3, k + 18, Blocks.cobblestone);
        world.setBlock(i + 7, j + 4, k + 4, Blocks.cobblestone);
        world.setBlock(i + 7, j + 4, k + 5, Blocks.cobblestone);
        world.setBlock(i + 7, j + 4, k + 6, Blocks.cobblestone);
        world.setBlock(i + 7, j + 4, k + 7, Blocks.cobblestone);
        world.setBlock(i + 7, j + 4, k + 8, Blocks.cobblestone);
        world.setBlock(i + 7, j + 4, k + 9, Blocks.cobblestone);
        world.setBlock(i + 7, j + 4, k + 10, Blocks.cobblestone);
        world.setBlock(i + 7, j + 4, k + 11, Blocks.cobblestone);
        world.setBlock(i + 7, j + 4, k + 12, Blocks.cobblestone);
        world.setBlock(i + 7, j + 4, k + 13, Blocks.cobblestone);
        world.setBlock(i + 7, j + 4, k + 14, Blocks.cobblestone);
        world.setBlock(i + 7, j + 4, k + 15, Blocks.cobblestone);
        world.setBlock(i + 7, j + 5, k + 4, Blocks.stonebrick);
        world.setBlock(i + 7, j + 5, k + 5, Blocks.stonebrick);
        world.setBlock(i + 7, j + 5, k + 6, Blocks.stonebrick);
        world.setBlock(i + 7, j + 5, k + 7, Blocks.stonebrick);
        world.setBlock(i + 7, j + 5, k + 8, Blocks.stonebrick);
        world.setBlock(i + 7, j + 5, k + 11, Blocks.stonebrick);
        world.setBlock(i + 7, j + 5, k + 12, Blocks.stonebrick);
        world.setBlock(i + 7, j + 5, k + 13, Blocks.stonebrick);
        world.setBlock(i + 7, j + 5, k + 14, Blocks.stonebrick);
        world.setBlock(i + 7, j + 5, k + 15, Blocks.stonebrick);
        world.setBlock(i + 7, j + 6, k + 4, Blocks.stonebrick);
        world.setBlock(i + 7, j + 6, k + 5, Blocks.stonebrick);
        world.setBlock(i + 7, j + 6, k + 7, Blocks.stonebrick);
        world.setBlock(i + 7, j + 6, k + 8, Blocks.stonebrick);
        world.setBlock(i + 7, j + 6, k + 11, Blocks.stonebrick);
        world.setBlock(i + 7, j + 6, k + 12, Blocks.stonebrick);
        world.setBlock(i + 7, j + 6, k + 14, Blocks.stonebrick);
        world.setBlock(i + 7, j + 6, k + 15, Blocks.stonebrick);
        world.setBlock(i + 7, j + 7, k + 4, Blocks.stonebrick);
        world.setBlock(i + 7, j + 7, k + 7, Blocks.stonebrick);
        world.setBlock(i + 7, j + 7, k + 8, Blocks.stonebrick);
        world.setBlock(i + 7, j + 7, k + 9, Blocks.stonebrick);
        world.setBlock(i + 7, j + 7, k + 10, Blocks.stonebrick);
        world.setBlock(i + 7, j + 7, k + 11, Blocks.stonebrick);
        world.setBlock(i + 7, j + 7, k + 12, Blocks.stonebrick);
        world.setBlock(i + 7, j + 7, k + 15, Blocks.stonebrick);
        world.setBlock(i + 7, j + 8, k + 7, Blocks.stonebrick);
        world.setBlock(i + 7, j + 8, k + 8, Blocks.stonebrick);
        world.setBlock(i + 7, j + 8, k + 9, Blocks.stonebrick);
        world.setBlock(i + 7, j + 8, k + 10, Blocks.stonebrick);
        world.setBlock(i + 7, j + 8, k + 11, Blocks.stonebrick);
        world.setBlock(i + 7, j + 8, k + 12, Blocks.stonebrick);
        world.setBlock(i + 7, j + 9, k + 7, Blocks.stonebrick);
        world.setBlock(i + 7, j + 9, k + 8, Blocks.stonebrick);
        world.setBlock(i + 7, j + 9, k + 9, Blocks.stonebrick);
        world.setBlock(i + 7, j + 9, k + 10, Blocks.stonebrick);
        world.setBlock(i + 7, j + 9, k + 11, Blocks.stonebrick);
        world.setBlock(i + 7, j + 9, k + 12, Blocks.stonebrick);
        world.setBlock(i + 7, j + 10, k + 7, Blocks.stonebrick);
        world.setBlock(i + 7, j + 10, k + 8, Blocks.stonebrick);
        world.setBlock(i + 7, j + 10, k + 9, Blocks.stonebrick);
        world.setBlock(i + 7, j + 10, k + 10, Blocks.stonebrick);
        world.setBlock(i + 7, j + 10, k + 11, Blocks.stonebrick);
        world.setBlock(i + 7, j + 10, k + 12, Blocks.stonebrick);
        world.setBlock(i + 7, j + 11, k + 7, Blocks.stonebrick);
        world.setBlock(i + 7, j + 11, k + 8, Blocks.stonebrick);
        world.setBlock(i + 7, j + 11, k + 9, Blocks.stonebrick);
        world.setBlock(i + 7, j + 11, k + 10, Blocks.stonebrick);
        world.setBlock(i + 7, j + 11, k + 11, Blocks.stonebrick);
        world.setBlock(i + 7, j + 11, k + 12, Blocks.stonebrick);
        world.setBlock(i + 7, j + 12, k + 6, Blocks.stonebrick);
        world.setBlock(i + 7, j + 12, k + 7, Blocks.stonebrick);
        world.setBlock(i + 7, j + 12, k + 8, Blocks.stonebrick);
        world.setBlock(i + 7, j + 12, k + 9, Blocks.stonebrick);
        world.setBlock(i + 7, j + 12, k + 10, Blocks.stonebrick);
        world.setBlock(i + 7, j + 12, k + 11, Blocks.stonebrick);
        world.setBlock(i + 7, j + 12, k + 12, Blocks.stonebrick);
        world.setBlock(i + 7, j + 12, k + 13, Blocks.stonebrick);
        world.setBlock(i + 7, j + 13, k + 6, Blocks.stonebrick);
        world.setBlock(i + 7, j + 13, k + 13, Blocks.stonebrick);
        world.setBlock(i + 8, j + 0, k + 0, Blocks.grass);
        world.setBlock(i + 8, j + 0, k + 1, Blocks.dirt);
        world.setBlock(i + 8, j + 0, k + 2, Blocks.grass);
        world.setBlock(i + 8, j + 0, k + 3, Blocks.grass);
        world.setBlock(i + 8, j + 0, k + 4, Blocks.grass);
        world.setBlock(i + 8, j + 0, k + 5, Blocks.dirt);
        world.setBlock(i + 8, j + 0, k + 6, Blocks.grass);
        world.setBlock(i + 8, j + 0, k + 7, Blocks.grass);
        world.setBlock(i + 8, j + 0, k + 8, Blocks.grass);
        world.setBlock(i + 8, j + 0, k + 9, Blocks.grass);
        world.setBlock(i + 8, j + 0, k + 10, Blocks.grass);
        world.setBlock(i + 8, j + 0, k + 11, Blocks.grass);
        world.setBlock(i + 8, j + 0, k + 12, Blocks.grass);
        world.setBlock(i + 8, j + 0, k + 13, Blocks.grass);
        world.setBlock(i + 8, j + 0, k + 14, Blocks.dirt);
        world.setBlock(i + 8, j + 0, k + 15, Blocks.grass);
        world.setBlock(i + 8, j + 0, k + 16, Blocks.grass);
        world.setBlock(i + 8, j + 0, k + 17, Blocks.grass);
        world.setBlock(i + 8, j + 0, k + 18, Blocks.dirt);
        world.setBlock(i + 8, j + 0, k + 19, Blocks.grass);
        world.setBlock(i + 8, j + 1, k + 1, Blocks.cobblestone);
        world.setBlock(i + 8, j + 1, k + 5, Blocks.cobblestone);
        world.setBlock(i + 8, j + 1, k + 14, Blocks.cobblestone);
        world.setBlock(i + 8, j + 1, k + 18, Blocks.cobblestone);
        world.setBlock(i + 8, j + 2, k + 1, Blocks.cobblestone);
        world.setBlock(i + 8, j + 2, k + 5, Blocks.cobblestone);
        world.setBlock(i + 8, j + 2, k + 14, Blocks.cobblestone);
        world.setBlock(i + 8, j + 2, k + 18, Blocks.cobblestone);
        world.setBlock(i + 8, j + 3, k + 5, Blocks.cobblestone);
        world.setBlock(i + 8, j + 3, k + 14, Blocks.cobblestone);
        world.setBlock(i + 8, j + 4, k + 5, Blocks.cobblestone);
        world.setBlock(i + 8, j + 4, k + 6, Blocks.cobblestone);
        world.setBlock(i + 8, j + 4, k + 7, Blocks.cobblestone);
        world.setBlock(i + 8, j + 4, k + 9, Blocks.stonebrick);
        world.setBlock(i + 8, j + 4, k + 10, Blocks.stonebrick);
        world.setBlock(i + 8, j + 4, k + 12, Blocks.cobblestone);
        world.setBlock(i + 8, j + 4, k + 13, Blocks.cobblestone);
        world.setBlock(i + 8, j + 4, k + 14, Blocks.cobblestone);
        world.setBlock(i + 8, j + 5, k + 5, Blocks.cobblestone);
        world.setBlock(i + 8, j + 5, k + 6, Blocks.stone_stairs, 1, 0);
        world.setBlock(i + 8, j + 5, k + 7, Blocks.stonebrick);
        world.setBlock(i + 8, j + 5, k + 12, Blocks.stonebrick);
        world.setBlock(i + 8, j + 5, k + 13, Blocks.stone_stairs, 1, 0);
        world.setBlock(i + 8, j + 5, k + 14, Blocks.cobblestone);
        world.setBlock(i + 8, j + 6, k + 7, Blocks.stonebrick);
        world.setBlock(i + 8, j + 6, k + 12, Blocks.stonebrick);
        world.setBlock(i + 8, j + 7, k + 7, Blocks.stonebrick);
        world.setBlock(i + 8, j + 7, k + 12, Blocks.stonebrick);
        world.setBlock(i + 8, j + 8, k + 7, Blocks.stonebrick);
        world.setBlock(i + 8, j + 8, k + 12, Blocks.stonebrick);
        world.setBlock(i + 8, j + 9, k + 7, Blocks.stonebrick);
        world.setBlock(i + 8, j + 9, k + 12, Blocks.stonebrick);
        world.setBlock(i + 8, j + 10, k + 7, Blocks.stonebrick);
        world.setBlock(i + 8, j + 10, k + 12, Blocks.stonebrick);
        world.setBlock(i + 8, j + 11, k + 7, Blocks.stonebrick);
        world.setBlock(i + 8, j + 11, k + 9, Blocks.stonebrick);
        world.setBlock(i + 8, j + 11, k + 10, Blocks.stonebrick);
        world.setBlock(i + 8, j + 11, k + 12, Blocks.stonebrick);
        world.setBlock(i + 8, j + 12, k + 6, Blocks.stonebrick);
        world.setBlock(i + 8, j + 12, k + 7, Blocks.stonebrick);
        world.setBlock(i + 8, j + 12, k + 12, Blocks.stonebrick);
        world.setBlock(i + 8, j + 12, k + 13, Blocks.stonebrick);
        world.setBlock(i + 8, j + 13, k + 6, Blocks.stonebrick);
        world.setBlock(i + 8, j + 13, k + 13, Blocks.stonebrick);
        world.setBlock(i + 9, j + 0, k + 0, Blocks.grass);
        world.setBlock(i + 9, j + 0, k + 1, Blocks.dirt);
        world.setBlock(i + 9, j + 0, k + 2, Blocks.grass);
        world.setBlock(i + 9, j + 0, k + 3, Blocks.grass);
        world.setBlock(i + 9, j + 0, k + 4, Blocks.grass);
        world.setBlock(i + 9, j + 0, k + 5, Blocks.dirt);
        world.setBlock(i + 9, j + 0, k + 6, Blocks.grass);
        world.setBlock(i + 9, j + 0, k + 7, Blocks.grass);
        world.setBlock(i + 9, j + 0, k + 8, Blocks.grass);
        world.setBlock(i + 9, j + 0, k + 9, Blocks.grass);
        world.setBlock(i + 9, j + 0, k + 10, Blocks.grass);
        world.setBlock(i + 9, j + 0, k + 11, Blocks.grass);
        world.setBlock(i + 9, j + 0, k + 12, Blocks.grass);
        world.setBlock(i + 9, j + 0, k + 13, Blocks.grass);
        world.setBlock(i + 9, j + 0, k + 14, Blocks.dirt);
        world.setBlock(i + 9, j + 0, k + 15, Blocks.grass);
        world.setBlock(i + 9, j + 0, k + 16, Blocks.grass);
        world.setBlock(i + 9, j + 0, k + 17, Blocks.grass);
        world.setBlock(i + 9, j + 0, k + 18, Blocks.dirt);
        world.setBlock(i + 9, j + 0, k + 19, Blocks.grass);
        world.setBlock(i + 9, j + 1, k + 1, Blocks.cobblestone);
        world.setBlock(i + 9, j + 1, k + 5, Blocks.cobblestone);
        world.setBlock(i + 9, j + 1, k + 14, Blocks.cobblestone);
        world.setBlock(i + 9, j + 1, k + 18, Blocks.cobblestone);
        world.setBlock(i + 9, j + 2, k + 1, Blocks.cobblestone);
        world.setBlock(i + 9, j + 2, k + 5, Blocks.cobblestone);
        world.setBlock(i + 9, j + 2, k + 14, Blocks.cobblestone);
        world.setBlock(i + 9, j + 2, k + 18, Blocks.cobblestone);
        world.setBlock(i + 9, j + 3, k + 1, Blocks.cobblestone);
        world.setBlock(i + 9, j + 3, k + 5, Blocks.cobblestone);
        world.setBlock(i + 9, j + 3, k + 14, Blocks.cobblestone);
        world.setBlock(i + 9, j + 3, k + 18, Blocks.cobblestone);
        world.setBlock(i + 9, j + 4, k + 5, Blocks.cobblestone);
        world.setBlock(i + 9, j + 4, k + 6, Blocks.cobblestone);
        world.setBlock(i + 9, j + 4, k + 7, Blocks.cobblestone);
        world.setBlock(i + 9, j + 4, k + 8, Blocks.stonebrick);
        world.setBlock(i + 9, j + 4, k + 9, Blocks.stonebrick);
        world.setBlock(i + 9, j + 4, k + 10, Blocks.stonebrick);
        world.setBlock(i + 9, j + 4, k + 11, Blocks.stonebrick);
        world.setBlock(i + 9, j + 4, k + 12, Blocks.cobblestone);
        world.setBlock(i + 9, j + 4, k + 13, Blocks.cobblestone);
        world.setBlock(i + 9, j + 4, k + 14, Blocks.cobblestone);
        world.setBlock(i + 9, j + 7, k + 7, Blocks.stonebrick);
        world.setBlock(i + 9, j + 7, k + 12, Blocks.stonebrick);
        world.setBlock(i + 9, j + 8, k + 7, Blocks.stonebrick);
        world.setBlock(i + 9, j + 8, k + 12, Blocks.stonebrick);
        world.setBlock(i + 9, j + 9, k + 7, Blocks.stonebrick);
        world.setBlock(i + 9, j + 9, k + 12, Blocks.stonebrick);
        world.setBlock(i + 9, j + 10, k + 7, Blocks.stonebrick);
        world.setBlock(i + 9, j + 10, k + 12, Blocks.stonebrick);
        world.setBlock(i + 9, j + 11, k + 7, Blocks.stonebrick);
        world.setBlock(i + 9, j + 11, k + 8, Blocks.stonebrick);
        world.setBlock(i + 9, j + 11, k + 9, Blocks.stonebrick);
        world.setBlock(i + 9, j + 11, k + 10, Blocks.stonebrick);
        world.setBlock(i + 9, j + 11, k + 11, Blocks.stonebrick);
        world.setBlock(i + 9, j + 11, k + 12, Blocks.stonebrick);
        world.setBlock(i + 9, j + 12, k + 6, Blocks.stonebrick);
        world.setBlock(i + 9, j + 12, k + 7, Blocks.stonebrick);
        Dungeons.spawner(world, i + 9, j + 12, k + 9, 12, 2);
        WorldGenWarlordDungeon.chest(world, rand, i + 9, j + 12, k + 10, "dungeonChest", rand.nextInt(5) + 1);
        world.setBlock(i + 9, j + 12, k + 12, Blocks.stonebrick);
        world.setBlock(i + 9, j + 12, k + 13, Blocks.stonebrick);
        world.setBlock(i + 9, j + 13, k + 6, Blocks.stonebrick);
        world.setBlock(i + 9, j + 13, k + 13, Blocks.stonebrick);
        world.setBlock(i + 9, j + 14, k + 6, Blocks.stonebrick);
        world.setBlock(i + 9, j + 14, k + 13, Blocks.stonebrick);
        world.setBlock(i + 10, j + 0, k + 0, Blocks.grass);
        world.setBlock(i + 10, j + 0, k + 1, Blocks.dirt);
        world.setBlock(i + 10, j + 0, k + 2, Blocks.grass);
        world.setBlock(i + 10, j + 0, k + 3, Blocks.grass);
        world.setBlock(i + 10, j + 0, k + 4, Blocks.grass);
        world.setBlock(i + 10, j + 0, k + 5, Blocks.dirt);
        world.setBlock(i + 10, j + 0, k + 6, Blocks.grass);
        world.setBlock(i + 10, j + 0, k + 7, Blocks.grass);
        world.setBlock(i + 10, j + 0, k + 8, Blocks.grass);
        world.setBlock(i + 10, j + 0, k + 9, Blocks.grass);
        world.setBlock(i + 10, j + 0, k + 10, Blocks.grass);
        world.setBlock(i + 10, j + 0, k + 11, Blocks.grass);
        world.setBlock(i + 10, j + 0, k + 12, Blocks.grass);
        world.setBlock(i + 10, j + 0, k + 13, Blocks.grass);
        world.setBlock(i + 10, j + 0, k + 14, Blocks.dirt);
        world.setBlock(i + 10, j + 0, k + 15, Blocks.grass);
        world.setBlock(i + 10, j + 0, k + 16, Blocks.grass);
        world.setBlock(i + 10, j + 0, k + 17, Blocks.grass);
        world.setBlock(i + 10, j + 0, k + 18, Blocks.dirt);
        world.setBlock(i + 10, j + 0, k + 19, Blocks.grass);
        world.setBlock(i + 10, j + 1, k + 1, Blocks.cobblestone);
        world.setBlock(i + 10, j + 1, k + 5, Blocks.cobblestone);
        world.setBlock(i + 10, j + 1, k + 14, Blocks.cobblestone);
        world.setBlock(i + 10, j + 1, k + 18, Blocks.cobblestone);
        world.setBlock(i + 10, j + 2, k + 1, Blocks.cobblestone);
        world.setBlock(i + 10, j + 2, k + 5, Blocks.cobblestone);
        world.setBlock(i + 10, j + 2, k + 14, Blocks.cobblestone);
        world.setBlock(i + 10, j + 2, k + 18, Blocks.cobblestone);
        world.setBlock(i + 10, j + 3, k + 1, Blocks.cobblestone);
        world.setBlock(i + 10, j + 3, k + 5, Blocks.cobblestone);
        world.setBlock(i + 10, j + 3, k + 14, Blocks.cobblestone);
        world.setBlock(i + 10, j + 3, k + 18, Blocks.cobblestone);
        world.setBlock(i + 10, j + 4, k + 5, Blocks.cobblestone);
        world.setBlock(i + 10, j + 4, k + 6, Blocks.cobblestone);
        world.setBlock(i + 10, j + 4, k + 7, Blocks.cobblestone);
        world.setBlock(i + 10, j + 4, k + 8, Blocks.stonebrick);
        world.setBlock(i + 10, j + 4, k + 9, Blocks.stonebrick);
        world.setBlock(i + 10, j + 4, k + 10, Blocks.stonebrick);
        world.setBlock(i + 10, j + 4, k + 11, Blocks.stonebrick);
        world.setBlock(i + 10, j + 4, k + 12, Blocks.cobblestone);
        world.setBlock(i + 10, j + 4, k + 13, Blocks.cobblestone);
        world.setBlock(i + 10, j + 4, k + 14, Blocks.cobblestone);
        world.setBlock(i + 10, j + 7, k + 7, Blocks.stonebrick);
        world.setBlock(i + 10, j + 7, k + 12, Blocks.stonebrick);
        world.setBlock(i + 10, j + 8, k + 7, Blocks.stonebrick);
        world.setBlock(i + 10, j + 8, k + 12, Blocks.stonebrick);
        world.setBlock(i + 10, j + 9, k + 7, Blocks.stonebrick);
        world.setBlock(i + 10, j + 9, k + 12, Blocks.stonebrick);
        world.setBlock(i + 10, j + 10, k + 7, Blocks.stonebrick);
        world.setBlock(i + 10, j + 10, k + 12, Blocks.stonebrick);
        world.setBlock(i + 10, j + 11, k + 7, Blocks.stonebrick);
        world.setBlock(i + 10, j + 11, k + 8, Blocks.stonebrick);
        world.setBlock(i + 10, j + 11, k + 9, Blocks.stonebrick);
        world.setBlock(i + 10, j + 11, k + 10, Blocks.stonebrick);
        world.setBlock(i + 10, j + 11, k + 11, Blocks.stonebrick);
        world.setBlock(i + 10, j + 11, k + 12, Blocks.stonebrick);
        world.setBlock(i + 10, j + 12, k + 6, Blocks.stonebrick);
        world.setBlock(i + 10, j + 12, k + 7, Blocks.stonebrick);
        WorldGenWarlordDungeon.chest(world, rand, i + 10, j + 12, k + 9, "dungeonChest", rand.nextInt(5) + 1);
        Dungeons.spawner(world, i + 10, j + 12, k + 10, 12, 2);
        world.setBlock(i + 10, j + 12, k + 12, Blocks.stonebrick);
        world.setBlock(i + 10, j + 12, k + 13, Blocks.stonebrick);
        world.setBlock(i + 10, j + 13, k + 6, Blocks.stonebrick);
        world.setBlock(i + 10, j + 13, k + 13, Blocks.stonebrick);
        world.setBlock(i + 10, j + 14, k + 6, Blocks.stonebrick);
        world.setBlock(i + 10, j + 14, k + 13, Blocks.stonebrick);
        world.setBlock(i + 11, j + 0, k + 0, Blocks.grass);
        world.setBlock(i + 11, j + 0, k + 1, Blocks.dirt);
        world.setBlock(i + 11, j + 0, k + 2, Blocks.grass);
        world.setBlock(i + 11, j + 0, k + 3, Blocks.grass);
        world.setBlock(i + 11, j + 0, k + 4, Blocks.grass);
        world.setBlock(i + 11, j + 0, k + 5, Blocks.dirt);
        world.setBlock(i + 11, j + 0, k + 6, Blocks.grass);
        world.setBlock(i + 11, j + 0, k + 7, Blocks.grass);
        world.setBlock(i + 11, j + 0, k + 8, Blocks.grass);
        world.setBlock(i + 11, j + 0, k + 9, Blocks.grass);
        world.setBlock(i + 11, j + 0, k + 10, Blocks.grass);
        world.setBlock(i + 11, j + 0, k + 11, Blocks.grass);
        world.setBlock(i + 11, j + 0, k + 12, Blocks.grass);
        world.setBlock(i + 11, j + 0, k + 13, Blocks.grass);
        world.setBlock(i + 11, j + 0, k + 14, Blocks.dirt);
        world.setBlock(i + 11, j + 0, k + 15, Blocks.grass);
        world.setBlock(i + 11, j + 0, k + 16, Blocks.grass);
        world.setBlock(i + 11, j + 0, k + 17, Blocks.grass);
        world.setBlock(i + 11, j + 0, k + 18, Blocks.dirt);
        world.setBlock(i + 11, j + 0, k + 19, Blocks.grass);
        world.setBlock(i + 11, j + 1, k + 1, Blocks.cobblestone);
        world.setBlock(i + 11, j + 1, k + 5, Blocks.cobblestone);
        world.setBlock(i + 11, j + 1, k + 14, Blocks.cobblestone);
        world.setBlock(i + 11, j + 1, k + 18, Blocks.cobblestone);
        world.setBlock(i + 11, j + 2, k + 1, Blocks.cobblestone);
        world.setBlock(i + 11, j + 2, k + 5, Blocks.cobblestone);
        world.setBlock(i + 11, j + 2, k + 14, Blocks.cobblestone);
        world.setBlock(i + 11, j + 2, k + 18, Blocks.cobblestone);
        world.setBlock(i + 11, j + 3, k + 5, Blocks.cobblestone);
        world.setBlock(i + 11, j + 3, k + 14, Blocks.cobblestone);
        world.setBlock(i + 11, j + 4, k + 5, Blocks.cobblestone);
        world.setBlock(i + 11, j + 4, k + 6, Blocks.cobblestone);
        world.setBlock(i + 11, j + 4, k + 7, Blocks.cobblestone);
        world.setBlock(i + 11, j + 4, k + 9, Blocks.stonebrick);
        world.setBlock(i + 11, j + 4, k + 10, Blocks.stonebrick);
        world.setBlock(i + 11, j + 4, k + 12, Blocks.cobblestone);
        world.setBlock(i + 11, j + 4, k + 13, Blocks.cobblestone);
        world.setBlock(i + 11, j + 4, k + 14, Blocks.cobblestone);
        world.setBlock(i + 11, j + 5, k + 5, Blocks.cobblestone);
        world.setBlock(i + 11, j + 5, k + 6, Blocks.stone_stairs);
        world.setBlock(i + 11, j + 5, k + 7, Blocks.stonebrick);
        world.setBlock(i + 11, j + 5, k + 12, Blocks.stonebrick);
        world.setBlock(i + 11, j + 5, k + 13, Blocks.stone_stairs);
        world.setBlock(i + 11, j + 5, k + 14, Blocks.cobblestone);
        world.setBlock(i + 11, j + 6, k + 7, Blocks.stonebrick);
        world.setBlock(i + 11, j + 6, k + 12, Blocks.stonebrick);
        world.setBlock(i + 11, j + 7, k + 7, Blocks.stonebrick);
        world.setBlock(i + 11, j + 7, k + 12, Blocks.stonebrick);
        world.setBlock(i + 11, j + 8, k + 7, Blocks.stonebrick);
        world.setBlock(i + 11, j + 8, k + 12, Blocks.stonebrick);
        world.setBlock(i + 11, j + 9, k + 7, Blocks.stonebrick);
        world.setBlock(i + 11, j + 9, k + 12, Blocks.stonebrick);
        world.setBlock(i + 11, j + 10, k + 7, Blocks.stonebrick);
        world.setBlock(i + 11, j + 10, k + 12, Blocks.stonebrick);
        world.setBlock(i + 11, j + 11, k + 7, Blocks.stonebrick);
        world.setBlock(i + 11, j + 11, k + 9, Blocks.stonebrick);
        world.setBlock(i + 11, j + 11, k + 10, Blocks.stonebrick);
        world.setBlock(i + 11, j + 11, k + 12, Blocks.stonebrick);
        world.setBlock(i + 11, j + 12, k + 6, Blocks.stonebrick);
        world.setBlock(i + 11, j + 12, k + 7, Blocks.stonebrick);
        world.setBlock(i + 11, j + 12, k + 12, Blocks.stonebrick);
        world.setBlock(i + 11, j + 12, k + 13, Blocks.stonebrick);
        world.setBlock(i + 11, j + 13, k + 6, Blocks.stonebrick);
        world.setBlock(i + 11, j + 13, k + 13, Blocks.stonebrick);
        world.setBlock(i + 12, j + 0, k + 0, Blocks.grass);
        world.setBlock(i + 12, j + 0, k + 1, Blocks.dirt);
        world.setBlock(i + 12, j + 0, k + 2, Blocks.grass);
        world.setBlock(i + 12, j + 0, k + 3, Blocks.grass);
        world.setBlock(i + 12, j + 0, k + 4, Blocks.dirt);
        world.setBlock(i + 12, j + 0, k + 5, Blocks.dirt);
        world.setBlock(i + 12, j + 0, k + 6, Blocks.dirt);
        world.setBlock(i + 12, j + 0, k + 7, Blocks.dirt);
        world.setBlock(i + 12, j + 0, k + 8, Blocks.dirt);
        world.setBlock(i + 12, j + 0, k + 9, Blocks.grass);
        world.setBlock(i + 12, j + 0, k + 10, Blocks.grass);
        world.setBlock(i + 12, j + 0, k + 11, Blocks.dirt);
        world.setBlock(i + 12, j + 0, k + 12, Blocks.dirt);
        world.setBlock(i + 12, j + 0, k + 13, Blocks.dirt);
        world.setBlock(i + 12, j + 0, k + 14, Blocks.dirt);
        world.setBlock(i + 12, j + 0, k + 15, Blocks.dirt);
        world.setBlock(i + 12, j + 0, k + 16, Blocks.grass);
        world.setBlock(i + 12, j + 0, k + 17, Blocks.grass);
        world.setBlock(i + 12, j + 0, k + 18, Blocks.dirt);
        world.setBlock(i + 12, j + 0, k + 19, Blocks.grass);
        world.setBlock(i + 12, j + 1, k + 1, Blocks.cobblestone);
        world.setBlock(i + 12, j + 1, k + 4, Blocks.cobblestone);
        world.setBlock(i + 12, j + 1, k + 5, Blocks.cobblestone);
        world.setBlock(i + 12, j + 1, k + 6, Blocks.cobblestone);
        world.setBlock(i + 12, j + 1, k + 7, Blocks.cobblestone);
        world.setBlock(i + 12, j + 1, k + 8, Blocks.cobblestone);
        world.setBlock(i + 12, j + 1, k + 11, Blocks.cobblestone);
        world.setBlock(i + 12, j + 1, k + 12, Blocks.cobblestone);
        world.setBlock(i + 12, j + 1, k + 13, Blocks.cobblestone);
        world.setBlock(i + 12, j + 1, k + 14, Blocks.cobblestone);
        world.setBlock(i + 12, j + 1, k + 15, Blocks.cobblestone);
        world.setBlock(i + 12, j + 1, k + 18, Blocks.cobblestone);
        world.setBlock(i + 12, j + 2, k + 1, Blocks.cobblestone);
        world.setBlock(i + 12, j + 2, k + 4, Blocks.cobblestone);
        world.setBlock(i + 12, j + 2, k + 5, Blocks.cobblestone);
        world.setBlock(i + 12, j + 2, k + 6, Blocks.cobblestone);
        world.setBlock(i + 12, j + 2, k + 7, Blocks.cobblestone);
        world.setBlock(i + 12, j + 2, k + 8, Blocks.cobblestone);
        world.setBlock(i + 12, j + 2, k + 11, Blocks.cobblestone);
        world.setBlock(i + 12, j + 2, k + 12, Blocks.cobblestone);
        world.setBlock(i + 12, j + 2, k + 13, Blocks.cobblestone);
        world.setBlock(i + 12, j + 2, k + 14, Blocks.cobblestone);
        world.setBlock(i + 12, j + 2, k + 15, Blocks.cobblestone);
        world.setBlock(i + 12, j + 2, k + 18, Blocks.cobblestone);
        world.setBlock(i + 12, j + 3, k + 1, Blocks.cobblestone);
        world.setBlock(i + 12, j + 3, k + 4, Blocks.cobblestone);
        world.setBlock(i + 12, j + 3, k + 5, Blocks.cobblestone);
        world.setBlock(i + 12, j + 3, k + 6, Blocks.cobblestone);
        world.setBlock(i + 12, j + 3, k + 7, Blocks.cobblestone);
        world.setBlock(i + 12, j + 3, k + 8, Blocks.cobblestone);
        world.setBlock(i + 12, j + 3, k + 11, Blocks.cobblestone);
        world.setBlock(i + 12, j + 3, k + 12, Blocks.cobblestone);
        world.setBlock(i + 12, j + 3, k + 13, Blocks.cobblestone);
        world.setBlock(i + 12, j + 3, k + 14, Blocks.cobblestone);
        world.setBlock(i + 12, j + 3, k + 15, Blocks.cobblestone);
        world.setBlock(i + 12, j + 3, k + 18, Blocks.cobblestone);
        world.setBlock(i + 12, j + 4, k + 4, Blocks.cobblestone);
        world.setBlock(i + 12, j + 4, k + 5, Blocks.cobblestone);
        world.setBlock(i + 12, j + 4, k + 6, Blocks.cobblestone);
        world.setBlock(i + 12, j + 4, k + 7, Blocks.cobblestone);
        world.setBlock(i + 12, j + 4, k + 8, Blocks.cobblestone);
        world.setBlock(i + 12, j + 4, k + 9, Blocks.cobblestone);
        world.setBlock(i + 12, j + 4, k + 10, Blocks.cobblestone);
        world.setBlock(i + 12, j + 4, k + 11, Blocks.cobblestone);
        world.setBlock(i + 12, j + 4, k + 12, Blocks.cobblestone);
        world.setBlock(i + 12, j + 4, k + 13, Blocks.cobblestone);
        world.setBlock(i + 12, j + 4, k + 14, Blocks.cobblestone);
        world.setBlock(i + 12, j + 4, k + 15, Blocks.cobblestone);
        world.setBlock(i + 12, j + 5, k + 4, Blocks.stonebrick);
        world.setBlock(i + 12, j + 5, k + 5, Blocks.stonebrick);
        world.setBlock(i + 12, j + 5, k + 6, Blocks.stonebrick);
        world.setBlock(i + 12, j + 5, k + 7, Blocks.stonebrick);
        world.setBlock(i + 12, j + 5, k + 8, Blocks.stonebrick);
        world.setBlock(i + 12, j + 5, k + 11, Blocks.stonebrick);
        world.setBlock(i + 12, j + 5, k + 12, Blocks.stonebrick);
        world.setBlock(i + 12, j + 5, k + 13, Blocks.stonebrick);
        world.setBlock(i + 12, j + 5, k + 14, Blocks.stonebrick);
        world.setBlock(i + 12, j + 5, k + 15, Blocks.stonebrick);
        world.setBlock(i + 12, j + 6, k + 4, Blocks.stonebrick);
        world.setBlock(i + 12, j + 6, k + 5, Blocks.stonebrick);
        world.setBlock(i + 12, j + 6, k + 7, Blocks.stonebrick);
        world.setBlock(i + 12, j + 6, k + 8, Blocks.stonebrick);
        world.setBlock(i + 12, j + 6, k + 11, Blocks.stonebrick);
        world.setBlock(i + 12, j + 6, k + 12, Blocks.stonebrick);
        world.setBlock(i + 12, j + 6, k + 14, Blocks.stonebrick);
        world.setBlock(i + 12, j + 6, k + 15, Blocks.stonebrick);
        world.setBlock(i + 12, j + 7, k + 4, Blocks.stonebrick);
        world.setBlock(i + 12, j + 7, k + 7, Blocks.stonebrick);
        world.setBlock(i + 12, j + 7, k + 8, Blocks.stonebrick);
        world.setBlock(i + 12, j + 7, k + 9, Blocks.stonebrick);
        world.setBlock(i + 12, j + 7, k + 10, Blocks.stonebrick);
        world.setBlock(i + 12, j + 7, k + 11, Blocks.stonebrick);
        world.setBlock(i + 12, j + 7, k + 12, Blocks.stonebrick);
        world.setBlock(i + 12, j + 7, k + 15, Blocks.stonebrick);
        world.setBlock(i + 12, j + 8, k + 7, Blocks.stonebrick);
        world.setBlock(i + 12, j + 8, k + 8, Blocks.stonebrick);
        world.setBlock(i + 12, j + 8, k + 9, Blocks.stonebrick);
        world.setBlock(i + 12, j + 8, k + 10, Blocks.stonebrick);
        world.setBlock(i + 12, j + 8, k + 11, Blocks.stonebrick);
        world.setBlock(i + 12, j + 8, k + 12, Blocks.stonebrick);
        world.setBlock(i + 12, j + 9, k + 7, Blocks.stonebrick);
        world.setBlock(i + 12, j + 9, k + 8, Blocks.stonebrick);
        world.setBlock(i + 12, j + 9, k + 9, Blocks.stonebrick);
        world.setBlock(i + 12, j + 9, k + 10, Blocks.stonebrick);
        world.setBlock(i + 12, j + 9, k + 11, Blocks.stonebrick);
        world.setBlock(i + 12, j + 9, k + 12, Blocks.stonebrick);
        world.setBlock(i + 12, j + 10, k + 7, Blocks.stonebrick);
        world.setBlock(i + 12, j + 10, k + 8, Blocks.stonebrick);
        world.setBlock(i + 12, j + 10, k + 9, Blocks.stonebrick);
        world.setBlock(i + 12, j + 10, k + 10, Blocks.stonebrick);
        world.setBlock(i + 12, j + 10, k + 11, Blocks.stonebrick);
        world.setBlock(i + 12, j + 10, k + 12, Blocks.stonebrick);
        world.setBlock(i + 12, j + 11, k + 7, Blocks.stonebrick);
        world.setBlock(i + 12, j + 11, k + 8, Blocks.stonebrick);
        world.setBlock(i + 12, j + 11, k + 9, Blocks.stonebrick);
        world.setBlock(i + 12, j + 11, k + 10, Blocks.stonebrick);
        world.setBlock(i + 12, j + 11, k + 11, Blocks.stonebrick);
        world.setBlock(i + 12, j + 11, k + 12, Blocks.stonebrick);
        world.setBlock(i + 12, j + 12, k + 6, Blocks.stonebrick);
        world.setBlock(i + 12, j + 12, k + 7, Blocks.stonebrick);
        world.setBlock(i + 12, j + 12, k + 8, Blocks.stonebrick);
        world.setBlock(i + 12, j + 12, k + 9, Blocks.stonebrick);
        world.setBlock(i + 12, j + 12, k + 10, Blocks.stonebrick);
        world.setBlock(i + 12, j + 12, k + 11, Blocks.stonebrick);
        world.setBlock(i + 12, j + 12, k + 12, Blocks.stonebrick);
        world.setBlock(i + 12, j + 12, k + 13, Blocks.stonebrick);
        world.setBlock(i + 12, j + 13, k + 6, Blocks.stonebrick);
        world.setBlock(i + 12, j + 13, k + 13, Blocks.stonebrick);
        world.setBlock(i + 13, j + 0, k + 0, Blocks.grass);
        world.setBlock(i + 13, j + 0, k + 1, Blocks.dirt);
        world.setBlock(i + 13, j + 0, k + 2, Blocks.grass);
        world.setBlock(i + 13, j + 0, k + 3, Blocks.grass);
        world.setBlock(i + 13, j + 0, k + 4, Blocks.dirt);
        world.setBlock(i + 13, j + 0, k + 5, Blocks.grass);
        world.setBlock(i + 13, j + 0, k + 6, Blocks.grass);
        world.setBlock(i + 13, j + 0, k + 7, Blocks.dirt);
        world.setBlock(i + 13, j + 0, k + 8, Blocks.grass);
        world.setBlock(i + 13, j + 0, k + 9, Blocks.grass);
        world.setBlock(i + 13, j + 0, k + 10, Blocks.grass);
        world.setBlock(i + 13, j + 0, k + 11, Blocks.grass);
        world.setBlock(i + 13, j + 0, k + 12, Blocks.dirt);
        world.setBlock(i + 13, j + 0, k + 13, Blocks.grass);
        world.setBlock(i + 13, j + 0, k + 14, Blocks.grass);
        world.setBlock(i + 13, j + 0, k + 15, Blocks.dirt);
        world.setBlock(i + 13, j + 0, k + 16, Blocks.grass);
        world.setBlock(i + 13, j + 0, k + 17, Blocks.grass);
        world.setBlock(i + 13, j + 0, k + 18, Blocks.dirt);
        world.setBlock(i + 13, j + 0, k + 19, Blocks.grass);
        world.setBlock(i + 13, j + 1, k + 1, Blocks.cobblestone);
        world.setBlock(i + 13, j + 1, k + 4, Blocks.cobblestone);
        world.setBlock(i + 13, j + 1, k + 7, Blocks.cobblestone);
        WorldGenWarlordDungeon.chest(world, rand, i + 13, j + 1, k + 8, "dungeonChest", rand.nextInt(5) + 1);
        Dungeons.spawner(world, i + 13, j + 1, k + 11, 12, 2);
        world.setBlock(i + 13, j + 1, k + 12, Blocks.cobblestone);
        world.setBlock(i + 13, j + 1, k + 15, Blocks.cobblestone);
        world.setBlock(i + 13, j + 1, k + 18, Blocks.cobblestone);
        world.setBlock(i + 13, j + 2, k + 1, Blocks.cobblestone);
        world.setBlock(i + 13, j + 2, k + 4, Blocks.cobblestone);
        world.setBlock(i + 13, j + 2, k + 7, Blocks.cobblestone);
        world.setBlock(i + 13, j + 2, k + 12, Blocks.cobblestone);
        world.setBlock(i + 13, j + 2, k + 15, Blocks.cobblestone);
        world.setBlock(i + 13, j + 2, k + 18, Blocks.cobblestone);
        world.setBlock(i + 13, j + 3, k + 1, Blocks.cobblestone);
        world.setBlock(i + 13, j + 3, k + 4, Blocks.cobblestone);
        world.setBlock(i + 13, j + 3, k + 7, Blocks.cobblestone);
        world.setBlock(i + 13, j + 3, k + 12, Blocks.cobblestone);
        world.setBlock(i + 13, j + 3, k + 15, Blocks.cobblestone);
        world.setBlock(i + 13, j + 3, k + 18, Blocks.cobblestone);
        world.setBlock(i + 13, j + 4, k + 4, Blocks.cobblestone);
        world.setBlock(i + 13, j + 4, k + 7, Blocks.cobblestone);
        world.setBlock(i + 13, j + 4, k + 8, Blocks.cobblestone);
        world.setBlock(i + 13, j + 4, k + 9, Blocks.cobblestone);
        world.setBlock(i + 13, j + 4, k + 10, Blocks.cobblestone);
        world.setBlock(i + 13, j + 4, k + 11, Blocks.cobblestone);
        world.setBlock(i + 13, j + 4, k + 12, Blocks.cobblestone);
        world.setBlock(i + 13, j + 4, k + 15, Blocks.cobblestone);
        world.setBlock(i + 13, j + 5, k + 4, Blocks.stonebrick);
        world.setBlock(i + 13, j + 5, k + 5, Blocks.stonebrick);
        world.setBlock(i + 13, j + 5, k + 6, Blocks.stonebrick);
        world.setBlock(i + 13, j + 5, k + 7, Blocks.stonebrick);
        world.setBlock(i + 13, j + 5, k + 8, Blocks.stone_stairs, 3, 0);
        world.setBlock(i + 13, j + 5, k + 11, Blocks.stone_stairs, 2, 0);
        world.setBlock(i + 13, j + 5, k + 12, Blocks.stonebrick);
        world.setBlock(i + 13, j + 5, k + 13, Blocks.stonebrick);
        world.setBlock(i + 13, j + 5, k + 14, Blocks.stonebrick);
        world.setBlock(i + 13, j + 5, k + 15, Blocks.stonebrick);
        world.setBlock(i + 13, j + 6, k + 4, Blocks.stonebrick);
        world.setBlock(i + 13, j + 6, k + 15, Blocks.stonebrick);
        world.setBlock(i + 13, j + 12, k + 6, Blocks.stonebrick);
        world.setBlock(i + 13, j + 12, k + 7, Blocks.stonebrick);
        world.setBlock(i + 13, j + 12, k + 8, Blocks.stonebrick);
        world.setBlock(i + 13, j + 12, k + 9, Blocks.stonebrick);
        world.setBlock(i + 13, j + 12, k + 10, Blocks.stonebrick);
        world.setBlock(i + 13, j + 12, k + 11, Blocks.stonebrick);
        world.setBlock(i + 13, j + 12, k + 12, Blocks.stonebrick);
        world.setBlock(i + 13, j + 12, k + 13, Blocks.stonebrick);
        world.setBlock(i + 13, j + 13, k + 6, Blocks.stonebrick);
        world.setBlock(i + 13, j + 13, k + 7, Blocks.stonebrick);
        world.setBlock(i + 13, j + 13, k + 8, Blocks.stonebrick);
        world.setBlock(i + 13, j + 13, k + 9, Blocks.stonebrick);
        world.setBlock(i + 13, j + 13, k + 10, Blocks.stonebrick);
        world.setBlock(i + 13, j + 13, k + 11, Blocks.stonebrick);
        world.setBlock(i + 13, j + 13, k + 12, Blocks.stonebrick);
        world.setBlock(i + 13, j + 13, k + 13, Blocks.stonebrick);
        world.setBlock(i + 13, j + 14, k + 6, Blocks.stonebrick);
        world.setBlock(i + 13, j + 14, k + 9, Blocks.stonebrick);
        world.setBlock(i + 13, j + 14, k + 10, Blocks.stonebrick);
        world.setBlock(i + 13, j + 14, k + 13, Blocks.stonebrick);
        world.setBlock(i + 14, j + 0, k + 0, Blocks.grass);
        world.setBlock(i + 14, j + 0, k + 1, Blocks.dirt);
        world.setBlock(i + 14, j + 0, k + 2, Blocks.grass);
        world.setBlock(i + 14, j + 0, k + 3, Blocks.grass);
        world.setBlock(i + 14, j + 0, k + 4, Blocks.dirt);
        world.setBlock(i + 14, j + 0, k + 5, Blocks.grass);
        world.setBlock(i + 14, j + 0, k + 6, Blocks.grass);
        world.setBlock(i + 14, j + 0, k + 7, Blocks.dirt);
        world.setBlock(i + 14, j + 0, k + 8, Blocks.dirt);
        world.setBlock(i + 14, j + 0, k + 9, Blocks.dirt);
        world.setBlock(i + 14, j + 0, k + 10, Blocks.dirt);
        world.setBlock(i + 14, j + 0, k + 11, Blocks.dirt);
        world.setBlock(i + 14, j + 0, k + 12, Blocks.dirt);
        world.setBlock(i + 14, j + 0, k + 13, Blocks.grass);
        world.setBlock(i + 14, j + 0, k + 14, Blocks.grass);
        world.setBlock(i + 14, j + 0, k + 15, Blocks.dirt);
        world.setBlock(i + 14, j + 0, k + 16, Blocks.grass);
        world.setBlock(i + 14, j + 0, k + 17, Blocks.grass);
        world.setBlock(i + 14, j + 0, k + 18, Blocks.dirt);
        world.setBlock(i + 14, j + 0, k + 19, Blocks.grass);
        world.setBlock(i + 14, j + 1, k + 1, Blocks.cobblestone);
        world.setBlock(i + 14, j + 1, k + 4, Blocks.cobblestone);
        world.setBlock(i + 14, j + 1, k + 7, Blocks.cobblestone);
        world.setBlock(i + 14, j + 1, k + 8, Blocks.cobblestone);
        world.setBlock(i + 14, j + 1, k + 9, Blocks.cobblestone);
        world.setBlock(i + 14, j + 1, k + 10, Blocks.cobblestone);
        world.setBlock(i + 14, j + 1, k + 11, Blocks.cobblestone);
        world.setBlock(i + 14, j + 1, k + 12, Blocks.cobblestone);
        world.setBlock(i + 14, j + 1, k + 15, Blocks.cobblestone);
        world.setBlock(i + 14, j + 1, k + 18, Blocks.cobblestone);
        world.setBlock(i + 14, j + 2, k + 1, Blocks.cobblestone);
        world.setBlock(i + 14, j + 2, k + 4, Blocks.cobblestone);
        world.setBlock(i + 14, j + 2, k + 7, Blocks.cobblestone);
        world.setBlock(i + 14, j + 2, k + 8, Blocks.cobblestone);
        world.setBlock(i + 14, j + 2, k + 9, Blocks.cobblestone);
        world.setBlock(i + 14, j + 2, k + 10, Blocks.cobblestone);
        world.setBlock(i + 14, j + 2, k + 11, Blocks.cobblestone);
        world.setBlock(i + 14, j + 2, k + 12, Blocks.cobblestone);
        world.setBlock(i + 14, j + 2, k + 15, Blocks.cobblestone);
        world.setBlock(i + 14, j + 2, k + 18, Blocks.cobblestone);
        world.setBlock(i + 14, j + 3, k + 4, Blocks.cobblestone);
        world.setBlock(i + 14, j + 3, k + 7, Blocks.cobblestone);
        world.setBlock(i + 14, j + 3, k + 8, Blocks.cobblestone);
        world.setBlock(i + 14, j + 3, k + 9, Blocks.cobblestone);
        world.setBlock(i + 14, j + 3, k + 10, Blocks.cobblestone);
        world.setBlock(i + 14, j + 3, k + 11, Blocks.cobblestone);
        world.setBlock(i + 14, j + 3, k + 12, Blocks.cobblestone);
        world.setBlock(i + 14, j + 3, k + 15, Blocks.cobblestone);
        world.setBlock(i + 14, j + 4, k + 4, Blocks.cobblestone);
        world.setBlock(i + 14, j + 4, k + 7, Blocks.cobblestone);
        world.setBlock(i + 14, j + 4, k + 8, Blocks.cobblestone);
        world.setBlock(i + 14, j + 4, k + 9, Blocks.cobblestone);
        world.setBlock(i + 14, j + 4, k + 10, Blocks.cobblestone);
        world.setBlock(i + 14, j + 4, k + 11, Blocks.cobblestone);
        world.setBlock(i + 14, j + 4, k + 12, Blocks.cobblestone);
        world.setBlock(i + 14, j + 4, k + 15, Blocks.cobblestone);
        world.setBlock(i + 14, j + 5, k + 4, Blocks.stonebrick);
        world.setBlock(i + 14, j + 5, k + 5, Blocks.stonebrick);
        world.setBlock(i + 14, j + 5, k + 6, Blocks.stonebrick);
        world.setBlock(i + 14, j + 5, k + 7, Blocks.stonebrick);
        world.setBlock(i + 14, j + 5, k + 8, Blocks.cobblestone);
        world.setBlock(i + 14, j + 5, k + 11, Blocks.cobblestone);
        world.setBlock(i + 14, j + 5, k + 12, Blocks.stonebrick);
        world.setBlock(i + 14, j + 5, k + 13, Blocks.stonebrick);
        world.setBlock(i + 14, j + 5, k + 14, Blocks.stonebrick);
        world.setBlock(i + 14, j + 5, k + 15, Blocks.stonebrick);
        world.setBlock(i + 14, j + 6, k + 4, Blocks.stonebrick);
        world.setBlock(i + 14, j + 6, k + 7, Blocks.stonebrick);
        world.setBlock(i + 14, j + 6, k + 12, Blocks.stonebrick);
        Dungeons.spawner(world, i + 14, j + 6, k + 14, 12, 2);
        world.setBlock(i + 14, j + 6, k + 15, Blocks.stonebrick);
        world.setBlock(i + 15, j + 0, k + 0, Blocks.grass);
        world.setBlock(i + 15, j + 0, k + 1, Blocks.dirt);
        world.setBlock(i + 15, j + 0, k + 2, Blocks.grass);
        world.setBlock(i + 15, j + 0, k + 3, Blocks.grass);
        world.setBlock(i + 15, j + 0, k + 4, Blocks.dirt);
        world.setBlock(i + 15, j + 0, k + 5, Blocks.dirt);
        world.setBlock(i + 15, j + 0, k + 6, Blocks.dirt);
        world.setBlock(i + 15, j + 0, k + 7, Blocks.dirt);
        world.setBlock(i + 15, j + 0, k + 8, Blocks.grass);
        world.setBlock(i + 15, j + 0, k + 9, Blocks.grass);
        world.setBlock(i + 15, j + 0, k + 10, Blocks.grass);
        world.setBlock(i + 15, j + 0, k + 11, Blocks.grass);
        world.setBlock(i + 15, j + 0, k + 12, Blocks.dirt);
        world.setBlock(i + 15, j + 0, k + 13, Blocks.dirt);
        world.setBlock(i + 15, j + 0, k + 14, Blocks.dirt);
        world.setBlock(i + 15, j + 0, k + 15, Blocks.dirt);
        world.setBlock(i + 15, j + 0, k + 16, Blocks.grass);
        world.setBlock(i + 15, j + 0, k + 17, Blocks.grass);
        world.setBlock(i + 15, j + 0, k + 18, Blocks.dirt);
        world.setBlock(i + 15, j + 0, k + 19, Blocks.grass);
        world.setBlock(i + 15, j + 1, k + 1, Blocks.cobblestone);
        world.setBlock(i + 15, j + 1, k + 4, Blocks.cobblestone);
        world.setBlock(i + 15, j + 1, k + 5, Blocks.cobblestone);
        world.setBlock(i + 15, j + 1, k + 6, Blocks.cobblestone);
        world.setBlock(i + 15, j + 1, k + 7, Blocks.cobblestone);
        world.setBlock(i + 15, j + 1, k + 12, Blocks.cobblestone);
        world.setBlock(i + 15, j + 1, k + 13, Blocks.cobblestone);
        world.setBlock(i + 15, j + 1, k + 14, Blocks.cobblestone);
        world.setBlock(i + 15, j + 1, k + 15, Blocks.cobblestone);
        world.setBlock(i + 15, j + 1, k + 18, Blocks.cobblestone);
        world.setBlock(i + 15, j + 2, k + 1, Blocks.cobblestone);
        world.setBlock(i + 15, j + 2, k + 4, Blocks.cobblestone);
        world.setBlock(i + 15, j + 2, k + 5, Blocks.cobblestone);
        world.setBlock(i + 15, j + 2, k + 6, Blocks.cobblestone);
        world.setBlock(i + 15, j + 2, k + 7, Blocks.cobblestone);
        world.setBlock(i + 15, j + 2, k + 12, Blocks.cobblestone);
        world.setBlock(i + 15, j + 2, k + 13, Blocks.cobblestone);
        world.setBlock(i + 15, j + 2, k + 14, Blocks.cobblestone);
        world.setBlock(i + 15, j + 2, k + 15, Blocks.cobblestone);
        world.setBlock(i + 15, j + 2, k + 18, Blocks.cobblestone);
        world.setBlock(i + 15, j + 3, k + 1, Blocks.cobblestone);
        world.setBlock(i + 15, j + 3, k + 4, Blocks.cobblestone);
        world.setBlock(i + 15, j + 3, k + 5, Blocks.cobblestone);
        world.setBlock(i + 15, j + 3, k + 6, Blocks.cobblestone);
        world.setBlock(i + 15, j + 3, k + 7, Blocks.cobblestone);
        world.setBlock(i + 15, j + 3, k + 12, Blocks.cobblestone);
        world.setBlock(i + 15, j + 3, k + 13, Blocks.cobblestone);
        world.setBlock(i + 15, j + 3, k + 14, Blocks.cobblestone);
        world.setBlock(i + 15, j + 3, k + 15, Blocks.cobblestone);
        world.setBlock(i + 15, j + 3, k + 18, Blocks.cobblestone);
        world.setBlock(i + 15, j + 4, k + 4, Blocks.cobblestone);
        world.setBlock(i + 15, j + 4, k + 5, Blocks.cobblestone);
        world.setBlock(i + 15, j + 4, k + 6, Blocks.cobblestone);
        world.setBlock(i + 15, j + 4, k + 7, Blocks.cobblestone);
        world.setBlock(i + 15, j + 4, k + 12, Blocks.cobblestone);
        world.setBlock(i + 15, j + 4, k + 13, Blocks.cobblestone);
        world.setBlock(i + 15, j + 4, k + 14, Blocks.cobblestone);
        world.setBlock(i + 15, j + 4, k + 15, Blocks.cobblestone);
        world.setBlock(i + 15, j + 5, k + 4, Blocks.stonebrick);
        world.setBlock(i + 15, j + 5, k + 5, Blocks.stonebrick);
        world.setBlock(i + 15, j + 5, k + 6, Blocks.stonebrick);
        world.setBlock(i + 15, j + 5, k + 7, Blocks.stonebrick);
        world.setBlock(i + 15, j + 5, k + 12, Blocks.stonebrick);
        world.setBlock(i + 15, j + 5, k + 13, Blocks.stonebrick);
        world.setBlock(i + 15, j + 5, k + 14, Blocks.stonebrick);
        world.setBlock(i + 15, j + 5, k + 15, Blocks.stonebrick);
        world.setBlock(i + 15, j + 6, k + 4, Blocks.stonebrick);
        world.setBlock(i + 15, j + 6, k + 5, Blocks.stonebrick);
        world.setBlock(i + 15, j + 6, k + 6, Blocks.stonebrick);
        world.setBlock(i + 15, j + 6, k + 7, Blocks.stonebrick);
        world.setBlock(i + 15, j + 6, k + 12, Blocks.stonebrick);
        world.setBlock(i + 15, j + 6, k + 13, Blocks.stonebrick);
        world.setBlock(i + 15, j + 6, k + 14, Blocks.stonebrick);
        world.setBlock(i + 15, j + 6, k + 15, Blocks.stonebrick);
        world.setBlock(i + 15, j + 7, k + 4, Blocks.stonebrick);
        world.setBlock(i + 15, j + 7, k + 7, Blocks.stonebrick);
        world.setBlock(i + 15, j + 7, k + 12, Blocks.stonebrick);
        world.setBlock(i + 15, j + 7, k + 15, Blocks.stonebrick);
        world.setBlock(i + 16, j + 0, k + 0, Blocks.grass);
        world.setBlock(i + 16, j + 0, k + 1, Blocks.dirt);
        world.setBlock(i + 16, j + 0, k + 2, Blocks.grass);
        world.setBlock(i + 16, j + 0, k + 3, Blocks.grass);
        world.setBlock(i + 16, j + 0, k + 4, Blocks.grass);
        world.setBlock(i + 16, j + 0, k + 5, Blocks.grass);
        world.setBlock(i + 16, j + 0, k + 6, Blocks.grass);
        world.setBlock(i + 16, j + 0, k + 7, Blocks.grass);
        world.setBlock(i + 16, j + 0, k + 8, Blocks.grass);
        world.setBlock(i + 16, j + 0, k + 9, Blocks.grass);
        world.setBlock(i + 16, j + 0, k + 10, Blocks.grass);
        world.setBlock(i + 16, j + 0, k + 11, Blocks.grass);
        world.setBlock(i + 16, j + 0, k + 12, Blocks.grass);
        world.setBlock(i + 16, j + 0, k + 13, Blocks.grass);
        world.setBlock(i + 16, j + 0, k + 14, Blocks.grass);
        world.setBlock(i + 16, j + 0, k + 15, Blocks.grass);
        world.setBlock(i + 16, j + 0, k + 16, Blocks.grass);
        world.setBlock(i + 16, j + 0, k + 17, Blocks.grass);
        world.setBlock(i + 16, j + 0, k + 18, Blocks.dirt);
        world.setBlock(i + 16, j + 0, k + 19, Blocks.grass);
        world.setBlock(i + 16, j + 1, k + 1, Blocks.cobblestone);
        world.setBlock(i + 16, j + 1, k + 18, Blocks.cobblestone);
        world.setBlock(i + 16, j + 2, k + 1, Blocks.cobblestone);
        world.setBlock(i + 16, j + 2, k + 18, Blocks.cobblestone);
        world.setBlock(i + 16, j + 3, k + 1, Blocks.cobblestone);
        world.setBlock(i + 16, j + 3, k + 18, Blocks.cobblestone);
        world.setBlock(i + 17, j + 0, k + 0, Blocks.grass);
        world.setBlock(i + 17, j + 0, k + 1, Blocks.dirt);
        world.setBlock(i + 17, j + 0, k + 2, Blocks.grass);
        world.setBlock(i + 17, j + 0, k + 3, Blocks.grass);
        world.setBlock(i + 17, j + 0, k + 4, Blocks.grass);
        world.setBlock(i + 17, j + 0, k + 5, Blocks.grass);
        world.setBlock(i + 17, j + 0, k + 6, Blocks.grass);
        world.setBlock(i + 17, j + 0, k + 7, Blocks.grass);
        world.setBlock(i + 17, j + 0, k + 8, Blocks.grass);
        world.setBlock(i + 17, j + 0, k + 9, Blocks.grass);
        world.setBlock(i + 17, j + 0, k + 10, Blocks.grass);
        world.setBlock(i + 17, j + 0, k + 11, Blocks.grass);
        world.setBlock(i + 17, j + 0, k + 12, Blocks.grass);
        world.setBlock(i + 17, j + 0, k + 13, Blocks.grass);
        world.setBlock(i + 17, j + 0, k + 14, Blocks.grass);
        world.setBlock(i + 17, j + 0, k + 15, Blocks.grass);
        world.setBlock(i + 17, j + 0, k + 16, Blocks.grass);
        world.setBlock(i + 17, j + 0, k + 17, Blocks.grass);
        world.setBlock(i + 17, j + 0, k + 18, Blocks.dirt);
        world.setBlock(i + 17, j + 0, k + 19, Blocks.grass);
        world.setBlock(i + 17, j + 1, k + 1, Blocks.cobblestone);
        world.setBlock(i + 17, j + 1, k + 18, Blocks.cobblestone);
        world.setBlock(i + 17, j + 2, k + 1, Blocks.cobblestone);
        world.setBlock(i + 17, j + 2, k + 18, Blocks.cobblestone);
        world.setBlock(i + 18, j + 0, k + 0, Blocks.grass);
        world.setBlock(i + 18, j + 0, k + 1, Blocks.dirt);
        world.setBlock(i + 18, j + 0, k + 2, Blocks.dirt);
        world.setBlock(i + 18, j + 0, k + 3, Blocks.dirt);
        world.setBlock(i + 18, j + 0, k + 4, Blocks.dirt);
        world.setBlock(i + 18, j + 0, k + 5, Blocks.dirt);
        world.setBlock(i + 18, j + 0, k + 6, Blocks.dirt);
        world.setBlock(i + 18, j + 0, k + 7, Blocks.dirt);
        world.setBlock(i + 18, j + 0, k + 8, Blocks.dirt);
        world.setBlock(i + 18, j + 0, k + 9, Blocks.dirt);
        world.setBlock(i + 18, j + 0, k + 10, Blocks.dirt);
        world.setBlock(i + 18, j + 0, k + 11, Blocks.dirt);
        world.setBlock(i + 18, j + 0, k + 12, Blocks.dirt);
        world.setBlock(i + 18, j + 0, k + 13, Blocks.dirt);
        world.setBlock(i + 18, j + 0, k + 14, Blocks.dirt);
        world.setBlock(i + 18, j + 0, k + 15, Blocks.dirt);
        world.setBlock(i + 18, j + 0, k + 16, Blocks.dirt);
        world.setBlock(i + 18, j + 0, k + 17, Blocks.dirt);
        world.setBlock(i + 18, j + 0, k + 18, Blocks.dirt);
        world.setBlock(i + 18, j + 0, k + 19, Blocks.grass);
        world.setBlock(i + 18, j + 1, k + 1, Blocks.cobblestone);
        world.setBlock(i + 18, j + 1, k + 2, Blocks.cobblestone);
        world.setBlock(i + 18, j + 1, k + 3, Blocks.cobblestone);
        world.setBlock(i + 18, j + 1, k + 4, Blocks.cobblestone);
        world.setBlock(i + 18, j + 1, k + 5, Blocks.cobblestone);
        world.setBlock(i + 18, j + 1, k + 6, Blocks.cobblestone);
        world.setBlock(i + 18, j + 1, k + 7, Blocks.cobblestone);
        world.setBlock(i + 18, j + 1, k + 8, Blocks.cobblestone);
        world.setBlock(i + 18, j + 1, k + 9, Blocks.cobblestone);
        world.setBlock(i + 18, j + 1, k + 10, Blocks.cobblestone);
        world.setBlock(i + 18, j + 1, k + 11, Blocks.cobblestone);
        world.setBlock(i + 18, j + 1, k + 12, Blocks.cobblestone);
        world.setBlock(i + 18, j + 1, k + 13, Blocks.cobblestone);
        world.setBlock(i + 18, j + 1, k + 14, Blocks.cobblestone);
        world.setBlock(i + 18, j + 1, k + 15, Blocks.cobblestone);
        world.setBlock(i + 18, j + 1, k + 16, Blocks.cobblestone);
        world.setBlock(i + 18, j + 1, k + 17, Blocks.cobblestone);
        world.setBlock(i + 18, j + 1, k + 18, Blocks.cobblestone);
        world.setBlock(i + 18, j + 2, k + 1, Blocks.cobblestone);
        world.setBlock(i + 18, j + 2, k + 2, Blocks.cobblestone);
        world.setBlock(i + 18, j + 2, k + 3, Blocks.cobblestone);
        world.setBlock(i + 18, j + 2, k + 4, Blocks.cobblestone);
        world.setBlock(i + 18, j + 2, k + 5, Blocks.cobblestone);
        world.setBlock(i + 18, j + 2, k + 6, Blocks.cobblestone);
        world.setBlock(i + 18, j + 2, k + 7, Blocks.cobblestone);
        world.setBlock(i + 18, j + 2, k + 8, Blocks.cobblestone);
        world.setBlock(i + 18, j + 2, k + 9, Blocks.cobblestone);
        world.setBlock(i + 18, j + 2, k + 10, Blocks.cobblestone);
        world.setBlock(i + 18, j + 2, k + 11, Blocks.cobblestone);
        world.setBlock(i + 18, j + 2, k + 12, Blocks.cobblestone);
        world.setBlock(i + 18, j + 2, k + 13, Blocks.cobblestone);
        world.setBlock(i + 18, j + 2, k + 14, Blocks.cobblestone);
        world.setBlock(i + 18, j + 2, k + 15, Blocks.cobblestone);
        world.setBlock(i + 18, j + 2, k + 16, Blocks.cobblestone);
        world.setBlock(i + 18, j + 2, k + 17, Blocks.cobblestone);
        world.setBlock(i + 18, j + 2, k + 18, Blocks.cobblestone);
        world.setBlock(i + 18, j + 3, k + 1, Blocks.cobblestone);
        world.setBlock(i + 18, j + 3, k + 3, Blocks.cobblestone);
        world.setBlock(i + 18, j + 3, k + 4, Blocks.cobblestone);
        world.setBlock(i + 18, j + 3, k + 6, Blocks.cobblestone);
        world.setBlock(i + 18, j + 3, k + 7, Blocks.cobblestone);
        world.setBlock(i + 18, j + 3, k + 9, Blocks.cobblestone);
        world.setBlock(i + 18, j + 3, k + 10, Blocks.cobblestone);
        world.setBlock(i + 18, j + 3, k + 12, Blocks.cobblestone);
        world.setBlock(i + 18, j + 3, k + 13, Blocks.cobblestone);
        world.setBlock(i + 18, j + 3, k + 15, Blocks.cobblestone);
        world.setBlock(i + 18, j + 3, k + 16, Blocks.cobblestone);
        world.setBlock(i + 18, j + 3, k + 18, Blocks.cobblestone);
        world.setBlock(i + 19, j + 0, k + 0, Blocks.grass);
        world.setBlock(i + 19, j + 0, k + 1, Blocks.grass);
        world.setBlock(i + 19, j + 0, k + 2, Blocks.grass);
        world.setBlock(i + 19, j + 0, k + 3, Blocks.grass);
        world.setBlock(i + 19, j + 0, k + 4, Blocks.grass);
        world.setBlock(i + 19, j + 0, k + 5, Blocks.grass);
        world.setBlock(i + 19, j + 0, k + 6, Blocks.grass);
        world.setBlock(i + 19, j + 0, k + 7, Blocks.grass);
        world.setBlock(i + 19, j + 0, k + 8, Blocks.grass);
        world.setBlock(i + 19, j + 0, k + 9, Blocks.grass);
        world.setBlock(i + 19, j + 0, k + 10, Blocks.grass);
        world.setBlock(i + 19, j + 0, k + 11, Blocks.grass);
        world.setBlock(i + 19, j + 0, k + 12, Blocks.grass);
        world.setBlock(i + 19, j + 0, k + 13, Blocks.grass);
        world.setBlock(i + 19, j + 0, k + 14, Blocks.grass);
        world.setBlock(i + 19, j + 0, k + 15, Blocks.grass);
        world.setBlock(i + 19, j + 0, k + 16, Blocks.grass);
        world.setBlock(i + 19, j + 0, k + 17, Blocks.grass);
        world.setBlock(i + 19, j + 0, k + 18, Blocks.grass);
        world.setBlock(i + 19, j + 0, k + 19, Blocks.grass);
        world.setBlock(i + 1, j + 4, k + 1, Blocks.torch, 4, 0);
        world.setBlock(i + 1, j + 4, k + 18, Blocks.torch, 4, 2);
        world.setBlock(i + 8, j + 1, k + 8, Blocks.ladder, 4, 0);
        world.setBlock(i + 8, j + 1, k + 11, Blocks.ladder, 4, 2);
        world.setBlock(i + 8, j + 2, k + 8, Blocks.ladder, 4, 0);
        world.setBlock(i + 8, j + 2, k + 11, Blocks.ladder, 4, 2);
        world.setBlock(i + 8, j + 3, k + 8, Blocks.ladder, 4, 0);
        world.setBlock(i + 8, j + 3, k + 11, Blocks.ladder, 4, 2);
        world.setBlock(i + 8, j + 4, k + 8, Blocks.ladder, 4, 0);
        world.setBlock(i + 8, j + 4, k + 11, Blocks.ladder, 4, 2);
        world.setBlock(i + 8, j + 5, k + 8, Blocks.ladder, 4, 0);
        world.setBlock(i + 8, j + 5, k + 11, Blocks.ladder, 4, 2);
        world.setBlock(i + 8, j + 6, k + 8, Blocks.ladder, 4, 0);
        world.setBlock(i + 8, j + 6, k + 11, Blocks.ladder, 4, 2);
        world.setBlock(i + 8, j + 7, k + 8, Blocks.ladder, 4, 0);
        world.setBlock(i + 8, j + 7, k + 11, Blocks.ladder, 4, 2);
        world.setBlock(i + 8, j + 8, k + 8, Blocks.ladder, 4, 0);
        world.setBlock(i + 8, j + 8, k + 11, Blocks.ladder, 4, 2);
        world.setBlock(i + 8, j + 9, k + 8, Blocks.ladder, 4, 0);
        world.setBlock(i + 8, j + 9, k + 11, Blocks.ladder, 4, 2);
        world.setBlock(i + 8, j + 10, k + 8, Blocks.ladder, 4, 0);
        world.setBlock(i + 8, j + 10, k + 11, Blocks.ladder, 4, 2);
        world.setBlock(i + 8, j + 11, k + 8, Blocks.ladder, 4, 0);
        world.setBlock(i + 8, j + 11, k + 11, Blocks.ladder, 4, 2);
        world.setBlock(i + 11, j + 1, k + 8, Blocks.ladder, 4, 0);
        world.setBlock(i + 11, j + 1, k + 11, Blocks.ladder, 4, 2);
        world.setBlock(i + 11, j + 2, k + 8, Blocks.ladder, 4, 0);
        world.setBlock(i + 11, j + 2, k + 11, Blocks.ladder, 4, 2);
        world.setBlock(i + 11, j + 3, k + 8, Blocks.ladder, 4, 0);
        world.setBlock(i + 11, j + 3, k + 11, Blocks.ladder, 4, 2);
        world.setBlock(i + 11, j + 4, k + 8, Blocks.ladder, 4, 0);
        world.setBlock(i + 11, j + 4, k + 11, Blocks.ladder, 4, 2);
        world.setBlock(i + 11, j + 5, k + 8, Blocks.ladder, 4, 0);
        world.setBlock(i + 11, j + 5, k + 11, Blocks.ladder, 4, 2);
        world.setBlock(i + 11, j + 6, k + 8, Blocks.ladder, 4, 0);
        world.setBlock(i + 11, j + 6, k + 11, Blocks.ladder, 4, 2);
        world.setBlock(i + 11, j + 7, k + 8, Blocks.ladder, 4, 0);
        world.setBlock(i + 11, j + 7, k + 11, Blocks.ladder, 4, 2);
        world.setBlock(i + 11, j + 8, k + 8, Blocks.ladder, 4, 0);
        world.setBlock(i + 11, j + 8, k + 11, Blocks.ladder, 4, 2);
        world.setBlock(i + 11, j + 9, k + 8, Blocks.ladder, 4, 0);
        world.setBlock(i + 11, j + 9, k + 11, Blocks.ladder, 4, 2);
        world.setBlock(i + 11, j + 10, k + 8, Blocks.ladder, 4, 0);
        world.setBlock(i + 11, j + 10, k + 11, Blocks.ladder, 4, 2);
        world.setBlock(i + 11, j + 11, k + 8, Blocks.ladder, 4, 0);
        world.setBlock(i + 11, j + 11, k + 11, Blocks.ladder, 4, 2);
        world.setBlock(i + 18, j + 4, k + 1, Blocks.torch, 4, 0);
        world.setBlock(i + 18, j + 4, k + 18, Blocks.torch, 4, 0);
        return true;
    }
}
