

package com.gibby.dungeon.gen;

import com.gibby.dungeon.Dungeons;
import net.minecraft.init.Blocks;
import net.minecraft.world.World;
import net.minecraft.world.gen.feature.WorldGenerator;

import java.util.Random;

public class SunsetIslandsLimeClay extends WorldGenerator
{
    public boolean generate(final World world, final Random rand, final int i, final int j, final int k) {
        world.setBlock(i + 1, j + 47, k + 74, Blocks.log);
        world.setBlock(i + 1, j + 48, k + 74, Blocks.log);
        world.setBlock(i + 2, j + 47, k + 74, Blocks.log);
        world.setBlock(i + 2, j + 47, k + 75, Blocks.log);
        world.setBlock(i + 2, j + 48, k + 74, Blocks.log);
        world.setBlock(i + 2, j + 48, k + 75, Blocks.log);
        world.setBlock(i + 3, j + 47, k + 73, Blocks.log);
        world.setBlock(i + 3, j + 47, k + 74, Blocks.log);
        world.setBlock(i + 3, j + 47, k + 75, Blocks.log);
        world.setBlock(i + 3, j + 47, k + 76, Blocks.log);
        world.setBlock(i + 3, j + 48, k + 73, Blocks.log);
        world.setBlock(i + 3, j + 48, k + 74, Blocks.log);
        world.setBlock(i + 3, j + 48, k + 75, Blocks.log);
        world.setBlock(i + 3, j + 48, k + 76, Blocks.log);
        world.setBlock(i + 4, j + 47, k + 70, Dungeons.blockUnbreableGrass);
        world.setBlock(i + 4, j + 47, k + 71, Blocks.log);
        world.setBlock(i + 4, j + 47, k + 73, Blocks.log);
        world.setBlock(i + 4, j + 47, k + 74, Blocks.log);
        world.setBlock(i + 4, j + 47, k + 75, Blocks.log);
        world.setBlock(i + 4, j + 47, k + 76, Blocks.log);
        world.setBlock(i + 4, j + 47, k + 78, Blocks.log);
        world.setBlock(i + 4, j + 48, k + 72, Blocks.log);
        world.setBlock(i + 4, j + 48, k + 73, Blocks.log);
        world.setBlock(i + 4, j + 48, k + 74, Blocks.log);
        world.setBlock(i + 4, j + 48, k + 75, Blocks.log);
        world.setBlock(i + 4, j + 48, k + 76, Blocks.log);
        world.setBlock(i + 5, j + 47, k + 71, Dungeons.blockUnbreableGrass);
        world.setBlock(i + 5, j + 47, k + 72, Blocks.log);
        world.setBlock(i + 5, j + 47, k + 73, Blocks.log);
        world.setBlock(i + 5, j + 47, k + 74, Blocks.log);
        world.setBlock(i + 5, j + 47, k + 75, Blocks.log);
        world.setBlock(i + 5, j + 47, k + 76, Blocks.log);
        world.setBlock(i + 5, j + 47, k + 77, Blocks.log);
        world.setBlock(i + 5, j + 47, k + 78, Blocks.log);
        world.setBlock(i + 5, j + 47, k + 79, Blocks.log);
        world.setBlock(i + 5, j + 48, k + 73, Blocks.log);
        world.setBlock(i + 5, j + 48, k + 74, Blocks.log);
        world.setBlock(i + 5, j + 48, k + 75, Blocks.log);
        world.setBlock(i + 5, j + 48, k + 76, Blocks.log);
        world.setBlock(i + 5, j + 48, k + 77, Blocks.log);
        world.setBlock(i + 6, j + 43, k + 89, Dungeons.blockUnbreableStone);
        world.setBlock(i + 6, j + 43, k + 90, Dungeons.blockUnbreableStone);
        world.setBlock(i + 6, j + 43, k + 91, Dungeons.blockUnbreableStone);
        world.setBlock(i + 6, j + 44, k + 87, Blocks.dirt);
        world.setBlock(i + 6, j + 44, k + 88, Dungeons.blockUnbreableStone);
        world.setBlock(i + 6, j + 44, k + 89, Dungeons.blockUnbreableStone);
        world.setBlock(i + 6, j + 44, k + 90, Dungeons.blockUnbreableStone);
        world.setBlock(i + 6, j + 44, k + 91, Dungeons.blockUnbreableStone);
        world.setBlock(i + 6, j + 44, k + 92, Dungeons.blockUnbreableStone);
        world.setBlock(i + 6, j + 44, k + 93, Blocks.dirt);
        world.setBlock(i + 6, j + 44, k + 94, Blocks.dirt);
        world.setBlock(i + 6, j + 45, k + 84, Dungeons.blockUnbreableGrass);
        world.setBlock(i + 6, j + 45, k + 85, Dungeons.blockUnbreableGrass);
        world.setBlock(i + 6, j + 45, k + 86, Dungeons.blockUnbreableGrass);
        world.setBlock(i + 6, j + 45, k + 87, Dungeons.blockUnbreableGrass);
        world.setBlock(i + 6, j + 45, k + 88, Dungeons.blockUnbreableGrass);
        world.setBlock(i + 6, j + 45, k + 89, Dungeons.blockUnbreableGrass);
        world.setBlock(i + 6, j + 45, k + 90, Blocks.dirt);
        world.setBlock(i + 6, j + 45, k + 91, Blocks.dirt);
        world.setBlock(i + 6, j + 45, k + 92, Blocks.dirt);
        world.setBlock(i + 6, j + 45, k + 93, Blocks.dirt);
        world.setBlock(i + 6, j + 45, k + 94, Blocks.dirt);
        world.setBlock(i + 6, j + 45, k + 95, Dungeons.blockUnbreableGrass);
        world.setBlock(i + 6, j + 45, k + 96, Dungeons.blockUnbreableGrass);
        world.setBlock(i + 6, j + 46, k + 90, Dungeons.blockUnbreableGrass);
        world.setBlock(i + 6, j + 46, k + 91, Dungeons.blockUnbreableGrass);
        world.setBlock(i + 6, j + 46, k + 92, Dungeons.blockUnbreableGrass);
        world.setBlock(i + 6, j + 46, k + 93, Dungeons.blockUnbreableGrass);
        world.setBlock(i + 6, j + 46, k + 94, Dungeons.blockUnbreableGrass);
        world.setBlock(i + 6, j + 46, k + 97, Dungeons.blockUnbreableGrass);
        world.setBlock(i + 6, j + 47, k + 72, Blocks.log);
        world.setBlock(i + 6, j + 47, k + 73, Blocks.log);
        world.setBlock(i + 6, j + 47, k + 74, Blocks.log);
        world.setBlock(i + 6, j + 47, k + 75, Blocks.log);
        world.setBlock(i + 6, j + 47, k + 76, Blocks.log);
        world.setBlock(i + 6, j + 47, k + 77, Blocks.log);
        world.setBlock(i + 6, j + 47, k + 78, Blocks.log);
        world.setBlock(i + 6, j + 47, k + 79, Blocks.log);
        world.setBlock(i + 6, j + 48, k + 75, Blocks.log);
        world.setBlock(i + 6, j + 48, k + 76, Blocks.log);
        world.setBlock(i + 6, j + 48, k + 77, Blocks.log);
        world.setBlock(i + 7, j + 43, k + 88, Dungeons.blockUnbreableStone);
        world.setBlock(i + 7, j + 43, k + 89, Dungeons.blockUnbreableStone);
        world.setBlock(i + 7, j + 43, k + 90, Dungeons.blockUnbreableStone);
        world.setBlock(i + 7, j + 43, k + 91, Dungeons.blockUnbreableStone);
        world.setBlock(i + 7, j + 43, k + 92, Dungeons.blockUnbreableStone);
        world.setBlock(i + 7, j + 43, k + 93, Dungeons.blockUnbreableStone);
        world.setBlock(i + 7, j + 44, k + 87, Dungeons.blockUnbreableStone);
        world.setBlock(i + 7, j + 44, k + 88, Dungeons.blockUnbreableStone);
        world.setBlock(i + 7, j + 44, k + 89, Dungeons.blockUnbreableStone);
        world.setBlock(i + 7, j + 44, k + 90, Dungeons.blockUnbreableStone);
        world.setBlock(i + 7, j + 44, k + 91, Dungeons.blockUnbreableStone);
        world.setBlock(i + 7, j + 44, k + 92, Dungeons.blockUnbreableStone);
        world.setBlock(i + 7, j + 44, k + 93, Dungeons.blockUnbreableStone);
        world.setBlock(i + 7, j + 44, k + 94, Dungeons.blockUnbreableStone);
        world.setBlock(i + 7, j + 45, k + 85, Blocks.dirt);
        world.setBlock(i + 7, j + 45, k + 86, Blocks.dirt);
        world.setBlock(i + 7, j + 45, k + 87, Blocks.dirt);
        world.setBlock(i + 7, j + 45, k + 88, Blocks.dirt);
        world.setBlock(i + 7, j + 45, k + 89, Dungeons.blockUnbreableStone);
        world.setBlock(i + 7, j + 45, k + 90, Blocks.dirt);
        world.setBlock(i + 7, j + 45, k + 91, Blocks.dirt);
        world.setBlock(i + 7, j + 45, k + 92, Blocks.dirt);
        world.setBlock(i + 7, j + 45, k + 93, Blocks.dirt);
        world.setBlock(i + 7, j + 45, k + 94, Blocks.dirt);
        world.setBlock(i + 7, j + 45, k + 115, Blocks.dirt);
        world.setBlock(i + 7, j + 45, k + 116, Blocks.dirt);
        world.setBlock(i + 7, j + 45, k + 117, Blocks.dirt);
        world.setBlock(i + 7, j + 45, k + 118, Blocks.dirt);
        world.setBlock(i + 7, j + 45, k + 119, Blocks.dirt);
        world.setBlock(i + 7, j + 46, k + 83, Dungeons.blockUnbreableGrass);
        world.setBlock(i + 7, j + 46, k + 84, Dungeons.blockUnbreableGrass);
        world.setBlock(i + 7, j + 46, k + 85, Dungeons.blockUnbreableGrass);
        world.setBlock(i + 7, j + 46, k + 86, Dungeons.blockUnbreableGrass);
        world.setBlock(i + 7, j + 46, k + 87, Dungeons.blockUnbreableGrass);
        world.setBlock(i + 7, j + 46, k + 88, Dungeons.blockUnbreableGrass);
        world.setBlock(i + 7, j + 46, k + 89, Blocks.dirt);
        world.setBlock(i + 7, j + 46, k + 90, Blocks.dirt);
        world.setBlock(i + 7, j + 46, k + 91, Blocks.dirt);
        world.setBlock(i + 7, j + 46, k + 92, Blocks.dirt);
        world.setBlock(i + 7, j + 46, k + 93, Blocks.dirt);
        world.setBlock(i + 7, j + 46, k + 94, Blocks.dirt);
        world.setBlock(i + 7, j + 46, k + 95, Blocks.dirt);
        world.setBlock(i + 7, j + 46, k + 96, Blocks.dirt);
        world.setBlock(i + 7, j + 46, k + 97, Dungeons.blockUnbreableGrass);
        world.setBlock(i + 7, j + 46, k + 113, Dungeons.blockUnbreableGrass);
        world.setBlock(i + 7, j + 46, k + 114, Dungeons.blockUnbreableGrass);
        world.setBlock(i + 7, j + 46, k + 115, Dungeons.blockUnbreableGrass);
        world.setBlock(i + 7, j + 46, k + 116, Dungeons.blockUnbreableGrass);
        world.setBlock(i + 7, j + 46, k + 117, Dungeons.blockUnbreableGrass);
        world.setBlock(i + 7, j + 46, k + 118, Dungeons.blockUnbreableGrass);
        world.setBlock(i + 7, j + 46, k + 119, Dungeons.blockUnbreableGrass);
        world.setBlock(i + 7, j + 46, k + 120, Dungeons.blockUnbreableGrass);
        world.setBlock(i + 7, j + 46, k + 121, Dungeons.blockUnbreableGrass);
        world.setBlock(i + 7, j + 47, k + 72, Blocks.log);
        world.setBlock(i + 7, j + 47, k + 73, Blocks.log);
        world.setBlock(i + 7, j + 47, k + 74, Blocks.log);
        world.setBlock(i + 7, j + 47, k + 75, Blocks.log);
        world.setBlock(i + 7, j + 47, k + 76, Blocks.log);
        world.setBlock(i + 7, j + 47, k + 77, Blocks.log);
        world.setBlock(i + 7, j + 47, k + 78, Blocks.log);
        world.setBlock(i + 7, j + 47, k + 79, Blocks.log);
        world.setBlock(i + 7, j + 47, k + 89, Dungeons.blockUnbreableGrass);
        world.setBlock(i + 7, j + 47, k + 90, Dungeons.blockUnbreableGrass);
        world.setBlock(i + 7, j + 47, k + 91, Dungeons.blockUnbreableGrass);
        world.setBlock(i + 7, j + 47, k + 92, Dungeons.blockUnbreableGrass);
        world.setBlock(i + 7, j + 47, k + 93, Dungeons.blockUnbreableGrass);
        world.setBlock(i + 7, j + 47, k + 94, Dungeons.blockUnbreableGrass);
        world.setBlock(i + 7, j + 47, k + 95, Dungeons.blockUnbreableGrass);
        world.setBlock(i + 7, j + 47, k + 96, Dungeons.blockUnbreableGrass);
        world.setBlock(i + 7, j + 48, k + 75, Blocks.log);
        world.setBlock(i + 7, j + 48, k + 76, Blocks.log);
        world.setBlock(i + 7, j + 48, k + 77, Blocks.log);
        world.setBlock(i + 8, j + 42, k + 89, Dungeons.blockUnbreableStone);
        world.setBlock(i + 8, j + 42, k + 90, Dungeons.blockUnbreableStone);
        world.setBlock(i + 8, j + 42, k + 91, Dungeons.blockUnbreableStone);
        world.setBlock(i + 8, j + 42, k + 92, Dungeons.blockUnbreableStone);
        world.setBlock(i + 8, j + 43, k + 87, Dungeons.blockUnbreableStone);
        world.setBlock(i + 8, j + 43, k + 88, Dungeons.blockUnbreableStone);
        world.setBlock(i + 8, j + 43, k + 89, Dungeons.blockUnbreableStone);
        world.setBlock(i + 8, j + 43, k + 90, Dungeons.blockUnbreableStone);
        world.setBlock(i + 8, j + 43, k + 91, Dungeons.blockUnbreableStone);
        world.setBlock(i + 8, j + 43, k + 92, Dungeons.blockUnbreableStone);
        world.setBlock(i + 8, j + 43, k + 93, Dungeons.blockUnbreableStone);
        world.setBlock(i + 8, j + 43, k + 94, Dungeons.blockUnbreableStone);
        world.setBlock(i + 8, j + 44, k + 86, Dungeons.blockUnbreableStone);
        world.setBlock(i + 8, j + 44, k + 87, Dungeons.blockUnbreableStone);
        world.setBlock(i + 8, j + 44, k + 88, Dungeons.blockUnbreableStone);
        world.setBlock(i + 8, j + 44, k + 89, Dungeons.blockUnbreableStone);
        world.setBlock(i + 8, j + 44, k + 90, Dungeons.blockUnbreableStone);
        world.setBlock(i + 8, j + 44, k + 91, Dungeons.blockUnbreableStone);
        world.setBlock(i + 8, j + 44, k + 92, Dungeons.blockUnbreableStone);
        world.setBlock(i + 8, j + 44, k + 93, Dungeons.blockUnbreableStone);
        world.setBlock(i + 8, j + 44, k + 94, Dungeons.blockUnbreableStone);
        world.setBlock(i + 8, j + 44, k + 95, Dungeons.blockUnbreableStone);
        world.setBlock(i + 8, j + 44, k + 115, Dungeons.blockUnbreableStone);
        world.setBlock(i + 8, j + 44, k + 116, Dungeons.blockUnbreableStone);
        world.setBlock(i + 8, j + 44, k + 117, Dungeons.blockUnbreableStone);
        world.setBlock(i + 8, j + 44, k + 118, Dungeons.blockUnbreableStone);
        world.setBlock(i + 8, j + 45, k + 84, Blocks.dirt);
        world.setBlock(i + 8, j + 45, k + 85, Blocks.dirt);
        world.setBlock(i + 8, j + 45, k + 86, Blocks.dirt);
        world.setBlock(i + 8, j + 45, k + 87, Blocks.dirt);
        world.setBlock(i + 8, j + 45, k + 88, Dungeons.blockUnbreableStone);
        world.setBlock(i + 8, j + 45, k + 89, Blocks.dirt);
        world.setBlock(i + 8, j + 45, k + 90, Blocks.dirt);
        world.setBlock(i + 8, j + 45, k + 91, Blocks.dirt);
        world.setBlock(i + 8, j + 45, k + 92, Blocks.dirt);
        world.setBlock(i + 8, j + 45, k + 93, Blocks.dirt);
        world.setBlock(i + 8, j + 45, k + 94, Blocks.dirt);
        world.setBlock(i + 8, j + 45, k + 95, Blocks.dirt);
        world.setBlock(i + 8, j + 45, k + 96, Blocks.dirt);
        world.setBlock(i + 8, j + 45, k + 113, Blocks.dirt);
        world.setBlock(i + 8, j + 45, k + 114, Blocks.dirt);
        world.setBlock(i + 8, j + 45, k + 115, Blocks.dirt);
        world.setBlock(i + 8, j + 45, k + 116, Blocks.dirt);
        world.setBlock(i + 8, j + 45, k + 117, Blocks.dirt);
        world.setBlock(i + 8, j + 45, k + 118, Blocks.dirt);
        world.setBlock(i + 8, j + 45, k + 119, Blocks.dirt);
        world.setBlock(i + 8, j + 46, k + 82, Dungeons.blockUnbreableGrass);
        world.setBlock(i + 8, j + 46, k + 83, Dungeons.blockUnbreableGrass);
        world.setBlock(i + 8, j + 46, k + 84, Dungeons.blockUnbreableGrass);
        world.setBlock(i + 8, j + 46, k + 85, Dungeons.blockUnbreableGrass);
        world.setBlock(i + 8, j + 46, k + 86, Dungeons.blockUnbreableGrass);
        world.setBlock(i + 8, j + 46, k + 87, Dungeons.blockUnbreableGrass);
        world.setBlock(i + 8, j + 46, k + 88, Blocks.dirt);
        world.setBlock(i + 8, j + 46, k + 89, Blocks.dirt);
        world.setBlock(i + 8, j + 46, k + 90, Blocks.dirt);
        world.setBlock(i + 8, j + 46, k + 91, Blocks.dirt);
        world.setBlock(i + 8, j + 46, k + 92, Blocks.dirt);
        world.setBlock(i + 8, j + 46, k + 93, Blocks.dirt);
        world.setBlock(i + 8, j + 46, k + 94, Blocks.dirt);
        world.setBlock(i + 8, j + 46, k + 95, Blocks.dirt);
        world.setBlock(i + 8, j + 46, k + 96, Blocks.dirt);
        world.setBlock(i + 8, j + 46, k + 97, Blocks.dirt);
        world.setBlock(i + 8, j + 46, k + 98, Dungeons.blockUnbreableGrass);
        world.setBlock(i + 8, j + 46, k + 112, Dungeons.blockUnbreableGrass);
        world.setBlock(i + 8, j + 46, k + 113, Dungeons.blockUnbreableGrass);
        world.setBlock(i + 8, j + 46, k + 114, Dungeons.blockUnbreableGrass);
        world.setBlock(i + 8, j + 46, k + 115, Dungeons.blockUnbreableGrass);
        world.setBlock(i + 8, j + 46, k + 116, Dungeons.blockUnbreableGrass);
        world.setBlock(i + 8, j + 46, k + 117, Dungeons.blockUnbreableGrass);
        world.setBlock(i + 8, j + 46, k + 118, Dungeons.blockUnbreableGrass);
        world.setBlock(i + 8, j + 46, k + 119, Dungeons.blockUnbreableGrass);
        world.setBlock(i + 8, j + 46, k + 120, Dungeons.blockUnbreableGrass);
        world.setBlock(i + 8, j + 46, k + 121, Dungeons.blockUnbreableGrass);
        world.setBlock(i + 8, j + 47, k + 73, Blocks.log);
        world.setBlock(i + 8, j + 47, k + 74, Blocks.log);
        world.setBlock(i + 8, j + 47, k + 75, Blocks.log);
        world.setBlock(i + 8, j + 47, k + 76, Blocks.log);
        world.setBlock(i + 8, j + 47, k + 77, Blocks.log);
        world.setBlock(i + 8, j + 47, k + 78, Blocks.log);
        world.setBlock(i + 8, j + 47, k + 79, Blocks.log);
        world.setBlock(i + 8, j + 47, k + 88, Dungeons.blockUnbreableGrass);
        world.setBlock(i + 8, j + 47, k + 89, Dungeons.blockUnbreableGrass);
        world.setBlock(i + 8, j + 47, k + 90, Blocks.dirt);
        world.setBlock(i + 8, j + 47, k + 91, Blocks.dirt);
        world.setBlock(i + 8, j + 47, k + 92, Blocks.dirt);
        world.setBlock(i + 8, j + 47, k + 93, Blocks.dirt);
        world.setBlock(i + 8, j + 47, k + 94, Blocks.dirt);
        world.setBlock(i + 8, j + 47, k + 95, Blocks.dirt);
        world.setBlock(i + 8, j + 47, k + 96, Blocks.dirt);
        world.setBlock(i + 8, j + 47, k + 97, Dungeons.blockUnbreableGrass);
        world.setBlock(i + 8, j + 48, k + 75, Blocks.log);
        world.setBlock(i + 8, j + 48, k + 76, Blocks.log);
        world.setBlock(i + 8, j + 48, k + 77, Blocks.log);
        world.setBlock(i + 8, j + 48, k + 90, Dungeons.blockUnbreableGrass);
        world.setBlock(i + 8, j + 48, k + 91, Dungeons.blockUnbreableGrass);
        world.setBlock(i + 8, j + 48, k + 92, Dungeons.blockUnbreableGrass);
        world.setBlock(i + 8, j + 48, k + 93, Dungeons.blockUnbreableGrass);
        world.setBlock(i + 8, j + 48, k + 94, Dungeons.blockUnbreableGrass);
        world.setBlock(i + 8, j + 48, k + 95, Dungeons.blockUnbreableGrass);
        world.setBlock(i + 8, j + 48, k + 96, Dungeons.blockUnbreableGrass);
        world.setBlock(i + 9, j + 38, k + 125, Blocks.log);
        world.setBlock(i + 9, j + 39, k + 124, Blocks.log);
        world.setBlock(i + 9, j + 39, k + 125, Blocks.log);
        world.setBlock(i + 9, j + 39, k + 126, Blocks.log);
        world.setBlock(i + 9, j + 40, k + 124, Blocks.log);
        world.setBlock(i + 9, j + 40, k + 125, Blocks.log);
        world.setBlock(i + 9, j + 40, k + 126, Blocks.log);
        world.setBlock(i + 9, j + 41, k + 123, Blocks.log);
        world.setBlock(i + 9, j + 41, k + 124, Blocks.log);
        world.setBlock(i + 9, j + 41, k + 125, Blocks.log);
        world.setBlock(i + 9, j + 42, k + 87, Dungeons.blockUnbreableStone);
        world.setBlock(i + 9, j + 42, k + 88, Dungeons.blockUnbreableStone);
        world.setBlock(i + 9, j + 42, k + 89, Dungeons.blockUnbreableStone);
        world.setBlock(i + 9, j + 42, k + 90, Dungeons.blockUnbreableStone);
        world.setBlock(i + 9, j + 42, k + 91, Dungeons.blockUnbreableStone);
        world.setBlock(i + 9, j + 42, k + 92, Dungeons.blockUnbreableStone);
        world.setBlock(i + 9, j + 42, k + 93, Dungeons.blockUnbreableStone);
        world.setBlock(i + 9, j + 42, k + 122, Blocks.log);
        world.setBlock(i + 9, j + 42, k + 123, Blocks.log);
        world.setBlock(i + 9, j + 42, k + 124, Blocks.log);
        world.setBlock(i + 9, j + 42, k + 125, Blocks.log);
        world.setBlock(i + 9, j + 42, k + 126, Blocks.log);
        world.setBlock(i + 9, j + 43, k + 86, Dungeons.blockUnbreableStone);
        world.setBlock(i + 9, j + 43, k + 87, Dungeons.blockUnbreableStone);
        world.setBlock(i + 9, j + 43, k + 88, Dungeons.blockUnbreableStone);
        world.setBlock(i + 9, j + 43, k + 89, Dungeons.blockUnbreableStone);
        world.setBlock(i + 9, j + 43, k + 90, Dungeons.blockUnbreableStone);
        world.setBlock(i + 9, j + 43, k + 91, Dungeons.blockUnbreableStone);
        world.setBlock(i + 9, j + 43, k + 92, Dungeons.blockUnbreableStone);
        world.setBlock(i + 9, j + 43, k + 93, Dungeons.blockUnbreableStone);
        world.setBlock(i + 9, j + 43, k + 94, Dungeons.blockUnbreableStone);
        world.setBlock(i + 9, j + 43, k + 115, Dungeons.blockUnbreableStone);
        world.setBlock(i + 9, j + 43, k + 116, Dungeons.blockUnbreableStone);
        world.setBlock(i + 9, j + 43, k + 117, Dungeons.blockUnbreableStone);
        world.setBlock(i + 9, j + 43, k + 123, Blocks.log);
        world.setBlock(i + 9, j + 43, k + 125, Blocks.log);
        world.setBlock(i + 9, j + 44, k + 85, Dungeons.blockUnbreableStone);
        world.setBlock(i + 9, j + 44, k + 86, Dungeons.blockUnbreableStone);
        world.setBlock(i + 9, j + 44, k + 87, Dungeons.blockUnbreableStone);
        world.setBlock(i + 9, j + 44, k + 88, Dungeons.blockUnbreableStone);
        world.setBlock(i + 9, j + 44, k + 89, Dungeons.blockUnbreableStone);
        world.setBlock(i + 9, j + 44, k + 90, Dungeons.blockUnbreableStone);
        world.setBlock(i + 9, j + 44, k + 91, Dungeons.blockUnbreableStone);
        world.setBlock(i + 9, j + 44, k + 92, Dungeons.blockUnbreableStone);
        world.setBlock(i + 9, j + 44, k + 93, Dungeons.blockUnbreableStone);
        world.setBlock(i + 9, j + 44, k + 94, Dungeons.blockUnbreableStone);
        world.setBlock(i + 9, j + 44, k + 95, Dungeons.blockUnbreableStone);
        world.setBlock(i + 9, j + 44, k + 114, Dungeons.blockUnbreableStone);
        world.setBlock(i + 9, j + 44, k + 115, Dungeons.blockUnbreableStone);
        world.setBlock(i + 9, j + 44, k + 116, Dungeons.blockUnbreableStone);
        world.setBlock(i + 9, j + 44, k + 117, Dungeons.blockUnbreableStone);
        world.setBlock(i + 9, j + 44, k + 118, Dungeons.blockUnbreableStone);
        world.setBlock(i + 9, j + 44, k + 119, Dungeons.blockUnbreableStone);
        world.setBlock(i + 9, j + 45, k + 83, Blocks.dirt);
        world.setBlock(i + 9, j + 45, k + 84, Blocks.dirt);
        world.setBlock(i + 9, j + 45, k + 85, Blocks.dirt);
        world.setBlock(i + 9, j + 45, k + 86, Blocks.dirt);
        world.setBlock(i + 9, j + 45, k + 87, Dungeons.blockUnbreableStone);
        world.setBlock(i + 9, j + 45, k + 88, Blocks.dirt);
        world.setBlock(i + 9, j + 45, k + 89, Blocks.dirt);
        world.setBlock(i + 9, j + 45, k + 90, Blocks.dirt);
        world.setBlock(i + 9, j + 45, k + 91, Blocks.dirt);
        world.setBlock(i + 9, j + 45, k + 92, Blocks.dirt);
        world.setBlock(i + 9, j + 45, k + 93, Blocks.dirt);
        world.setBlock(i + 9, j + 45, k + 94, Blocks.dirt);
        world.setBlock(i + 9, j + 45, k + 95, Blocks.dirt);
        world.setBlock(i + 9, j + 45, k + 96, Blocks.dirt);
        world.setBlock(i + 9, j + 45, k + 97, Blocks.dirt);
        world.setBlock(i + 9, j + 45, k + 113, Blocks.dirt);
        world.setBlock(i + 9, j + 45, k + 114, Blocks.dirt);
        world.setBlock(i + 9, j + 45, k + 115, Blocks.dirt);
        world.setBlock(i + 9, j + 45, k + 116, Blocks.dirt);
        world.setBlock(i + 9, j + 45, k + 117, Blocks.dirt);
        world.setBlock(i + 9, j + 45, k + 118, Blocks.dirt);
        world.setBlock(i + 9, j + 45, k + 119, Blocks.dirt);
        world.setBlock(i + 9, j + 45, k + 120, Blocks.dirt);
        world.setBlock(i + 9, j + 46, k + 81, Dungeons.blockUnbreableGrass);
        world.setBlock(i + 9, j + 46, k + 82, Dungeons.blockUnbreableGrass);
        world.setBlock(i + 9, j + 46, k + 83, Dungeons.blockUnbreableGrass);
        world.setBlock(i + 9, j + 46, k + 84, Dungeons.blockUnbreableGrass);
        world.setBlock(i + 9, j + 46, k + 85, Dungeons.blockUnbreableGrass);
        world.setBlock(i + 9, j + 46, k + 86, Dungeons.blockUnbreableGrass);
        world.setBlock(i + 9, j + 46, k + 87, Blocks.dirt);
        world.setBlock(i + 9, j + 46, k + 88, Blocks.dirt);
        world.setBlock(i + 9, j + 46, k + 89, Blocks.dirt);
        world.setBlock(i + 9, j + 46, k + 90, Blocks.dirt);
        world.setBlock(i + 9, j + 46, k + 91, Blocks.dirt);
        world.setBlock(i + 9, j + 46, k + 92, Blocks.dirt);
        world.setBlock(i + 9, j + 46, k + 93, Blocks.dirt);
        world.setBlock(i + 9, j + 46, k + 94, Blocks.dirt);
        world.setBlock(i + 9, j + 46, k + 95, Blocks.dirt);
        world.setBlock(i + 9, j + 46, k + 96, Blocks.dirt);
        world.setBlock(i + 9, j + 46, k + 97, Blocks.dirt);
        world.setBlock(i + 9, j + 46, k + 98, Blocks.dirt);
        world.setBlock(i + 9, j + 46, k + 99, Dungeons.blockUnbreableGrass);
        world.setBlock(i + 9, j + 46, k + 111, Dungeons.blockUnbreableGrass);
        world.setBlock(i + 9, j + 46, k + 112, Dungeons.blockUnbreableGrass);
        world.setBlock(i + 9, j + 46, k + 113, Dungeons.blockUnbreableGrass);
        world.setBlock(i + 9, j + 46, k + 114, Dungeons.blockUnbreableGrass);
        world.setBlock(i + 9, j + 46, k + 115, Dungeons.blockUnbreableGrass);
        world.setBlock(i + 9, j + 46, k + 116, Dungeons.blockUnbreableGrass);
        world.setBlock(i + 9, j + 46, k + 117, Dungeons.blockUnbreableGrass);
        world.setBlock(i + 9, j + 46, k + 118, Dungeons.blockUnbreableGrass);
        world.setBlock(i + 9, j + 46, k + 119, Dungeons.blockUnbreableGrass);
        world.setBlock(i + 9, j + 46, k + 120, Dungeons.blockUnbreableGrass);
        world.setBlock(i + 9, j + 46, k + 121, Dungeons.blockUnbreableGrass);
        world.setBlock(i + 9, j + 46, k + 122, Dungeons.blockUnbreableGrass);
        world.setBlock(i + 9, j + 47, k + 73, Blocks.log);
        world.setBlock(i + 9, j + 47, k + 74, Blocks.log);
        world.setBlock(i + 9, j + 47, k + 75, Blocks.log);
        world.setBlock(i + 9, j + 47, k + 76, Blocks.log);
        world.setBlock(i + 9, j + 47, k + 77, Blocks.log);
        world.setBlock(i + 9, j + 47, k + 78, Blocks.log);
        world.setBlock(i + 9, j + 47, k + 79, Blocks.log);
        world.setBlock(i + 9, j + 47, k + 87, Dungeons.blockUnbreableGrass);
        world.setBlock(i + 9, j + 47, k + 88, Blocks.dirt);
        world.setBlock(i + 9, j + 47, k + 89, Blocks.dirt);
        world.setBlock(i + 9, j + 47, k + 90, Blocks.dirt);
        world.setBlock(i + 9, j + 47, k + 91, Blocks.dirt);
        world.setBlock(i + 9, j + 47, k + 92, Blocks.dirt);
        world.setBlock(i + 9, j + 47, k + 93, Blocks.dirt);
        world.setBlock(i + 9, j + 47, k + 94, Blocks.dirt);
        world.setBlock(i + 9, j + 47, k + 95, Blocks.dirt);
        world.setBlock(i + 9, j + 47, k + 96, Blocks.dirt);
        world.setBlock(i + 9, j + 47, k + 97, Dungeons.blockUnbreableGrass);
        world.setBlock(i + 9, j + 47, k + 98, Dungeons.blockUnbreableGrass);
        world.setBlock(i + 9, j + 48, k + 75, Blocks.log);
        world.setBlock(i + 9, j + 48, k + 76, Blocks.log);
        world.setBlock(i + 9, j + 48, k + 77, Blocks.log);
        world.setBlock(i + 9, j + 48, k + 88, Dungeons.blockUnbreableGrass);
        world.setBlock(i + 9, j + 48, k + 89, Dungeons.blockUnbreableGrass);
        world.setBlock(i + 9, j + 48, k + 90, Blocks.dirt);
        world.setBlock(i + 9, j + 48, k + 91, Blocks.dirt);
        world.setBlock(i + 9, j + 48, k + 92, Blocks.dirt);
        world.setBlock(i + 9, j + 48, k + 93, Blocks.dirt);
        world.setBlock(i + 9, j + 48, k + 94, Blocks.dirt);
        world.setBlock(i + 9, j + 48, k + 95, Blocks.dirt);
        world.setBlock(i + 9, j + 48, k + 96, Dungeons.blockUnbreableGrass);
        world.setBlock(i + 9, j + 49, k + 90, Dungeons.blockUnbreableGrass);
        world.setBlock(i + 9, j + 49, k + 91, Dungeons.blockUnbreableGrass);
        world.setBlock(i + 9, j + 49, k + 92, Dungeons.blockUnbreableGrass);
        world.setBlock(i + 9, j + 49, k + 93, Dungeons.blockUnbreableGrass);
        world.setBlock(i + 9, j + 49, k + 94, Dungeons.blockUnbreableGrass);
        world.setBlock(i + 9, j + 49, k + 95, Dungeons.blockUnbreableGrass);
        world.setBlock(i + 9, j + 128, k + 45, Blocks.wool, 1, 0);
        world.setBlock(i + 9, j + 128, k + 46, Blocks.wool, 1, 0);
        world.setBlock(i + 9, j + 128, k + 47, Blocks.wool, 1, 0);
        world.setBlock(i + 9, j + 128, k + 51, Blocks.wool, 1, 0);
        world.setBlock(i + 9, j + 128, k + 52, Blocks.wool, 1, 0);
        world.setBlock(i + 9, j + 129, k + 53, Blocks.wool, 1, 0);
        world.setBlock(i + 10, j + 35, k + 20, Blocks.log);
        world.setBlock(i + 10, j + 36, k + 19, Blocks.log);
        world.setBlock(i + 10, j + 36, k + 20, Blocks.log);
        world.setBlock(i + 10, j + 36, k + 21, Blocks.log);
        world.setBlock(i + 10, j + 37, k + 20, Blocks.log);
        world.setBlock(i + 10, j + 37, k + 21, Blocks.log);
        world.setBlock(i + 10, j + 37, k + 22, Blocks.log);
        world.setBlock(i + 10, j + 38, k + 21, Blocks.log);
        world.setBlock(i + 10, j + 38, k + 124, Blocks.log);
        world.setBlock(i + 10, j + 38, k + 125, Blocks.log);
        world.setBlock(i + 10, j + 38, k + 126, Blocks.log);
        world.setBlock(i + 10, j + 39, k + 124, Blocks.log);
        world.setBlock(i + 10, j + 39, k + 125, Blocks.log);
        world.setBlock(i + 10, j + 39, k + 126, Blocks.log);
        world.setBlock(i + 10, j + 40, k + 123, Blocks.log);
        world.setBlock(i + 10, j + 40, k + 124, Blocks.log);
        world.setBlock(i + 10, j + 40, k + 125, Blocks.log);
        world.setBlock(i + 10, j + 40, k + 126, Blocks.log);
        world.setBlock(i + 10, j + 41, k + 87, Dungeons.blockUnbreableStone);
        world.setBlock(i + 10, j + 41, k + 88, Dungeons.blockUnbreableStone);
        world.setBlock(i + 10, j + 41, k + 89, Dungeons.blockUnbreableStone);
        world.setBlock(i + 10, j + 41, k + 90, Dungeons.blockUnbreableStone);
        world.setBlock(i + 10, j + 41, k + 91, Dungeons.blockUnbreableStone);
        world.setBlock(i + 10, j + 41, k + 122, Blocks.log);
        world.setBlock(i + 10, j + 41, k + 123, Blocks.log);
        world.setBlock(i + 10, j + 41, k + 124, Blocks.log);
        world.setBlock(i + 10, j + 41, k + 125, Blocks.log);
        world.setBlock(i + 10, j + 41, k + 126, Blocks.log);
        world.setBlock(i + 10, j + 42, k + 85, Dungeons.blockUnbreableStone);
        world.setBlock(i + 10, j + 42, k + 86, Dungeons.blockUnbreableStone);
        world.setBlock(i + 10, j + 42, k + 87, Dungeons.blockUnbreableStone);
        world.setBlock(i + 10, j + 42, k + 88, Dungeons.blockUnbreableStone);
        world.setBlock(i + 10, j + 42, k + 89, Dungeons.blockUnbreableStone);
        world.setBlock(i + 10, j + 42, k + 90, Dungeons.blockUnbreableStone);
        world.setBlock(i + 10, j + 42, k + 91, Dungeons.blockUnbreableStone);
        world.setBlock(i + 10, j + 42, k + 92, Dungeons.blockUnbreableStone);
        world.setBlock(i + 10, j + 42, k + 93, Dungeons.blockUnbreableStone);
        world.setBlock(i + 10, j + 42, k + 94, Dungeons.blockUnbreableStone);
        world.setBlock(i + 10, j + 42, k + 122, Blocks.log);
        world.setBlock(i + 10, j + 42, k + 123, Blocks.log);
        world.setBlock(i + 10, j + 42, k + 124, Blocks.log);
        world.setBlock(i + 10, j + 42, k + 125, Blocks.log);
        world.setBlock(i + 10, j + 42, k + 126, Blocks.log);
        world.setBlock(i + 10, j + 43, k + 83, Blocks.dirt);
        world.setBlock(i + 10, j + 43, k + 84, Dungeons.blockUnbreableStone);
        world.setBlock(i + 10, j + 43, k + 85, Dungeons.blockUnbreableStone);
        world.setBlock(i + 10, j + 43, k + 86, Dungeons.blockUnbreableStone);
        world.setBlock(i + 10, j + 43, k + 87, Dungeons.blockUnbreableStone);
        world.setBlock(i + 10, j + 43, k + 88, Dungeons.blockUnbreableStone);
        world.setBlock(i + 10, j + 43, k + 89, Dungeons.blockUnbreableStone);
        world.setBlock(i + 10, j + 43, k + 90, Dungeons.blockUnbreableStone);
        world.setBlock(i + 10, j + 43, k + 91, Dungeons.blockUnbreableStone);
        world.setBlock(i + 10, j + 43, k + 92, Dungeons.blockUnbreableStone);
        world.setBlock(i + 10, j + 43, k + 93, Dungeons.blockUnbreableStone);
        world.setBlock(i + 10, j + 43, k + 94, Dungeons.blockUnbreableStone);
        world.setBlock(i + 10, j + 43, k + 95, Dungeons.blockUnbreableStone);
        world.setBlock(i + 10, j + 43, k + 115, Dungeons.blockUnbreableStone);
        world.setBlock(i + 10, j + 43, k + 116, Dungeons.blockUnbreableStone);
        world.setBlock(i + 10, j + 43, k + 117, Dungeons.blockUnbreableStone);
        world.setBlock(i + 10, j + 43, k + 118, Dungeons.blockUnbreableStone);
        world.setBlock(i + 10, j + 43, k + 122, Blocks.log);
        world.setBlock(i + 10, j + 43, k + 123, Blocks.log);
        world.setBlock(i + 10, j + 43, k + 124, Blocks.log);
        world.setBlock(i + 10, j + 43, k + 125, Blocks.log);
        world.setBlock(i + 10, j + 43, k + 126, Blocks.log);
        world.setBlock(i + 10, j + 44, k + 82, Blocks.dirt);
        world.setBlock(i + 10, j + 44, k + 83, Blocks.dirt);
        world.setBlock(i + 10, j + 44, k + 84, Dungeons.blockUnbreableStone);
        world.setBlock(i + 10, j + 44, k + 85, Dungeons.blockUnbreableStone);
        world.setBlock(i + 10, j + 44, k + 86, Dungeons.blockUnbreableStone);
        world.setBlock(i + 10, j + 44, k + 87, Dungeons.blockUnbreableStone);
        world.setBlock(i + 10, j + 44, k + 88, Dungeons.blockUnbreableStone);
        world.setBlock(i + 10, j + 44, k + 89, Dungeons.blockUnbreableStone);
        world.setBlock(i + 10, j + 44, k + 90, Dungeons.blockUnbreableStone);
        world.setBlock(i + 10, j + 44, k + 91, Dungeons.blockUnbreableStone);
        world.setBlock(i + 10, j + 44, k + 92, Dungeons.blockUnbreableStone);
        world.setBlock(i + 10, j + 44, k + 93, Dungeons.blockUnbreableStone);
        world.setBlock(i + 10, j + 44, k + 94, Dungeons.blockUnbreableStone);
        world.setBlock(i + 10, j + 44, k + 95, Dungeons.blockUnbreableStone);
        world.setBlock(i + 10, j + 44, k + 113, Dungeons.blockUnbreableStone);
        world.setBlock(i + 10, j + 44, k + 114, Dungeons.blockUnbreableStone);
        world.setBlock(i + 10, j + 44, k + 115, Dungeons.blockUnbreableStone);
        world.setBlock(i + 10, j + 44, k + 116, Dungeons.blockUnbreableStone);
        world.setBlock(i + 10, j + 44, k + 117, Dungeons.blockUnbreableStone);
        world.setBlock(i + 10, j + 44, k + 118, Dungeons.blockUnbreableStone);
        world.setBlock(i + 10, j + 44, k + 119, Dungeons.blockUnbreableStone);
        world.setBlock(i + 10, j + 44, k + 121, Blocks.log);
        world.setBlock(i + 10, j + 44, k + 122, Blocks.log);
        world.setBlock(i + 10, j + 44, k + 123, Blocks.log);
        world.setBlock(i + 10, j + 45, k + 82, Blocks.dirt);
        world.setBlock(i + 10, j + 45, k + 83, Blocks.dirt);
        world.setBlock(i + 10, j + 45, k + 84, Blocks.dirt);
        world.setBlock(i + 10, j + 45, k + 85, Blocks.dirt);
        world.setBlock(i + 10, j + 45, k + 86, Blocks.dirt);
        world.setBlock(i + 10, j + 45, k + 87, Dungeons.blockUnbreableStone);
        world.setBlock(i + 10, j + 45, k + 88, Blocks.dirt);
        world.setBlock(i + 10, j + 45, k + 89, Blocks.dirt);
        world.setBlock(i + 10, j + 45, k + 90, Blocks.dirt);
        world.setBlock(i + 10, j + 45, k + 91, Blocks.dirt);
        world.setBlock(i + 10, j + 45, k + 92, Blocks.dirt);
        world.setBlock(i + 10, j + 45, k + 93, Blocks.dirt);
        world.setBlock(i + 10, j + 45, k + 94, Blocks.dirt);
        world.setBlock(i + 10, j + 45, k + 95, Blocks.dirt);
        world.setBlock(i + 10, j + 45, k + 96, Dungeons.blockUnbreableStone);
        world.setBlock(i + 10, j + 45, k + 97, Blocks.dirt);
        world.setBlock(i + 10, j + 45, k + 112, Blocks.dirt);
        world.setBlock(i + 10, j + 45, k + 113, Blocks.dirt);
        world.setBlock(i + 10, j + 45, k + 114, Blocks.dirt);
        world.setBlock(i + 10, j + 45, k + 115, Blocks.dirt);
        world.setBlock(i + 10, j + 45, k + 116, Blocks.dirt);
        world.setBlock(i + 10, j + 45, k + 117, Blocks.dirt);
        world.setBlock(i + 10, j + 45, k + 118, Blocks.dirt);
        world.setBlock(i + 10, j + 45, k + 119, Blocks.dirt);
        world.setBlock(i + 10, j + 45, k + 120, Blocks.log);
        world.setBlock(i + 10, j + 45, k + 121, Blocks.log);
        world.setBlock(i + 10, j + 45, k + 122, Blocks.log);
        world.setBlock(i + 10, j + 46, k + 79, Blocks.dirt);
        world.setBlock(i + 10, j + 46, k + 80, Dungeons.blockUnbreableGrass);
        world.setBlock(i + 10, j + 46, k + 81, Dungeons.blockUnbreableGrass);
        world.setBlock(i + 10, j + 46, k + 82, Dungeons.blockUnbreableGrass);
        world.setBlock(i + 10, j + 46, k + 83, Dungeons.blockUnbreableGrass);
        world.setBlock(i + 10, j + 46, k + 84, Dungeons.blockUnbreableGrass);
        world.setBlock(i + 10, j + 46, k + 85, Dungeons.blockUnbreableGrass);
        world.setBlock(i + 10, j + 46, k + 86, Dungeons.blockUnbreableGrass);
        world.setBlock(i + 10, j + 46, k + 87, Blocks.dirt);
        world.setBlock(i + 10, j + 46, k + 88, Blocks.dirt);
        world.setBlock(i + 10, j + 46, k + 89, Blocks.dirt);
        world.setBlock(i + 10, j + 46, k + 90, Blocks.dirt);
        world.setBlock(i + 10, j + 46, k + 91, Blocks.dirt);
        world.setBlock(i + 10, j + 46, k + 92, Blocks.dirt);
        world.setBlock(i + 10, j + 46, k + 93, Blocks.dirt);
        world.setBlock(i + 10, j + 46, k + 94, Blocks.dirt);
        world.setBlock(i + 10, j + 46, k + 95, Blocks.dirt);
        world.setBlock(i + 10, j + 46, k + 96, Blocks.dirt);
        world.setBlock(i + 10, j + 46, k + 97, Blocks.dirt);
        world.setBlock(i + 10, j + 46, k + 98, Blocks.dirt);
        world.setBlock(i + 10, j + 46, k + 99, Dungeons.blockUnbreableGrass);
        world.setBlock(i + 10, j + 46, k + 111, Dungeons.blockUnbreableGrass);
        world.setBlock(i + 10, j + 46, k + 112, Dungeons.blockUnbreableGrass);
        world.setBlock(i + 10, j + 46, k + 113, Dungeons.blockUnbreableGrass);
        world.setBlock(i + 10, j + 46, k + 114, Dungeons.blockUnbreableGrass);
        world.setBlock(i + 10, j + 46, k + 115, Dungeons.blockUnbreableGrass);
        world.setBlock(i + 10, j + 46, k + 116, Dungeons.blockUnbreableGrass);
        world.setBlock(i + 10, j + 46, k + 117, Dungeons.blockUnbreableGrass);
        world.setBlock(i + 10, j + 46, k + 118, Dungeons.blockUnbreableGrass);
        world.setBlock(i + 10, j + 46, k + 119, Dungeons.blockUnbreableGrass);
        world.setBlock(i + 10, j + 46, k + 120, Dungeons.blockUnbreableGrass);
        world.setBlock(i + 10, j + 46, k + 121, Blocks.log);
        world.setBlock(i + 10, j + 46, k + 122, Dungeons.blockUnbreableGrass);
        world.setBlock(i + 10, j + 47, k + 73, Blocks.log);
        world.setBlock(i + 10, j + 47, k + 74, Blocks.log);
        world.setBlock(i + 10, j + 47, k + 75, Blocks.log);
        world.setBlock(i + 10, j + 47, k + 76, Blocks.log);
        world.setBlock(i + 10, j + 47, k + 77, Blocks.log);
        world.setBlock(i + 10, j + 47, k + 78, Blocks.log);
        world.setBlock(i + 10, j + 47, k + 79, Blocks.log);
        world.setBlock(i + 10, j + 47, k + 87, Dungeons.blockUnbreableGrass);
        world.setBlock(i + 10, j + 47, k + 88, Blocks.dirt);
        world.setBlock(i + 10, j + 47, k + 89, Blocks.dirt);
        world.setBlock(i + 10, j + 47, k + 90, Blocks.dirt);
        world.setBlock(i + 10, j + 47, k + 91, Blocks.dirt);
        world.setBlock(i + 10, j + 47, k + 92, Blocks.dirt);
        world.setBlock(i + 10, j + 47, k + 93, Blocks.dirt);
        world.setBlock(i + 10, j + 47, k + 94, Blocks.dirt);
        world.setBlock(i + 10, j + 47, k + 95, Blocks.dirt);
        world.setBlock(i + 10, j + 47, k + 96, Blocks.dirt);
        world.setBlock(i + 10, j + 47, k + 97, Dungeons.blockUnbreableGrass);
        world.setBlock(i + 10, j + 47, k + 98, Dungeons.blockUnbreableGrass);
        world.setBlock(i + 10, j + 48, k + 75, Blocks.log);
        world.setBlock(i + 10, j + 48, k + 76, Blocks.log);
        world.setBlock(i + 10, j + 48, k + 77, Blocks.log);
        world.setBlock(i + 10, j + 48, k + 88, Dungeons.blockUnbreableGrass);
        world.setBlock(i + 10, j + 48, k + 89, Blocks.dirt);
        world.setBlock(i + 10, j + 48, k + 90, Blocks.dirt);
        world.setBlock(i + 10, j + 48, k + 91, Blocks.dirt);
        world.setBlock(i + 10, j + 48, k + 92, Blocks.dirt);
        world.setBlock(i + 10, j + 48, k + 93, Blocks.dirt);
        world.setBlock(i + 10, j + 48, k + 94, Blocks.dirt);
        world.setBlock(i + 10, j + 48, k + 95, Blocks.dirt);
        world.setBlock(i + 10, j + 48, k + 96, Blocks.dirt);
        world.setBlock(i + 10, j + 49, k + 89, Dungeons.blockUnbreableGrass);
        world.setBlock(i + 10, j + 49, k + 90, Dungeons.blockUnbreableGrass);
        world.setBlock(i + 10, j + 49, k + 91, Blocks.dirt);
        world.setBlock(i + 10, j + 49, k + 92, Blocks.dirt);
        world.setBlock(i + 10, j + 49, k + 93, Blocks.dirt);
        world.setBlock(i + 10, j + 49, k + 94, Blocks.dirt);
        world.setBlock(i + 10, j + 49, k + 95, Dungeons.blockUnbreableGrass);
        world.setBlock(i + 10, j + 49, k + 96, Dungeons.blockUnbreableGrass);
        world.setBlock(i + 10, j + 50, k + 91, Dungeons.blockUnbreableGrass);
        world.setBlock(i + 10, j + 50, k + 92, Dungeons.blockUnbreableGrass);
        world.setBlock(i + 10, j + 50, k + 93, Dungeons.blockUnbreableGrass);
        world.setBlock(i + 10, j + 50, k + 94, Dungeons.blockUnbreableGrass);
        world.setBlock(i + 10, j + 89, k + 43, Blocks.wool, 1, 0);
        world.setBlock(i + 10, j + 89, k + 44, Blocks.wool, 1, 0);
        world.setBlock(i + 10, j + 89, k + 47, Blocks.wool, 1, 0);
        world.setBlock(i + 10, j + 90, k + 45, Blocks.wool, 1, 0);
        world.setBlock(i + 10, j + 90, k + 46, Blocks.wool, 1, 0);
        world.setBlock(i + 10, j + 129, k + 42, Blocks.wool, 1, 0);
        world.setBlock(i + 10, j + 129, k + 43, Blocks.wool, 1, 0);
        world.setBlock(i + 10, j + 129, k + 44, Blocks.wool, 1, 0);
        world.setBlock(i + 10, j + 129, k + 45, Blocks.wool, 1, 0);
        world.setBlock(i + 10, j + 129, k + 48, Blocks.wool, 1, 0);
        world.setBlock(i + 10, j + 129, k + 49, Blocks.wool, 1, 0);
        world.setBlock(i + 10, j + 129, k + 50, Blocks.wool, 1, 0);
        world.setBlock(i + 10, j + 129, k + 55, Blocks.wool, 1, 0);
        world.setBlock(i + 10, j + 129, k + 56, Blocks.wool, 1, 0);
        world.setBlock(i + 10, j + 130, k + 46, Blocks.wool, 1, 0);
        world.setBlock(i + 10, j + 130, k + 47, Blocks.wool, 1, 0);
        world.setBlock(i + 10, j + 130, k + 51, Blocks.wool, 1, 0);
        world.setBlock(i + 10, j + 130, k + 52, Blocks.wool, 1, 0);
        world.setBlock(i + 10, j + 130, k + 53, Blocks.wool, 1, 0);
        world.setBlock(i + 10, j + 130, k + 54, Blocks.wool, 1, 0);
        world.setBlock(i + 11, j + 35, k + 19, Blocks.log);
        world.setBlock(i + 11, j + 35, k + 20, Blocks.log);
        world.setBlock(i + 11, j + 35, k + 21, Blocks.log);
        world.setBlock(i + 11, j + 36, k + 19, Blocks.log);
        world.setBlock(i + 11, j + 36, k + 20, Blocks.log);
        world.setBlock(i + 11, j + 36, k + 21, Blocks.log);
        world.setBlock(i + 11, j + 36, k + 22, Blocks.log);
        world.setBlock(i + 11, j + 37, k + 19, Blocks.log);
        world.setBlock(i + 11, j + 37, k + 20, Blocks.log);
        world.setBlock(i + 11, j + 37, k + 21, Blocks.log);
        world.setBlock(i + 11, j + 37, k + 22, Blocks.log);
        world.setBlock(i + 11, j + 38, k + 20, Blocks.log);
        world.setBlock(i + 11, j + 38, k + 21, Blocks.log);
        world.setBlock(i + 11, j + 38, k + 22, Blocks.log);
        world.setBlock(i + 11, j + 38, k + 125, Blocks.log);
        world.setBlock(i + 11, j + 39, k + 21, Blocks.log);
        world.setBlock(i + 11, j + 39, k + 124, Blocks.log);
        world.setBlock(i + 11, j + 39, k + 125, Blocks.log);
        world.setBlock(i + 11, j + 39, k + 126, Blocks.log);
        world.setBlock(i + 11, j + 40, k + 89, Dungeons.blockUnbreableStone);
        world.setBlock(i + 11, j + 40, k + 90, Dungeons.blockUnbreableStone);
        world.setBlock(i + 11, j + 40, k + 124, Blocks.log);
        world.setBlock(i + 11, j + 40, k + 125, Blocks.log);
        world.setBlock(i + 11, j + 40, k + 126, Blocks.log);
        world.setBlock(i + 11, j + 41, k + 86, Dungeons.blockUnbreableStone);
        world.setBlock(i + 11, j + 41, k + 87, Dungeons.blockUnbreableStone);
        world.setBlock(i + 11, j + 41, k + 88, Dungeons.blockUnbreableStone);
        world.setBlock(i + 11, j + 41, k + 89, Dungeons.blockUnbreableStone);
        world.setBlock(i + 11, j + 41, k + 90, Dungeons.blockUnbreableStone);
        world.setBlock(i + 11, j + 41, k + 91, Dungeons.blockUnbreableStone);
        world.setBlock(i + 11, j + 41, k + 92, Dungeons.blockUnbreableStone);
        world.setBlock(i + 11, j + 41, k + 93, Dungeons.blockUnbreableStone);
        world.setBlock(i + 11, j + 41, k + 123, Blocks.log);
        world.setBlock(i + 11, j + 41, k + 124, Blocks.log);
        world.setBlock(i + 11, j + 41, k + 125, Blocks.log);
        world.setBlock(i + 11, j + 42, k + 84, Dungeons.blockUnbreableStone);
        world.setBlock(i + 11, j + 42, k + 85, Dungeons.blockUnbreableStone);
        world.setBlock(i + 11, j + 42, k + 86, Dungeons.blockUnbreableStone);
        world.setBlock(i + 11, j + 42, k + 87, Dungeons.blockUnbreableStone);
        world.setBlock(i + 11, j + 42, k + 88, Dungeons.blockUnbreableStone);
        world.setBlock(i + 11, j + 42, k + 89, Dungeons.blockUnbreableStone);
        world.setBlock(i + 11, j + 42, k + 90, Dungeons.blockUnbreableStone);
        world.setBlock(i + 11, j + 42, k + 91, Dungeons.blockUnbreableStone);
        world.setBlock(i + 11, j + 42, k + 92, Dungeons.blockUnbreableStone);
        world.setBlock(i + 11, j + 42, k + 93, Dungeons.blockUnbreableStone);
        world.setBlock(i + 11, j + 42, k + 94, Dungeons.blockUnbreableStone);
        world.setBlock(i + 11, j + 42, k + 115, Dungeons.blockUnbreableStone);
        world.setBlock(i + 11, j + 42, k + 116, Dungeons.blockUnbreableStone);
        world.setBlock(i + 11, j + 42, k + 117, Dungeons.blockUnbreableStone);
        world.setBlock(i + 11, j + 42, k + 122, Blocks.log);
        world.setBlock(i + 11, j + 42, k + 123, Blocks.log);
        world.setBlock(i + 11, j + 42, k + 124, Blocks.log);
        world.setBlock(i + 11, j + 42, k + 125, Blocks.log);
        world.setBlock(i + 11, j + 42, k + 126, Blocks.log);
        world.setBlock(i + 11, j + 43, k + 82, Blocks.dirt);
        world.setBlock(i + 11, j + 43, k + 83, Blocks.dirt);
        world.setBlock(i + 11, j + 43, k + 84, Dungeons.blockUnbreableStone);
        world.setBlock(i + 11, j + 43, k + 85, Dungeons.blockUnbreableStone);
        world.setBlock(i + 11, j + 43, k + 86, Dungeons.blockUnbreableStone);
        world.setBlock(i + 11, j + 43, k + 87, Dungeons.blockUnbreableStone);
        world.setBlock(i + 11, j + 43, k + 88, Dungeons.blockUnbreableStone);
        world.setBlock(i + 11, j + 43, k + 89, Dungeons.blockUnbreableStone);
        world.setBlock(i + 11, j + 43, k + 90, Dungeons.blockUnbreableStone);
        world.setBlock(i + 11, j + 43, k + 91, Dungeons.blockUnbreableStone);
        world.setBlock(i + 11, j + 43, k + 92, Dungeons.blockUnbreableStone);
        world.setBlock(i + 11, j + 43, k + 93, Dungeons.blockUnbreableStone);
        world.setBlock(i + 11, j + 43, k + 94, Dungeons.blockUnbreableStone);
        world.setBlock(i + 11, j + 43, k + 95, Dungeons.blockUnbreableStone);
        world.setBlock(i + 11, j + 43, k + 114, Dungeons.blockUnbreableStone);
        world.setBlock(i + 11, j + 43, k + 115, Dungeons.blockUnbreableStone);
        world.setBlock(i + 11, j + 43, k + 116, Dungeons.blockUnbreableStone);
        world.setBlock(i + 11, j + 43, k + 117, Dungeons.blockUnbreableStone);
        world.setBlock(i + 11, j + 43, k + 118, Dungeons.blockUnbreableStone);
        world.setBlock(i + 11, j + 43, k + 119, Dungeons.blockUnbreableStone);
        world.setBlock(i + 11, j + 43, k + 121, Blocks.log);
        world.setBlock(i + 11, j + 43, k + 122, Blocks.log);
        world.setBlock(i + 11, j + 43, k + 123, Blocks.log);
        world.setBlock(i + 11, j + 43, k + 124, Blocks.log);
        world.setBlock(i + 11, j + 43, k + 125, Blocks.log);
        world.setBlock(i + 11, j + 44, k + 80, Blocks.dirt);
        world.setBlock(i + 11, j + 44, k + 81, Blocks.dirt);
        world.setBlock(i + 11, j + 44, k + 82, Blocks.dirt);
        world.setBlock(i + 11, j + 44, k + 83, Blocks.dirt);
        world.setBlock(i + 11, j + 44, k + 84, Dungeons.blockUnbreableStone);
        world.setBlock(i + 11, j + 44, k + 85, Dungeons.blockUnbreableStone);
        world.setBlock(i + 11, j + 44, k + 86, Dungeons.blockUnbreableStone);
        world.setBlock(i + 11, j + 44, k + 87, Dungeons.blockUnbreableStone);
        world.setBlock(i + 11, j + 44, k + 88, Dungeons.blockUnbreableStone);
        world.setBlock(i + 11, j + 44, k + 89, Dungeons.blockUnbreableStone);
        world.setBlock(i + 11, j + 44, k + 90, Dungeons.blockUnbreableStone);
        world.setBlock(i + 11, j + 44, k + 91, Dungeons.blockUnbreableStone);
        world.setBlock(i + 11, j + 44, k + 92, Dungeons.blockUnbreableStone);
        world.setBlock(i + 11, j + 44, k + 93, Dungeons.blockUnbreableStone);
        world.setBlock(i + 11, j + 44, k + 94, Dungeons.blockUnbreableStone);
        world.setBlock(i + 11, j + 44, k + 95, Dungeons.blockUnbreableStone);
        world.setBlock(i + 11, j + 44, k + 96, Dungeons.blockUnbreableStone);
        world.setBlock(i + 11, j + 44, k + 113, Dungeons.blockUnbreableStone);
        world.setBlock(i + 11, j + 44, k + 114, Dungeons.blockUnbreableStone);
        world.setBlock(i + 11, j + 44, k + 115, Dungeons.blockUnbreableStone);
        world.setBlock(i + 11, j + 44, k + 116, Dungeons.blockUnbreableStone);
        world.setBlock(i + 11, j + 44, k + 117, Dungeons.blockUnbreableStone);
        world.setBlock(i + 11, j + 44, k + 118, Dungeons.blockUnbreableStone);
        world.setBlock(i + 11, j + 44, k + 119, Dungeons.blockUnbreableStone);
        world.setBlock(i + 11, j + 44, k + 120, Blocks.log);
        world.setBlock(i + 11, j + 44, k + 121, Blocks.log);
        world.setBlock(i + 11, j + 44, k + 122, Blocks.log);
        world.setBlock(i + 11, j + 44, k + 123, Blocks.log);
        world.setBlock(i + 11, j + 44, k + 124, Blocks.log);
        world.setBlock(i + 11, j + 45, k + 80, Blocks.dirt);
        world.setBlock(i + 11, j + 45, k + 81, Blocks.dirt);
        world.setBlock(i + 11, j + 45, k + 82, Blocks.dirt);
        world.setBlock(i + 11, j + 45, k + 83, Blocks.dirt);
        world.setBlock(i + 11, j + 45, k + 84, Blocks.dirt);
        world.setBlock(i + 11, j + 45, k + 85, Blocks.dirt);
        world.setBlock(i + 11, j + 45, k + 86, Blocks.dirt);
        world.setBlock(i + 11, j + 45, k + 87, Dungeons.blockUnbreableStone);
        world.setBlock(i + 11, j + 45, k + 88, Blocks.dirt);
        world.setBlock(i + 11, j + 45, k + 89, Blocks.dirt);
        world.setBlock(i + 11, j + 45, k + 90, Blocks.dirt);
        world.setBlock(i + 11, j + 45, k + 91, Blocks.dirt);
        world.setBlock(i + 11, j + 45, k + 92, Blocks.dirt);
        world.setBlock(i + 11, j + 45, k + 93, Blocks.dirt);
        world.setBlock(i + 11, j + 45, k + 94, Blocks.dirt);
        world.setBlock(i + 11, j + 45, k + 95, Blocks.dirt);
        world.setBlock(i + 11, j + 45, k + 96, Blocks.dirt);
        world.setBlock(i + 11, j + 45, k + 97, Blocks.dirt);
        world.setBlock(i + 11, j + 45, k + 112, Blocks.dirt);
        world.setBlock(i + 11, j + 45, k + 113, Blocks.dirt);
        world.setBlock(i + 11, j + 45, k + 114, Blocks.dirt);
        world.setBlock(i + 11, j + 45, k + 115, Blocks.dirt);
        world.setBlock(i + 11, j + 45, k + 116, Blocks.dirt);
        world.setBlock(i + 11, j + 45, k + 117, Blocks.dirt);
        world.setBlock(i + 11, j + 45, k + 118, Blocks.dirt);
        world.setBlock(i + 11, j + 45, k + 119, Blocks.dirt);
        world.setBlock(i + 11, j + 45, k + 120, Blocks.log);
        world.setBlock(i + 11, j + 45, k + 121, Blocks.log);
        world.setBlock(i + 11, j + 45, k + 122, Blocks.log);
        world.setBlock(i + 11, j + 45, k + 123, Blocks.log);
        world.setBlock(i + 11, j + 46, k + 23, Dungeons.blockUnbreableGrass);
        world.setBlock(i + 11, j + 46, k + 24, Dungeons.blockUnbreableGrass);
        world.setBlock(i + 11, j + 46, k + 25, Dungeons.blockUnbreableGrass);
        world.setBlock(i + 11, j + 46, k + 26, Dungeons.blockUnbreableGrass);
        world.setBlock(i + 11, j + 46, k + 27, Dungeons.blockUnbreableGrass);
        world.setBlock(i + 11, j + 46, k + 28, Dungeons.blockUnbreableGrass);
        world.setBlock(i + 11, j + 46, k + 29, Dungeons.blockUnbreableGrass);
        world.setBlock(i + 11, j + 46, k + 30, Dungeons.blockUnbreableGrass);
        world.setBlock(i + 11, j + 46, k + 77, Blocks.dirt);
        world.setBlock(i + 11, j + 46, k + 78, Blocks.dirt);
        world.setBlock(i + 11, j + 46, k + 79, Blocks.dirt);
        world.setBlock(i + 11, j + 46, k + 80, Blocks.dirt);
        world.setBlock(i + 11, j + 46, k + 81, Blocks.dirt);
        world.setBlock(i + 11, j + 46, k + 82, Dungeons.blockUnbreableGrass);
        world.setBlock(i + 11, j + 46, k + 83, Dungeons.blockUnbreableGrass);
        world.setBlock(i + 11, j + 46, k + 84, Dungeons.blockUnbreableGrass);
        world.setBlock(i + 11, j + 46, k + 85, Dungeons.blockUnbreableGrass);
        world.setBlock(i + 11, j + 46, k + 86, Dungeons.blockUnbreableGrass);
        world.setBlock(i + 11, j + 46, k + 87, Blocks.dirt);
        world.setBlock(i + 11, j + 46, k + 88, Blocks.dirt);
        world.setBlock(i + 11, j + 46, k + 89, Blocks.dirt);
        world.setBlock(i + 11, j + 46, k + 90, Blocks.dirt);
        world.setBlock(i + 11, j + 46, k + 91, Blocks.dirt);
        world.setBlock(i + 11, j + 46, k + 92, Blocks.dirt);
        world.setBlock(i + 11, j + 46, k + 93, Blocks.dirt);
        world.setBlock(i + 11, j + 46, k + 94, Blocks.dirt);
        world.setBlock(i + 11, j + 46, k + 95, Blocks.dirt);
        world.setBlock(i + 11, j + 46, k + 96, Blocks.dirt);
        world.setBlock(i + 11, j + 46, k + 97, Blocks.dirt);
        world.setBlock(i + 11, j + 46, k + 98, Blocks.dirt);
        world.setBlock(i + 11, j + 46, k + 99, Dungeons.blockUnbreableGrass);
        world.setBlock(i + 11, j + 46, k + 111, Dungeons.blockUnbreableGrass);
        world.setBlock(i + 11, j + 46, k + 112, Dungeons.blockUnbreableGrass);
        world.setBlock(i + 11, j + 46, k + 113, Dungeons.blockUnbreableGrass);
        world.setBlock(i + 11, j + 46, k + 114, Dungeons.blockUnbreableGrass);
        world.setBlock(i + 11, j + 46, k + 115, Dungeons.blockUnbreableGrass);
        world.setBlock(i + 11, j + 46, k + 116, Dungeons.blockUnbreableGrass);
        world.setBlock(i + 11, j + 46, k + 117, Dungeons.blockUnbreableGrass);
        world.setBlock(i + 11, j + 46, k + 118, Dungeons.blockUnbreableGrass);
        world.setBlock(i + 11, j + 46, k + 119, Blocks.dirt);
        world.setBlock(i + 11, j + 46, k + 120, Blocks.log);
        world.setBlock(i + 11, j + 46, k + 121, Blocks.log);
        world.setBlock(i + 11, j + 46, k + 122, Blocks.log);
        world.setBlock(i + 11, j + 47, k + 74, Blocks.log);
        world.setBlock(i + 11, j + 47, k + 75, Blocks.log);
        world.setBlock(i + 11, j + 47, k + 76, Blocks.log);
        world.setBlock(i + 11, j + 47, k + 77, Blocks.log);
        world.setBlock(i + 11, j + 47, k + 78, Blocks.log);
        world.setBlock(i + 11, j + 47, k + 79, Blocks.log);
        world.setBlock(i + 11, j + 47, k + 80, Blocks.log);
        world.setBlock(i + 11, j + 47, k + 81, Blocks.log);
        world.setBlock(i + 11, j + 47, k + 87, Dungeons.blockUnbreableGrass);
        world.setBlock(i + 11, j + 47, k + 88, Blocks.dirt);
        world.setBlock(i + 11, j + 47, k + 89, Blocks.dirt);
        world.setBlock(i + 11, j + 47, k + 90, Blocks.dirt);
        world.setBlock(i + 11, j + 47, k + 91, Blocks.dirt);
        world.setBlock(i + 11, j + 47, k + 92, Blocks.dirt);
        world.setBlock(i + 11, j + 47, k + 93, Blocks.dirt);
        world.setBlock(i + 11, j + 47, k + 94, Blocks.dirt);
        world.setBlock(i + 11, j + 47, k + 95, Blocks.dirt);
        world.setBlock(i + 11, j + 47, k + 96, Blocks.dirt);
        world.setBlock(i + 11, j + 47, k + 97, Blocks.dirt);
        world.setBlock(i + 11, j + 47, k + 98, Dungeons.blockUnbreableGrass);
        world.setBlock(i + 11, j + 47, k + 119, Blocks.log);
        world.setBlock(i + 11, j + 47, k + 120, Blocks.log);
        world.setBlock(i + 11, j + 47, k + 121, Blocks.log);
        world.setBlock(i + 11, j + 48, k + 75, Blocks.log);
        world.setBlock(i + 11, j + 48, k + 76, Blocks.log);
        world.setBlock(i + 11, j + 48, k + 77, Blocks.log);
        world.setBlock(i + 11, j + 48, k + 78, Blocks.log);
        world.setBlock(i + 11, j + 48, k + 79, Blocks.log);
        world.setBlock(i + 11, j + 48, k + 88, Dungeons.blockUnbreableGrass);
        world.setBlock(i + 11, j + 48, k + 89, Blocks.dirt);
        world.setBlock(i + 11, j + 48, k + 90, Blocks.dirt);
        world.setBlock(i + 11, j + 48, k + 91, Blocks.dirt);
        world.setBlock(i + 11, j + 48, k + 92, Blocks.dirt);
        world.setBlock(i + 11, j + 48, k + 93, Blocks.dirt);
        world.setBlock(i + 11, j + 48, k + 94, Blocks.dirt);
        world.setBlock(i + 11, j + 48, k + 95, Blocks.dirt);
        world.setBlock(i + 11, j + 48, k + 96, Blocks.dirt);
        world.setBlock(i + 11, j + 48, k + 97, Dungeons.blockUnbreableGrass);
        world.setBlock(i + 11, j + 49, k + 89, Dungeons.blockUnbreableGrass);
        world.setBlock(i + 11, j + 49, k + 90, Blocks.dirt);
        world.setBlock(i + 11, j + 49, k + 91, Blocks.dirt);
        world.setBlock(i + 11, j + 49, k + 92, Blocks.dirt);
        world.setBlock(i + 11, j + 49, k + 93, Blocks.dirt);
        world.setBlock(i + 11, j + 49, k + 94, Blocks.dirt);
        world.setBlock(i + 11, j + 49, k + 95, Blocks.dirt);
        world.setBlock(i + 11, j + 49, k + 96, Dungeons.blockUnbreableGrass);
        world.setBlock(i + 11, j + 50, k + 90, Dungeons.blockUnbreableGrass);
        world.setBlock(i + 11, j + 50, k + 91, Dungeons.blockUnbreableGrass);
        world.setBlock(i + 11, j + 50, k + 92, Dungeons.blockUnbreableGrass);
        world.setBlock(i + 11, j + 50, k + 93, Dungeons.blockUnbreableGrass);
        world.setBlock(i + 11, j + 50, k + 94, Dungeons.blockUnbreableGrass);
        world.setBlock(i + 11, j + 50, k + 95, Dungeons.blockUnbreableGrass);
        world.setBlock(i + 11, j + 89, k + 41, Blocks.wool, 1, 0);
        world.setBlock(i + 11, j + 90, k + 42, Blocks.wool, 1, 0);
        world.setBlock(i + 11, j + 90, k + 43, Blocks.wool, 1, 0);
        world.setBlock(i + 11, j + 90, k + 48, Blocks.wool, 1, 0);
        world.setBlock(i + 11, j + 90, k + 49, Blocks.wool, 1, 0);
        world.setBlock(i + 11, j + 91, k + 44, Blocks.wool, 1, 0);
        world.setBlock(i + 11, j + 91, k + 45, Blocks.wool, 1, 0);
        world.setBlock(i + 11, j + 91, k + 46, Blocks.wool, 1, 0);
        world.setBlock(i + 11, j + 91, k + 47, Blocks.wool, 1, 0);
        world.setBlock(i + 11, j + 129, k + 39, Blocks.wool, 1, 0);
        world.setBlock(i + 11, j + 129, k + 40, Blocks.wool, 1, 0);
        world.setBlock(i + 11, j + 129, k + 41, Blocks.wool, 1, 0);
        world.setBlock(i + 11, j + 129, k + 57, Blocks.wool, 1, 0);
        world.setBlock(i + 11, j + 130, k + 42, Blocks.wool, 1, 0);
        world.setBlock(i + 11, j + 130, k + 43, Blocks.wool, 1, 0);
        world.setBlock(i + 11, j + 130, k + 44, Blocks.wool, 1, 0);
        world.setBlock(i + 11, j + 130, k + 45, Blocks.wool, 1, 0);
        world.setBlock(i + 11, j + 130, k + 55, Blocks.wool, 1, 0);
        world.setBlock(i + 11, j + 130, k + 56, Blocks.wool, 1, 0);
        world.setBlock(i + 11, j + 131, k + 46, Blocks.wool, 1, 0);
        world.setBlock(i + 11, j + 131, k + 47, Blocks.wool, 1, 0);
        world.setBlock(i + 11, j + 131, k + 48, Blocks.wool, 1, 0);
        world.setBlock(i + 11, j + 131, k + 49, Blocks.wool, 1, 0);
        world.setBlock(i + 11, j + 131, k + 50, Blocks.wool, 1, 0);
        world.setBlock(i + 11, j + 131, k + 51, Blocks.wool, 1, 0);
        world.setBlock(i + 11, j + 131, k + 52, Blocks.wool, 1, 0);
        world.setBlock(i + 11, j + 131, k + 53, Blocks.wool, 1, 0);
        world.setBlock(i + 11, j + 131, k + 54, Blocks.wool, 1, 0);
        world.setBlock(i + 12, j + 35, k + 20, Blocks.log);
        world.setBlock(i + 12, j + 36, k + 19, Blocks.log);
        world.setBlock(i + 12, j + 36, k + 20, Blocks.log);
        world.setBlock(i + 12, j + 36, k + 21, Blocks.log);
        world.setBlock(i + 12, j + 37, k + 20, Blocks.log);
        world.setBlock(i + 12, j + 37, k + 21, Blocks.log);
        world.setBlock(i + 12, j + 37, k + 22, Blocks.log);
        world.setBlock(i + 12, j + 38, k + 20, Blocks.log);
        world.setBlock(i + 12, j + 38, k + 21, Blocks.log);
        world.setBlock(i + 12, j + 38, k + 22, Blocks.log);
        world.setBlock(i + 12, j + 38, k + 23, Blocks.log);
        world.setBlock(i + 12, j + 39, k + 20, Blocks.log);
        world.setBlock(i + 12, j + 39, k + 21, Blocks.log);
        world.setBlock(i + 12, j + 39, k + 22, Blocks.log);
        world.setBlock(i + 12, j + 39, k + 23, Blocks.log);
        world.setBlock(i + 12, j + 39, k + 89, Dungeons.blockUnbreableStone);
        world.setBlock(i + 12, j + 40, k + 22, Blocks.log);
        world.setBlock(i + 12, j + 40, k + 86, Dungeons.blockUnbreableStone);
        world.setBlock(i + 12, j + 40, k + 87, Dungeons.blockUnbreableStone);
        world.setBlock(i + 12, j + 40, k + 88, Dungeons.blockUnbreableStone);
        world.setBlock(i + 12, j + 40, k + 89, Dungeons.blockUnbreableStone);
        world.setBlock(i + 12, j + 40, k + 90, Dungeons.blockUnbreableStone);
        world.setBlock(i + 12, j + 40, k + 91, Dungeons.blockUnbreableStone);
        world.setBlock(i + 12, j + 40, k + 92, Dungeons.blockUnbreableStone);
        world.setBlock(i + 12, j + 41, k + 84, Dungeons.blockUnbreableStone);
        world.setBlock(i + 12, j + 41, k + 85, Dungeons.blockUnbreableStone);
        world.setBlock(i + 12, j + 41, k + 86, Dungeons.blockUnbreableStone);
        world.setBlock(i + 12, j + 41, k + 87, Dungeons.blockUnbreableStone);
        world.setBlock(i + 12, j + 41, k + 88, Dungeons.blockUnbreableStone);
        world.setBlock(i + 12, j + 41, k + 89, Dungeons.blockUnbreableStone);
        world.setBlock(i + 12, j + 41, k + 90, Dungeons.blockUnbreableStone);
        world.setBlock(i + 12, j + 41, k + 91, Dungeons.blockUnbreableStone);
        world.setBlock(i + 12, j + 41, k + 92, Dungeons.blockUnbreableStone);
        world.setBlock(i + 12, j + 41, k + 93, Dungeons.blockUnbreableStone);
        world.setBlock(i + 12, j + 41, k + 94, Dungeons.blockUnbreableStone);
        world.setBlock(i + 12, j + 42, k + 83, Dungeons.blockUnbreableStone);
        world.setBlock(i + 12, j + 42, k + 84, Dungeons.blockUnbreableStone);
        world.setBlock(i + 12, j + 42, k + 85, Dungeons.blockUnbreableStone);
        world.setBlock(i + 12, j + 42, k + 86, Dungeons.blockUnbreableStone);
        world.setBlock(i + 12, j + 42, k + 87, Dungeons.blockUnbreableStone);
        world.setBlock(i + 12, j + 42, k + 88, Dungeons.blockUnbreableStone);
        world.setBlock(i + 12, j + 42, k + 89, Dungeons.blockUnbreableStone);
        world.setBlock(i + 12, j + 42, k + 90, Dungeons.blockUnbreableStone);
        world.setBlock(i + 12, j + 42, k + 91, Dungeons.blockUnbreableStone);
        world.setBlock(i + 12, j + 42, k + 92, Dungeons.blockUnbreableStone);
        world.setBlock(i + 12, j + 42, k + 93, Dungeons.blockUnbreableStone);
        world.setBlock(i + 12, j + 42, k + 94, Dungeons.blockUnbreableStone);
        world.setBlock(i + 12, j + 42, k + 114, Dungeons.blockUnbreableStone);
        world.setBlock(i + 12, j + 42, k + 115, Dungeons.blockUnbreableStone);
        world.setBlock(i + 12, j + 42, k + 116, Dungeons.blockUnbreableStone);
        world.setBlock(i + 12, j + 42, k + 117, Dungeons.blockUnbreableStone);
        world.setBlock(i + 12, j + 42, k + 118, Dungeons.blockUnbreableStone);
        world.setBlock(i + 12, j + 42, k + 123, Blocks.log);
        world.setBlock(i + 12, j + 43, k + 81, Dungeons.blockUnbreableStone);
        world.setBlock(i + 12, j + 43, k + 82, Dungeons.blockUnbreableStone);
        world.setBlock(i + 12, j + 43, k + 83, Dungeons.blockUnbreableStone);
        world.setBlock(i + 12, j + 43, k + 84, Dungeons.blockUnbreableStone);
        world.setBlock(i + 12, j + 43, k + 85, Dungeons.blockUnbreableStone);
        world.setBlock(i + 12, j + 43, k + 86, Dungeons.blockUnbreableStone);
        world.setBlock(i + 12, j + 43, k + 87, Dungeons.blockUnbreableStone);
        world.setBlock(i + 12, j + 43, k + 88, Dungeons.blockUnbreableStone);
        world.setBlock(i + 12, j + 43, k + 89, Dungeons.blockUnbreableStone);
        world.setBlock(i + 12, j + 43, k + 90, Dungeons.blockUnbreableStone);
        world.setBlock(i + 12, j + 43, k + 91, Dungeons.blockUnbreableStone);
        world.setBlock(i + 12, j + 43, k + 92, Dungeons.blockUnbreableStone);
        world.setBlock(i + 12, j + 43, k + 93, Dungeons.blockUnbreableStone);
        world.setBlock(i + 12, j + 43, k + 94, Dungeons.blockUnbreableStone);
        world.setBlock(i + 12, j + 43, k + 95, Dungeons.blockUnbreableStone);
        world.setBlock(i + 12, j + 43, k + 113, Dungeons.blockUnbreableStone);
        world.setBlock(i + 12, j + 43, k + 114, Dungeons.blockUnbreableStone);
        world.setBlock(i + 12, j + 43, k + 115, Dungeons.blockUnbreableStone);
        world.setBlock(i + 12, j + 43, k + 116, Dungeons.blockUnbreableStone);
        world.setBlock(i + 12, j + 43, k + 117, Dungeons.blockUnbreableStone);
        world.setBlock(i + 12, j + 43, k + 118, Dungeons.blockUnbreableStone);
        world.setBlock(i + 12, j + 43, k + 119, Dungeons.blockUnbreableStone);
        world.setBlock(i + 12, j + 43, k + 122, Blocks.log);
        world.setBlock(i + 12, j + 43, k + 123, Blocks.log);
        world.setBlock(i + 12, j + 43, k + 124, Blocks.log);
        world.setBlock(i + 12, j + 44, k + 79, Blocks.dirt);
        world.setBlock(i + 12, j + 44, k + 80, Blocks.dirt);
        world.setBlock(i + 12, j + 44, k + 81, Dungeons.blockUnbreableStone);
        world.setBlock(i + 12, j + 44, k + 82, Dungeons.blockUnbreableStone);
        world.setBlock(i + 12, j + 44, k + 83, Dungeons.blockUnbreableStone);
        world.setBlock(i + 12, j + 44, k + 84, Dungeons.blockUnbreableStone);
        world.setBlock(i + 12, j + 44, k + 85, Dungeons.blockUnbreableStone);
        world.setBlock(i + 12, j + 44, k + 86, Dungeons.blockUnbreableStone);
        world.setBlock(i + 12, j + 44, k + 87, Dungeons.blockUnbreableStone);
        world.setBlock(i + 12, j + 44, k + 88, Dungeons.blockUnbreableStone);
        world.setBlock(i + 12, j + 44, k + 89, Dungeons.blockUnbreableStone);
        world.setBlock(i + 12, j + 44, k + 90, Dungeons.blockUnbreableStone);
        world.setBlock(i + 12, j + 44, k + 91, Dungeons.blockUnbreableStone);
        world.setBlock(i + 12, j + 44, k + 92, Dungeons.blockUnbreableStone);
        world.setBlock(i + 12, j + 44, k + 93, Dungeons.blockUnbreableStone);
        world.setBlock(i + 12, j + 44, k + 94, Dungeons.blockUnbreableStone);
        world.setBlock(i + 12, j + 44, k + 95, Dungeons.blockUnbreableStone);
        world.setBlock(i + 12, j + 44, k + 112, Dungeons.blockUnbreableStone);
        world.setBlock(i + 12, j + 44, k + 113, Dungeons.blockUnbreableStone);
        world.setBlock(i + 12, j + 44, k + 114, Dungeons.blockUnbreableStone);
        world.setBlock(i + 12, j + 44, k + 115, Dungeons.blockUnbreableStone);
        world.setBlock(i + 12, j + 44, k + 116, Dungeons.blockUnbreableStone);
        world.setBlock(i + 12, j + 44, k + 117, Dungeons.blockUnbreableStone);
        world.setBlock(i + 12, j + 44, k + 118, Dungeons.blockUnbreableStone);
        world.setBlock(i + 12, j + 44, k + 119, Dungeons.blockUnbreableStone);
        world.setBlock(i + 12, j + 44, k + 120, Dungeons.blockUnbreableStone);
        world.setBlock(i + 12, j + 44, k + 121, Blocks.log);
        world.setBlock(i + 12, j + 44, k + 122, Blocks.log);
        world.setBlock(i + 12, j + 44, k + 123, Blocks.log);
        world.setBlock(i + 12, j + 45, k + 27, Blocks.dirt);
        world.setBlock(i + 12, j + 45, k + 28, Blocks.dirt);
        world.setBlock(i + 12, j + 45, k + 32, Blocks.dirt);
        world.setBlock(i + 12, j + 45, k + 33, Blocks.dirt);
        world.setBlock(i + 12, j + 45, k + 34, Blocks.dirt);
        world.setBlock(i + 12, j + 45, k + 35, Blocks.dirt);
        world.setBlock(i + 12, j + 45, k + 36, Blocks.dirt);
        world.setBlock(i + 12, j + 45, k + 37, Dungeons.blockUnbreableGrass);
        world.setBlock(i + 12, j + 45, k + 38, Dungeons.blockUnbreableGrass);
        world.setBlock(i + 12, j + 45, k + 79, Blocks.dirt);
        world.setBlock(i + 12, j + 45, k + 80, Blocks.dirt);
        world.setBlock(i + 12, j + 45, k + 81, Blocks.dirt);
        world.setBlock(i + 12, j + 45, k + 82, Blocks.dirt);
        world.setBlock(i + 12, j + 45, k + 83, Blocks.dirt);
        world.setBlock(i + 12, j + 45, k + 84, Blocks.dirt);
        world.setBlock(i + 12, j + 45, k + 85, Blocks.dirt);
        world.setBlock(i + 12, j + 45, k + 86, Blocks.dirt);
        world.setBlock(i + 12, j + 45, k + 87, Dungeons.blockUnbreableStone);
        world.setBlock(i + 12, j + 45, k + 88, Blocks.dirt);
        world.setBlock(i + 12, j + 45, k + 89, Blocks.dirt);
        world.setBlock(i + 12, j + 45, k + 90, Blocks.dirt);
        world.setBlock(i + 12, j + 45, k + 91, Blocks.dirt);
        world.setBlock(i + 12, j + 45, k + 92, Blocks.dirt);
        world.setBlock(i + 12, j + 45, k + 93, Blocks.dirt);
        world.setBlock(i + 12, j + 45, k + 94, Blocks.dirt);
        world.setBlock(i + 12, j + 45, k + 95, Blocks.dirt);
        world.setBlock(i + 12, j + 45, k + 96, Dungeons.blockUnbreableStone);
        world.setBlock(i + 12, j + 45, k + 97, Blocks.dirt);
        world.setBlock(i + 12, j + 45, k + 98, Blocks.dirt);
        world.setBlock(i + 12, j + 45, k + 111, Blocks.dirt);
        world.setBlock(i + 12, j + 45, k + 112, Blocks.dirt);
        world.setBlock(i + 12, j + 45, k + 113, Blocks.dirt);
        world.setBlock(i + 12, j + 45, k + 114, Blocks.dirt);
        world.setBlock(i + 12, j + 45, k + 115, Blocks.dirt);
        world.setBlock(i + 12, j + 45, k + 116, Blocks.dirt);
        world.setBlock(i + 12, j + 45, k + 117, Blocks.dirt);
        world.setBlock(i + 12, j + 45, k + 118, Blocks.dirt);
        world.setBlock(i + 12, j + 45, k + 119, Blocks.dirt);
        world.setBlock(i + 12, j + 45, k + 120, Blocks.log);
        world.setBlock(i + 12, j + 45, k + 121, Blocks.log);
        world.setBlock(i + 12, j + 45, k + 122, Blocks.log);
        world.setBlock(i + 12, j + 46, k + 22, Dungeons.blockUnbreableGrass);
        world.setBlock(i + 12, j + 46, k + 23, Dungeons.blockUnbreableGrass);
        world.setBlock(i + 12, j + 46, k + 24, Dungeons.blockUnbreableGrass);
        world.setBlock(i + 12, j + 46, k + 25, Dungeons.blockUnbreableGrass);
        world.setBlock(i + 12, j + 46, k + 26, Dungeons.blockUnbreableGrass);
        world.setBlock(i + 12, j + 46, k + 27, Dungeons.blockUnbreableGrass);
        world.setBlock(i + 12, j + 46, k + 28, Dungeons.blockUnbreableGrass);
        world.setBlock(i + 12, j + 46, k + 29, Dungeons.blockUnbreableGrass);
        world.setBlock(i + 12, j + 46, k + 30, Dungeons.blockUnbreableGrass);
        world.setBlock(i + 12, j + 46, k + 32, Dungeons.blockUnbreableGrass);
        world.setBlock(i + 12, j + 46, k + 33, Dungeons.blockUnbreableGrass);
        world.setBlock(i + 12, j + 46, k + 34, Dungeons.blockUnbreableGrass);
        world.setBlock(i + 12, j + 46, k + 35, Dungeons.blockUnbreableGrass);
        world.setBlock(i + 12, j + 46, k + 36, Dungeons.blockUnbreableGrass);
        world.setBlock(i + 12, j + 46, k + 76, Blocks.dirt);
        world.setBlock(i + 12, j + 46, k + 77, Blocks.dirt);
        world.setBlock(i + 12, j + 46, k + 78, Blocks.dirt);
        world.setBlock(i + 12, j + 46, k + 79, Blocks.dirt);
        world.setBlock(i + 12, j + 46, k + 80, Blocks.dirt);
        world.setBlock(i + 12, j + 46, k + 81, Blocks.dirt);
        world.setBlock(i + 12, j + 46, k + 82, Dungeons.blockUnbreableGrass);
        world.setBlock(i + 12, j + 46, k + 83, Dungeons.blockUnbreableGrass);
        world.setBlock(i + 12, j + 46, k + 84, Dungeons.blockUnbreableGrass);
        world.setBlock(i + 12, j + 46, k + 85, Dungeons.blockUnbreableGrass);
        world.setBlock(i + 12, j + 46, k + 86, Dungeons.blockUnbreableGrass);
        world.setBlock(i + 12, j + 46, k + 87, Blocks.dirt);
        world.setBlock(i + 12, j + 46, k + 88, Blocks.dirt);
        world.setBlock(i + 12, j + 46, k + 89, Blocks.dirt);
        world.setBlock(i + 12, j + 46, k + 90, Blocks.dirt);
        world.setBlock(i + 12, j + 46, k + 91, Blocks.dirt);
        world.setBlock(i + 12, j + 46, k + 92, Blocks.dirt);
        world.setBlock(i + 12, j + 46, k + 93, Blocks.dirt);
        world.setBlock(i + 12, j + 46, k + 94, Blocks.dirt);
        world.setBlock(i + 12, j + 46, k + 95, Blocks.dirt);
        world.setBlock(i + 12, j + 46, k + 96, Blocks.dirt);
        world.setBlock(i + 12, j + 46, k + 97, Blocks.dirt);
        world.setBlock(i + 12, j + 46, k + 98, Blocks.dirt);
        world.setBlock(i + 12, j + 46, k + 99, Blocks.dirt);
        world.setBlock(i + 12, j + 46, k + 110, Dungeons.blockUnbreableGrass);
        world.setBlock(i + 12, j + 46, k + 111, Dungeons.blockUnbreableGrass);
        world.setBlock(i + 12, j + 46, k + 112, Dungeons.blockUnbreableGrass);
        world.setBlock(i + 12, j + 46, k + 113, Dungeons.blockUnbreableGrass);
        world.setBlock(i + 12, j + 46, k + 114, Dungeons.blockUnbreableGrass);
        world.setBlock(i + 12, j + 46, k + 115, Dungeons.blockUnbreableGrass);
        world.setBlock(i + 12, j + 46, k + 116, Dungeons.blockUnbreableGrass);
        world.setBlock(i + 12, j + 46, k + 117, Blocks.dirt);
        world.setBlock(i + 12, j + 46, k + 118, Blocks.dirt);
        world.setBlock(i + 12, j + 46, k + 119, Blocks.dirt);
        world.setBlock(i + 12, j + 46, k + 120, Blocks.dirt);
        world.setBlock(i + 12, j + 46, k + 121, Blocks.log);
        world.setBlock(i + 12, j + 46, k + 122, Dungeons.blockUnbreableGrass);
        world.setBlock(i + 12, j + 47, k + 31, Dungeons.blockUnbreableGrass);
        world.setBlock(i + 12, j + 47, k + 74, Blocks.log);
        world.setBlock(i + 12, j + 47, k + 75, Blocks.log);
        world.setBlock(i + 12, j + 47, k + 76, Blocks.log);
        world.setBlock(i + 12, j + 47, k + 77, Blocks.log);
        world.setBlock(i + 12, j + 47, k + 78, Blocks.log);
        world.setBlock(i + 12, j + 47, k + 79, Blocks.log);
        world.setBlock(i + 12, j + 47, k + 80, Blocks.log);
        world.setBlock(i + 12, j + 47, k + 81, Blocks.log);
        world.setBlock(i + 12, j + 47, k + 87, Dungeons.blockUnbreableGrass);
        world.setBlock(i + 12, j + 47, k + 88, Blocks.dirt);
        world.setBlock(i + 12, j + 47, k + 89, Blocks.dirt);
        world.setBlock(i + 12, j + 47, k + 90, Blocks.dirt);
        world.setBlock(i + 12, j + 47, k + 91, Blocks.dirt);
        world.setBlock(i + 12, j + 47, k + 92, Blocks.dirt);
        world.setBlock(i + 12, j + 47, k + 93, Blocks.dirt);
        world.setBlock(i + 12, j + 47, k + 94, Blocks.dirt);
        world.setBlock(i + 12, j + 47, k + 95, Blocks.dirt);
        world.setBlock(i + 12, j + 47, k + 96, Blocks.dirt);
        world.setBlock(i + 12, j + 47, k + 97, Blocks.dirt);
        world.setBlock(i + 12, j + 47, k + 98, Dungeons.blockUnbreableGrass);
        world.setBlock(i + 12, j + 47, k + 99, Dungeons.blockUnbreableGrass);
        world.setBlock(i + 12, j + 47, k + 117, Blocks.log);
        world.setBlock(i + 12, j + 47, k + 118, Blocks.log);
        world.setBlock(i + 12, j + 47, k + 119, Blocks.log);
        world.setBlock(i + 12, j + 47, k + 120, Blocks.log);
        world.setBlock(i + 12, j + 47, k + 121, Blocks.log);
        world.setBlock(i + 12, j + 48, k + 77, Blocks.log);
        world.setBlock(i + 12, j + 48, k + 78, Blocks.log);
        world.setBlock(i + 12, j + 48, k + 79, Blocks.log);
        world.setBlock(i + 12, j + 48, k + 88, Dungeons.blockUnbreableGrass);
        world.setBlock(i + 12, j + 48, k + 89, Blocks.dirt);
        world.setBlock(i + 12, j + 48, k + 90, Blocks.dirt);
        world.setBlock(i + 12, j + 48, k + 91, Blocks.dirt);
        world.setBlock(i + 12, j + 48, k + 92, Blocks.dirt);
        world.setBlock(i + 12, j + 48, k + 93, Blocks.dirt);
        world.setBlock(i + 12, j + 48, k + 94, Blocks.dirt);
        world.setBlock(i + 12, j + 48, k + 95, Blocks.dirt);
        world.setBlock(i + 12, j + 48, k + 96, Blocks.dirt);
        world.setBlock(i + 12, j + 48, k + 97, Dungeons.blockUnbreableGrass);
        world.setBlock(i + 12, j + 49, k + 89, Dungeons.blockUnbreableGrass);
        world.setBlock(i + 12, j + 49, k + 90, Blocks.dirt);
        world.setBlock(i + 12, j + 49, k + 91, Blocks.dirt);
        world.setBlock(i + 12, j + 49, k + 92, Blocks.dirt);
        world.setBlock(i + 12, j + 49, k + 93, Blocks.dirt);
        world.setBlock(i + 12, j + 49, k + 94, Blocks.dirt);
        world.setBlock(i + 12, j + 49, k + 95, Blocks.dirt);
        world.setBlock(i + 12, j + 49, k + 96, Blocks.dirt);
        world.setBlock(i + 12, j + 50, k + 90, Dungeons.blockUnbreableGrass);
        world.setBlock(i + 12, j + 50, k + 91, Blocks.dirt);
        world.setBlock(i + 12, j + 50, k + 92, Blocks.dirt);
        world.setBlock(i + 12, j + 50, k + 93, Blocks.dirt);
        world.setBlock(i + 12, j + 50, k + 94, Blocks.dirt);
        world.setBlock(i + 12, j + 50, k + 95, Dungeons.blockUnbreableGrass);
        world.setBlock(i + 12, j + 50, k + 96, Dungeons.blockUnbreableGrass);
        world.setBlock(i + 12, j + 51, k + 91, Dungeons.blockUnbreableGrass);
        world.setBlock(i + 12, j + 51, k + 92, Dungeons.blockUnbreableGrass);
        world.setBlock(i + 12, j + 51, k + 93, Dungeons.blockUnbreableGrass);
        world.setBlock(i + 12, j + 51, k + 94, Dungeons.blockUnbreableGrass);
        world.setBlock(i + 12, j + 89, k + 40, Blocks.wool, 1, 0);
        world.setBlock(i + 12, j + 90, k + 41, Blocks.wool, 1, 0);
        world.setBlock(i + 12, j + 90, k + 42, Blocks.wool, 1, 0);
        world.setBlock(i + 12, j + 91, k + 43, Blocks.wool, 1, 0);
        world.setBlock(i + 12, j + 91, k + 44, Blocks.wool, 1, 0);
        world.setBlock(i + 12, j + 91, k + 47, Blocks.wool, 1, 0);
        world.setBlock(i + 12, j + 91, k + 48, Blocks.wool, 1, 0);
        world.setBlock(i + 12, j + 91, k + 49, Blocks.wool, 1, 0);
        world.setBlock(i + 12, j + 92, k + 45, Blocks.wool, 1, 0);
        world.setBlock(i + 12, j + 92, k + 46, Blocks.wool, 1, 0);
        world.setBlock(i + 12, j + 92, k + 50, Blocks.wool, 1, 0);
        world.setBlock(i + 12, j + 129, k + 38, Blocks.wool, 1, 0);
        world.setBlock(i + 12, j + 129, k + 58, Blocks.wool, 1, 0);
        world.setBlock(i + 12, j + 130, k + 39, Blocks.wool, 1, 0);
        world.setBlock(i + 12, j + 130, k + 40, Blocks.wool, 1, 0);
        world.setBlock(i + 12, j + 130, k + 41, Blocks.wool, 1, 0);
        world.setBlock(i + 12, j + 130, k + 57, Blocks.wool, 1, 0);
        world.setBlock(i + 12, j + 131, k + 42, Blocks.wool, 1, 0);
        world.setBlock(i + 12, j + 131, k + 43, Blocks.wool, 1, 0);
        world.setBlock(i + 12, j + 131, k + 44, Blocks.wool, 1, 0);
        world.setBlock(i + 12, j + 131, k + 45, Blocks.wool, 1, 0);
        world.setBlock(i + 12, j + 131, k + 46, Blocks.wool, 1, 0);
        world.setBlock(i + 12, j + 131, k + 47, Blocks.wool, 1, 0);
        world.setBlock(i + 12, j + 131, k + 55, Blocks.wool, 1, 0);
        world.setBlock(i + 12, j + 131, k + 56, Blocks.wool, 1, 0);
        world.setBlock(i + 12, j + 132, k + 48, Blocks.wool, 1, 0);
        world.setBlock(i + 12, j + 132, k + 49, Blocks.wool, 1, 0);
        world.setBlock(i + 12, j + 132, k + 50, Blocks.wool, 1, 0);
        world.setBlock(i + 12, j + 132, k + 51, Blocks.wool, 1, 0);
        world.setBlock(i + 12, j + 132, k + 52, Blocks.wool, 1, 0);
        world.setBlock(i + 12, j + 132, k + 53, Blocks.wool, 1, 0);
        world.setBlock(i + 12, j + 132, k + 54, Blocks.wool, 1, 0);
        world.setBlock(i + 13, j + 37, k + 21, Blocks.log);
        world.setBlock(i + 13, j + 37, k + 22, Blocks.log);
        world.setBlock(i + 13, j + 37, k + 23, Blocks.log);
        world.setBlock(i + 13, j + 38, k + 20, Blocks.log);
        world.setBlock(i + 13, j + 38, k + 21, Blocks.log);
        world.setBlock(i + 13, j + 38, k + 22, Blocks.log);
        world.setBlock(i + 13, j + 38, k + 23, Blocks.log);
        world.setBlock(i + 13, j + 39, k + 21, Blocks.log);
        world.setBlock(i + 13, j + 39, k + 22, Blocks.log);
        world.setBlock(i + 13, j + 39, k + 23, Blocks.log);
        world.setBlock(i + 13, j + 39, k + 24, Blocks.log);
        world.setBlock(i + 13, j + 39, k + 86, Dungeons.blockUnbreableStone);
        world.setBlock(i + 13, j + 39, k + 87, Dungeons.blockUnbreableStone);
        world.setBlock(i + 13, j + 39, k + 88, Dungeons.blockUnbreableStone);
        world.setBlock(i + 13, j + 39, k + 89, Dungeons.blockUnbreableStone);
        world.setBlock(i + 13, j + 39, k + 90, Dungeons.blockUnbreableStone);
        world.setBlock(i + 13, j + 39, k + 91, Dungeons.blockUnbreableStone);
        world.setBlock(i + 13, j + 40, k + 21, Blocks.log);
        world.setBlock(i + 13, j + 40, k + 22, Blocks.log);
        world.setBlock(i + 13, j + 40, k + 23, Blocks.log);
        world.setBlock(i + 13, j + 40, k + 84, Dungeons.blockUnbreableStone);
        world.setBlock(i + 13, j + 40, k + 85, Dungeons.blockUnbreableStone);
        world.setBlock(i + 13, j + 40, k + 86, Dungeons.blockUnbreableStone);
        world.setBlock(i + 13, j + 40, k + 87, Dungeons.blockUnbreableStone);
        world.setBlock(i + 13, j + 40, k + 88, Dungeons.blockUnbreableStone);
        world.setBlock(i + 13, j + 40, k + 89, Dungeons.blockUnbreableStone);
        world.setBlock(i + 13, j + 40, k + 90, Dungeons.blockUnbreableStone);
        world.setBlock(i + 13, j + 40, k + 91, Dungeons.blockUnbreableStone);
        world.setBlock(i + 13, j + 40, k + 92, Dungeons.blockUnbreableStone);
        world.setBlock(i + 13, j + 40, k + 93, Dungeons.blockUnbreableStone);
        world.setBlock(i + 13, j + 41, k + 83, Dungeons.blockUnbreableStone);
        world.setBlock(i + 13, j + 41, k + 84, Dungeons.blockUnbreableStone);
        world.setBlock(i + 13, j + 41, k + 85, Dungeons.blockUnbreableStone);
        world.setBlock(i + 13, j + 41, k + 86, Dungeons.blockUnbreableStone);
        world.setBlock(i + 13, j + 41, k + 87, Dungeons.blockUnbreableStone);
        world.setBlock(i + 13, j + 41, k + 88, Dungeons.blockUnbreableStone);
        world.setBlock(i + 13, j + 41, k + 89, Dungeons.blockUnbreableStone);
        world.setBlock(i + 13, j + 41, k + 90, Dungeons.blockUnbreableStone);
        world.setBlock(i + 13, j + 41, k + 91, Dungeons.blockUnbreableStone);
        world.setBlock(i + 13, j + 41, k + 92, Dungeons.blockUnbreableStone);
        world.setBlock(i + 13, j + 41, k + 93, Dungeons.blockUnbreableStone);
        world.setBlock(i + 13, j + 41, k + 94, Dungeons.blockUnbreableStone);
        world.setBlock(i + 13, j + 41, k + 114, Dungeons.blockUnbreableStone);
        world.setBlock(i + 13, j + 41, k + 115, Dungeons.blockUnbreableStone);
        world.setBlock(i + 13, j + 41, k + 116, Dungeons.blockUnbreableStone);
        world.setBlock(i + 13, j + 41, k + 117, Dungeons.blockUnbreableStone);
        world.setBlock(i + 13, j + 42, k + 82, Dungeons.blockUnbreableStone);
        world.setBlock(i + 13, j + 42, k + 83, Dungeons.blockUnbreableStone);
        world.setBlock(i + 13, j + 42, k + 84, Dungeons.blockUnbreableStone);
        world.setBlock(i + 13, j + 42, k + 85, Dungeons.blockUnbreableStone);
        world.setBlock(i + 13, j + 42, k + 86, Dungeons.blockUnbreableStone);
        world.setBlock(i + 13, j + 42, k + 87, Dungeons.blockUnbreableStone);
        world.setBlock(i + 13, j + 42, k + 88, Dungeons.blockUnbreableStone);
        world.setBlock(i + 13, j + 42, k + 89, Dungeons.blockUnbreableStone);
        world.setBlock(i + 13, j + 42, k + 90, Dungeons.blockUnbreableStone);
        world.setBlock(i + 13, j + 42, k + 91, Dungeons.blockUnbreableStone);
        world.setBlock(i + 13, j + 42, k + 92, Dungeons.blockUnbreableStone);
        world.setBlock(i + 13, j + 42, k + 93, Dungeons.blockUnbreableStone);
        world.setBlock(i + 13, j + 42, k + 94, Dungeons.blockUnbreableStone);
        world.setBlock(i + 13, j + 42, k + 113, Dungeons.blockUnbreableStone);
        world.setBlock(i + 13, j + 42, k + 114, Dungeons.blockUnbreableStone);
        world.setBlock(i + 13, j + 42, k + 115, Dungeons.blockUnbreableStone);
        world.setBlock(i + 13, j + 42, k + 116, Dungeons.blockUnbreableStone);
        world.setBlock(i + 13, j + 42, k + 117, Dungeons.blockUnbreableStone);
        world.setBlock(i + 13, j + 42, k + 118, Dungeons.blockUnbreableStone);
        world.setBlock(i + 13, j + 42, k + 119, Dungeons.blockUnbreableStone);
        world.setBlock(i + 13, j + 43, k + 80, Dungeons.blockUnbreableStone);
        world.setBlock(i + 13, j + 43, k + 81, Dungeons.blockUnbreableStone);
        world.setBlock(i + 13, j + 43, k + 82, Dungeons.blockUnbreableStone);
        world.setBlock(i + 13, j + 43, k + 83, Dungeons.blockUnbreableStone);
        world.setBlock(i + 13, j + 43, k + 84, Dungeons.blockUnbreableStone);
        world.setBlock(i + 13, j + 43, k + 85, Dungeons.blockUnbreableStone);
        world.setBlock(i + 13, j + 43, k + 86, Dungeons.blockUnbreableStone);
        world.setBlock(i + 13, j + 43, k + 87, Dungeons.blockUnbreableStone);
        world.setBlock(i + 13, j + 43, k + 88, Dungeons.blockUnbreableStone);
        world.setBlock(i + 13, j + 43, k + 89, Dungeons.blockUnbreableStone);
        world.setBlock(i + 13, j + 43, k + 90, Dungeons.blockUnbreableStone);
        world.setBlock(i + 13, j + 43, k + 91, Dungeons.blockUnbreableStone);
        world.setBlock(i + 13, j + 43, k + 92, Dungeons.blockUnbreableStone);
        world.setBlock(i + 13, j + 43, k + 93, Dungeons.blockUnbreableStone);
        world.setBlock(i + 13, j + 43, k + 94, Dungeons.blockUnbreableStone);
        world.setBlock(i + 13, j + 43, k + 95, Dungeons.blockUnbreableStone);
        world.setBlock(i + 13, j + 43, k + 112, Dungeons.blockUnbreableStone);
        world.setBlock(i + 13, j + 43, k + 113, Dungeons.blockUnbreableStone);
        world.setBlock(i + 13, j + 43, k + 114, Dungeons.blockUnbreableStone);
        world.setBlock(i + 13, j + 43, k + 115, Dungeons.blockUnbreableStone);
        world.setBlock(i + 13, j + 43, k + 116, Dungeons.blockUnbreableStone);
        world.setBlock(i + 13, j + 43, k + 117, Dungeons.blockUnbreableStone);
        world.setBlock(i + 13, j + 43, k + 118, Dungeons.blockUnbreableStone);
        world.setBlock(i + 13, j + 43, k + 119, Dungeons.blockUnbreableStone);
        world.setBlock(i + 13, j + 43, k + 120, Dungeons.blockUnbreableStone);
        world.setBlock(i + 13, j + 44, k + 25, Dungeons.blockUnbreableStone);
        world.setBlock(i + 13, j + 44, k + 26, Dungeons.blockUnbreableStone);
        world.setBlock(i + 13, j + 44, k + 27, Dungeons.blockUnbreableStone);
        world.setBlock(i + 13, j + 44, k + 77, Blocks.dirt);
        world.setBlock(i + 13, j + 44, k + 78, Blocks.dirt);
        world.setBlock(i + 13, j + 44, k + 79, Dungeons.blockUnbreableStone);
        world.setBlock(i + 13, j + 44, k + 80, Dungeons.blockUnbreableStone);
        world.setBlock(i + 13, j + 44, k + 81, Dungeons.blockUnbreableStone);
        world.setBlock(i + 13, j + 44, k + 82, Dungeons.blockUnbreableStone);
        world.setBlock(i + 13, j + 44, k + 83, Dungeons.blockUnbreableStone);
        world.setBlock(i + 13, j + 44, k + 84, Dungeons.blockUnbreableStone);
        world.setBlock(i + 13, j + 44, k + 85, Dungeons.blockUnbreableStone);
        world.setBlock(i + 13, j + 44, k + 86, Dungeons.blockUnbreableStone);
        world.setBlock(i + 13, j + 44, k + 87, Dungeons.blockUnbreableStone);
        world.setBlock(i + 13, j + 44, k + 88, Dungeons.blockUnbreableStone);
        world.setBlock(i + 13, j + 44, k + 89, Dungeons.blockUnbreableStone);
        world.setBlock(i + 13, j + 44, k + 90, Dungeons.blockUnbreableStone);
        world.setBlock(i + 13, j + 44, k + 91, Dungeons.blockUnbreableStone);
        world.setBlock(i + 13, j + 44, k + 92, Dungeons.blockUnbreableStone);
        world.setBlock(i + 13, j + 44, k + 93, Dungeons.blockUnbreableStone);
        world.setBlock(i + 13, j + 44, k + 94, Dungeons.blockUnbreableStone);
        world.setBlock(i + 13, j + 44, k + 95, Dungeons.blockUnbreableStone);
        world.setBlock(i + 13, j + 44, k + 96, Dungeons.blockUnbreableStone);
        world.setBlock(i + 13, j + 44, k + 97, Blocks.dirt);
        world.setBlock(i + 13, j + 44, k + 111, Dungeons.blockUnbreableStone);
        world.setBlock(i + 13, j + 44, k + 112, Dungeons.blockUnbreableStone);
        world.setBlock(i + 13, j + 44, k + 113, Dungeons.blockUnbreableStone);
        world.setBlock(i + 13, j + 44, k + 114, Dungeons.blockUnbreableStone);
        world.setBlock(i + 13, j + 44, k + 115, Dungeons.blockUnbreableStone);
        world.setBlock(i + 13, j + 44, k + 116, Dungeons.blockUnbreableStone);
        world.setBlock(i + 13, j + 44, k + 117, Dungeons.blockUnbreableStone);
        world.setBlock(i + 13, j + 44, k + 118, Dungeons.blockUnbreableStone);
        world.setBlock(i + 13, j + 44, k + 119, Dungeons.blockUnbreableStone);
        world.setBlock(i + 13, j + 44, k + 120, Dungeons.blockUnbreableStone);
        world.setBlock(i + 13, j + 44, k + 121, Dungeons.blockUnbreableStone);
        world.setBlock(i + 13, j + 45, k + 23, Blocks.dirt);
        world.setBlock(i + 13, j + 45, k + 24, Blocks.dirt);
        world.setBlock(i + 13, j + 45, k + 25, Blocks.dirt);
        world.setBlock(i + 13, j + 45, k + 26, Blocks.dirt);
        world.setBlock(i + 13, j + 45, k + 27, Blocks.dirt);
        world.setBlock(i + 13, j + 45, k + 28, Blocks.dirt);
        world.setBlock(i + 13, j + 45, k + 29, Blocks.dirt);
        world.setBlock(i + 13, j + 45, k + 31, Blocks.dirt);
        world.setBlock(i + 13, j + 45, k + 32, Blocks.dirt);
        world.setBlock(i + 13, j + 45, k + 33, Blocks.dirt);
        world.setBlock(i + 13, j + 45, k + 34, Blocks.dirt);
        world.setBlock(i + 13, j + 45, k + 35, Blocks.dirt);
        world.setBlock(i + 13, j + 45, k + 36, Blocks.dirt);
        world.setBlock(i + 13, j + 45, k + 37, Blocks.dirt);
        world.setBlock(i + 13, j + 45, k + 39, Dungeons.blockUnbreableGrass);
        world.setBlock(i + 13, j + 45, k + 77, Blocks.dirt);
        world.setBlock(i + 13, j + 45, k + 78, Blocks.dirt);
        world.setBlock(i + 13, j + 45, k + 79, Blocks.dirt);
        world.setBlock(i + 13, j + 45, k + 80, Blocks.dirt);
        world.setBlock(i + 13, j + 45, k + 81, Blocks.dirt);
        world.setBlock(i + 13, j + 45, k + 82, Blocks.dirt);
        world.setBlock(i + 13, j + 45, k + 83, Blocks.dirt);
        world.setBlock(i + 13, j + 45, k + 84, Blocks.dirt);
        world.setBlock(i + 13, j + 45, k + 85, Blocks.dirt);
        world.setBlock(i + 13, j + 45, k + 86, Blocks.dirt);
        world.setBlock(i + 13, j + 45, k + 87, Dungeons.blockUnbreableStone);
        world.setBlock(i + 13, j + 45, k + 88, Blocks.dirt);
        world.setBlock(i + 13, j + 45, k + 89, Blocks.dirt);
        world.setBlock(i + 13, j + 45, k + 90, Blocks.dirt);
        world.setBlock(i + 13, j + 45, k + 91, Blocks.dirt);
        world.setBlock(i + 13, j + 45, k + 92, Blocks.dirt);
        world.setBlock(i + 13, j + 45, k + 93, Blocks.dirt);
        world.setBlock(i + 13, j + 45, k + 94, Blocks.dirt);
        world.setBlock(i + 13, j + 45, k + 95, Blocks.dirt);
        world.setBlock(i + 13, j + 45, k + 96, Blocks.dirt);
        world.setBlock(i + 13, j + 45, k + 97, Blocks.dirt);
        world.setBlock(i + 13, j + 45, k + 98, Blocks.dirt);
        world.setBlock(i + 13, j + 45, k + 99, Blocks.dirt);
        world.setBlock(i + 13, j + 45, k + 111, Blocks.dirt);
        world.setBlock(i + 13, j + 45, k + 112, Blocks.dirt);
        world.setBlock(i + 13, j + 45, k + 113, Blocks.dirt);
        world.setBlock(i + 13, j + 45, k + 114, Blocks.dirt);
        world.setBlock(i + 13, j + 45, k + 115, Blocks.dirt);
        world.setBlock(i + 13, j + 45, k + 116, Blocks.dirt);
        world.setBlock(i + 13, j + 45, k + 117, Blocks.dirt);
        world.setBlock(i + 13, j + 45, k + 118, Blocks.dirt);
        world.setBlock(i + 13, j + 45, k + 119, Blocks.dirt);
        world.setBlock(i + 13, j + 45, k + 120, Blocks.dirt);
        world.setBlock(i + 13, j + 45, k + 121, Blocks.dirt);
        world.setBlock(i + 13, j + 45, k + 122, Blocks.dirt);
        world.setBlock(i + 13, j + 46, k + 22, Dungeons.blockUnbreableGrass);
        world.setBlock(i + 13, j + 46, k + 23, Dungeons.blockUnbreableGrass);
        world.setBlock(i + 13, j + 46, k + 24, Dungeons.blockUnbreableGrass);
        world.setBlock(i + 13, j + 46, k + 25, Dungeons.blockUnbreableGrass);
        world.setBlock(i + 13, j + 46, k + 26, Dungeons.blockUnbreableGrass);
        world.setBlock(i + 13, j + 46, k + 27, Dungeons.blockUnbreableGrass);
        world.setBlock(i + 13, j + 46, k + 28, Dungeons.blockUnbreableGrass);
        world.setBlock(i + 13, j + 46, k + 29, Dungeons.blockUnbreableGrass);
        world.setBlock(i + 13, j + 46, k + 30, Blocks.dirt);
        world.setBlock(i + 13, j + 46, k + 31, Blocks.dirt);
        world.setBlock(i + 13, j + 46, k + 32, Blocks.dirt);
        world.setBlock(i + 13, j + 46, k + 33, Blocks.dirt);
        world.setBlock(i + 13, j + 46, k + 34, Blocks.dirt);
        world.setBlock(i + 13, j + 46, k + 35, Blocks.dirt);
        world.setBlock(i + 13, j + 46, k + 36, Blocks.dirt);
        world.setBlock(i + 13, j + 46, k + 37, Dungeons.blockUnbreableGrass);
        world.setBlock(i + 13, j + 46, k + 38, Dungeons.blockUnbreableGrass);
        world.setBlock(i + 13, j + 46, k + 76, Blocks.dirt);
        world.setBlock(i + 13, j + 46, k + 77, Blocks.dirt);
        world.setBlock(i + 13, j + 46, k + 78, Blocks.dirt);
        world.setBlock(i + 13, j + 46, k + 79, Blocks.dirt);
        world.setBlock(i + 13, j + 46, k + 80, Blocks.dirt);
        world.setBlock(i + 13, j + 46, k + 81, Blocks.dirt);
        world.setBlock(i + 13, j + 46, k + 82, Blocks.dirt);
        world.setBlock(i + 13, j + 46, k + 83, Dungeons.blockUnbreableGrass);
        world.setBlock(i + 13, j + 46, k + 84, Dungeons.blockUnbreableGrass);
        world.setBlock(i + 13, j + 46, k + 85, Dungeons.blockUnbreableGrass);
        world.setBlock(i + 13, j + 46, k + 86, Dungeons.blockUnbreableGrass);
        world.setBlock(i + 13, j + 46, k + 87, Blocks.dirt);
        world.setBlock(i + 13, j + 46, k + 88, Blocks.dirt);
        world.setBlock(i + 13, j + 46, k + 89, Blocks.dirt);
        world.setBlock(i + 13, j + 46, k + 90, Blocks.dirt);
        world.setBlock(i + 13, j + 46, k + 91, Blocks.dirt);
        world.setBlock(i + 13, j + 46, k + 92, Blocks.dirt);
        world.setBlock(i + 13, j + 46, k + 93, Blocks.dirt);
        world.setBlock(i + 13, j + 46, k + 94, Blocks.dirt);
        world.setBlock(i + 13, j + 46, k + 95, Blocks.dirt);
        world.setBlock(i + 13, j + 46, k + 96, Blocks.dirt);
        world.setBlock(i + 13, j + 46, k + 97, Dungeons.blockUnbreableGrass);
        world.setBlock(i + 13, j + 46, k + 98, Blocks.dirt);
        world.setBlock(i + 13, j + 46, k + 99, Blocks.dirt);
        world.setBlock(i + 13, j + 46, k + 110, Dungeons.blockUnbreableGrass);
        world.setBlock(i + 13, j + 46, k + 111, Dungeons.blockUnbreableGrass);
        world.setBlock(i + 13, j + 46, k + 112, Dungeons.blockUnbreableGrass);
        world.setBlock(i + 13, j + 46, k + 113, Dungeons.blockUnbreableGrass);
        world.setBlock(i + 13, j + 46, k + 114, Dungeons.blockUnbreableGrass);
        world.setBlock(i + 13, j + 46, k + 115, Dungeons.blockUnbreableGrass);
        world.setBlock(i + 13, j + 46, k + 116, Dungeons.blockUnbreableGrass);
        world.setBlock(i + 13, j + 46, k + 117, Blocks.dirt);
        world.setBlock(i + 13, j + 46, k + 118, Blocks.dirt);
        world.setBlock(i + 13, j + 46, k + 119, Blocks.dirt);
        world.setBlock(i + 13, j + 46, k + 120, Blocks.dirt);
        world.setBlock(i + 13, j + 46, k + 121, Blocks.dirt);
        world.setBlock(i + 13, j + 46, k + 122, Dungeons.blockUnbreableGrass);
        world.setBlock(i + 13, j + 46, k + 123, Dungeons.blockUnbreableGrass);
        world.setBlock(i + 13, j + 46, k + 124, Dungeons.blockUnbreableGrass);
        world.setBlock(i + 13, j + 47, k + 30, Dungeons.blockUnbreableGrass);
        world.setBlock(i + 13, j + 47, k + 31, Dungeons.blockUnbreableGrass);
        world.setBlock(i + 13, j + 47, k + 32, Dungeons.blockUnbreableGrass);
        world.setBlock(i + 13, j + 47, k + 33, Dungeons.blockUnbreableGrass);
        world.setBlock(i + 13, j + 47, k + 34, Dungeons.blockUnbreableGrass);
        world.setBlock(i + 13, j + 47, k + 35, Dungeons.blockUnbreableGrass);
        world.setBlock(i + 13, j + 47, k + 36, Dungeons.blockUnbreableGrass);
        world.setBlock(i + 13, j + 47, k + 50, Blocks.log);
        world.setBlock(i + 13, j + 47, k + 51, Blocks.log);
        world.setBlock(i + 13, j + 47, k + 52, Blocks.log);
        world.setBlock(i + 13, j + 47, k + 74, Blocks.log);
        world.setBlock(i + 13, j + 47, k + 75, Blocks.log);
        world.setBlock(i + 13, j + 47, k + 76, Blocks.log);
        world.setBlock(i + 13, j + 47, k + 77, Blocks.log);
        world.setBlock(i + 13, j + 47, k + 78, Blocks.log);
        world.setBlock(i + 13, j + 47, k + 79, Blocks.log);
        world.setBlock(i + 13, j + 47, k + 80, Blocks.log);
        world.setBlock(i + 13, j + 47, k + 81, Blocks.log);
        world.setBlock(i + 13, j + 47, k + 82, Dungeons.blockUnbreableGrass);
        world.setBlock(i + 13, j + 47, k + 87, Dungeons.blockUnbreableGrass);
        world.setBlock(i + 13, j + 47, k + 88, Blocks.dirt);
        world.setBlock(i + 13, j + 47, k + 89, Blocks.dirt);
        world.setBlock(i + 13, j + 47, k + 90, Blocks.dirt);
        world.setBlock(i + 13, j + 47, k + 91, Blocks.dirt);
        world.setBlock(i + 13, j + 47, k + 92, Blocks.dirt);
        world.setBlock(i + 13, j + 47, k + 93, Blocks.dirt);
        world.setBlock(i + 13, j + 47, k + 94, Blocks.dirt);
        world.setBlock(i + 13, j + 47, k + 95, Blocks.dirt);
        world.setBlock(i + 13, j + 47, k + 96, Blocks.dirt);
        world.setBlock(i + 13, j + 47, k + 98, Blocks.dirt);
        world.setBlock(i + 13, j + 47, k + 99, Dungeons.blockUnbreableGrass);
        world.setBlock(i + 13, j + 47, k + 117, Blocks.log);
        world.setBlock(i + 13, j + 47, k + 118, Blocks.log);
        world.setBlock(i + 13, j + 47, k + 119, Blocks.log);
        world.setBlock(i + 13, j + 47, k + 120, Blocks.log);
        world.setBlock(i + 13, j + 47, k + 121, Blocks.log);
        world.setBlock(i + 13, j + 48, k + 77, Blocks.log);
        world.setBlock(i + 13, j + 48, k + 78, Blocks.log);
        world.setBlock(i + 13, j + 48, k + 79, Blocks.log);
        world.setBlock(i + 13, j + 48, k + 80, Blocks.log);
        world.setBlock(i + 13, j + 48, k + 88, Dungeons.blockUnbreableGrass);
        world.setBlock(i + 13, j + 48, k + 89, Blocks.dirt);
        world.setBlock(i + 13, j + 48, k + 90, Blocks.dirt);
        world.setBlock(i + 13, j + 48, k + 91, Blocks.dirt);
        world.setBlock(i + 13, j + 48, k + 92, Blocks.dirt);
        world.setBlock(i + 13, j + 48, k + 93, Blocks.dirt);
        world.setBlock(i + 13, j + 48, k + 94, Blocks.dirt);
        world.setBlock(i + 13, j + 48, k + 95, Blocks.dirt);
        world.setBlock(i + 13, j + 48, k + 96, Blocks.dirt);
        world.setBlock(i + 13, j + 48, k + 97, Blocks.dirt);
        world.setBlock(i + 13, j + 48, k + 98, Dungeons.blockUnbreableGrass);
        world.setBlock(i + 13, j + 49, k + 89, Dungeons.blockUnbreableGrass);
