

package com.gibby.dungeon.gen;

import net.minecraft.world.gen.feature.*;
import net.minecraft.world.*;
import java.util.*;
import net.minecraft.init.*;
import com.gibby.dungeon.*;

public class SunsetIslandsGreen extends WorldGenerator
{
    public boolean generate(final World world, final Random rand, final int i, final int j, final int k) {
        world.setBlock(i + 0, j + 36, k + 75, Blocks.stone);
        world.setBlock(i + 0, j + 36, k + 76, Blocks.stone);
        world.setBlock(i + 0, j + 36, k + 77, Blocks.stone);
        world.setBlock(i + 0, j + 36, k + 78, Blocks.stone);
        world.setBlock(i + 0, j + 36, k + 79, Blocks.stone);
        world.setBlock(i + 0, j + 36, k + 80, Blocks.stone);
        world.setBlock(i + 0, j + 36, k + 81, Blocks.stone);
        world.setBlock(i + 0, j + 36, k + 82, Blocks.stone);
        world.setBlock(i + 0, j + 36, k + 83, Blocks.stone);
        world.setBlock(i + 0, j + 36, k + 84, Blocks.stone);
        world.setBlock(i + 0, j + 36, k + 85, Blocks.stone);
        world.setBlock(i + 0, j + 36, k + 86, Blocks.stone);
        world.setBlock(i + 0, j + 37, k + 72, Blocks.stone);
        world.setBlock(i + 0, j + 37, k + 73, Blocks.stone);
        world.setBlock(i + 0, j + 37, k + 74, Blocks.stone);
        world.setBlock(i + 0, j + 37, k + 75, Blocks.stone);
        world.setBlock(i + 0, j + 37, k + 76, Blocks.stone);
        world.setBlock(i + 0, j + 37, k + 77, Blocks.stone);
        world.setBlock(i + 0, j + 37, k + 78, Blocks.stone);
        world.setBlock(i + 0, j + 37, k + 79, Blocks.stone);
        world.setBlock(i + 0, j + 37, k + 80, Blocks.stone);
        world.setBlock(i + 0, j + 37, k + 81, Blocks.stone);
        world.setBlock(i + 0, j + 37, k + 82, Blocks.stone);
        world.setBlock(i + 0, j + 37, k + 83, Blocks.stone);
        world.setBlock(i + 0, j + 37, k + 84, Blocks.stone);
        world.setBlock(i + 0, j + 37, k + 85, Blocks.stone);
        world.setBlock(i + 0, j + 37, k + 86, Blocks.stone);
        world.setBlock(i + 0, j + 37, k + 87, Blocks.stone);
        world.setBlock(i + 0, j + 37, k + 88, Blocks.stone);
        world.setBlock(i + 0, j + 38, k + 72, Blocks.stone);
        world.setBlock(i + 0, j + 38, k + 73, Blocks.stone);
        world.setBlock(i + 0, j + 38, k + 74, Blocks.stone);
        world.setBlock(i + 0, j + 38, k + 75, Blocks.stone);
        world.setBlock(i + 0, j + 38, k + 76, Blocks.stone);
        world.setBlock(i + 0, j + 38, k + 77, Blocks.stone);
        world.setBlock(i + 0, j + 38, k + 78, Blocks.stone);
        world.setBlock(i + 0, j + 38, k + 79, Blocks.stone);
        world.setBlock(i + 0, j + 38, k + 80, Blocks.stone);
        world.setBlock(i + 0, j + 38, k + 81, Blocks.stone);
        world.setBlock(i + 0, j + 38, k + 82, Blocks.stone);
        world.setBlock(i + 0, j + 38, k + 83, Blocks.stone);
        world.setBlock(i + 0, j + 38, k + 84, Blocks.stone);
        world.setBlock(i + 0, j + 38, k + 85, Blocks.stone);
        world.setBlock(i + 0, j + 38, k + 86, Blocks.stone);
        world.setBlock(i + 0, j + 38, k + 87, Blocks.stone);
        world.setBlock(i + 0, j + 38, k + 88, Blocks.stone);
        world.setBlock(i + 0, j + 38, k + 89, Blocks.stone);
        world.setBlock(i + 0, j + 39, k + 71, Blocks.stone);
        world.setBlock(i + 0, j + 39, k + 72, Blocks.stone);
        world.setBlock(i + 0, j + 39, k + 73, Blocks.stone);
        world.setBlock(i + 0, j + 39, k + 74, Blocks.stone);
        world.setBlock(i + 0, j + 39, k + 75, Blocks.stone);
        world.setBlock(i + 0, j + 39, k + 76, Blocks.stone);
        world.setBlock(i + 0, j + 39, k + 77, Blocks.stone);
        world.setBlock(i + 0, j + 39, k + 78, Blocks.stone);
        world.setBlock(i + 0, j + 39, k + 79, Blocks.stone);
        world.setBlock(i + 0, j + 39, k + 80, Blocks.stone);
        world.setBlock(i + 0, j + 39, k + 81, Blocks.stone);
        world.setBlock(i + 0, j + 39, k + 82, Blocks.stone);
        world.setBlock(i + 0, j + 39, k + 83, Blocks.stone);
        world.setBlock(i + 0, j + 39, k + 84, Blocks.stone);
        world.setBlock(i + 0, j + 39, k + 85, Blocks.stone);
        world.setBlock(i + 0, j + 39, k + 86, Blocks.stone);
        world.setBlock(i + 0, j + 39, k + 87, Blocks.stone);
        world.setBlock(i + 0, j + 39, k + 88, Blocks.stone);
        world.setBlock(i + 0, j + 39, k + 89, Blocks.stone);
        world.setBlock(i + 0, j + 39, k + 90, Blocks.stone);
        world.setBlock(i + 0, j + 40, k + 71, Blocks.stone);
        world.setBlock(i + 0, j + 40, k + 72, Blocks.stone);
        world.setBlock(i + 0, j + 40, k + 73, Blocks.stone);
        world.setBlock(i + 0, j + 40, k + 74, Blocks.stone);
        world.setBlock(i + 0, j + 40, k + 75, Blocks.stone);
        world.setBlock(i + 0, j + 40, k + 76, Blocks.stone);
        world.setBlock(i + 0, j + 40, k + 77, Blocks.stone);
        world.setBlock(i + 0, j + 40, k + 78, Blocks.stone);
        world.setBlock(i + 0, j + 40, k + 79, Blocks.stone);
        world.setBlock(i + 0, j + 40, k + 80, Blocks.stone);
        world.setBlock(i + 0, j + 40, k + 81, Blocks.stone);
        world.setBlock(i + 0, j + 40, k + 82, Blocks.stone);
        world.setBlock(i + 0, j + 40, k + 83, Blocks.stone);
        world.setBlock(i + 0, j + 40, k + 84, Blocks.stone);
        world.setBlock(i + 0, j + 40, k + 85, Blocks.stone);
        world.setBlock(i + 0, j + 40, k + 86, Blocks.stone);
        world.setBlock(i + 0, j + 40, k + 87, Blocks.stone);
        world.setBlock(i + 0, j + 40, k + 88, Blocks.stone);
        world.setBlock(i + 0, j + 40, k + 89, Blocks.stone);
        world.setBlock(i + 0, j + 40, k + 90, Blocks.stone);
        world.setBlock(i + 0, j + 40, k + 91, Blocks.stone);
        world.setBlock(i + 0, j + 41, k + 71, Blocks.stone);
        world.setBlock(i + 0, j + 41, k + 72, Blocks.stone);
        world.setBlock(i + 0, j + 41, k + 73, Blocks.stone);
        world.setBlock(i + 0, j + 41, k + 74, Blocks.stone);
        world.setBlock(i + 0, j + 41, k + 75, Blocks.stone);
        world.setBlock(i + 0, j + 41, k + 76, Blocks.stone);
        world.setBlock(i + 0, j + 41, k + 77, Blocks.stone);
        world.setBlock(i + 0, j + 41, k + 78, Blocks.stone);
        world.setBlock(i + 0, j + 41, k + 79, Blocks.stone);
        world.setBlock(i + 0, j + 41, k + 80, Blocks.stone);
        world.setBlock(i + 0, j + 41, k + 81, Blocks.stone);
        world.setBlock(i + 0, j + 41, k + 82, Blocks.stone);
        world.setBlock(i + 0, j + 41, k + 83, Blocks.stone);
        world.setBlock(i + 0, j + 41, k + 84, Blocks.stone);
        world.setBlock(i + 0, j + 41, k + 85, Blocks.stone);
        world.setBlock(i + 0, j + 41, k + 86, Blocks.stone);
        world.setBlock(i + 0, j + 41, k + 87, Blocks.stone);
        world.setBlock(i + 0, j + 41, k + 88, Blocks.stone);
        world.setBlock(i + 0, j + 41, k + 89, Blocks.stone);
        world.setBlock(i + 0, j + 41, k + 90, Blocks.stone);
        world.setBlock(i + 0, j + 41, k + 91, Blocks.stone);
        world.setBlock(i + 0, j + 42, k + 72, Blocks.stone);
        world.setBlock(i + 0, j + 42, k + 73, Blocks.stone);
        world.setBlock(i + 0, j + 42, k + 74, Blocks.stone);
        world.setBlock(i + 0, j + 42, k + 75, Blocks.stone);
        world.setBlock(i + 0, j + 42, k + 76, Blocks.stone);
        world.setBlock(i + 0, j + 42, k + 77, Blocks.stone);
        world.setBlock(i + 0, j + 42, k + 78, Blocks.stone);
        world.setBlock(i + 0, j + 42, k + 79, Blocks.stone);
        world.setBlock(i + 0, j + 42, k + 80, Blocks.stone);
        world.setBlock(i + 0, j + 42, k + 81, Blocks.stone);
        world.setBlock(i + 0, j + 42, k + 82, Blocks.stone);
        world.setBlock(i + 0, j + 42, k + 83, Blocks.stone);
        world.setBlock(i + 0, j + 42, k + 84, Blocks.stone);
        world.setBlock(i + 0, j + 42, k + 85, Blocks.stone);
        world.setBlock(i + 0, j + 42, k + 86, Blocks.stone);
        world.setBlock(i + 0, j + 42, k + 87, Blocks.stone);
        world.setBlock(i + 0, j + 42, k + 88, Blocks.stone);
        world.setBlock(i + 0, j + 42, k + 89, Blocks.stone);
        world.setBlock(i + 0, j + 43, k + 73, Blocks.stone);
        world.setBlock(i + 0, j + 43, k + 74, Blocks.stone);
        world.setBlock(i + 0, j + 43, k + 75, Blocks.stone);
        world.setBlock(i + 0, j + 43, k + 76, Blocks.stone);
        world.setBlock(i + 0, j + 43, k + 77, Blocks.stone);
        world.setBlock(i + 0, j + 43, k + 78, Blocks.stone);
        world.setBlock(i + 0, j + 43, k + 79, Blocks.stone);
        world.setBlock(i + 0, j + 43, k + 80, Blocks.stone);
        world.setBlock(i + 0, j + 43, k + 81, Blocks.stone);
        world.setBlock(i + 0, j + 43, k + 82, Blocks.stone);
        world.setBlock(i + 0, j + 43, k + 83, Blocks.stone);
        world.setBlock(i + 0, j + 43, k + 84, Blocks.stone);
        world.setBlock(i + 0, j + 43, k + 85, Blocks.stone);
        world.setBlock(i + 0, j + 44, k + 74, Blocks.stone);
        world.setBlock(i + 0, j + 44, k + 75, Blocks.stone);
        world.setBlock(i + 0, j + 44, k + 76, Blocks.stone);
        world.setBlock(i + 0, j + 44, k + 77, Blocks.stone);
        world.setBlock(i + 0, j + 44, k + 78, Blocks.stone);
        world.setBlock(i + 0, j + 44, k + 79, Blocks.stone);
        world.setBlock(i + 0, j + 44, k + 80, Blocks.stone);
        world.setBlock(i + 0, j + 44, k + 81, Blocks.stone);
        world.setBlock(i + 0, j + 44, k + 82, Blocks.stone);
        world.setBlock(i + 0, j + 44, k + 83, Blocks.stone);
        world.setBlock(i + 0, j + 44, k + 84, Blocks.stone);
        world.setBlock(i + 0, j + 45, k + 75, Blocks.stone);
        world.setBlock(i + 0, j + 45, k + 76, Blocks.stone);
        world.setBlock(i + 0, j + 45, k + 77, Blocks.stone);
        world.setBlock(i + 0, j + 45, k + 78, Blocks.stone);
        world.setBlock(i + 0, j + 45, k + 79, Blocks.stone);
        world.setBlock(i + 0, j + 45, k + 80, Blocks.stone);
        world.setBlock(i + 0, j + 45, k + 81, Blocks.stone);
        world.setBlock(i + 0, j + 45, k + 82, Blocks.stone);
        world.setBlock(i + 0, j + 46, k + 76, Blocks.stone);
        world.setBlock(i + 0, j + 46, k + 77, Blocks.stone);
        world.setBlock(i + 0, j + 46, k + 78, Blocks.stone);
        world.setBlock(i + 0, j + 46, k + 79, Blocks.stone);
        world.setBlock(i + 0, j + 46, k + 80, Blocks.stone);
        world.setBlock(i + 0, j + 46, k + 82, Blocks.stone);
        world.setBlock(i + 0, j + 110, k + 0, Blocks.wool, 6, 0);
        world.setBlock(i + 1, j + 36, k + 73, Blocks.stone);
        world.setBlock(i + 1, j + 36, k + 74, Blocks.stone);
        world.setBlock(i + 1, j + 36, k + 75, Blocks.stone);
        world.setBlock(i + 1, j + 36, k + 76, Blocks.stone);
        world.setBlock(i + 1, j + 36, k + 77, Blocks.stone);
        world.setBlock(i + 1, j + 36, k + 78, Blocks.stone);
        world.setBlock(i + 1, j + 36, k + 79, Blocks.stone);
        world.setBlock(i + 1, j + 36, k + 80, Blocks.stone);
        world.setBlock(i + 1, j + 36, k + 81, Blocks.stone);
        world.setBlock(i + 1, j + 36, k + 82, Blocks.stone);
        world.setBlock(i + 1, j + 36, k + 83, Blocks.stone);
        world.setBlock(i + 1, j + 36, k + 84, Blocks.stone);
        world.setBlock(i + 1, j + 36, k + 85, Blocks.stone);
        world.setBlock(i + 1, j + 36, k + 86, Blocks.stone);
        world.setBlock(i + 1, j + 37, k + 72, Blocks.stone);
        world.setBlock(i + 1, j + 37, k + 73, Blocks.stone);
        world.setBlock(i + 1, j + 37, k + 74, Blocks.stone);
        world.setBlock(i + 1, j + 37, k + 75, Blocks.stone);
        world.setBlock(i + 1, j + 37, k + 76, Blocks.stone);
        world.setBlock(i + 1, j + 37, k + 77, Blocks.stone);
        world.setBlock(i + 1, j + 37, k + 78, Blocks.stone);
        world.setBlock(i + 1, j + 37, k + 79, Blocks.stone);
        world.setBlock(i + 1, j + 37, k + 80, Blocks.stone);
        world.setBlock(i + 1, j + 37, k + 81, Blocks.stone);
        world.setBlock(i + 1, j + 37, k + 82, Blocks.stone);
        world.setBlock(i + 1, j + 37, k + 83, Blocks.stone);
        world.setBlock(i + 1, j + 37, k + 84, Blocks.stone);
        world.setBlock(i + 1, j + 37, k + 85, Blocks.stone);
        world.setBlock(i + 1, j + 37, k + 86, Blocks.stone);
        world.setBlock(i + 1, j + 37, k + 87, Blocks.stone);
        world.setBlock(i + 1, j + 38, k + 71, Blocks.stone);
        world.setBlock(i + 1, j + 38, k + 72, Blocks.stone);
        world.setBlock(i + 1, j + 38, k + 73, Blocks.stone);
        world.setBlock(i + 1, j + 38, k + 74, Blocks.stone);
        world.setBlock(i + 1, j + 38, k + 75, Blocks.stone);
        world.setBlock(i + 1, j + 38, k + 76, Blocks.stone);
        world.setBlock(i + 1, j + 38, k + 77, Blocks.stone);
        world.setBlock(i + 1, j + 38, k + 78, Blocks.stone);
        world.setBlock(i + 1, j + 38, k + 79, Blocks.stone);
        world.setBlock(i + 1, j + 38, k + 80, Blocks.stone);
        world.setBlock(i + 1, j + 38, k + 81, Blocks.stone);
        world.setBlock(i + 1, j + 38, k + 82, Blocks.stone);
        world.setBlock(i + 1, j + 38, k + 83, Blocks.stone);
        world.setBlock(i + 1, j + 38, k + 84, Blocks.stone);
        world.setBlock(i + 1, j + 38, k + 85, Blocks.stone);
        world.setBlock(i + 1, j + 38, k + 86, Blocks.stone);
        world.setBlock(i + 1, j + 38, k + 87, Blocks.stone);
        world.setBlock(i + 1, j + 38, k + 88, Blocks.stone);
        world.setBlock(i + 1, j + 38, k + 89, Blocks.stone);
        world.setBlock(i + 1, j + 38, k + 90, Blocks.stone);
        world.setBlock(i + 1, j + 38, k + 92, Blocks.stone);
        world.setBlock(i + 1, j + 39, k + 71, Blocks.stone);
        world.setBlock(i + 1, j + 39, k + 72, Blocks.stone);
        world.setBlock(i + 1, j + 39, k + 73, Blocks.stone);
        world.setBlock(i + 1, j + 39, k + 74, Blocks.stone);
        world.setBlock(i + 1, j + 39, k + 75, Blocks.stone);
        world.setBlock(i + 1, j + 39, k + 76, Blocks.stone);
        world.setBlock(i + 1, j + 39, k + 77, Blocks.stone);
        world.setBlock(i + 1, j + 39, k + 78, Blocks.stone);
        world.setBlock(i + 1, j + 39, k + 79, Blocks.stone);
        world.setBlock(i + 1, j + 39, k + 80, Blocks.stone);
        world.setBlock(i + 1, j + 39, k + 81, Blocks.stone);
        world.setBlock(i + 1, j + 39, k + 82, Blocks.stone);
        world.setBlock(i + 1, j + 39, k + 83, Blocks.stone);
        world.setBlock(i + 1, j + 39, k + 84, Blocks.stone);
        world.setBlock(i + 1, j + 39, k + 85, Blocks.stone);
        world.setBlock(i + 1, j + 39, k + 86, Blocks.stone);
        world.setBlock(i + 1, j + 39, k + 87, Blocks.stone);
        world.setBlock(i + 1, j + 39, k + 88, Blocks.stone);
        world.setBlock(i + 1, j + 39, k + 89, Blocks.stone);
        world.setBlock(i + 1, j + 39, k + 90, Blocks.dirt);
        world.setBlock(i + 1, j + 39, k + 91, Blocks.stone);
        world.setBlock(i + 1, j + 39, k + 92, Blocks.stone);
        world.setBlock(i + 1, j + 39, k + 93, Blocks.stone);
        world.setBlock(i + 1, j + 40, k + 71, Blocks.stone);
        world.setBlock(i + 1, j + 40, k + 72, Blocks.stone);
        world.setBlock(i + 1, j + 40, k + 73, Blocks.stone);
        world.setBlock(i + 1, j + 40, k + 74, Blocks.stone);
        world.setBlock(i + 1, j + 40, k + 75, Blocks.stone);
        world.setBlock(i + 1, j + 40, k + 76, Blocks.stone);
        world.setBlock(i + 1, j + 40, k + 77, Blocks.stone);
        world.setBlock(i + 1, j + 40, k + 78, Blocks.stone);
        world.setBlock(i + 1, j + 40, k + 79, Blocks.stone);
        world.setBlock(i + 1, j + 40, k + 80, Blocks.stone);
        world.setBlock(i + 1, j + 40, k + 81, Blocks.stone);
        world.setBlock(i + 1, j + 40, k + 82, Blocks.stone);
        world.setBlock(i + 1, j + 40, k + 83, Blocks.stone);
        world.setBlock(i + 1, j + 40, k + 84, Blocks.stone);
        world.setBlock(i + 1, j + 40, k + 85, Blocks.stone);
        world.setBlock(i + 1, j + 40, k + 86, Blocks.stone);
        world.setBlock(i + 1, j + 40, k + 87, Blocks.stone);
        world.setBlock(i + 1, j + 40, k + 88, Blocks.stone);
        world.setBlock(i + 1, j + 40, k + 89, Blocks.stone);
        world.setBlock(i + 1, j + 40, k + 90, Blocks.stone);
        world.setBlock(i + 1, j + 40, k + 91, Blocks.stone);
        world.setBlock(i + 1, j + 40, k + 92, Blocks.stone);
        world.setBlock(i + 1, j + 40, k + 93, Blocks.stone);
        world.setBlock(i + 1, j + 40, k + 94, Blocks.stone);
        world.setBlock(i + 1, j + 41, k + 71, Blocks.stone);
        world.setBlock(i + 1, j + 41, k + 72, Blocks.stone);
        world.setBlock(i + 1, j + 41, k + 73, Blocks.stone);
        world.setBlock(i + 1, j + 41, k + 74, Blocks.stone);
        world.setBlock(i + 1, j + 41, k + 75, Blocks.stone);
        world.setBlock(i + 1, j + 41, k + 76, Blocks.stone);
        world.setBlock(i + 1, j + 41, k + 77, Blocks.stone);
        world.setBlock(i + 1, j + 41, k + 78, Blocks.stone);
        world.setBlock(i + 1, j + 41, k + 79, Blocks.stone);
        world.setBlock(i + 1, j + 41, k + 80, Blocks.stone);
        world.setBlock(i + 1, j + 41, k + 81, Blocks.stone);
        world.setBlock(i + 1, j + 41, k + 82, Blocks.stone);
        world.setBlock(i + 1, j + 41, k + 83, Blocks.stone);
        world.setBlock(i + 1, j + 41, k + 84, Blocks.stone);
        world.setBlock(i + 1, j + 41, k + 85, Blocks.stone);
        world.setBlock(i + 1, j + 41, k + 86, Blocks.stone);
        world.setBlock(i + 1, j + 41, k + 87, Blocks.stone);
        world.setBlock(i + 1, j + 41, k + 88, Blocks.stone);
        world.setBlock(i + 1, j + 41, k + 89, Blocks.stone);
        world.setBlock(i + 1, j + 41, k + 90, Blocks.stone);
        world.setBlock(i + 1, j + 41, k + 91, Blocks.stone);
        world.setBlock(i + 1, j + 41, k + 92, Blocks.stone);
        world.setBlock(i + 1, j + 41, k + 93, Blocks.stone);
        world.setBlock(i + 1, j + 42, k + 72, Blocks.stone);
        world.setBlock(i + 1, j + 42, k + 73, Blocks.stone);
        world.setBlock(i + 1, j + 42, k + 74, Blocks.stone);
        world.setBlock(i + 1, j + 42, k + 75, Blocks.stone);
        world.setBlock(i + 1, j + 42, k + 76, Blocks.stone);
        world.setBlock(i + 1, j + 42, k + 77, Blocks.stone);
        world.setBlock(i + 1, j + 42, k + 78, Blocks.stone);
        world.setBlock(i + 1, j + 42, k + 79, Blocks.stone);
        world.setBlock(i + 1, j + 42, k + 80, Blocks.stone);
        world.setBlock(i + 1, j + 42, k + 81, Blocks.stone);
        world.setBlock(i + 1, j + 42, k + 82, Blocks.stone);
        world.setBlock(i + 1, j + 42, k + 83, Blocks.stone);
        world.setBlock(i + 1, j + 42, k + 84, Blocks.stone);
        world.setBlock(i + 1, j + 42, k + 85, Blocks.stone);
        world.setBlock(i + 1, j + 42, k + 86, Blocks.stone);
        world.setBlock(i + 1, j + 42, k + 87, Blocks.stone);
        world.setBlock(i + 1, j + 42, k + 88, Blocks.stone);
        world.setBlock(i + 1, j + 42, k + 89, Blocks.stone);
        world.setBlock(i + 1, j + 43, k + 73, Blocks.stone);
        world.setBlock(i + 1, j + 43, k + 74, Blocks.stone);
        world.setBlock(i + 1, j + 43, k + 75, Blocks.stone);
        world.setBlock(i + 1, j + 43, k + 76, Blocks.stone);
        world.setBlock(i + 1, j + 43, k + 77, Blocks.stone);
        world.setBlock(i + 1, j + 43, k + 78, Blocks.stone);
        world.setBlock(i + 1, j + 43, k + 79, Blocks.stone);
        world.setBlock(i + 1, j + 43, k + 80, Blocks.stone);
        world.setBlock(i + 1, j + 43, k + 81, Blocks.stone);
        world.setBlock(i + 1, j + 43, k + 82, Blocks.stone);
        world.setBlock(i + 1, j + 43, k + 83, Blocks.stone);
        world.setBlock(i + 1, j + 43, k + 84, Blocks.stone);
        world.setBlock(i + 1, j + 43, k + 85, Blocks.stone);
        world.setBlock(i + 1, j + 44, k + 73, Blocks.stone);
        world.setBlock(i + 1, j + 44, k + 74, Blocks.stone);
        world.setBlock(i + 1, j + 44, k + 75, Blocks.stone);
        world.setBlock(i + 1, j + 44, k + 76, Blocks.stone);
        world.setBlock(i + 1, j + 44, k + 77, Blocks.stone);
        world.setBlock(i + 1, j + 44, k + 78, Blocks.stone);
        world.setBlock(i + 1, j + 44, k + 79, Blocks.stone);
        world.setBlock(i + 1, j + 44, k + 80, Blocks.stone);
        world.setBlock(i + 1, j + 44, k + 81, Blocks.stone);
        world.setBlock(i + 1, j + 44, k + 82, Blocks.stone);
        world.setBlock(i + 1, j + 44, k + 83, Blocks.stone);
        world.setBlock(i + 1, j + 45, k + 73, Blocks.stone);
        world.setBlock(i + 1, j + 45, k + 74, Blocks.stone);
        world.setBlock(i + 1, j + 45, k + 75, Blocks.stone);
        world.setBlock(i + 1, j + 45, k + 76, Blocks.stone);
        world.setBlock(i + 1, j + 45, k + 77, Blocks.stone);
        world.setBlock(i + 1, j + 45, k + 78, Blocks.stone);
        world.setBlock(i + 1, j + 45, k + 79, Blocks.stone);
        world.setBlock(i + 1, j + 45, k + 80, Blocks.stone);
        world.setBlock(i + 1, j + 45, k + 81, Blocks.stone);
        world.setBlock(i + 1, j + 46, k + 74, Blocks.stone);
        world.setBlock(i + 1, j + 46, k + 75, Blocks.stone);
        world.setBlock(i + 1, j + 46, k + 76, Blocks.stone);
        world.setBlock(i + 1, j + 46, k + 77, Blocks.stone);
        world.setBlock(i + 1, j + 46, k + 79, Blocks.stone);
        world.setBlock(i + 2, j + 35, k + 84, Blocks.stone);
        world.setBlock(i + 2, j + 36, k + 74, Blocks.stone);
        world.setBlock(i + 2, j + 36, k + 75, Blocks.stone);
        world.setBlock(i + 2, j + 36, k + 76, Blocks.stone);
        world.setBlock(i + 2, j + 36, k + 77, Blocks.stone);
        world.setBlock(i + 2, j + 36, k + 78, Blocks.stone);
        world.setBlock(i + 2, j + 36, k + 79, Blocks.stone);
        world.setBlock(i + 2, j + 36, k + 80, Blocks.stone);
        world.setBlock(i + 2, j + 36, k + 81, Blocks.stone);
        world.setBlock(i + 2, j + 36, k + 82, Blocks.stone);
        world.setBlock(i + 2, j + 36, k + 83, Blocks.stone);
        world.setBlock(i + 2, j + 36, k + 84, Blocks.stone);
        world.setBlock(i + 2, j + 36, k + 85, Blocks.stone);
        world.setBlock(i + 2, j + 36, k + 86, Blocks.stone);
        world.setBlock(i + 2, j + 37, k + 72, Blocks.stone);
        world.setBlock(i + 2, j + 37, k + 73, Blocks.stone);
        world.setBlock(i + 2, j + 37, k + 74, Blocks.stone);
        world.setBlock(i + 2, j + 37, k + 75, Blocks.stone);
        world.setBlock(i + 2, j + 37, k + 76, Blocks.stone);
        world.setBlock(i + 2, j + 37, k + 77, Blocks.stone);
        world.setBlock(i + 2, j + 37, k + 78, Blocks.stone);
        world.setBlock(i + 2, j + 37, k + 79, Blocks.stone);
        world.setBlock(i + 2, j + 37, k + 80, Blocks.stone);
        world.setBlock(i + 2, j + 37, k + 81, Blocks.stone);
        world.setBlock(i + 2, j + 37, k + 82, Blocks.stone);
        world.setBlock(i + 2, j + 37, k + 83, Blocks.stone);
        world.setBlock(i + 2, j + 37, k + 84, Blocks.stone);
        world.setBlock(i + 2, j + 37, k + 85, Blocks.stone);
        world.setBlock(i + 2, j + 37, k + 86, Blocks.stone);
        world.setBlock(i + 2, j + 37, k + 87, Blocks.stone);
        world.setBlock(i + 2, j + 37, k + 91, Blocks.stone);
        world.setBlock(i + 2, j + 37, k + 92, Blocks.stone);
        world.setBlock(i + 2, j + 38, k + 72, Blocks.stone);
        world.setBlock(i + 2, j + 38, k + 73, Blocks.stone);
        world.setBlock(i + 2, j + 38, k + 74, Blocks.stone);
        world.setBlock(i + 2, j + 38, k + 75, Blocks.stone);
        world.setBlock(i + 2, j + 38, k + 76, Blocks.stone);
        world.setBlock(i + 2, j + 38, k + 77, Blocks.stone);
        world.setBlock(i + 2, j + 38, k + 78, Blocks.stone);
        world.setBlock(i + 2, j + 38, k + 79, Blocks.stone);
        world.setBlock(i + 2, j + 38, k + 80, Blocks.stone);
        world.setBlock(i + 2, j + 38, k + 81, Blocks.stone);
        world.setBlock(i + 2, j + 38, k + 82, Blocks.stone);
        world.setBlock(i + 2, j + 38, k + 83, Blocks.stone);
        world.setBlock(i + 2, j + 38, k + 84, Blocks.stone);
        world.setBlock(i + 2, j + 38, k + 85, Blocks.stone);
        world.setBlock(i + 2, j + 38, k + 86, Blocks.stone);
        world.setBlock(i + 2, j + 38, k + 87, Blocks.stone);
        world.setBlock(i + 2, j + 38, k + 88, Blocks.stone);
        world.setBlock(i + 2, j + 38, k + 89, Blocks.stone);
        world.setBlock(i + 2, j + 38, k + 90, Blocks.stone);
        world.setBlock(i + 2, j + 38, k + 91, Blocks.stone);
        world.setBlock(i + 2, j + 38, k + 92, Blocks.stone);
        world.setBlock(i + 2, j + 38, k + 93, Blocks.stone);
        world.setBlock(i + 2, j + 39, k + 71, Blocks.stone);
        world.setBlock(i + 2, j + 39, k + 72, Blocks.stone);
        world.setBlock(i + 2, j + 39, k + 73, Blocks.stone);
        world.setBlock(i + 2, j + 39, k + 74, Blocks.stone);
        world.setBlock(i + 2, j + 39, k + 75, Blocks.stone);
        world.setBlock(i + 2, j + 39, k + 76, Blocks.stone);
        world.setBlock(i + 2, j + 39, k + 77, Blocks.stone);
        world.setBlock(i + 2, j + 39, k + 78, Blocks.stone);
        world.setBlock(i + 2, j + 39, k + 79, Blocks.stone);
        world.setBlock(i + 2, j + 39, k + 80, Blocks.stone);
        world.setBlock(i + 2, j + 39, k + 81, Blocks.stone);
        world.setBlock(i + 2, j + 39, k + 82, Blocks.stone);
        world.setBlock(i + 2, j + 39, k + 83, Blocks.stone);
        world.setBlock(i + 2, j + 39, k + 84, Blocks.stone);
        world.setBlock(i + 2, j + 39, k + 85, Blocks.stone);
        world.setBlock(i + 2, j + 39, k + 86, Blocks.stone);
        world.setBlock(i + 2, j + 39, k + 87, Blocks.stone);
        world.setBlock(i + 2, j + 39, k + 88, Blocks.stone);
        world.setBlock(i + 2, j + 39, k + 89, Blocks.stone);
        world.setBlock(i + 2, j + 39, k + 90, Blocks.stone);
        world.setBlock(i + 2, j + 39, k + 91, Blocks.stone);
        world.setBlock(i + 2, j + 39, k + 92, Blocks.stone);
        world.setBlock(i + 2, j + 39, k + 93, Blocks.stone);
        world.setBlock(i + 2, j + 39, k + 94, Blocks.stone);
        world.setBlock(i + 2, j + 39, k + 95, Blocks.stone);
        world.setBlock(i + 2, j + 40, k + 71, Blocks.stone);
        world.setBlock(i + 2, j + 40, k + 72, Blocks.stone);
        world.setBlock(i + 2, j + 40, k + 73, Blocks.stone);
        world.setBlock(i + 2, j + 40, k + 74, Blocks.stone);
        world.setBlock(i + 2, j + 40, k + 75, Blocks.stone);
        world.setBlock(i + 2, j + 40, k + 76, Blocks.stone);
        world.setBlock(i + 2, j + 40, k + 77, Blocks.stone);
        world.setBlock(i + 2, j + 40, k + 78, Blocks.stone);
        world.setBlock(i + 2, j + 40, k + 79, Blocks.stone);
        world.setBlock(i + 2, j + 40, k + 80, Blocks.stone);
        world.setBlock(i + 2, j + 40, k + 81, Blocks.stone);
        world.setBlock(i + 2, j + 40, k + 82, Blocks.stone);
        world.setBlock(i + 2, j + 40, k + 83, Blocks.stone);
        world.setBlock(i + 2, j + 40, k + 84, Blocks.stone);
        world.setBlock(i + 2, j + 40, k + 85, Blocks.stone);
        world.setBlock(i + 2, j + 40, k + 86, Blocks.stone);
        world.setBlock(i + 2, j + 40, k + 87, Blocks.stone);
        world.setBlock(i + 2, j + 40, k + 88, Blocks.stone);
        world.setBlock(i + 2, j + 40, k + 89, Blocks.stone);
        world.setBlock(i + 2, j + 40, k + 90, Blocks.stone);
        world.setBlock(i + 2, j + 40, k + 91, Blocks.stone);
        world.setBlock(i + 2, j + 40, k + 92, Blocks.stone);
        world.setBlock(i + 2, j + 40, k + 93, Blocks.stone);
        world.setBlock(i + 2, j + 40, k + 94, Blocks.stone);
        world.setBlock(i + 2, j + 40, k + 95, Blocks.stone);
        world.setBlock(i + 2, j + 41, k + 71, Blocks.stone);
        world.setBlock(i + 2, j + 41, k + 72, Blocks.stone);
        world.setBlock(i + 2, j + 41, k + 73, Blocks.stone);
        world.setBlock(i + 2, j + 41, k + 74, Blocks.stone);
        world.setBlock(i + 2, j + 41, k + 75, Blocks.stone);
        world.setBlock(i + 2, j + 41, k + 76, Blocks.stone);
        world.setBlock(i + 2, j + 41, k + 77, Blocks.stone);
        world.setBlock(i + 2, j + 41, k + 78, Blocks.stone);
        world.setBlock(i + 2, j + 41, k + 79, Blocks.stone);
        world.setBlock(i + 2, j + 41, k + 80, Blocks.stone);
        world.setBlock(i + 2, j + 41, k + 81, Blocks.stone);
        world.setBlock(i + 2, j + 41, k + 82, Blocks.stone);
        world.setBlock(i + 2, j + 41, k + 83, Blocks.stone);
        world.setBlock(i + 2, j + 41, k + 84, Blocks.stone);
        world.setBlock(i + 2, j + 41, k + 85, Blocks.stone);
        world.setBlock(i + 2, j + 41, k + 86, Blocks.stone);
        world.setBlock(i + 2, j + 41, k + 87, Blocks.stone);
        world.setBlock(i + 2, j + 41, k + 88, Blocks.stone);
        world.setBlock(i + 2, j + 41, k + 89, Blocks.stone);
        world.setBlock(i + 2, j + 41, k + 90, Blocks.stone);
        world.setBlock(i + 2, j + 41, k + 91, Blocks.stone);
        world.setBlock(i + 2, j + 41, k + 92, Blocks.stone);
        world.setBlock(i + 2, j + 41, k + 93, Blocks.stone);
        world.setBlock(i + 2, j + 41, k + 94, Blocks.stone);
        world.setBlock(i + 2, j + 41, k + 95, Blocks.stone);
        world.setBlock(i + 2, j + 42, k + 72, Blocks.stone);
        world.setBlock(i + 2, j + 42, k + 73, Blocks.stone);
        world.setBlock(i + 2, j + 42, k + 74, Blocks.stone);
        world.setBlock(i + 2, j + 42, k + 75, Blocks.stone);
        world.setBlock(i + 2, j + 42, k + 76, Blocks.stone);
        world.setBlock(i + 2, j + 42, k + 77, Blocks.stone);
        world.setBlock(i + 2, j + 42, k + 78, Blocks.stone);
        world.setBlock(i + 2, j + 42, k + 79, Blocks.stone);
        world.setBlock(i + 2, j + 42, k + 80, Blocks.stone);
        world.setBlock(i + 2, j + 42, k + 81, Blocks.stone);
        world.setBlock(i + 2, j + 42, k + 82, Blocks.stone);
        world.setBlock(i + 2, j + 42, k + 83, Blocks.stone);
        world.setBlock(i + 2, j + 42, k + 84, Blocks.stone);
        world.setBlock(i + 2, j + 42, k + 85, Blocks.stone);
        world.setBlock(i + 2, j + 42, k + 86, Blocks.stone);
        world.setBlock(i + 2, j + 42, k + 87, Blocks.stone);
        world.setBlock(i + 2, j + 42, k + 88, Blocks.stone);
        world.setBlock(i + 2, j + 42, k + 89, Blocks.stone);
        world.setBlock(i + 2, j + 42, k + 90, Blocks.stone);
        world.setBlock(i + 2, j + 42, k + 91, Blocks.stone);
        world.setBlock(i + 2, j + 42, k + 92, Blocks.stone);
        world.setBlock(i + 2, j + 42, k + 93, Blocks.stone);
        world.setBlock(i + 2, j + 42, k + 94, Blocks.stone);
        world.setBlock(i + 2, j + 43, k + 72, Blocks.stone);
        world.setBlock(i + 2, j + 43, k + 73, Blocks.stone);
        world.setBlock(i + 2, j + 43, k + 74, Blocks.stone);
        world.setBlock(i + 2, j + 43, k + 75, Blocks.stone);
        world.setBlock(i + 2, j + 43, k + 76, Blocks.stone);
        world.setBlock(i + 2, j + 43, k + 77, Blocks.stone);
        world.setBlock(i + 2, j + 43, k + 78, Blocks.stone);
        world.setBlock(i + 2, j + 43, k + 79, Blocks.stone);
        world.setBlock(i + 2, j + 43, k + 80, Blocks.stone);
        world.setBlock(i + 2, j + 43, k + 81, Blocks.stone);
        world.setBlock(i + 2, j + 43, k + 82, Blocks.stone);
        world.setBlock(i + 2, j + 43, k + 83, Blocks.stone);
        world.setBlock(i + 2, j + 43, k + 84, Blocks.stone);
        world.setBlock(i + 2, j + 43, k + 85, Blocks.stone);
        world.setBlock(i + 2, j + 44, k + 72, Blocks.stone);
        world.setBlock(i + 2, j + 44, k + 73, Blocks.stone);
        world.setBlock(i + 2, j + 44, k + 74, Blocks.stone);
        world.setBlock(i + 2, j + 44, k + 75, Blocks.stone);
        world.setBlock(i + 2, j + 44, k + 76, Blocks.stone);
        world.setBlock(i + 2, j + 44, k + 77, Blocks.stone);
        world.setBlock(i + 2, j + 44, k + 78, Blocks.stone);
        world.setBlock(i + 2, j + 44, k + 79, Blocks.stone);
        world.setBlock(i + 2, j + 44, k + 80, Blocks.stone);
        world.setBlock(i + 2, j + 44, k + 81, Blocks.stone);
        world.setBlock(i + 2, j + 44, k + 82, Blocks.stone);
        world.setBlock(i + 2, j + 44, k + 83, Blocks.stone);
        world.setBlock(i + 2, j + 45, k + 72, Blocks.stone);
        world.setBlock(i + 2, j + 45, k + 73, Blocks.stone);
        world.setBlock(i + 2, j + 45, k + 74, Blocks.stone);
        world.setBlock(i + 2, j + 45, k + 75, Blocks.stone);
        world.setBlock(i + 2, j + 45, k + 76, Blocks.stone);
        world.setBlock(i + 2, j + 45, k + 77, Blocks.stone);
        world.setBlock(i + 2, j + 45, k + 78, Blocks.stone);
        world.setBlock(i + 2, j + 45, k + 80, Blocks.stone);
        Dungeons.spawnerRepeater(world, i + 2, j + 45, k + 81, 5, 1, 200);
        world.setBlock(i + 2, j + 46, k + 74, Blocks.stone);
        world.setBlock(i + 2, j + 46, k + 75, Blocks.stone);
        world.setBlock(i + 3, j + 34, k + 83, Blocks.stone);
        world.setBlock(i + 3, j + 34, k + 84, Blocks.stone);
        world.setBlock(i + 3, j + 35, k + 79, Blocks.stone);
        world.setBlock(i + 3, j + 35, k + 80, Blocks.stone);
        world.setBlock(i + 3, j + 35, k + 81, Blocks.stone);
        world.setBlock(i + 3, j + 35, k + 82, Blocks.stone);
        world.setBlock(i + 3, j + 35, k + 83, Blocks.stone);
        world.setBlock(i + 3, j + 35, k + 84, Blocks.stone);
        world.setBlock(i + 3, j + 35, k + 85, Blocks.stone);
        world.setBlock(i + 3, j + 35, k + 86, Blocks.stone);
        world.setBlock(i + 3, j + 36, k + 75, Blocks.stone);
        world.setBlock(i + 3, j + 36, k + 76, Blocks.stone);
        world.setBlock(i + 3, j + 36, k + 77, Blocks.stone);
        world.setBlock(i + 3, j + 36, k + 78, Blocks.stone);
        world.setBlock(i + 3, j + 36, k + 79, Blocks.stone);
        world.setBlock(i + 3, j + 36, k + 80, Blocks.stone);
        world.setBlock(i + 3, j + 36, k + 81, Blocks.stone);
        world.setBlock(i + 3, j + 36, k + 82, Blocks.stone);
        world.setBlock(i + 3, j + 36, k + 83, Blocks.stone);
        world.setBlock(i + 3, j + 36, k + 84, Blocks.stone);
        world.setBlock(i + 3, j + 36, k + 85, Blocks.stone);
        world.setBlock(i + 3, j + 36, k + 86, Blocks.stone);
        world.setBlock(i + 3, j + 36, k + 87, Blocks.stone);
        world.setBlock(i + 3, j + 37, k + 73, Blocks.stone);
        world.setBlock(i + 3, j + 37, k + 74, Blocks.stone);
        world.setBlock(i + 3, j + 37, k + 75, Blocks.stone);
        world.setBlock(i + 3, j + 37, k + 76, Blocks.stone);
        world.setBlock(i + 3, j + 37, k + 77, Blocks.stone);
        world.setBlock(i + 3, j + 37, k + 78, Blocks.stone);
        world.setBlock(i + 3, j + 37, k + 79, Blocks.stone);
        world.setBlock(i + 3, j + 37, k + 80, Blocks.stone);
        world.setBlock(i + 3, j + 37, k + 81, Blocks.stone);
        world.setBlock(i + 3, j + 37, k + 82, Blocks.stone);
        world.setBlock(i + 3, j + 37, k + 83, Blocks.stone);
        world.setBlock(i + 3, j + 37, k + 84, Blocks.stone);
        world.setBlock(i + 3, j + 37, k + 85, Blocks.stone);
        world.setBlock(i + 3, j + 37, k + 86, Blocks.stone);
        world.setBlock(i + 3, j + 37, k + 87, Blocks.stone);
        world.setBlock(i + 3, j + 37, k + 88, Blocks.stone);
        world.setBlock(i + 3, j + 37, k + 90, Blocks.stone);
        world.setBlock(i + 3, j + 37, k + 91, Blocks.stone);
        world.setBlock(i + 3, j + 37, k + 92, Blocks.stone);
        world.setBlock(i + 3, j + 37, k + 93, Blocks.stone);
        world.setBlock(i + 3, j + 37, k + 94, Blocks.stone);
        world.setBlock(i + 3, j + 38, k + 72, Blocks.stone);
        world.setBlock(i + 3, j + 38, k + 73, Blocks.stone);
        world.setBlock(i + 3, j + 38, k + 74, Blocks.stone);
        world.setBlock(i + 3, j + 38, k + 75, Blocks.stone);
        world.setBlock(i + 3, j + 38, k + 76, Blocks.stone);
        world.setBlock(i + 3, j + 38, k + 77, Blocks.stone);
        world.setBlock(i + 3, j + 38, k + 78, Blocks.stone);
        world.setBlock(i + 3, j + 38, k + 79, Blocks.stone);
        world.setBlock(i + 3, j + 38, k + 80, Blocks.stone);
        world.setBlock(i + 3, j + 38, k + 81, Blocks.stone);
        world.setBlock(i + 3, j + 38, k + 82, Blocks.stone);
        world.setBlock(i + 3, j + 38, k + 83, Blocks.stone);
        world.setBlock(i + 3, j + 38, k + 84, Blocks.stone);
        world.setBlock(i + 3, j + 38, k + 85, Blocks.stone);
        world.setBlock(i + 3, j + 38, k + 86, Blocks.stone);
        world.setBlock(i + 3, j + 38, k + 87, Blocks.stone);
        world.setBlock(i + 3, j + 38, k + 88, Blocks.stone);
        world.setBlock(i + 3, j + 38, k + 89, Blocks.stone);
        world.setBlock(i + 3, j + 38, k + 90, Blocks.stone);
        world.setBlock(i + 3, j + 38, k + 91, Blocks.stone);
        world.setBlock(i + 3, j + 38, k + 92, Blocks.stone);
        world.setBlock(i + 3, j + 38, k + 93, Blocks.stone);
        world.setBlock(i + 3, j + 38, k + 94, Blocks.stone);
        world.setBlock(i + 3, j + 38, k + 95, Blocks.stone);
        world.setBlock(i + 3, j + 39, k + 72, Blocks.stone);
        world.setBlock(i + 3, j + 39, k + 73, Blocks.stone);
        world.setBlock(i + 3, j + 39, k + 74, Blocks.stone);
        world.setBlock(i + 3, j + 39, k + 75, Blocks.stone);
        world.setBlock(i + 3, j + 39, k + 76, Blocks.stone);
        world.setBlock(i + 3, j + 39, k + 77, Blocks.stone);
        world.setBlock(i + 3, j + 39, k + 78, Blocks.stone);
        world.setBlock(i + 3, j + 39, k + 79, Blocks.stone);
        world.setBlock(i + 3, j + 39, k + 80, Blocks.stone);
        world.setBlock(i + 3, j + 39, k + 81, Blocks.stone);
        world.setBlock(i + 3, j + 39, k + 82, Blocks.stone);
        world.setBlock(i + 3, j + 39, k + 83, Blocks.stone);
        world.setBlock(i + 3, j + 39, k + 84, Blocks.stone);
        world.setBlock(i + 3, j + 39, k + 85, Blocks.stone);
        world.setBlock(i + 3, j + 39, k + 86, Blocks.stone);
        world.setBlock(i + 3, j + 39, k + 87, Blocks.stone);
        world.setBlock(i + 3, j + 39, k + 88, Blocks.stone);
        world.setBlock(i + 3, j + 39, k + 89, Blocks.stone);
        world.setBlock(i + 3, j + 39, k + 90, Blocks.stone);
        world.setBlock(i + 3, j + 39, k + 91, Blocks.stone);
        world.setBlock(i + 3, j + 39, k + 92, Blocks.stone);
        world.setBlock(i + 3, j + 39, k + 93, Blocks.stone);
        world.setBlock(i + 3, j + 39, k + 94, Blocks.stone);
        world.setBlock(i + 3, j + 39, k + 95, Blocks.stone);
        world.setBlock(i + 3, j + 40, k + 66, Blocks.cobblestone);
        world.setBlock(i + 3, j + 40, k + 67, Blocks.cobblestone);
        world.setBlock(i + 3, j + 40, k + 68, Blocks.cobblestone);
        world.setBlock(i + 3, j + 40, k + 69, Blocks.cobblestone);
        world.setBlock(i + 3, j + 40, k + 70, Blocks.cobblestone);
        world.setBlock(i + 3, j + 40, k + 71, Blocks.cobblestone);
        world.setBlock(i + 3, j + 40, k + 72, Blocks.stone);
        world.setBlock(i + 3, j + 40, k + 73, Blocks.stone);
        world.setBlock(i + 3, j + 40, k + 74, Blocks.stone);
        world.setBlock(i + 3, j + 40, k + 75, Blocks.stone);
        world.setBlock(i + 3, j + 40, k + 76, Blocks.stone);
        world.setBlock(i + 3, j + 40, k + 77, Blocks.stone);
        world.setBlock(i + 3, j + 40, k + 78, Blocks.stone);
        world.setBlock(i + 3, j + 40, k + 79, Blocks.stone);
        world.setBlock(i + 3, j + 40, k + 80, Blocks.stone);
        world.setBlock(i + 3, j + 40, k + 81, Blocks.stone);
        world.setBlock(i + 3, j + 40, k + 82, Blocks.stone);
        world.setBlock(i + 3, j + 40, k + 83, Blocks.stone);
        world.setBlock(i + 3, j + 40, k + 84, Blocks.stone);
        world.setBlock(i + 3, j + 40, k + 85, Blocks.stone);
        world.setBlock(i + 3, j + 40, k + 86, Blocks.stone);
        world.setBlock(i + 3, j + 40, k + 87, Blocks.stone);
        world.setBlock(i + 3, j + 40, k + 88, Blocks.stone);
        world.setBlock(i + 3, j + 40, k + 89, Blocks.stone);
        world.setBlock(i + 3, j + 40, k + 90, Blocks.stone);
        world.setBlock(i + 3, j + 40, k + 91, Blocks.stone);
        world.setBlock(i + 3, j + 40, k + 92, Blocks.stone);
        world.setBlock(i + 3, j + 40, k + 93, Blocks.stone);
        world.setBlock(i + 3, j + 40, k + 94, Blocks.stone);
        world.setBlock(i + 3, j + 40, k + 95, Blocks.stone);
        world.setBlock(i + 3, j + 40, k + 96, Blocks.stone);
        world.setBlock(i + 3, j + 41, k + 66, Blocks.cobblestone);
        world.setBlock(i + 3, j + 41, k + 67, Blocks.cobblestone);
        world.setBlock(i + 3, j + 41, k + 68, Blocks.cobblestone);
        world.setBlock(i + 3, j + 41, k + 69, Blocks.cobblestone);
        world.setBlock(i + 3, j + 41, k + 70, Blocks.cobblestone);
        world.setBlock(i + 3, j + 41, k + 71, Blocks.cobblestone);
        world.setBlock(i + 3, j + 41, k + 72, Blocks.stone);
        world.setBlock(i + 3, j + 41, k + 73, Blocks.stone);
        world.setBlock(i + 3, j + 41, k + 74, Blocks.stone);
        world.setBlock(i + 3, j + 41, k + 75, Blocks.stone);
        world.setBlock(i + 3, j + 41, k + 76, Blocks.stone);
        world.setBlock(i + 3, j + 41, k + 77, Blocks.stone);
        world.setBlock(i + 3, j + 41, k + 78, Blocks.stone);
        world.setBlock(i + 3, j + 41, k + 79, Blocks.stone);
        world.setBlock(i + 3, j + 41, k + 80, Blocks.stone);
        world.setBlock(i + 3, j + 41, k + 81, Blocks.stone);
        world.setBlock(i + 3, j + 41, k + 82, Blocks.stone);
        world.setBlock(i + 3, j + 41, k + 83, Blocks.stone);
        world.setBlock(i + 3, j + 41, k + 84, Blocks.stone);
        world.setBlock(i + 3, j + 41, k + 85, Blocks.stone);
        world.setBlock(i + 3, j + 41, k + 86, Blocks.stone);
        world.setBlock(i + 3, j + 41, k + 87, Blocks.stone);
        world.setBlock(i + 3, j + 41, k + 88, Blocks.stone);
        world.setBlock(i + 3, j + 41, k + 89, Blocks.stone);
        world.setBlock(i + 3, j + 41, k + 90, Blocks.stone);
        world.setBlock(i + 3, j + 41, k + 91, Blocks.stone);
        world.setBlock(i + 3, j + 41, k + 92, Blocks.stone);
        world.setBlock(i + 3, j + 41, k + 93, Blocks.stone);
        world.setBlock(i + 3, j + 41, k + 94, Blocks.stone);
        world.setBlock(i + 3, j + 41, k + 95, Blocks.stone);
        world.setBlock(i + 3, j + 41, k + 96, Blocks.stone);
        world.setBlock(i + 3, j + 42, k + 66, Blocks.iron_ore);
        world.setBlock(i + 3, j + 42, k + 67, Blocks.iron_ore);
        world.setBlock(i + 3, j + 42, k + 68, Blocks.iron_ore);
        world.setBlock(i + 3, j + 42, k + 69, Blocks.iron_ore);
        world.setBlock(i + 3, j + 42, k + 70, Blocks.iron_ore);
        world.setBlock(i + 3, j + 42, k + 71, Blocks.iron_ore);
        world.setBlock(i + 3, j + 42, k + 72, Blocks.stone);
        world.setBlock(i + 3, j + 42, k + 73, Blocks.stone);
        world.setBlock(i + 3, j + 42, k + 74, Blocks.stone);
        world.setBlock(i + 3, j + 42, k + 75, Blocks.stone);
        world.setBlock(i + 3, j + 42, k + 76, Blocks.stone);
        world.setBlock(i + 3, j + 42, k + 77, Blocks.stone);
        world.setBlock(i + 3, j + 42, k + 78, Blocks.stone);
        world.setBlock(i + 3, j + 42, k + 79, Blocks.stone);
        world.setBlock(i + 3, j + 42, k + 80, Blocks.stone);
        world.setBlock(i + 3, j + 42, k + 81, Blocks.stone);
        world.setBlock(i + 3, j + 42, k + 82, Blocks.stone);
        world.setBlock(i + 3, j + 42, k + 83, Blocks.stone);
        world.setBlock(i + 3, j + 42, k + 84, Blocks.stone);
        world.setBlock(i + 3, j + 42, k + 85, Blocks.stone);
        world.setBlock(i + 3, j + 42, k + 86, Blocks.stone);
        world.setBlock(i + 3, j + 42, k + 87, Blocks.stone);
        world.setBlock(i + 3, j + 42, k + 88, Blocks.stone);
        world.setBlock(i + 3, j + 42, k + 89, Blocks.stone);
        world.setBlock(i + 3, j + 42, k + 90, Blocks.stone);
        world.setBlock(i + 3, j + 42, k + 91, Blocks.stone);
        world.setBlock(i + 3, j + 42, k + 92, Blocks.stone);
        world.setBlock(i + 3, j + 42, k + 93, Blocks.stone);
        world.setBlock(i + 3, j + 42, k + 94, Blocks.stone);
        world.setBlock(i + 3, j + 43, k + 72, Blocks.stone);
        world.setBlock(i + 3, j + 43, k + 73, Blocks.stone);
        world.setBlock(i + 3, j + 43, k + 74, Blocks.stone);
        world.setBlock(i + 3, j + 43, k + 75, Blocks.stone);
        world.setBlock(i + 3, j + 43, k + 76, Blocks.stone);
        world.setBlock(i + 3, j + 43, k + 77, Blocks.stone);
        world.setBlock(i + 3, j + 43, k + 78, Blocks.stone);
        world.setBlock(i + 3, j + 43, k + 79, Blocks.stone);
        world.setBlock(i + 3, j + 43, k + 80, Blocks.stone);
        world.setBlock(i + 3, j + 43, k + 81, Blocks.stone);
        world.setBlock(i + 3, j + 43, k + 82, Blocks.stone);
        world.setBlock(i + 3, j + 43, k + 83, Blocks.stone);
        world.setBlock(i + 3, j + 43, k + 84, Blocks.stone);
        world.setBlock(i + 3, j + 44, k + 72, Blocks.stone);
        world.setBlock(i + 3, j + 44, k + 73, Blocks.stone);
        world.setBlock(i + 3, j + 44, k + 74, Blocks.stone);
        world.setBlock(i + 3, j + 44, k + 75, Blocks.stone);
        world.setBlock(i + 3, j + 44, k + 76, Blocks.stone);
        world.setBlock(i + 3, j + 44, k + 77, Blocks.stone);
        world.setBlock(i + 3, j + 44, k + 78, Blocks.stone);
        world.setBlock(i + 3, j + 44, k + 79, Blocks.stone);
        world.setBlock(i + 3, j + 44, k + 80, Blocks.stone);
        world.setBlock(i + 3, j + 44, k + 81, Blocks.stone);
        world.setBlock(i + 3, j + 44, k + 82, Blocks.stone);
        world.setBlock(i + 3, j + 45, k + 72, Blocks.stone);
        world.setBlock(i + 3, j + 45, k + 73, Blocks.stone);
        world.setBlock(i + 3, j + 45, k + 74, Blocks.stone);
        world.setBlock(i + 3, j + 45, k + 75, Blocks.stone);
        world.setBlock(i + 3, j + 45, k + 76, Blocks.stone);
        world.setBlock(i + 3, j + 45, k + 77, Blocks.stone);
        world.setBlock(i + 3, j + 46, k + 74, Blocks.stone);
        world.setBlock(i + 4, j + 33, k + 82, Blocks.stone);
        world.setBlock(i + 4, j + 33, k + 83, Blocks.stone);
        world.setBlock(i + 4, j + 33, k + 84, Blocks.stone);
        world.setBlock(i + 4, j + 34, k + 80, Blocks.stone);
        world.setBlock(i + 4, j + 34, k + 81, Blocks.stone);
        world.setBlock(i + 4, j + 34, k + 82, Blocks.stone);
        world.setBlock(i + 4, j + 34, k + 83, Blocks.stone);
        world.setBlock(i + 4, j + 34, k + 84, Blocks.stone);
        world.setBlock(i + 4, j + 34, k + 85, Blocks.stone);
        world.setBlock(i + 4, j + 35, k + 78, Blocks.stone);
        world.setBlock(i + 4, j + 35, k + 79, Blocks.stone);
        world.setBlock(i + 4, j + 35, k + 80, Blocks.stone);
        world.setBlock(i + 4, j + 35, k + 81, Blocks.stone);
        world.setBlock(i + 4, j + 35, k + 82, Blocks.stone);
        world.setBlock(i + 4, j + 35, k + 83, Blocks.stone);
        world.setBlock(i + 4, j + 35, k + 84, Blocks.stone);
        world.setBlock(i + 4, j + 35, k + 85, Blocks.stone);
        world.setBlock(i + 4, j + 35, k + 86, Blocks.stone);
        world.setBlock(i + 4, j + 36, k + 75, Blocks.stone);
        world.setBlock(i + 4, j + 36, k + 76, Blocks.stone);
        world.setBlock(i + 4, j + 36, k + 77, Blocks.stone);
        world.setBlock(i + 4, j + 36, k + 78, Blocks.stone);
        world.setBlock(i + 4, j + 36, k + 79, Blocks.stone);
        world.setBlock(i + 4, j + 36, k + 80, Blocks.stone);
        world.setBlock(i + 4, j + 36, k + 81, Blocks.stone);
        world.setBlock(i + 4, j + 36, k + 82, Blocks.stone);
        world.setBlock(i + 4, j + 36, k + 83, Blocks.stone);
        world.setBlock(i + 4, j + 36, k + 84, Blocks.stone);
        world.setBlock(i + 4, j + 36, k + 85, Blocks.stone);
        world.setBlock(i + 4, j + 36, k + 86, Blocks.stone);
        world.setBlock(i + 4, j + 36, k + 87, Blocks.stone);
        world.setBlock(i + 4, j + 36, k + 88, Blocks.stone);
        world.setBlock(i + 4, j + 36, k + 89, Blocks.stone);
        world.setBlock(i + 4, j + 36, k + 90, Blocks.stone);
        world.setBlock(i + 4, j + 36, k + 91, Blocks.stone);
        world.setBlock(i + 4, j + 36, k + 92, Blocks.stone);
        world.setBlock(i + 4, j + 37, k + 74, Blocks.stone);
        world.setBlock(i + 4, j + 37, k + 75, Blocks.stone);
        world.setBlock(i + 4, j + 37, k + 76, Blocks.stone);
        world.setBlock(i + 4, j + 37, k + 77, Blocks.stone);
        world.setBlock(i + 4, j + 37, k + 78, Blocks.stone);
        world.setBlock(i + 4, j + 37, k + 79, Blocks.stone);
        world.setBlock(i + 4, j + 37, k + 80, Blocks.stone);
        world.setBlock(i + 4, j + 37, k + 81, Blocks.stone);
        world.setBlock(i + 4, j + 37, k + 82, Blocks.stone);
        world.setBlock(i + 4, j + 37, k + 83, Blocks.stone);
        world.setBlock(i + 4, j + 37, k + 84, Blocks.stone);
        world.setBlock(i + 4, j + 37, k + 85, Blocks.stone);
        world.setBlock(i + 4, j + 37, k + 86, Blocks.stone);
        world.setBlock(i + 4, j + 37, k + 87, Blocks.stone);
        world.setBlock(i + 4, j + 37, k + 88, Blocks.stone);
        world.setBlock(i + 4, j + 37, k + 89, Blocks.stone);
        world.setBlock(i + 4, j + 37, k + 90, Blocks.stone);
        world.setBlock(i + 4, j + 37, k + 91, Blocks.stone);
        world.setBlock(i + 4, j + 37, k + 92, Blocks.stone);
        world.setBlock(i + 4, j + 37, k + 93, Blocks.stone);
        world.setBlock(i + 4, j + 37, k + 94, Blocks.stone);
        world.setBlock(i + 4, j + 37, k + 95, Blocks.stone);
        world.setBlock(i + 4, j + 38, k + 73, Blocks.stone);
        world.setBlock(i + 4, j + 38, k + 74, Blocks.stone);
        world.setBlock(i + 4, j + 38, k + 75, Blocks.stone);
        world.setBlock(i + 4, j + 38, k + 76, Blocks.stone);
        world.setBlock(i + 4, j + 38, k + 77, Blocks.stone);
        world.setBlock(i + 4, j + 38, k + 78, Blocks.stone);
        world.setBlock(i + 4, j + 38, k + 79, Blocks.stone);
        world.setBlock(i + 4, j + 38, k + 80, Blocks.stone);
        world.setBlock(i + 4, j + 38, k + 81, Blocks.stone);
        world.setBlock(i + 4, j + 38, k + 82, Blocks.stone);
        world.setBlock(i + 4, j + 38, k + 83, Blocks.stone);
        world.setBlock(i + 4, j + 38, k + 84, Blocks.stone);
        world.setBlock(i + 4, j + 38, k + 85, Blocks.stone);
        world.setBlock(i + 4, j + 38, k + 86, Blocks.stone);
        world.setBlock(i + 4, j + 38, k + 87, Blocks.stone);
        world.setBlock(i + 4, j + 38, k + 89, Blocks.stone);
        world.setBlock(i + 4, j + 38, k + 90, Blocks.stone);
        world.setBlock(i + 4, j + 38, k + 91, Blocks.stone);
        world.setBlock(i + 4, j + 38, k + 92, Blocks.stone);
        world.setBlock(i + 4, j + 38, k + 93, Blocks.stone);
        world.setBlock(i + 4, j + 38, k + 94, Blocks.stone);
        world.setBlock(i + 4, j + 38, k + 95, Blocks.stone);
        world.setBlock(i + 4, j + 39, k + 72, Blocks.stone);
        world.setBlock(i + 4, j + 39, k + 73, Blocks.stone);
        world.setBlock(i + 4, j + 39, k + 74, Blocks.stone);
        world.setBlock(i + 4, j + 39, k + 75, Blocks.stone);
        world.setBlock(i + 4, j + 39, k + 76, Blocks.stone);
        world.setBlock(i + 4, j + 39, k + 77, Blocks.stone);
        world.setBlock(i + 4, j + 39, k + 78, Blocks.stone);
        world.setBlock(i + 4, j + 39, k + 79, Blocks.stone);
        world.setBlock(i + 4, j + 39, k + 80, Blocks.stone);
        world.setBlock(i + 4, j + 39, k + 81, Blocks.stone);
        world.setBlock(i + 4, j + 39, k + 82, Blocks.stone);
        world.setBlock(i + 4, j + 39, k + 83, Blocks.stone);
        world.setBlock(i + 4, j + 39, k + 84, Blocks.stone);
        world.setBlock(i + 4, j + 39, k + 85, Blocks.stone);
        world.setBlock(i + 4, j + 39, k + 86, Blocks.stone);
        world.setBlock(i + 4, j + 39, k + 88, Blocks.stone);
        world.setBlock(i + 4, j + 39, k + 89, Blocks.stone);
        world.setBlock(i + 4, j + 39, k + 90, Blocks.stone);
        world.setBlock(i + 4, j + 39, k + 91, Blocks.stone);
        world.setBlock(i + 4, j + 39, k + 92, Blocks.stone);
        world.setBlock(i + 4, j + 39, k + 93, Blocks.stone);
        world.setBlock(i + 4, j + 39, k + 94, Blocks.stone);
        world.setBlock(i + 4, j + 39, k + 95, Blocks.stone);
        world.setBlock(i + 4, j + 39, k + 96, Blocks.stone);
        world.setBlock(i + 4, j + 40, k + 66, Blocks.cobblestone);
        world.setBlock(i + 4, j + 40, k + 67, Blocks.cobblestone);
        world.setBlock(i + 4, j + 40, k + 68, Blocks.cobblestone);
        world.setBlock(i + 4, j + 40, k + 69, Blocks.cobblestone);
        world.setBlock(i + 4, j + 40, k + 70, Blocks.cobblestone);
        world.setBlock(i + 4, j + 40, k + 71, Blocks.cobblestone);
        world.setBlock(i + 4, j + 40, k + 72, Blocks.stone);
        world.setBlock(i + 4, j + 40, k + 73, Blocks.stone);
        world.setBlock(i + 4, j + 40, k + 74, Blocks.stone);
        world.setBlock(i + 4, j + 40, k + 75, Blocks.stone);
        world.setBlock(i + 4, j + 40, k + 76, Blocks.stone);
        world.setBlock(i + 4, j + 40, k + 77, Blocks.stone);
        world.setBlock(i + 4, j + 40, k + 78, Blocks.stone);
        world.setBlock(i + 4, j + 40, k + 79, Blocks.stone);
        world.setBlock(i + 4, j + 40, k + 80, Blocks.stone);
        world.setBlock(i + 4, j + 40, k + 81, Blocks.stone);
        world.setBlock(i + 4, j + 40, k + 82, Blocks.stone);
        world.setBlock(i + 4, j + 40, k + 83, Blocks.stone);
        world.setBlock(i + 4, j + 40, k + 84, Blocks.stone);
        world.setBlock(i + 4, j + 40, k + 85, Blocks.stone);
        world.setBlock(i + 4, j + 40, k + 86, Blocks.stone);
        world.setBlock(i + 4, j + 40, k + 87, Blocks.stone);
        world.setBlock(i + 4, j + 40, k + 88, Blocks.stone);
        world.setBlock(i + 4, j + 40, k + 89, Blocks.stone);
        world.setBlock(i + 4, j + 40, k + 90, Blocks.stone);
        world.setBlock(i + 4, j + 40, k + 91, Blocks.stone);
        world.setBlock(i + 4, j + 40, k + 92, Blocks.stone);
        world.setBlock(i + 4, j + 40, k + 93, Blocks.stone);
        world.setBlock(i + 4, j + 40, k + 94, Blocks.stone);
        world.setBlock(i + 4, j + 40, k + 95, Blocks.stone);
        world.setBlock(i + 4, j + 40, k + 96, Blocks.stone);
        world.setBlock(i + 4, j + 41, k + 66, Blocks.cobblestone);
        world.setBlock(i + 4, j + 41, k + 67, Blocks.cobblestone);
        world.setBlock(i + 4, j + 41, k + 68, Blocks.cobblestone);
        world.setBlock(i + 4, j + 41, k + 69, Blocks.cobblestone);
        world.setBlock(i + 4, j + 41, k + 70, Blocks.cobblestone);
        world.setBlock(i + 4, j + 41, k + 71, Blocks.cobblestone);
        world.setBlock(i + 4, j + 41, k + 72, Blocks.stone);
        world.setBlock(i + 4, j + 41, k + 73, Blocks.stone);
        world.setBlock(i + 4, j + 41, k + 74, Blocks.stone);
        world.setBlock(i + 4, j + 41, k + 75, Blocks.stone);
        world.setBlock(i + 4, j + 41, k + 76, Blocks.stone);
        world.setBlock(i + 4, j + 41, k + 77, Blocks.stone);
        world.setBlock(i + 4, j + 41, k + 78, Blocks.stone);
        world.setBlock(i + 4, j + 41, k + 79, Blocks.stone);
        world.setBlock(i + 4, j + 41, k + 80, Blocks.stone);
        world.setBlock(i + 4, j + 41, k + 81, Blocks.stone);
        world.setBlock(i + 4, j + 41, k + 82, Blocks.stone);
        world.setBlock(i + 4, j + 41, k + 83, Blocks.stone);
        world.setBlock(i + 4, j + 41, k + 84, Blocks.stone);
        world.setBlock(i + 4, j + 41, k + 85, Blocks.stone);
        world.setBlock(i + 4, j + 41, k + 86, Blocks.stone);
        world.setBlock(i + 4, j + 41, k + 87, Blocks.stone);
        world.setBlock(i + 4, j + 41, k + 88, Blocks.stone);
        world.setBlock(i + 4, j + 41, k + 89, Blocks.stone);
        world.setBlock(i + 4, j + 41, k + 90, Blocks.stone);
        world.setBlock(i + 4, j + 41, k + 91, Blocks.stone);
        world.setBlock(i + 4, j + 41, k + 92, Blocks.stone);
        world.setBlock(i + 4, j + 41, k + 93, Blocks.stone);
        world.setBlock(i + 4, j + 41, k + 94, Blocks.stone);
        world.setBlock(i + 4, j + 41, k + 95, Blocks.stone);
        world.setBlock(i + 4, j + 41, k + 96, Blocks.stone);
        world.setBlock(i + 4, j + 42, k + 66, Blocks.iron_ore);
        world.setBlock(i + 4, j + 42, k + 67, Blocks.iron_ore);
        world.setBlock(i + 4, j + 42, k + 68, Blocks.iron_ore);
        world.setBlock(i + 4, j + 42, k + 69, Blocks.iron_ore);
        world.setBlock(i + 4, j + 42, k + 70, Blocks.iron_ore);
        world.setBlock(i + 4, j + 42, k + 71, Blocks.iron_ore);
        world.setBlock(i + 4, j + 42, k + 72, Blocks.stone);
        world.setBlock(i + 4, j + 42, k + 73, Blocks.stone);
        world.setBlock(i + 4, j + 42, k + 74, Blocks.stone);
        world.setBlock(i + 4, j + 42, k + 75, Blocks.stone);
        world.setBlock(i + 4, j + 42, k + 76, Blocks.stone);
        world.setBlock(i + 4, j + 42, k + 77, Blocks.stone);
        world.setBlock(i + 4, j + 42, k + 78, Blocks.stone);
        world.setBlock(i + 4, j + 42, k + 79, Blocks.stone);
        world.setBlock(i + 4, j + 42, k + 80, Blocks.stone);
        world.setBlock(i + 4, j + 42, k + 81, Blocks.stone);
        world.setBlock(i + 4, j + 42, k + 82, Blocks.stone);
        world.setBlock(i + 4, j + 42, k + 83, Blocks.stone);
        world.setBlock(i + 4, j + 42, k + 84, Blocks.stone);
        world.setBlock(i + 4, j + 42, k + 85, Blocks.stone);
        world.setBlock(i + 4, j + 42, k + 86, Blocks.stone);
        world.setBlock(i + 4, j + 42, k + 87, Blocks.stone);
        world.setBlock(i + 4, j + 42, k + 88, Blocks.stone);
        world.setBlock(i + 4, j + 42, k + 89, Blocks.stone);
        world.setBlock(i + 4, j + 42, k + 90, Blocks.stone);
        world.setBlock(i + 4, j + 42, k + 91, Blocks.stone);
        world.setBlock(i + 4, j + 42, k + 92, Blocks.stone);
        world.setBlock(i + 4, j + 42, k + 93, Blocks.stone);
        world.setBlock(i + 4, j + 42, k + 94, Blocks.stone);
        world.setBlock(i + 4, j + 42, k + 95, Blocks.stone);
        world.setBlock(i + 4, j + 43, k + 66, Blocks.iron_ore);
        world.setBlock(i + 4, j + 43, k + 67, Blocks.iron_ore);
        world.setBlock(i + 4, j + 43, k + 68, Blocks.iron_ore);
        world.setBlock(i + 4, j + 43, k + 69, Blocks.iron_ore);
        world.setBlock(i + 4, j + 43, k + 70, Blocks.iron_ore);
        world.setBlock(i + 4, j + 43, k + 71, Blocks.iron_ore);
        world.setBlock(i + 4, j + 43, k + 72, Blocks.stone);
        world.setBlock(i + 4, j + 43, k + 73, Blocks.stone);
        world.setBlock(i + 4, j + 43, k + 74, Blocks.stone);
        world.setBlock(i + 4, j + 43, k + 75, Blocks.stone);
        world.setBlock(i + 4, j + 43, k + 76, Blocks.stone);
        world.setBlock(i + 4, j + 43, k + 77, Blocks.stone);
        world.setBlock(i + 4, j + 43, k + 78, Blocks.stone);
        world.setBlock(i + 4, j + 43, k + 79, Blocks.stone);
        world.setBlock(i + 4, j + 43, k + 80, Blocks.stone);
        world.setBlock(i + 4, j + 43, k + 81, Blocks.stone);
        world.setBlock(i + 4, j + 43, k + 82, Blocks.stone);
        world.setBlock(i + 4, j + 43, k + 83, Blocks.stone);
        world.setBlock(i + 4, j + 43, k + 84, Blocks.stone);
        world.setBlock(i + 4, j + 44, k + 72, Blocks.stone);
        world.setBlock(i + 4, j + 44, k + 73, Blocks.stone);
        world.setBlock(i + 4, j + 44, k + 74, Blocks.stone);
        world.setBlock(i + 4, j + 44, k + 75, Blocks.stone);
        world.setBlock(i + 4, j + 44, k + 76, Blocks.stone);
        world.setBlock(i + 4, j + 44, k + 77, Blocks.stone);
        world.setBlock(i + 4, j + 44, k + 78, Blocks.stone);
        world.setBlock(i + 4, j + 44, k + 79, Blocks.stone);
        world.setBlock(i + 4, j + 44, k + 80, Blocks.stone);
        world.setBlock(i + 4, j + 44, k + 81, Blocks.stone);
        world.setBlock(i + 4, j + 45, k + 73, Blocks.stone);
        world.setBlock(i + 4, j + 45, k + 74, Blocks.stone);
        world.setBlock(i + 4, j + 45, k + 75, Blocks.stone);
        world.setBlock(i + 4, j + 45, k + 76, Blocks.stone);
        world.setBlock(i + 4, j + 45, k + 77, Blocks.stone);
        world.setBlock(i + 4, j + 45, k + 78, Blocks.stone);
        world.setBlock(i + 4, j + 46, k + 74, Blocks.stone);
        world.setBlock(i + 4, j + 46, k + 75, Blocks.stone);
        world.setBlock(i + 4, j + 46, k + 77, Blocks.stone);
        world.setBlock(i + 5, j + 32, k + 83, Blocks.stone);
        world.setBlock(i + 5, j + 32, k + 84, Blocks.stone);
        world.setBlock(i + 5, j + 33, k + 82, Blocks.stone);
        world.setBlock(i + 5, j + 33, k + 83, Blocks.stone);
        world.setBlock(i + 5, j + 33, k + 84, Blocks.stone);
        world.setBlock(i + 5, j + 33, k + 85, Blocks.stone);
        world.setBlock(i + 5, j + 34, k + 79, Blocks.stone);
        world.setBlock(i + 5, j + 34, k + 80, Blocks.stone);
        world.setBlock(i + 5, j + 34, k + 81, Blocks.stone);
        world.setBlock(i + 5, j + 34, k + 82, Blocks.stone);
        world.setBlock(i + 5, j + 34, k + 83, Blocks.stone);
        world.setBlock(i + 5, j + 34, k + 84, Blocks.stone);
        world.setBlock(i + 5, j + 34, k + 85, Blocks.stone);
        world.setBlock(i + 5, j + 34, k + 86, Blocks.stone);
        world.setBlock(i + 5, j + 35, k + 78, Blocks.stone);
        world.setBlock(i + 5, j + 35, k + 79, Blocks.stone);
        world.setBlock(i + 5, j + 35, k + 80, Blocks.stone);
        world.setBlock(i + 5, j + 35, k + 81, Blocks.stone);
        world.setBlock(i + 5, j + 35, k + 82, Blocks.stone);
        world.setBlock(i + 5, j + 35, k + 83, Blocks.stone);
        world.setBlock(i + 5, j + 35, k + 84, Blocks.stone);
        world.setBlock(i + 5, j + 35, k + 85, Blocks.stone);
        world.setBlock(i + 5, j + 35, k + 86, Blocks.stone);
        world.setBlock(i + 5, j + 36, k + 75, Blocks.stone);
        world.setBlock(i + 5, j + 36, k + 76, Blocks.stone);
        world.setBlock(i + 5, j + 36, k + 77, Blocks.stone);
        world.setBlock(i + 5, j + 36, k + 78, Blocks.stone);
        world.setBlock(i + 5, j + 36, k + 79, Blocks.stone);
        world.setBlock(i + 5, j + 36, k + 80, Blocks.stone);
        world.setBlock(i + 5, j + 36, k + 81, Blocks.stone);
        world.setBlock(i + 5, j + 36, k + 82, Blocks.stone);
        world.setBlock(i + 5, j + 36, k + 83, Blocks.stone);
        world.setBlock(i + 5, j + 36, k + 84, Blocks.stone);
        world.setBlock(i + 5, j + 36, k + 85, Blocks.stone);
        world.setBlock(i + 5, j + 36, k + 86, Blocks.stone);
        world.setBlock(i + 5, j + 36, k + 87, Blocks.stone);
        world.setBlock(i + 5, j + 36, k + 88, Blocks.stone);
        world.setBlock(i + 5, j + 36, k + 89, Blocks.stone);
        world.setBlock(i + 5, j + 36, k + 90, Blocks.stone);
        world.setBlock(i + 5, j + 36, k + 91, Blocks.stone);
        world.setBlock(i + 5, j + 36, k + 92, Blocks.stone);
        world.setBlock(i + 5, j + 36, k + 93, Blocks.stone);
        world.setBlock(i + 5, j + 37, k + 74, Blocks.stone);
        world.setBlock(i + 5, j + 37, k + 75, Blocks.stone);
        world.setBlock(i + 5, j + 37, k + 76, Blocks.stone);
        world.setBlock(i + 5, j + 37, k + 77, Blocks.stone);
        world.setBlock(i + 5, j + 37, k + 78, Blocks.stone);
        world.setBlock(i + 5, j + 37, k + 79, Blocks.stone);
        world.setBlock(i + 5, j + 37, k + 80, Blocks.stone);
        world.setBlock(i + 5, j + 37, k + 81, Blocks.stone);
        world.setBlock(i + 5, j + 37, k + 82, Blocks.stone);
        world.setBlock(i + 5, j + 37, k + 83, Blocks.stone);
        world.setBlock(i + 5, j + 37, k + 84, Blocks.stone);
        world.setBlock(i + 5, j + 37, k + 85, Blocks.stone);
        world.setBlock(i + 5, j + 37, k + 86, Blocks.stone);
        world.setBlock(i + 5, j + 37, k + 87, Blocks.stone);
        world.setBlock(i + 5, j + 37, k + 88, Blocks.stone);
        world.setBlock(i + 5, j + 37, k + 89, Blocks.stone);
        world.setBlock(i + 5, j + 37, k + 90, Blocks.stone);
        world.setBlock(i + 5, j + 37, k + 91, Blocks.stone);
        world.setBlock(i + 5, j + 37, k + 92, Blocks.stone);
        world.setBlock(i + 5, j + 37, k + 93, Blocks.stone);
        world.setBlock(i + 5, j + 37, k + 94, Blocks.stone);
        world.setBlock(i + 5, j + 37, k + 95, Blocks.stone);
        world.setBlock(i + 5, j + 38, k + 73, Blocks.stone);
        world.setBlock(i + 5, j + 38, k + 74, Blocks.stone);
        world.setBlock(i + 5, j + 38, k + 75, Blocks.stone);
        world.setBlock(i + 5, j + 38, k + 76, Blocks.stone);
        world.setBlock(i + 5, j + 38, k + 77, Blocks.stone);
        world.setBlock(i + 5, j + 38, k + 78, Blocks.stone);
        world.setBlock(i + 5, j + 38, k + 79, Blocks.stone);
        world.setBlock(i + 5, j + 38, k + 80, Blocks.stone);
        world.setBlock(i + 5, j + 38, k + 81, Blocks.stone);
        world.setBlock(i + 5, j + 38, k + 82, Blocks.stone);
        world.setBlock(i + 5, j + 38, k + 83, Blocks.stone);
        world.setBlock(i + 5, j + 38, k + 84, Blocks.stone);
        world.setBlock(i + 5, j + 38, k + 85, Blocks.stone);
        world.setBlock(i + 5, j + 38, k + 86, Blocks.stone);
        world.setBlock(i + 5, j + 38, k + 87, Blocks.stone);
        world.setBlock(i + 5, j + 38, k + 88, Blocks.stone);
        world.setBlock(i + 5, j + 38, k + 89, Blocks.stone);
        world.setBlock(i + 5, j + 38, k + 90, Blocks.stone);
        world.setBlock(i + 5, j + 38, k + 91, Blocks.stone);
        world.setBlock(i + 5, j + 38, k + 92, Blocks.stone);
        world.setBlock(i + 5, j + 38, k + 93, Blocks.stone);
        world.setBlock(i + 5, j + 38, k + 94, Blocks.stone);
        world.setBlock(i + 5, j + 38, k + 95, Blocks.stone);
        world.setBlock(i + 5, j + 38, k + 96, Blocks.stone);
        world.setBlock(i + 5, j + 39, k + 73, Blocks.stone);
        world.setBlock(i + 5, j + 39, k + 74, Blocks.stone);
        world.setBlock(i + 5, j + 39, k + 75, Blocks.stone);
        world.setBlock(i + 5, j + 39, k + 76, Blocks.stone);
        world.setBlock(i + 5, j + 39, k + 77, Blocks.stone);
        world.setBlock(i + 5, j + 39, k + 78, Blocks.stone);
        world.setBlock(i + 5, j + 39, k + 79, Blocks.stone);
        world.setBlock(i + 5, j + 39, k + 80, Blocks.stone);
        world.setBlock(i + 5, j + 39, k + 81, Blocks.stone);
        world.setBlock(i + 5, j + 39, k + 82, Blocks.stone);
        world.setBlock(i + 5, j + 39, k + 83, Blocks.stone);
        world.setBlock(i + 5, j + 39, k + 84, Blocks.stone);
        world.setBlock(i + 5, j + 39, k + 85, Blocks.stone);
        world.setBlock(i + 5, j + 39, k + 86, Blocks.stone);
        world.setBlock(i + 5, j + 39, k + 87, Blocks.stone);
        world.setBlock(i + 5, j + 39, k + 88, Blocks.stone);
        world.setBlock(i + 5, j + 39, k + 89, Blocks.stone);
        world.setBlock(i + 5, j + 39, k + 90, Blocks.stone);
        world.setBlock(i + 5, j + 39, k + 91, Blocks.stone);
        world.setBlock(i + 5, j + 39, k + 92, Blocks.stone);
        world.setBlock(i + 5, j + 39, k + 93, Blocks.stone);
        world.setBlock(i + 5, j + 39, k + 94, Blocks.stone);
        world.setBlock(i + 5, j + 39, k + 95, Blocks.stone);
        world.setBlock(i + 5, j + 39, k + 96, Blocks.stone);
        world.setBlock(i + 5, j + 40, k + 66, Blocks.cobblestone);
        world.setBlock(i + 5, j + 40, k + 67, Blocks.cobblestone);
        world.setBlock(i + 5, j + 40, k + 68, Blocks.cobblestone);
        world.setBlock(i + 5, j + 40, k + 69, Blocks.cobblestone);
        world.setBlock(i + 5, j + 40, k + 70, Blocks.cobblestone);
        world.setBlock(i + 5, j + 40, k + 71, Blocks.cobblestone);
        world.setBlock(i + 5, j + 40, k + 73, Blocks.stone);
        world.setBlock(i + 5, j + 40, k + 74, Blocks.stone);
        world.setBlock(i + 5, j + 40, k + 75, Blocks.stone);
        world.setBlock(i + 5, j + 40, k + 76, Blocks.stone);
        world.setBlock(i + 5, j + 40, k + 77, Blocks.stone);
        world.setBlock(i + 5, j + 40, k + 78, Blocks.stone);
        world.setBlock(i + 5, j + 40, k + 79, Blocks.stone);
        world.setBlock(i + 5, j + 40, k + 80, Blocks.stone);
        world.setBlock(i + 5, j + 40, k + 81, Blocks.stone);
        world.setBlock(i + 5, j + 40, k + 82, Blocks.stone);
        world.setBlock(i + 5, j + 40, k + 83, Blocks.stone);
        world.setBlock(i + 5, j + 40, k + 84, Blocks.stone);
        world.setBlock(i + 5, j + 40, k + 85, Blocks.stone);
        world.setBlock(i + 5, j + 40, k + 86, Blocks.stone);
        world.setBlock(i + 5, j + 40, k + 87, Blocks.stone);
        world.setBlock(i + 5, j + 40, k + 88, Blocks.stone);
        world.setBlock(i + 5, j + 40, k + 89, Blocks.stone);
        world.setBlock(i + 5, j + 40, k + 90, Blocks.stone);
        world.setBlock(i + 5, j + 40, k + 91, Blocks.stone);
        world.setBlock(i + 5, j + 40, k + 92, Blocks.stone);
        world.setBlock(i + 5, j + 40, k + 93, Blocks.stone);
        world.setBlock(i + 5, j + 40, k + 94, Blocks.stone);
        world.setBlock(i + 5, j + 40, k + 95, Blocks.stone);
        world.setBlock(i + 5, j + 40, k + 96, Blocks.stone);
        world.setBlock(i + 5, j + 41, k + 66, Blocks.cobblestone);
        world.setBlock(i + 5, j + 41, k + 67, Blocks.cobblestone);
        world.setBlock(i + 5, j + 41, k + 68, Blocks.cobblestone);
        world.setBlock(i + 5, j + 41, k + 69, Blocks.cobblestone);
        world.setBlock(i + 5, j + 41, k + 70, Blocks.cobblestone);
        world.setBlock(i + 5, j + 41, k + 71, Blocks.cobblestone);
        world.setBlock(i + 5, j + 41, k + 72, Blocks.cobblestone);
        world.setBlock(i + 5, j + 41, k + 73, Blocks.stone);
        world.setBlock(i + 5, j + 41, k + 74, Blocks.stone);
        world.setBlock(i + 5, j + 41, k + 75, Blocks.stone);
        world.setBlock(i + 5, j + 41, k + 76, Blocks.stone);
        world.setBlock(i + 5, j + 41, k + 77, Blocks.stone);
        world.setBlock(i + 5, j + 41, k + 78, Blocks.stone);
        world.setBlock(i + 5, j + 41, k + 79, Blocks.stone);
        world.setBlock(i + 5, j + 41, k + 80, Blocks.stone);
        world.setBlock(i + 5, j + 41, k + 81, Blocks.stone);
        world.setBlock(i + 5, j + 41, k + 82, Blocks.stone);
        world.setBlock(i + 5, j + 41, k + 83, Blocks.stone);
        world.setBlock(i + 5, j + 41, k + 84, Blocks.stone);
        world.setBlock(i + 5, j + 41, k + 85, Blocks.stone);
        world.setBlock(i + 5, j + 41, k + 86, Blocks.stone);
        world.setBlock(i + 5, j + 41, k + 87, Blocks.stone);
        world.setBlock(i + 5, j + 41, k + 88, Blocks.stone);
        world.setBlock(i + 5, j + 41, k + 89, Blocks.stone);
        world.setBlock(i + 5, j + 41, k + 90, Blocks.stone);
        world.setBlock(i + 5, j + 41, k + 91, Blocks.stone);
        world.setBlock(i + 5, j + 41, k + 92, Blocks.stone);
        world.setBlock(i + 5, j + 41, k + 93, Blocks.stone);
        world.setBlock(i + 5, j + 41, k + 94, Blocks.stone);
        world.setBlock(i + 5, j + 41, k + 95, Blocks.stone);
        world.setBlock(i + 5, j + 41, k + 96, Blocks.stone);
        world.setBlock(i + 5, j + 42, k + 66, Blocks.iron_ore);
        world.setBlock(i + 5, j + 42, k + 67, Blocks.iron_ore);
        world.setBlock(i + 5, j + 42, k + 68, Blocks.iron_ore);
        world.setBlock(i + 5, j + 42, k + 69, Blocks.iron_ore);
        world.setBlock(i + 5, j + 42, k + 70, Blocks.iron_ore);
        world.setBlock(i + 5, j + 42, k + 71, Blocks.iron_ore);
        world.setBlock(i + 5, j + 42, k + 72, Blocks.iron_ore);
        world.setBlock(i + 5, j + 42, k + 73, Blocks.stone);
        world.setBlock(i + 5, j + 42, k + 74, Blocks.stone);
        world.setBlock(i + 5, j + 42, k + 75, Blocks.stone);
        world.setBlock(i + 5, j + 42, k + 76, Blocks.stone);
        world.setBlock(i + 5, j + 42, k + 77, Blocks.stone);
        world.setBlock(i + 5, j + 42, k + 78, Blocks.stone);
        world.setBlock(i + 5, j + 42, k + 79, Blocks.stone);
        world.setBlock(i + 5, j + 42, k + 80, Blocks.stone);
        world.setBlock(i + 5, j + 42, k + 81, Blocks.stone);
        world.setBlock(i + 5, j + 42, k + 82, Blocks.stone);
        world.setBlock(i + 5, j + 42, k + 83, Blocks.stone);
        world.setBlock(i + 5, j + 42, k + 84, Blocks.stone);
        world.setBlock(i + 5, j + 42, k + 85, Blocks.stone);
        world.setBlock(i + 5, j + 42, k + 86, Blocks.stone);
        world.setBlock(i + 5, j + 42, k + 87, Blocks.stone);
        world.setBlock(i + 5, j + 42, k + 88, Blocks.stone);
        world.setBlock(i + 5, j + 42, k + 89, Blocks.stone);
        world.setBlock(i + 5, j + 42, k + 90, Blocks.stone);
        world.setBlock(i + 5, j + 42, k + 91, Blocks.stone);
        world.setBlock(i + 5, j + 42, k + 92, Blocks.stone);
        world.setBlock(i + 5, j + 42, k + 93, Blocks.stone);
        world.setBlock(i + 5, j + 42, k + 94, Blocks.stone);
        world.setBlock(i + 5, j + 42, k + 95, Blocks.stone);
        world.setBlock(i + 5, j + 43, k + 73, Blocks.stone);
        world.setBlock(i + 5, j + 43, k + 74, Blocks.stone);
        world.setBlock(i + 5, j + 43, k + 75, Blocks.stone);
        world.setBlock(i + 5, j + 43, k + 76, Blocks.stone);
        world.setBlock(i + 5, j + 43, k + 77, Blocks.stone);
        world.setBlock(i + 5, j + 43, k + 78, Blocks.stone);
        world.setBlock(i + 5, j + 43, k + 79, Blocks.stone);
        world.setBlock(i + 5, j + 43, k + 80, Blocks.stone);
        world.setBlock(i + 5, j + 43, k + 81, Blocks.stone);
        world.setBlock(i + 5, j + 43, k + 82, Blocks.stone);
        world.setBlock(i + 5, j + 43, k + 83, Blocks.stone);
        world.setBlock(i + 5, j + 43, k + 84, Blocks.stone);
        world.setBlock(i + 5, j + 44, k + 73, Blocks.stone);
        world.setBlock(i + 5, j + 44, k + 74, Blocks.stone);
        world.setBlock(i + 5, j + 44, k + 75, Blocks.stone);
        world.setBlock(i + 5, j + 44, k + 76, Blocks.stone);
        world.setBlock(i + 5, j + 44, k + 77, Blocks.stone);
        world.setBlock(i + 5, j + 44, k + 78, Blocks.stone);
        world.setBlock(i + 5, j + 44, k + 79, Blocks.stone);
        world.setBlock(i + 5, j + 44, k + 80, Blocks.stone);
        world.setBlock(i + 5, j + 45, k + 73, Blocks.stone);
        world.setBlock(i + 5, j + 45, k + 74, Blocks.stone);
        world.setBlock(i + 5, j + 45, k + 75, Blocks.stone);
        world.setBlock(i + 5, j + 45, k + 76, Blocks.stone);
        world.setBlock(i + 5, j + 45, k + 77, Blocks.stone);
        world.setBlock(i + 5, j + 45, k + 78, Blocks.stone);
        world.setBlock(i + 5, j + 46, k + 74, Blocks.stone);
        world.setBlock(i + 5, j + 46, k + 75, Blocks.stone);
        world.setBlock(i + 5, j + 46, k + 76, Blocks.stone);
        world.setBlock(i + 5, j + 46, k + 77, Blocks.stone);
        world.setBlock(i + 5, j + 47, k + 75, Blocks.stone);
        world.setBlock(i + 5, j + 47, k + 76, Blocks.stone);
        world.setBlock(i + 6, j + 32, k + 82, Blocks.stone);
        world.setBlock(i + 6, j + 32, k + 83, Blocks.stone);
        world.setBlock(i + 6, j + 32, k + 84, Blocks.stone);
        world.setBlock(i + 6, j + 33, k + 81, Blocks.stone);
        world.setBlock(i + 6, j + 33, k + 82, Blocks.stone);
        world.setBlock(i + 6, j + 33, k + 83, Blocks.stone);
        world.setBlock(i + 6, j + 33, k + 84, Blocks.stone);
        world.setBlock(i + 6, j + 33, k + 85, Blocks.stone);
        world.setBlock(i + 6, j + 34, k + 79, Blocks.stone);
        world.setBlock(i + 6, j + 34, k + 80, Blocks.stone);
        world.setBlock(i + 6, j + 34, k + 81, Blocks.stone);
        world.setBlock(i + 6, j + 34, k + 82, Blocks.stone);
        world.setBlock(i + 6, j + 34, k + 83, Blocks.stone);
        world.setBlock(i + 6, j + 34, k + 84, Blocks.stone);
        world.setBlock(i + 6, j + 34, k + 85, Blocks.stone);
        world.setBlock(i + 6, j + 34, k + 86, Blocks.stone);
        world.setBlock(i + 6, j + 35, k + 78, Blocks.stone);
        world.setBlock(i + 6, j + 35, k + 79, Blocks.stone);
        world.setBlock(i + 6, j + 35, k + 80, Blocks.stone);
        world.setBlock(i + 6, j + 35, k + 81, Blocks.stone);
        world.setBlock(i + 6, j + 35, k + 82, Blocks.stone);
        world.setBlock(i + 6, j + 35, k + 83, Blocks.stone);
        world.setBlock(i + 6, j + 35, k + 84, Blocks.stone);
        world.setBlock(i + 6, j + 35, k + 85, Blocks.stone);
        world.setBlock(i + 6, j + 35, k + 86, Blocks.stone);
        world.setBlock(i + 6, j + 36, k + 75, Blocks.stone);
        world.setBlock(i + 6, j + 36, k + 76, Blocks.stone);
        world.setBlock(i + 6, j + 36, k + 77, Blocks.stone);
        world.setBlock(i + 6, j + 36, k + 78, Blocks.stone);
        world.setBlock(i + 6, j + 36, k + 79, Blocks.stone);
        world.setBlock(i + 6, j + 36, k + 80, Blocks.stone);
        world.setBlock(i + 6, j + 36, k + 81, Blocks.stone);
        world.setBlock(i + 6, j + 36, k + 82, Blocks.stone);
        world.setBlock(i + 6, j + 36, k + 83, Blocks.stone);
        world.setBlock(i + 6, j + 36, k + 84, Blocks.stone);
        world.setBlock(i + 6, j + 36, k + 85, Blocks.stone);
        world.setBlock(i + 6, j + 36, k + 86, Blocks.stone);
        world.setBlock(i + 6, j + 36, k + 87, Blocks.stone);
        world.setBlock(i + 6, j + 36, k + 88, Blocks.stone);
        world.setBlock(i + 6, j + 36, k + 89, Blocks.stone);
        world.setBlock(i + 6, j + 36, k + 90, Blocks.stone);
        world.setBlock(i + 6, j + 36, k + 91, Blocks.stone);
        world.setBlock(i + 6, j + 36, k + 92, Blocks.stone);
        world.setBlock(i + 6, j + 36, k + 93, Blocks.stone);
        world.setBlock(i + 6, j + 37, k + 74, Blocks.stone);
        world.setBlock(i + 6, j + 37, k + 75, Blocks.stone);
        world.setBlock(i + 6, j + 37, k + 76, Blocks.stone);
        world.setBlock(i + 6, j + 37, k + 77, Blocks.stone);
        world.setBlock(i + 6, j + 37, k + 78, Blocks.stone);
        world.setBlock(i + 6, j + 37, k + 79, Blocks.stone);
        world.setBlock(i + 6, j + 37, k + 80, Blocks.stone);
        world.setBlock(i + 6, j + 37, k + 81, Blocks.stone);
        world.setBlock(i + 6, j + 37, k + 82, Blocks.stone);
        world.setBlock(i + 6, j + 37, k + 83, Blocks.stone);
        world.setBlock(i + 6, j + 37, k + 84, Blocks.stone);
        world.setBlock(i + 6, j + 37, k + 85, Blocks.stone);
        world.setBlock(i + 6, j + 37, k + 86, Blocks.stone);
        world.setBlock(i + 6, j + 37, k + 87, Blocks.stone);
        world.setBlock(i + 6, j + 37, k + 88, Blocks.stone);
        world.setBlock(i + 6, j + 37, k + 89, Blocks.stone);
        world.setBlock(i + 6, j + 37, k + 90, Blocks.stone);
        world.setBlock(i + 6, j + 37, k + 91, Blocks.stone);
        world.setBlock(i + 6, j + 37, k + 92, Blocks.stone);
        world.setBlock(i + 6, j + 37, k + 93, Blocks.stone);
        world.setBlock(i + 6, j + 37, k + 94, Blocks.stone);
        world.setBlock(i + 6, j + 37, k + 95, Blocks.stone);
        world.setBlock(i + 6, j + 38, k + 74, Blocks.stone);
        world.setBlock(i + 6, j + 38, k + 75, Blocks.stone);
        world.setBlock(i + 6, j + 38, k + 76, Blocks.stone);
        world.setBlock(i + 6, j + 38, k + 77, Blocks.stone);
        world.setBlock(i + 6, j + 38, k + 78, Blocks.stone);
        world.setBlock(i + 6, j + 38, k + 79, Blocks.stone);
        world.setBlock(i + 6, j + 38, k + 80, Blocks.stone);
        world.setBlock(i + 6, j + 38, k + 81, Blocks.stone);
        world.setBlock(i + 6, j + 38, k + 82, Blocks.stone);
        world.setBlock(i + 6, j + 38, k + 83, Blocks.stone);
        world.setBlock(i + 6, j + 38, k + 84, Blocks.stone);
        world.setBlock(i + 6, j + 38, k + 85, Blocks.stone);
        world.setBlock(i + 6, j + 38, k + 86, Blocks.stone);
        world.setBlock(i + 6, j + 38, k + 87, Blocks.stone);
        world.setBlock(i + 6, j + 38, k + 88, Blocks.stone);
        world.setBlock(i + 6, j + 38, k + 89, Blocks.stone);
        world.setBlock(i + 6, j + 38, k + 90, Blocks.stone);
        world.setBlock(i + 6, j + 38, k + 91, Blocks.stone);
        world.setBlock(i + 6, j + 38, k + 92, Blocks.stone);
        world.setBlock(i + 6, j + 38, k + 93, Blocks.stone);
        world.setBlock(i + 6, j + 38, k + 94, Blocks.stone);
        world.setBlock(i + 6, j + 38, k + 95, Blocks.stone);
        world.setBlock(i + 6, j + 39, k + 73, Blocks.stone);
        world.setBlock(i + 6, j + 39, k + 74, Blocks.stone);
        world.setBlock(i + 6, j + 39, k + 75, Blocks.stone);
        world.setBlock(i + 6, j + 39, k + 76, Blocks.stone);
        world.setBlock(i + 6, j + 39, k + 77, Blocks.stone);
        world.setBlock(i + 6, j + 39, k + 78, Blocks.stone);
        world.setBlock(i + 6, j + 39, k + 79, Blocks.stone);
        world.setBlock(i + 6, j + 39, k + 80, Blocks.stone);
        world.setBlock(i + 6, j + 39, k + 81, Blocks.stone);
        world.setBlock(i + 6, j + 39, k + 82, Blocks.stone);
        world.setBlock(i + 6, j + 39, k + 83, Blocks.stone);
        world.setBlock(i + 6, j + 39, k + 84, Blocks.stone);
        world.setBlock(i + 6, j + 39, k + 85, Blocks.stone);
        world.setBlock(i + 6, j + 39, k + 86, Blocks.stone);
        world.setBlock(i + 6, j + 39, k + 87, Blocks.stone);
        world.setBlock(i + 6, j + 39, k + 88, Blocks.stone);
        world.setBlock(i + 6, j + 39, k + 89, Blocks.stone);
        world.setBlock(i + 6, j + 39, k + 90, Blocks.stone);
        world.setBlock(i + 6, j + 39, k + 91, Blocks.stone);
        world.setBlock(i + 6, j + 39, k + 92, Blocks.stone);
        world.setBlock(i + 6, j + 39, k + 93, Blocks.stone);
        world.setBlock(i + 6, j + 39, k + 94, Blocks.stone);
        world.setBlock(i + 6, j + 39, k + 95, Blocks.stone);
        world.setBlock(i + 6, j + 39, k + 96, Blocks.stone);
        world.setBlock(i + 6, j + 40, k + 66, Blocks.cobblestone);
        world.setBlock(i + 6, j + 40, k + 67, Blocks.cobblestone);
        world.setBlock(i + 6, j + 40, k + 68, Blocks.cobblestone);
        world.setBlock(i + 6, j + 40, k + 69, Blocks.cobblestone);
        world.setBlock(i + 6, j + 40, k + 70, Blocks.cobblestone);
        world.setBlock(i + 6, j + 40, k + 71, Blocks.cobblestone);
        world.setBlock(i + 6, j + 40, k + 73, Blocks.stone);
        world.setBlock(i + 6, j + 40, k + 74, Blocks.stone);
        world.setBlock(i + 6, j + 40, k + 75, Blocks.stone);
        world.setBlock(i + 6, j + 40, k + 76, Blocks.stone);
        world.setBlock(i + 6, j + 40, k + 77, Blocks.stone);
        world.setBlock(i + 6, j + 40, k + 78, Blocks.stone);
        world.setBlock(i + 6, j + 40, k + 79, Blocks.stone);
        world.setBlock(i + 6, j + 40, k + 80, Blocks.stone);
        world.setBlock(i + 6, j + 40, k + 81, Blocks.stone);
        world.setBlock(i + 6, j + 40, k + 82, Blocks.stone);
        world.setBlock(i + 6, j + 40, k + 83, Blocks.stone);
        world.setBlock(i + 6, j + 40, k + 84, Blocks.stone);
        world.setBlock(i + 6, j + 40, k + 85, Blocks.stone);
        world.setBlock(i + 6, j + 40, k + 86, Blocks.stone);
        world.setBlock(i + 6, j + 40, k + 87, Blocks.stone);
        world.setBlock(i + 6, j + 40, k + 88, Blocks.stone);
        world.setBlock(i + 6, j + 40, k + 89, Blocks.stone);
        world.setBlock(i + 6, j + 40, k + 90, Blocks.stone);
        world.setBlock(i + 6, j + 40, k + 91, Blocks.stone);
        world.setBlock(i + 6, j + 40, k + 92, Blocks.stone);
        world.setBlock(i + 6, j + 40, k + 93, Blocks.stone);
        world.setBlock(i + 6, j + 40, k + 94, Blocks.stone);
        world.setBlock(i + 6, j + 40, k + 95, Blocks.stone);
        world.setBlock(i + 6, j + 40, k + 96, Blocks.stone);
        world.setBlock(i + 6, j + 41, k + 66, Blocks.cobblestone);
        world.setBlock(i + 6, j + 41, k + 67, Blocks.cobblestone);
        world.setBlock(i + 6, j + 41, k + 68, Blocks.cobblestone);
        world.setBlock(i + 6, j + 41, k + 69, Blocks.cobblestone);
        world.setBlock(i + 6, j + 41, k + 70, Blocks.cobblestone);
        world.setBlock(i + 6, j + 41, k + 71, Blocks.cobblestone);
        world.setBlock(i + 6, j + 41, k + 73, Blocks.stone);
        world.setBlock(i + 6, j + 41, k + 74, Blocks.stone);
        world.setBlock(i + 6, j + 41, k + 75, Blocks.stone);
        world.setBlock(i + 6, j + 41, k + 76, Blocks.stone);
        world.setBlock(i + 6, j + 41, k + 77, Blocks.stone);
        world.setBlock(i + 6, j + 41, k + 78, Blocks.stone);
        world.setBlock(i + 6, j + 41, k + 79, Blocks.stone);
        world.setBlock(i + 6, j + 41, k + 80, Blocks.stone);
        world.setBlock(i + 6, j + 41, k + 81, Blocks.stone);
        world.setBlock(i + 6, j + 41, k + 82, Blocks.stone);
        world.setBlock(i + 6, j + 41, k + 83, Blocks.stone);
        world.setBlock(i + 6, j + 41, k + 84, Blocks.stone);
        world.setBlock(i + 6, j + 41, k + 85, Blocks.stone);
        world.setBlock(i + 6, j + 41, k + 86, Blocks.stone);
        world.setBlock(i + 6, j + 41, k + 87, Blocks.stone);
        world.setBlock(i + 6, j + 41, k + 88, Blocks.stone);
        world.setBlock(i + 6, j + 41, k + 89, Blocks.stone);
        world.setBlock(i + 6, j + 41, k + 90, Blocks.stone);
        world.setBlock(i + 6, j + 41, k + 91, Blocks.stone);
        world.setBlock(i + 6, j + 41, k + 92, Blocks.stone);
        world.setBlock(i + 6, j + 41, k + 93, Blocks.stone);
        world.setBlock(i + 6, j + 41, k + 94, Blocks.stone);
        world.setBlock(i + 6, j + 41, k + 95, Blocks.stone);
        world.setBlock(i + 6, j + 41, k + 96, Blocks.stone);
        world.setBlock(i + 6, j + 42, k + 66, Blocks.iron_ore);
        world.setBlock(i + 6, j + 42, k + 67, Blocks.iron_ore);
        world.setBlock(i + 6, j + 42, k + 68, Blocks.iron_ore);
        world.setBlock(i + 6, j + 42, k + 69, Blocks.iron_ore);
        world.setBlock(i + 6, j + 42, k + 70, Blocks.iron_ore);
        world.setBlock(i + 6, j + 42, k + 71, Blocks.iron_ore);
        world.setBlock(i + 6, j + 42, k + 72, Blocks.stone);
        world.setBlock(i + 6, j + 42, k + 73, Blocks.stone);
        world.setBlock(i + 6, j + 42, k + 74, Blocks.stone);
        world.setBlock(i + 6, j + 42, k + 75, Blocks.stone);
        world.setBlock(i + 6, j + 42, k + 76, Blocks.stone);
        world.setBlock(i + 6, j + 42, k + 77, Blocks.stone);
        world.setBlock(i + 6, j + 42, k + 78, Blocks.stone);
        world.setBlock(i + 6, j + 42, k + 79, Blocks.stone);
        world.setBlock(i + 6, j + 42, k + 80, Blocks.stone);
        world.setBlock(i + 6, j + 42, k + 81, Blocks.stone);
        world.setBlock(i + 6, j + 42, k + 82, Blocks.stone);
        world.setBlock(i + 6, j + 42, k + 83, Blocks.stone);
        world.setBlock(i + 6, j + 42, k + 84, Blocks.stone);
        world.setBlock(i + 6, j + 42, k + 85, Blocks.stone);
        world.setBlock(i + 6, j + 42, k + 86, Blocks.stone);
        world.setBlock(i + 6, j + 42, k + 87, Blocks.stone);
        world.setBlock(i + 6, j + 42, k + 88, Blocks.stone);
        world.setBlock(i + 6, j + 42, k + 89, Blocks.stone);
        world.setBlock(i + 6, j + 42, k + 90, Blocks.stone);
        world.setBlock(i + 6, j + 42, k + 91, Blocks.stone);
        world.setBlock(i + 6, j + 42, k + 92, Blocks.stone);
        world.setBlock(i + 6, j + 42, k + 93, Blocks.stone);
        world.setBlock(i + 6, j + 42, k + 94, Blocks.stone);
        world.setBlock(i + 6, j + 42, k + 95, Blocks.stone);
        world.setBlock(i + 6, j + 43, k + 72, Blocks.stone);
        world.setBlock(i + 6, j + 43, k + 73, Blocks.stone);
        world.setBlock(i + 6, j + 43, k + 74, Blocks.stone);
        world.setBlock(i + 6, j + 43, k + 75, Blocks.stone);
        world.setBlock(i + 6, j + 43, k + 76, Blocks.stone);
        world.setBlock(i + 6, j + 43, k + 77, Blocks.stone);
        world.setBlock(i + 6, j + 43, k + 78, Blocks.stone);
        world.setBlock(i + 6, j + 43, k + 79, Blocks.stone);
        world.setBlock(i + 6, j + 43, k + 80, Blocks.stone);
        world.setBlock(i + 6, j + 43, k + 81, Blocks.stone);
        world.setBlock(i + 6, j + 43, k + 82, Blocks.stone);
        world.setBlock(i + 6, j + 43, k + 83, Blocks.stone);
        world.setBlock(i + 6, j + 43, k + 84, Blocks.stone);
        world.setBlock(i + 6, j + 43, k + 85, Blocks.stone);
        world.setBlock(i + 6, j + 43, k + 86, Blocks.stone);
        world.setBlock(i + 6, j + 43, k + 92, Blocks.stone);
        world.setBlock(i + 6, j + 43, k + 93, Blocks.stone);
        world.setBlock(i + 6, j + 44, k + 72, Blocks.stone);
        world.setBlock(i + 6, j + 44, k + 73, Blocks.stone);
        world.setBlock(i + 6, j + 44, k + 74, Blocks.stone);
        world.setBlock(i + 6, j + 44, k + 75, Blocks.stone);
        world.setBlock(i + 6, j + 44, k + 76, Blocks.stone);
        world.setBlock(i + 6, j + 44, k + 77, Blocks.stone);
        world.setBlock(i + 6, j + 44, k + 78, Blocks.stone);
        world.setBlock(i + 6, j + 44, k + 79, Blocks.stone);
        world.setBlock(i + 6, j + 44, k + 80, Blocks.stone);
        world.setBlock(i + 6, j + 44, k + 81, Blocks.stone);
        world.setBlock(i + 6, j + 45, k + 72, Blocks.stone);
        world.setBlock(i + 6, j + 45, k + 73, Blocks.stone);
        world.setBlock(i + 6, j + 45, k + 74, Blocks.stone);
        world.setBlock(i + 6, j + 45, k + 75, Blocks.stone);
        world.setBlock(i + 6, j + 45, k + 76, Blocks.stone);
        world.setBlock(i + 6, j + 45, k + 77, Blocks.stone);
        world.setBlock(i + 6, j + 45, k + 78, Blocks.stone);
        world.setBlock(i + 6, j + 46, k + 73, Blocks.stone);
        world.setBlock(i + 6, j + 46, k + 74, Blocks.stone);
        world.setBlock(i + 6, j + 46, k + 75, Blocks.stone);
        world.setBlock(i + 6, j + 46, k + 76, Blocks.stone);
        world.setBlock(i + 6, j + 46, k + 77, Blocks.stone);
        world.setBlock(i + 6, j + 47, k + 75, Blocks.stone);
        world.setBlock(i + 6, j + 47, k + 76, Blocks.stone);
        world.setBlock(i + 6, j + 47, k + 77, Blocks.stone);
        world.setBlock(i + 6, j + 48, k + 76, Blocks.stone);
        world.setBlock(i + 6, j + 48, k + 77, Blocks.stone);
        world.setBlock(i + 6, j + 49, k + 77, Blocks.stone);
        world.setBlock(i + 6, j + 50, k + 77, Blocks.stone);
        world.setBlock(i + 7, j + 28, k + 84, Blocks.stone);
        world.setBlock(i + 7, j + 29, k + 83, Blocks.stone);
        world.setBlock(i + 7, j + 29, k + 84, Blocks.stone);
        world.setBlock(i + 7, j + 30, k + 83, Blocks.stone);
        world.setBlock(i + 7, j + 30, k + 84, Blocks.stone);
        world.setBlock(i + 7, j + 30, k + 85, Blocks.stone);
        world.setBlock(i + 7, j + 31, k + 82, Blocks.stone);
        world.setBlock(i + 7, j + 31, k + 83, Blocks.stone);
        world.setBlock(i + 7, j + 31, k + 84, Blocks.stone);
        world.setBlock(i + 7, j + 31, k + 85, Blocks.stone);
        world.setBlock(i + 7, j + 32, k + 82, Blocks.stone);
        world.setBlock(i + 7, j + 32, k + 83, Blocks.stone);
        world.setBlock(i + 7, j + 32, k + 84, Blocks.stone);
        world.setBlock(i + 7, j + 32, k + 85, Blocks.stone);
        world.setBlock(i + 7, j + 33, k + 80, Blocks.stone);
        world.setBlock(i + 7, j + 33, k + 81, Blocks.stone);
        world.setBlock(i + 7, j + 33, k + 82, Blocks.stone);
        world.setBlock(i + 7, j + 33, k + 83, Blocks.stone);
        world.setBlock(i + 7, j + 33, k + 84, Blocks.stone);
        world.setBlock(i + 7, j + 33, k + 85, Blocks.stone);
        world.setBlock(i + 7, j + 34, k + 79, Blocks.stone);
        world.setBlock(i + 7, j + 34, k + 80, Blocks.stone);
        world.setBlock(i + 7, j + 34, k + 81, Blocks.stone);
        world.setBlock(i + 7, j + 34, k + 82, Blocks.stone);
        world.setBlock(i + 7, j + 34, k + 83, Blocks.stone);
        world.setBlock(i + 7, j + 34, k + 84, Blocks.stone);
        world.setBlock(i + 7, j + 34, k + 85, Blocks.stone);
        world.setBlock(i + 7, j + 34, k + 86, Blocks.stone);
        world.setBlock(i + 7, j + 34, k + 87, Blocks.stone);
        world.setBlock(i + 7, j + 35, k + 78, Blocks.stone);
        world.setBlock(i + 7, j + 35, k + 79, Blocks.stone);
        world.setBlock(i + 7, j + 35, k + 80, Blocks.stone);
        world.setBlock(i + 7, j + 35, k + 81, Blocks.stone);
        world.setBlock(i + 7, j + 35, k + 82, Blocks.stone);
        world.setBlock(i + 7, j + 35, k + 83, Blocks.stone);
        world.setBlock(i + 7, j + 35, k + 84, Blocks.stone);
        world.setBlock(i + 7, j + 35, k + 85, Blocks.stone);
        this.generate2(world, rand, i, j, k);
        return true;
    }
    
    public boolean generate2(final World world, final Random rand, final int i, final int j, final int k) {
        world.setBlock(i + 7, j + 35, k + 86, Blocks.stone);
        world.setBlock(i + 7, j + 35, k + 87, Blocks.stone);
        world.setBlock(i + 7, j + 35, k + 88, Blocks.stone);
        world.setBlock(i + 7, j + 36, k + 76, Blocks.stone);
        world.setBlock(i + 7, j + 36, k + 77, Blocks.stone);
        world.setBlock(i + 7, j + 36, k + 78, Blocks.stone);
        world.setBlock(i + 7, j + 36, k + 79, Blocks.stone);
        world.setBlock(i + 7, j + 36, k + 80, Blocks.stone);
        world.setBlock(i + 7, j + 36, k + 81, Blocks.stone);
        world.setBlock(i + 7, j + 36, k + 82, Blocks.stone);
        world.setBlock(i + 7, j + 36, k + 83, Blocks.stone);
        world.setBlock(i + 7, j + 36, k + 84, Blocks.stone);
        world.setBlock(i + 7, j + 36, k + 85, Blocks.stone);
        world.setBlock(i + 7, j + 36, k + 86, Blocks.stone);
        world.setBlock(i + 7, j + 36, k + 87, Blocks.stone);
        world.setBlock(i + 7, j + 36, k + 88, Blocks.stone);
        world.setBlock(i + 7, j + 36, k + 89, Blocks.stone);
        world.setBlock(i + 7, j + 36, k + 90, Blocks.stone);
        world.setBlock(i + 7, j + 36, k + 91, Blocks.stone);
        world.setBlock(i + 7, j + 36, k + 92, Blocks.stone);
        world.setBlock(i + 7, j + 37, k + 75, Blocks.stone);
        world.setBlock(i + 7, j + 37, k + 76, Blocks.stone);
        world.setBlock(i + 7, j + 37, k + 77, Blocks.stone);
        world.setBlock(i + 7, j + 37, k + 78, Blocks.stone);
        world.setBlock(i + 7, j + 37, k + 79, Blocks.stone);
        world.setBlock(i + 7, j + 37, k + 80, Blocks.stone);
        world.setBlock(i + 7, j + 37, k + 81, Blocks.stone);
        world.setBlock(i + 7, j + 37, k + 82, Blocks.stone);
        world.setBlock(i + 7, j + 37, k + 83, Blocks.stone);
        world.setBlock(i + 7, j + 37, k + 84, Blocks.stone);
        world.setBlock(i + 7, j + 37, k + 85, Blocks.stone);
        world.setBlock(i + 7, j + 37, k + 86, Blocks.stone);
        world.setBlock(i + 7, j + 37, k + 87, Blocks.stone);
        world.setBlock(i + 7, j + 37, k + 88, Blocks.stone);
        world.setBlock(i + 7, j + 37, k + 89, Blocks.stone);
        world.setBlock(i + 7, j + 37, k + 90, Blocks.stone);
        world.setBlock(i + 7, j + 37, k + 91, Blocks.stone);
        world.setBlock(i + 7, j + 37, k + 92, Blocks.stone);
        world.setBlock(i + 7, j + 37, k + 93, Blocks.stone);
        world.setBlock(i + 7, j + 37, k + 94, Blocks.stone);
        world.setBlock(i + 7, j + 38, k + 74, Blocks.stone);
        world.setBlock(i + 7, j + 38, k + 75, Blocks.stone);
        world.setBlock(i + 7, j + 38, k + 76, Blocks.stone);
        world.setBlock(i + 7, j + 38, k + 77, Blocks.stone);
        world.setBlock(i + 7, j + 38, k + 78, Blocks.stone);
        world.setBlock(i + 7, j + 38, k + 79, Blocks.stone);
        world.setBlock(i + 7, j + 38, k + 80, Blocks.stone);
        world.setBlock(i + 7, j + 38, k + 81, Blocks.stone);
        world.setBlock(i + 7, j + 38, k + 82, Blocks.stone);
        world.setBlock(i + 7, j + 38, k + 83, Blocks.stone);
        world.setBlock(i + 7, j + 38, k + 84, Blocks.stone);
        world.setBlock(i + 7, j + 38, k + 85, Blocks.stone);
        world.setBlock(i + 7, j + 38, k + 86, Blocks.stone);
        world.setBlock(i + 7, j + 38, k + 87, Blocks.stone);
        world.setBlock(i + 7, j + 38, k + 88, Blocks.stone);
        world.setBlock(i + 7, j + 38, k + 89, Blocks.stone);
        world.setBlock(i + 7, j + 38, k + 90, Blocks.stone);
        world.setBlock(i + 7, j + 38, k + 91, Blocks.stone);
        world.setBlock(i + 7, j + 38, k + 92, Blocks.stone);
        world.setBlock(i + 7, j + 38, k + 93, Blocks.stone);
        world.setBlock(i + 7, j + 38, k + 94, Blocks.stone);
        world.setBlock(i + 7, j + 38, k + 95, Blocks.stone);
        world.setBlock(i + 7, j + 39, k + 74, Blocks.stone);
        world.setBlock(i + 7, j + 39, k + 75, Blocks.stone);
        world.setBlock(i + 7, j + 39, k + 76, Blocks.stone);
        world.setBlock(i + 7, j + 39, k + 77, Blocks.stone);
        world.setBlock(i + 7, j + 39, k + 78, Blocks.stone);
        world.setBlock(i + 7, j + 39, k + 79, Blocks.stone);
        world.setBlock(i + 7, j + 39, k + 80, Blocks.stone);
        world.setBlock(i + 7, j + 39, k + 81, Blocks.stone);
        world.setBlock(i + 7, j + 39, k + 82, Blocks.stone);
        world.setBlock(i + 7, j + 39, k + 83, Blocks.stone);
        world.setBlock(i + 7, j + 39, k + 84, Blocks.stone);
        world.setBlock(i + 7, j + 39, k + 85, Blocks.stone);
        world.setBlock(i + 7, j + 39, k + 86, Blocks.stone);
        world.setBlock(i + 7, j + 39, k + 87, Blocks.stone);
        world.setBlock(i + 7, j + 39, k + 88, Blocks.stone);
        world.setBlock(i + 7, j + 39, k + 89, Blocks.stone);
        world.setBlock(i + 7, j + 39, k + 90, Blocks.stone);
        world.setBlock(i + 7, j + 39, k + 91, Blocks.stone);
        world.setBlock(i + 7, j + 39, k + 92, Blocks.stone);
        world.setBlock(i + 7, j + 39, k + 93, Blocks.stone);
        world.setBlock(i + 7, j + 39, k + 94, Blocks.stone);
        world.setBlock(i + 7, j + 39, k + 95, Blocks.stone);
        world.setBlock(i + 7, j + 40, k + 66, Blocks.cobblestone);
        world.setBlock(i + 7, j + 40, k + 67, Blocks.cobblestone);
        world.setBlock(i + 7, j + 40, k + 68, Blocks.cobblestone);
        world.setBlock(i + 7, j + 40, k + 69, Blocks.cobblestone);
        world.setBlock(i + 7, j + 40, k + 70, Blocks.cobblestone);
        world.setBlock(i + 7, j + 40, k + 71, Blocks.cobblestone);
        world.setBlock(i + 7, j + 40, k + 72, Blocks.stone);
        world.setBlock(i + 7, j + 40, k + 73, Blocks.stone);
        world.setBlock(i + 7, j + 40, k + 74, Blocks.stone);
        world.setBlock(i + 7, j + 40, k + 75, Blocks.stone);
        world.setBlock(i + 7, j + 40, k + 76, Blocks.stone);
        world.setBlock(i + 7, j + 40, k + 77, Blocks.stone);
        world.setBlock(i + 7, j + 40, k + 78, Blocks.stone);
        world.setBlock(i + 7, j + 40, k + 79, Blocks.stone);
        world.setBlock(i + 7, j + 40, k + 80, Blocks.stone);
        world.setBlock(i + 7, j + 40, k + 81, Blocks.stone);
        world.setBlock(i + 7, j + 40, k + 82, Blocks.stone);
        world.setBlock(i + 7, j + 40, k + 83, Blocks.stone);
        world.setBlock(i + 7, j + 40, k + 84, Blocks.stone);
        world.setBlock(i + 7, j + 40, k + 85, Blocks.stone);
        world.setBlock(i + 7, j + 40, k + 86, Blocks.stone);
        world.setBlock(i + 7, j + 40, k + 87, Blocks.stone);
        world.setBlock(i + 7, j + 40, k + 88, Blocks.stone);
        world.setBlock(i + 7, j + 40, k + 89, Blocks.stone);
        world.setBlock(i + 7, j + 40, k + 90, Blocks.stone);
        world.setBlock(i + 7, j + 40, k + 91, Blocks.stone);
        world.setBlock(i + 7, j + 40, k + 92, Blocks.stone);
        world.setBlock(i + 7, j + 40, k + 93, Blocks.stone);
        world.setBlock(i + 7, j + 40, k + 94, Blocks.stone);
        world.setBlock(i + 7, j + 40, k + 95, Blocks.stone);
        world.setBlock(i + 7, j + 41, k + 66, Blocks.cobblestone);
        world.setBlock(i + 7, j + 41, k + 67, Blocks.cobblestone);
        world.setBlock(i + 7, j + 41, k + 68, Blocks.cobblestone);
        world.setBlock(i + 7, j + 41, k + 69, Blocks.cobblestone);
        world.setBlock(i + 7, j + 41, k + 70, Blocks.cobblestone);
        world.setBlock(i + 7, j + 41, k + 71, Blocks.cobblestone);
        world.setBlock(i + 7, j + 41, k + 72, Blocks.stone);
        world.setBlock(i + 7, j + 41, k + 73, Blocks.stone);
