

package com.gibby.dungeon.gen;

import net.minecraft.world.gen.feature.*;
import net.minecraft.world.*;
import java.util.*;
import net.minecraft.init.*;
import net.minecraft.block.*;
import com.gibby.dungeon.*;

public class treefortress extends WorldGenerator
{
    public boolean generate(final World world, final Random rand, final int i, final int j, final int k) {
        if (world.getBlock(i, j, k) != Blocks.grass || world.getBlock(i, j + 1, k) != Blocks.air) {
            return false;
        }
        world.setBlock(i, j + 5, k + 4, (Block)Blocks.leaves, 12, 0);
        world.setBlock(i, j + 5, k + 5, (Block)Blocks.leaves);
        world.setBlock(i, j + 5, k + 6, (Block)Blocks.leaves);
        world.setBlock(i, j + 6, k + 3, (Block)Blocks.leaves, 4, 0);
        world.setBlock(i, j + 6, k + 4, (Block)Blocks.leaves, 12, 0);
        world.setBlock(i, j + 6, k + 5, (Block)Blocks.leaves, 12, 0);
        world.setBlock(i, j + 6, k + 6, (Block)Blocks.leaves, 12, 0);
        world.setBlock(i, j + 7, k + 3, (Block)Blocks.leaves, 4, 0);
        world.setBlock(i, j + 7, k + 4, (Block)Blocks.leaves, 12, 0);
        world.setBlock(i, j + 7, k + 5, (Block)Blocks.leaves, 12, 0);
        world.setBlock(i, j + 7, k + 6, (Block)Blocks.leaves, 12, 0);
        world.setBlock(i + 1, j + 4, k + 2, (Block)Blocks.leaves);
        world.setBlock(i + 1, j + 4, k + 3, (Block)Blocks.leaves);
        world.setBlock(i + 1, j + 4, k + 4, (Block)Blocks.leaves);
        world.setBlock(i + 1, j + 4, k + 5, (Block)Blocks.leaves);
        world.setBlock(i + 1, j + 4, k + 6, (Block)Blocks.leaves);
        world.setBlock(i + 1, j + 5, k + 1, (Block)Blocks.leaves, 12, 0);
        world.setBlock(i + 1, j + 5, k + 2, (Block)Blocks.leaves);
        world.setBlock(i + 1, j + 5, k + 3, (Block)Blocks.leaves);
        world.setBlock(i + 1, j + 5, k + 4, (Block)Blocks.leaves);
        world.setBlock(i + 1, j + 5, k + 5, (Block)Blocks.leaves);
        world.setBlock(i + 1, j + 5, k + 6, (Block)Blocks.leaves);
        world.setBlock(i + 1, j + 5, k + 7, (Block)Blocks.leaves);
        world.setBlock(i + 1, j + 6, k + 1, (Block)Blocks.leaves, 4, 0);
        world.setBlock(i + 1, j + 6, k + 2, (Block)Blocks.leaves, 12, 0);
        world.setBlock(i + 1, j + 6, k + 3, (Block)Blocks.leaves);
        world.setBlock(i + 1, j + 6, k + 4, (Block)Blocks.leaves, 12, 0);
        world.setBlock(i + 1, j + 6, k + 5, (Block)Blocks.leaves);
        world.setBlock(i + 1, j + 6, k + 6, (Block)Blocks.leaves);
        world.setBlock(i + 1, j + 6, k + 7, (Block)Blocks.leaves, 12, 0);
        world.setBlock(i + 1, j + 7, k + 1, (Block)Blocks.leaves, 4, 0);
        world.setBlock(i + 1, j + 7, k + 2, (Block)Blocks.leaves, 4, 0);
        world.setBlock(i + 1, j + 7, k + 3, (Block)Blocks.leaves, 12, 0);
        world.setBlock(i + 1, j + 7, k + 4, (Block)Blocks.leaves, 12, 0);
        world.setBlock(i + 1, j + 7, k + 5, (Block)Blocks.leaves);
        world.setBlock(i + 1, j + 7, k + 7, (Block)Blocks.leaves, 12, 0);
        world.setBlock(i + 1, j + 8, k + 1, (Block)Blocks.leaves, 4, 0);
        world.setBlock(i + 1, j + 8, k + 2, (Block)Blocks.leaves, 4, 0);
        world.setBlock(i + 1, j + 8, k + 3, (Block)Blocks.leaves, 4, 0);
        world.setBlock(i + 1, j + 8, k + 4, (Block)Blocks.leaves, 12, 0);
        world.setBlock(i + 1, j + 8, k + 5, (Block)Blocks.leaves, 12, 0);
        world.setBlock(i + 1, j + 8, k + 6, (Block)Blocks.leaves, 12, 0);
        world.setBlock(i + 1, j + 8, k + 7, (Block)Blocks.leaves, 12, 0);
        world.setBlock(i + 1, j + 9, k + 1, (Block)Blocks.leaves, 4, 0);
        world.setBlock(i + 1, j + 9, k + 2, (Block)Blocks.leaves, 4, 0);
        world.setBlock(i + 1, j + 9, k + 3, (Block)Blocks.leaves, 4, 0);
        world.setBlock(i + 1, j + 9, k + 4, (Block)Blocks.leaves, 12, 0);
        world.setBlock(i + 1, j + 9, k + 5, (Block)Blocks.leaves, 12, 0);
        world.setBlock(i + 1, j + 9, k + 6, (Block)Blocks.leaves, 12, 0);
        world.setBlock(i + 1, j + 9, k + 7, (Block)Blocks.leaves, 12, 0);
        world.setBlock(i + 1, j + 10, k + 1, (Block)Blocks.leaves, 4, 0);
        world.setBlock(i + 1, j + 10, k + 3, (Block)Blocks.leaves, 4, 0);
        world.setBlock(i + 1, j + 10, k + 5, (Block)Blocks.leaves, 12, 0);
        world.setBlock(i + 1, j + 10, k + 7, (Block)Blocks.leaves, 12, 0);
        world.setBlock(i + 2, j + 3, k + 3, (Block)Blocks.leaves);
        world.setBlock(i + 2, j + 4, k + 1, (Block)Blocks.leaves);
        world.setBlock(i + 2, j + 4, k + 2, (Block)Blocks.leaves);
        world.setBlock(i + 2, j + 4, k + 3, (Block)Blocks.leaves);
        world.setBlock(i + 2, j + 4, k + 4, (Block)Blocks.leaves);
        world.setBlock(i + 2, j + 4, k + 5, (Block)Blocks.leaves);
        world.setBlock(i + 2, j + 4, k + 6, (Block)Blocks.leaves);
        world.setBlock(i + 2, j + 4, k + 7, (Block)Blocks.leaves, 4, 0);
        world.setBlock(i + 2, j + 5, k + 1, (Block)Blocks.leaves);
        world.setBlock(i + 2, j + 5, k + 2, (Block)Blocks.leaves);
        world.setBlock(i + 2, j + 5, k + 3, (Block)Blocks.leaves);
        world.setBlock(i + 2, j + 5, k + 4, (Block)Blocks.leaves);
        world.setBlock(i + 2, j + 5, k + 5, (Block)Blocks.leaves);
        world.setBlock(i + 2, j + 5, k + 6, (Block)Blocks.leaves);
        world.setBlock(i + 2, j + 5, k + 7, (Block)Blocks.leaves);
        world.setBlock(i + 2, j + 6, k + 1, (Block)Blocks.leaves);
        world.setBlock(i + 2, j + 6, k + 2, (Block)Blocks.leaves);
        world.setBlock(i + 2, j + 6, k + 3, (Block)Blocks.leaves);
        world.setBlock(i + 2, j + 6, k + 4, (Block)Blocks.leaves);
        world.setBlock(i + 2, j + 6, k + 5, (Block)Blocks.leaves);
        world.setBlock(i + 2, j + 6, k + 6, (Block)Blocks.leaves);
        world.setBlock(i + 2, j + 6, k + 7, (Block)Blocks.leaves);
        world.setBlock(i + 2, j + 6, k + 8, (Block)Blocks.leaves, 12, 0);
        world.setBlock(i + 2, j + 7, k + 1, (Block)Blocks.leaves, 4, 0);
        world.setBlock(i + 2, j + 7, k + 2, (Block)Blocks.leaves, 4, 0);
        world.setBlock(i + 2, j + 7, k + 3, (Block)Blocks.leaves, 12, 0);
        world.setBlock(i + 2, j + 7, k + 4, (Block)Blocks.leaves, 12, 0);
        world.setBlock(i + 2, j + 7, k + 5, (Block)Blocks.leaves);
        world.setBlock(i + 2, j + 7, k + 6, (Block)Blocks.leaves);
        world.setBlock(i + 2, j + 7, k + 7, (Block)Blocks.leaves, 12, 0);
        world.setBlock(i + 2, j + 8, k + 1, (Block)Blocks.leaves, 4, 0);
        world.setBlock(i + 2, j + 8, k + 2, (Block)Blocks.leaves, 4, 0);
        world.setBlock(i + 2, j + 8, k + 3, (Block)Blocks.leaves, 12, 0);
        world.setBlock(i + 2, j + 8, k + 4, (Block)Blocks.leaves, 12, 0);
        world.setBlock(i + 2, j + 8, k + 5, (Block)Blocks.leaves, 12, 0);
        world.setBlock(i + 2, j + 8, k + 6, (Block)Blocks.leaves, 12, 0);
        world.setBlock(i + 2, j + 8, k + 7, (Block)Blocks.leaves, 12, 0);
        world.setBlock(i + 2, j + 9, k + 1, (Block)Blocks.leaves, 4, 0);
        world.setBlock(i + 2, j + 9, k + 7, (Block)Blocks.leaves, 12, 0);
        world.setBlock(i + 3, j + 3, k + 2, (Block)Blocks.leaves);
        world.setBlock(i + 3, j + 3, k + 3, (Block)Blocks.leaves);
        world.setBlock(i + 3, j + 3, k + 5, (Block)Blocks.leaves);
        world.setBlock(i + 3, j + 4, k + 1, (Block)Blocks.leaves);
        world.setBlock(i + 3, j + 4, k + 2, (Block)Blocks.leaves);
        world.setBlock(i + 3, j + 4, k + 3, (Block)Blocks.leaves);
        world.setBlock(i + 3, j + 4, k + 5, (Block)Blocks.leaves);
        world.setBlock(i + 3, j + 4, k + 6, (Block)Blocks.leaves);
        world.setBlock(i + 3, j + 4, k + 7, (Block)Blocks.leaves);
        world.setBlock(i + 3, j + 5, k + 0, (Block)Blocks.leaves);
        world.setBlock(i + 3, j + 5, k + 1, (Block)Blocks.leaves);
        world.setBlock(i + 3, j + 5, k + 2, (Block)Blocks.leaves);
        world.setBlock(i + 3, j + 5, k + 3, (Block)Blocks.leaves);
        world.setBlock(i + 3, j + 5, k + 5, (Block)Blocks.leaves);
        world.setBlock(i + 3, j + 5, k + 6, (Block)Blocks.leaves);
        world.setBlock(i + 3, j + 5, k + 7, (Block)Blocks.leaves);
        world.setBlock(i + 3, j + 5, k + 8, (Block)Blocks.leaves, 4, 0);
        world.setBlock(i + 3, j + 6, k + 0, (Block)Blocks.leaves);
        world.setBlock(i + 3, j + 6, k + 1, (Block)Blocks.leaves);
        world.setBlock(i + 3, j + 6, k + 2, (Block)Blocks.leaves);
        world.setBlock(i + 3, j + 6, k + 3, (Block)Blocks.leaves);
        world.setBlock(i + 3, j + 6, k + 5, (Block)Blocks.leaves);
        world.setBlock(i + 3, j + 6, k + 6, (Block)Blocks.leaves);
        world.setBlock(i + 3, j + 6, k + 7, (Block)Blocks.leaves);
        world.setBlock(i + 3, j + 6, k + 8, (Block)Blocks.leaves);
        world.setBlock(i + 3, j + 7, k + 1, (Block)Blocks.leaves, 12, 0);
        world.setBlock(i + 3, j + 7, k + 2, (Block)Blocks.leaves);
        world.setBlock(i + 3, j + 7, k + 3, (Block)Blocks.leaves);
        world.setBlock(i + 3, j + 7, k + 5, (Block)Blocks.leaves);
        world.setBlock(i + 3, j + 7, k + 6, (Block)Blocks.leaves);
        world.setBlock(i + 3, j + 7, k + 7, (Block)Blocks.leaves);
        world.setBlock(i + 3, j + 8, k + 1, (Block)Blocks.leaves, 12, 0);
        world.setBlock(i + 3, j + 8, k + 2, (Block)Blocks.leaves, 4, 0);
        world.setBlock(i + 3, j + 8, k + 3, (Block)Blocks.leaves, 12, 0);
        world.setBlock(i + 3, j + 8, k + 5, (Block)Blocks.leaves, 12, 0);
        world.setBlock(i + 3, j + 8, k + 6, (Block)Blocks.leaves, 12, 0);
        world.setBlock(i + 3, j + 8, k + 7, (Block)Blocks.leaves, 12, 0);
        world.setBlock(i + 3, j + 9, k + 1, (Block)Blocks.leaves, 12, 0);
        world.setBlock(i + 3, j + 9, k + 7, (Block)Blocks.leaves, 4, 0);
        world.setBlock(i + 3, j + 10, k + 1, (Block)Blocks.leaves, 12, 0);
        world.setBlock(i + 3, j + 10, k + 7, (Block)Blocks.leaves, 4, 0);
        world.setBlock(i + 4, j + 0, k + 3, Blocks.log);
        world.setBlock(i + 4, j + 0, k + 4, Blocks.log);
        world.setBlock(i + 4, j + 1, k + 3, Blocks.log);
        world.setBlock(i + 4, j + 1, k + 4, Blocks.log);
        world.setBlock(i + 4, j + 2, k + 3, Blocks.log);
        world.setBlock(i + 4, j + 2, k + 4, Blocks.log);
        world.setBlock(i + 4, j + 3, k + 2, (Block)Blocks.leaves, 4, 0);
        world.setBlock(i + 4, j + 3, k + 3, Blocks.log);
        world.setBlock(i + 4, j + 3, k + 4, Blocks.log);
        world.setBlock(i + 4, j + 3, k + 5, (Block)Blocks.leaves);
        world.setBlock(i + 4, j + 3, k + 6, (Block)Blocks.leaves);
        world.setBlock(i + 4, j + 4, k + 1, (Block)Blocks.leaves);
        world.setBlock(i + 4, j + 4, k + 2, Blocks.log, 8, 0);
        world.setBlock(i + 4, j + 4, k + 3, Blocks.log, 8, 0);
        world.setBlock(i + 4, j + 4, k + 4, Blocks.log);
        world.setBlock(i + 4, j + 4, k + 5, (Block)Blocks.leaves);
        world.setBlock(i + 4, j + 4, k + 6, (Block)Blocks.leaves);
        world.setBlock(i + 4, j + 4, k + 7, (Block)Blocks.leaves);
        world.setBlock(i + 4, j + 5, k + 0, (Block)Blocks.leaves);
        world.setBlock(i + 4, j + 5, k + 1, (Block)Blocks.leaves);
        world.setBlock(i + 4, j + 5, k + 2, (Block)Blocks.leaves);
        world.setBlock(i + 4, j + 5, k + 3, (Block)Blocks.leaves);
        world.setBlock(i + 4, j + 5, k + 4, Blocks.log);
        world.setBlock(i + 4, j + 5, k + 5, Blocks.log, 8, 0);
        world.setBlock(i + 4, j + 5, k + 6, Blocks.log, 8, 0);
        world.setBlock(i + 4, j + 5, k + 7, (Block)Blocks.leaves);
        world.setBlock(i + 4, j + 5, k + 8, (Block)Blocks.leaves, 12, 0);
        world.setBlock(i + 4, j + 6, k + 0, (Block)Blocks.leaves);
        world.setBlock(i + 4, j + 6, k + 1, (Block)Blocks.leaves);
        world.setBlock(i + 4, j + 6, k + 2, (Block)Blocks.leaves);
        world.setBlock(i + 4, j + 6, k + 3, (Block)Blocks.leaves);
        world.setBlock(i + 4, j + 6, k + 4, Blocks.log);
        world.setBlock(i + 4, j + 6, k + 5, (Block)Blocks.leaves);
        world.setBlock(i + 4, j + 6, k + 6, (Block)Blocks.leaves);
        world.setBlock(i + 4, j + 6, k + 7, (Block)Blocks.leaves);
        world.setBlock(i + 4, j + 6, k + 8, (Block)Blocks.leaves);
        world.setBlock(i + 4, j + 7, k + 1, (Block)Blocks.leaves);
        world.setBlock(i + 4, j + 7, k + 2, (Block)Blocks.leaves);
        world.setBlock(i + 4, j + 7, k + 3, (Block)Blocks.leaves);
        world.setBlock(i + 4, j + 7, k + 4, Blocks.log);
        world.setBlock(i + 4, j + 7, k + 5, (Block)Blocks.leaves);
        world.setBlock(i + 4, j + 7, k + 6, (Block)Blocks.leaves);
        world.setBlock(i + 4, j + 7, k + 7, (Block)Blocks.leaves);
        world.setBlock(i + 4, j + 7, k + 8, (Block)Blocks.leaves);
        world.setBlock(i + 4, j + 8, k + 1, (Block)Blocks.leaves, 12, 0);
        world.setBlock(i + 4, j + 8, k + 2, (Block)Blocks.leaves, 12, 0);
        world.setBlock(i + 4, j + 8, k + 3, (Block)Blocks.leaves, 4, 0);
        world.setBlock(i + 4, j + 8, k + 4, (Block)Blocks.leaves, 4, 0);
        world.setBlock(i + 4, j + 8, k + 5, (Block)Blocks.leaves, 4, 0);
        world.setBlock(i + 4, j + 8, k + 6, (Block)Blocks.leaves, 4, 0);
        world.setBlock(i + 4, j + 8, k + 7, (Block)Blocks.leaves);
        world.setBlock(i + 4, j + 9, k + 1, (Block)Blocks.leaves, 12, 0);
        world.setBlock(i + 4, j + 9, k + 7, (Block)Blocks.leaves, 4, 0);
        world.setBlock(i + 5, j + 3, k + 3, (Block)Blocks.leaves, 4, 0);
        world.setBlock(i + 5, j + 3, k + 4, (Block)Blocks.leaves, 4, 0);
        world.setBlock(i + 5, j + 3, k + 5, (Block)Blocks.leaves);
        world.setBlock(i + 5, j + 4, k + 1, (Block)Blocks.leaves, 4, 0);
        world.setBlock(i + 5, j + 4, k + 2, (Block)Blocks.leaves);
        world.setBlock(i + 5, j + 4, k + 3, (Block)Blocks.leaves);
        world.setBlock(i + 5, j + 4, k + 4, (Block)Blocks.leaves);
        world.setBlock(i + 5, j + 4, k + 5, (Block)Blocks.leaves);
        world.setBlock(i + 5, j + 4, k + 6, (Block)Blocks.leaves);
        world.setBlock(i + 5, j + 4, k + 7, (Block)Blocks.leaves);
        world.setBlock(i + 5, j + 5, k + 0, (Block)Blocks.leaves);
        world.setBlock(i + 5, j + 5, k + 1, (Block)Blocks.leaves);
        world.setBlock(i + 5, j + 5, k + 2, (Block)Blocks.leaves);
        world.setBlock(i + 5, j + 5, k + 3, Blocks.log, 4, 0);
        world.setBlock(i + 5, j + 5, k + 4, (Block)Blocks.leaves);
        world.setBlock(i + 5, j + 5, k + 5, (Block)Blocks.leaves);
        world.setBlock(i + 5, j + 5, k + 6, (Block)Blocks.leaves);
        world.setBlock(i + 5, j + 5, k + 7, (Block)Blocks.leaves);
        world.setBlock(i + 5, j + 6, k + 0, (Block)Blocks.leaves);
        world.setBlock(i + 5, j + 6, k + 1, (Block)Blocks.leaves);
        world.setBlock(i + 5, j + 6, k + 2, (Block)Blocks.leaves);
        world.setBlock(i + 5, j + 6, k + 3, (Block)Blocks.leaves);
        world.setBlock(i + 5, j + 6, k + 4, Blocks.log, 4, 0);
        world.setBlock(i + 5, j + 6, k + 5, Blocks.log, 4, 0);
        world.setBlock(i + 5, j + 6, k + 6, (Block)Blocks.leaves);
        world.setBlock(i + 5, j + 6, k + 7, (Block)Blocks.leaves);
        world.setBlock(i + 5, j + 6, k + 8, (Block)Blocks.leaves);
        world.setBlock(i + 5, j + 7, k + 1, (Block)Blocks.leaves, 12, 0);
        world.setBlock(i + 5, j + 7, k + 2, (Block)Blocks.leaves);
        world.setBlock(i + 5, j + 7, k + 3, (Block)Blocks.leaves);
        world.setBlock(i + 5, j + 7, k + 4, (Block)Blocks.leaves);
        world.setBlock(i + 5, j + 7, k + 5, (Block)Blocks.leaves);
        world.setBlock(i + 5, j + 7, k + 6, (Block)Blocks.leaves);
        world.setBlock(i + 5, j + 7, k + 7, (Block)Blocks.leaves);
        world.setBlock(i + 5, j + 7, k + 8, (Block)Blocks.leaves);
        world.setBlock(i + 5, j + 8, k + 1, (Block)Blocks.leaves, 12, 0);
        world.setBlock(i + 5, j + 8, k + 2, (Block)Blocks.leaves, 12, 0);
        world.setBlock(i + 5, j + 8, k + 3, (Block)Blocks.leaves, 4, 0);
        world.setBlock(i + 5, j + 8, k + 4, (Block)Blocks.leaves, 4, 0);
        world.setBlock(i + 5, j + 8, k + 5, (Block)Blocks.leaves, 4, 0);
        world.setBlock(i + 5, j + 8, k + 6, (Block)Blocks.leaves, 4, 0);
        world.setBlock(i + 5, j + 8, k + 7, (Block)Blocks.leaves);
        world.setBlock(i + 5, j + 9, k + 1, (Block)Blocks.leaves, 4, 0);
        world.setBlock(i + 5, j + 9, k + 7, (Block)Blocks.leaves, 4, 0);
        world.setBlock(i + 5, j + 10, k + 1, (Block)Blocks.leaves, 4, 0);
        world.setBlock(i + 5, j + 10, k + 7, (Block)Blocks.leaves, 4, 0);
        world.setBlock(i + 6, j + 4, k + 2, (Block)Blocks.leaves, 12, 0);
        world.setBlock(i + 6, j + 4, k + 3, (Block)Blocks.leaves, 4, 0);
        world.setBlock(i + 6, j + 4, k + 4, (Block)Blocks.leaves);
        world.setBlock(i + 6, j + 4, k + 5, (Block)Blocks.leaves);
        world.setBlock(i + 6, j + 4, k + 6, (Block)Blocks.leaves);
        world.setBlock(i + 6, j + 5, k + 1, (Block)Blocks.leaves);
        world.setBlock(i + 6, j + 5, k + 2, (Block)Blocks.leaves);
        world.setBlock(i + 6, j + 5, k + 3, (Block)Blocks.leaves);
        world.setBlock(i + 6, j + 5, k + 4, (Block)Blocks.leaves);
        world.setBlock(i + 6, j + 5, k + 5, (Block)Blocks.leaves);
        world.setBlock(i + 6, j + 5, k + 6, (Block)Blocks.leaves);
        world.setBlock(i + 6, j + 5, k + 7, (Block)Blocks.leaves, 12, 0);
        world.setBlock(i + 6, j + 6, k + 1, (Block)Blocks.leaves);
        world.setBlock(i + 6, j + 6, k + 2, (Block)Blocks.leaves);
        world.setBlock(i + 6, j + 6, k + 3, (Block)Blocks.leaves);
        world.setBlock(i + 6, j + 6, k + 4, (Block)Blocks.leaves);
        world.setBlock(i + 6, j + 6, k + 5, (Block)Blocks.leaves);
        world.setBlock(i + 6, j + 6, k + 6, (Block)Blocks.leaves);
        world.setBlock(i + 6, j + 6, k + 7, (Block)Blocks.leaves);
        world.setBlock(i + 6, j + 7, k + 1, (Block)Blocks.leaves, 12, 0);
        world.setBlock(i + 6, j + 7, k + 2, (Block)Blocks.leaves);
        world.setBlock(i + 6, j + 7, k + 3, (Block)Blocks.leaves);
        world.setBlock(i + 6, j + 7, k + 4, (Block)Blocks.leaves);
        world.setBlock(i + 6, j + 7, k + 5, (Block)Blocks.leaves);
        world.setBlock(i + 6, j + 7, k + 6, (Block)Blocks.leaves);
        world.setBlock(i + 6, j + 7, k + 7, (Block)Blocks.leaves);
        world.setBlock(i + 6, j + 8, k + 1, (Block)Blocks.leaves, 12, 0);
        world.setBlock(i + 6, j + 8, k + 2, (Block)Blocks.leaves, 12, 0);
        world.setBlock(i + 6, j + 8, k + 3, (Block)Blocks.leaves, 4, 0);
        world.setBlock(i + 6, j + 8, k + 4, (Block)Blocks.leaves, 4, 0);
        world.setBlock(i + 6, j + 8, k + 5, (Block)Blocks.leaves, 4, 0);
        world.setBlock(i + 6, j + 8, k + 6, (Block)Blocks.leaves);
        world.setBlock(i + 6, j + 8, k + 7, (Block)Blocks.leaves, 4, 0);
        world.setBlock(i + 6, j + 9, k + 1, (Block)Blocks.leaves, 4, 0);
        Dungeons.spawner(world, i + 6, j + 9, k + 4, 12, 2);
        WorldGenWarlordDungeon.chest(world, rand, i + 6, j + 9, k + 5, "dungeonChest", rand.nextInt(5) + 1);
        world.setBlock(i + 6, j + 9, k + 7, (Block)Blocks.leaves, 4, 0);
        world.setBlock(i + 7, j + 5, k + 2, (Block)Blocks.leaves, 12, 0);
        world.setBlock(i + 7, j + 5, k + 3, (Block)Blocks.leaves, 4, 0);
        world.setBlock(i + 7, j + 5, k + 4, (Block)Blocks.leaves, 4, 0);
        world.setBlock(i + 7, j + 5, k + 5, (Block)Blocks.leaves, 4, 0);
        world.setBlock(i + 7, j + 5, k + 6, (Block)Blocks.leaves, 4, 0);
        world.setBlock(i + 7, j + 6, k + 1, (Block)Blocks.leaves, 12, 0);
        world.setBlock(i + 7, j + 6, k + 2, (Block)Blocks.leaves);
        world.setBlock(i + 7, j + 6, k + 3, (Block)Blocks.leaves);
        world.setBlock(i + 7, j + 6, k + 4, (Block)Blocks.leaves);
        world.setBlock(i + 7, j + 6, k + 5, (Block)Blocks.leaves, 4, 0);
        world.setBlock(i + 7, j + 6, k + 6, (Block)Blocks.leaves, 4, 0);
        world.setBlock(i + 7, j + 6, k + 7, (Block)Blocks.leaves, 4, 0);
        world.setBlock(i + 7, j + 7, k + 1, (Block)Blocks.leaves, 12, 0);
        world.setBlock(i + 7, j + 7, k + 2, (Block)Blocks.leaves, 4, 0);
        world.setBlock(i + 7, j + 7, k + 3, (Block)Blocks.leaves);
        world.setBlock(i + 7, j + 7, k + 4, (Block)Blocks.leaves);
        world.setBlock(i + 7, j + 7, k + 5, (Block)Blocks.leaves);
        world.setBlock(i + 7, j + 7, k + 6, (Block)Blocks.leaves);
        world.setBlock(i + 7, j + 7, k + 7, (Block)Blocks.leaves, 4, 0);
        world.setBlock(i + 7, j + 8, k + 1, (Block)Blocks.leaves, 12, 0);
        world.setBlock(i + 7, j + 8, k + 2, (Block)Blocks.leaves, 12, 0);
        world.setBlock(i + 7, j + 8, k + 3, (Block)Blocks.leaves, 4, 0);
        world.setBlock(i + 7, j + 8, k + 4, (Block)Blocks.leaves);
        world.setBlock(i + 7, j + 8, k + 5, (Block)Blocks.leaves);
        world.setBlock(i + 7, j + 8, k + 6, (Block)Blocks.leaves, 4, 0);
        world.setBlock(i + 7, j + 8, k + 7, (Block)Blocks.leaves, 4, 0);
        world.setBlock(i + 7, j + 9, k + 1, (Block)Blocks.leaves, 12, 0);
        world.setBlock(i + 7, j + 9, k + 2, (Block)Blocks.leaves, 12, 0);
        world.setBlock(i + 7, j + 9, k + 3, (Block)Blocks.leaves, 4, 0);
        world.setBlock(i + 7, j + 9, k + 4, (Block)Blocks.leaves, 4, 0);
        world.setBlock(i + 7, j + 9, k + 5, (Block)Blocks.leaves, 12, 0);
        world.setBlock(i + 7, j + 9, k + 6, (Block)Blocks.leaves, 12, 0);
        world.setBlock(i + 7, j + 9, k + 7, (Block)Blocks.leaves, 4, 0);
        world.setBlock(i + 7, j + 10, k + 1, (Block)Blocks.leaves, 12, 0);
        world.setBlock(i + 7, j + 10, k + 3, (Block)Blocks.leaves, 4, 0);
        world.setBlock(i + 7, j + 10, k + 5, (Block)Blocks.leaves, 12, 0);
        world.setBlock(i + 7, j + 10, k + 7, (Block)Blocks.leaves, 4, 0);
        world.setBlock(i + 3, j + 0, k + 4, Blocks.ladder, 4, 0);
        world.setBlock(i + 3, j + 1, k + 4, Blocks.ladder, 4, 0);
        world.setBlock(i + 3, j + 2, k + 4, Blocks.ladder, 4, 0);
        world.setBlock(i + 3, j + 3, k + 4, Blocks.ladder, 4, 0);
        world.setBlock(i + 3, j + 4, k + 4, Blocks.ladder, 4, 0);
        world.setBlock(i + 3, j + 5, k + 4, Blocks.ladder, 4, 0);
        world.setBlock(i + 3, j + 6, k + 4, Blocks.ladder, 4, 0);
        world.setBlock(i + 3, j + 7, k + 4, Blocks.ladder, 4, 0);
        return true;
    }
}
