

package com.gibby.dungeon.gen;

import com.gibby.dungeon.Dungeons;
import net.minecraft.init.Blocks;
import net.minecraft.world.World;
import net.minecraft.world.gen.feature.WorldGenerator;

import java.util.Random;

public class WorldGenAmethystRuins extends WorldGenerator
{
    public boolean generate(final World world, final Random rand, final int i, final int j, final int k) {
        if (world.getBlock(i, j, k) == Blocks.air || world.getBlock(i + 20, j, k + 20) == Blocks.air || world.getBlock(i, j + 4, k) != Blocks.air || world.getBlock(i + 20, j + 4, k + 20) != Blocks.air || world.getBlock(i, j + 15, k) != Blocks.air || world.getBlock(i + 20, j + 15, k + 20) != Blocks.air) {
            return false;
        }
        world.setBlock(i + 3, j, k + 14, Dungeons.amethystStone);
        world.setBlock(i + 3, j, k + 15, Dungeons.amethystStone);
        world.setBlock(i + 3, j, k + 16, Dungeons.amethystStone);
        world.setBlock(i + 3, j, k + 17, Dungeons.amethystStone);
        world.setBlock(i + 3, j, k + 18, Dungeons.amethystStone);
        world.setBlock(i + 3, j, k + 19, Dungeons.amethystStone);
        world.setBlock(i + 3, j, k + 20, Dungeons.amethystStone);
        world.setBlock(i + 3, j, k + 21, Dungeons.amethystStone);
        world.setBlock(i + 3, j, k + 22, Dungeons.amethystStone);
        world.setBlock(i + 3, j, k + 23, Dungeons.amethystStone);
        world.setBlock(i + 3, j, k + 24, Dungeons.amethystStone);
        world.setBlock(i + 3, j, k + 25, Dungeons.amethystStone);
        world.setBlock(i + 3, j, k + 26, Dungeons.amethystStone);
        world.setBlock(i + 3, j, k + 27, Dungeons.amethystStone);
        world.setBlock(i + 3, j, k + 28, Dungeons.amethystStone);
        world.setBlock(i + 3, j, k + 29, Dungeons.amethystStone);
        world.setBlock(i + 3, j, k + 30, Dungeons.amethystStone);
        world.setBlock(i + 3, j, k + 31, Dungeons.amethystStone);
        world.setBlock(i + 3, j, k + 32, Dungeons.amethystStone);
        world.setBlock(i + 3, j, k + 33, Dungeons.amethystStone);
        world.setBlock(i + 3, j, k + 34, Dungeons.amethystStone);
        world.setBlock(i + 3, j + 1, k + 14, Dungeons.amethystStone);
        world.setBlock(i + 3, j + 1, k + 15, Dungeons.amethystStone);
        world.setBlock(i + 3, j + 1, k + 16, Dungeons.amethystStone);
        world.setBlock(i + 3, j + 1, k + 17, Dungeons.amethystStone);
        world.setBlock(i + 3, j + 1, k + 18, Dungeons.amethystStone);
        world.setBlock(i + 3, j + 1, k + 19, Dungeons.amethystStone);
        world.setBlock(i + 3, j + 1, k + 20, Dungeons.amethystStone);
        world.setBlock(i + 3, j + 1, k + 21, Dungeons.amethystStone);
        world.setBlock(i + 3, j + 1, k + 22, Dungeons.amethystStone);
        world.setBlock(i + 3, j + 1, k + 23, Dungeons.amethystStone);
        world.setBlock(i + 3, j + 1, k + 24, Dungeons.amethystStone);
        world.setBlock(i + 3, j + 1, k + 25, Dungeons.amethystStone);
        world.setBlock(i + 3, j + 1, k + 26, Dungeons.amethystStone);
        world.setBlock(i + 3, j + 1, k + 27, Dungeons.amethystStone);
        world.setBlock(i + 3, j + 1, k + 28, Dungeons.amethystStone);
        world.setBlock(i + 3, j + 1, k + 29, Dungeons.amethystStone);
        world.setBlock(i + 3, j + 1, k + 30, Dungeons.amethystStone);
        world.setBlock(i + 3, j + 1, k + 31, Dungeons.amethystStone);
        world.setBlock(i + 3, j + 1, k + 32, Dungeons.amethystStone);
        world.setBlock(i + 3, j + 1, k + 33, Dungeons.amethystStone);
        world.setBlock(i + 3, j + 1, k + 34, Dungeons.amethystStone);
        world.setBlock(i + 3, j + 2, k + 14, Dungeons.amethystStone);
        world.setBlock(i + 3, j + 2, k + 15, Dungeons.amethystStone);
        world.setBlock(i + 3, j + 2, k + 16, Dungeons.amethystStone);
        world.setBlock(i + 3, j + 2, k + 17, Dungeons.amethystStone);
        world.setBlock(i + 3, j + 2, k + 18, Dungeons.amethystStone);
        world.setBlock(i + 3, j + 2, k + 19, Dungeons.amethystStone);
        world.setBlock(i + 3, j + 2, k + 20, Dungeons.amethystStone);
        world.setBlock(i + 3, j + 2, k + 21, Dungeons.amethystStone);
        world.setBlock(i + 3, j + 2, k + 22, Dungeons.amethystStone);
        world.setBlock(i + 3, j + 2, k + 23, Dungeons.amethystStone);
        world.setBlock(i + 3, j + 2, k + 24, Dungeons.amethystStone);
        world.setBlock(i + 3, j + 2, k + 25, Dungeons.amethystStone);
        world.setBlock(i + 3, j + 2, k + 26, Dungeons.amethystStone);
        world.setBlock(i + 3, j + 2, k + 27, Dungeons.amethystStone);
        world.setBlock(i + 3, j + 2, k + 28, Dungeons.amethystStone);
        world.setBlock(i + 3, j + 2, k + 29, Dungeons.amethystStone);
        world.setBlock(i + 3, j + 2, k + 30, Dungeons.amethystStone);
        world.setBlock(i + 3, j + 2, k + 31, Dungeons.amethystStone);
        world.setBlock(i + 3, j + 2, k + 32, Dungeons.amethystStone);
        world.setBlock(i + 3, j + 2, k + 33, Dungeons.amethystStone);
        world.setBlock(i + 3, j + 2, k + 34, Dungeons.amethystStone);
        world.setBlock(i + 3, j + 3, k + 14, Dungeons.amethystStone);
        world.setBlock(i + 3, j + 3, k + 15, Dungeons.amethystStone);
        world.setBlock(i + 3, j + 3, k + 16, Dungeons.amethystStone);
        world.setBlock(i + 3, j + 3, k + 17, Dungeons.amethystStone);
        world.setBlock(i + 3, j + 3, k + 18, Dungeons.amethystStone);
        world.setBlock(i + 3, j + 3, k + 19, Dungeons.amethystStone);
        world.setBlock(i + 3, j + 3, k + 20, Dungeons.amethystStone);
        world.setBlock(i + 3, j + 3, k + 21, Dungeons.amethystStone);
        world.setBlock(i + 3, j + 3, k + 22, Dungeons.amethystStone);
        world.setBlock(i + 3, j + 3, k + 23, Dungeons.amethystStone);
        world.setBlock(i + 3, j + 3, k + 24, Dungeons.amethystStone);
        world.setBlock(i + 3, j + 3, k + 25, Dungeons.amethystStone);
        world.setBlock(i + 3, j + 3, k + 26, Dungeons.amethystStone);
        world.setBlock(i + 3, j + 3, k + 27, Dungeons.amethystStone);
        world.setBlock(i + 3, j + 3, k + 28, Dungeons.amethystStone);
        world.setBlock(i + 3, j + 3, k + 29, Dungeons.amethystStone);
        world.setBlock(i + 3, j + 3, k + 30, Dungeons.amethystStone);
        world.setBlock(i + 3, j + 3, k + 31, Dungeons.amethystStone);
        world.setBlock(i + 3, j + 3, k + 32, Dungeons.amethystStone);
        world.setBlock(i + 3, j + 3, k + 33, Dungeons.amethystStone);
        world.setBlock(i + 3, j + 3, k + 34, Dungeons.amethystStone);
        world.setBlock(i + 3, j + 4, k + 14, Dungeons.amethystStone);
        world.setBlock(i + 3, j + 4, k + 15, Dungeons.amethystStone);
        world.setBlock(i + 3, j + 4, k + 16, Dungeons.amethystStone);
        world.setBlock(i + 3, j + 4, k + 17, Dungeons.amethystStone);
        world.setBlock(i + 3, j + 4, k + 18, Dungeons.amethystStone);
        world.setBlock(i + 3, j + 4, k + 19, Dungeons.amethystStone);
        world.setBlock(i + 3, j + 4, k + 20, Dungeons.amethystStone);
        world.setBlock(i + 3, j + 4, k + 21, Dungeons.amethystStone);
        world.setBlock(i + 3, j + 4, k + 22, Dungeons.amethystStone);
        world.setBlock(i + 3, j + 4, k + 23, Dungeons.amethystStone);
        world.setBlock(i + 3, j + 4, k + 24, Dungeons.amethystStone);
        world.setBlock(i + 3, j + 4, k + 25, Dungeons.amethystStone);
        world.setBlock(i + 3, j + 4, k + 26, Dungeons.amethystStone);
        world.setBlock(i + 3, j + 4, k + 27, Dungeons.amethystStone);
        world.setBlock(i + 3, j + 4, k + 28, Dungeons.amethystStone);
        world.setBlock(i + 3, j + 4, k + 29, Dungeons.amethystStone);
        world.setBlock(i + 3, j + 4, k + 30, Dungeons.amethystStone);
        world.setBlock(i + 3, j + 4, k + 31, Dungeons.amethystStone);
        world.setBlock(i + 3, j + 4, k + 32, Dungeons.amethystStone);
        world.setBlock(i + 3, j + 4, k + 33, Dungeons.amethystStone);
        world.setBlock(i + 3, j + 4, k + 34, Dungeons.amethystStone);
        world.setBlock(i + 3, j + 5, k + 14, Dungeons.amethystStone);
        world.setBlock(i + 3, j + 5, k + 15, Dungeons.amethystStone);
        world.setBlock(i + 3, j + 5, k + 16, Dungeons.amethystStone);
        world.setBlock(i + 3, j + 5, k + 17, Dungeons.amethystStone);
        world.setBlock(i + 3, j + 5, k + 18, Dungeons.amethystStone);
        world.setBlock(i + 3, j + 5, k + 19, Dungeons.amethystStone);
        world.setBlock(i + 3, j + 5, k + 20, Dungeons.amethystStone);
        world.setBlock(i + 3, j + 5, k + 21, Dungeons.amethystStone);
        world.setBlock(i + 3, j + 5, k + 22, Dungeons.amethystStone);
        world.setBlock(i + 3, j + 5, k + 23, Dungeons.amethystStone);
        world.setBlock(i + 3, j + 5, k + 24, Dungeons.amethystStone);
        world.setBlock(i + 3, j + 5, k + 25, Dungeons.amethystStone);
        world.setBlock(i + 3, j + 5, k + 26, Dungeons.amethystStone);
        world.setBlock(i + 3, j + 5, k + 27, Dungeons.amethystStone);
        world.setBlock(i + 3, j + 5, k + 28, Dungeons.amethystStone);
        world.setBlock(i + 3, j + 5, k + 29, Dungeons.amethystStone);
        world.setBlock(i + 3, j + 5, k + 30, Dungeons.amethystStone);
        world.setBlock(i + 3, j + 5, k + 31, Dungeons.amethystStone);
        world.setBlock(i + 3, j + 5, k + 32, Dungeons.amethystStone);
        world.setBlock(i + 3, j + 5, k + 33, Dungeons.amethystStone);
        world.setBlock(i + 3, j + 5, k + 34, Dungeons.amethystStone);
        world.setBlock(i + 3, j + 6, k + 14, Dungeons.amethystStone);
        world.setBlock(i + 3, j + 6, k + 15, Dungeons.amethystStone);
        world.setBlock(i + 3, j + 6, k + 16, Dungeons.amethystStone);
        world.setBlock(i + 3, j + 6, k + 17, Dungeons.amethystStone);
        world.setBlock(i + 3, j + 6, k + 18, Dungeons.amethystStone);
        world.setBlock(i + 3, j + 6, k + 19, Dungeons.amethystStone);
        world.setBlock(i + 3, j + 6, k + 20, Dungeons.amethystStone);
        world.setBlock(i + 3, j + 6, k + 21, Dungeons.amethystStone);
        world.setBlock(i + 3, j + 6, k + 22, Dungeons.amethystStone);
        world.setBlock(i + 3, j + 6, k + 23, Dungeons.amethystStone);
        world.setBlock(i + 3, j + 6, k + 24, Dungeons.amethystStone);
        world.setBlock(i + 3, j + 6, k + 25, Dungeons.amethystStone);
        world.setBlock(i + 3, j + 6, k + 26, Dungeons.amethystStone);
        world.setBlock(i + 3, j + 6, k + 27, Dungeons.amethystStone);
        world.setBlock(i + 3, j + 6, k + 28, Dungeons.amethystStone);
        world.setBlock(i + 3, j + 6, k + 29, Dungeons.amethystStone);
        world.setBlock(i + 3, j + 6, k + 30, Dungeons.amethystStone);
        world.setBlock(i + 3, j + 6, k + 31, Dungeons.amethystStone);
        world.setBlock(i + 3, j + 6, k + 32, Dungeons.amethystStone);
        world.setBlock(i + 3, j + 6, k + 33, Dungeons.amethystStone);
        world.setBlock(i + 3, j + 6, k + 34, Dungeons.amethystStone);
        world.setBlock(i + 3, j + 7, k + 14, Dungeons.amethystStone);
        world.setBlock(i + 3, j + 7, k + 15, Dungeons.amethystStone);
        world.setBlock(i + 3, j + 7, k + 16, Dungeons.amethystStone);
        world.setBlock(i + 3, j + 7, k + 17, Dungeons.amethystStone);
        world.setBlock(i + 3, j + 7, k + 18, Dungeons.amethystStone);
        world.setBlock(i + 3, j + 7, k + 19, Dungeons.amethystStone);
        world.setBlock(i + 3, j + 7, k + 20, Dungeons.amethystStone);
        world.setBlock(i + 3, j + 7, k + 21, Dungeons.amethystStone);
        world.setBlock(i + 3, j + 7, k + 22, Dungeons.amethystStone);
        world.setBlock(i + 3, j + 7, k + 23, Dungeons.amethystStone);
        world.setBlock(i + 3, j + 7, k + 24, Dungeons.amethystStone);
        world.setBlock(i + 3, j + 7, k + 25, Dungeons.amethystStone);
        world.setBlock(i + 3, j + 7, k + 26, Dungeons.amethystStone);
        world.setBlock(i + 3, j + 7, k + 27, Dungeons.amethystStone);
        world.setBlock(i + 3, j + 7, k + 28, Dungeons.amethystStone);
        world.setBlock(i + 3, j + 7, k + 29, Dungeons.amethystStone);
        world.setBlock(i + 3, j + 7, k + 30, Dungeons.amethystStone);
        world.setBlock(i + 3, j + 7, k + 31, Dungeons.amethystStone);
        world.setBlock(i + 3, j + 7, k + 32, Dungeons.amethystStone);
        world.setBlock(i + 3, j + 7, k + 33, Dungeons.amethystStone);
        world.setBlock(i + 3, j + 7, k + 34, Dungeons.amethystStone);
        world.setBlock(i + 3, j + 8, k + 14, Dungeons.amethystStone);
        world.setBlock(i + 3, j + 8, k + 15, Dungeons.amethystStone);
        world.setBlock(i + 3, j + 8, k + 16, Dungeons.amethystStone);
        world.setBlock(i + 3, j + 8, k + 17, Dungeons.amethystStone);
        world.setBlock(i + 3, j + 8, k + 18, Dungeons.amethystStone);
        world.setBlock(i + 3, j + 8, k + 19, Dungeons.amethystStone);
        world.setBlock(i + 3, j + 8, k + 20, Dungeons.amethystStone);
        world.setBlock(i + 3, j + 8, k + 21, Dungeons.amethystStone);
        world.setBlock(i + 3, j + 8, k + 22, Dungeons.amethystStone);
        world.setBlock(i + 3, j + 8, k + 23, Dungeons.amethystStone);
        world.setBlock(i + 3, j + 8, k + 24, Dungeons.amethystStone);
        world.setBlock(i + 3, j + 8, k + 25, Dungeons.amethystStone);
        world.setBlock(i + 3, j + 8, k + 26, Dungeons.amethystStone);
        world.setBlock(i + 3, j + 8, k + 27, Dungeons.amethystStone);
        world.setBlock(i + 3, j + 8, k + 28, Dungeons.amethystStone);
        world.setBlock(i + 3, j + 8, k + 29, Dungeons.amethystStone);
        world.setBlock(i + 3, j + 8, k + 30, Dungeons.amethystStone);
        world.setBlock(i + 3, j + 8, k + 31, Dungeons.amethystStone);
        world.setBlock(i + 3, j + 8, k + 32, Dungeons.amethystStone);
        world.setBlock(i + 3, j + 8, k + 33, Dungeons.amethystStone);
        world.setBlock(i + 3, j + 8, k + 34, Dungeons.amethystStone);
        world.setBlock(i + 3, j + 9, k + 14, Dungeons.amethystStone);
        world.setBlock(i + 3, j + 9, k + 15, Dungeons.amethystStone);
        world.setBlock(i + 3, j + 9, k + 16, Dungeons.amethystStone);
        world.setBlock(i + 3, j + 9, k + 17, Dungeons.amethystStone);
        world.setBlock(i + 3, j + 9, k + 18, Dungeons.amethystStone);
        world.setBlock(i + 3, j + 9, k + 19, Dungeons.amethystStone);
        world.setBlock(i + 3, j + 9, k + 20, Dungeons.amethystStone);
        world.setBlock(i + 3, j + 9, k + 21, Dungeons.amethystStone);
        world.setBlock(i + 3, j + 9, k + 22, Dungeons.amethystStone);
        world.setBlock(i + 3, j + 9, k + 23, Dungeons.amethystStone);
        world.setBlock(i + 3, j + 9, k + 24, Dungeons.amethystStone);
        world.setBlock(i + 3, j + 9, k + 25, Dungeons.amethystStone);
        world.setBlock(i + 3, j + 9, k + 26, Dungeons.amethystStone);
        world.setBlock(i + 3, j + 9, k + 27, Dungeons.amethystStone);
        world.setBlock(i + 3, j + 9, k + 28, Dungeons.amethystStone);
        world.setBlock(i + 3, j + 9, k + 29, Dungeons.amethystStone);
        world.setBlock(i + 3, j + 9, k + 30, Dungeons.amethystStone);
        world.setBlock(i + 3, j + 9, k + 31, Dungeons.amethystStone);
        world.setBlock(i + 3, j + 9, k + 32, Dungeons.amethystStone);
        world.setBlock(i + 3, j + 9, k + 33, Dungeons.amethystStone);
        world.setBlock(i + 3, j + 9, k + 34, Dungeons.amethystStone);
        world.setBlock(i + 3, j + 10, k + 14, Dungeons.amethystStone);
        world.setBlock(i + 3, j + 10, k + 15, Dungeons.amethystStone);
        world.setBlock(i + 3, j + 10, k + 16, Dungeons.amethystStone);
        world.setBlock(i + 3, j + 10, k + 17, Dungeons.amethystStone);
        world.setBlock(i + 3, j + 10, k + 18, Dungeons.amethystStone);
        world.setBlock(i + 3, j + 10, k + 19, Dungeons.amethystStone);
        world.setBlock(i + 3, j + 10, k + 20, Dungeons.amethystStone);
        world.setBlock(i + 3, j + 10, k + 21, Dungeons.amethystStone);
        world.setBlock(i + 3, j + 10, k + 22, Dungeons.amethystStone);
        world.setBlock(i + 3, j + 10, k + 23, Dungeons.amethystStone);
        world.setBlock(i + 3, j + 10, k + 24, Dungeons.amethystStone);
        world.setBlock(i + 3, j + 10, k + 25, Dungeons.amethystStone);
        world.setBlock(i + 3, j + 10, k + 26, Dungeons.amethystStone);
        world.setBlock(i + 3, j + 10, k + 27, Dungeons.amethystStone);
        world.setBlock(i + 3, j + 10, k + 28, Dungeons.amethystStone);
        world.setBlock(i + 3, j + 10, k + 29, Dungeons.amethystStone);
        world.setBlock(i + 3, j + 10, k + 30, Dungeons.amethystStone);
        world.setBlock(i + 3, j + 10, k + 31, Dungeons.amethystStone);
        world.setBlock(i + 3, j + 10, k + 32, Dungeons.amethystStone);
        world.setBlock(i + 3, j + 10, k + 33, Dungeons.amethystStone);
        world.setBlock(i + 3, j + 10, k + 34, Dungeons.amethystStone);
        world.setBlock(i + 4, j, k + 11, Dungeons.amethystStone);
        world.setBlock(i + 4, j, k + 12, Dungeons.amethystStone);
        world.setBlock(i + 4, j, k + 13, Dungeons.amethystStone);
        world.setBlock(i + 4, j, k + 14, Dungeons.amethystStone);
        world.setBlock(i + 4, j, k + 15, Dungeons.amethystStone);
        world.setBlock(i + 4, j, k + 16, Dungeons.amethystStone);
        world.setBlock(i + 4, j, k + 17, Dungeons.amethystStone);
        world.setBlock(i + 4, j, k + 18, Dungeons.amethystStone);
        world.setBlock(i + 4, j, k + 19, Dungeons.amethystStone);
        world.setBlock(i + 4, j, k + 20, Dungeons.amethystStone);
        world.setBlock(i + 4, j, k + 21, Dungeons.amethystStone);
        world.setBlock(i + 4, j, k + 22, Dungeons.amethystStone);
        world.setBlock(i + 4, j, k + 23, Dungeons.amethystStone);
        world.setBlock(i + 4, j, k + 24, Dungeons.amethystStone);
        world.setBlock(i + 4, j, k + 25, Dungeons.amethystStone);
        world.setBlock(i + 4, j, k + 26, Dungeons.amethystStone);
        world.setBlock(i + 4, j, k + 27, Dungeons.amethystStone);
        world.setBlock(i + 4, j, k + 28, Dungeons.amethystStone);
        world.setBlock(i + 4, j, k + 29, Dungeons.amethystStone);
        world.setBlock(i + 4, j, k + 30, Dungeons.amethystStone);
        world.setBlock(i + 4, j, k + 31, Dungeons.amethystStone);
        world.setBlock(i + 4, j, k + 32, Dungeons.amethystStone);
        world.setBlock(i + 4, j, k + 33, Dungeons.amethystStone);
        world.setBlock(i + 4, j, k + 34, Dungeons.amethystStone);
        world.setBlock(i + 4, j, k + 35, Dungeons.amethystStone);
        world.setBlock(i + 4, j, k + 36, Dungeons.amethystStone);
        world.setBlock(i + 4, j, k + 37, Dungeons.amethystStone);
        world.setBlock(i + 4, j + 1, k + 11, Dungeons.amethystStone);
        world.setBlock(i + 4, j + 1, k + 12, Dungeons.amethystStone);
        world.setBlock(i + 4, j + 1, k + 13, Dungeons.amethystStone);
        world.setBlock(i + 4, j + 1, k + 14, Dungeons.amethystStone);
        world.setBlock(i + 4, j + 1, k + 15, Dungeons.amethystStone);
        world.setBlock(i + 4, j + 1, k + 16, Dungeons.amethystStone);
        world.setBlock(i + 4, j + 1, k + 17, Dungeons.amethystStone);
        world.setBlock(i + 4, j + 1, k + 18, Dungeons.amethystStone);
        world.setBlock(i + 4, j + 1, k + 19, Dungeons.amethystStone);
        world.setBlock(i + 4, j + 1, k + 20, Dungeons.amethystStone);
        world.setBlock(i + 4, j + 1, k + 21, Dungeons.amethystStone);
        world.setBlock(i + 4, j + 1, k + 22, Dungeons.amethystStone);
        world.setBlock(i + 4, j + 1, k + 23, Dungeons.amethystStone);
        world.setBlock(i + 4, j + 1, k + 24, Dungeons.amethystStone);
        world.setBlock(i + 4, j + 1, k + 25, Dungeons.amethystStone);
        world.setBlock(i + 4, j + 1, k + 26, Dungeons.amethystStone);
        world.setBlock(i + 4, j + 1, k + 27, Dungeons.amethystStone);
        world.setBlock(i + 4, j + 1, k + 28, Dungeons.amethystStone);
        world.setBlock(i + 4, j + 1, k + 29, Dungeons.amethystStone);
        world.setBlock(i + 4, j + 1, k + 30, Dungeons.amethystStone);
        world.setBlock(i + 4, j + 1, k + 31, Dungeons.amethystStone);
        world.setBlock(i + 4, j + 1, k + 32, Dungeons.amethystStone);
        world.setBlock(i + 4, j + 1, k + 33, Dungeons.amethystStone);
        world.setBlock(i + 4, j + 1, k + 34, Dungeons.amethystStone);
        world.setBlock(i + 4, j + 1, k + 35, Dungeons.amethystStone);
        world.setBlock(i + 4, j + 1, k + 36, Dungeons.amethystStone);
        world.setBlock(i + 4, j + 1, k + 37, Dungeons.amethystStone);
        world.setBlock(i + 4, j + 2, k + 11, Dungeons.amethystStone);
        world.setBlock(i + 4, j + 2, k + 12, Dungeons.amethystStone);
        world.setBlock(i + 4, j + 2, k + 13, Dungeons.amethystStone);
        world.setBlock(i + 4, j + 2, k + 14, Dungeons.amethystStone);
        world.setBlock(i + 4, j + 2, k + 15, Dungeons.amethystStone);
        world.setBlock(i + 4, j + 2, k + 16, Dungeons.amethystStone);
        world.setBlock(i + 4, j + 2, k + 17, Dungeons.amethystStone);
        world.setBlock(i + 4, j + 2, k + 18, Dungeons.amethystStone);
        world.setBlock(i + 4, j + 2, k + 19, Dungeons.amethystStone);
        world.setBlock(i + 4, j + 2, k + 20, Dungeons.amethystStone);
        world.setBlock(i + 4, j + 2, k + 21, Dungeons.amethystStone);
        world.setBlock(i + 4, j + 2, k + 22, Dungeons.amethystStone);
        world.setBlock(i + 4, j + 2, k + 23, Dungeons.amethystStone);
        world.setBlock(i + 4, j + 2, k + 24, Dungeons.amethystStone);
        world.setBlock(i + 4, j + 2, k + 25, Dungeons.amethystStone);
        world.setBlock(i + 4, j + 2, k + 26, Dungeons.amethystStone);
        world.setBlock(i + 4, j + 2, k + 27, Dungeons.amethystStone);
        world.setBlock(i + 4, j + 2, k + 28, Dungeons.amethystStone);
        world.setBlock(i + 4, j + 2, k + 29, Dungeons.amethystStone);
        world.setBlock(i + 4, j + 2, k + 30, Dungeons.amethystStone);
        world.setBlock(i + 4, j + 2, k + 31, Dungeons.amethystStone);
        world.setBlock(i + 4, j + 2, k + 32, Dungeons.amethystStone);
        world.setBlock(i + 4, j + 2, k + 33, Dungeons.amethystStone);
        world.setBlock(i + 4, j + 2, k + 34, Dungeons.amethystStone);
        world.setBlock(i + 4, j + 2, k + 35, Dungeons.amethystStone);
        world.setBlock(i + 4, j + 2, k + 36, Dungeons.amethystStone);
        world.setBlock(i + 4, j + 2, k + 37, Dungeons.amethystStone);
        world.setBlock(i + 4, j + 3, k + 11, Dungeons.amethystStone);
        world.setBlock(i + 4, j + 3, k + 12, Dungeons.amethystStone);
        world.setBlock(i + 4, j + 3, k + 13, Dungeons.amethystStone);
        world.setBlock(i + 4, j + 3, k + 14, Dungeons.amethystStone);
        world.setBlock(i + 4, j + 3, k + 15, Dungeons.amethystStone);
        world.setBlock(i + 4, j + 3, k + 16, Dungeons.amethystStone);
        world.setBlock(i + 4, j + 3, k + 17, Dungeons.amethystStone);
        world.setBlock(i + 4, j + 3, k + 18, Dungeons.amethystStone);
        world.setBlock(i + 4, j + 3, k + 19, Dungeons.amethystStone);
        world.setBlock(i + 4, j + 3, k + 20, Dungeons.amethystStone);
        world.setBlock(i + 4, j + 3, k + 21, Dungeons.amethystStone);
        world.setBlock(i + 4, j + 3, k + 22, Dungeons.amethystStone);
        world.setBlock(i + 4, j + 3, k + 23, Dungeons.amethystStone);
        world.setBlock(i + 4, j + 3, k + 24, Dungeons.amethystStone);
        world.setBlock(i + 4, j + 3, k + 25, Dungeons.amethystStone);
        world.setBlock(i + 4, j + 3, k + 26, Dungeons.amethystStone);
        world.setBlock(i + 4, j + 3, k + 27, Dungeons.amethystStone);
        world.setBlock(i + 4, j + 3, k + 28, Dungeons.amethystStone);
        world.setBlock(i + 4, j + 3, k + 29, Dungeons.amethystStone);
        world.setBlock(i + 4, j + 3, k + 30, Dungeons.amethystStone);
        world.setBlock(i + 4, j + 3, k + 31, Dungeons.amethystStone);
        world.setBlock(i + 4, j + 3, k + 32, Dungeons.amethystStone);
        world.setBlock(i + 4, j + 3, k + 33, Dungeons.amethystStone);
        world.setBlock(i + 4, j + 3, k + 34, Dungeons.amethystStone);
        world.setBlock(i + 4, j + 3, k + 35, Dungeons.amethystStone);
        world.setBlock(i + 4, j + 3, k + 36, Dungeons.amethystStone);
        world.setBlock(i + 4, j + 3, k + 37, Dungeons.amethystStone);
        world.setBlock(i + 4, j + 4, k + 11, Dungeons.amethystStone);
        world.setBlock(i + 4, j + 4, k + 12, Dungeons.amethystStone);
        world.setBlock(i + 4, j + 4, k + 13, Dungeons.amethystStone);
        world.setBlock(i + 4, j + 4, k + 14, Dungeons.amethystStone);
        world.setBlock(i + 4, j + 4, k + 15, Dungeons.amethystStone);
        world.setBlock(i + 4, j + 4, k + 16, Dungeons.amethystStone);
        world.setBlock(i + 4, j + 4, k + 17, Dungeons.amethystStone);
        world.setBlock(i + 4, j + 4, k + 18, Dungeons.amethystStone);
        world.setBlock(i + 4, j + 4, k + 19, Dungeons.amethystStone);
        world.setBlock(i + 4, j + 4, k + 20, Dungeons.amethystStone);
        world.setBlock(i + 4, j + 4, k + 21, Dungeons.amethystStone);
        world.setBlock(i + 4, j + 4, k + 22, Dungeons.amethystStone);
        world.setBlock(i + 4, j + 4, k + 23, Dungeons.amethystStone);
        world.setBlock(i + 4, j + 4, k + 24, Dungeons.amethystStone);
        world.setBlock(i + 4, j + 4, k + 25, Dungeons.amethystStone);
        world.setBlock(i + 4, j + 4, k + 26, Dungeons.amethystStone);
        world.setBlock(i + 4, j + 4, k + 27, Dungeons.amethystStone);
        world.setBlock(i + 4, j + 4, k + 28, Dungeons.amethystStone);
        world.setBlock(i + 4, j + 4, k + 29, Dungeons.amethystStone);
        world.setBlock(i + 4, j + 4, k + 30, Dungeons.amethystStone);
        world.setBlock(i + 4, j + 4, k + 31, Dungeons.amethystStone);
        world.setBlock(i + 4, j + 4, k + 32, Dungeons.amethystStone);
        world.setBlock(i + 4, j + 4, k + 33, Dungeons.amethystStone);
        world.setBlock(i + 4, j + 4, k + 34, Dungeons.amethystStone);
        world.setBlock(i + 4, j + 4, k + 35, Dungeons.amethystStone);
        world.setBlock(i + 4, j + 4, k + 36, Dungeons.amethystStone);
        world.setBlock(i + 4, j + 4, k + 37, Dungeons.amethystStone);
        world.setBlock(i + 4, j + 5, k + 11, Dungeons.amethystStone);
        world.setBlock(i + 4, j + 5, k + 13, Dungeons.amethystStone);
        world.setBlock(i + 4, j + 5, k + 14, Dungeons.amethystStone);
        world.setBlock(i + 4, j + 5, k + 15, Dungeons.amethystStone);
        world.setBlock(i + 4, j + 5, k + 16, Dungeons.amethystStone);
        world.setBlock(i + 4, j + 5, k + 17, Dungeons.amethystStone);
        world.setBlock(i + 4, j + 5, k + 18, Dungeons.amethystStone);
        world.setBlock(i + 4, j + 5, k + 19, Dungeons.amethystStone);
        world.setBlock(i + 4, j + 5, k + 20, Dungeons.amethystStone);
        world.setBlock(i + 4, j + 5, k + 21, Dungeons.amethystStone);
        world.setBlock(i + 4, j + 5, k + 22, Dungeons.amethystStone);
        world.setBlock(i + 4, j + 5, k + 23, Dungeons.amethystStone);
        world.setBlock(i + 4, j + 5, k + 24, Dungeons.amethystStone);
        world.setBlock(i + 4, j + 5, k + 25, Dungeons.amethystStone);
        world.setBlock(i + 4, j + 5, k + 26, Dungeons.amethystStone);
        world.setBlock(i + 4, j + 5, k + 27, Dungeons.amethystStone);
        world.setBlock(i + 4, j + 5, k + 28, Dungeons.amethystStone);
        world.setBlock(i + 4, j + 5, k + 29, Dungeons.amethystStone);
        world.setBlock(i + 4, j + 5, k + 30, Dungeons.amethystStone);
        world.setBlock(i + 4, j + 5, k + 31, Dungeons.amethystStone);
        world.setBlock(i + 4, j + 5, k + 32, Dungeons.amethystStone);
        world.setBlock(i + 4, j + 5, k + 33, Dungeons.amethystStone);
        world.setBlock(i + 4, j + 5, k + 34, Dungeons.amethystStone);
        world.setBlock(i + 4, j + 5, k + 35, Dungeons.amethystStone);
        world.setBlock(i + 4, j + 5, k + 37, Dungeons.amethystStone);
        world.setBlock(i + 4, j + 6, k + 11, Dungeons.amethystStone);
        world.setBlock(i + 4, j + 6, k + 13, Dungeons.amethystStone);
        world.setBlock(i + 4, j + 6, k + 14, Dungeons.amethystStone);
        world.setBlock(i + 4, j + 6, k + 15, Dungeons.amethystStone);
        world.setBlock(i + 4, j + 6, k + 16, Dungeons.amethystStone);
        world.setBlock(i + 4, j + 6, k + 17, Dungeons.amethystStone);
        world.setBlock(i + 4, j + 6, k + 18, Dungeons.amethystStone);
        world.setBlock(i + 4, j + 6, k + 19, Dungeons.amethystStone);
        world.setBlock(i + 4, j + 6, k + 20, Dungeons.amethystStone);
        world.setBlock(i + 4, j + 6, k + 21, Dungeons.amethystStone);
        world.setBlock(i + 4, j + 6, k + 22, Dungeons.amethystStone);
        world.setBlock(i + 4, j + 6, k + 23, Dungeons.amethystStone);
        world.setBlock(i + 4, j + 6, k + 24, Dungeons.amethystStone);
        world.setBlock(i + 4, j + 6, k + 25, Dungeons.amethystStone);
        world.setBlock(i + 4, j + 6, k + 26, Dungeons.amethystStone);
        world.setBlock(i + 4, j + 6, k + 27, Dungeons.amethystStone);
        world.setBlock(i + 4, j + 6, k + 28, Dungeons.amethystStone);
        world.setBlock(i + 4, j + 6, k + 29, Dungeons.amethystStone);
        world.setBlock(i + 4, j + 6, k + 30, Dungeons.amethystStone);
        world.setBlock(i + 4, j + 6, k + 31, Dungeons.amethystStone);
        world.setBlock(i + 4, j + 6, k + 32, Dungeons.amethystStone);
        world.setBlock(i + 4, j + 6, k + 33, Dungeons.amethystStone);
        world.setBlock(i + 4, j + 6, k + 34, Dungeons.amethystStone);
        world.setBlock(i + 4, j + 6, k + 35, Dungeons.amethystStone);
        world.setBlock(i + 4, j + 6, k + 37, Dungeons.amethystStone);
        world.setBlock(i + 4, j + 7, k + 11, Dungeons.amethystStone);
        world.setBlock(i + 4, j + 7, k + 12, Dungeons.amethystStone);
        world.setBlock(i + 4, j + 7, k + 13, Dungeons.amethystStone);
        world.setBlock(i + 4, j + 7, k + 14, Dungeons.amethystStone);
        world.setBlock(i + 4, j + 7, k + 15, Dungeons.amethystStone);
        world.setBlock(i + 4, j + 7, k + 16, Dungeons.amethystStone);
        world.setBlock(i + 4, j + 7, k + 17, Dungeons.amethystStone);
        world.setBlock(i + 4, j + 7, k + 18, Dungeons.amethystStone);
        world.setBlock(i + 4, j + 7, k + 19, Dungeons.amethystStone);
        world.setBlock(i + 4, j + 7, k + 20, Dungeons.amethystStone);
        world.setBlock(i + 4, j + 7, k + 21, Dungeons.amethystStone);
        world.setBlock(i + 4, j + 7, k + 22, Dungeons.amethystStone);
        world.setBlock(i + 4, j + 7, k + 23, Dungeons.amethystStone);
        world.setBlock(i + 4, j + 7, k + 24, Dungeons.amethystStone);
        world.setBlock(i + 4, j + 7, k + 25, Dungeons.amethystStone);
        world.setBlock(i + 4, j + 7, k + 26, Dungeons.amethystStone);
        world.setBlock(i + 4, j + 7, k + 27, Dungeons.amethystStone);
        world.setBlock(i + 4, j + 7, k + 28, Dungeons.amethystStone);
        world.setBlock(i + 4, j + 7, k + 29, Dungeons.amethystStone);
        world.setBlock(i + 4, j + 7, k + 30, Dungeons.amethystStone);
        world.setBlock(i + 4, j + 7, k + 31, Dungeons.amethystStone);
        world.setBlock(i + 4, j + 7, k + 32, Dungeons.amethystStone);
        world.setBlock(i + 4, j + 7, k + 33, Dungeons.amethystStone);
        world.setBlock(i + 4, j + 7, k + 34, Dungeons.amethystStone);
        world.setBlock(i + 4, j + 7, k + 35, Dungeons.amethystStone);
        world.setBlock(i + 4, j + 7, k + 36, Dungeons.amethystStone);
        world.setBlock(i + 4, j + 7, k + 37, Dungeons.amethystStone);
        world.setBlock(i + 4, j + 8, k + 11, Dungeons.amethystStone);
        world.setBlock(i + 4, j + 8, k + 12, Dungeons.amethystStone);
        world.setBlock(i + 4, j + 8, k + 13, Dungeons.amethystStone);
        world.setBlock(i + 4, j + 8, k + 14, Dungeons.amethystStone);
        world.setBlock(i + 4, j + 8, k + 15, Dungeons.amethystStone);
        world.setBlock(i + 4, j + 8, k + 16, Dungeons.amethystStone);
        world.setBlock(i + 4, j + 8, k + 17, Dungeons.amethystStone);
        world.setBlock(i + 4, j + 8, k + 18, Dungeons.amethystStone);
        world.setBlock(i + 4, j + 8, k + 19, Dungeons.amethystStone);
        world.setBlock(i + 4, j + 8, k + 20, Dungeons.amethystStone);
        world.setBlock(i + 4, j + 8, k + 21, Dungeons.amethystStone);
        world.setBlock(i + 4, j + 8, k + 22, Dungeons.amethystStone);
        world.setBlock(i + 4, j + 8, k + 23, Dungeons.amethystStone);
        world.setBlock(i + 4, j + 8, k + 24, Dungeons.amethystStone);
        world.setBlock(i + 4, j + 8, k + 25, Dungeons.amethystStone);
        world.setBlock(i + 4, j + 8, k + 26, Dungeons.amethystStone);
        world.setBlock(i + 4, j + 8, k + 27, Dungeons.amethystStone);
        world.setBlock(i + 4, j + 8, k + 28, Dungeons.amethystStone);
        world.setBlock(i + 4, j + 8, k + 29, Dungeons.amethystStone);
        world.setBlock(i + 4, j + 8, k + 30, Dungeons.amethystStone);
        world.setBlock(i + 4, j + 8, k + 31, Dungeons.amethystStone);
        world.setBlock(i + 4, j + 8, k + 32, Dungeons.amethystStone);
        world.setBlock(i + 4, j + 8, k + 33, Dungeons.amethystStone);
        world.setBlock(i + 4, j + 8, k + 34, Dungeons.amethystStone);
        world.setBlock(i + 4, j + 8, k + 35, Dungeons.amethystStone);
        world.setBlock(i + 4, j + 8, k + 36, Dungeons.amethystStone);
        world.setBlock(i + 4, j + 8, k + 37, Dungeons.amethystStone);
        world.setBlock(i + 4, j + 9, k + 11, Dungeons.amethystStone);
        world.setBlock(i + 4, j + 9, k + 12, Dungeons.amethystStone);
        world.setBlock(i + 4, j + 9, k + 13, Dungeons.amethystStone);
        world.setBlock(i + 4, j + 9, k + 14, Dungeons.amethystStone);
        world.setBlock(i + 4, j + 9, k + 15, Dungeons.amethystStone);
        world.setBlock(i + 4, j + 9, k + 16, Dungeons.amethystStone);
        world.setBlock(i + 4, j + 9, k + 17, Dungeons.amethystStone);
        world.setBlock(i + 4, j + 9, k + 18, Dungeons.amethystStone);
        world.setBlock(i + 4, j + 9, k + 19, Dungeons.amethystStone);
        world.setBlock(i + 4, j + 9, k + 20, Dungeons.amethystStone);
        world.setBlock(i + 4, j + 9, k + 21, Dungeons.amethystStone);
        world.setBlock(i + 4, j + 9, k + 22, Dungeons.amethystStone);
        world.setBlock(i + 4, j + 9, k + 23, Dungeons.amethystStone);
        world.setBlock(i + 4, j + 9, k + 24, Dungeons.amethystStone);
        world.setBlock(i + 4, j + 9, k + 25, Dungeons.amethystStone);
        world.setBlock(i + 4, j + 9, k + 26, Dungeons.amethystStone);
        world.setBlock(i + 4, j + 9, k + 27, Dungeons.amethystStone);
        world.setBlock(i + 4, j + 9, k + 28, Dungeons.amethystStone);
        world.setBlock(i + 4, j + 9, k + 29, Dungeons.amethystStone);
        world.setBlock(i + 4, j + 9, k + 30, Dungeons.amethystStone);
        world.setBlock(i + 4, j + 9, k + 31, Dungeons.amethystStone);
        world.setBlock(i + 4, j + 9, k + 32, Dungeons.amethystStone);
        world.setBlock(i + 4, j + 9, k + 33, Dungeons.amethystStone);
        world.setBlock(i + 4, j + 9, k + 34, Dungeons.amethystStone);
        world.setBlock(i + 4, j + 9, k + 35, Dungeons.amethystStone);
        world.setBlock(i + 4, j + 9, k + 36, Dungeons.amethystStone);
        world.setBlock(i + 4, j + 9, k + 37, Dungeons.amethystStone);
        world.setBlock(i + 4, j + 10, k + 11, Dungeons.amethystStone);
        world.setBlock(i + 4, j + 10, k + 12, Dungeons.amethystStone);
        world.setBlock(i + 4, j + 10, k + 13, Dungeons.amethystStone);
        world.setBlock(i + 4, j + 10, k + 14, Dungeons.amethystStone);
        world.setBlock(i + 4, j + 10, k + 15, Dungeons.amethystStone);
        world.setBlock(i + 4, j + 10, k + 16, Dungeons.amethystStone);
        world.setBlock(i + 4, j + 10, k + 17, Dungeons.amethystStone);
        world.setBlock(i + 4, j + 10, k + 18, Dungeons.amethystStone);
        world.setBlock(i + 4, j + 10, k + 19, Dungeons.amethystStone);
        world.setBlock(i + 4, j + 10, k + 20, Dungeons.amethystStone);
        world.setBlock(i + 4, j + 10, k + 21, Dungeons.amethystStone);
        world.setBlock(i + 4, j + 10, k + 22, Dungeons.amethystStone);
        world.setBlock(i + 4, j + 10, k + 23, Dungeons.amethystStone);
        world.setBlock(i + 4, j + 10, k + 24, Dungeons.amethystStone);
        world.setBlock(i + 4, j + 10, k + 25, Dungeons.amethystStone);
        world.setBlock(i + 4, j + 10, k + 26, Dungeons.amethystStone);
        world.setBlock(i + 4, j + 10, k + 27, Dungeons.amethystStone);
        world.setBlock(i + 4, j + 10, k + 28, Dungeons.amethystStone);
        world.setBlock(i + 4, j + 10, k + 29, Dungeons.amethystStone);
        world.setBlock(i + 4, j + 10, k + 30, Dungeons.amethystStone);
        world.setBlock(i + 4, j + 10, k + 31, Dungeons.amethystStone);
        world.setBlock(i + 4, j + 10, k + 32, Dungeons.amethystStone);
        world.setBlock(i + 4, j + 10, k + 33, Dungeons.amethystStone);
        world.setBlock(i + 4, j + 10, k + 34, Dungeons.amethystStone);
        world.setBlock(i + 4, j + 10, k + 35, Dungeons.amethystStone);
        world.setBlock(i + 4, j + 10, k + 36, Dungeons.amethystStone);
        world.setBlock(i + 4, j + 10, k + 37, Dungeons.amethystStone);
        world.setBlock(i + 5, j, k + 8, Dungeons.amethystStone);
        world.setBlock(i + 5, j, k + 9, Dungeons.amethystStone);
        world.setBlock(i + 5, j, k + 10, Dungeons.amethystStone);
        world.setBlock(i + 5, j, k + 11, Dungeons.amethystStone);
        world.setBlock(i + 5, j, k + 12, Dungeons.amethystStone);
        world.setBlock(i + 5, j, k + 13, Dungeons.amethystStone);
        world.setBlock(i + 5, j, k + 14, Dungeons.amethystStone);
        world.setBlock(i + 5, j, k + 15, Dungeons.amethystStone);
        world.setBlock(i + 5, j, k + 16, Dungeons.amethystStone);
        world.setBlock(i + 5, j, k + 17, Dungeons.amethystStone);
        world.setBlock(i + 5, j, k + 18, Dungeons.amethystStone);
        world.setBlock(i + 5, j, k + 19, Dungeons.amethystStone);
        world.setBlock(i + 5, j, k + 20, Dungeons.amethystStone);
        world.setBlock(i + 5, j, k + 21, Dungeons.amethystStone);
        world.setBlock(i + 5, j, k + 22, Dungeons.amethystStone);
        world.setBlock(i + 5, j, k + 23, Dungeons.amethystStone);
        world.setBlock(i + 5, j, k + 24, Dungeons.amethystStone);
        world.setBlock(i + 5, j, k + 25, Dungeons.amethystStone);
        world.setBlock(i + 5, j, k + 26, Dungeons.amethystStone);
        world.setBlock(i + 5, j, k + 27, Dungeons.amethystStone);
        world.setBlock(i + 5, j, k + 28, Dungeons.amethystStone);
        world.setBlock(i + 5, j, k + 29, Dungeons.amethystStone);
        world.setBlock(i + 5, j, k + 30, Dungeons.amethystStone);
        world.setBlock(i + 5, j, k + 31, Dungeons.amethystStone);
        world.setBlock(i + 5, j, k + 32, Dungeons.amethystStone);
        world.setBlock(i + 5, j, k + 33, Dungeons.amethystStone);
        world.setBlock(i + 5, j, k + 34, Dungeons.amethystStone);
        world.setBlock(i + 5, j, k + 35, Dungeons.amethystStone);
        world.setBlock(i + 5, j, k + 36, Dungeons.amethystStone);
        world.setBlock(i + 5, j, k + 37, Dungeons.amethystStone);
        world.setBlock(i + 5, j, k + 38, Dungeons.amethystStone);
        world.setBlock(i + 5, j + 1, k + 8, Dungeons.amethystStone);
        world.setBlock(i + 5, j + 1, k + 9, Dungeons.amethystStone);
        world.setBlock(i + 5, j + 1, k + 10, Dungeons.amethystStone);
        world.setBlock(i + 5, j + 1, k + 11, Dungeons.amethystStone);
        world.setBlock(i + 5, j + 1, k + 12, Dungeons.amethystStone);
        world.setBlock(i + 5, j + 1, k + 13, Dungeons.amethystStone);
        world.setBlock(i + 5, j + 1, k + 14, Dungeons.amethystStone);
        world.setBlock(i + 5, j + 1, k + 15, Dungeons.amethystStone);
        world.setBlock(i + 5, j + 1, k + 16, Dungeons.amethystStone);
        world.setBlock(i + 5, j + 1, k + 17, Dungeons.amethystStone);
        world.setBlock(i + 5, j + 1, k + 18, Dungeons.amethystStone);
        world.setBlock(i + 5, j + 1, k + 19, Dungeons.amethystStone);
        world.setBlock(i + 5, j + 1, k + 20, Dungeons.amethystStone);
        world.setBlock(i + 5, j + 1, k + 21, Dungeons.amethystStone);
        world.setBlock(i + 5, j + 1, k + 22, Dungeons.amethystStone);
        world.setBlock(i + 5, j + 1, k + 23, Dungeons.amethystStone);
        world.setBlock(i + 5, j + 1, k + 24, Dungeons.amethystStone);
        world.setBlock(i + 5, j + 1, k + 25, Dungeons.amethystStone);
        world.setBlock(i + 5, j + 1, k + 26, Dungeons.amethystStone);
        world.setBlock(i + 5, j + 1, k + 27, Dungeons.amethystStone);
        world.setBlock(i + 5, j + 1, k + 28, Dungeons.amethystStone);
        world.setBlock(i + 5, j + 1, k + 29, Dungeons.amethystStone);
        world.setBlock(i + 5, j + 1, k + 30, Dungeons.amethystStone);
        world.setBlock(i + 5, j + 1, k + 31, Dungeons.amethystStone);
        world.setBlock(i + 5, j + 1, k + 32, Dungeons.amethystStone);
        world.setBlock(i + 5, j + 1, k + 33, Dungeons.amethystStone);
        world.setBlock(i + 5, j + 1, k + 34, Dungeons.amethystStone);
        world.setBlock(i + 5, j + 1, k + 35, Dungeons.amethystStone);
        world.setBlock(i + 5, j + 1, k + 36, Dungeons.amethystStone);
        world.setBlock(i + 5, j + 1, k + 37, Dungeons.amethystStone);
        world.setBlock(i + 5, j + 1, k + 38, Dungeons.amethystStone);
        world.setBlock(i + 5, j + 2, k + 8, Dungeons.amethystStone);
        world.setBlock(i + 5, j + 2, k + 9, Dungeons.amethystStone);
        world.setBlock(i + 5, j + 2, k + 10, Dungeons.amethystStone);
        world.setBlock(i + 5, j + 2, k + 11, Dungeons.amethystStone);
        world.setBlock(i + 5, j + 2, k + 12, Dungeons.amethystStone);
        world.setBlock(i + 5, j + 2, k + 13, Dungeons.amethystStone);
        world.setBlock(i + 5, j + 2, k + 14, Dungeons.amethystStone);
        world.setBlock(i + 5, j + 2, k + 15, Dungeons.amethystStone);
        world.setBlock(i + 5, j + 2, k + 16, Dungeons.amethystStone);
        world.setBlock(i + 5, j + 2, k + 17, Dungeons.amethystStone);
        world.setBlock(i + 5, j + 2, k + 18, Dungeons.amethystStone);
        world.setBlock(i + 5, j + 2, k + 19, Dungeons.amethystStone);
        world.setBlock(i + 5, j + 2, k + 20, Dungeons.amethystStone);
        world.setBlock(i + 5, j + 2, k + 21, Dungeons.amethystStone);
        world.setBlock(i + 5, j + 2, k + 22, Dungeons.amethystStone);
        world.setBlock(i + 5, j + 2, k + 23, Dungeons.amethystStone);
        world.setBlock(i + 5, j + 2, k + 24, Dungeons.amethystStone);
        world.setBlock(i + 5, j + 2, k + 25, Dungeons.amethystStone);
        world.setBlock(i + 5, j + 2, k + 26, Dungeons.amethystStone);
        world.setBlock(i + 5, j + 2, k + 27, Dungeons.amethystStone);
        world.setBlock(i + 5, j + 2, k + 28, Dungeons.amethystStone);
        world.setBlock(i + 5, j + 2, k + 29, Dungeons.amethystStone);
        world.setBlock(i + 5, j + 2, k + 30, Dungeons.amethystStone);
        world.setBlock(i + 5, j + 2, k + 31, Dungeons.amethystStone);
        world.setBlock(i + 5, j + 2, k + 32, Dungeons.amethystStone);
        world.setBlock(i + 5, j + 2, k + 33, Dungeons.amethystStone);
        world.setBlock(i + 5, j + 2, k + 34, Dungeons.amethystStone);
        world.setBlock(i + 5, j + 2, k + 35, Dungeons.amethystStone);
        world.setBlock(i + 5, j + 2, k + 36, Dungeons.amethystStone);
        world.setBlock(i + 5, j + 2, k + 37, Dungeons.amethystStone);
        world.setBlock(i + 5, j + 2, k + 38, Dungeons.amethystStone);
        world.setBlock(i + 5, j + 3, k + 8, Dungeons.amethystStone);
        world.setBlock(i + 5, j + 3, k + 9, Dungeons.amethystStone);
        world.setBlock(i + 5, j + 3, k + 10, Dungeons.amethystStone);
        world.setBlock(i + 5, j + 3, k + 11, Dungeons.amethystStone);
        world.setBlock(i + 5, j + 3, k + 13, Dungeons.amethystStone);
        world.setBlock(i + 5, j + 3, k + 14, Dungeons.amethystStone);
        world.setBlock(i + 5, j + 3, k + 15, Dungeons.amethystStone);
        world.setBlock(i + 5, j + 3, k + 16, Dungeons.amethystStone);
        world.setBlock(i + 5, j + 3, k + 17, Dungeons.amethystStone);
        world.setBlock(i + 5, j + 3, k + 18, Dungeons.amethystStone);
        world.setBlock(i + 5, j + 3, k + 19, Dungeons.amethystStone);
        world.setBlock(i + 5, j + 3, k + 20, Dungeons.amethystStone);
        world.setBlock(i + 5, j + 3, k + 21, Dungeons.amethystStone);
        world.setBlock(i + 5, j + 3, k + 22, Dungeons.amethystStone);
        world.setBlock(i + 5, j + 3, k + 23, Dungeons.amethystStone);
        world.setBlock(i + 5, j + 3, k + 24, Dungeons.amethystStone);
        world.setBlock(i + 5, j + 3, k + 25, Dungeons.amethystStone);
        world.setBlock(i + 5, j + 3, k + 26, Dungeons.amethystStone);
        world.setBlock(i + 5, j + 3, k + 27, Dungeons.amethystStone);
        world.setBlock(i + 5, j + 3, k + 28, Dungeons.amethystStone);
        world.setBlock(i + 5, j + 3, k + 29, Dungeons.amethystStone);
        world.setBlock(i + 5, j + 3, k + 30, Dungeons.amethystStone);
        world.setBlock(i + 5, j + 3, k + 31, Dungeons.amethystStone);
        world.setBlock(i + 5, j + 3, k + 32, Dungeons.amethystStone);
        world.setBlock(i + 5, j + 3, k + 33, Dungeons.amethystStone);
        world.setBlock(i + 5, j + 3, k + 34, Dungeons.amethystStone);
        world.setBlock(i + 5, j + 3, k + 35, Dungeons.amethystStone);
        world.setBlock(i + 5, j + 3, k + 37, Dungeons.amethystStone);
        world.setBlock(i + 5, j + 3, k + 38, Dungeons.amethystStone);
        world.setBlock(i + 5, j + 4, k + 8, Dungeons.amethystStone);
        world.setBlock(i + 5, j + 4, k + 9, Dungeons.amethystStone);
        world.setBlock(i + 5, j + 4, k + 10, Dungeons.amethystStone);
        world.setBlock(i + 5, j + 4, k + 11, Dungeons.amethystStone);
        world.setBlock(i + 5, j + 4, k + 13, Dungeons.amethystStone);
        world.setBlock(i + 5, j + 4, k + 14, Dungeons.amethystStone);
        world.setBlock(i + 5, j + 4, k + 15, Dungeons.amethystStone);
        world.setBlock(i + 5, j + 4, k + 16, Dungeons.amethystStone);
        world.setBlock(i + 5, j + 4, k + 17, Dungeons.amethystStone);
        world.setBlock(i + 5, j + 4, k + 18, Dungeons.amethystStone);
        world.setBlock(i + 5, j + 4, k + 19, Dungeons.amethystStone);
        world.setBlock(i + 5, j + 4, k + 20, Dungeons.amethystStone);
        world.setBlock(i + 5, j + 4, k + 21, Dungeons.amethystStone);
        world.setBlock(i + 5, j + 4, k + 22, Dungeons.amethystStone);
        world.setBlock(i + 5, j + 4, k + 23, Dungeons.amethystStone);
        world.setBlock(i + 5, j + 4, k + 24, Dungeons.amethystStone);
        world.setBlock(i + 5, j + 4, k + 25, Dungeons.amethystStone);
        world.setBlock(i + 5, j + 4, k + 26, Dungeons.amethystStone);
        world.setBlock(i + 5, j + 4, k + 27, Dungeons.amethystStone);
        world.setBlock(i + 5, j + 4, k + 28, Dungeons.amethystStone);
        world.setBlock(i + 5, j + 4, k + 29, Dungeons.amethystStone);
        world.setBlock(i + 5, j + 4, k + 30, Dungeons.amethystStone);
        world.setBlock(i + 5, j + 4, k + 31, Dungeons.amethystStone);
        world.setBlock(i + 5, j + 4, k + 32, Dungeons.amethystStone);
        world.setBlock(i + 5, j + 4, k + 33, Dungeons.amethystStone);
        world.setBlock(i + 5, j + 4, k + 34, Dungeons.amethystStone);
        world.setBlock(i + 5, j + 4, k + 35, Dungeons.amethystStone);
        world.setBlock(i + 5, j + 4, k + 37, Dungeons.amethystStone);
        world.setBlock(i + 5, j + 4, k + 38, Dungeons.amethystStone);
        world.setBlock(i + 5, j + 5, k + 8, Dungeons.amethystStone);
        world.setBlock(i + 5, j + 5, k + 10, Dungeons.amethystStone);
        world.setBlock(i + 5, j + 5, k + 11, Dungeons.amethystStone);
        world.setBlock(i + 5, j + 5, k + 13, Dungeons.amethystStone);
        world.setBlock(i + 5, j + 5, k + 14, Dungeons.amethystStone);
        world.setBlock(i + 5, j + 5, k + 15, Dungeons.amethystStone);
        world.setBlock(i + 5, j + 5, k + 16, Dungeons.amethystStone);
        world.setBlock(i + 5, j + 5, k + 17, Dungeons.amethystStone);
        world.setBlock(i + 5, j + 5, k + 18, Dungeons.amethystStone);
        world.setBlock(i + 5, j + 5, k + 19, Dungeons.amethystStone);
        world.setBlock(i + 5, j + 5, k + 20, Dungeons.amethystStone);
        world.setBlock(i + 5, j + 5, k + 21, Dungeons.amethystStone);
        world.setBlock(i + 5, j + 5, k + 22, Dungeons.amethystStone);
        world.setBlock(i + 5, j + 5, k + 23, Dungeons.amethystStone);
        world.setBlock(i + 5, j + 5, k + 24, Dungeons.amethystStone);
        world.setBlock(i + 5, j + 5, k + 25, Dungeons.amethystStone);
        world.setBlock(i + 5, j + 5, k + 26, Dungeons.amethystStone);
        world.setBlock(i + 5, j + 5, k + 27, Dungeons.amethystStone);
        world.setBlock(i + 5, j + 5, k + 28, Dungeons.amethystStone);
        world.setBlock(i + 5, j + 5, k + 29, Dungeons.amethystStone);
        world.setBlock(i + 5, j + 5, k + 30, Dungeons.amethystStone);
        world.setBlock(i + 5, j + 5, k + 31, Dungeons.amethystStone);
        world.setBlock(i + 5, j + 5, k + 32, Dungeons.amethystStone);
        world.setBlock(i + 5, j + 5, k + 33, Dungeons.amethystStone);
        world.setBlock(i + 5, j + 5, k + 34, Dungeons.amethystStone);
        world.setBlock(i + 5, j + 5, k + 35, Dungeons.amethystStone);
        world.setBlock(i + 5, j + 5, k + 37, Dungeons.amethystStone);
        world.setBlock(i + 5, j + 5, k + 38, Dungeons.amethystStone);
        world.setBlock(i + 5, j + 6, k + 8, Dungeons.amethystStone);
        world.setBlock(i + 5, j + 6, k + 10, Dungeons.amethystStone);
        world.setBlock(i + 5, j + 6, k + 11, Dungeons.amethystStone);
        world.setBlock(i + 5, j + 6, k + 13, Dungeons.amethystStone);
        world.setBlock(i + 5, j + 6, k + 14, Dungeons.amethystStone);
        world.setBlock(i + 5, j + 6, k + 15, Dungeons.amethystStone);
        world.setBlock(i + 5, j + 6, k + 16, Dungeons.amethystStone);
        world.setBlock(i + 5, j + 6, k + 17, Dungeons.amethystStone);
        world.setBlock(i + 5, j + 6, k + 18, Dungeons.amethystStone);
        world.setBlock(i + 5, j + 6, k + 19, Dungeons.amethystStone);
        world.setBlock(i + 5, j + 6, k + 20, Dungeons.amethystStone);
        world.setBlock(i + 5, j + 6, k + 21, Dungeons.amethystStone);
        world.setBlock(i + 5, j + 6, k + 22, Dungeons.amethystStone);
        world.setBlock(i + 5, j + 6, k + 23, Dungeons.amethystStone);
        world.setBlock(i + 5, j + 6, k + 24, Dungeons.amethystStone);
        world.setBlock(i + 5, j + 6, k + 25, Dungeons.amethystStone);
        world.setBlock(i + 5, j + 6, k + 26, Dungeons.amethystStone);
        world.setBlock(i + 5, j + 6, k + 27, Dungeons.amethystStone);
        world.setBlock(i + 5, j + 6, k + 28, Dungeons.amethystStone);
        world.setBlock(i + 5, j + 6, k + 29, Dungeons.amethystStone);
        world.setBlock(i + 5, j + 6, k + 30, Dungeons.amethystStone);
        world.setBlock(i + 5, j + 6, k + 31, Dungeons.amethystStone);
        world.setBlock(i + 5, j + 6, k + 32, Dungeons.amethystStone);
        world.setBlock(i + 5, j + 6, k + 33, Dungeons.amethystStone);
        world.setBlock(i + 5, j + 6, k + 34, Dungeons.amethystStone);
        world.setBlock(i + 5, j + 6, k + 35, Dungeons.amethystStone);
        world.setBlock(i + 5, j + 6, k + 37, Dungeons.amethystStone);
        world.setBlock(i + 5, j + 6, k + 38, Dungeons.amethystStone);
        world.setBlock(i + 5, j + 7, k + 8, Dungeons.amethystStone);
        world.setBlock(i + 5, j + 7, k + 9, Dungeons.amethystStone);
        world.setBlock(i + 5, j + 7, k + 10, Dungeons.amethystStone);
        world.setBlock(i + 5, j + 7, k + 11, Dungeons.amethystStone);
        world.setBlock(i + 5, j + 7, k + 12, Dungeons.amethystStone);
        world.setBlock(i + 5, j + 7, k + 13, Dungeons.amethystStone);
        world.setBlock(i + 5, j + 7, k + 14, Dungeons.amethystStone);
        world.setBlock(i + 5, j + 7, k + 15, Dungeons.amethystStone);
        world.setBlock(i + 5, j + 7, k + 16, Dungeons.amethystStone);
        world.setBlock(i + 5, j + 7, k + 17, Dungeons.amethystStone);
        world.setBlock(i + 5, j + 7, k + 18, Dungeons.amethystStone);
        world.setBlock(i + 5, j + 7, k + 19, Dungeons.amethystStone);
        world.setBlock(i + 5, j + 7, k + 20, Dungeons.amethystStone);
        world.setBlock(i + 5, j + 7, k + 21, Dungeons.amethystStone);
        world.setBlock(i + 5, j + 7, k + 22, Dungeons.amethystStone);
        world.setBlock(i + 5, j + 7, k + 23, Dungeons.amethystStone);
        world.setBlock(i + 5, j + 7, k + 24, Dungeons.amethystStone);
        world.setBlock(i + 5, j + 7, k + 25, Dungeons.amethystStone);
        world.setBlock(i + 5, j + 7, k + 26, Dungeons.amethystStone);
        world.setBlock(i + 5, j + 7, k + 27, Dungeons.amethystStone);
        world.setBlock(i + 5, j + 7, k + 28, Dungeons.amethystStone);
        world.setBlock(i + 5, j + 7, k + 29, Dungeons.amethystStone);
        world.setBlock(i + 5, j + 7, k + 30, Dungeons.amethystStone);
        world.setBlock(i + 5, j + 7, k + 31, Dungeons.amethystStone);
        world.setBlock(i + 5, j + 7, k + 32, Dungeons.amethystStone);
        world.setBlock(i + 5, j + 7, k + 33, Dungeons.amethystStone);
        world.setBlock(i + 5, j + 7, k + 34, Dungeons.amethystStone);
        world.setBlock(i + 5, j + 7, k + 35, Dungeons.amethystStone);
        world.setBlock(i + 5, j + 7, k + 36, Dungeons.amethystStone);
        world.setBlock(i + 5, j + 7, k + 37, Dungeons.amethystStone);
        world.setBlock(i + 5, j + 7, k + 38, Dungeons.amethystStone);
        world.setBlock(i + 5, j + 8, k + 8, Dungeons.amethystStone);
        world.setBlock(i + 5, j + 8, k + 9, Dungeons.amethystStone);
        world.setBlock(i + 5, j + 8, k + 10, Dungeons.amethystStone);
        world.setBlock(i + 5, j + 8, k + 11, Dungeons.amethystStone);
        world.setBlock(i + 5, j + 8, k + 12, Dungeons.amethystStone);
        world.setBlock(i + 5, j + 8, k + 13, Dungeons.amethystStone);
        world.setBlock(i + 5, j + 8, k + 14, Dungeons.amethystStone);
        world.setBlock(i + 5, j + 8, k + 15, Dungeons.amethystStone);
        world.setBlock(i + 5, j + 8, k + 16, Dungeons.amethystStone);
        world.setBlock(i + 5, j + 8, k + 17, Dungeons.amethystStone);
        world.setBlock(i + 5, j + 8, k + 18, Dungeons.amethystStone);
        world.setBlock(i + 5, j + 8, k + 19, Dungeons.amethystStone);
        world.setBlock(i + 5, j + 8, k + 20, Dungeons.amethystStone);
        world.setBlock(i + 5, j + 8, k + 21, Dungeons.amethystStone);
        world.setBlock(i + 5, j + 8, k + 22, Dungeons.amethystStone);
        world.setBlock(i + 5, j + 8, k + 23, Dungeons.amethystStone);
        world.setBlock(i + 5, j + 8, k + 24, Dungeons.amethystStone);
        world.setBlock(i + 5, j + 8, k + 25, Dungeons.amethystStone);
        world.setBlock(i + 5, j + 8, k + 26, Dungeons.amethystStone);
        world.setBlock(i + 5, j + 8, k + 27, Dungeons.amethystStone);
        world.setBlock(i + 5, j + 8, k + 28, Dungeons.amethystStone);
        world.setBlock(i + 5, j + 8, k + 29, Dungeons.amethystStone);
        world.setBlock(i + 5, j + 8, k + 30, Dungeons.amethystStone);
        world.setBlock(i + 5, j + 8, k + 31, Dungeons.amethystStone);
        world.setBlock(i + 5, j + 8, k + 32, Dungeons.amethystStone);
        world.setBlock(i + 5, j + 8, k + 33, Dungeons.amethystStone);
        world.setBlock(i + 5, j + 8, k + 34, Dungeons.amethystStone);
        world.setBlock(i + 5, j + 8, k + 35, Dungeons.amethystStone);
        world.setBlock(i + 5, j + 8, k + 36, Dungeons.amethystStone);
        world.setBlock(i + 5, j + 8, k + 37, Dungeons.amethystStone);
        world.setBlock(i + 5, j + 8, k + 38, Dungeons.amethystStone);
        world.setBlock(i + 5, j + 9, k + 8, Dungeons.amethystStone);
        world.setBlock(i + 5, j + 9, k + 9, Dungeons.amethystStone);
        world.setBlock(i + 5, j + 9, k + 10, Dungeons.amethystStone);
        world.setBlock(i + 5, j + 9, k + 11, Dungeons.amethystStone);
        world.setBlock(i + 5, j + 9, k + 12, Dungeons.amethystStone);
        world.setBlock(i + 5, j + 9, k + 13, Dungeons.amethystStone);
        world.setBlock(i + 5, j + 9, k + 14, Dungeons.amethystStone);
        world.setBlock(i + 5, j + 9, k + 15, Dungeons.amethystStone);
        world.setBlock(i + 5, j + 9, k + 16, Dungeons.amethystStone);
        world.setBlock(i + 5, j + 9, k + 17, Dungeons.amethystStone);
        world.setBlock(i + 5, j + 9, k + 18, Dungeons.amethystStone);
        world.setBlock(i + 5, j + 9, k + 19, Dungeons.amethystStone);
        world.setBlock(i + 5, j + 9, k + 20, Dungeons.amethystStone);
        world.setBlock(i + 5, j + 9, k + 21, Dungeons.amethystStone);
        world.setBlock(i + 5, j + 9, k + 22, Dungeons.amethystStone);
        world.setBlock(i + 5, j + 9, k + 23, Dungeons.amethystStone);
        world.setBlock(i + 5, j + 9, k + 24, Dungeons.amethystStone);
        world.setBlock(i + 5, j + 9, k + 25, Dungeons.amethystStone);
        world.setBlock(i + 5, j + 9, k + 26, Dungeons.amethystStone);
        world.setBlock(i + 5, j + 9, k + 27, Dungeons.amethystStone);
        world.setBlock(i + 5, j + 9, k + 28, Dungeons.amethystStone);
        world.setBlock(i + 5, j + 9, k + 29, Dungeons.amethystStone);
        world.setBlock(i + 5, j + 9, k + 30, Dungeons.amethystStone);
        world.setBlock(i + 5, j + 9, k + 31, Dungeons.amethystStone);
        world.setBlock(i + 5, j + 9, k + 32, Dungeons.amethystStone);
        world.setBlock(i + 5, j + 9, k + 33, Dungeons.amethystStone);
        world.setBlock(i + 5, j + 9, k + 34, Dungeons.amethystStone);
        world.setBlock(i + 5, j + 9, k + 35, Dungeons.amethystStone);
        world.setBlock(i + 5, j + 9, k + 36, Dungeons.amethystStone);
        world.setBlock(i + 5, j + 9, k + 37, Dungeons.amethystStone);
        world.setBlock(i + 5, j + 9, k + 38, Dungeons.amethystStone);
        world.setBlock(i + 5, j + 10, k + 8, Dungeons.amethystStone);
        world.setBlock(i + 5, j + 10, k + 9, Dungeons.amethystStone);
        world.setBlock(i + 5, j + 10, k + 10, Dungeons.amethystStone);
        world.setBlock(i + 5, j + 10, k + 11, Dungeons.amethystStone);
        world.setBlock(i + 5, j + 10, k + 12, Dungeons.amethystStone);
        world.setBlock(i + 5, j + 10, k + 13, Dungeons.amethystStone);
        world.setBlock(i + 5, j + 10, k + 14, Dungeons.amethystStone);
        world.setBlock(i + 5, j + 10, k + 15, Dungeons.amethystStone);
        world.setBlock(i + 5, j + 10, k + 16, Dungeons.amethystStone);
        world.setBlock(i + 5, j + 10, k + 17, Dungeons.amethystStone);
        world.setBlock(i + 5, j + 10, k + 18, Dungeons.amethystStone);
        world.setBlock(i + 5, j + 10, k + 19, Dungeons.amethystStone);
        world.setBlock(i + 5, j + 10, k + 20, Dungeons.amethystStone);
        world.setBlock(i + 5, j + 10, k + 21, Dungeons.amethystStone);
        world.setBlock(i + 5, j + 10, k + 22, Dungeons.amethystStone);
        world.setBlock(i + 5, j + 10, k + 23, Dungeons.amethystStone);
        world.setBlock(i + 5, j + 10, k + 24, Dungeons.amethystStone);
        world.setBlock(i + 5, j + 10, k + 25, Dungeons.amethystStone);
        world.setBlock(i + 5, j + 10, k + 26, Dungeons.amethystStone);
        world.setBlock(i + 5, j + 10, k + 27, Dungeons.amethystStone);
        world.setBlock(i + 5, j + 10, k + 28, Dungeons.amethystStone);
        world.setBlock(i + 5, j + 10, k + 29, Dungeons.amethystStone);
        world.setBlock(i + 5, j + 10, k + 30, Dungeons.amethystStone);
        world.setBlock(i + 5, j + 10, k + 31, Dungeons.amethystStone);
        world.setBlock(i + 5, j + 10, k + 32, Dungeons.amethystStone);
        world.setBlock(i + 5, j + 10, k + 33, Dungeons.amethystStone);
        world.setBlock(i + 5, j + 10, k + 34, Dungeons.amethystStone);
        world.setBlock(i + 5, j + 10, k + 35, Dungeons.amethystStone);
        world.setBlock(i + 5, j + 10, k + 36, Dungeons.amethystStone);
        world.setBlock(i + 5, j + 10, k + 37, Dungeons.amethystStone);
        world.setBlock(i + 5, j + 10, k + 38, Dungeons.amethystStone);
        world.setBlock(i + 6, j, k + 7, Dungeons.amethystStone);
        world.setBlock(i + 6, j, k + 8, Dungeons.amethystStone);
        world.setBlock(i + 6, j, k + 9, Dungeons.amethystStone);
        world.setBlock(i + 6, j, k + 10, Dungeons.amethystStone);
        world.setBlock(i + 6, j, k + 11, Dungeons.amethystStone);
        world.setBlock(i + 6, j, k + 12, Dungeons.amethystStone);
        world.setBlock(i + 6, j, k + 13, Dungeons.amethystStone);
        world.setBlock(i + 6, j, k + 14, Dungeons.amethystStone);
        world.setBlock(i + 6, j, k + 15, Dungeons.amethystStone);
        world.setBlock(i + 6, j, k + 16, Dungeons.amethystStone);
        world.setBlock(i + 6, j, k + 17, Dungeons.amethystStone);
        world.setBlock(i + 6, j, k + 18, Dungeons.amethystStone);
        world.setBlock(i + 6, j, k + 19, Dungeons.amethystStone);
        world.setBlock(i + 6, j, k + 20, Dungeons.amethystStone);
        world.setBlock(i + 6, j, k + 21, Dungeons.amethystStone);
        world.setBlock(i + 6, j, k + 22, Dungeons.amethystStone);
        world.setBlock(i + 6, j, k + 23, Dungeons.amethystStone);
        world.setBlock(i + 6, j, k + 24, Dungeons.amethystStone);
        world.setBlock(i + 6, j, k + 25, Dungeons.amethystStone);
        world.setBlock(i + 6, j, k + 26, Dungeons.amethystStone);
        world.setBlock(i + 6, j, k + 27, Dungeons.amethystStone);
        world.setBlock(i + 6, j, k + 28, Dungeons.amethystStone);
        world.setBlock(i + 6, j, k + 29, Dungeons.amethystStone);
        world.setBlock(i + 6, j, k + 30, Dungeons.amethystStone);
        world.setBlock(i + 6, j, k + 31, Dungeons.amethystStone);
        world.setBlock(i + 6, j, k + 32, Dungeons.amethystStone);
        world.setBlock(i + 6, j, k + 33, Dungeons.amethystStone);
        world.setBlock(i + 6, j, k + 34, Dungeons.amethystStone);
        world.setBlock(i + 6, j, k + 35, Dungeons.amethystStone);
        world.setBlock(i + 6, j, k + 36, Dungeons.amethystStone);
        world.setBlock(i + 6, j, k + 37, Dungeons.amethystStone);
        world.setBlock(i + 6, j, k + 38, Dungeons.amethystStone);
        world.setBlock(i + 6, j, k + 39, Dungeons.amethystStone);
        world.setBlock(i + 6, j + 1, k + 7, Dungeons.amethystStone);
        world.setBlock(i + 6, j + 1, k + 8, Dungeons.amethystStone);
        world.setBlock(i + 6, j + 1, k + 9, Dungeons.amethystStone);
        world.setBlock(i + 6, j + 1, k + 10, Dungeons.amethystStone);
        world.setBlock(i + 6, j + 1, k + 11, Dungeons.amethystStone);
        world.setBlock(i + 6, j + 1, k + 12, Dungeons.amethystStone);
        world.setBlock(i + 6, j + 1, k + 13, Dungeons.amethystStone);
        world.setBlock(i + 6, j + 1, k + 14, Dungeons.amethystStone);
        world.setBlock(i + 6, j + 1, k + 15, Dungeons.amethystStone);
        world.setBlock(i + 6, j + 1, k + 16, Dungeons.amethystStone);
        world.setBlock(i + 6, j + 1, k + 17, Dungeons.amethystStone);
        world.setBlock(i + 6, j + 1, k + 18, Dungeons.amethystStone);
        world.setBlock(i + 6, j + 1, k + 19, Dungeons.amethystStone);
        world.setBlock(i + 6, j + 1, k + 20, Dungeons.amethystStone);
        world.setBlock(i + 6, j + 1, k + 21, Dungeons.amethystStone);
        world.setBlock(i + 6, j + 1, k + 22, Dungeons.amethystStone);
        world.setBlock(i + 6, j + 1, k + 23, Dungeons.amethystStone);
        world.setBlock(i + 6, j + 1, k + 24, Dungeons.amethystStone);
        world.setBlock(i + 6, j + 1, k + 25, Dungeons.amethystStone);
        world.setBlock(i + 6, j + 1, k + 26, Dungeons.amethystStone);
        world.setBlock(i + 6, j + 1, k + 27, Dungeons.amethystStone);
        world.setBlock(i + 6, j + 1, k + 28, Dungeons.amethystStone);
        world.setBlock(i + 6, j + 1, k + 29, Dungeons.amethystStone);
        world.setBlock(i + 6, j + 1, k + 30, Dungeons.amethystStone);
        world.setBlock(i + 6, j + 1, k + 31, Dungeons.amethystStone);
        world.setBlock(i + 6, j + 1, k + 32, Dungeons.amethystStone);
        world.setBlock(i + 6, j + 1, k + 33, Dungeons.amethystStone);
        world.setBlock(i + 6, j + 1, k + 34, Dungeons.amethystStone);
        world.setBlock(i + 6, j + 1, k + 35, Dungeons.amethystStone);
        world.setBlock(i + 6, j + 1, k + 36, Dungeons.amethystStone);
        world.setBlock(i + 6, j + 1, k + 37, Dungeons.amethystStone);
        world.setBlock(i + 6, j + 1, k + 38, Dungeons.amethystStone);
        world.setBlock(i + 6, j + 1, k + 39, Dungeons.amethystStone);
        world.setBlock(i + 6, j + 2, k + 7, Dungeons.amethystStone);
        world.setBlock(i + 6, j + 2, k + 8, Dungeons.amethystStone);
        world.setBlock(i + 6, j + 2, k + 9, Dungeons.amethystStone);
        world.setBlock(i + 6, j + 2, k + 10, Dungeons.amethystStone);
        world.setBlock(i + 6, j + 2, k + 11, Dungeons.amethystStone);
        world.setBlock(i + 6, j + 2, k + 12, Dungeons.amethystStone);
        world.setBlock(i + 6, j + 2, k + 13, Dungeons.amethystStone);
        world.setBlock(i + 6, j + 2, k + 14, Dungeons.amethystStone);
        world.setBlock(i + 6, j + 2, k + 15, Dungeons.amethystStone);
        world.setBlock(i + 6, j + 2, k + 16, Dungeons.amethystStone);
        world.setBlock(i + 6, j + 2, k + 17, Dungeons.amethystStone);
        world.setBlock(i + 6, j + 2, k + 18, Dungeons.amethystStone);
        world.setBlock(i + 6, j + 2, k + 19, Dungeons.amethystStone);
        world.setBlock(i + 6, j + 2, k + 20, Dungeons.amethystStone);
        world.setBlock(i + 6, j + 2, k + 21, Dungeons.amethystStone);
        world.setBlock(i + 6, j + 2, k + 22, Dungeons.amethystStone);
        world.setBlock(i + 6, j + 2, k + 23, Dungeons.amethystStone);
        world.setBlock(i + 6, j + 2, k + 24, Dungeons.amethystStone);
        world.setBlock(i + 6, j + 2, k + 25, Dungeons.amethystStone);
        world.setBlock(i + 6, j + 2, k + 26, Dungeons.amethystStone);
        world.setBlock(i + 6, j + 2, k + 27, Dungeons.amethystStone);
        world.setBlock(i + 6, j + 2, k + 28, Dungeons.amethystStone);
        world.setBlock(i + 6, j + 2, k + 29, Dungeons.amethystStone);
        world.setBlock(i + 6, j + 2, k + 30, Dungeons.amethystStone);
        world.setBlock(i + 6, j + 2, k + 31, Dungeons.amethystStone);
        world.setBlock(i + 6, j + 2, k + 32, Dungeons.amethystStone);
        world.setBlock(i + 6, j + 2, k + 33, Dungeons.amethystStone);
        world.setBlock(i + 6, j + 2, k + 34, Dungeons.amethystStone);
        world.setBlock(i + 6, j + 2, k + 35, Dungeons.amethystStone);
        world.setBlock(i + 6, j + 2, k + 36, Dungeons.amethystStone);
        world.setBlock(i + 6, j + 2, k + 37, Dungeons.amethystStone);
        world.setBlock(i + 6, j + 2, k + 38, Dungeons.amethystStone);
        world.setBlock(i + 6, j + 2, k + 39, Dungeons.amethystStone);
        world.setBlock(i + 6, j + 3, k + 7, Dungeons.amethystStone);
        world.setBlock(i + 6, j + 3, k + 8, Dungeons.amethystStone);
        world.setBlock(i + 6, j + 3, k + 10, Dungeons.amethystStone);
        world.setBlock(i + 6, j + 3, k + 11, Dungeons.amethystStone);
        world.setBlock(i + 6, j + 3, k + 12, Dungeons.amethystStone);
        world.setBlock(i + 6, j + 3, k + 13, Dungeons.amethystStone);
        world.setBlock(i + 6, j + 3, k + 14, Dungeons.amethystStone);
        world.setBlock(i + 6, j + 3, k + 15, Dungeons.amethystStone);
        world.setBlock(i + 6, j + 3, k + 16, Dungeons.amethystStone);
        world.setBlock(i + 6, j + 3, k + 17, Dungeons.amethystStone);
        world.setBlock(i + 6, j + 3, k + 18, Dungeons.amethystStone);
        world.setBlock(i + 6, j + 3, k + 19, Dungeons.amethystStone);
        world.setBlock(i + 6, j + 3, k + 20, Dungeons.amethystStone);
        world.setBlock(i + 6, j + 3, k + 21, Dungeons.amethystStone);
        world.setBlock(i + 6, j + 3, k + 22, Dungeons.amethystStone);
        world.setBlock(i + 6, j + 3, k + 23, Dungeons.amethystStone);
        world.setBlock(i + 6, j + 3, k + 24, Dungeons.amethystStone);
        world.setBlock(i + 6, j + 3, k + 25, Dungeons.amethystStone);
        world.setBlock(i + 6, j + 3, k + 26, Dungeons.amethystStone);
        world.setBlock(i + 6, j + 3, k + 27, Dungeons.amethystStone);
        world.setBlock(i + 6, j + 3, k + 28, Dungeons.amethystStone);
        world.setBlock(i + 6, j + 3, k + 29, Dungeons.amethystStone);
        world.setBlock(i + 6, j + 3, k + 30, Dungeons.amethystStone);
        world.setBlock(i + 6, j + 3, k + 31, Dungeons.amethystStone);
        world.setBlock(i + 6, j + 3, k + 32, Dungeons.amethystStone);
        world.setBlock(i + 6, j + 3, k + 33, Dungeons.amethystStone);
        world.setBlock(i + 6, j + 3, k + 34, Dungeons.amethystStone);
        world.setBlock(i + 6, j + 3, k + 35, Dungeons.amethystStone);
        world.setBlock(i + 6, j + 3, k + 36, Dungeons.amethystStone);
        world.setBlock(i + 6, j + 3, k + 37, Dungeons.amethystStone);
        world.setBlock(i + 6, j + 3, k + 38, Dungeons.amethystStone);
        world.setBlock(i + 6, j + 3, k + 39, Dungeons.amethystStone);
        world.setBlock(i + 6, j + 4, k + 7, Dungeons.amethystStone);
        world.setBlock(i + 6, j + 4, k + 8, Dungeons.amethystStone);
        world.setBlock(i + 6, j + 4, k + 10, Dungeons.amethystStone);
        world.setBlock(i + 6, j + 4, k + 11, Dungeons.amethystStone);
        world.setBlock(i + 6, j + 4, k + 12, Dungeons.amethystStone);
        world.setBlock(i + 6, j + 4, k + 13, Dungeons.amethystStone);
        world.setBlock(i + 6, j + 4, k + 14, Dungeons.amethystStone);
        world.setBlock(i + 6, j + 4, k + 15, Dungeons.amethystStone);
        world.setBlock(i + 6, j + 4, k + 16, Dungeons.amethystStone);
        world.setBlock(i + 6, j + 4, k + 17, Dungeons.amethystStone);
        world.setBlock(i + 6, j + 4, k + 18, Dungeons.amethystStone);
        world.setBlock(i + 6, j + 4, k + 19, Dungeons.amethystStone);
        world.setBlock(i + 6, j + 4, k + 20, Dungeons.amethystStone);
        world.setBlock(i + 6, j + 4, k + 21, Dungeons.amethystStone);
        world.setBlock(i + 6, j + 4, k + 22, Dungeons.amethystStone);
        world.setBlock(i + 6, j + 4, k + 23, Dungeons.amethystStone);
        world.setBlock(i + 6, j + 4, k + 24, Dungeons.amethystStone);
        world.setBlock(i + 6, j + 4, k + 25, Dungeons.amethystStone);
        world.setBlock(i + 6, j + 4, k + 26, Dungeons.amethystStone);
        world.setBlock(i + 6, j + 4, k + 27, Dungeons.amethystStone);
        world.setBlock(i + 6, j + 4, k + 28, Dungeons.amethystStone);
        world.setBlock(i + 6, j + 4, k + 29, Dungeons.amethystStone);
        world.setBlock(i + 6, j + 4, k + 30, Dungeons.amethystStone);
        world.setBlock(i + 6, j + 4, k + 31, Dungeons.amethystStone);
        world.setBlock(i + 6, j + 4, k + 32, Dungeons.amethystStone);
        world.setBlock(i + 6, j + 4, k + 33, Dungeons.amethystStone);
        world.setBlock(i + 6, j + 4, k + 34, Dungeons.amethystStone);
        world.setBlock(i + 6, j + 4, k + 35, Dungeons.amethystStone);
        world.setBlock(i + 6, j + 4, k + 36, Dungeons.amethystStone);
        world.setBlock(i + 6, j + 4, k + 37, Dungeons.amethystStone);
        world.setBlock(i + 6, j + 4, k + 38, Dungeons.amethystStone);
        world.setBlock(i + 6, j + 4, k + 39, Dungeons.amethystStone);
        world.setBlock(i + 6, j + 5, k + 7, Dungeons.amethystStone);
        world.setBlock(i + 6, j + 5, k + 8, Dungeons.amethystStone);
        world.setBlock(i + 6, j + 5, k + 10, Dungeons.amethystStone);
        world.setBlock(i + 6, j + 5, k + 11, Dungeons.amethystStone);
        world.setBlock(i + 6, j + 5, k + 12, Dungeons.amethystStone);
        world.setBlock(i + 6, j + 5, k + 13, Dungeons.amethystStone);
        world.setBlock(i + 6, j + 5, k + 14, Dungeons.amethystStone);
        world.setBlock(i + 6, j + 5, k + 15, Dungeons.amethystStone);
        world.setBlock(i + 6, j + 5, k + 16, Dungeons.amethystStone);
        world.setBlock(i + 6, j + 5, k + 17, Dungeons.amethystStone);
        world.setBlock(i + 6, j + 5, k + 18, Dungeons.amethystStone);
        world.setBlock(i + 6, j + 5, k + 19, Dungeons.amethystStone);
        world.setBlock(i + 6, j + 5, k + 20, Dungeons.amethystStone);
        world.setBlock(i + 6, j + 5, k + 21, Dungeons.amethystStone);
        world.setBlock(i + 6, j + 5, k + 22, Dungeons.amethystStone);
        world.setBlock(i + 6, j + 5, k + 23, Dungeons.amethystStone);
        world.setBlock(i + 6, j + 5, k + 24, Dungeons.amethystStone);
        world.setBlock(i + 6, j + 5, k + 25, Dungeons.amethystStone);
        world.setBlock(i + 6, j + 5, k + 26, Dungeons.amethystStone);
        world.setBlock(i + 6, j + 5, k + 27, Dungeons.amethystStone);
        world.setBlock(i + 6, j + 5, k + 28, Dungeons.amethystStone);
        world.setBlock(i + 6, j + 5, k + 29, Dungeons.amethystStone);
        world.setBlock(i + 6, j + 5, k + 30, Dungeons.amethystStone);
        world.setBlock(i + 6, j + 5, k + 31, Dungeons.amethystStone);
        world.setBlock(i + 6, j + 5, k + 32, Dungeons.amethystStone);
        world.setBlock(i + 6, j + 5, k + 33, Dungeons.amethystStone);
        world.setBlock(i + 6, j + 5, k + 34, Dungeons.amethystStone);
        world.setBlock(i + 6, j + 5, k + 35, Dungeons.amethystStone);
        world.setBlock(i + 6, j + 5, k + 36, Dungeons.amethystStone);
        world.setBlock(i + 6, j + 5, k + 37, Dungeons.amethystStone);
        world.setBlock(i + 6, j + 5, k + 38, Dungeons.amethystStone);
        world.setBlock(i + 6, j + 5, k + 39, Dungeons.amethystStone);
        world.setBlock(i + 6, j + 6, k + 7, Dungeons.amethystStone);
        world.setBlock(i + 6, j + 6, k + 8, Dungeons.amethystStone);
        world.setBlock(i + 6, j + 6, k + 10, Dungeons.amethystStone);
        world.setBlock(i + 6, j + 6, k + 11, Dungeons.amethystStone);
        world.setBlock(i + 6, j + 6, k + 12, Dungeons.amethystStone);
        world.setBlock(i + 6, j + 6, k + 13, Dungeons.amethystStone);
        world.setBlock(i + 6, j + 6, k + 14, Dungeons.amethystStone);
        world.setBlock(i + 6, j + 6, k + 15, Dungeons.amethystStone);
        world.setBlock(i + 6, j + 6, k + 16, Dungeons.amethystStone);
        world.setBlock(i + 6, j + 6, k + 17, Dungeons.amethystStone);
        world.setBlock(i + 6, j + 6, k + 18, Dungeons.amethystStone);
        world.setBlock(i + 6, j + 6, k + 19, Dungeons.amethystStone);
        world.setBlock(i + 6, j + 6, k + 20, Dungeons.amethystStone);
        world.setBlock(i + 6, j + 6, k + 21, Dungeons.amethystStone);
        world.setBlock(i + 6, j + 6, k + 22, Dungeons.amethystStone);
        world.setBlock(i + 6, j + 6, k + 23, Dungeons.amethystStone);
        world.setBlock(i + 6, j + 6, k + 24, Dungeons.amethystStone);
        world.setBlock(i + 6, j + 6, k + 25, Dungeons.amethystStone);
        world.setBlock(i + 6, j + 6, k + 26, Dungeons.amethystStone);
        world.setBlock(i + 6, j + 6, k + 27, Dungeons.amethystStone);
        world.setBlock(i + 6, j + 6, k + 28, Dungeons.amethystStone);
        world.setBlock(i + 6, j + 6, k + 29, Dungeons.amethystStone);
        world.setBlock(i + 6, j + 6, k + 30, Dungeons.amethystStone);
        world.setBlock(i + 6, j + 6, k + 31, Dungeons.amethystStone);
        world.setBlock(i + 6, j + 6, k + 32, Dungeons.amethystStone);
        world.setBlock(i + 6, j + 6, k + 33, Dungeons.amethystStone);
        world.setBlock(i + 6, j + 6, k + 34, Dungeons.amethystStone);
        world.setBlock(i + 6, j + 6, k + 35, Dungeons.amethystStone);
        world.setBlock(i + 6, j + 6, k + 36, Dungeons.amethystStone);
        world.setBlock(i + 6, j + 6, k + 37, Dungeons.amethystStone);
        world.setBlock(i + 6, j + 6, k + 38, Dungeons.amethystStone);
        world.setBlock(i + 6, j + 6, k + 39, Dungeons.amethystStone);
        world.setBlock(i + 6, j + 7, k + 7, Dungeons.amethystStone);
        world.setBlock(i + 6, j + 7, k + 8, Dungeons.amethystStone);
        world.setBlock(i + 6, j + 7, k + 9, Dungeons.amethystStone);
        world.setBlock(i + 6, j + 7, k + 10, Dungeons.amethystStone);
        world.setBlock(i + 6, j + 7, k + 11, Dungeons.amethystStone);
        world.setBlock(i + 6, j + 7, k + 12, Dungeons.amethystStone);
        world.setBlock(i + 6, j + 7, k + 13, Dungeons.amethystStone);
        world.setBlock(i + 6, j + 7, k + 14, Dungeons.amethystStone);
        world.setBlock(i + 6, j + 7, k + 15, Dungeons.amethystStone);
        world.setBlock(i + 6, j + 7, k + 16, Dungeons.amethystStone);
        world.setBlock(i + 6, j + 7, k + 17, Dungeons.amethystStone);
        world.setBlock(i + 6, j + 7, k + 18, Dungeons.amethystStone);
        world.setBlock(i + 6, j + 7, k + 19, Dungeons.amethystStone);
        world.setBlock(i + 6, j + 7, k + 20, Dungeons.amethystStone);
        world.setBlock(i + 6, j + 7, k + 21, Dungeons.amethystStone);
        world.setBlock(i + 6, j + 7, k + 22, Dungeons.amethystStone);
        world.setBlock(i + 6, j + 7, k + 23, Dungeons.amethystStone);
        world.setBlock(i + 6, j + 7, k + 24, Dungeons.amethystStone);
        world.setBlock(i + 6, j + 7, k + 25, Dungeons.amethystStone);
        world.setBlock(i + 6, j + 7, k + 26, Dungeons.amethystStone);
        world.setBlock(i + 6, j + 7, k + 27, Dungeons.amethystStone);
        world.setBlock(i + 6, j + 7, k + 28, Dungeons.amethystStone);
        world.setBlock(i + 6, j + 7, k + 29, Dungeons.amethystStone);
        world.setBlock(i + 6, j + 7, k + 30, Dungeons.amethystStone);
        world.setBlock(i + 6, j + 7, k + 31, Dungeons.amethystStone);
        world.setBlock(i + 6, j + 7, k + 32, Dungeons.amethystStone);
        world.setBlock(i + 6, j + 7, k + 33, Dungeons.amethystStone);
        world.setBlock(i + 6, j + 7, k + 34, Dungeons.amethystStone);
        world.setBlock(i + 6, j + 7, k + 35, Dungeons.amethystStone);
        world.setBlock(i + 6, j + 7, k + 36, Dungeons.amethystStone);
        world.setBlock(i + 6, j + 7, k + 37, Dungeons.amethystStone);
        world.setBlock(i + 6, j + 7, k + 38, Dungeons.amethystStone);
        world.setBlock(i + 6, j + 7, k + 39, Dungeons.amethystStone);
        world.setBlock(i + 6, j + 8, k + 7, Dungeons.amethystStone);
        world.setBlock(i + 6, j + 8, k + 8, Dungeons.amethystStone);
        world.setBlock(i + 6, j + 8, k + 9, Dungeons.amethystStone);
        world.setBlock(i + 6, j + 8, k + 10, Dungeons.amethystStone);
        world.setBlock(i + 6, j + 8, k + 11, Dungeons.amethystStone);
        world.setBlock(i + 6, j + 8, k + 12, Dungeons.amethystStone);
        world.setBlock(i + 6, j + 8, k + 13, Dungeons.amethystStone);
        world.setBlock(i + 6, j + 8, k + 14, Dungeons.amethystStone);
        world.setBlock(i + 6, j + 8, k + 15, Dungeons.amethystStone);
        world.setBlock(i + 6, j + 8, k + 16, Dungeons.amethystStone);
        world.setBlock(i + 6, j + 8, k + 17, Dungeons.amethystStone);
        world.setBlock(i + 6, j + 8, k + 18, Dungeons.amethystStone);
        world.setBlock(i + 6, j + 8, k + 19, Dungeons.amethystStone);
        world.setBlock(i + 6, j + 8, k + 20, Dungeons.amethystStone);
        world.setBlock(i + 6, j + 8, k + 21, Dungeons.amethystStone);
        world.setBlock(i + 6, j + 8, k + 22, Dungeons.amethystStone);
        world.setBlock(i + 6, j + 8, k + 23, Dungeons.amethystStone);
        world.setBlock(i + 6, j + 8, k + 24, Dungeons.amethystStone);
        world.setBlock(i + 6, j + 8, k + 25, Dungeons.amethystStone);
        world.setBlock(i + 6, j + 8, k + 26, Dungeons.amethystStone);
        world.setBlock(i + 6, j + 8, k + 27, Dungeons.amethystStone);
        world.setBlock(i + 6, j + 8, k + 28, Dungeons.amethystStone);
        world.setBlock(i + 6, j + 8, k + 29, Dungeons.amethystStone);
        world.setBlock(i + 6, j + 8, k + 30, Dungeons.amethystStone);
        world.setBlock(i + 6, j + 8, k + 31, Dungeons.amethystStone);
        world.setBlock(i + 6, j + 8, k + 32, Dungeons.amethystStone);
        world.setBlock(i + 6, j + 8, k + 33, Dungeons.amethystStone);
        world.setBlock(i + 6, j + 8, k + 34, Dungeons.amethystStone);
        world.setBlock(i + 6, j + 8, k + 35, Dungeons.amethystStone);
        world.setBlock(i + 6, j + 8, k + 36, Dungeons.amethystStone);
        world.setBlock(i + 6, j + 8, k + 37, Dungeons.amethystStone);
        world.setBlock(i + 6, j + 8, k + 38, Dungeons.amethystStone);
        world.setBlock(i + 6, j + 8, k + 39, Dungeons.amethystStone);
        world.setBlock(i + 6, j + 9, k + 7, Dungeons.amethystStone);
        world.setBlock(i + 6, j + 9, k + 8, Dungeons.amethystStone);
        world.setBlock(i + 6, j + 9, k + 9, Dungeons.amethystStone);
        world.setBlock(i + 6, j + 9, k + 10, Dungeons.amethystStone);
        world.setBlock(i + 6, j + 9, k + 11, Dungeons.amethystStone);
        world.setBlock(i + 6, j + 9, k + 12, Dungeons.amethystStone);
        world.setBlock(i + 6, j + 9, k + 13, Dungeons.amethystStone);
        world.setBlock(i + 6, j + 9, k + 14, Dungeons.amethystStone);
        world.setBlock(i + 6, j + 9, k + 15, Dungeons.amethystStone);
        world.setBlock(i + 6, j + 9, k + 16, Dungeons.amethystStone);
        world.setBlock(i + 6, j + 9, k + 17, Dungeons.amethystStone);
        world.setBlock(i + 6, j + 9, k + 18, Dungeons.amethystStone);
        world.setBlock(i + 6, j + 9, k + 19, Dungeons.amethystStone);
        world.setBlock(i + 6, j + 9, k + 20, Dungeons.amethystStone);
        world.setBlock(i + 6, j + 9, k + 21, Dungeons.amethystStone);
        world.setBlock(i + 6, j + 9, k + 22, Dungeons.amethystStone);
        world.setBlock(i + 6, j + 9, k + 23, Dungeons.amethystStone);
        world.setBlock(i + 6, j + 9, k + 24, Dungeons.amethystStone);
        world.setBlock(i + 6, j + 9, k + 25, Dungeons.amethystStone);
        world.setBlock(i + 6, j + 9, k + 26, Dungeons.amethystStone);
        world.setBlock(i + 6, j + 9, k + 27, Dungeons.amethystStone);
        world.setBlock(i + 6, j + 9, k + 28, Dungeons.amethystStone);
        world.setBlock(i + 6, j + 9, k + 29, Dungeons.amethystStone);
        world.setBlock(i + 6, j + 9, k + 30, Dungeons.amethystStone);
        world.setBlock(i + 6, j + 9, k + 31, Dungeons.amethystStone);
        world.setBlock(i + 6, j + 9, k + 32, Dungeons.amethystStone);
        world.setBlock(i + 6, j + 9, k + 33, Dungeons.amethystStone);
        world.setBlock(i + 6, j + 9, k + 34, Dungeons.amethystStone);
        world.setBlock(i + 6, j + 9, k + 35, Dungeons.amethystStone);
        world.setBlock(i + 6, j + 9, k + 36, Dungeons.amethystStone);
        world.setBlock(i + 6, j + 9, k + 37, Dungeons.amethystStone);
        world.setBlock(i + 6, j + 9, k + 38, Dungeons.amethystStone);
        world.setBlock(i + 6, j + 9, k + 39, Dungeons.amethystStone);
        world.setBlock(i + 6, j + 10, k + 7, Dungeons.amethystStone);
        world.setBlock(i + 6, j + 10, k + 8, Dungeons.amethystStone);
        world.setBlock(i + 6, j + 10, k + 9, Dungeons.amethystStone);
        world.setBlock(i + 6, j + 10, k + 10, Dungeons.amethystStone);
        world.setBlock(i + 6, j + 10, k + 11, Dungeons.amethystStone);
        world.setBlock(i + 6, j + 10, k + 12, Dungeons.amethystStone);
        world.setBlock(i + 6, j + 10, k + 13, Dungeons.amethystStone);
        world.setBlock(i + 6, j + 10, k + 14, Dungeons.amethystStone);
        world.setBlock(i + 6, j + 10, k + 15, Dungeons.amethystStone);
        world.setBlock(i + 6, j + 10, k + 16, Dungeons.amethystStone);
        world.setBlock(i + 6, j + 10, k + 17, Dungeons.amethystStone);
        world.setBlock(i + 6, j + 10, k + 18, Dungeons.amethystStone);
        world.setBlock(i + 6, j + 10, k + 19, Dungeons.amethystStone);
        world.setBlock(i + 6, j + 10, k + 20, Dungeons.amethystStone);
        world.setBlock(i + 6, j + 10, k + 21, Dungeons.amethystStone);
        world.setBlock(i + 6, j + 10, k + 22, Dungeons.amethystStone);
        world.setBlock(i + 6, j + 10, k + 23, Dungeons.amethystStone);
        world.setBlock(i + 6, j + 10, k + 24, Dungeons.amethystStone);
        world.setBlock(i + 6, j + 10, k + 25, Dungeons.amethystStone);
        world.setBlock(i + 6, j + 10, k + 26, Dungeons.amethystStone);
        world.setBlock(i + 6, j + 10, k + 27, Dungeons.amethystStone);
        world.setBlock(i + 6, j + 10, k + 28, Dungeons.amethystStone);
        world.setBlock(i + 6, j + 10, k + 29, Dungeons.amethystStone);
        world.setBlock(i + 6, j + 10, k + 30, Dungeons.amethystStone);
        world.setBlock(i + 6, j + 10, k + 31, Dungeons.amethystStone);
        world.setBlock(i + 6, j + 10, k + 32, Dungeons.amethystStone);
        world.setBlock(i + 6, j + 10, k + 33, Dungeons.amethystStone);
        world.setBlock(i + 6, j + 10, k + 34, Dungeons.amethystStone);
        world.setBlock(i + 6, j + 10, k + 35, Dungeons.amethystStone);
        world.setBlock(i + 6, j + 10, k + 36, Dungeons.amethystStone);
        world.setBlock(i + 6, j + 10, k + 37, Dungeons.amethystStone);
        world.setBlock(i + 6, j + 10, k + 38, Dungeons.amethystStone);
        world.setBlock(i + 6, j + 10, k + 39, Dungeons.amethystStone);
        world.setBlock(i + 7, j, k + 6, Dungeons.amethystStone);
        world.setBlock(i + 7, j, k + 7, Dungeons.amethystStone);
        world.setBlock(i + 7, j, k + 8, Dungeons.amethystStone);
        world.setBlock(i + 7, j, k + 9, Dungeons.amethystStone);
        world.setBlock(i + 7, j, k + 10, Dungeons.amethystStone);
        world.setBlock(i + 7, j, k + 11, Dungeons.amethystStone);
        world.setBlock(i + 7, j, k + 12, Dungeons.amethystStone);
        world.setBlock(i + 7, j, k + 13, Dungeons.amethystStone);
        world.setBlock(i + 7, j, k + 14, Dungeons.amethystStone);
        world.setBlock(i + 7, j, k + 15, Dungeons.amethystStone);
        world.setBlock(i + 7, j, k + 16, Dungeons.amethystStone);
        world.setBlock(i + 7, j, k + 17, Dungeons.amethystStone);
        world.setBlock(i + 7, j, k + 18, Dungeons.amethystStone);
        world.setBlock(i + 7, j, k + 19, Dungeons.amethystStone);
        world.setBlock(i + 7, j, k + 20, Dungeons.amethystStone);
        world.setBlock(i + 7, j, k + 21, Dungeons.amethystStone);
        world.setBlock(i + 7, j, k + 22, Dungeons.amethystStone);
        world.setBlock(i + 7, j, k + 23, Dungeons.amethystStone);
        world.setBlock(i + 7, j, k + 24, Dungeons.amethystStone);
        world.setBlock(i + 7, j, k + 25, Dungeons.amethystStone);
        world.setBlock(i + 7, j, k + 26, Dungeons.amethystStone);
        world.setBlock(i + 7, j, k + 27, Dungeons.amethystStone);
        world.setBlock(i + 7, j, k + 28, Dungeons.amethystStone);
        world.setBlock(i + 7, j, k + 29, Dungeons.amethystStone);
        world.setBlock(i + 7, j, k + 30, Dungeons.amethystStone);
        world.setBlock(i + 7, j, k + 31, Dungeons.amethystStone);
        world.setBlock(i + 7, j, k + 32, Dungeons.amethystStone);
        world.setBlock(i + 7, j, k + 33, Dungeons.amethystStone);
        world.setBlock(i + 7, j, k + 34, Dungeons.amethystStone);
        world.setBlock(i + 7, j, k + 35, Dungeons.amethystStone);
        world.setBlock(i + 7, j, k + 36, Dungeons.amethystStone);
        world.setBlock(i + 7, j, k + 37, Dungeons.amethystStone);
        world.setBlock(i + 7, j, k + 38, Dungeons.amethystStone);
        world.setBlock(i + 7, j, k + 39, Dungeons.amethystStone);
        world.setBlock(i + 7, j, k + 40, Dungeons.amethystStone);
        world.setBlock(i + 7, j + 1, k + 6, Dungeons.amethystStone);
        world.setBlock(i + 7, j + 1, k + 7, Dungeons.amethystStone);
        world.setBlock(i + 7, j + 1, k + 8, Dungeons.amethystStone);
        world.setBlock(i + 7, j + 1, k + 9, Dungeons.amethystStone);
        world.setBlock(i + 7, j + 1, k + 10, Dungeons.amethystStone);
        world.setBlock(i + 7, j + 1, k + 11, Dungeons.amethystStone);
        world.setBlock(i + 7, j + 1, k + 12, Dungeons.amethystStone);
        world.setBlock(i + 7, j + 1, k + 13, Dungeons.amethystStone);
        world.setBlock(i + 7, j + 1, k + 14, Dungeons.amethystStone);
        world.setBlock(i + 7, j + 1, k + 15, Dungeons.amethystStone);
        world.setBlock(i + 7, j + 1, k + 16, Dungeons.amethystStone);
        world.setBlock(i + 7, j + 1, k + 17, Dungeons.amethystStone);
        world.setBlock(i + 7, j + 1, k + 18, Dungeons.amethystStone);
        world.setBlock(i + 7, j + 1, k + 19, Dungeons.amethystStone);
        world.setBlock(i + 7, j + 1, k + 20, Dungeons.amethystStone);
        world.setBlock(i + 7, j + 1, k + 21, Dungeons.amethystStone);
        world.setBlock(i + 7, j + 1, k + 22, Dungeons.amethystStone);
        world.setBlock(i + 7, j + 1, k + 23, Dungeons.amethystStone);
        world.setBlock(i + 7, j + 1, k + 24, Dungeons.amethystStone);
        world.setBlock(i + 7, j + 1, k + 25, Dungeons.amethystStone);
        world.setBlock(i + 7, j + 1, k + 26, Dungeons.amethystStone);
        world.setBlock(i + 7, j + 1, k + 27, Dungeons.amethystStone);
        world.setBlock(i + 7, j + 1, k + 28, Dungeons.amethystStone);
        world.setBlock(i + 7, j + 1, k + 29, Dungeons.amethystStone);
        world.setBlock(i + 7, j + 1, k + 30, Dungeons.amethystStone);
        world.setBlock(i + 7, j + 1, k + 31, Dungeons.amethystStone);
        world.setBlock(i + 7, j + 1, k + 32, Dungeons.amethystStone);
        world.setBlock(i + 7, j + 1, k + 33, Dungeons.amethystStone);
        world.setBlock(i + 7, j + 1, k + 34, Dungeons.amethystStone);
        world.setBlock(i + 7, j + 1, k + 35, Dungeons.amethystStone);
        world.setBlock(i + 7, j + 1, k + 36, Dungeons.amethystStone);
        world.setBlock(i + 7, j + 1, k + 37, Dungeons.amethystStone);
        world.setBlock(i + 7, j + 1, k + 38, Dungeons.amethystStone);
        world.setBlock(i + 7, j + 1, k + 39, Dungeons.amethystStone);
        world.setBlock(i + 7, j + 1, k + 40, Dungeons.amethystStone);
        world.setBlock(i + 7, j + 2, k + 6, Dungeons.amethystStone);
        world.setBlock(i + 7, j + 2, k + 7, Dungeons.amethystStone);
        world.setBlock(i + 7, j + 2, k + 8, Dungeons.amethystStone);
        world.setBlock(i + 7, j + 2, k + 9, Dungeons.amethystStone);
        world.setBlock(i + 7, j + 2, k + 10, Dungeons.amethystStone);
        world.setBlock(i + 7, j + 2, k + 11, Dungeons.amethystStone);
        world.setBlock(i + 7, j + 2, k + 12, Dungeons.amethystStone);
        world.setBlock(i + 7, j + 2, k + 13, Dungeons.amethystStone);
        world.setBlock(i + 7, j + 2, k + 14, Dungeons.amethystStone);
        world.setBlock(i + 7, j + 2, k + 15, Dungeons.amethystStone);
        world.setBlock(i + 7, j + 2, k + 16, Dungeons.amethystStone);
        world.setBlock(i + 7, j + 2, k + 17, Dungeons.amethystStone);
        world.setBlock(i + 7, j + 2, k + 18, Dungeons.amethystStone);
        world.setBlock(i + 7, j + 2, k + 19, Dungeons.amethystStone);
        world.setBlock(i + 7, j + 2, k + 20, Dungeons.amethystStone);
        world.setBlock(i + 7, j + 2, k + 21, Dungeons.amethystStone);
        world.setBlock(i + 7, j + 2, k + 22, Dungeons.amethystStone);
        world.setBlock(i + 7, j + 2, k + 23, Dungeons.amethystStone);
        world.setBlock(i + 7, j + 2, k + 24, Dungeons.amethystStone);
        world.setBlock(i + 7, j + 2, k + 25, Dungeons.amethystStone);
        world.setBlock(i + 7, j + 2, k + 26, Dungeons.amethystStone);
        world.setBlock(i + 7, j + 2, k + 27, Dungeons.amethystStone);
        world.setBlock(i + 7, j + 2, k + 28, Dungeons.amethystStone);
        world.setBlock(i + 7, j + 2, k + 29, Dungeons.amethystStone);
        world.setBlock(i + 7, j + 2, k + 30, Dungeons.amethystStone);
        world.setBlock(i + 7, j + 2, k + 31, Dungeons.amethystStone);
        world.setBlock(i + 7, j + 2, k + 32, Dungeons.amethystStone);
        world.setBlock(i + 7, j + 2, k + 33, Dungeons.amethystStone);
        world.setBlock(i + 7, j + 2, k + 34, Dungeons.amethystStone);
        world.setBlock(i + 7, j + 2, k + 35, Dungeons.amethystStone);
        world.setBlock(i + 7, j + 2, k + 36, Dungeons.amethystStone);
        world.setBlock(i + 7, j + 2, k + 37, Dungeons.amethystStone);
        world.setBlock(i + 7, j + 2, k + 38, Dungeons.amethystStone);
        world.setBlock(i + 7, j + 2, k + 39, Dungeons.amethystStone);
        world.setBlock(i + 7, j + 2, k + 40, Dungeons.amethystStone);
        world.setBlock(i + 7, j + 3, k + 6, Dungeons.amethystStone);
        world.setBlock(i + 7, j + 3, k + 7, Dungeons.amethystStone);
        world.setBlock(i + 7, j + 3, k + 8, Dungeons.amethystStone);
        world.setBlock(i + 7, j + 3, k + 9, Dungeons.amethystStone);
        world.setBlock(i + 7, j + 3, k + 10, Dungeons.amethystStone);
        world.setBlock(i + 7, j + 3, k + 11, Dungeons.amethystStone);
        world.setBlock(i + 7, j + 3, k + 12, Dungeons.amethystStone);
        world.setBlock(i + 7, j + 3, k + 13, Dungeons.amethystStone);
        world.setBlock(i + 7, j + 3, k + 14, Dungeons.amethystStone);
        world.setBlock(i + 7, j + 3, k + 15, Dungeons.amethystStone);
        world.setBlock(i + 7, j + 3, k + 16, Dungeons.amethystStone);
        world.setBlock(i + 7, j + 3, k + 17, Dungeons.amethystStone);
        world.setBlock(i + 7, j + 3, k + 18, Dungeons.amethystStone);
        world.setBlock(i + 7, j + 3, k + 19, Dungeons.amethystStone);
        world.setBlock(i + 7, j + 3, k + 20, Dungeons.amethystStone);
        world.setBlock(i + 7, j + 3, k + 21, Dungeons.amethystStone);
        world.setBlock(i + 7, j + 3, k + 22, Dungeons.amethystStone);
        world.setBlock(i + 7, j + 3, k + 23, Dungeons.amethystStone);
        world.setBlock(i + 7, j + 3, k + 24, Dungeons.amethystStone);
        world.setBlock(i + 7, j + 3, k + 25, Dungeons.amethystStone);
        world.setBlock(i + 7, j + 3, k + 26, Dungeons.amethystStone);
        world.setBlock(i + 7, j + 3, k + 27, Dungeons.amethystStone);
        world.setBlock(i + 7, j + 3, k + 28, Dungeons.amethystStone);
        world.setBlock(i + 7, j + 3, k + 29, Dungeons.amethystStone);
        world.setBlock(i + 7, j + 3, k + 30, Dungeons.amethystStone);
        world.setBlock(i + 7, j + 3, k + 31, Dungeons.amethystStone);
        world.setBlock(i + 7, j + 3, k + 32, Dungeons.amethystStone);
        world.setBlock(i + 7, j + 3, k + 33, Dungeons.amethystStone);
        world.setBlock(i + 7, j + 3, k + 34, Dungeons.amethystStone);
        world.setBlock(i + 7, j + 3, k + 35, Dungeons.amethystStone);
        world.setBlock(i + 7, j + 3, k + 36, Dungeons.amethystStone);
        world.setBlock(i + 7, j + 3, k + 37, Dungeons.amethystStone);
        world.setBlock(i + 7, j + 3, k + 38, Dungeons.amethystStone);
        world.setBlock(i + 7, j + 3, k + 39, Dungeons.amethystStone);
        world.setBlock(i + 7, j + 3, k + 40, Dungeons.amethystStone);
        world.setBlock(i + 7, j + 4, k + 6, Dungeons.amethystStone);
        world.setBlock(i + 7, j + 4, k + 7, Dungeons.amethystStone);
        world.setBlock(i + 7, j + 4, k + 8, Dungeons.amethystStone);
        world.setBlock(i + 7, j + 4, k + 9, Dungeons.amethystStone);
        world.setBlock(i + 7, j + 4, k + 10, Dungeons.amethystStone);
        world.setBlock(i + 7, j + 4, k + 11, Dungeons.amethystStone);
        world.setBlock(i + 7, j + 4, k + 12, Dungeons.amethystStone);
        world.setBlock(i + 7, j + 4, k + 13, Dungeons.amethystStone);
        world.setBlock(i + 7, j + 4, k + 14, Dungeons.amethystStone);
        world.setBlock(i + 7, j + 4, k + 15, Dungeons.amethystStone);
        world.setBlock(i + 7, j + 4, k + 16, Dungeons.amethystStone);
        world.setBlock(i + 7, j + 4, k + 17, Dungeons.amethystStone);
        world.setBlock(i + 7, j + 4, k + 18, Dungeons.amethystStone);
        world.setBlock(i + 7, j + 4, k + 19, Dungeons.amethystStone);
        world.setBlock(i + 7, j + 4, k + 20, Dungeons.amethystStone);
        world.setBlock(i + 7, j + 4, k + 21, Dungeons.amethystStone);
        world.setBlock(i + 7, j + 4, k + 22, Dungeons.amethystStone);
        world.setBlock(i + 7, j + 4, k + 23, Dungeons.amethystStone);
        world.setBlock(i + 7, j + 4, k + 24, Dungeons.amethystStone);
        world.setBlock(i + 7, j + 4, k + 25, Dungeons.amethystStone);
        world.setBlock(i + 7, j + 4, k + 26, Dungeons.amethystStone);
        world.setBlock(i + 7, j + 4, k + 27, Dungeons.amethystStone);
        world.setBlock(i + 7, j + 4, k + 28, Dungeons.amethystStone);
        world.setBlock(i + 7, j + 4, k + 29, Dungeons.amethystStone);
        world.setBlock(i + 7, j + 4, k + 30, Dungeons.amethystStone);
        world.setBlock(i + 7, j + 4, k + 31, Dungeons.amethystStone);
        world.setBlock(i + 7, j + 4, k + 32, Dungeons.amethystStone);
        world.setBlock(i + 7, j + 4, k + 33, Dungeons.amethystStone);
        world.setBlock(i + 7, j + 4, k + 34, Dungeons.amethystStone);
        world.setBlock(i + 7, j + 4, k + 35, Dungeons.amethystStone);
        world.setBlock(i + 7, j + 4, k + 36, Dungeons.amethystStone);
        world.setBlock(i + 7, j + 4, k + 37, Dungeons.amethystStone);
        world.setBlock(i + 7, j + 4, k + 38, Dungeons.amethystStone);
        world.setBlock(i + 7, j + 4, k + 39, Dungeons.amethystStone);
        world.setBlock(i + 7, j + 4, k + 40, Dungeons.amethystStone);
        world.setBlock(i + 7, j + 5, k + 6, Dungeons.amethystStone);
        world.setBlock(i + 7, j + 5, k + 7, Dungeons.amethystStone);
        world.setBlock(i + 7, j + 5, k + 8, Dungeons.amethystStone);
        world.setBlock(i + 7, j + 5, k + 9, Dungeons.amethystStone);
        world.setBlock(i + 7, j + 5, k + 10, Dungeons.amethystStone);
        world.setBlock(i + 7, j + 5, k + 11, Dungeons.amethystStone);
        world.setBlock(i + 7, j + 5, k + 12, Dungeons.amethystStone);
        world.setBlock(i + 7, j + 5, k + 13, Dungeons.amethystStone);
        world.setBlock(i + 7, j + 5, k + 14, Dungeons.amethystStone);
        world.setBlock(i + 7, j + 5, k + 15, Dungeons.amethystStone);
        world.setBlock(i + 7, j + 5, k + 16, Dungeons.amethystStone);
        world.setBlock(i + 7, j + 5, k + 17, Dungeons.amethystStone);
        world.setBlock(i + 7, j + 5, k + 18, Dungeons.amethystStone);
        world.setBlock(i + 7, j + 5, k + 19, Dungeons.amethystStone);
        world.setBlock(i + 7, j + 5, k + 20, Dungeons.amethystStone);
        world.setBlock(i + 7, j + 5, k + 21, Dungeons.amethystStone);
        world.setBlock(i + 7, j + 5, k + 22, Dungeons.amethystStone);
        world.setBlock(i + 7, j + 5, k + 23, Dungeons.amethystStone);
        world.setBlock(i + 7, j + 5, k + 24, Dungeons.amethystStone);
        world.setBlock(i + 7, j + 5, k + 25, Dungeons.amethystStone);
        world.setBlock(i + 7, j + 5, k + 26, Dungeons.amethystStone);
        world.setBlock(i + 7, j + 5, k + 27, Dungeons.amethystStone);
        world.setBlock(i + 7, j + 5, k + 28, Dungeons.amethystStone);
        world.setBlock(i + 7, j + 5, k + 29, Dungeons.amethystStone);
        world.setBlock(i + 7, j + 5, k + 30, Dungeons.amethystStone);
        world.setBlock(i + 7, j + 5, k + 31, Dungeons.amethystStone);
        world.setBlock(i + 7, j + 5, k + 32, Dungeons.amethystStone);
        world.setBlock(i + 7, j + 5, k + 33, Dungeons.amethystStone);
        world.setBlock(i + 7, j + 5, k + 34, Dungeons.amethystStone);
        world.setBlock(i + 7, j + 5, k + 35, Dungeons.amethystStone);
        world.setBlock(i + 7, j + 5, k + 36, Dungeons.amethystStone);
        world.setBlock(i + 7, j + 5, k + 37, Dungeons.amethystStone);
        world.setBlock(i + 7, j + 5, k + 38, Dungeons.amethystStone);
        world.setBlock(i + 7, j + 5, k + 39, Dungeons.amethystStone);
        world.setBlock(i + 7, j + 5, k + 40, Dungeons.amethystStone);
        world.setBlock(i + 7, j + 6, k + 6, Dungeons.amethystStone);
        world.setBlock(i + 7, j + 6, k + 7, Dungeons.amethystStone);
