

package com.gibby.dungeon.gen;

import com.gibby.dungeon.Dungeons;
import cpw.mods.fml.common.IWorldGenerator;
import net.minecraft.block.Block;
import net.minecraft.init.Blocks;
import net.minecraft.world.IBlockAccess;
import net.minecraft.world.World;
import net.minecraft.world.chunk.IChunkProvider;
import net.minecraft.world.gen.feature.WorldGenerator;

import java.util.Random;

public class WorldGenMontaneDungeon_5 extends WorldGenerator implements IWorldGenerator
{
    public void generate(final Random random, final int chunkX, final int chunkZ, final World world, final IChunkProvider chunkGenerator, final IChunkProvider chunkProvider) {
    }

    public void setBlock(final World world, final int x, final int y, final int z, final Block block, final int metadata) {
        final Block b1 = world.getBlock(x, y, z);
        if (b1.isAir((IBlockAccess)world, x, y, z) || b1.isLeaves((IBlockAccess)world, x, y, z)) {
            world.setBlock(x, y, z, block, metadata, 2);
        }
    }

    public boolean generate(final World world, final Random rand, final int i, final int j, final int k) {
        this.setBlock(world, i, j + 38, k + 100, Blocks.cobblestone_wall, 0);
        this.setBlock(world, i, j + 38, k + 101, Dungeons.blockUnbreableStonebrick, 0);
        this.setBlock(world, i, j + 38, k + 102, Dungeons.blockUnbreableStonebrick, 0);
        this.setBlock(world, i, j + 38, k + 103, Dungeons.blockUnbreableStonebrick, 0);
        this.setBlock(world, i, j + 38, k + 104, Dungeons.blockUnbreableStonebrick, 0);
        this.setBlock(world, i, j + 38, k + 105, Dungeons.blockUnbreableStonebrick, 0);
        this.setBlock(world, i, j + 38, k + 106, Dungeons.blockUnbreableStonebrick, 0);
        this.setBlock(world, i, j + 38, k + 107, Dungeons.blockUnbreableStonebrick, 0);
        this.setBlock(world, i, j + 38, k + 108, Blocks.cobblestone_wall, 0);
        this.setBlock(world, i, j + 39, k + 100, Blocks.cobblestone_wall, 0);
        this.setBlock(world, i, j + 39, k + 101, Dungeons.blockUnbreableStonebrick, 0);
        this.setBlock(world, i, j + 39, k + 102, Dungeons.blockUnbreableStonebrick, 0);
        this.setBlock(world, i, j + 39, k + 103, Dungeons.blockUnbreableStonebrick, 0);
        this.setBlock(world, i, j + 39, k + 104, Dungeons.blockUnbreableStonebrick, 0);
        this.setBlock(world, i, j + 39, k + 105, Dungeons.blockUnbreableStonebrick, 0);
        this.setBlock(world, i, j + 39, k + 106, Dungeons.blockUnbreableStonebrick, 0);
        this.setBlock(world, i, j + 39, k + 107, Dungeons.blockUnbreableStonebrick, 0);
        this.setBlock(world, i, j + 39, k + 108, Blocks.cobblestone_wall, 0);
        this.setBlock(world, i + 1, j + 38, k + 100, Blocks.cobblestone_wall, 0);
        this.setBlock(world, i + 1, j + 38, k + 101, Dungeons.blockUnbreableStonebrick, 0);
        this.setBlock(world, i + 1, j + 38, k + 102, Dungeons.blockUnbreableStonebrick, 0);
        this.setBlock(world, i + 1, j + 38, k + 103, Dungeons.blockUnbreableStonebrick, 0);
        this.setBlock(world, i + 1, j + 38, k + 104, Dungeons.blockUnbreableStonebrick, 0);
        this.setBlock(world, i + 1, j + 38, k + 105, Dungeons.blockUnbreableStonebrick, 0);
        this.setBlock(world, i + 1, j + 38, k + 106, Dungeons.blockUnbreableStonebrick, 0);
        this.setBlock(world, i + 1, j + 38, k + 107, Dungeons.blockUnbreableStonebrick, 0);
        this.setBlock(world, i + 1, j + 38, k + 108, Blocks.cobblestone_wall, 0);
        this.setBlock(world, i + 1, j + 39, k + 100, Blocks.cobblestone_wall, 0);
        this.setBlock(world, i + 1, j + 39, k + 101, Dungeons.blockUnbreableStonebrick, 0);
        this.setBlock(world, i + 1, j + 39, k + 102, Dungeons.blockUnbreableStonebrick, 0);
        this.setBlock(world, i + 1, j + 39, k + 103, Dungeons.blockUnbreableStonebrick, 0);
        this.setBlock(world, i + 1, j + 39, k + 104, Dungeons.blockUnbreableStonebrick, 0);
        this.setBlock(world, i + 1, j + 39, k + 105, Dungeons.blockUnbreableStonebrick, 0);
        this.setBlock(world, i + 1, j + 39, k + 106, Dungeons.blockUnbreableStonebrick, 0);
        this.setBlock(world, i + 1, j + 39, k + 107, Dungeons.blockUnbreableStonebrick, 0);
        this.setBlock(world, i + 1, j + 39, k + 108, Blocks.cobblestone_wall, 0);
        Dungeons.spawner(world, i + 1, j + 40, k + 104, 37, 3);
        Dungeons.spawner(world, i, j + 40, k + 104, 38, 1);
        this.setBlock(world, i + 2, j + 38, k + 100, Dungeons.blockUnbreableStonebrick, 0);
        this.setBlock(world, i + 2, j + 38, k + 101, Dungeons.blockUnbreableStonebrick, 0);
        this.setBlock(world, i + 2, j + 38, k + 102, Dungeons.blockUnbreableStonebrick, 0);
        this.setBlock(world, i + 2, j + 38, k + 103, Dungeons.blockUnbreableStonebrick, 0);
        this.setBlock(world, i + 2, j + 38, k + 104, Dungeons.blockUnbreableStonebrick, 0);
        this.setBlock(world, i + 2, j + 38, k + 105, Dungeons.blockUnbreableStonebrick, 0);
        this.setBlock(world, i + 2, j + 38, k + 106, Dungeons.blockUnbreableStonebrick, 0);
        this.setBlock(world, i + 2, j + 38, k + 107, Dungeons.blockUnbreableStonebrick, 0);
        this.setBlock(world, i + 2, j + 38, k + 108, Dungeons.blockUnbreableStonebrick, 0);
        this.setBlock(world, i + 2, j + 39, k + 100, Dungeons.blockUnbreableStonebrick, 0);
        this.setBlock(world, i + 2, j + 39, k + 101, Dungeons.blockUnbreableStonebrick, 0);
        this.setBlock(world, i + 2, j + 39, k + 102, Dungeons.blockUnbreableStonebrick, 0);
        this.setBlock(world, i + 2, j + 39, k + 103, Dungeons.blockUnbreableStonebrick, 0);
        this.setBlock(world, i + 2, j + 39, k + 104, Dungeons.blockUnbreableStonebrick, 0);
        this.setBlock(world, i + 2, j + 39, k + 105, Dungeons.blockUnbreableStonebrick, 0);
        this.setBlock(world, i + 2, j + 39, k + 106, Dungeons.blockUnbreableStonebrick, 0);
        this.setBlock(world, i + 2, j + 39, k + 107, Dungeons.blockUnbreableStonebrick, 0);
        this.setBlock(world, i + 2, j + 39, k + 108, Dungeons.blockUnbreableStonebrick, 0);
        this.setBlock(world, i + 2, j + 40, k + 100, Dungeons.blockUnbreableStonebrick, 0);
        this.setBlock(world, i + 2, j + 40, k + 108, Dungeons.blockUnbreableStonebrick, 0);
        this.setBlock(world, i + 2, j + 41, k + 100, Dungeons.blockUnbreableStonebrick, 0);
        this.setBlock(world, i + 2, j + 41, k + 108, Dungeons.blockUnbreableStonebrick, 0);
        this.setBlock(world, i + 3, j + 38, k + 100, Dungeons.blockUnbreableStonebrick, 0);
        this.setBlock(world, i + 3, j + 38, k + 101, Dungeons.blockUnbreableStonebrick, 0);
        this.setBlock(world, i + 3, j + 38, k + 102, Dungeons.blockUnbreableStonebrick, 0);
        this.setBlock(world, i + 3, j + 38, k + 103, Dungeons.blockUnbreableStonebrick, 0);
        this.setBlock(world, i + 3, j + 38, k + 104, Dungeons.blockUnbreableStonebrick, 0);
        this.setBlock(world, i + 3, j + 38, k + 105, Dungeons.blockUnbreableStonebrick, 0);
        this.setBlock(world, i + 3, j + 38, k + 106, Dungeons.blockUnbreableStonebrick, 0);
        this.setBlock(world, i + 3, j + 38, k + 107, Dungeons.blockUnbreableStonebrick, 0);
        this.setBlock(world, i + 3, j + 38, k + 108, Dungeons.blockUnbreableStonebrick, 0);
        this.setBlock(world, i + 3, j + 39, k + 100, Dungeons.blockUnbreableStonebrick, 0);
        this.setBlock(world, i + 3, j + 39, k + 101, Dungeons.blockUnbreableStonebrick, 0);
        this.setBlock(world, i + 3, j + 39, k + 102, Dungeons.blockUnbreableStonebrick, 0);
        this.setBlock(world, i + 3, j + 39, k + 103, Dungeons.blockUnbreableStonebrick, 0);
        this.setBlock(world, i + 3, j + 39, k + 104, Dungeons.blockUnbreableStonebrick, 0);
        this.setBlock(world, i + 3, j + 39, k + 105, Dungeons.blockUnbreableStonebrick, 0);
        this.setBlock(world, i + 3, j + 39, k + 106, Dungeons.blockUnbreableStonebrick, 0);
        this.setBlock(world, i + 3, j + 39, k + 107, Dungeons.blockUnbreableStonebrick, 0);
        this.setBlock(world, i + 3, j + 39, k + 108, Dungeons.blockUnbreableStonebrick, 0);
        this.setBlock(world, i + 3, j + 40, k + 100, Dungeons.blockUnbreableStonebrick, 0);
        this.setBlock(world, i + 3, j + 40, k + 108, Dungeons.blockUnbreableStonebrick, 0);
        this.setBlock(world, i + 3, j + 41, k + 100, Dungeons.blockUnbreableStonebrick, 0);
        this.setBlock(world, i + 3, j + 41, k + 108, Dungeons.blockUnbreableStonebrick, 0);
        this.setBlock(world, i + 4, j + 38, k + 100, Blocks.cobblestone_wall, 0);
        this.setBlock(world, i + 4, j + 38, k + 101, Dungeons.blockUnbreableStonebrick, 0);
        this.setBlock(world, i + 4, j + 38, k + 102, Dungeons.blockUnbreableStonebrick, 0);
        this.setBlock(world, i + 4, j + 38, k + 103, Dungeons.blockUnbreableStonebrick, 0);
        this.setBlock(world, i + 4, j + 38, k + 104, Dungeons.blockUnbreableStonebrick, 0);
        this.setBlock(world, i + 4, j + 38, k + 105, Dungeons.blockUnbreableStonebrick, 0);
        this.setBlock(world, i + 4, j + 38, k + 106, Dungeons.blockUnbreableStonebrick, 0);
        this.setBlock(world, i + 4, j + 38, k + 107, Dungeons.blockUnbreableStonebrick, 0);
        this.setBlock(world, i + 4, j + 38, k + 108, Blocks.cobblestone_wall, 0);
        this.setBlock(world, i + 4, j + 39, k + 100, Blocks.cobblestone_wall, 0);
        this.setBlock(world, i + 4, j + 39, k + 101, Dungeons.blockUnbreableStonebrick, 0);
        this.setBlock(world, i + 4, j + 39, k + 102, Dungeons.blockUnbreableStonebrick, 0);
        this.setBlock(world, i + 4, j + 39, k + 103, Dungeons.blockUnbreableStonebrick, 0);
        this.setBlock(world, i + 4, j + 39, k + 104, Dungeons.blockUnbreableStonebrick, 0);
        this.setBlock(world, i + 4, j + 39, k + 105, Dungeons.blockUnbreableStonebrick, 0);
        this.setBlock(world, i + 4, j + 39, k + 106, Dungeons.blockUnbreableStonebrick, 0);
        this.setBlock(world, i + 4, j + 39, k + 107, Dungeons.blockUnbreableStonebrick, 0);
        this.setBlock(world, i + 4, j + 39, k + 108, Blocks.cobblestone_wall, 0);
        this.setBlock(world, i + 5, j + 38, k + 100, Blocks.cobblestone_wall, 0);
        this.setBlock(world, i + 5, j + 38, k + 101, Dungeons.blockUnbreableStonebrick, 0);
        this.setBlock(world, i + 5, j + 38, k + 102, Dungeons.blockUnbreableStonebrick, 0);
        this.setBlock(world, i + 5, j + 38, k + 103, Dungeons.blockUnbreableStonebrick, 0);
        this.setBlock(world, i + 5, j + 38, k + 104, Dungeons.blockUnbreableStonebrick, 0);
        this.setBlock(world, i + 5, j + 38, k + 105, Dungeons.blockUnbreableStonebrick, 0);
        this.setBlock(world, i + 5, j + 38, k + 106, Dungeons.blockUnbreableStonebrick, 0);
        this.setBlock(world, i + 5, j + 38, k + 107, Dungeons.blockUnbreableStonebrick, 0);
        this.setBlock(world, i + 5, j + 38, k + 108, Blocks.cobblestone_wall, 0);
        this.setBlock(world, i + 5, j + 39, k + 100, Blocks.cobblestone_wall, 0);
        this.setBlock(world, i + 5, j + 39, k + 101, Dungeons.blockUnbreableStonebrick, 0);
        this.setBlock(world, i + 5, j + 39, k + 102, Dungeons.blockUnbreableStonebrick, 0);
        this.setBlock(world, i + 5, j + 39, k + 103, Dungeons.blockUnbreableStonebrick, 0);
        this.setBlock(world, i + 5, j + 39, k + 104, Dungeons.blockUnbreableStonebrick, 0);
        this.setBlock(world, i + 5, j + 39, k + 105, Dungeons.blockUnbreableStonebrick, 0);
        this.setBlock(world, i + 5, j + 39, k + 106, Dungeons.blockUnbreableStonebrick, 0);
        this.setBlock(world, i + 5, j + 39, k + 107, Dungeons.blockUnbreableStonebrick, 0);
        this.setBlock(world, i + 5, j + 39, k + 108, Blocks.cobblestone_wall, 0);
        this.setBlock(world, i + 6, j + 38, k + 100, Blocks.cobblestone_wall, 0);
        this.setBlock(world, i + 6, j + 38, k + 101, Dungeons.blockUnbreableStonebrick, 0);
        this.setBlock(world, i + 6, j + 38, k + 102, Dungeons.blockUnbreableStonebrick, 0);
        this.setBlock(world, i + 6, j + 38, k + 103, Dungeons.blockUnbreableStonebrick, 0);
        this.setBlock(world, i + 6, j + 38, k + 104, Dungeons.blockUnbreableStonebrick, 0);
        this.setBlock(world, i + 6, j + 38, k + 105, Dungeons.blockUnbreableStonebrick, 0);
        this.setBlock(world, i + 6, j + 38, k + 106, Dungeons.blockUnbreableStonebrick, 0);
        this.setBlock(world, i + 6, j + 38, k + 107, Dungeons.blockUnbreableStonebrick, 0);
        this.setBlock(world, i + 6, j + 38, k + 108, Blocks.cobblestone_wall, 0);
        this.setBlock(world, i + 6, j + 39, k + 100, Blocks.cobblestone_wall, 0);
        this.setBlock(world, i + 6, j + 39, k + 101, Dungeons.blockUnbreableStonebrick, 0);
        this.setBlock(world, i + 6, j + 39, k + 102, Dungeons.blockUnbreableStonebrick, 0);
        this.setBlock(world, i + 6, j + 39, k + 103, Dungeons.blockUnbreableStonebrick, 0);
        this.setBlock(world, i + 6, j + 39, k + 104, Dungeons.blockUnbreableStonebrick, 0);
        this.setBlock(world, i + 6, j + 39, k + 105, Dungeons.blockUnbreableStonebrick, 0);
        this.setBlock(world, i + 6, j + 39, k + 106, Dungeons.blockUnbreableStonebrick, 0);
        this.setBlock(world, i + 6, j + 39, k + 107, Dungeons.blockUnbreableStonebrick, 0);
        this.setBlock(world, i + 6, j + 39, k + 108, Blocks.cobblestone_wall, 0);
        this.setBlock(world, i + 7, j + 38, k + 100, Dungeons.blockUnbreableStonebrick, 0);
        this.setBlock(world, i + 7, j + 38, k + 101, Dungeons.blockUnbreableStonebrick, 0);
        this.setBlock(world, i + 7, j + 38, k + 102, Dungeons.blockUnbreableStonebrick, 0);
        this.setBlock(world, i + 7, j + 38, k + 103, Dungeons.blockUnbreableStonebrick, 0);
        this.setBlock(world, i + 7, j + 38, k + 104, Dungeons.blockUnbreableStonebrick, 0);
        this.setBlock(world, i + 7, j + 38, k + 105, Dungeons.blockUnbreableStonebrick, 0);
        this.setBlock(world, i + 7, j + 38, k + 106, Dungeons.blockUnbreableStonebrick, 0);
        this.setBlock(world, i + 7, j + 38, k + 107, Dungeons.blockUnbreableStonebrick, 0);
        this.setBlock(world, i + 7, j + 38, k + 108, Dungeons.blockUnbreableStonebrick, 0);
        this.setBlock(world, i + 7, j + 39, k + 100, Dungeons.blockUnbreableStonebrick, 0);
        this.setBlock(world, i + 7, j + 39, k + 101, Dungeons.blockUnbreableStonebrick, 0);
        this.setBlock(world, i + 7, j + 39, k + 102, Dungeons.blockUnbreableStonebrick, 0);
        this.setBlock(world, i + 7, j + 39, k + 103, Dungeons.blockUnbreableStonebrick, 0);
        this.setBlock(world, i + 7, j + 39, k + 104, Dungeons.blockUnbreableStonebrick, 0);
        this.setBlock(world, i + 7, j + 39, k + 105, Dungeons.blockUnbreableStonebrick, 0);
        this.setBlock(world, i + 7, j + 39, k + 106, Dungeons.blockUnbreableStonebrick, 0);
        this.setBlock(world, i + 7, j + 39, k + 107, Dungeons.blockUnbreableStonebrick, 0);
        this.setBlock(world, i + 7, j + 39, k + 108, Dungeons.blockUnbreableStonebrick, 0);
        this.setBlock(world, i + 7, j + 40, k + 100, Dungeons.blockUnbreableStonebrick, 0);
        this.setBlock(world, i + 7, j + 40, k + 108, Dungeons.blockUnbreableStonebrick, 0);
        this.setBlock(world, i + 7, j + 41, k + 100, Dungeons.blockUnbreableStonebrick, 0);
        this.setBlock(world, i + 7, j + 41, k + 108, Dungeons.blockUnbreableStonebrick, 0);
        this.setBlock(world, i + 8, j + 38, k + 100, Dungeons.blockUnbreableStonebrick, 0);
        this.setBlock(world, i + 8, j + 38, k + 101, Dungeons.blockUnbreableStonebrick, 0);
        this.setBlock(world, i + 8, j + 38, k + 102, Dungeons.blockUnbreableStonebrick, 0);
        this.setBlock(world, i + 8, j + 38, k + 103, Dungeons.blockUnbreableStonebrick, 0);
        this.setBlock(world, i + 8, j + 38, k + 104, Dungeons.blockUnbreableStonebrick, 0);
        this.setBlock(world, i + 8, j + 38, k + 105, Dungeons.blockUnbreableStonebrick, 0);
        this.setBlock(world, i + 8, j + 38, k + 106, Dungeons.blockUnbreableStonebrick, 0);
        this.setBlock(world, i + 8, j + 38, k + 107, Dungeons.blockUnbreableStonebrick, 0);
        this.setBlock(world, i + 8, j + 38, k + 108, Dungeons.blockUnbreableStonebrick, 0);
        this.setBlock(world, i + 8, j + 39, k + 100, Dungeons.blockUnbreableStonebrick, 0);
        this.setBlock(world, i + 8, j + 39, k + 101, Dungeons.blockUnbreableStonebrick, 0);
        this.setBlock(world, i + 8, j + 39, k + 102, Dungeons.blockUnbreableStonebrick, 0);
        this.setBlock(world, i + 8, j + 39, k + 103, Dungeons.blockUnbreableStonebrick, 0);
        this.setBlock(world, i + 8, j + 39, k + 104, Dungeons.blockUnbreableStonebrick, 0);
        this.setBlock(world, i + 8, j + 39, k + 105, Dungeons.blockUnbreableStonebrick, 0);
        this.setBlock(world, i + 8, j + 39, k + 106, Dungeons.blockUnbreableStonebrick, 0);
        this.setBlock(world, i + 8, j + 39, k + 107, Dungeons.blockUnbreableStonebrick, 0);
        this.setBlock(world, i + 8, j + 39, k + 108, Dungeons.blockUnbreableStonebrick, 0);
        this.setBlock(world, i + 8, j + 40, k + 100, Dungeons.blockUnbreableStonebrick, 0);
        this.setBlock(world, i + 8, j + 40, k + 108, Dungeons.blockUnbreableStonebrick, 0);
        this.setBlock(world, i + 8, j + 41, k + 100, Dungeons.blockUnbreableStonebrick, 0);
        this.setBlock(world, i + 8, j + 41, k + 108, Dungeons.blockUnbreableStonebrick, 0);
        this.setBlock(world, i + 9, j + 38, k + 100, Blocks.cobblestone_wall, 0);
        this.setBlock(world, i + 9, j + 38, k + 101, Dungeons.blockUnbreableStonebrick, 0);
        this.setBlock(world, i + 9, j + 38, k + 102, Dungeons.blockUnbreableStonebrick, 0);
        this.setBlock(world, i + 9, j + 38, k + 103, Dungeons.blockUnbreableStonebrick, 0);
        this.setBlock(world, i + 9, j + 38, k + 104, Dungeons.blockUnbreableStonebrick, 0);
        this.setBlock(world, i + 9, j + 38, k + 105, Dungeons.blockUnbreableStonebrick, 0);
        this.setBlock(world, i + 9, j + 38, k + 106, Dungeons.blockUnbreableStonebrick, 0);
        this.setBlock(world, i + 9, j + 38, k + 107, Dungeons.blockUnbreableStonebrick, 0);
        this.setBlock(world, i + 9, j + 38, k + 108, Blocks.cobblestone_wall, 0);
        this.setBlock(world, i + 9, j + 39, k + 100, Blocks.cobblestone_wall, 0);
        this.setBlock(world, i + 9, j + 39, k + 101, Dungeons.blockUnbreableStonebrick, 0);
        this.setBlock(world, i + 9, j + 39, k + 102, Dungeons.blockUnbreableStonebrick, 0);
        this.setBlock(world, i + 9, j + 39, k + 103, Dungeons.blockUnbreableStonebrick, 0);
        this.setBlock(world, i + 9, j + 39, k + 104, Dungeons.blockUnbreableStonebrick, 0);
        this.setBlock(world, i + 9, j + 39, k + 105, Dungeons.blockUnbreableStonebrick, 0);
        this.setBlock(world, i + 9, j + 39, k + 106, Dungeons.blockUnbreableStonebrick, 0);
        this.setBlock(world, i + 9, j + 39, k + 107, Dungeons.blockUnbreableStonebrick, 0);
        this.setBlock(world, i + 9, j + 39, k + 108, Blocks.cobblestone_wall, 0);
        this.setBlock(world, i + 10, j + 38, k + 100, Blocks.cobblestone_wall, 0);
        this.setBlock(world, i + 10, j + 38, k + 101, Dungeons.blockUnbreableStonebrick, 0);
        this.setBlock(world, i + 10, j + 38, k + 102, Dungeons.blockUnbreableStonebrick, 0);
        this.setBlock(world, i + 10, j + 38, k + 103, Dungeons.blockUnbreableStonebrick, 0);
        this.setBlock(world, i + 10, j + 38, k + 104, Dungeons.blockUnbreableStonebrick, 0);
        this.setBlock(world, i + 10, j + 38, k + 105, Dungeons.blockUnbreableStonebrick, 0);
        this.setBlock(world, i + 10, j + 38, k + 106, Dungeons.blockUnbreableStonebrick, 0);
        this.setBlock(world, i + 10, j + 38, k + 107, Dungeons.blockUnbreableStonebrick, 0);
        this.setBlock(world, i + 10, j + 38, k + 108, Blocks.cobblestone_wall, 0);
        this.setBlock(world, i + 10, j + 39, k + 100, Blocks.cobblestone_wall, 0);
        this.setBlock(world, i + 10, j + 39, k + 101, Dungeons.blockUnbreableStonebrick, 0);
        this.setBlock(world, i + 10, j + 39, k + 102, Dungeons.blockUnbreableStonebrick, 0);
        this.setBlock(world, i + 10, j + 39, k + 103, Dungeons.blockUnbreableStonebrick, 0);
        this.setBlock(world, i + 10, j + 39, k + 104, Dungeons.blockUnbreableStonebrick, 0);
        this.setBlock(world, i + 10, j + 39, k + 105, Dungeons.blockUnbreableStonebrick, 0);
        this.setBlock(world, i + 10, j + 39, k + 106, Dungeons.blockUnbreableStonebrick, 0);
        this.setBlock(world, i + 10, j + 39, k + 107, Dungeons.blockUnbreableStonebrick, 0);
        this.setBlock(world, i + 10, j + 39, k + 108, Blocks.cobblestone_wall, 0);
        this.setBlock(world, i + 11, j + 38, k + 100, Blocks.cobblestone_wall, 0);
        this.setBlock(world, i + 11, j + 38, k + 101, Dungeons.blockUnbreableStonebrick, 0);
        this.setBlock(world, i + 11, j + 38, k + 102, Dungeons.blockUnbreableStonebrick, 0);
        this.setBlock(world, i + 11, j + 38, k + 103, Dungeons.blockUnbreableStonebrick, 0);
        this.setBlock(world, i + 11, j + 38, k + 104, Dungeons.blockUnbreableStonebrick, 0);
        this.setBlock(world, i + 11, j + 38, k + 105, Dungeons.blockUnbreableStonebrick, 0);
        this.setBlock(world, i + 11, j + 38, k + 106, Dungeons.blockUnbreableStonebrick, 0);
        this.setBlock(world, i + 11, j + 38, k + 107, Dungeons.blockUnbreableStonebrick, 0);
        this.setBlock(world, i + 11, j + 38, k + 108, Blocks.cobblestone_wall, 0);
        this.setBlock(world, i + 11, j + 39, k + 100, Blocks.cobblestone_wall, 0);
        this.setBlock(world, i + 11, j + 39, k + 101, Dungeons.blockUnbreableStonebrick, 0);
        this.setBlock(world, i + 11, j + 39, k + 102, Dungeons.blockUnbreableStonebrick, 0);
        this.setBlock(world, i + 11, j + 39, k + 103, Dungeons.blockUnbreableStonebrick, 0);
        this.setBlock(world, i + 11, j + 39, k + 104, Dungeons.blockUnbreableStonebrick, 0);
        this.setBlock(world, i + 11, j + 39, k + 105, Dungeons.blockUnbreableStonebrick, 0);
        this.setBlock(world, i + 11, j + 39, k + 106, Dungeons.blockUnbreableStonebrick, 0);
        this.setBlock(world, i + 11, j + 39, k + 107, Dungeons.blockUnbreableStonebrick, 0);
        this.setBlock(world, i + 11, j + 39, k + 108, Blocks.cobblestone_wall, 0);
        this.setBlock(world, i + 12, j + 38, k + 100, Dungeons.blockUnbreableStonebrick, 0);
        this.setBlock(world, i + 12, j + 38, k + 101, Dungeons.blockUnbreableStonebrick, 0);
        this.setBlock(world, i + 12, j + 38, k + 102, Dungeons.blockUnbreableStonebrick, 0);
        this.setBlock(world, i + 12, j + 38, k + 103, Dungeons.blockUnbreableStonebrick, 0);
        this.setBlock(world, i + 12, j + 38, k + 104, Dungeons.blockUnbreableStonebrick, 0);
        this.setBlock(world, i + 12, j + 38, k + 105, Dungeons.blockUnbreableStonebrick, 0);
        this.setBlock(world, i + 12, j + 38, k + 106, Dungeons.blockUnbreableStonebrick, 0);
        this.setBlock(world, i + 12, j + 38, k + 107, Dungeons.blockUnbreableStonebrick, 0);
        this.setBlock(world, i + 12, j + 38, k + 108, Dungeons.blockUnbreableStonebrick, 0);
        this.setBlock(world, i + 12, j + 39, k + 100, Dungeons.blockUnbreableStonebrick, 0);
        this.setBlock(world, i + 12, j + 39, k + 101, Dungeons.blockUnbreableStonebrick, 0);
        this.setBlock(world, i + 12, j + 39, k + 102, Dungeons.blockUnbreableStonebrick, 0);
        this.setBlock(world, i + 12, j + 39, k + 103, Dungeons.blockUnbreableStonebrick, 0);
        this.setBlock(world, i + 12, j + 39, k + 104, Dungeons.blockUnbreableStonebrick, 0);
        this.setBlock(world, i + 12, j + 39, k + 105, Dungeons.blockUnbreableStonebrick, 0);
        this.setBlock(world, i + 12, j + 39, k + 106, Dungeons.blockUnbreableStonebrick, 0);
        this.setBlock(world, i + 12, j + 39, k + 107, Dungeons.blockUnbreableStonebrick, 0);
        this.setBlock(world, i + 12, j + 39, k + 108, Dungeons.blockUnbreableStonebrick, 0);
        this.setBlock(world, i + 12, j + 40, k + 100, Dungeons.blockUnbreableStonebrick, 0);
        this.setBlock(world, i + 12, j + 40, k + 108, Dungeons.blockUnbreableStonebrick, 0);
        this.setBlock(world, i + 12, j + 41, k + 100, Dungeons.blockUnbreableStonebrick, 0);
        this.setBlock(world, i + 12, j + 41, k + 108, Dungeons.blockUnbreableStonebrick, 0);
        this.setBlock(world, i + 13, j + 38, k + 100, Dungeons.blockUnbreableStonebrick, 0);
        this.setBlock(world, i + 13, j + 38, k + 101, Dungeons.blockUnbreableStonebrick, 0);
        this.setBlock(world, i + 13, j + 38, k + 102, Dungeons.blockUnbreableStonebrick, 0);
        this.setBlock(world, i + 13, j + 38, k + 103, Dungeons.blockUnbreableStonebrick, 0);
        this.setBlock(world, i + 13, j + 38, k + 104, Dungeons.blockUnbreableStonebrick, 0);
        this.setBlock(world, i + 13, j + 38, k + 105, Dungeons.blockUnbreableStonebrick, 0);
        this.setBlock(world, i + 13, j + 38, k + 106, Dungeons.blockUnbreableStonebrick, 0);
        this.setBlock(world, i + 13, j + 38, k + 107, Dungeons.blockUnbreableStonebrick, 0);
        this.setBlock(world, i + 13, j + 38, k + 108, Dungeons.blockUnbreableStonebrick, 0);
        this.setBlock(world, i + 13, j + 39, k + 100, Dungeons.blockUnbreableStonebrick, 0);
        this.setBlock(world, i + 13, j + 39, k + 101, Dungeons.blockUnbreableStonebrick, 0);
        this.setBlock(world, i + 13, j + 39, k + 102, Dungeons.blockUnbreableStonebrick, 0);
        this.setBlock(world, i + 13, j + 39, k + 103, Dungeons.blockUnbreableStonebrick, 0);
        this.setBlock(world, i + 13, j + 39, k + 104, Dungeons.blockUnbreableStonebrick, 0);
        this.setBlock(world, i + 13, j + 39, k + 105, Dungeons.blockUnbreableStonebrick, 0);
        this.setBlock(world, i + 13, j + 39, k + 106, Dungeons.blockUnbreableStonebrick, 0);
        this.setBlock(world, i + 13, j + 39, k + 107, Dungeons.blockUnbreableStonebrick, 0);
        this.setBlock(world, i + 13, j + 39, k + 108, Dungeons.blockUnbreableStonebrick, 0);
        this.setBlock(world, i + 13, j + 40, k + 100, Dungeons.blockUnbreableStonebrick, 0);
        this.setBlock(world, i + 13, j + 40, k + 108, Dungeons.blockUnbreableStonebrick, 0);
        this.setBlock(world, i + 13, j + 41, k + 100, Dungeons.blockUnbreableStonebrick, 0);
        this.setBlock(world, i + 13, j + 41, k + 108, Dungeons.blockUnbreableStonebrick, 0);
        this.setBlock(world, i + 14, j + 38, k + 100, Blocks.cobblestone_wall, 0);
        this.setBlock(world, i + 14, j + 38, k + 101, Dungeons.blockUnbreableStonebrick, 0);
        this.setBlock(world, i + 14, j + 38, k + 102, Dungeons.blockUnbreableStonebrick, 0);
        this.setBlock(world, i + 14, j + 38, k + 103, Dungeons.blockUnbreableStonebrick, 0);
        this.setBlock(world, i + 14, j + 38, k + 104, Dungeons.blockUnbreableStonebrick, 0);
        this.setBlock(world, i + 14, j + 38, k + 105, Dungeons.blockUnbreableStonebrick, 0);
        this.setBlock(world, i + 14, j + 38, k + 106, Dungeons.blockUnbreableStonebrick, 0);
        this.setBlock(world, i + 14, j + 38, k + 107, Dungeons.blockUnbreableStonebrick, 0);
        this.setBlock(world, i + 14, j + 38, k + 108, Blocks.cobblestone_wall, 0);
        this.setBlock(world, i + 14, j + 39, k + 100, Blocks.cobblestone_wall, 0);
        this.setBlock(world, i + 14, j + 39, k + 101, Dungeons.blockUnbreableStonebrick, 0);
        this.setBlock(world, i + 14, j + 39, k + 102, Dungeons.blockUnbreableStonebrick, 0);
        this.setBlock(world, i + 14, j + 39, k + 103, Dungeons.blockUnbreableStonebrick, 0);
        this.setBlock(world, i + 14, j + 39, k + 104, Dungeons.blockUnbreableStonebrick, 0);
        this.setBlock(world, i + 14, j + 39, k + 105, Dungeons.blockUnbreableStonebrick, 0);
        this.setBlock(world, i + 14, j + 39, k + 106, Dungeons.blockUnbreableStonebrick, 0);
        this.setBlock(world, i + 14, j + 39, k + 107, Dungeons.blockUnbreableStonebrick, 0);
        this.setBlock(world, i + 14, j + 39, k + 108, Blocks.cobblestone_wall, 0);
        this.setBlock(world, i + 15, j + 38, k + 100, Blocks.cobblestone_wall, 0);
        this.setBlock(world, i + 15, j + 38, k + 101, Dungeons.blockUnbreableStonebrick, 0);
        this.setBlock(world, i + 15, j + 38, k + 102, Dungeons.blockUnbreableStonebrick, 0);
        this.setBlock(world, i + 15, j + 38, k + 103, Dungeons.blockUnbreableStonebrick, 0);
        this.setBlock(world, i + 15, j + 38, k + 104, Dungeons.blockUnbreableStonebrick, 0);
        this.setBlock(world, i + 15, j + 38, k + 105, Dungeons.blockUnbreableStonebrick, 0);
        this.setBlock(world, i + 15, j + 38, k + 106, Dungeons.blockUnbreableStonebrick, 0);
        this.setBlock(world, i + 15, j + 38, k + 107, Dungeons.blockUnbreableStonebrick, 0);
        this.setBlock(world, i + 15, j + 38, k + 108, Blocks.cobblestone_wall, 0);
        this.setBlock(world, i + 15, j + 39, k + 100, Blocks.cobblestone_wall, 0);
        this.setBlock(world, i + 15, j + 39, k + 101, Dungeons.blockUnbreableStonebrick, 0);
        this.setBlock(world, i + 15, j + 39, k + 102, Dungeons.blockUnbreableStonebrick, 0);
        this.setBlock(world, i + 15, j + 39, k + 103, Dungeons.blockUnbreableStonebrick, 0);
        this.setBlock(world, i + 15, j + 39, k + 104, Dungeons.blockUnbreableStonebrick, 0);
        this.setBlock(world, i + 15, j + 39, k + 105, Dungeons.blockUnbreableStonebrick, 0);
        this.setBlock(world, i + 15, j + 39, k + 106, Dungeons.blockUnbreableStonebrick, 0);
        this.setBlock(world, i + 15, j + 39, k + 107, Dungeons.blockUnbreableStonebrick, 0);
        this.setBlock(world, i + 15, j + 39, k + 108, Blocks.cobblestone_wall, 0);
        this.setBlock(world, i + 16, j + 38, k + 100, Blocks.cobblestone_wall, 0);
        this.setBlock(world, i + 16, j + 38, k + 101, Dungeons.blockUnbreableStonebrick, 0);
        this.setBlock(world, i + 16, j + 38, k + 102, Dungeons.blockUnbreableStonebrick, 0);
        this.setBlock(world, i + 16, j + 38, k + 103, Dungeons.blockUnbreableStonebrick, 0);
        this.setBlock(world, i + 16, j + 38, k + 104, Dungeons.blockUnbreableStonebrick, 0);
        this.setBlock(world, i + 16, j + 38, k + 105, Dungeons.blockUnbreableStonebrick, 0);
        this.setBlock(world, i + 16, j + 38, k + 106, Dungeons.blockUnbreableStonebrick, 0);
        this.setBlock(world, i + 16, j + 38, k + 107, Dungeons.blockUnbreableStonebrick, 0);
        this.setBlock(world, i + 16, j + 38, k + 108, Blocks.cobblestone_wall, 0);
        this.setBlock(world, i + 16, j + 39, k + 100, Blocks.cobblestone_wall, 0);
        this.setBlock(world, i + 16, j + 39, k + 101, Dungeons.blockUnbreableStonebrick, 0);
        this.setBlock(world, i + 16, j + 39, k + 102, Dungeons.blockUnbreableStonebrick, 0);
        this.setBlock(world, i + 16, j + 39, k + 103, Dungeons.blockUnbreableStonebrick, 0);
        this.setBlock(world, i + 16, j + 39, k + 104, Dungeons.blockUnbreableStonebrick, 0);
        this.setBlock(world, i + 16, j + 39, k + 105, Dungeons.blockUnbreableStonebrick, 0);
        this.setBlock(world, i + 16, j + 39, k + 106, Dungeons.blockUnbreableStonebrick, 0);
        this.setBlock(world, i + 16, j + 39, k + 107, Dungeons.blockUnbreableStonebrick, 0);
        this.setBlock(world, i + 16, j + 39, k + 108, Blocks.cobblestone_wall, 0);
        this.setBlock(world, i + 17, j + 38, k + 100, Dungeons.blockUnbreableStonebrick, 0);
        this.setBlock(world, i + 17, j + 38, k + 101, Dungeons.blockUnbreableStonebrick, 0);
        this.setBlock(world, i + 17, j + 38, k + 102, Dungeons.blockUnbreableStonebrick, 0);
        this.setBlock(world, i + 17, j + 38, k + 103, Dungeons.blockUnbreableStonebrick, 0);
        this.setBlock(world, i + 17, j + 38, k + 104, Dungeons.blockUnbreableStonebrick, 0);
        this.setBlock(world, i + 17, j + 38, k + 105, Dungeons.blockUnbreableStonebrick, 0);
        this.setBlock(world, i + 17, j + 38, k + 106, Dungeons.blockUnbreableStonebrick, 0);
        this.setBlock(world, i + 17, j + 38, k + 107, Dungeons.blockUnbreableStonebrick, 0);
        this.setBlock(world, i + 17, j + 38, k + 108, Dungeons.blockUnbreableStonebrick, 0);
        this.setBlock(world, i + 17, j + 39, k + 100, Dungeons.blockUnbreableStonebrick, 0);
        this.setBlock(world, i + 17, j + 39, k + 101, Dungeons.blockUnbreableStonebrick, 0);
        this.setBlock(world, i + 17, j + 39, k + 102, Dungeons.blockUnbreableStonebrick, 0);
        this.setBlock(world, i + 17, j + 39, k + 103, Dungeons.blockUnbreableStonebrick, 0);
        this.setBlock(world, i + 17, j + 39, k + 104, Dungeons.blockUnbreableStonebrick, 0);
        this.setBlock(world, i + 17, j + 39, k + 105, Dungeons.blockUnbreableStonebrick, 0);
        this.setBlock(world, i + 17, j + 39, k + 106, Dungeons.blockUnbreableStonebrick, 0);
        this.setBlock(world, i + 17, j + 39, k + 107, Dungeons.blockUnbreableStonebrick, 0);
        this.setBlock(world, i + 17, j + 39, k + 108, Dungeons.blockUnbreableStonebrick, 0);
        this.setBlock(world, i + 17, j + 40, k + 100, Dungeons.blockUnbreableStonebrick, 0);
        this.setBlock(world, i + 17, j + 40, k + 108, Dungeons.blockUnbreableStonebrick, 0);
        this.setBlock(world, i + 17, j + 41, k + 100, Dungeons.blockUnbreableStonebrick, 0);
        this.setBlock(world, i + 17, j + 41, k + 108, Dungeons.blockUnbreableStonebrick, 0);
        this.setBlock(world, i + 18, j + 38, k + 100, Dungeons.blockUnbreableStonebrick, 0);
        this.setBlock(world, i + 18, j + 38, k + 101, Dungeons.blockUnbreableStonebrick, 0);
        this.setBlock(world, i + 18, j + 38, k + 102, Dungeons.blockUnbreableStonebrick, 0);
        this.setBlock(world, i + 18, j + 38, k + 103, Dungeons.blockUnbreableStonebrick, 0);
        this.setBlock(world, i + 18, j + 38, k + 104, Dungeons.blockUnbreableStonebrick, 0);
        this.setBlock(world, i + 18, j + 38, k + 105, Dungeons.blockUnbreableStonebrick, 0);
        this.setBlock(world, i + 18, j + 38, k + 106, Dungeons.blockUnbreableStonebrick, 0);
        this.setBlock(world, i + 18, j + 38, k + 107, Dungeons.blockUnbreableStonebrick, 0);
        this.setBlock(world, i + 18, j + 38, k + 108, Dungeons.blockUnbreableStonebrick, 0);
        this.setBlock(world, i + 18, j + 39, k + 100, Dungeons.blockUnbreableStonebrick, 0);
        this.setBlock(world, i + 18, j + 39, k + 101, Dungeons.blockUnbreableStonebrick, 0);
        this.setBlock(world, i + 18, j + 39, k + 102, Dungeons.blockUnbreableStonebrick, 0);
        this.setBlock(world, i + 18, j + 39, k + 103, Dungeons.blockUnbreableStonebrick, 0);
        this.setBlock(world, i + 18, j + 39, k + 104, Dungeons.blockUnbreableStonebrick, 0);
        this.setBlock(world, i + 18, j + 39, k + 105, Dungeons.blockUnbreableStonebrick, 0);
        this.setBlock(world, i + 18, j + 39, k + 106, Dungeons.blockUnbreableStonebrick, 0);
        this.setBlock(world, i + 18, j + 39, k + 107, Dungeons.blockUnbreableStonebrick, 0);
        this.setBlock(world, i + 18, j + 39, k + 108, Dungeons.blockUnbreableStonebrick, 0);
        this.setBlock(world, i + 18, j + 40, k + 100, Dungeons.blockUnbreableStonebrick, 0);
        this.setBlock(world, i + 18, j + 40, k + 108, Dungeons.blockUnbreableStonebrick, 0);
        this.setBlock(world, i + 18, j + 41, k + 100, Dungeons.blockUnbreableStonebrick, 0);
        this.setBlock(world, i + 18, j + 41, k + 108, Dungeons.blockUnbreableStonebrick, 0);
        this.setBlock(world, i + 19, j + 38, k + 100, Blocks.cobblestone_wall, 0);
        this.setBlock(world, i + 19, j + 38, k + 101, Dungeons.blockUnbreableStonebrick, 0);
        this.setBlock(world, i + 19, j + 38, k + 102, Dungeons.blockUnbreableStonebrick, 0);
        this.setBlock(world, i + 19, j + 38, k + 103, Dungeons.blockUnbreableStonebrick, 0);
        this.setBlock(world, i + 19, j + 38, k + 104, Dungeons.blockUnbreableStonebrick, 0);
        this.setBlock(world, i + 19, j + 38, k + 105, Dungeons.blockUnbreableStonebrick, 0);
        this.setBlock(world, i + 19, j + 38, k + 106, Dungeons.blockUnbreableStonebrick, 0);
        this.setBlock(world, i + 19, j + 38, k + 107, Dungeons.blockUnbreableStonebrick, 0);
        this.setBlock(world, i + 19, j + 38, k + 108, Blocks.cobblestone_wall, 0);
        this.setBlock(world, i + 19, j + 39, k + 100, Blocks.cobblestone_wall, 0);
        this.setBlock(world, i + 19, j + 39, k + 101, Dungeons.blockUnbreableStonebrick, 0);
        this.setBlock(world, i + 19, j + 39, k + 102, Dungeons.blockUnbreableStonebrick, 0);
        this.setBlock(world, i + 19, j + 39, k + 103, Dungeons.blockUnbreableStonebrick, 0);
        this.setBlock(world, i + 19, j + 39, k + 104, Dungeons.blockUnbreableStonebrick, 0);
        this.setBlock(world, i + 19, j + 39, k + 105, Dungeons.blockUnbreableStonebrick, 0);
        this.setBlock(world, i + 19, j + 39, k + 106, Dungeons.blockUnbreableStonebrick, 0);
        this.setBlock(world, i + 19, j + 39, k + 107, Dungeons.blockUnbreableStonebrick, 0);
        this.setBlock(world, i + 19, j + 39, k + 108, Blocks.cobblestone_wall, 0);
        this.setBlock(world, i + 20, j + 38, k + 100, Blocks.cobblestone_wall, 0);
        this.setBlock(world, i + 20, j + 38, k + 101, Dungeons.blockUnbreableStonebrick, 0);
        this.setBlock(world, i + 20, j + 38, k + 102, Dungeons.blockUnbreableStonebrick, 0);
        this.setBlock(world, i + 20, j + 38, k + 103, Dungeons.blockUnbreableStonebrick, 0);
        this.setBlock(world, i + 20, j + 38, k + 104, Dungeons.blockUnbreableStonebrick, 0);
        this.setBlock(world, i + 20, j + 38, k + 105, Dungeons.blockUnbreableStonebrick, 0);
        this.setBlock(world, i + 20, j + 38, k + 106, Dungeons.blockUnbreableStonebrick, 0);
        this.setBlock(world, i + 20, j + 38, k + 107, Dungeons.blockUnbreableStonebrick, 0);
        this.setBlock(world, i + 20, j + 38, k + 108, Blocks.cobblestone_wall, 0);
        this.setBlock(world, i + 20, j + 39, k + 100, Blocks.cobblestone_wall, 0);
        this.setBlock(world, i + 20, j + 39, k + 101, Dungeons.blockUnbreableStonebrick, 0);
        this.setBlock(world, i + 20, j + 39, k + 102, Dungeons.blockUnbreableStonebrick, 0);
        this.setBlock(world, i + 20, j + 39, k + 103, Dungeons.blockUnbreableStonebrick, 0);
        this.setBlock(world, i + 20, j + 39, k + 104, Dungeons.blockUnbreableStonebrick, 0);
        this.setBlock(world, i + 20, j + 39, k + 105, Dungeons.blockUnbreableStonebrick, 0);
        this.setBlock(world, i + 20, j + 39, k + 106, Dungeons.blockUnbreableStonebrick, 0);
        this.setBlock(world, i + 20, j + 39, k + 107, Dungeons.blockUnbreableStonebrick, 0);
        this.setBlock(world, i + 20, j + 39, k + 108, Blocks.cobblestone_wall, 0);
        this.setBlock(world, i + 21, j + 38, k + 100, Blocks.cobblestone_wall, 0);
        this.setBlock(world, i + 21, j + 38, k + 101, Dungeons.blockUnbreableStonebrick, 0);
        this.setBlock(world, i + 21, j + 38, k + 102, Dungeons.blockUnbreableStonebrick, 0);
        this.setBlock(world, i + 21, j + 38, k + 103, Dungeons.blockUnbreableStonebrick, 0);
        this.setBlock(world, i + 21, j + 38, k + 104, Dungeons.blockUnbreableStonebrick, 0);
        this.setBlock(world, i + 21, j + 38, k + 105, Dungeons.blockUnbreableStonebrick, 0);
        this.setBlock(world, i + 21, j + 38, k + 106, Dungeons.blockUnbreableStonebrick, 0);
        this.setBlock(world, i + 21, j + 38, k + 107, Dungeons.blockUnbreableStonebrick, 0);
        this.setBlock(world, i + 21, j + 38, k + 108, Blocks.cobblestone_wall, 0);
        this.setBlock(world, i + 21, j + 39, k + 100, Blocks.cobblestone_wall, 0);
        this.setBlock(world, i + 21, j + 39, k + 101, Dungeons.blockUnbreableStonebrick, 0);
        this.setBlock(world, i + 21, j + 39, k + 102, Dungeons.blockUnbreableStonebrick, 0);
        this.setBlock(world, i + 21, j + 39, k + 103, Dungeons.blockUnbreableStonebrick, 0);
        this.setBlock(world, i + 21, j + 39, k + 104, Dungeons.blockUnbreableStonebrick, 0);
        this.setBlock(world, i + 21, j + 39, k + 105, Dungeons.blockUnbreableStonebrick, 0);
        this.setBlock(world, i + 21, j + 39, k + 106, Dungeons.blockUnbreableStonebrick, 0);
        this.setBlock(world, i + 21, j + 39, k + 107, Dungeons.blockUnbreableStonebrick, 0);
        this.setBlock(world, i + 21, j + 39, k + 108, Blocks.cobblestone_wall, 0);
        Dungeons.spawner(world, i + 18, j + 40, k + 104, 38, 2);
        Dungeons.spawner(world, i + 21, j + 40, k + 104, 39, 2);
        Dungeons.spawner(world, i + 20, j + 40, k + 104, 37, 3);
        this.setBlock(world, i + 22, j + 38, k + 100, Dungeons.blockUnbreableStonebrick, 0);
        this.setBlock(world, i + 22, j + 38, k + 101, Dungeons.blockUnbreableStonebrick, 0);
        this.setBlock(world, i + 22, j + 38, k + 102, Dungeons.blockUnbreableStonebrick, 0);
        this.setBlock(world, i + 22, j + 38, k + 103, Dungeons.blockUnbreableStonebrick, 0);
        this.setBlock(world, i + 22, j + 38, k + 104, Dungeons.blockUnbreableStonebrick, 0);
        this.setBlock(world, i + 22, j + 38, k + 105, Dungeons.blockUnbreableStonebrick, 0);
        this.setBlock(world, i + 22, j + 38, k + 106, Dungeons.blockUnbreableStonebrick, 0);
        this.setBlock(world, i + 22, j + 38, k + 107, Dungeons.blockUnbreableStonebrick, 0);
        this.setBlock(world, i + 22, j + 38, k + 108, Dungeons.blockUnbreableStonebrick, 0);
        this.setBlock(world, i + 22, j + 39, k + 100, Dungeons.blockUnbreableStonebrick, 0);
        this.setBlock(world, i + 22, j + 39, k + 101, Dungeons.blockUnbreableStonebrick, 0);
        this.setBlock(world, i + 22, j + 39, k + 102, Dungeons.blockUnbreableStonebrick, 0);
        this.setBlock(world, i + 22, j + 39, k + 103, Dungeons.blockUnbreableStonebrick, 0);
        this.setBlock(world, i + 22, j + 39, k + 104, Dungeons.blockUnbreableStonebrick, 0);
        this.setBlock(world, i + 22, j + 39, k + 105, Dungeons.blockUnbreableStonebrick, 0);
        this.setBlock(world, i + 22, j + 39, k + 106, Dungeons.blockUnbreableStonebrick, 0);
        this.setBlock(world, i + 22, j + 39, k + 107, Dungeons.blockUnbreableStonebrick, 0);
        this.setBlock(world, i + 22, j + 39, k + 108, Dungeons.blockUnbreableStonebrick, 0);
        this.setBlock(world, i + 22, j + 40, k + 100, Dungeons.blockUnbreableStonebrick, 0);
        this.setBlock(world, i + 22, j + 40, k + 108, Dungeons.blockUnbreableStonebrick, 0);
        this.setBlock(world, i + 22, j + 41, k + 100, Dungeons.blockUnbreableStonebrick, 0);
        this.setBlock(world, i + 22, j + 41, k + 108, Dungeons.blockUnbreableStonebrick, 0);
        this.setBlock(world, i + 23, j + 38, k + 100, Dungeons.blockUnbreableStonebrick, 0);
        this.setBlock(world, i + 23, j + 38, k + 101, Dungeons.blockUnbreableStonebrick, 0);
        this.setBlock(world, i + 23, j + 38, k + 102, Dungeons.blockUnbreableStonebrick, 0);
        this.setBlock(world, i + 23, j + 38, k + 103, Dungeons.blockUnbreableStonebrick, 0);
        this.setBlock(world, i + 23, j + 38, k + 104, Dungeons.blockUnbreableStonebrick, 0);
        this.setBlock(world, i + 23, j + 38, k + 105, Dungeons.blockUnbreableStonebrick, 0);
        this.setBlock(world, i + 23, j + 38, k + 106, Dungeons.blockUnbreableStonebrick, 0);
        this.setBlock(world, i + 23, j + 38, k + 107, Dungeons.blockUnbreableStonebrick, 0);
        this.setBlock(world, i + 23, j + 38, k + 108, Dungeons.blockUnbreableStonebrick, 0);
        this.setBlock(world, i + 23, j + 39, k + 100, Dungeons.blockUnbreableStonebrick, 0);
        this.setBlock(world, i + 23, j + 39, k + 101, Dungeons.blockUnbreableStonebrick, 0);
        this.setBlock(world, i + 23, j + 39, k + 102, Dungeons.blockUnbreableStonebrick, 0);
        this.setBlock(world, i + 23, j + 39, k + 103, Dungeons.blockUnbreableStonebrick, 0);
        this.setBlock(world, i + 23, j + 39, k + 104, Dungeons.blockUnbreableStonebrick, 0);
        this.setBlock(world, i + 23, j + 39, k + 105, Dungeons.blockUnbreableStonebrick, 0);
        this.setBlock(world, i + 23, j + 39, k + 106, Dungeons.blockUnbreableStonebrick, 0);
        this.setBlock(world, i + 23, j + 39, k + 107, Dungeons.blockUnbreableStonebrick, 0);
        this.setBlock(world, i + 23, j + 39, k + 108, Dungeons.blockUnbreableStonebrick, 0);
        this.setBlock(world, i + 23, j + 40, k + 100, Dungeons.blockUnbreableStonebrick, 0);
        this.setBlock(world, i + 23, j + 40, k + 108, Dungeons.blockUnbreableStonebrick, 0);
        this.setBlock(world, i + 23, j + 41, k + 100, Dungeons.blockUnbreableStonebrick, 0);
        this.setBlock(world, i + 23, j + 41, k + 108, Dungeons.blockUnbreableStonebrick, 0);
        this.setBlock(world, i + 24, j + 38, k + 100, Blocks.cobblestone_wall, 0);
        this.setBlock(world, i + 24, j + 38, k + 101, Dungeons.blockUnbreableStonebrick, 0);
        this.setBlock(world, i + 24, j + 38, k + 102, Dungeons.blockUnbreableStonebrick, 0);
        this.setBlock(world, i + 24, j + 38, k + 103, Dungeons.blockUnbreableStonebrick, 0);
        this.setBlock(world, i + 24, j + 38, k + 104, Dungeons.blockUnbreableStonebrick, 0);
        this.setBlock(world, i + 24, j + 38, k + 105, Dungeons.blockUnbreableStonebrick, 0);
        this.setBlock(world, i + 24, j + 38, k + 106, Dungeons.blockUnbreableStonebrick, 0);
        this.setBlock(world, i + 24, j + 38, k + 107, Dungeons.blockUnbreableStonebrick, 0);
        this.setBlock(world, i + 24, j + 38, k + 108, Blocks.cobblestone_wall, 0);
        this.setBlock(world, i + 24, j + 39, k + 100, Blocks.cobblestone_wall, 0);
        this.setBlock(world, i + 24, j + 39, k + 101, Dungeons.blockUnbreableStonebrick, 0);
        this.setBlock(world, i + 24, j + 39, k + 102, Dungeons.blockUnbreableStonebrick, 0);
        this.setBlock(world, i + 24, j + 39, k + 103, Dungeons.blockUnbreableStonebrick, 0);
        this.setBlock(world, i + 24, j + 39, k + 104, Dungeons.blockUnbreableStonebrick, 0);
        this.setBlock(world, i + 24, j + 39, k + 105, Dungeons.blockUnbreableStonebrick, 0);
        this.setBlock(world, i + 24, j + 39, k + 106, Dungeons.blockUnbreableStonebrick, 0);
        this.setBlock(world, i + 24, j + 39, k + 107, Dungeons.blockUnbreableStonebrick, 0);
        this.setBlock(world, i + 24, j + 39, k + 108, Blocks.cobblestone_wall, 0);
        this.setBlock(world, i + 25, j + 38, k + 100, Blocks.cobblestone_wall, 0);
        this.setBlock(world, i + 25, j + 38, k + 101, Dungeons.blockUnbreableStonebrick, 0);
        this.setBlock(world, i + 25, j + 38, k + 102, Dungeons.blockUnbreableStonebrick, 0);
        this.setBlock(world, i + 25, j + 38, k + 103, Dungeons.blockUnbreableStonebrick, 0);
        this.setBlock(world, i + 25, j + 38, k + 104, Dungeons.blockUnbreableStonebrick, 0);
        this.setBlock(world, i + 25, j + 38, k + 105, Dungeons.blockUnbreableStonebrick, 0);
        this.setBlock(world, i + 25, j + 38, k + 106, Dungeons.blockUnbreableStonebrick, 0);
        this.setBlock(world, i + 25, j + 38, k + 107, Dungeons.blockUnbreableStonebrick, 0);
        this.setBlock(world, i + 25, j + 38, k + 108, Blocks.cobblestone_wall, 0);
        this.setBlock(world, i + 25, j + 39, k + 100, Blocks.cobblestone_wall, 0);
        this.setBlock(world, i + 25, j + 39, k + 101, Dungeons.blockUnbreableStonebrick, 0);
        this.setBlock(world, i + 25, j + 39, k + 102, Dungeons.blockUnbreableStonebrick, 0);
        this.setBlock(world, i + 25, j + 39, k + 103, Dungeons.blockUnbreableStonebrick, 0);
        this.setBlock(world, i + 25, j + 39, k + 104, Dungeons.blockUnbreableStonebrick, 0);
        this.setBlock(world, i + 25, j + 39, k + 105, Dungeons.blockUnbreableStonebrick, 0);
        this.setBlock(world, i + 25, j + 39, k + 106, Dungeons.blockUnbreableStonebrick, 0);
        this.setBlock(world, i + 25, j + 39, k + 107, Dungeons.blockUnbreableStonebrick, 0);
        this.setBlock(world, i + 25, j + 39, k + 108, Blocks.cobblestone_wall, 0);
        this.setBlock(world, i + 26, j + 38, k + 100, Blocks.cobblestone_wall, 0);
        this.setBlock(world, i + 26, j + 38, k + 101, Dungeons.blockUnbreableStonebrick, 0);
        this.setBlock(world, i + 26, j + 38, k + 102, Dungeons.blockUnbreableStonebrick, 0);
        this.setBlock(world, i + 26, j + 38, k + 103, Dungeons.blockUnbreableStonebrick, 0);
        this.setBlock(world, i + 26, j + 38, k + 104, Dungeons.blockUnbreableStonebrick, 0);
        this.setBlock(world, i + 26, j + 38, k + 105, Dungeons.blockUnbreableStonebrick, 0);
        this.setBlock(world, i + 26, j + 38, k + 106, Dungeons.blockUnbreableStonebrick, 0);
        this.setBlock(world, i + 26, j + 38, k + 107, Dungeons.blockUnbreableStonebrick, 0);
        this.setBlock(world, i + 26, j + 38, k + 108, Blocks.cobblestone_wall, 0);
        this.setBlock(world, i + 26, j + 39, k + 100, Blocks.cobblestone_wall, 0);
        this.setBlock(world, i + 26, j + 39, k + 101, Dungeons.blockUnbreableStonebrick, 0);
        this.setBlock(world, i + 26, j + 39, k + 102, Dungeons.blockUnbreableStonebrick, 0);
        this.setBlock(world, i + 26, j + 39, k + 103, Dungeons.blockUnbreableStonebrick, 0);
        this.setBlock(world, i + 26, j + 39, k + 104, Dungeons.blockUnbreableStonebrick, 0);
        this.setBlock(world, i + 26, j + 39, k + 105, Dungeons.blockUnbreableStonebrick, 0);
        this.setBlock(world, i + 26, j + 39, k + 106, Dungeons.blockUnbreableStonebrick, 0);
        this.setBlock(world, i + 26, j + 39, k + 107, Dungeons.blockUnbreableStonebrick, 0);
        this.setBlock(world, i + 26, j + 39, k + 108, Blocks.cobblestone_wall, 0);
        this.setBlock(world, i + 26, j + 43, k + 95, Blocks.cobblestone_wall, 0);
        this.setBlock(world, i + 26, j + 43, k + 96, Blocks.cobblestone_wall, 0);
        this.setBlock(world, i + 26, j + 43, k + 97, Blocks.cobblestone_wall, 0);
        this.setBlock(world, i + 26, j + 43, k + 111, Blocks.cobblestone_wall, 0);
        this.setBlock(world, i + 26, j + 43, k + 112, Blocks.cobblestone_wall, 0);
        this.setBlock(world, i + 26, j + 43, k + 113, Blocks.cobblestone_wall, 0);
        this.setBlock(world, i + 26, j + 44, k + 95, Blocks.stained_hardened_clay, 9);
        this.setBlock(world, i + 26, j + 44, k + 96, Blocks.stained_hardened_clay, 9);
        this.setBlock(world, i + 26, j + 44, k + 97, Blocks.stained_hardened_clay, 9);
        this.setBlock(world, i + 26, j + 44, k + 111, Blocks.stained_hardened_clay, 9);
        this.setBlock(world, i + 26, j + 44, k + 112, Blocks.stained_hardened_clay, 9);
        this.setBlock(world, i + 26, j + 44, k + 113, Blocks.stained_hardened_clay, 9);
        this.setBlock(world, i + 26, j + 48, k + 95, Blocks.cobblestone_wall, 0);
        this.setBlock(world, i + 26, j + 48, k + 96, Blocks.cobblestone_wall, 0);
        this.setBlock(world, i + 26, j + 48, k + 97, Blocks.cobblestone_wall, 0);
        this.setBlock(world, i + 26, j + 48, k + 111, Blocks.cobblestone_wall, 0);
        this.setBlock(world, i + 26, j + 48, k + 112, Blocks.cobblestone_wall, 0);
        this.setBlock(world, i + 26, j + 48, k + 113, Blocks.cobblestone_wall, 0);
        this.setBlock(world, i + 26, j + 49, k + 95, Blocks.stained_hardened_clay, 9);
        this.setBlock(world, i + 26, j + 49, k + 96, Blocks.stained_hardened_clay, 9);
        this.setBlock(world, i + 26, j + 49, k + 97, Blocks.stained_hardened_clay, 9);
        this.setBlock(world, i + 26, j + 49, k + 111, Blocks.stained_hardened_clay, 9);
        this.setBlock(world, i + 26, j + 49, k + 112, Blocks.stained_hardened_clay, 9);
        this.setBlock(world, i + 26, j + 49, k + 113, Blocks.stained_hardened_clay, 9);
        this.setBlock(world, i + 26, j + 53, k + 95, Blocks.cobblestone_wall, 0);
        this.setBlock(world, i + 26, j + 53, k + 96, Blocks.cobblestone_wall, 0);
        this.setBlock(world, i + 26, j + 53, k + 97, Blocks.cobblestone_wall, 0);
        this.setBlock(world, i + 26, j + 53, k + 111, Blocks.cobblestone_wall, 0);
        this.setBlock(world, i + 26, j + 53, k + 112, Blocks.cobblestone_wall, 0);
        this.setBlock(world, i + 26, j + 53, k + 113, Blocks.cobblestone_wall, 0);
        this.setBlock(world, i + 27, j + 38, k + 96, Dungeons.blockUnbreableStonebrick, 0);
        this.setBlock(world, i + 27, j + 38, k + 97, Dungeons.blockUnbreableStonebrick, 0);
        this.setBlock(world, i + 27, j + 38, k + 100, Dungeons.blockUnbreableStonebrick, 0);
        this.setBlock(world, i + 27, j + 38, k + 101, Dungeons.blockUnbreableStonebrick, 0);
        this.setBlock(world, i + 27, j + 38, k + 102, Dungeons.blockUnbreableStonebrick, 0);
        this.setBlock(world, i + 27, j + 38, k + 103, Dungeons.blockUnbreableStonebrick, 0);
        this.setBlock(world, i + 27, j + 38, k + 104, Dungeons.blockUnbreableStonebrick, 0);
        this.setBlock(world, i + 27, j + 38, k + 105, Dungeons.blockUnbreableStonebrick, 0);
        this.setBlock(world, i + 27, j + 38, k + 106, Dungeons.blockUnbreableStonebrick, 0);
        this.setBlock(world, i + 27, j + 38, k + 107, Dungeons.blockUnbreableStonebrick, 0);
        this.setBlock(world, i + 27, j + 38, k + 108, Dungeons.blockUnbreableStonebrick, 0);
        this.setBlock(world, i + 27, j + 38, k + 111, Dungeons.blockUnbreableStonebrick, 0);
        this.setBlock(world, i + 27, j + 38, k + 112, Dungeons.blockUnbreableStonebrick, 0);
        this.setBlock(world, i + 27, j + 39, k + 95, Dungeons.blockUnbreableStonebrick, 0);
        this.setBlock(world, i + 27, j + 39, k + 96, Dungeons.blockUnbreableStonebrick, 0);
        this.setBlock(world, i + 27, j + 39, k + 97, Dungeons.blockUnbreableStonebrick, 0);
        this.setBlock(world, i + 27, j + 39, k + 100, Dungeons.blockUnbreableStonebrick, 0);
        this.setBlock(world, i + 27, j + 39, k + 101, Dungeons.blockUnbreableStonebrick, 0);
        this.setBlock(world, i + 27, j + 39, k + 102, Dungeons.blockUnbreableStonebrick, 0);
        this.setBlock(world, i + 27, j + 39, k + 103, Dungeons.blockUnbreableStonebrick, 0);
        this.setBlock(world, i + 27, j + 39, k + 104, Dungeons.blockUnbreableStonebrick, 0);
        this.setBlock(world, i + 27, j + 39, k + 105, Dungeons.blockUnbreableStonebrick, 0);
        this.setBlock(world, i + 27, j + 39, k + 106, Dungeons.blockUnbreableStonebrick, 0);
        this.setBlock(world, i + 27, j + 39, k + 107, Dungeons.blockUnbreableStonebrick, 0);
        this.setBlock(world, i + 27, j + 39, k + 108, Dungeons.blockUnbreableStonebrick, 0);
        this.setBlock(world, i + 27, j + 39, k + 111, Dungeons.blockUnbreableStonebrick, 0);
        this.setBlock(world, i + 27, j + 39, k + 112, Dungeons.blockUnbreableStonebrick, 0);
        this.setBlock(world, i + 27, j + 39, k + 113, Dungeons.blockUnbreableStonebrick, 0);
        this.setBlock(world, i + 27, j + 40, k + 95, Dungeons.blockUnbreableStonebrick, 0);
        this.setBlock(world, i + 27, j + 40, k + 96, Dungeons.blockUnbreableStonebrick, 0);
        this.setBlock(world, i + 27, j + 40, k + 97, Dungeons.blockUnbreableStonebrick, 0);
        this.setBlock(world, i + 27, j + 40, k + 100, Dungeons.blockUnbreableStonebrick, 0);
        this.setBlock(world, i + 27, j + 40, k + 108, Dungeons.blockUnbreableStonebrick, 0);
        this.setBlock(world, i + 27, j + 40, k + 111, Dungeons.blockUnbreableStonebrick, 0);
        this.setBlock(world, i + 27, j + 40, k + 112, Dungeons.blockUnbreableStonebrick, 0);
        this.setBlock(world, i + 27, j + 40, k + 113, Dungeons.blockUnbreableStonebrick, 0);
        this.setBlock(world, i + 27, j + 41, k + 95, Dungeons.blockUnbreableStonebrick, 0);
        this.setBlock(world, i + 27, j + 41, k + 96, Dungeons.blockUnbreableStonebrick, 0);
        this.setBlock(world, i + 27, j + 41, k + 97, Dungeons.blockUnbreableStonebrick, 0);
        this.setBlock(world, i + 27, j + 41, k + 100, Dungeons.blockUnbreableStonebrick, 0);
        this.setBlock(world, i + 27, j + 41, k + 108, Dungeons.blockUnbreableStonebrick, 0);
        this.setBlock(world, i + 27, j + 41, k + 111, Dungeons.blockUnbreableStonebrick, 0);
        this.setBlock(world, i + 27, j + 41, k + 112, Dungeons.blockUnbreableStonebrick, 0);
        this.setBlock(world, i + 27, j + 41, k + 113, Dungeons.blockUnbreableStonebrick, 0);
        this.setBlock(world, i + 27, j + 42, k + 95, Dungeons.blockUnbreableStonebrick, 0);
        this.setBlock(world, i + 27, j + 42, k + 96, Dungeons.blockUnbreableStonebrick, 0);
        this.setBlock(world, i + 27, j + 42, k + 97, Dungeons.blockUnbreableStonebrick, 0);
        this.setBlock(world, i + 27, j + 42, k + 111, Dungeons.blockUnbreableStonebrick, 0);
        this.setBlock(world, i + 27, j + 42, k + 112, Dungeons.blockUnbreableStonebrick, 0);
        this.setBlock(world, i + 27, j + 42, k + 113, Dungeons.blockUnbreableStonebrick, 0);
        this.setBlock(world, i + 27, j + 43, k + 94, Blocks.cobblestone_wall, 0);
        this.setBlock(world, i + 27, j + 43, k + 95, Dungeons.blockUnbreableStonebrick, 0);
        this.setBlock(world, i + 27, j + 43, k + 96, Dungeons.blockUnbreableStonebrick, 0);
        this.setBlock(world, i + 27, j + 43, k + 97, Dungeons.blockUnbreableStonebrick, 0);
        this.setBlock(world, i + 27, j + 43, k + 98, Blocks.cobblestone_wall, 0);
        this.setBlock(world, i + 27, j + 43, k + 110, Blocks.cobblestone_wall, 0);
        this.setBlock(world, i + 27, j + 43, k + 111, Dungeons.blockUnbreableStonebrick, 0);
        this.setBlock(world, i + 27, j + 43, k + 112, Dungeons.blockUnbreableStonebrick, 0);
        this.setBlock(world, i + 27, j + 43, k + 113, Dungeons.blockUnbreableStonebrick, 0);
        this.setBlock(world, i + 27, j + 43, k + 114, Blocks.cobblestone_wall, 0);
        this.setBlock(world, i + 27, j + 44, k + 94, Blocks.stained_hardened_clay, 9);
        this.setBlock(world, i + 27, j + 44, k + 95, Dungeons.blockUnbreableStonebrick, 0);
        this.setBlock(world, i + 27, j + 44, k + 96, Dungeons.blockUnbreableStonebrick, 0);
        this.setBlock(world, i + 27, j + 44, k + 97, Dungeons.blockUnbreableStonebrick, 0);
        this.setBlock(world, i + 27, j + 44, k + 98, Blocks.stained_hardened_clay, 9);
        this.setBlock(world, i + 27, j + 44, k + 110, Blocks.stained_hardened_clay, 9);
        this.setBlock(world, i + 27, j + 44, k + 111, Dungeons.blockUnbreableStonebrick, 0);
        this.setBlock(world, i + 27, j + 44, k + 112, Dungeons.blockUnbreableStonebrick, 0);
        this.setBlock(world, i + 27, j + 44, k + 113, Dungeons.blockUnbreableStonebrick, 0);
        this.setBlock(world, i + 27, j + 44, k + 114, Blocks.stained_hardened_clay, 9);
        this.setBlock(world, i + 27, j + 45, k + 95, Dungeons.blockUnbreableStonebrick, 0);
        this.setBlock(world, i + 27, j + 45, k + 96, Blocks.iron_bars, 0);
        this.setBlock(world, i + 27, j + 45, k + 97, Dungeons.blockUnbreableStonebrick, 0);
        this.setBlock(world, i + 27, j + 45, k + 111, Dungeons.blockUnbreableStonebrick, 0);
        this.setBlock(world, i + 27, j + 45, k + 112, Blocks.iron_bars, 0);
        this.setBlock(world, i + 27, j + 45, k + 113, Dungeons.blockUnbreableStonebrick, 0);
        this.setBlock(world, i + 27, j + 46, k + 95, Dungeons.blockUnbreableStonebrick, 0);
        this.setBlock(world, i + 27, j + 46, k + 96, Blocks.iron_bars, 0);
        this.setBlock(world, i + 27, j + 46, k + 97, Dungeons.blockUnbreableStonebrick, 0);
        this.setBlock(world, i + 27, j + 46, k + 111, Dungeons.blockUnbreableStonebrick, 0);
        this.setBlock(world, i + 27, j + 46, k + 112, Blocks.iron_bars, 0);
        this.setBlock(world, i + 27, j + 46, k + 113, Dungeons.blockUnbreableStonebrick, 0);
        this.setBlock(world, i + 27, j + 47, k + 95, Dungeons.blockUnbreableStonebrick, 0);
        this.setBlock(world, i + 27, j + 47, k + 96, Dungeons.blockUnbreableStonebrick, 0);
        this.setBlock(world, i + 27, j + 47, k + 97, Dungeons.blockUnbreableStonebrick, 0);
        this.setBlock(world, i + 27, j + 47, k + 111, Dungeons.blockUnbreableStonebrick, 0);
        this.setBlock(world, i + 27, j + 47, k + 112, Dungeons.blockUnbreableStonebrick, 0);
        this.setBlock(world, i + 27, j + 47, k + 113, Dungeons.blockUnbreableStonebrick, 0);
        this.setBlock(world, i + 27, j + 48, k + 94, Blocks.cobblestone_wall, 0);
        this.setBlock(world, i + 27, j + 48, k + 95, Dungeons.blockUnbreableStonebrick, 0);
        this.setBlock(world, i + 27, j + 48, k + 96, Dungeons.blockUnbreableStonebrick, 0);
        this.setBlock(world, i + 27, j + 48, k + 97, Dungeons.blockUnbreableStonebrick, 0);
        this.setBlock(world, i + 27, j + 48, k + 98, Blocks.cobblestone_wall, 0);
        this.setBlock(world, i + 27, j + 48, k + 110, Blocks.cobblestone_wall, 0);
        this.setBlock(world, i + 27, j + 48, k + 111, Dungeons.blockUnbreableStonebrick, 0);
        this.setBlock(world, i + 27, j + 48, k + 112, Dungeons.blockUnbreableStonebrick, 0);
        this.setBlock(world, i + 27, j + 48, k + 113, Dungeons.blockUnbreableStonebrick, 0);
        this.setBlock(world, i + 27, j + 48, k + 114, Blocks.cobblestone_wall, 0);
        this.setBlock(world, i + 27, j + 49, k + 94, Blocks.stained_hardened_clay, 9);
        this.setBlock(world, i + 27, j + 49, k + 95, Dungeons.blockUnbreableStonebrick, 0);
        this.setBlock(world, i + 27, j + 49, k + 96, Dungeons.blockUnbreableStonebrick, 0);
        this.setBlock(world, i + 27, j + 49, k + 97, Dungeons.blockUnbreableStonebrick, 0);
        this.setBlock(world, i + 27, j + 49, k + 98, Blocks.stained_hardened_clay, 9);
        this.setBlock(world, i + 27, j + 49, k + 110, Blocks.stained_hardened_clay, 9);
        this.setBlock(world, i + 27, j + 49, k + 111, Dungeons.blockUnbreableStonebrick, 0);
        this.setBlock(world, i + 27, j + 49, k + 112, Dungeons.blockUnbreableStonebrick, 0);
        this.setBlock(world, i + 27, j + 49, k + 113, Dungeons.blockUnbreableStonebrick, 0);
        this.setBlock(world, i + 27, j + 49, k + 114, Blocks.stained_hardened_clay, 9);
        this.setBlock(world, i + 27, j + 50, k + 94, Blocks.stained_hardened_clay, 9);
        this.setBlock(world, i + 27, j + 50, k + 95, Dungeons.blockUnbreableStonebrick, 0);
        this.setBlock(world, i + 27, j + 50, k + 97, Dungeons.blockUnbreableStonebrick, 0);
        this.setBlock(world, i + 27, j + 50, k + 110, Blocks.stained_hardened_clay, 9);
        this.setBlock(world, i + 27, j + 50, k + 111, Dungeons.blockUnbreableStonebrick, 0);
        this.setBlock(world, i + 27, j + 50, k + 113, Dungeons.blockUnbreableStonebrick, 0);
        this.setBlock(world, i + 27, j + 51, k + 95, Dungeons.blockUnbreableStonebrick, 0);
        this.setBlock(world, i + 27, j + 51, k + 97, Dungeons.blockUnbreableStonebrick, 0);
        this.setBlock(world, i + 27, j + 51, k + 111, Dungeons.blockUnbreableStonebrick, 0);
        this.setBlock(world, i + 27, j + 51, k + 113, Dungeons.blockUnbreableStonebrick, 0);
        this.setBlock(world, i + 27, j + 52, k + 95, Dungeons.blockUnbreableStonebrick, 0);
        this.setBlock(world, i + 27, j + 52, k + 96, Dungeons.blockUnbreableStonebrick, 0);
        this.setBlock(world, i + 27, j + 52, k + 97, Dungeons.blockUnbreableStonebrick, 0);
        this.setBlock(world, i + 27, j + 52, k + 111, Dungeons.blockUnbreableStonebrick, 0);
        this.setBlock(world, i + 27, j + 52, k + 112, Dungeons.blockUnbreableStonebrick, 0);
        this.setBlock(world, i + 27, j + 52, k + 113, Dungeons.blockUnbreableStonebrick, 0);
        this.setBlock(world, i + 27, j + 53, k + 94, Blocks.cobblestone_wall, 0);
        this.setBlock(world, i + 27, j + 53, k + 95, Dungeons.blockUnbreableStonebrick, 0);
        this.setBlock(world, i + 27, j + 53, k + 96, Dungeons.blockUnbreableStonebrick, 0);
        this.setBlock(world, i + 27, j + 53, k + 97, Dungeons.blockUnbreableStonebrick, 0);
        this.setBlock(world, i + 27, j + 53, k + 98, Blocks.cobblestone_wall, 0);
        this.setBlock(world, i + 27, j + 53, k + 110, Blocks.cobblestone_wall, 0);
        this.setBlock(world, i + 27, j + 53, k + 111, Dungeons.blockUnbreableStonebrick, 0);
        this.setBlock(world, i + 27, j + 53, k + 112, Dungeons.blockUnbreableStonebrick, 0);
        this.setBlock(world, i + 27, j + 53, k + 113, Dungeons.blockUnbreableStonebrick, 0);
        this.setBlock(world, i + 27, j + 53, k + 114, Blocks.cobblestone_wall, 0);
        this.setBlock(world, i + 28, j + 37, k + 96, Dungeons.blockUnbreableStonebrick, 0);
        this.setBlock(world, i + 28, j + 37, k + 97, Dungeons.blockUnbreableStonebrick, 0);
        this.setBlock(world, i + 28, j + 37, k + 98, Dungeons.blockUnbreableStonebrick, 0);
        this.setBlock(world, i + 28, j + 37, k + 110, Dungeons.blockUnbreableStonebrick, 0);
        this.setBlock(world, i + 28, j + 37, k + 111, Dungeons.blockUnbreableStonebrick, 0);
        this.setBlock(world, i + 28, j + 37, k + 112, Dungeons.blockUnbreableStonebrick, 0);
        this.setBlock(world, i + 28, j + 38, k + 95, Dungeons.blockUnbreableStonebrick, 0);
        this.setBlock(world, i + 28, j + 38, k + 96, Dungeons.blockUnbreableStonebrick, 0);
        this.setBlock(world, i + 28, j + 38, k + 97, Dungeons.blockUnbreableStonebrick, 0);
        this.setBlock(world, i + 28, j + 38, k + 98, Dungeons.blockUnbreableStonebrick, 0);
        this.setBlock(world, i + 28, j + 38, k + 100, Dungeons.blockUnbreableStonebrick, 0);
        this.setBlock(world, i + 28, j + 38, k + 101, Dungeons.blockUnbreableStonebrick, 0);
        this.setBlock(world, i + 28, j + 38, k + 102, Dungeons.blockUnbreableStonebrick, 0);
        this.setBlock(world, i + 28, j + 38, k + 103, Dungeons.blockUnbreableStonebrick, 0);
        this.setBlock(world, i + 28, j + 38, k + 104, Dungeons.blockUnbreableStonebrick, 0);
        this.setBlock(world, i + 28, j + 38, k + 105, Dungeons.blockUnbreableStonebrick, 0);
        this.setBlock(world, i + 28, j + 38, k + 106, Dungeons.blockUnbreableStonebrick, 0);
        this.setBlock(world, i + 28, j + 38, k + 107, Dungeons.blockUnbreableStonebrick, 0);
        this.setBlock(world, i + 28, j + 38, k + 108, Dungeons.blockUnbreableStonebrick, 0);
        this.setBlock(world, i + 28, j + 38, k + 110, Dungeons.blockUnbreableStonebrick, 0);
        this.setBlock(world, i + 28, j + 38, k + 111, Dungeons.blockUnbreableStonebrick, 0);
        this.setBlock(world, i + 28, j + 38, k + 112, Dungeons.blockUnbreableStonebrick, 0);
        this.setBlock(world, i + 28, j + 38, k + 113, Dungeons.blockUnbreableStonebrick, 0);
        this.setBlock(world, i + 28, j + 39, k + 94, Dungeons.blockUnbreableStonebrick, 0);
        this.setBlock(world, i + 28, j + 39, k + 95, Dungeons.blockUnbreableStonebrick, 0);
        this.setBlock(world, i + 28, j + 39, k + 96, Dungeons.blockUnbreableStonebrick, 0);
        this.setBlock(world, i + 28, j + 39, k + 97, Dungeons.blockUnbreableStonebrick, 0);
        this.setBlock(world, i + 28, j + 39, k + 98, Dungeons.blockUnbreableStonebrick, 0);
        this.setBlock(world, i + 28, j + 39, k + 100, Dungeons.blockUnbreableStonebrick, 0);
        this.setBlock(world, i + 28, j + 39, k + 101, Dungeons.blockUnbreableStonebrick, 0);
        this.setBlock(world, i + 28, j + 39, k + 102, Dungeons.blockUnbreableStonebrick, 0);
        this.setBlock(world, i + 28, j + 39, k + 103, Dungeons.blockUnbreableStonebrick, 0);
        this.setBlock(world, i + 28, j + 39, k + 104, Dungeons.blockUnbreableStonebrick, 0);
        this.setBlock(world, i + 28, j + 39, k + 105, Dungeons.blockUnbreableStonebrick, 0);
        this.setBlock(world, i + 28, j + 39, k + 106, Dungeons.blockUnbreableStonebrick, 0);
        this.setBlock(world, i + 28, j + 39, k + 107, Dungeons.blockUnbreableStonebrick, 0);
        this.setBlock(world, i + 28, j + 39, k + 108, Dungeons.blockUnbreableStonebrick, 0);
        this.setBlock(world, i + 28, j + 39, k + 110, Dungeons.blockUnbreableStonebrick, 0);
        this.setBlock(world, i + 28, j + 39, k + 111, Dungeons.blockUnbreableStonebrick, 0);
        this.setBlock(world, i + 28, j + 39, k + 112, Dungeons.blockUnbreableStonebrick, 0);
        this.setBlock(world, i + 28, j + 39, k + 113, Dungeons.blockUnbreableStonebrick, 0);
        this.setBlock(world, i + 28, j + 39, k + 114, Dungeons.blockUnbreableStonebrick, 0);
        this.setBlock(world, i + 28, j + 40, k + 94, Dungeons.blockUnbreableStonebrick, 0);
        this.setBlock(world, i + 28, j + 40, k + 98, Dungeons.blockUnbreableStonebrick, 0);
        this.setBlock(world, i + 28, j + 40, k + 100, Dungeons.blockUnbreableStonebrick, 0);
        this.setBlock(world, i + 28, j + 40, k + 108, Dungeons.blockUnbreableStonebrick, 0);
        this.setBlock(world, i + 28, j + 40, k + 110, Dungeons.blockUnbreableStonebrick, 0);
        this.setBlock(world, i + 28, j + 40, k + 114, Dungeons.blockUnbreableStonebrick, 0);
        this.setBlock(world, i + 28, j + 41, k + 94, Dungeons.blockUnbreableStonebrick, 0);
        this.setBlock(world, i + 28, j + 41, k + 98, Dungeons.blockUnbreableStonebrick, 0);
        this.setBlock(world, i + 28, j + 41, k + 100, Dungeons.blockUnbreableStonebrick, 0);
        this.setBlock(world, i + 28, j + 41, k + 108, Dungeons.blockUnbreableStonebrick, 0);
        this.setBlock(world, i + 28, j + 41, k + 110, Dungeons.blockUnbreableStonebrick, 0);
        this.setBlock(world, i + 28, j + 41, k + 114, Dungeons.blockUnbreableStonebrick, 0);
        this.setBlock(world, i + 28, j + 42, k + 94, Dungeons.blockUnbreableStonebrick, 0);
        this.setBlock(world, i + 28, j + 42, k + 98, Dungeons.blockUnbreableStonebrick, 0);
        this.setBlock(world, i + 28, j + 42, k + 110, Dungeons.blockUnbreableStonebrick, 0);
        this.setBlock(world, i + 28, j + 42, k + 114, Dungeons.blockUnbreableStonebrick, 0);
        this.setBlock(world, i + 28, j + 43, k + 93, Blocks.cobblestone_wall, 0);
        this.setBlock(world, i + 28, j + 43, k + 94, Dungeons.blockUnbreableStonebrick, 0);
        this.setBlock(world, i + 28, j + 43, k + 98, Dungeons.blockUnbreableStonebrick, 0);
        this.setBlock(world, i + 28, j + 43, k + 99, Blocks.cobblestone_wall, 0);
        this.setBlock(world, i + 28, j + 43, k + 109, Blocks.cobblestone_wall, 0);
        this.setBlock(world, i + 28, j + 43, k + 110, Dungeons.blockUnbreableStonebrick, 0);
        this.setBlock(world, i + 28, j + 43, k + 114, Dungeons.blockUnbreableStonebrick, 0);
        this.setBlock(world, i + 28, j + 43, k + 115, Blocks.cobblestone_wall, 0);
        this.setBlock(world, i + 28, j + 44, k + 93, Blocks.stained_hardened_clay, 9);
        this.setBlock(world, i + 28, j + 44, k + 94, Dungeons.blockUnbreableStonebrick, 0);
        this.setBlock(world, i + 28, j + 44, k + 98, Dungeons.blockUnbreableStonebrick, 0);
        this.setBlock(world, i + 28, j + 44, k + 99, Blocks.stained_hardened_clay, 9);
        this.setBlock(world, i + 28, j + 44, k + 109, Blocks.stained_hardened_clay, 9);
        this.setBlock(world, i + 28, j + 44, k + 110, Dungeons.blockUnbreableStonebrick, 0);
        this.setBlock(world, i + 28, j + 44, k + 114, Dungeons.blockUnbreableStonebrick, 0);
        this.setBlock(world, i + 28, j + 44, k + 115, Blocks.stained_hardened_clay, 9);
        this.setBlock(world, i + 28, j + 45, k + 94, Dungeons.blockUnbreableStonebrick, 0);
        this.setBlock(world, i + 28, j + 45, k + 98, Dungeons.blockUnbreableStonebrick, 0);
        this.setBlock(world, i + 28, j + 45, k + 110, Dungeons.blockUnbreableStonebrick, 0);
        this.setBlock(world, i + 28, j + 45, k + 114, Dungeons.blockUnbreableStonebrick, 0);
        this.setBlock(world, i + 28, j + 46, k + 94, Dungeons.blockUnbreableStonebrick, 0);
        this.setBlock(world, i + 28, j + 46, k + 98, Dungeons.blockUnbreableStonebrick, 0);
        this.setBlock(world, i + 28, j + 46, k + 110, Dungeons.blockUnbreableStonebrick, 0);
        this.setBlock(world, i + 28, j + 46, k + 114, Dungeons.blockUnbreableStonebrick, 0);
        this.setBlock(world, i + 28, j + 47, k + 94, Dungeons.blockUnbreableStonebrick, 0);
        this.setBlock(world, i + 28, j + 47, k + 98, Dungeons.blockUnbreableStonebrick, 0);
        this.setBlock(world, i + 28, j + 47, k + 110, Dungeons.blockUnbreableStonebrick, 0);
        this.setBlock(world, i + 28, j + 47, k + 114, Dungeons.blockUnbreableStonebrick, 0);
        this.setBlock(world, i + 28, j + 48, k + 93, Blocks.cobblestone_wall, 0);
        this.setBlock(world, i + 28, j + 48, k + 94, Dungeons.blockUnbreableStonebrick, 0);
        this.setBlock(world, i + 28, j + 48, k + 98, Dungeons.blockUnbreableStonebrick, 0);
        this.setBlock(world, i + 28, j + 48, k + 99, Blocks.cobblestone_wall, 0);
        this.setBlock(world, i + 28, j + 48, k + 109, Blocks.cobblestone_wall, 0);
        this.setBlock(world, i + 28, j + 48, k + 110, Dungeons.blockUnbreableStonebrick, 0);
        this.setBlock(world, i + 28, j + 48, k + 114, Dungeons.blockUnbreableStonebrick, 0);
        this.setBlock(world, i + 28, j + 48, k + 115, Blocks.cobblestone_wall, 0);
        this.setBlock(world, i + 28, j + 49, k + 93, Blocks.stained_hardened_clay, 9);
        this.setBlock(world, i + 28, j + 49, k + 94, Dungeons.blockUnbreableStonebrick, 0);
        this.setBlock(world, i + 28, j + 49, k + 95, Dungeons.blockUnbreableStonebrick, 0);
        this.setBlock(world, i + 28, j + 49, k + 96, Dungeons.blockUnbreableStonebrick, 0);
        this.setBlock(world, i + 28, j + 49, k + 97, Dungeons.blockUnbreableStonebrick, 0);
        this.setBlock(world, i + 28, j + 49, k + 98, Dungeons.blockUnbreableStonebrick, 0);
        this.setBlock(world, i + 28, j + 49, k + 99, Blocks.stained_hardened_clay, 9);
        this.setBlock(world, i + 28, j + 49, k + 100, Dungeons.blockUnbreableStonebrick, 0);
        this.setBlock(world, i + 28, j + 49, k + 101, Blocks.cobblestone_wall, 0);
        this.setBlock(world, i + 28, j + 49, k + 102, Dungeons.blockUnbreableStonebrick, 0);
        this.setBlock(world, i + 28, j + 49, k + 103, Blocks.cobblestone_wall, 0);
        this.setBlock(world, i + 28, j + 49, k + 104, Dungeons.blockUnbreableStonebrick, 0);
        this.setBlock(world, i + 28, j + 49, k + 105, Blocks.cobblestone_wall, 0);
        this.setBlock(world, i + 28, j + 49, k + 106, Dungeons.blockUnbreableStonebrick, 0);
        this.setBlock(world, i + 28, j + 49, k + 107, Blocks.cobblestone_wall, 0);
        this.setBlock(world, i + 28, j + 49, k + 108, Dungeons.blockUnbreableStonebrick, 0);
        this.setBlock(world, i + 28, j + 49, k + 109, Blocks.stained_hardened_clay, 9);
        this.setBlock(world, i + 28, j + 49, k + 110, Dungeons.blockUnbreableStonebrick, 0);
        this.setBlock(world, i + 28, j + 49, k + 111, Dungeons.blockUnbreableStonebrick, 0);
        this.setBlock(world, i + 28, j + 49, k + 112, Dungeons.blockUnbreableStonebrick, 0);
        this.setBlock(world, i + 28, j + 49, k + 113, Dungeons.blockUnbreableStonebrick, 0);
        this.setBlock(world, i + 28, j + 49, k + 114, Dungeons.blockUnbreableStonebrick, 0);
        this.setBlock(world, i + 28, j + 49, k + 115, Blocks.stained_hardened_clay, 9);
        this.setBlock(world, i + 28, j + 50, k + 94, Dungeons.blockUnbreableStonebrick, 0);
        this.setBlock(world, i + 28, j + 50, k + 98, Dungeons.blockUnbreableStonebrick, 0);
        this.setBlock(world, i + 28, j + 50, k + 99, Blocks.stained_hardened_clay, 9);
        this.setBlock(world, i + 28, j + 50, k + 100, Dungeons.blockUnbreableStonebrick, 0);
        this.setBlock(world, i + 28, j + 50, k + 102, Dungeons.blockUnbreableStonebrick, 0);
        this.setBlock(world, i + 28, j + 50, k + 104, Dungeons.blockUnbreableStonebrick, 0);
        this.setBlock(world, i + 28, j + 50, k + 106, Dungeons.blockUnbreableStonebrick, 0);
        this.setBlock(world, i + 28, j + 50, k + 108, Dungeons.blockUnbreableStonebrick, 0);
        this.setBlock(world, i + 28, j + 50, k + 110, Dungeons.blockUnbreableStonebrick, 0);
        this.setBlock(world, i + 28, j + 50, k + 114, Dungeons.blockUnbreableStonebrick, 0);
        this.setBlock(world, i + 28, j + 50, k + 115, Blocks.stained_hardened_clay, 9);
        this.setBlock(world, i + 28, j + 51, k + 94, Dungeons.blockUnbreableStonebrick, 0);
        this.setBlock(world, i + 28, j + 51, k + 98, Dungeons.blockUnbreableStonebrick, 0);
        this.setBlock(world, i + 28, j + 51, k + 110, Dungeons.blockUnbreableStonebrick, 0);
        this.setBlock(world, i + 28, j + 51, k + 114, Dungeons.blockUnbreableStonebrick, 0);
        this.setBlock(world, i + 28, j + 52, k + 94, Dungeons.blockUnbreableStonebrick, 0);
        this.setBlock(world, i + 28, j + 52, k + 98, Dungeons.blockUnbreableStonebrick, 0);
        this.setBlock(world, i + 28, j + 52, k + 110, Dungeons.blockUnbreableStonebrick, 0);
        this.setBlock(world, i + 28, j + 52, k + 114, Dungeons.blockUnbreableStonebrick, 0);
        this.setBlock(world, i + 28, j + 53, k + 93, Blocks.cobblestone_wall, 0);
        this.setBlock(world, i + 28, j + 53, k + 94, Blocks.bedrock, 0);
        this.setBlock(world, i + 28, j + 53, k + 98, Blocks.bedrock, 0);
        this.setBlock(world, i + 28, j + 53, k + 99, Blocks.cobblestone_wall, 0);
        this.setBlock(world, i + 28, j + 53, k + 109, Blocks.cobblestone_wall, 0);
        this.setBlock(world, i + 28, j + 53, k + 110, Blocks.bedrock, 0);
        this.setBlock(world, i + 28, j + 53, k + 114, Blocks.bedrock, 0);
        this.setBlock(world, i + 28, j + 53, k + 115, Blocks.cobblestone_wall, 0);
        this.setBlock(world, i + 28, j + 54, k + 95, Blocks.bedrock, 0);
        this.setBlock(world, i + 28, j + 54, k + 96, Dungeons.blockUnbreableStonebrick, 0);
        this.setBlock(world, i + 28, j + 54, k + 97, Blocks.bedrock, 0);
        this.setBlock(world, i + 28, j + 54, k + 111, Blocks.bedrock, 0);
        this.setBlock(world, i + 28, j + 54, k + 112, Dungeons.blockUnbreableStonebrick, 0);
        this.setBlock(world, i + 28, j + 54, k + 113, Blocks.bedrock, 0);
        this.setBlock(world, i + 28, j + 55, k + 95, Blocks.bedrock, 0);
        this.setBlock(world, i + 28, j + 55, k + 97, Blocks.bedrock, 0);
        this.setBlock(world, i + 28, j + 55, k + 111, Blocks.bedrock, 0);
        this.setBlock(world, i + 28, j + 55, k + 113, Blocks.bedrock, 0);
        this.setBlock(world, i + 29, j + 35, k + 97, Dungeons.blockUnbreableStonebrick, 0);
        this.setBlock(world, i + 29, j + 35, k + 98, Dungeons.blockUnbreableStonebrick, 0);
        this.setBlock(world, i + 29, j + 35, k + 99, Dungeons.blockUnbreableStonebrick, 0);
        this.setBlock(world, i + 29, j + 35, k + 100, Dungeons.blockUnbreableStonebrick, 0);
        this.setBlock(world, i + 29, j + 35, k + 101, Dungeons.blockUnbreableStonebrick, 0);
        this.setBlock(world, i + 29, j + 35, k + 107, Dungeons.blockUnbreableStonebrick, 0);
        this.setBlock(world, i + 29, j + 35, k + 108, Dungeons.blockUnbreableStonebrick, 0);
        this.setBlock(world, i + 29, j + 35, k + 109, Dungeons.blockUnbreableStonebrick, 0);
        this.setBlock(world, i + 29, j + 35, k + 110, Dungeons.blockUnbreableStonebrick, 0);
        this.setBlock(world, i + 29, j + 35, k + 111, Dungeons.blockUnbreableStonebrick, 0);
        this.setBlock(world, i + 29, j + 36, k + 96, Dungeons.blockUnbreableStonebrick, 0);
        this.setBlock(world, i + 29, j + 36, k + 97, Dungeons.blockUnbreableStonebrick, 0);
        this.setBlock(world, i + 29, j + 36, k + 98, Dungeons.blockUnbreableStonebrick, 0);
        this.setBlock(world, i + 29, j + 36, k + 99, Dungeons.blockUnbreableStonebrick, 0);
        this.setBlock(world, i + 29, j + 36, k + 100, Dungeons.blockUnbreableStonebrick, 0);
        this.setBlock(world, i + 29, j + 36, k + 101, Dungeons.blockUnbreableStonebrick, 0);
        this.setBlock(world, i + 29, j + 36, k + 102, Dungeons.blockUnbreableStonebrick, 0);
        this.setBlock(world, i + 29, j + 36, k + 106, Dungeons.blockUnbreableStonebrick, 0);
        this.setBlock(world, i + 29, j + 36, k + 107, Dungeons.blockUnbreableStonebrick, 0);
        this.setBlock(world, i + 29, j + 36, k + 108, Dungeons.blockUnbreableStonebrick, 0);
        this.setBlock(world, i + 29, j + 36, k + 109, Dungeons.blockUnbreableStonebrick, 0);
        this.setBlock(world, i + 29, j + 36, k + 110, Dungeons.blockUnbreableStonebrick, 0);
        this.setBlock(world, i + 29, j + 36, k + 111, Dungeons.blockUnbreableStonebrick, 0);
        this.setBlock(world, i + 29, j + 36, k + 112, Dungeons.blockUnbreableStonebrick, 0);
        this.setBlock(world, i + 29, j + 37, k + 95, Dungeons.blockUnbreableStonebrick, 0);
        this.setBlock(world, i + 29, j + 37, k + 96, Dungeons.blockUnbreableStonebrick, 0);
        this.setBlock(world, i + 29, j + 37, k + 97, Dungeons.blockUnbreableStonebrick, 0);
        this.setBlock(world, i + 29, j + 37, k + 98, Dungeons.blockUnbreableStonebrick, 0);
        this.setBlock(world, i + 29, j + 37, k + 99, Dungeons.blockUnbreableStonebrick, 0);
        this.setBlock(world, i + 29, j + 37, k + 100, Dungeons.blockUnbreableStonebrick, 0);
        this.setBlock(world, i + 29, j + 37, k + 101, Dungeons.blockUnbreableStonebrick, 0);
        this.setBlock(world, i + 29, j + 37, k + 102, Dungeons.blockUnbreableStonebrick, 0);
        this.setBlock(world, i + 29, j + 37, k + 103, Dungeons.blockUnbreableStonebrick, 0);
        this.setBlock(world, i + 29, j + 37, k + 105, Dungeons.blockUnbreableStonebrick, 0);
        this.setBlock(world, i + 29, j + 37, k + 106, Dungeons.blockUnbreableStonebrick, 0);
        this.setBlock(world, i + 29, j + 37, k + 107, Dungeons.blockUnbreableStonebrick, 0);
        this.setBlock(world, i + 29, j + 37, k + 108, Dungeons.blockUnbreableStonebrick, 0);
        this.setBlock(world, i + 29, j + 37, k + 109, Dungeons.blockUnbreableStonebrick, 0);
        this.setBlock(world, i + 29, j + 37, k + 110, Dungeons.blockUnbreableStonebrick, 0);
        this.setBlock(world, i + 29, j + 37, k + 111, Dungeons.blockUnbreableStonebrick, 0);
        this.setBlock(world, i + 29, j + 37, k + 112, Dungeons.blockUnbreableStonebrick, 0);
        this.setBlock(world, i + 29, j + 37, k + 113, Dungeons.blockUnbreableStonebrick, 0);
        this.setBlock(world, i + 29, j + 38, k + 94, Dungeons.blockUnbreableStonebrick, 0);
        this.setBlock(world, i + 29, j + 38, k + 95, Dungeons.blockUnbreableStonebrick, 0);
        this.setBlock(world, i + 29, j + 38, k + 96, Dungeons.blockUnbreableStonebrick, 0);
        this.setBlock(world, i + 29, j + 38, k + 97, Dungeons.blockUnbreableStonebrick, 0);
        this.setBlock(world, i + 29, j + 38, k + 98, Dungeons.blockUnbreableStonebrick, 0);
        this.setBlock(world, i + 29, j + 38, k + 99, Dungeons.blockUnbreableStonebrick, 0);
        this.setBlock(world, i + 29, j + 38, k + 100, Blocks.cobblestone_wall, 0);
        this.setBlock(world, i + 29, j + 38, k + 101, Dungeons.blockUnbreableStonebrick, 0);
        this.setBlock(world, i + 29, j + 38, k + 102, Dungeons.blockUnbreableStonebrick, 0);
        this.setBlock(world, i + 29, j + 38, k + 103, Dungeons.blockUnbreableStonebrick, 0);
        this.setBlock(world, i + 29, j + 38, k + 104, Dungeons.blockUnbreableStonebrick, 0);
        this.setBlock(world, i + 29, j + 38, k + 105, Dungeons.blockUnbreableStonebrick, 0);
        this.setBlock(world, i + 29, j + 38, k + 106, Dungeons.blockUnbreableStonebrick, 0);
        this.setBlock(world, i + 29, j + 38, k + 107, Dungeons.blockUnbreableStonebrick, 0);
        this.setBlock(world, i + 29, j + 38, k + 108, Blocks.cobblestone_wall, 0);
        this.setBlock(world, i + 29, j + 38, k + 109, Dungeons.blockUnbreableStonebrick, 0);
        this.setBlock(world, i + 29, j + 38, k + 110, Dungeons.blockUnbreableStonebrick, 0);
        this.setBlock(world, i + 29, j + 38, k + 111, Dungeons.blockUnbreableStonebrick, 0);
        this.setBlock(world, i + 29, j + 38, k + 112, Dungeons.blockUnbreableStonebrick, 0);
        this.setBlock(world, i + 29, j + 38, k + 113, Dungeons.blockUnbreableStonebrick, 0);
        this.setBlock(world, i + 29, j + 38, k + 114, Dungeons.blockUnbreableStonebrick, 0);
        this.setBlock(world, i + 29, j + 39, k + 93, Dungeons.blockUnbreableStonebrick, 0);
        this.setBlock(world, i + 29, j + 39, k + 94, Dungeons.blockUnbreableStonebrick, 0);
        this.setBlock(world, i + 29, j + 39, k + 95, Dungeons.blockUnbreableStonebrick, 0);
        this.setBlock(world, i + 29, j + 39, k + 96, Dungeons.blockUnbreableStonebrick, 0);
        this.setBlock(world, i + 29, j + 39, k + 97, Dungeons.blockUnbreableStonebrick, 0);
        this.setBlock(world, i + 29, j + 39, k + 98, Dungeons.blockUnbreableStonebrick, 0);
        this.setBlock(world, i + 29, j + 39, k + 99, Dungeons.blockUnbreableStonebrick, 0);
        this.setBlock(world, i + 29, j + 39, k + 100, Blocks.stained_hardened_clay, 9);
        this.setBlock(world, i + 29, j + 39, k + 101, Dungeons.blockUnbreableStonebrick, 0);
        this.setBlock(world, i + 29, j + 39, k + 102, Dungeons.blockUnbreableStonebrick, 0);
        this.setBlock(world, i + 29, j + 39, k + 103, Dungeons.blockUnbreableStonebrick, 0);
        this.setBlock(world, i + 29, j + 39, k + 104, Dungeons.blockUnbreableStonebrick, 0);
        this.setBlock(world, i + 29, j + 39, k + 105, Dungeons.blockUnbreableStonebrick, 0);
        this.setBlock(world, i + 29, j + 39, k + 106, Dungeons.blockUnbreableStonebrick, 0);
        this.setBlock(world, i + 29, j + 39, k + 107, Dungeons.blockUnbreableStonebrick, 0);
        this.setBlock(world, i + 29, j + 39, k + 108, Blocks.stained_hardened_clay, 9);
        this.setBlock(world, i + 29, j + 39, k + 109, Dungeons.blockUnbreableStonebrick, 0);
        this.setBlock(world, i + 29, j + 39, k + 110, Dungeons.blockUnbreableStonebrick, 0);
        this.setBlock(world, i + 29, j + 39, k + 111, Dungeons.blockUnbreableStonebrick, 0);
        this.setBlock(world, i + 29, j + 39, k + 112, Dungeons.blockUnbreableStonebrick, 0);
        this.setBlock(world, i + 29, j + 39, k + 113, Dungeons.blockUnbreableStonebrick, 0);
        this.setBlock(world, i + 29, j + 39, k + 114, Dungeons.blockUnbreableStonebrick, 0);
        this.setBlock(world, i + 29, j + 39, k + 115, Dungeons.blockUnbreableStonebrick, 0);
        this.setBlock(world, i + 29, j + 40, k + 93, Dungeons.blockUnbreableStonebrick, 0);
        this.setBlock(world, i + 29, j + 40, k + 95, Dungeons.blockUnbreableStonebrick, 0);
        this.setBlock(world, i + 29, j + 40, k + 96, Dungeons.blockUnbreableStonebrick, 0);
        this.setBlock(world, i + 29, j + 40, k + 97, Dungeons.blockUnbreableStone_brick_stairs, 3);
        this.setBlock(world, i + 29, j + 40, k + 99, Dungeons.blockUnbreableStonebrick, 0);
        this.setBlock(world, i + 29, j + 40, k + 109, Dungeons.blockUnbreableStonebrick, 0);
        this.setBlock(world, i + 29, j + 40, k + 111, Dungeons.blockUnbreableStonebrick, 0);
        this.setBlock(world, i + 29, j + 40, k + 112, Dungeons.blockUnbreableStonebrick, 0);
        this.setBlock(world, i + 29, j + 40, k + 113, Dungeons.blockUnbreableStone_brick_stairs, 3);
        this.setBlock(world, i + 29, j + 40, k + 115, Dungeons.blockUnbreableStonebrick, 0);
        this.setBlock(world, i + 29, j + 41, k + 93, Dungeons.blockUnbreableStonebrick, 0);
        this.setBlock(world, i + 29, j + 41, k + 95, Dungeons.blockUnbreableStonebrick, 0);
        this.setBlock(world, i + 29, j + 41, k + 96, Dungeons.blockUnbreableStone_brick_stairs, 3);
        this.setBlock(world, i + 29, j + 41, k + 99, Dungeons.blockUnbreableStonebrick, 0);
        this.setBlock(world, i + 29, j + 41, k + 109, Dungeons.blockUnbreableStonebrick, 0);
        this.setBlock(world, i + 29, j + 41, k + 111, Dungeons.blockUnbreableStonebrick, 0);
        this.setBlock(world, i + 29, j + 41, k + 112, Dungeons.blockUnbreableStone_brick_stairs, 3);
        this.setBlock(world, i + 29, j + 41, k + 115, Dungeons.blockUnbreableStonebrick, 0);
        this.setBlock(world, i + 29, j + 42, k + 93, Dungeons.blockUnbreableStonebrick, 0);
        this.setBlock(world, i + 29, j + 42, k + 95, Dungeons.blockUnbreableStone_brick_stairs, 3);
        this.setBlock(world, i + 29, j + 42, k + 99, Dungeons.blockUnbreableStonebrick, 0);
        this.setBlock(world, i + 29, j + 42, k + 109, Dungeons.blockUnbreableStonebrick, 0);
        this.setBlock(world, i + 29, j + 42, k + 111, Dungeons.blockUnbreableStone_brick_stairs, 3);
        this.setBlock(world, i + 29, j + 42, k + 115, Dungeons.blockUnbreableStonebrick, 0);
        this.setBlock(world, i + 29, j + 43, k + 92, Blocks.cobblestone_wall, 0);
        this.setBlock(world, i + 29, j + 43, k + 93, Dungeons.blockUnbreableStonebrick, 0);
        this.setBlock(world, i + 29, j + 43, k + 99, Dungeons.blockUnbreableStonebrick, 0);
        this.setBlock(world, i + 29, j + 43, k + 100, Blocks.cobblestone_wall, 0);
        this.setBlock(world, i + 29, j + 43, k + 108, Blocks.cobblestone_wall, 0);
        this.setBlock(world, i + 29, j + 43, k + 109, Dungeons.blockUnbreableStonebrick, 0);
        this.setBlock(world, i + 29, j + 43, k + 115, Dungeons.blockUnbreableStonebrick, 0);
        this.setBlock(world, i + 29, j + 43, k + 116, Blocks.cobblestone_wall, 0);
        this.setBlock(world, i + 29, j + 44, k + 92, Blocks.stained_hardened_clay, 9);
        this.setBlock(world, i + 29, j + 44, k + 93, Dungeons.blockUnbreableStonebrick, 0);
        this.setBlock(world, i + 29, j + 44, k + 99, Dungeons.blockUnbreableStonebrick, 0);
        this.setBlock(world, i + 29, j + 44, k + 100, Blocks.stained_hardened_clay, 9);
        this.setBlock(world, i + 29, j + 44, k + 108, Blocks.stained_hardened_clay, 9);
        this.setBlock(world, i + 29, j + 44, k + 109, Dungeons.blockUnbreableStonebrick, 0);
        this.setBlock(world, i + 29, j + 44, k + 115, Dungeons.blockUnbreableStonebrick, 0);
        this.setBlock(world, i + 29, j + 44, k + 116, Blocks.stained_hardened_clay, 9);
        this.setBlock(world, i + 29, j + 45, k + 93, Dungeons.blockUnbreableStonebrick, 0);
        this.setBlock(world, i + 29, j + 45, k + 99, Dungeons.blockUnbreableStonebrick, 0);
        this.setBlock(world, i + 29, j + 45, k + 109, Dungeons.blockUnbreableStonebrick, 0);
        this.setBlock(world, i + 29, j + 45, k + 115, Dungeons.blockUnbreableStonebrick, 0);
        this.setBlock(world, i + 29, j + 46, k + 93, Dungeons.blockUnbreableStonebrick, 0);
        this.setBlock(world, i + 29, j + 46, k + 99, Dungeons.blockUnbreableStonebrick, 0);
        this.setBlock(world, i + 29, j + 46, k + 100, Dungeons.blockUnbreableStonebrick, 0);
        this.setBlock(world, i + 29, j + 46, k + 108, Dungeons.blockUnbreableStonebrick, 0);
        this.setBlock(world, i + 29, j + 46, k + 109, Dungeons.blockUnbreableStonebrick, 0);
        this.setBlock(world, i + 29, j + 46, k + 115, Dungeons.blockUnbreableStonebrick, 0);
        this.setBlock(world, i + 29, j + 47, k + 93, Dungeons.blockUnbreableStonebrick, 0);
        this.setBlock(world, i + 29, j + 47, k + 97, Dungeons.blockUnbreableStonebrick, 0);
        this.setBlock(world, i + 29, j + 47, k + 99, Dungeons.blockUnbreableStonebrick, 0);
        this.setBlock(world, i + 29, j + 47, k + 100, Dungeons.blockUnbreableStonebrick, 0);
        this.setBlock(world, i + 29, j + 47, k + 108, Dungeons.blockUnbreableStonebrick, 0);
        this.setBlock(world, i + 29, j + 47, k + 109, Dungeons.blockUnbreableStonebrick, 0);
        this.setBlock(world, i + 29, j + 47, k + 113, Dungeons.blockUnbreableStonebrick, 0);
        this.setBlock(world, i + 29, j + 47, k + 115, Dungeons.blockUnbreableStonebrick, 0);
        this.setBlock(world, i + 29, j + 48, k + 92, Blocks.cobblestone_wall, 0);
        this.setBlock(world, i + 29, j + 48, k + 93, Dungeons.blockUnbreableStonebrick, 0);
        this.setBlock(world, i + 29, j + 48, k + 96, Dungeons.blockUnbreableStonebrick, 0);
        this.setBlock(world, i + 29, j + 48, k + 97, Dungeons.blockUnbreableStone_brick_stairs, 3);
        this.setBlock(world, i + 29, j + 48, k + 99, Dungeons.blockUnbreableStonebrick, 0);
        this.setBlock(world, i + 29, j + 48, k + 101, Dungeons.blockUnbreableStonebrick, 0);
        this.setBlock(world, i + 29, j + 48, k + 102, Dungeons.blockUnbreableStonebrick, 0);
        this.setBlock(world, i + 29, j + 48, k + 106, Dungeons.blockUnbreableStonebrick, 0);
        this.setBlock(world, i + 29, j + 48, k + 107, Dungeons.blockUnbreableStonebrick, 0);
        this.setBlock(world, i + 29, j + 48, k + 109, Dungeons.blockUnbreableStonebrick, 0);
        this.setBlock(world, i + 29, j + 48, k + 112, Dungeons.blockUnbreableStonebrick, 0);
        this.setBlock(world, i + 29, j + 48, k + 113, Dungeons.blockUnbreableStone_brick_stairs, 3);
        this.setBlock(world, i + 29, j + 48, k + 115, Dungeons.blockUnbreableStonebrick, 0);
        this.setBlock(world, i + 29, j + 48, k + 116, Blocks.cobblestone_wall, 0);
        this.setBlock(world, i + 29, j + 49, k + 92, Blocks.stained_hardened_clay, 9);
        this.setBlock(world, i + 29, j + 49, k + 93, Dungeons.blockUnbreableStonebrick, 0);
        this.setBlock(world, i + 29, j + 49, k + 94, Dungeons.blockUnbreableStonebrick, 0);
        this.setBlock(world, i + 29, j + 49, k + 95, Dungeons.blockUnbreableStonebrick, 0);
        this.setBlock(world, i + 29, j + 49, k + 96, Dungeons.blockUnbreableStone_brick_stairs, 3);
        this.setBlock(world, i + 29, j + 49, k + 98, Dungeons.blockUnbreableStonebrick, 0);
        this.setBlock(world, i + 29, j + 49, k + 99, Dungeons.blockUnbreableStonebrick, 0);
        this.setBlock(world, i + 29, j + 49, k + 100, Dungeons.blockUnbreableStonebrick, 0);
        this.setBlock(world, i + 29, j + 49, k + 101, Dungeons.blockUnbreableStonebrick, 0);
        this.setBlock(world, i + 29, j + 49, k + 102, Dungeons.blockUnbreableStonebrick, 0);
        this.setBlock(world, i + 29, j + 49, k + 103, Dungeons.blockUnbreableStonebrick, 0);
        this.setBlock(world, i + 29, j + 49, k + 104, Dungeons.blockUnbreableStonebrick, 0);
        this.setBlock(world, i + 29, j + 49, k + 105, Dungeons.blockUnbreableStonebrick, 0);
        this.setBlock(world, i + 29, j + 49, k + 106, Dungeons.blockUnbreableStonebrick, 0);
        this.setBlock(world, i + 29, j + 49, k + 107, Dungeons.blockUnbreableStonebrick, 0);
        this.setBlock(world, i + 29, j + 49, k + 108, Dungeons.blockUnbreableStonebrick, 0);
        this.setBlock(world, i + 29, j + 49, k + 109, Dungeons.blockUnbreableStonebrick, 0);
        this.setBlock(world, i + 29, j + 49, k + 110, Dungeons.blockUnbreableStonebrick, 0);
        this.setBlock(world, i + 29, j + 49, k + 111, Dungeons.blockUnbreableStonebrick, 0);
        this.setBlock(world, i + 29, j + 49, k + 112, Dungeons.blockUnbreableStone_brick_stairs, 3);
        this.setBlock(world, i + 29, j + 49, k + 114, Dungeons.blockUnbreableStonebrick, 0);
        this.setBlock(world, i + 29, j + 49, k + 115, Dungeons.blockUnbreableStonebrick, 0);
        this.setBlock(world, i + 29, j + 49, k + 116, Blocks.stained_hardened_clay, 9);
        this.setBlock(world, i + 29, j + 50, k + 93, Dungeons.blockUnbreableStonebrick, 0);
        this.setBlock(world, i + 29, j + 50, k + 99, Dungeons.blockUnbreableStonebrick, 0);
        WorldGenWarlordDungeon.chest(world, rand, i + 29, j + 50, k + 104, "MontaneDungeon", 6);
        this.setBlock(world, i + 29, j + 50, k + 109, Dungeons.blockUnbreableStonebrick, 0);
        this.setBlock(world, i + 29, j + 50, k + 115, Dungeons.blockUnbreableStonebrick, 0);
        this.setBlock(world, i + 29, j + 51, k + 93, Dungeons.blockUnbreableStonebrick, 0);
        this.setBlock(world, i + 29, j + 51, k + 99, Dungeons.blockUnbreableStonebrick, 0);
        this.setBlock(world, i + 29, j + 51, k + 109, Dungeons.blockUnbreableStonebrick, 0);
        this.setBlock(world, i + 29, j + 51, k + 115, Dungeons.blockUnbreableStonebrick, 0);
        this.setBlock(world, i + 29, j + 52, k + 93, Dungeons.blockUnbreableStonebrick, 0);
        this.setBlock(world, i + 29, j + 52, k + 99, Dungeons.blockUnbreableStonebrick, 0);
        this.setBlock(world, i + 29, j + 52, k + 109, Dungeons.blockUnbreableStonebrick, 0);
        this.setBlock(world, i + 29, j + 52, k + 115, Dungeons.blockUnbreableStonebrick, 0);
        this.setBlock(world, i + 29, j + 53, k + 92, Blocks.cobblestone_wall, 0);
        this.setBlock(world, i + 29, j + 53, k + 93, Dungeons.blockUnbreableStonebrick, 0);
        this.setBlock(world, i + 29, j + 53, k + 99, Dungeons.blockUnbreableStonebrick, 0);
        this.setBlock(world, i + 29, j + 53, k + 100, Blocks.cobblestone_wall, 0);
        this.setBlock(world, i + 29, j + 53, k + 108, Blocks.cobblestone_wall, 0);
        this.setBlock(world, i + 29, j + 53, k + 109, Dungeons.blockUnbreableStonebrick, 0);
        this.setBlock(world, i + 29, j + 53, k + 115, Dungeons.blockUnbreableStonebrick, 0);
        this.setBlock(world, i + 29, j + 53, k + 116, Blocks.cobblestone_wall, 0);
        this.setBlock(world, i + 29, j + 54, k + 94, Blocks.bedrock, 0);
        this.setBlock(world, i + 29, j + 54, k + 95, Dungeons.blockUnbreableStonebrick, 0);
        this.setBlock(world, i + 29, j + 54, k + 97, Dungeons.blockUnbreableStonebrick, 0);
        this.setBlock(world, i + 29, j + 54, k + 98, Blocks.bedrock, 0);
        this.setBlock(world, i + 29, j + 54, k + 110, Blocks.bedrock, 0);
        this.setBlock(world, i + 29, j + 54, k + 111, Dungeons.blockUnbreableStonebrick, 0);
        this.setBlock(world, i + 29, j + 54, k + 113, Dungeons.blockUnbreableStonebrick, 0);
        this.setBlock(world, i + 29, j + 54, k + 114, Blocks.bedrock, 0);
        this.setBlock(world, i + 29, j + 55, k + 94, Blocks.bedrock, 0);
        this.setBlock(world, i + 29, j + 55, k + 95, Blocks.bedrock, 0);
        this.setBlock(world, i + 29, j + 55, k + 96, Dungeons.blockUnbreableStonebrick, 0);
        this.setBlock(world, i + 29, j + 55, k + 97, Blocks.bedrock, 0);
        this.setBlock(world, i + 29, j + 55, k + 98, Blocks.bedrock, 0);
        this.setBlock(world, i + 29, j + 55, k + 110, Blocks.bedrock, 0);
        this.setBlock(world, i + 29, j + 55, k + 111, Blocks.bedrock, 0);
        this.setBlock(world, i + 29, j + 55, k + 112, Dungeons.blockUnbreableStonebrick, 0);
        this.setBlock(world, i + 29, j + 55, k + 113, Blocks.bedrock, 0);
        this.setBlock(world, i + 29, j + 55, k + 114, Blocks.bedrock, 0);
        this.setBlock(world, i + 29, j + 56, k + 95, Blocks.bedrock, 0);
        this.setBlock(world, i + 29, j + 56, k + 96, Dungeons.blockUnbreableStonebrick, 0);
        this.setBlock(world, i + 29, j + 56, k + 97, Blocks.bedrock, 0);
        this.setBlock(world, i + 29, j + 56, k + 111, Blocks.bedrock, 0);
        this.setBlock(world, i + 29, j + 56, k + 112, Dungeons.blockUnbreableStonebrick, 0);
        this.setBlock(world, i + 29, j + 56, k + 113, Blocks.bedrock, 0);
        this.setBlock(world, i + 29, j + 57, k + 96, Dungeons.blockUnbreableStonebrick, 0);
        this.setBlock(world, i + 29, j + 57, k + 112, Dungeons.blockUnbreableStonebrick, 0);
        this.setBlock(world, i + 29, j + 58, k + 96, Dungeons.blockUnbreableStonebrick, 0);
        this.setBlock(world, i + 29, j + 58, k + 112, Dungeons.blockUnbreableStonebrick, 0);
        this.setBlock(world, i + 30, j + 34, k + 97, Dungeons.blockUnbreableStonebrick, 0);
        this.setBlock(world, i + 30, j + 34, k + 98, Dungeons.blockUnbreableStonebrick, 0);
        this.setBlock(world, i + 30, j + 34, k + 99, Dungeons.blockUnbreableStonebrick, 0);
        this.setBlock(world, i + 30, j + 34, k + 100, Dungeons.blockUnbreableStonebrick, 0);
        this.setBlock(world, i + 30, j + 34, k + 101, Dungeons.blockUnbreableStonebrick, 0);
        this.setBlock(world, i + 30, j + 34, k + 107, Dungeons.blockUnbreableStonebrick, 0);
        this.setBlock(world, i + 30, j + 34, k + 108, Dungeons.blockUnbreableStonebrick, 0);
        this.setBlock(world, i + 30, j + 34, k + 109, Dungeons.blockUnbreableStonebrick, 0);
        this.setBlock(world, i + 30, j + 34, k + 110, Dungeons.blockUnbreableStonebrick, 0);
        this.setBlock(world, i + 30, j + 34, k + 111, Dungeons.blockUnbreableStonebrick, 0);
        this.setBlock(world, i + 30, j + 35, k + 96, Dungeons.blockUnbreableStonebrick, 0);
        this.setBlock(world, i + 30, j + 35, k + 97, Dungeons.blockUnbreableStonebrick, 0);
