

package com.gibby.dungeon.gen;

import net.minecraft.world.gen.feature.*;
import cpw.mods.fml.common.*;
import java.util.*;
import net.minecraft.world.chunk.*;
import net.minecraft.block.*;
import net.minecraft.world.*;
import net.minecraft.init.*;
import com.gibby.dungeon.*;

public class WorldGenMontaneDungeon_1 extends WorldGenerator implements IWorldGenerator
{
    public void generate(final Random random, final int chunkX, final int chunkZ, final World world, final IChunkProvider chunkGenerator, final IChunkProvider chunkProvider) {
    }
    
    public void setBlock(final World world, final int x, final int y, final int z, final Block block, final int metadata) {
        final Block b1 = world.getBlock(x, y, z);
        if (b1.isAir((IBlockAccess)world, x, y, z) || b1.isLeaves((IBlockAccess)world, x, y, z)) {
            world.setBlock(x, y, z, block, metadata, 2);
        }
    }
    
    public boolean generate(final World world, final Random rand, final int i, final int j, final int k) {
        this.setBlock(world, i + 4, j + 34, k + 22, Blocks.stone, 0);
        this.setBlock(world, i + 4, j + 34, k + 23, Blocks.stone, 0);
        this.setBlock(world, i + 4, j + 34, k + 24, Blocks.stone, 0);
        this.setBlock(world, i + 4, j + 35, k + 21, Blocks.mycelium, 0);
        this.setBlock(world, i + 4, j + 35, k + 22, Blocks.dirt, 0);
        this.setBlock(world, i + 4, j + 35, k + 23, Blocks.dirt, 0);
        this.setBlock(world, i + 4, j + 35, k + 24, Blocks.dirt, 0);
        this.setBlock(world, i + 4, j + 35, k + 25, Blocks.dirt, 0);
        this.setBlock(world, i + 4, j + 35, k + 26, Blocks.dirt, 0);
        this.setBlock(world, i + 4, j + 36, k + 22, Blocks.bedrock, 0);
        this.setBlock(world, i + 4, j + 36, k + 23, Blocks.cobblestone, 0);
        this.setBlock(world, i + 4, j + 36, k + 24, Blocks.stone, 0);
        this.setBlock(world, i + 4, j + 36, k + 25, Blocks.stone, 0);
        this.setBlock(world, i + 4, j + 36, k + 26, Blocks.stone, 0);
        this.setBlock(world, i + 5, j + 33, k + 21, Blocks.stone, 0);
        this.setBlock(world, i + 5, j + 33, k + 22, Blocks.stone, 0);
        this.setBlock(world, i + 5, j + 33, k + 23, Blocks.stone, 0);
        this.setBlock(world, i + 5, j + 33, k + 24, Blocks.stone, 0);
        this.setBlock(world, i + 5, j + 33, k + 25, Blocks.stone, 0);
        this.setBlock(world, i + 5, j + 34, k + 21, Blocks.stone, 0);
        this.setBlock(world, i + 5, j + 34, k + 22, Blocks.stone, 0);
        this.setBlock(world, i + 5, j + 34, k + 23, Blocks.stone, 0);
        this.setBlock(world, i + 5, j + 34, k + 24, Blocks.stone, 0);
        this.setBlock(world, i + 5, j + 34, k + 25, Blocks.stone, 0);
        this.setBlock(world, i + 5, j + 35, k + 20, Blocks.mycelium, 0);
        this.setBlock(world, i + 5, j + 35, k + 21, Blocks.dirt, 0);
        this.setBlock(world, i + 5, j + 35, k + 22, Blocks.dirt, 0);
        this.setBlock(world, i + 5, j + 35, k + 23, Blocks.dirt, 0);
        this.setBlock(world, i + 5, j + 35, k + 24, Blocks.dirt, 0);
        this.setBlock(world, i + 5, j + 35, k + 25, Blocks.dirt, 0);
        this.setBlock(world, i + 5, j + 35, k + 26, Blocks.dirt, 0);
        this.setBlock(world, i + 5, j + 35, k + 27, Blocks.dirt, 0);
        this.setBlock(world, i + 5, j + 36, k + 21, Blocks.stone, 0);
        this.setBlock(world, i + 5, j + 36, k + 22, Blocks.stone, 0);
        this.setBlock(world, i + 5, j + 36, k + 23, Blocks.stone, 0);
        this.setBlock(world, i + 5, j + 36, k + 24, Blocks.stone, 0);
        this.setBlock(world, i + 5, j + 36, k + 25, Blocks.stone, 0);
        this.setBlock(world, i + 5, j + 36, k + 26, Blocks.stone, 0);
        this.setBlock(world, i + 5, j + 36, k + 27, Blocks.stone, 0);
        this.setBlock(world, i + 5, j + 37, k + 21, Blocks.stone, 0);
        this.setBlock(world, i + 5, j + 37, k + 22, Blocks.cobblestone, 0);
        this.setBlock(world, i + 5, j + 37, k + 23, Blocks.stone, 0);
        this.setBlock(world, i + 5, j + 37, k + 24, Blocks.bedrock, 0);
        this.setBlock(world, i + 5, j + 37, k + 25, Blocks.stone, 0);
        this.setBlock(world, i + 5, j + 37, k + 26, Blocks.bedrock, 0);
        this.setBlock(world, i + 5, j + 37, k + 27, Blocks.stone, 0);
        this.setBlock(world, i + 6, j + 32, k + 22, Blocks.stone, 0);
        this.setBlock(world, i + 6, j + 32, k + 23, Blocks.stone, 0);
        this.setBlock(world, i + 6, j + 32, k + 24, Blocks.stone, 0);
        this.setBlock(world, i + 6, j + 33, k + 21, Blocks.stone, 0);
        this.setBlock(world, i + 6, j + 33, k + 22, Blocks.stone, 0);
        this.setBlock(world, i + 6, j + 33, k + 23, Blocks.stone, 0);
        this.setBlock(world, i + 6, j + 33, k + 24, Blocks.stone, 0);
        this.setBlock(world, i + 6, j + 33, k + 25, Blocks.stone, 0);
        this.setBlock(world, i + 6, j + 34, k + 20, Blocks.stone, 0);
        this.setBlock(world, i + 6, j + 34, k + 21, Blocks.stone, 0);
        this.setBlock(world, i + 6, j + 34, k + 22, Blocks.stone, 0);
        this.setBlock(world, i + 6, j + 34, k + 23, Blocks.stone, 0);
        this.setBlock(world, i + 6, j + 34, k + 24, Blocks.stone, 0);
        this.setBlock(world, i + 6, j + 34, k + 25, Blocks.stone, 0);
        this.setBlock(world, i + 6, j + 34, k + 26, Blocks.stone, 0);
        this.setBlock(world, i + 6, j + 34, k + 27, Blocks.stone, 0);
        this.setBlock(world, i + 6, j + 34, k + 28, Blocks.stone, 0);
        this.setBlock(world, i + 6, j + 34, k + 29, Blocks.stone, 0);
        this.setBlock(world, i + 6, j + 35, k + 19, Blocks.mycelium, 0);
        this.setBlock(world, i + 6, j + 35, k + 20, Blocks.dirt, 0);
        this.setBlock(world, i + 6, j + 35, k + 21, Blocks.dirt, 0);
        this.setBlock(world, i + 6, j + 35, k + 22, Blocks.dirt, 0);
        this.setBlock(world, i + 6, j + 35, k + 23, Blocks.dirt, 0);
        this.setBlock(world, i + 6, j + 35, k + 24, Blocks.dirt, 0);
        this.setBlock(world, i + 6, j + 35, k + 25, Blocks.dirt, 0);
        this.setBlock(world, i + 6, j + 35, k + 26, Blocks.dirt, 0);
        this.setBlock(world, i + 6, j + 35, k + 27, Blocks.dirt, 0);
        this.setBlock(world, i + 6, j + 35, k + 28, Blocks.dirt, 0);
        this.setBlock(world, i + 6, j + 35, k + 29, Blocks.dirt, 0);
        this.setBlock(world, i + 6, j + 35, k + 32, Blocks.dirt, 0);
        this.setBlock(world, i + 6, j + 35, k + 33, Blocks.dirt, 0);
        this.setBlock(world, i + 6, j + 35, k + 34, Blocks.dirt, 0);
        this.setBlock(world, i + 6, j + 36, k + 20, Blocks.stone, 0);
        this.setBlock(world, i + 6, j + 36, k + 21, Blocks.stone, 0);
        this.setBlock(world, i + 6, j + 36, k + 22, Blocks.stone, 0);
        this.setBlock(world, i + 6, j + 36, k + 23, Blocks.stone, 0);
        this.setBlock(world, i + 6, j + 36, k + 24, Blocks.stone, 0);
        this.setBlock(world, i + 6, j + 36, k + 25, Blocks.stone, 0);
        this.setBlock(world, i + 6, j + 36, k + 26, Blocks.stone, 0);
        this.setBlock(world, i + 6, j + 36, k + 27, Blocks.stone, 0);
        this.setBlock(world, i + 6, j + 36, k + 28, Blocks.cobblestone, 0);
        this.setBlock(world, i + 6, j + 36, k + 29, Blocks.cobblestone, 0);
        this.setBlock(world, i + 6, j + 36, k + 31, Blocks.stone, 0);
        this.setBlock(world, i + 6, j + 36, k + 32, Blocks.mycelium, 0);
        this.setBlock(world, i + 6, j + 36, k + 33, Blocks.mycelium, 0);
        this.setBlock(world, i + 6, j + 36, k + 34, Blocks.mycelium, 0);
        this.setBlock(world, i + 6, j + 37, k + 20, Blocks.stone, 0);
        this.setBlock(world, i + 6, j + 37, k + 21, Blocks.stone, 0);
        this.setBlock(world, i + 6, j + 37, k + 22, Blocks.stone, 0);
        this.setBlock(world, i + 6, j + 37, k + 23, Blocks.stone, 0);
        this.setBlock(world, i + 6, j + 37, k + 24, Blocks.stone, 0);
        this.setBlock(world, i + 6, j + 37, k + 25, Blocks.stone, 0);
        this.setBlock(world, i + 6, j + 37, k + 26, Blocks.stone, 0);
        this.setBlock(world, i + 6, j + 37, k + 27, Blocks.stone, 0);
        this.setBlock(world, i + 6, j + 37, k + 28, Blocks.stone, 0);
        this.setBlock(world, i + 6, j + 38, k + 22, Blocks.stone, 0);
        this.setBlock(world, i + 6, j + 38, k + 23, Blocks.stone, 0);
        this.setBlock(world, i + 6, j + 38, k + 24, Blocks.cobblestone, 0);
        this.setBlock(world, i + 6, j + 38, k + 25, Blocks.cobblestone, 0);
        this.setBlock(world, i + 6, j + 38, k + 26, Blocks.stone, 0);
        this.setBlock(world, i + 6, j + 38, k + 27, Blocks.stone, 0);
        this.setBlock(world, i + 7, j + 32, k + 22, Blocks.stone, 0);
        this.setBlock(world, i + 7, j + 32, k + 23, Blocks.stone, 0);
        this.setBlock(world, i + 7, j + 32, k + 24, Blocks.stone, 0);
        this.setBlock(world, i + 7, j + 33, k + 21, Blocks.stone, 0);
        this.setBlock(world, i + 7, j + 33, k + 22, Blocks.stone, 0);
        this.setBlock(world, i + 7, j + 33, k + 23, Blocks.stone, 0);
        this.setBlock(world, i + 7, j + 33, k + 24, Blocks.stone, 0);
        this.setBlock(world, i + 7, j + 33, k + 25, Blocks.stone, 0);
        this.setBlock(world, i + 7, j + 33, k + 26, Blocks.stone, 0);
        this.setBlock(world, i + 7, j + 33, k + 27, Blocks.stone, 0);
        this.setBlock(world, i + 7, j + 33, k + 28, Blocks.stone, 0);
        this.setBlock(world, i + 7, j + 33, k + 29, Blocks.stone, 0);
        this.setBlock(world, i + 7, j + 33, k + 30, Blocks.stone, 0);
        this.setBlock(world, i + 7, j + 34, k + 18, Blocks.stone, 0);
        this.setBlock(world, i + 7, j + 34, k + 19, Blocks.stone, 0);
        this.setBlock(world, i + 7, j + 34, k + 20, Blocks.stone, 0);
        this.setBlock(world, i + 7, j + 34, k + 21, Blocks.stone, 0);
        this.setBlock(world, i + 7, j + 34, k + 22, Blocks.stone, 0);
        this.setBlock(world, i + 7, j + 34, k + 23, Blocks.stone, 0);
        this.setBlock(world, i + 7, j + 34, k + 24, Blocks.stone, 0);
        this.setBlock(world, i + 7, j + 34, k + 25, Blocks.stone, 0);
        this.setBlock(world, i + 7, j + 34, k + 26, Blocks.stone, 0);
        this.setBlock(world, i + 7, j + 34, k + 27, Blocks.stone, 0);
        this.setBlock(world, i + 7, j + 34, k + 28, Blocks.stone, 0);
        this.setBlock(world, i + 7, j + 34, k + 29, Blocks.stone, 0);
        this.setBlock(world, i + 7, j + 34, k + 30, Blocks.stone, 0);
        this.setBlock(world, i + 7, j + 34, k + 32, Blocks.stone, 0);
        this.setBlock(world, i + 7, j + 34, k + 33, Blocks.stone, 0);
        this.setBlock(world, i + 7, j + 34, k + 34, Blocks.stone, 0);
        this.setBlock(world, i + 7, j + 35, k + 18, Blocks.dirt, 0);
        this.setBlock(world, i + 7, j + 35, k + 19, Blocks.dirt, 0);
        this.setBlock(world, i + 7, j + 35, k + 20, Blocks.dirt, 0);
        this.setBlock(world, i + 7, j + 35, k + 21, Blocks.dirt, 0);
        this.setBlock(world, i + 7, j + 35, k + 22, Blocks.dirt, 0);
        this.setBlock(world, i + 7, j + 35, k + 23, Blocks.dirt, 0);
        this.setBlock(world, i + 7, j + 35, k + 24, Blocks.dirt, 0);
        this.setBlock(world, i + 7, j + 35, k + 25, Blocks.dirt, 0);
        this.setBlock(world, i + 7, j + 35, k + 26, Blocks.dirt, 0);
        this.setBlock(world, i + 7, j + 35, k + 27, Blocks.dirt, 0);
        this.setBlock(world, i + 7, j + 35, k + 28, Blocks.dirt, 0);
        this.setBlock(world, i + 7, j + 35, k + 29, Blocks.dirt, 0);
        this.setBlock(world, i + 7, j + 35, k + 30, Blocks.dirt, 0);
        this.setBlock(world, i + 7, j + 35, k + 32, Blocks.dirt, 0);
        this.setBlock(world, i + 7, j + 35, k + 33, Blocks.dirt, 0);
        this.setBlock(world, i + 7, j + 35, k + 34, Blocks.dirt, 0);
        this.setBlock(world, i + 7, j + 35, k + 35, Blocks.dirt, 0);
        this.setBlock(world, i + 7, j + 36, k + 18, Blocks.bedrock, 0);
        this.setBlock(world, i + 7, j + 36, k + 19, Blocks.stone, 0);
        this.setBlock(world, i + 7, j + 36, k + 20, Blocks.cobblestone, 0);
        this.setBlock(world, i + 7, j + 36, k + 21, Blocks.cobblestone, 0);
        this.setBlock(world, i + 7, j + 36, k + 22, Blocks.stone, 0);
        this.setBlock(world, i + 7, j + 36, k + 23, Blocks.cobblestone, 0);
        this.setBlock(world, i + 7, j + 36, k + 24, Blocks.cobblestone, 0);
        this.setBlock(world, i + 7, j + 36, k + 25, Blocks.stone, 0);
        this.setBlock(world, i + 7, j + 36, k + 26, Blocks.bedrock, 0);
        this.setBlock(world, i + 7, j + 36, k + 27, Blocks.stone, 0);
        this.setBlock(world, i + 7, j + 36, k + 28, Blocks.stone, 0);
        this.setBlock(world, i + 7, j + 36, k + 29, Blocks.bedrock, 0);
        this.setBlock(world, i + 7, j + 36, k + 30, Blocks.bedrock, 0);
        this.setBlock(world, i + 7, j + 36, k + 31, Blocks.stone, 0);
        this.setBlock(world, i + 7, j + 36, k + 32, Blocks.stone, 0);
        this.setBlock(world, i + 7, j + 36, k + 33, Blocks.stone, 0);
        this.setBlock(world, i + 7, j + 36, k + 34, Blocks.stone, 0);
        this.setBlock(world, i + 7, j + 36, k + 35, Blocks.stone, 0);
        this.setBlock(world, i + 7, j + 37, k + 20, Blocks.cobblestone, 0);
        this.setBlock(world, i + 7, j + 37, k + 21, Blocks.stone, 0);
        this.setBlock(world, i + 7, j + 37, k + 22, Blocks.stone, 0);
        this.setBlock(world, i + 7, j + 37, k + 23, Blocks.stone, 0);
        this.setBlock(world, i + 7, j + 37, k + 24, Blocks.stone, 0);
        this.setBlock(world, i + 7, j + 37, k + 25, Blocks.stone, 0);
        this.setBlock(world, i + 7, j + 37, k + 26, Blocks.stone, 0);
        this.setBlock(world, i + 7, j + 37, k + 27, Blocks.stone, 0);
        this.setBlock(world, i + 7, j + 37, k + 28, Blocks.bedrock, 0);
        this.setBlock(world, i + 7, j + 37, k + 29, Blocks.stone, 0);
        this.setBlock(world, i + 7, j + 37, k + 30, Blocks.stone, 0);
        this.setBlock(world, i + 7, j + 38, k + 20, Blocks.cobblestone, 0);
        this.setBlock(world, i + 7, j + 38, k + 21, Blocks.stone, 0);
        this.setBlock(world, i + 7, j + 38, k + 22, Blocks.bedrock, 0);
        this.setBlock(world, i + 7, j + 38, k + 23, Blocks.stone, 0);
        this.setBlock(world, i + 7, j + 38, k + 24, Blocks.cobblestone, 0);
        this.setBlock(world, i + 7, j + 38, k + 25, Blocks.bedrock, 0);
        this.setBlock(world, i + 7, j + 38, k + 26, Blocks.bedrock, 0);
        this.setBlock(world, i + 7, j + 38, k + 27, Blocks.stone, 0);
        this.setBlock(world, i + 7, j + 38, k + 28, Blocks.cobblestone, 0);
        this.setBlock(world, i + 7, j + 39, k + 23, Blocks.stone, 0);
        this.setBlock(world, i + 7, j + 39, k + 24, Blocks.bedrock, 0);
        this.setBlock(world, i + 7, j + 39, k + 25, Blocks.stone, 0);
        this.setBlock(world, i + 7, j + 39, k + 26, Blocks.bedrock, 0);
        this.setBlock(world, i + 7, j + 39, k + 27, Blocks.stone, 0);
        this.setBlock(world, i + 8, j + 31, k + 24, Blocks.stone, 0);
        this.setBlock(world, i + 8, j + 31, k + 25, Blocks.stone, 0);
        this.setBlock(world, i + 8, j + 31, k + 26, Blocks.stone, 0);
        this.setBlock(world, i + 8, j + 32, k + 22, Blocks.stone, 0);
        this.setBlock(world, i + 8, j + 32, k + 23, Blocks.stone, 0);
        this.setBlock(world, i + 8, j + 32, k + 24, Blocks.stone, 0);
        this.setBlock(world, i + 8, j + 32, k + 25, Blocks.stone, 0);
        this.setBlock(world, i + 8, j + 32, k + 26, Blocks.stone, 0);
        this.setBlock(world, i + 8, j + 32, k + 27, Blocks.stone, 0);
        this.setBlock(world, i + 8, j + 32, k + 28, Blocks.stone, 0);
        this.setBlock(world, i + 8, j + 32, k + 29, Blocks.stone, 0);
        this.setBlock(world, i + 8, j + 32, k + 30, Blocks.stone, 0);
        this.setBlock(world, i + 8, j + 33, k + 17, Blocks.stone, 0);
        this.setBlock(world, i + 8, j + 33, k + 18, Blocks.stone, 0);
        this.setBlock(world, i + 8, j + 33, k + 19, Blocks.stone, 0);
        this.setBlock(world, i + 8, j + 33, k + 20, Blocks.stone, 0);
        this.setBlock(world, i + 8, j + 33, k + 21, Blocks.stone, 0);
        this.setBlock(world, i + 8, j + 33, k + 22, Blocks.stone, 0);
        this.setBlock(world, i + 8, j + 33, k + 23, Blocks.stone, 0);
        this.setBlock(world, i + 8, j + 33, k + 24, Blocks.stone, 0);
        this.setBlock(world, i + 8, j + 33, k + 25, Blocks.stone, 0);
        this.setBlock(world, i + 8, j + 33, k + 26, Blocks.stone, 0);
        this.setBlock(world, i + 8, j + 33, k + 27, Blocks.stone, 0);
        this.setBlock(world, i + 8, j + 33, k + 28, Blocks.stone, 0);
        this.setBlock(world, i + 8, j + 33, k + 29, Blocks.stone, 0);
        this.setBlock(world, i + 8, j + 33, k + 30, Blocks.stone, 0);
        this.setBlock(world, i + 8, j + 33, k + 31, Blocks.stone, 0);
        this.setBlock(world, i + 8, j + 33, k + 32, Blocks.stone, 0);
        this.setBlock(world, i + 8, j + 33, k + 33, Blocks.stone, 0);
        this.setBlock(world, i + 8, j + 33, k + 34, Blocks.stone, 0);
        this.setBlock(world, i + 8, j + 33, k + 35, Blocks.stone, 0);
        this.setBlock(world, i + 8, j + 34, k + 17, Blocks.stone, 0);
        this.setBlock(world, i + 8, j + 34, k + 18, Blocks.stone, 0);
        this.setBlock(world, i + 8, j + 34, k + 19, Blocks.stone, 0);
        this.setBlock(world, i + 8, j + 34, k + 20, Blocks.stone, 0);
        this.setBlock(world, i + 8, j + 34, k + 21, Blocks.stone, 0);
        this.setBlock(world, i + 8, j + 34, k + 22, Blocks.stone, 0);
        this.setBlock(world, i + 8, j + 34, k + 23, Blocks.stone, 0);
        this.setBlock(world, i + 8, j + 34, k + 24, Blocks.stone, 0);
        this.setBlock(world, i + 8, j + 34, k + 25, Blocks.stone, 0);
        this.setBlock(world, i + 8, j + 34, k + 26, Blocks.stone, 0);
        this.setBlock(world, i + 8, j + 34, k + 27, Blocks.stone, 0);
        this.setBlock(world, i + 8, j + 34, k + 28, Blocks.stone, 0);
        this.setBlock(world, i + 8, j + 34, k + 29, Blocks.stone, 0);
        this.setBlock(world, i + 8, j + 34, k + 30, Blocks.stone, 0);
        this.setBlock(world, i + 8, j + 34, k + 31, Blocks.stone, 0);
        this.setBlock(world, i + 8, j + 34, k + 32, Blocks.stone, 0);
        this.setBlock(world, i + 8, j + 34, k + 33, Blocks.stone, 0);
        this.setBlock(world, i + 8, j + 34, k + 34, Blocks.stone, 0);
        this.setBlock(world, i + 8, j + 34, k + 35, Blocks.stone, 0);
        this.setBlock(world, i + 8, j + 35, k + 17, Blocks.dirt, 0);
        this.setBlock(world, i + 8, j + 35, k + 18, Blocks.dirt, 0);
        this.setBlock(world, i + 8, j + 35, k + 19, Blocks.dirt, 0);
        this.setBlock(world, i + 8, j + 35, k + 20, Blocks.dirt, 0);
        this.setBlock(world, i + 8, j + 35, k + 21, Blocks.dirt, 0);
        this.setBlock(world, i + 8, j + 35, k + 22, Blocks.dirt, 0);
        this.setBlock(world, i + 8, j + 35, k + 23, Blocks.dirt, 0);
        this.setBlock(world, i + 8, j + 35, k + 24, Blocks.dirt, 0);
        this.setBlock(world, i + 8, j + 35, k + 25, Blocks.dirt, 0);
        this.setBlock(world, i + 8, j + 35, k + 26, Blocks.dirt, 0);
        this.setBlock(world, i + 8, j + 35, k + 27, Blocks.dirt, 0);
        this.setBlock(world, i + 8, j + 35, k + 28, Blocks.dirt, 0);
        this.setBlock(world, i + 8, j + 35, k + 29, Blocks.dirt, 0);
        this.setBlock(world, i + 8, j + 35, k + 30, Blocks.dirt, 0);
        this.setBlock(world, i + 8, j + 35, k + 31, Blocks.dirt, 0);
        this.setBlock(world, i + 8, j + 35, k + 32, Blocks.dirt, 0);
        this.setBlock(world, i + 8, j + 35, k + 33, Blocks.dirt, 0);
        this.setBlock(world, i + 8, j + 35, k + 34, Blocks.dirt, 0);
        this.setBlock(world, i + 8, j + 35, k + 35, Blocks.dirt, 0);
        this.setBlock(world, i + 8, j + 35, k + 36, Blocks.dirt, 0);
        this.setBlock(world, i + 8, j + 36, k + 17, Blocks.stone, 0);
        this.setBlock(world, i + 8, j + 36, k + 18, Blocks.stone, 0);
        this.setBlock(world, i + 8, j + 36, k + 19, Blocks.stone, 0);
        this.setBlock(world, i + 8, j + 36, k + 20, Blocks.stone, 0);
        this.setBlock(world, i + 8, j + 36, k + 21, Blocks.bedrock, 0);
        this.setBlock(world, i + 8, j + 36, k + 22, Blocks.stone, 0);
        this.setBlock(world, i + 8, j + 36, k + 23, Blocks.stone, 0);
        this.setBlock(world, i + 8, j + 36, k + 24, Blocks.stone, 0);
        this.setBlock(world, i + 8, j + 36, k + 25, Blocks.stone, 0);
        this.setBlock(world, i + 8, j + 36, k + 26, Blocks.stone, 0);
        this.setBlock(world, i + 8, j + 36, k + 27, Blocks.stone, 0);
        this.setBlock(world, i + 8, j + 36, k + 28, Blocks.stone, 0);
        this.setBlock(world, i + 8, j + 36, k + 29, Blocks.bedrock, 0);
        this.setBlock(world, i + 8, j + 36, k + 30, Blocks.stone, 0);
        this.setBlock(world, i + 8, j + 36, k + 31, Blocks.stone, 0);
        this.setBlock(world, i + 8, j + 36, k + 32, Blocks.stone, 0);
        this.setBlock(world, i + 8, j + 36, k + 33, Blocks.stone, 0);
        this.setBlock(world, i + 8, j + 36, k + 34, Blocks.stone, 0);
        this.setBlock(world, i + 8, j + 36, k + 35, Blocks.stone, 0);
        this.setBlock(world, i + 8, j + 36, k + 36, Blocks.stone, 0);
        this.setBlock(world, i + 8, j + 37, k + 16, Blocks.stone, 0);
        this.setBlock(world, i + 8, j + 37, k + 17, Blocks.stone, 0);
        this.setBlock(world, i + 8, j + 37, k + 18, Blocks.stone, 0);
        this.setBlock(world, i + 8, j + 37, k + 19, Blocks.stone, 0);
        this.setBlock(world, i + 8, j + 37, k + 20, Blocks.stone, 0);
        this.setBlock(world, i + 8, j + 37, k + 21, Blocks.stone, 0);
        this.setBlock(world, i + 8, j + 37, k + 22, Blocks.stone, 0);
        this.setBlock(world, i + 8, j + 37, k + 23, Blocks.stone, 0);
        this.setBlock(world, i + 8, j + 37, k + 24, Blocks.stone, 0);
        this.setBlock(world, i + 8, j + 37, k + 25, Blocks.stone, 0);
        this.setBlock(world, i + 8, j + 37, k + 26, Blocks.stone, 0);
        this.setBlock(world, i + 8, j + 37, k + 27, Blocks.cobblestone, 0);
        this.setBlock(world, i + 8, j + 37, k + 28, Blocks.stone, 0);
        this.setBlock(world, i + 8, j + 37, k + 29, Blocks.stone, 0);
        this.setBlock(world, i + 8, j + 37, k + 30, Blocks.stone, 0);
        this.setBlock(world, i + 8, j + 37, k + 31, Blocks.bedrock, 0);
        this.setBlock(world, i + 8, j + 37, k + 32, Blocks.stone, 0);
        this.setBlock(world, i + 8, j + 37, k + 33, Blocks.stone, 0);
        this.setBlock(world, i + 8, j + 37, k + 34, Blocks.stone, 0);
        this.setBlock(world, i + 8, j + 38, k + 18, Blocks.stone, 0);
        this.setBlock(world, i + 8, j + 38, k + 19, Blocks.stone, 0);
        this.setBlock(world, i + 8, j + 38, k + 20, Blocks.stone, 0);
        this.setBlock(world, i + 8, j + 38, k + 21, Blocks.stone, 0);
        this.setBlock(world, i + 8, j + 38, k + 22, Blocks.stone, 0);
        this.setBlock(world, i + 8, j + 38, k + 23, Blocks.stone, 0);
        this.setBlock(world, i + 8, j + 38, k + 24, Blocks.stone, 0);
        this.setBlock(world, i + 8, j + 38, k + 25, Blocks.stone, 0);
        this.setBlock(world, i + 8, j + 38, k + 26, Blocks.stone, 0);
        this.setBlock(world, i + 8, j + 38, k + 27, Blocks.cobblestone, 0);
        this.setBlock(world, i + 8, j + 38, k + 28, Blocks.bedrock, 0);
        this.setBlock(world, i + 8, j + 38, k + 29, Blocks.stone, 0);
        this.setBlock(world, i + 8, j + 38, k + 30, Blocks.stone, 0);
        this.setBlock(world, i + 8, j + 39, k + 19, Blocks.stone, 0);
        this.setBlock(world, i + 8, j + 39, k + 20, Blocks.cobblestone, 0);
        this.setBlock(world, i + 8, j + 39, k + 21, Blocks.stone, 0);
        this.setBlock(world, i + 8, j + 39, k + 22, Blocks.stone, 0);
        this.setBlock(world, i + 8, j + 39, k + 23, Blocks.stone, 0);
        this.setBlock(world, i + 8, j + 39, k + 24, Blocks.stone, 0);
        this.setBlock(world, i + 8, j + 39, k + 25, Blocks.stone, 0);
        this.setBlock(world, i + 8, j + 39, k + 26, Blocks.stone, 0);
        this.setBlock(world, i + 8, j + 39, k + 27, Blocks.stone, 0);
        this.setBlock(world, i + 8, j + 39, k + 28, Blocks.stone, 0);
        this.setBlock(world, i + 8, j + 40, k + 19, Blocks.stone, 0);
        this.setBlock(world, i + 8, j + 40, k + 25, Blocks.stone, 0);
        this.setBlock(world, i + 8, j + 40, k + 26, Blocks.stone, 0);
        this.setBlock(world, i + 8, j + 40, k + 27, Blocks.stone, 0);
        this.setBlock(world, i + 9, j + 30, k + 25, Blocks.stone, 0);
        this.setBlock(world, i + 9, j + 31, k + 22, Blocks.stone, 0);
        this.setBlock(world, i + 9, j + 31, k + 23, Blocks.stone, 0);
        this.setBlock(world, i + 9, j + 31, k + 24, Blocks.stone, 0);
        this.setBlock(world, i + 9, j + 31, k + 25, Blocks.stone, 0);
        this.setBlock(world, i + 9, j + 31, k + 26, Blocks.bedrock, 0);
        this.setBlock(world, i + 9, j + 32, k + 18, Blocks.stone, 0);
        this.setBlock(world, i + 9, j + 32, k + 19, Blocks.stone, 0);
        this.setBlock(world, i + 9, j + 32, k + 20, Blocks.stone, 0);
        this.setBlock(world, i + 9, j + 32, k + 21, Blocks.bedrock, 0);
        this.setBlock(world, i + 9, j + 32, k + 22, Blocks.bedrock, 0);
        this.setBlock(world, i + 9, j + 32, k + 23, Blocks.stone, 0);
        this.setBlock(world, i + 9, j + 32, k + 24, Blocks.bedrock, 0);
        this.setBlock(world, i + 9, j + 32, k + 25, Blocks.stone, 0);
        this.setBlock(world, i + 9, j + 32, k + 26, Blocks.bedrock, 0);
        this.setBlock(world, i + 9, j + 32, k + 27, Blocks.stone, 0);
        this.setBlock(world, i + 9, j + 32, k + 28, Blocks.stone, 0);
        this.setBlock(world, i + 9, j + 32, k + 29, Blocks.stone, 0);
        this.setBlock(world, i + 9, j + 32, k + 30, Blocks.stone, 0);
        this.setBlock(world, i + 9, j + 32, k + 31, Blocks.bedrock, 0);
        this.setBlock(world, i + 9, j + 32, k + 32, Blocks.stone, 0);
        this.setBlock(world, i + 9, j + 32, k + 33, Blocks.stone, 0);
        this.setBlock(world, i + 9, j + 32, k + 34, Blocks.stone, 0);
        this.setBlock(world, i + 9, j + 33, k + 17, Blocks.stone, 0);
        this.setBlock(world, i + 9, j + 33, k + 18, Blocks.stone, 0);
        this.setBlock(world, i + 9, j + 33, k + 19, Blocks.stone, 0);
        this.setBlock(world, i + 9, j + 33, k + 20, Blocks.stone, 0);
        this.setBlock(world, i + 9, j + 33, k + 21, Blocks.stone, 0);
        this.setBlock(world, i + 9, j + 33, k + 22, Blocks.stone, 0);
        this.setBlock(world, i + 9, j + 33, k + 23, Blocks.stone, 0);
        this.setBlock(world, i + 9, j + 33, k + 24, Blocks.stone, 0);
        this.setBlock(world, i + 9, j + 33, k + 25, Blocks.stone, 0);
        this.setBlock(world, i + 9, j + 33, k + 26, Blocks.stone, 0);
        this.setBlock(world, i + 9, j + 33, k + 27, Blocks.stone, 0);
        this.setBlock(world, i + 9, j + 33, k + 28, Blocks.stone, 0);
        this.setBlock(world, i + 9, j + 33, k + 29, Blocks.stone, 0);
        this.setBlock(world, i + 9, j + 33, k + 30, Blocks.stone, 0);
        this.setBlock(world, i + 9, j + 33, k + 31, Blocks.stone, 0);
        this.setBlock(world, i + 9, j + 33, k + 32, Blocks.stone, 0);
        this.setBlock(world, i + 9, j + 33, k + 33, Blocks.stone, 0);
        this.setBlock(world, i + 9, j + 33, k + 34, Blocks.stone, 0);
        this.setBlock(world, i + 9, j + 33, k + 35, Blocks.stone, 0);
        this.setBlock(world, i + 9, j + 34, k + 16, Blocks.stone, 0);
        this.setBlock(world, i + 9, j + 34, k + 17, Blocks.stone, 0);
        this.setBlock(world, i + 9, j + 34, k + 18, Blocks.stone, 0);
        this.setBlock(world, i + 9, j + 34, k + 19, Blocks.stone, 0);
        this.setBlock(world, i + 9, j + 34, k + 20, Blocks.stone, 0);
        this.setBlock(world, i + 9, j + 34, k + 21, Blocks.stone, 0);
        this.setBlock(world, i + 9, j + 34, k + 22, Blocks.stone, 0);
        this.setBlock(world, i + 9, j + 34, k + 23, Blocks.stone, 0);
        this.setBlock(world, i + 9, j + 34, k + 24, Blocks.stone, 0);
        this.setBlock(world, i + 9, j + 34, k + 25, Blocks.stone, 0);
        this.setBlock(world, i + 9, j + 34, k + 26, Blocks.stone, 0);
        this.setBlock(world, i + 9, j + 34, k + 27, Blocks.stone, 0);
        this.setBlock(world, i + 9, j + 34, k + 28, Blocks.stone, 0);
        this.setBlock(world, i + 9, j + 34, k + 29, Blocks.stone, 0);
        this.setBlock(world, i + 9, j + 34, k + 30, Blocks.stone, 0);
        this.setBlock(world, i + 9, j + 34, k + 31, Blocks.stone, 0);
        this.setBlock(world, i + 9, j + 34, k + 32, Blocks.stone, 0);
        this.setBlock(world, i + 9, j + 34, k + 33, Blocks.stone, 0);
        this.setBlock(world, i + 9, j + 34, k + 34, Blocks.stone, 0);
        this.setBlock(world, i + 9, j + 34, k + 35, Blocks.stone, 0);
        this.setBlock(world, i + 9, j + 34, k + 36, Blocks.stone, 0);
        this.setBlock(world, i + 9, j + 35, k + 15, Blocks.dirt, 0);
        this.setBlock(world, i + 9, j + 35, k + 16, Blocks.dirt, 0);
        this.setBlock(world, i + 9, j + 35, k + 17, Blocks.dirt, 0);
        this.setBlock(world, i + 9, j + 35, k + 18, Blocks.dirt, 0);
        this.setBlock(world, i + 9, j + 35, k + 19, Blocks.dirt, 0);
        this.setBlock(world, i + 9, j + 35, k + 20, Blocks.dirt, 0);
        this.setBlock(world, i + 9, j + 35, k + 21, Blocks.dirt, 0);
        this.setBlock(world, i + 9, j + 35, k + 22, Blocks.dirt, 0);
        this.setBlock(world, i + 9, j + 35, k + 23, Blocks.dirt, 0);
        this.setBlock(world, i + 9, j + 35, k + 24, Blocks.dirt, 0);
        this.setBlock(world, i + 9, j + 35, k + 25, Blocks.dirt, 0);
        this.setBlock(world, i + 9, j + 35, k + 26, Blocks.dirt, 0);
        this.setBlock(world, i + 9, j + 35, k + 27, Blocks.dirt, 0);
        this.setBlock(world, i + 9, j + 35, k + 28, Blocks.dirt, 0);
        this.setBlock(world, i + 9, j + 35, k + 29, Blocks.dirt, 0);
        this.setBlock(world, i + 9, j + 35, k + 30, Blocks.dirt, 0);
        this.setBlock(world, i + 9, j + 35, k + 31, Blocks.dirt, 0);
        this.setBlock(world, i + 9, j + 35, k + 32, Blocks.dirt, 0);
        this.setBlock(world, i + 9, j + 35, k + 33, Blocks.dirt, 0);
        this.setBlock(world, i + 9, j + 35, k + 34, Blocks.dirt, 0);
        this.setBlock(world, i + 9, j + 35, k + 35, Blocks.dirt, 0);
        this.setBlock(world, i + 9, j + 35, k + 36, Blocks.dirt, 0);
        this.setBlock(world, i + 9, j + 35, k + 37, Blocks.dirt, 0);
        this.setBlock(world, i + 9, j + 36, k + 15, Blocks.mycelium, 0);
        this.setBlock(world, i + 9, j + 36, k + 16, Blocks.dirt, 0);
        this.setBlock(world, i + 9, j + 36, k + 17, Blocks.dirt, 0);
        this.setBlock(world, i + 9, j + 36, k + 18, Blocks.stone, 0);
        this.setBlock(world, i + 9, j + 36, k + 19, Blocks.cobblestone, 0);
        this.setBlock(world, i + 9, j + 36, k + 20, Blocks.stone, 0);
        this.setBlock(world, i + 9, j + 36, k + 21, Blocks.stone, 0);
        this.setBlock(world, i + 9, j + 36, k + 22, Blocks.stone, 0);
        this.setBlock(world, i + 9, j + 36, k + 23, Blocks.stone, 0);
        this.setBlock(world, i + 9, j + 36, k + 24, Blocks.cobblestone, 0);
        this.setBlock(world, i + 9, j + 36, k + 25, Blocks.stone, 0);
        this.setBlock(world, i + 9, j + 36, k + 26, Blocks.bedrock, 0);
        this.setBlock(world, i + 9, j + 36, k + 27, Blocks.stone, 0);
        this.setBlock(world, i + 9, j + 36, k + 28, Blocks.stone, 0);
        this.setBlock(world, i + 9, j + 36, k + 29, Blocks.stone, 0);
        this.setBlock(world, i + 9, j + 36, k + 30, Blocks.cobblestone, 0);
        this.setBlock(world, i + 9, j + 36, k + 31, Blocks.cobblestone, 0);
        this.setBlock(world, i + 9, j + 36, k + 32, Blocks.stone, 0);
        this.setBlock(world, i + 9, j + 36, k + 33, Blocks.stone, 0);
        this.setBlock(world, i + 9, j + 36, k + 34, Blocks.stone, 0);
        this.setBlock(world, i + 9, j + 36, k + 35, Blocks.stone, 0);
        this.setBlock(world, i + 9, j + 36, k + 36, Blocks.stone, 0);
        this.setBlock(world, i + 9, j + 36, k + 37, Blocks.cobblestone, 0);
        this.setBlock(world, i + 9, j + 37, k + 16, Blocks.stone, 0);
        this.setBlock(world, i + 9, j + 37, k + 17, Blocks.stone, 0);
        this.setBlock(world, i + 9, j + 37, k + 18, Blocks.stone, 0);
        this.setBlock(world, i + 9, j + 37, k + 19, Blocks.cobblestone, 0);
        this.setBlock(world, i + 9, j + 37, k + 20, Blocks.cobblestone, 0);
        this.setBlock(world, i + 9, j + 37, k + 21, Blocks.stone, 0);
        this.setBlock(world, i + 9, j + 37, k + 22, Blocks.cobblestone, 0);
        this.setBlock(world, i + 9, j + 37, k + 23, Blocks.stone, 0);
        this.setBlock(world, i + 9, j + 37, k + 24, Blocks.cobblestone, 0);
        this.setBlock(world, i + 9, j + 37, k + 25, Blocks.bedrock, 0);
        this.setBlock(world, i + 9, j + 37, k + 26, Blocks.stone, 0);
        this.setBlock(world, i + 9, j + 37, k + 27, Blocks.stone, 0);
        this.setBlock(world, i + 9, j + 37, k + 28, Blocks.stone, 0);
        this.setBlock(world, i + 9, j + 37, k + 29, Blocks.stone, 0);
        this.setBlock(world, i + 9, j + 37, k + 30, Blocks.stone, 0);
        this.setBlock(world, i + 9, j + 37, k + 31, Blocks.bedrock, 0);
        this.setBlock(world, i + 9, j + 37, k + 32, Blocks.stone, 0);
        this.setBlock(world, i + 9, j + 37, k + 33, Blocks.bedrock, 0);
        this.setBlock(world, i + 9, j + 37, k + 34, Blocks.stone, 0);
        this.setBlock(world, i + 9, j + 37, k + 35, Blocks.stone, 0);
        this.setBlock(world, i + 9, j + 38, k + 17, Blocks.bedrock, 0);
        this.setBlock(world, i + 9, j + 38, k + 18, Blocks.stone, 0);
        this.setBlock(world, i + 9, j + 38, k + 19, Blocks.stone, 0);
        this.setBlock(world, i + 9, j + 38, k + 20, Blocks.stone, 0);
        this.setBlock(world, i + 9, j + 38, k + 21, Blocks.stone, 0);
        this.setBlock(world, i + 9, j + 38, k + 22, Blocks.stone, 0);
        this.setBlock(world, i + 9, j + 38, k + 23, Blocks.stone, 0);
        this.setBlock(world, i + 9, j + 38, k + 24, Blocks.cobblestone, 0);
        this.setBlock(world, i + 9, j + 38, k + 25, Blocks.stone, 0);
        this.setBlock(world, i + 9, j + 38, k + 26, Blocks.stone, 0);
        this.setBlock(world, i + 9, j + 38, k + 27, Blocks.stone, 0);
        this.setBlock(world, i + 9, j + 38, k + 28, Blocks.stone, 0);
        this.setBlock(world, i + 9, j + 38, k + 29, Blocks.stone, 0);
        this.setBlock(world, i + 9, j + 38, k + 30, Blocks.stone, 0);
        this.setBlock(world, i + 9, j + 38, k + 31, Blocks.cobblestone, 0);
        this.setBlock(world, i + 9, j + 39, k + 19, Blocks.stone, 0);
        this.setBlock(world, i + 9, j + 39, k + 20, Blocks.bedrock, 0);
        this.setBlock(world, i + 9, j + 39, k + 21, Blocks.stone, 0);
        this.setBlock(world, i + 9, j + 39, k + 22, Blocks.stone, 0);
        this.setBlock(world, i + 9, j + 39, k + 23, Blocks.stone, 0);
        this.setBlock(world, i + 9, j + 39, k + 24, Blocks.stone, 0);
        this.setBlock(world, i + 9, j + 39, k + 25, Blocks.stone, 0);
        this.setBlock(world, i + 9, j + 39, k + 26, Blocks.stone, 0);
        this.setBlock(world, i + 9, j + 39, k + 27, Blocks.stone, 0);
        this.setBlock(world, i + 9, j + 39, k + 28, Blocks.stone, 0);
        this.setBlock(world, i + 9, j + 40, k + 19, Blocks.stone, 0);
        this.setBlock(world, i + 9, j + 40, k + 20, Blocks.stone, 0);
        this.setBlock(world, i + 9, j + 40, k + 21, Blocks.stone, 0);
        this.setBlock(world, i + 9, j + 40, k + 22, Blocks.cobblestone, 0);
        this.setBlock(world, i + 9, j + 40, k + 23, Blocks.stone, 0);
        this.setBlock(world, i + 9, j + 40, k + 24, Blocks.stone, 0);
        this.setBlock(world, i + 9, j + 40, k + 25, Blocks.stone, 0);
        this.setBlock(world, i + 9, j + 40, k + 26, Blocks.stone, 0);
        this.setBlock(world, i + 9, j + 40, k + 27, Blocks.cobblestone, 0);
        this.setBlock(world, i + 9, j + 41, k + 19, Blocks.bedrock, 0);
        this.setBlock(world, i + 9, j + 41, k + 20, Blocks.stone, 0);
        this.setBlock(world, i + 9, j + 41, k + 21, Blocks.stone, 0);
        this.setBlock(world, i + 9, j + 41, k + 22, Blocks.stone, 0);
        this.setBlock(world, i + 9, j + 41, k + 23, Blocks.stone, 0);
        this.setBlock(world, i + 9, j + 41, k + 24, Blocks.stone, 0);
        this.setBlock(world, i + 9, j + 41, k + 25, Blocks.stone, 0);
        this.setBlock(world, i + 9, j + 41, k + 26, Blocks.stone, 0);
        this.setBlock(world, i + 9, j + 41, k + 27, Blocks.stone, 0);
        this.setBlock(world, i + 10, j + 30, k + 22, Blocks.stone, 0);
        this.setBlock(world, i + 10, j + 30, k + 23, Blocks.stone, 0);
        this.setBlock(world, i + 10, j + 30, k + 24, Blocks.cobblestone, 0);
        this.setBlock(world, i + 10, j + 30, k + 25, Blocks.cobblestone, 0);
        this.setBlock(world, i + 10, j + 31, k + 22, Blocks.cobblestone, 0);
        this.setBlock(world, i + 10, j + 31, k + 23, Blocks.stone, 0);
        this.setBlock(world, i + 10, j + 31, k + 24, Blocks.stone, 0);
        this.setBlock(world, i + 10, j + 31, k + 25, Blocks.stone, 0);
        this.setBlock(world, i + 10, j + 31, k + 26, Blocks.stone, 0);
        this.setBlock(world, i + 10, j + 31, k + 27, Blocks.stone, 0);
        this.setBlock(world, i + 10, j + 31, k + 28, Blocks.stone, 0);
        this.setBlock(world, i + 10, j + 31, k + 29, Blocks.stone, 0);
        this.setBlock(world, i + 10, j + 31, k + 30, Blocks.bedrock, 0);
        this.setBlock(world, i + 10, j + 31, k + 31, Blocks.stone, 0);
        this.setBlock(world, i + 10, j + 31, k + 32, Blocks.bedrock, 0);
        this.setBlock(world, i + 10, j + 31, k + 33, Blocks.stone, 0);
        this.setBlock(world, i + 10, j + 32, k + 18, Blocks.stone, 0);
        this.setBlock(world, i + 10, j + 32, k + 19, Blocks.stone, 0);
        this.setBlock(world, i + 10, j + 32, k + 20, Blocks.stone, 0);
        this.setBlock(world, i + 10, j + 32, k + 21, Blocks.stone, 0);
        this.setBlock(world, i + 10, j + 32, k + 22, Blocks.stone, 0);
        this.setBlock(world, i + 10, j + 32, k + 23, Blocks.stone, 0);
        this.setBlock(world, i + 10, j + 32, k + 24, Blocks.stone, 0);
        this.setBlock(world, i + 10, j + 32, k + 25, Blocks.stone, 0);
        this.setBlock(world, i + 10, j + 32, k + 26, Blocks.stone, 0);
        this.setBlock(world, i + 10, j + 32, k + 27, Blocks.stone, 0);
        this.setBlock(world, i + 10, j + 32, k + 28, Blocks.stone, 0);
        this.setBlock(world, i + 10, j + 32, k + 29, Blocks.stone, 0);
        this.setBlock(world, i + 10, j + 32, k + 30, Blocks.stone, 0);
        this.setBlock(world, i + 10, j + 32, k + 31, Blocks.stone, 0);
        this.setBlock(world, i + 10, j + 32, k + 32, Blocks.stone, 0);
        this.setBlock(world, i + 10, j + 32, k + 33, Blocks.stone, 0);
        this.setBlock(world, i + 10, j + 32, k + 34, Blocks.stone, 0);
        this.setBlock(world, i + 10, j + 33, k + 17, Blocks.stone, 0);
        this.setBlock(world, i + 10, j + 33, k + 18, Blocks.stone, 0);
        this.setBlock(world, i + 10, j + 33, k + 19, Blocks.stone, 0);
        this.setBlock(world, i + 10, j + 33, k + 20, Blocks.stone, 0);
        this.setBlock(world, i + 10, j + 33, k + 21, Blocks.stone, 0);
        this.setBlock(world, i + 10, j + 33, k + 22, Blocks.stone, 0);
        this.setBlock(world, i + 10, j + 33, k + 23, Blocks.stone, 0);
        this.setBlock(world, i + 10, j + 33, k + 24, Blocks.stone, 0);
        this.setBlock(world, i + 10, j + 33, k + 25, Blocks.stone, 0);
        this.setBlock(world, i + 10, j + 33, k + 26, Blocks.stone, 0);
        this.setBlock(world, i + 10, j + 33, k + 27, Blocks.stone, 0);
        this.setBlock(world, i + 10, j + 33, k + 28, Blocks.stone, 0);
        this.setBlock(world, i + 10, j + 33, k + 29, Blocks.stone, 0);
        this.setBlock(world, i + 10, j + 33, k + 30, Blocks.stone, 0);
        this.setBlock(world, i + 10, j + 33, k + 31, Blocks.stone, 0);
        this.setBlock(world, i + 10, j + 33, k + 32, Blocks.stone, 0);
        this.setBlock(world, i + 10, j + 33, k + 33, Blocks.stone, 0);
        this.setBlock(world, i + 10, j + 33, k + 34, Blocks.stone, 0);
        this.setBlock(world, i + 10, j + 33, k + 35, Blocks.stone, 0);
        this.setBlock(world, i + 10, j + 34, k + 17, Blocks.stone, 0);
        this.setBlock(world, i + 10, j + 34, k + 18, Blocks.stone, 0);
        this.setBlock(world, i + 10, j + 34, k + 19, Blocks.stone, 0);
        this.setBlock(world, i + 10, j + 34, k + 20, Blocks.stone, 0);
        this.setBlock(world, i + 10, j + 34, k + 21, Blocks.stone, 0);
        this.setBlock(world, i + 10, j + 34, k + 22, Blocks.stone, 0);
        this.setBlock(world, i + 10, j + 34, k + 23, Blocks.stone, 0);
        this.setBlock(world, i + 10, j + 34, k + 24, Blocks.stone, 0);
        this.setBlock(world, i + 10, j + 34, k + 25, Blocks.stone, 0);
        this.setBlock(world, i + 10, j + 34, k + 26, Blocks.stone, 0);
        this.setBlock(world, i + 10, j + 34, k + 27, Blocks.stone, 0);
        this.setBlock(world, i + 10, j + 34, k + 28, Blocks.stone, 0);
        this.setBlock(world, i + 10, j + 34, k + 29, Blocks.stone, 0);
        this.setBlock(world, i + 10, j + 34, k + 30, Blocks.stone, 0);
        this.setBlock(world, i + 10, j + 34, k + 31, Blocks.stone, 0);
        this.setBlock(world, i + 10, j + 34, k + 32, Blocks.stone, 0);
        this.setBlock(world, i + 10, j + 34, k + 33, Blocks.stone, 0);
        this.setBlock(world, i + 10, j + 34, k + 34, Blocks.stone, 0);
        this.setBlock(world, i + 10, j + 34, k + 35, Blocks.stone, 0);
        this.setBlock(world, i + 10, j + 34, k + 36, Blocks.stone, 0);
        this.setBlock(world, i + 10, j + 35, k + 15, Blocks.dirt, 0);
        this.setBlock(world, i + 10, j + 35, k + 16, Blocks.dirt, 0);
        this.setBlock(world, i + 10, j + 35, k + 17, Blocks.dirt, 0);
        this.setBlock(world, i + 10, j + 35, k + 18, Blocks.dirt, 0);
        this.setBlock(world, i + 10, j + 35, k + 19, Blocks.dirt, 0);
        this.setBlock(world, i + 10, j + 35, k + 20, Blocks.dirt, 0);
        this.setBlock(world, i + 10, j + 35, k + 21, Blocks.dirt, 0);
        this.setBlock(world, i + 10, j + 35, k + 22, Blocks.dirt, 0);
        this.setBlock(world, i + 10, j + 35, k + 23, Blocks.dirt, 0);
        this.setBlock(world, i + 10, j + 35, k + 24, Blocks.dirt, 0);
        this.setBlock(world, i + 10, j + 35, k + 25, Blocks.dirt, 0);
        this.setBlock(world, i + 10, j + 35, k + 26, Blocks.dirt, 0);
        this.setBlock(world, i + 10, j + 35, k + 27, Blocks.dirt, 0);
        this.setBlock(world, i + 10, j + 35, k + 28, Blocks.dirt, 0);
        this.setBlock(world, i + 10, j + 35, k + 29, Blocks.dirt, 0);
        this.setBlock(world, i + 10, j + 35, k + 30, Blocks.dirt, 0);
        this.setBlock(world, i + 10, j + 35, k + 31, Blocks.dirt, 0);
        this.setBlock(world, i + 10, j + 35, k + 32, Blocks.dirt, 0);
        this.setBlock(world, i + 10, j + 35, k + 33, Blocks.dirt, 0);
        this.setBlock(world, i + 10, j + 35, k + 34, Blocks.dirt, 0);
        this.setBlock(world, i + 10, j + 35, k + 35, Blocks.dirt, 0);
        this.setBlock(world, i + 10, j + 35, k + 36, Blocks.dirt, 0);
        this.setBlock(world, i + 10, j + 35, k + 37, Blocks.dirt, 0);
        this.setBlock(world, i + 10, j + 36, k + 15, Blocks.dirt, 0);
        this.setBlock(world, i + 10, j + 36, k + 16, Blocks.cobblestone, 0);
        this.setBlock(world, i + 10, j + 36, k + 17, Blocks.dirt, 0);
        this.setBlock(world, i + 10, j + 36, k + 18, Blocks.stone, 0);
        this.setBlock(world, i + 10, j + 36, k + 19, Blocks.stone, 0);
        this.setBlock(world, i + 10, j + 36, k + 20, Blocks.stone, 0);
        this.setBlock(world, i + 10, j + 36, k + 21, Blocks.stone, 0);
        this.setBlock(world, i + 10, j + 36, k + 22, Blocks.bedrock, 0);
        this.setBlock(world, i + 10, j + 36, k + 23, Blocks.stone, 0);
        this.setBlock(world, i + 10, j + 36, k + 24, Blocks.stone, 0);
        this.setBlock(world, i + 10, j + 36, k + 25, Blocks.bedrock, 0);
        this.setBlock(world, i + 10, j + 36, k + 26, Blocks.cobblestone, 0);
        this.setBlock(world, i + 10, j + 36, k + 27, Blocks.stone, 0);
        this.setBlock(world, i + 10, j + 36, k + 28, Blocks.stone, 0);
        this.setBlock(world, i + 10, j + 36, k + 29, Blocks.stone, 0);
        this.setBlock(world, i + 10, j + 36, k + 30, Blocks.stone, 0);
        this.setBlock(world, i + 10, j + 36, k + 31, Blocks.cobblestone, 0);
        this.setBlock(world, i + 10, j + 36, k + 32, Blocks.stone, 0);
        this.setBlock(world, i + 10, j + 36, k + 33, Blocks.stone, 0);
        this.setBlock(world, i + 10, j + 36, k + 34, Blocks.stone, 0);
        this.setBlock(world, i + 10, j + 36, k + 35, Blocks.stone, 0);
        this.setBlock(world, i + 10, j + 36, k + 36, Blocks.bedrock, 0);
        this.setBlock(world, i + 10, j + 36, k + 37, Blocks.stone, 0);
        this.setBlock(world, i + 10, j + 37, k + 15, Blocks.bedrock, 0);
        this.setBlock(world, i + 10, j + 37, k + 16, Blocks.stone, 0);
        this.setBlock(world, i + 10, j + 37, k + 17, Blocks.stone, 0);
        this.setBlock(world, i + 10, j + 37, k + 18, Blocks.stone, 0);
        this.setBlock(world, i + 10, j + 37, k + 19, Blocks.stone, 0);
        this.setBlock(world, i + 10, j + 37, k + 20, Blocks.bedrock, 0);
        this.setBlock(world, i + 10, j + 37, k + 21, Blocks.stone, 0);
        this.setBlock(world, i + 10, j + 37, k + 22, Blocks.bedrock, 0);
        this.setBlock(world, i + 10, j + 37, k + 23, Blocks.bedrock, 0);
        this.setBlock(world, i + 10, j + 37, k + 24, Blocks.stone, 0);
        this.setBlock(world, i + 10, j + 37, k + 25, Blocks.stone, 0);
        this.setBlock(world, i + 10, j + 37, k + 26, Blocks.stone, 0);
        this.setBlock(world, i + 10, j + 37, k + 27, Blocks.stone, 0);
        this.setBlock(world, i + 10, j + 37, k + 28, Blocks.stone, 0);
        this.setBlock(world, i + 10, j + 37, k + 29, Blocks.stone, 0);
        this.setBlock(world, i + 10, j + 37, k + 30, Blocks.stone, 0);
        this.setBlock(world, i + 10, j + 37, k + 31, Blocks.stone, 0);
        this.setBlock(world, i + 10, j + 37, k + 32, Blocks.stone, 0);
        this.setBlock(world, i + 10, j + 37, k + 33, Blocks.cobblestone, 0);
        this.setBlock(world, i + 10, j + 37, k + 34, Blocks.stone, 0);
        this.setBlock(world, i + 10, j + 37, k + 35, Blocks.bedrock, 0);
        this.setBlock(world, i + 10, j + 38, k + 17, Blocks.stone, 0);
        this.setBlock(world, i + 10, j + 38, k + 18, Blocks.stone, 0);
        this.setBlock(world, i + 10, j + 38, k + 19, Blocks.stone, 0);
        this.setBlock(world, i + 10, j + 38, k + 20, Blocks.stone, 0);
        this.setBlock(world, i + 10, j + 38, k + 21, Blocks.stone, 0);
        this.setBlock(world, i + 10, j + 38, k + 22, Blocks.bedrock, 0);
        this.setBlock(world, i + 10, j + 38, k + 23, Blocks.stone, 0);
        this.setBlock(world, i + 10, j + 38, k + 24, Blocks.stone, 0);
        this.setBlock(world, i + 10, j + 38, k + 25, Blocks.cobblestone, 0);
        this.setBlock(world, i + 10, j + 38, k + 26, Blocks.stone, 0);
        this.setBlock(world, i + 10, j + 38, k + 27, Blocks.bedrock, 0);
        this.setBlock(world, i + 10, j + 38, k + 28, Blocks.bedrock, 0);
        this.setBlock(world, i + 10, j + 38, k + 29, Blocks.stone, 0);
        this.setBlock(world, i + 10, j + 38, k + 30, Blocks.bedrock, 0);
        this.setBlock(world, i + 10, j + 38, k + 31, Blocks.stone, 0);
        this.setBlock(world, i + 10, j + 38, k + 32, Blocks.stone, 0);
        this.setBlock(world, i + 10, j + 38, k + 33, Blocks.cobblestone, 0);
        this.setBlock(world, i + 10, j + 39, k + 19, Blocks.stone, 0);
        this.setBlock(world, i + 10, j + 39, k + 20, Blocks.bedrock, 0);
        this.setBlock(world, i + 10, j + 39, k + 21, Blocks.cobblestone, 0);
        this.setBlock(world, i + 10, j + 39, k + 22, Blocks.stone, 0);
        this.setBlock(world, i + 10, j + 39, k + 23, Blocks.stone, 0);
        this.setBlock(world, i + 10, j + 39, k + 24, Blocks.stone, 0);
        this.setBlock(world, i + 10, j + 39, k + 25, Blocks.cobblestone, 0);
        this.setBlock(world, i + 10, j + 39, k + 26, Blocks.stone, 0);
        this.setBlock(world, i + 10, j + 39, k + 27, Blocks.stone, 0);
        this.setBlock(world, i + 10, j + 39, k + 28, Blocks.stone, 0);
        this.setBlock(world, i + 10, j + 39, k + 29, Blocks.bedrock, 0);
        this.setBlock(world, i + 10, j + 39, k + 30, Blocks.bedrock, 0);
        this.setBlock(world, i + 10, j + 40, k + 19, Blocks.stone, 0);
        this.setBlock(world, i + 10, j + 40, k + 20, Blocks.stone, 0);
        this.setBlock(world, i + 10, j + 40, k + 21, Blocks.bedrock, 0);
        this.setBlock(world, i + 10, j + 40, k + 22, Blocks.stone, 0);
        this.setBlock(world, i + 10, j + 40, k + 23, Blocks.stone, 0);
        this.setBlock(world, i + 10, j + 40, k + 24, Blocks.stone, 0);
        this.setBlock(world, i + 10, j + 40, k + 25, Blocks.stone, 0);
        this.setBlock(world, i + 10, j + 40, k + 26, Blocks.stone, 0);
        this.setBlock(world, i + 10, j + 40, k + 27, Blocks.cobblestone, 0);
        this.setBlock(world, i + 10, j + 40, k + 28, Blocks.stone, 0);
        this.setBlock(world, i + 10, j + 40, k + 29, Blocks.stone, 0);
        this.setBlock(world, i + 10, j + 40, k + 30, Blocks.stone, 0);
        this.setBlock(world, i + 10, j + 41, k + 19, Blocks.stone, 0);
        this.setBlock(world, i + 10, j + 41, k + 20, Blocks.stone, 0);
        this.setBlock(world, i + 10, j + 41, k + 21, Blocks.bedrock, 0);
        this.setBlock(world, i + 10, j + 41, k + 22, Blocks.stone, 0);
        this.setBlock(world, i + 10, j + 41, k + 23, Blocks.stone, 0);
        this.setBlock(world, i + 10, j + 41, k + 24, Blocks.stone, 0);
        this.setBlock(world, i + 10, j + 41, k + 25, Blocks.stone, 0);
        this.setBlock(world, i + 10, j + 41, k + 26, Blocks.bedrock, 0);
        this.setBlock(world, i + 10, j + 41, k + 27, Blocks.stone, 0);
        this.setBlock(world, i + 10, j + 41, k + 28, Blocks.stone, 0);
        this.setBlock(world, i + 10, j + 41, k + 29, Blocks.stone, 0);
        this.setBlock(world, i + 10, j + 41, k + 30, Blocks.stone, 0);
        this.setBlock(world, i + 10, j + 42, k + 21, Blocks.stone, 0);
        this.setBlock(world, i + 10, j + 42, k + 22, Blocks.stone, 0);
        this.setBlock(world, i + 10, j + 42, k + 23, Blocks.stone, 0);
        this.setBlock(world, i + 10, j + 42, k + 24, Blocks.stone, 0);
        this.setBlock(world, i + 10, j + 42, k + 25, Blocks.stone, 0);
        this.setBlock(world, i + 10, j + 42, k + 26, Blocks.stone, 0);
        this.setBlock(world, i + 10, j + 42, k + 27, Blocks.cobblestone, 0);
        this.setBlock(world, i + 10, j + 42, k + 28, Blocks.stone, 0);
        this.setBlock(world, i + 10, j + 43, k + 25, Blocks.stone, 0);
        this.setBlock(world, i + 10, j + 43, k + 26, Blocks.bedrock, 0);
        this.setBlock(world, i + 10, j + 43, k + 27, Blocks.bedrock, 0);
        this.setBlock(world, i + 11, j + 29, k + 21, Blocks.stone, 0);
        this.setBlock(world, i + 11, j + 29, k + 22, Blocks.stone, 0);
        this.setBlock(world, i + 11, j + 29, k + 23, Blocks.stone, 0);
        this.setBlock(world, i + 11, j + 29, k + 24, Blocks.stone, 0);
        this.setBlock(world, i + 11, j + 29, k + 25, Blocks.stone, 0);
        this.setBlock(world, i + 11, j + 30, k + 21, Blocks.stone, 0);
        this.setBlock(world, i + 11, j + 30, k + 22, Blocks.bedrock, 0);
        this.setBlock(world, i + 11, j + 30, k + 23, Blocks.bedrock, 0);
        this.setBlock(world, i + 11, j + 30, k + 24, Blocks.stone, 0);
        this.setBlock(world, i + 11, j + 30, k + 25, Blocks.stone, 0);
        this.setBlock(world, i + 11, j + 30, k + 26, Blocks.stone, 0);
        this.setBlock(world, i + 11, j + 31, k + 21, Blocks.bedrock, 0);
        this.setBlock(world, i + 11, j + 31, k + 22, Blocks.cobblestone, 0);
        this.setBlock(world, i + 11, j + 31, k + 23, Blocks.stone, 0);
        this.setBlock(world, i + 11, j + 31, k + 24, Blocks.cobblestone, 0);
        this.setBlock(world, i + 11, j + 31, k + 25, Blocks.stone, 0);
        this.setBlock(world, i + 11, j + 31, k + 26, Blocks.stone, 0);
        this.setBlock(world, i + 11, j + 31, k + 27, Blocks.cobblestone, 0);
        this.setBlock(world, i + 11, j + 31, k + 28, Blocks.bedrock, 0);
        this.setBlock(world, i + 11, j + 31, k + 29, Blocks.stone, 0);
        this.setBlock(world, i + 11, j + 31, k + 30, Blocks.cobblestone, 0);
        this.setBlock(world, i + 11, j + 31, k + 31, Blocks.stone, 0);
        this.setBlock(world, i + 11, j + 31, k + 32, Blocks.cobblestone, 0);
        this.setBlock(world, i + 11, j + 31, k + 33, Blocks.stone, 0);
        this.setBlock(world, i + 11, j + 31, k + 34, Blocks.stone, 0);
        this.setBlock(world, i + 11, j + 32, k + 18, Blocks.stone, 0);
        this.setBlock(world, i + 11, j + 32, k + 19, Blocks.stone, 0);
        this.setBlock(world, i + 11, j + 32, k + 20, Blocks.stone, 0);
        this.setBlock(world, i + 11, j + 32, k + 21, Blocks.stone, 0);
        this.setBlock(world, i + 11, j + 32, k + 22, Blocks.stone, 0);
        this.setBlock(world, i + 11, j + 32, k + 23, Blocks.bedrock, 0);
        this.setBlock(world, i + 11, j + 32, k + 24, Blocks.stone, 0);
        this.setBlock(world, i + 11, j + 32, k + 25, Blocks.stone, 0);
        this.setBlock(world, i + 11, j + 32, k + 26, Blocks.stone, 0);
        this.setBlock(world, i + 11, j + 32, k + 27, Blocks.cobblestone, 0);
        this.setBlock(world, i + 11, j + 32, k + 28, Blocks.stone, 0);
        this.setBlock(world, i + 11, j + 32, k + 29, Blocks.cobblestone, 0);
        this.setBlock(world, i + 11, j + 32, k + 30, Blocks.stone, 0);
        this.setBlock(world, i + 11, j + 32, k + 31, Blocks.bedrock, 0);
        this.setBlock(world, i + 11, j + 32, k + 32, Blocks.stone, 0);
        this.setBlock(world, i + 11, j + 32, k + 33, Blocks.stone, 0);
        this.setBlock(world, i + 11, j + 32, k + 34, Blocks.stone, 0);
        this.setBlock(world, i + 11, j + 33, k + 17, Blocks.stone, 0);
        this.setBlock(world, i + 11, j + 33, k + 18, Blocks.stone, 0);
        this.setBlock(world, i + 11, j + 33, k + 19, Blocks.stone, 0);
        this.setBlock(world, i + 11, j + 33, k + 20, Blocks.stone, 0);
        this.setBlock(world, i + 11, j + 33, k + 21, Blocks.stone, 0);
        this.setBlock(world, i + 11, j + 33, k + 22, Blocks.stone, 0);
        this.setBlock(world, i + 11, j + 33, k + 23, Blocks.stone, 0);
        this.setBlock(world, i + 11, j + 33, k + 24, Blocks.stone, 0);
        this.setBlock(world, i + 11, j + 33, k + 25, Blocks.stone, 0);
        this.setBlock(world, i + 11, j + 33, k + 26, Blocks.stone, 0);
        this.setBlock(world, i + 11, j + 33, k + 27, Blocks.stone, 0);
        this.setBlock(world, i + 11, j + 33, k + 28, Blocks.stone, 0);
        this.setBlock(world, i + 11, j + 33, k + 29, Blocks.stone, 0);
        this.setBlock(world, i + 11, j + 33, k + 30, Blocks.stone, 0);
        this.setBlock(world, i + 11, j + 33, k + 31, Blocks.stone, 0);
        this.setBlock(world, i + 11, j + 33, k + 32, Blocks.stone, 0);
        this.setBlock(world, i + 11, j + 33, k + 33, Blocks.stone, 0);
        this.setBlock(world, i + 11, j + 33, k + 34, Blocks.stone, 0);
        this.setBlock(world, i + 11, j + 33, k + 35, Blocks.stone, 0);
        this.setBlock(world, i + 11, j + 34, k + 17, Blocks.stone, 0);
        this.setBlock(world, i + 11, j + 34, k + 18, Blocks.stone, 0);
        this.setBlock(world, i + 11, j + 34, k + 19, Blocks.stone, 0);
        this.setBlock(world, i + 11, j + 34, k + 20, Blocks.stone, 0);
        this.setBlock(world, i + 11, j + 34, k + 21, Blocks.stone, 0);
        this.setBlock(world, i + 11, j + 34, k + 22, Blocks.stone, 0);
        this.setBlock(world, i + 11, j + 34, k + 23, Blocks.stone, 0);
        this.setBlock(world, i + 11, j + 34, k + 24, Blocks.stone, 0);
        this.setBlock(world, i + 11, j + 34, k + 25, Blocks.stone, 0);
        this.setBlock(world, i + 11, j + 34, k + 26, Blocks.stone, 0);
        this.setBlock(world, i + 11, j + 34, k + 27, Blocks.stone, 0);
        this.setBlock(world, i + 11, j + 34, k + 28, Blocks.stone, 0);
        this.setBlock(world, i + 11, j + 34, k + 29, Blocks.stone, 0);
        this.setBlock(world, i + 11, j + 34, k + 30, Blocks.stone, 0);
        this.setBlock(world, i + 11, j + 34, k + 31, Blocks.stone, 0);
        this.setBlock(world, i + 11, j + 34, k + 32, Blocks.stone, 0);
        this.setBlock(world, i + 11, j + 34, k + 33, Blocks.stone, 0);
        this.setBlock(world, i + 11, j + 34, k + 34, Blocks.stone, 0);
        this.setBlock(world, i + 11, j + 34, k + 35, Blocks.stone, 0);
        this.setBlock(world, i + 11, j + 34, k + 36, Blocks.stone, 0);
        this.setBlock(world, i + 11, j + 35, k + 13, Blocks.mycelium, 0);
        this.setBlock(world, i + 11, j + 35, k + 14, Blocks.dirt, 0);
        this.setBlock(world, i + 11, j + 35, k + 15, Blocks.dirt, 0);
        this.setBlock(world, i + 11, j + 35, k + 16, Blocks.dirt, 0);
        this.setBlock(world, i + 11, j + 35, k + 17, Blocks.dirt, 0);
        this.setBlock(world, i + 11, j + 35, k + 18, Blocks.dirt, 0);
        this.setBlock(world, i + 11, j + 35, k + 19, Blocks.dirt, 0);
        this.setBlock(world, i + 11, j + 35, k + 20, Blocks.dirt, 0);
        this.setBlock(world, i + 11, j + 35, k + 21, Blocks.dirt, 0);
        this.setBlock(world, i + 11, j + 35, k + 22, Blocks.dirt, 0);
        this.setBlock(world, i + 11, j + 35, k + 23, Blocks.dirt, 0);
        this.setBlock(world, i + 11, j + 35, k + 24, Blocks.dirt, 0);
        this.setBlock(world, i + 11, j + 35, k + 25, Blocks.dirt, 0);
        this.setBlock(world, i + 11, j + 35, k + 26, Blocks.dirt, 0);
        this.setBlock(world, i + 11, j + 35, k + 27, Blocks.dirt, 0);
        this.setBlock(world, i + 11, j + 35, k + 28, Blocks.dirt, 0);
        this.setBlock(world, i + 11, j + 35, k + 29, Blocks.dirt, 0);
        this.setBlock(world, i + 11, j + 35, k + 30, Blocks.dirt, 0);
        this.setBlock(world, i + 11, j + 35, k + 31, Blocks.dirt, 0);
        this.setBlock(world, i + 11, j + 35, k + 32, Blocks.dirt, 0);
        this.setBlock(world, i + 11, j + 35, k + 33, Blocks.dirt, 0);
        this.setBlock(world, i + 11, j + 35, k + 34, Blocks.dirt, 0);
        this.setBlock(world, i + 11, j + 35, k + 35, Blocks.dirt, 0);
        this.setBlock(world, i + 11, j + 35, k + 36, Blocks.dirt, 0);
        this.setBlock(world, i + 11, j + 35, k + 37, Blocks.dirt, 0);
        this.setBlock(world, i + 11, j + 35, k + 38, Blocks.mycelium, 0);
        this.setBlock(world, i + 11, j + 36, k + 14, Blocks.mycelium, 0);
        this.setBlock(world, i + 11, j + 36, k + 15, Blocks.dirt, 0);
        this.setBlock(world, i + 11, j + 36, k + 16, Blocks.stone, 0);
        this.setBlock(world, i + 11, j + 36, k + 17, Blocks.stone, 0);
        this.setBlock(world, i + 11, j + 36, k + 18, Blocks.bedrock, 0);
        this.setBlock(world, i + 11, j + 36, k + 19, Blocks.cobblestone, 0);
        this.setBlock(world, i + 11, j + 36, k + 20, Blocks.stone, 0);
        this.setBlock(world, i + 11, j + 36, k + 21, Blocks.cobblestone, 0);
        this.setBlock(world, i + 11, j + 36, k + 22, Blocks.stone, 0);
        this.setBlock(world, i + 11, j + 36, k + 23, Blocks.cobblestone, 0);
        this.setBlock(world, i + 11, j + 36, k + 24, Blocks.stone, 0);
        this.setBlock(world, i + 11, j + 36, k + 25, Blocks.cobblestone, 0);
        this.setBlock(world, i + 11, j + 36, k + 26, Blocks.stone, 0);
        this.setBlock(world, i + 11, j + 36, k + 27, Blocks.cobblestone, 0);
        this.setBlock(world, i + 11, j + 36, k + 28, Blocks.stone, 0);
        this.setBlock(world, i + 11, j + 36, k + 29, Blocks.stone, 0);
        this.setBlock(world, i + 11, j + 36, k + 30, Blocks.stone, 0);
        this.setBlock(world, i + 11, j + 36, k + 31, Blocks.stone, 0);
        this.setBlock(world, i + 11, j + 36, k + 32, Blocks.cobblestone, 0);
        this.setBlock(world, i + 11, j + 36, k + 33, Blocks.stone, 0);
        this.setBlock(world, i + 11, j + 36, k + 34, Blocks.stone, 0);
        this.setBlock(world, i + 11, j + 36, k + 35, Blocks.bedrock, 0);
        this.setBlock(world, i + 11, j + 36, k + 36, Blocks.stone, 0);
        this.setBlock(world, i + 11, j + 36, k + 37, Blocks.stone, 0);
        this.setBlock(world, i + 11, j + 37, k + 15, Blocks.stone, 0);
        this.setBlock(world, i + 11, j + 37, k + 16, Blocks.stone, 0);
        this.setBlock(world, i + 11, j + 37, k + 17, Blocks.cobblestone, 0);
        this.setBlock(world, i + 11, j + 37, k + 18, Blocks.stone, 0);
        this.setBlock(world, i + 11, j + 37, k + 19, Blocks.bedrock, 0);
        this.setBlock(world, i + 11, j + 37, k + 20, Blocks.stone, 0);
        this.setBlock(world, i + 11, j + 37, k + 21, Blocks.stone, 0);
        this.setBlock(world, i + 11, j + 37, k + 22, Blocks.stone, 0);
        this.setBlock(world, i + 11, j + 37, k + 23, Blocks.bedrock, 0);
        this.setBlock(world, i + 11, j + 37, k + 24, Blocks.stone, 0);
        this.setBlock(world, i + 11, j + 37, k + 25, Blocks.cobblestone, 0);
        this.setBlock(world, i + 11, j + 37, k + 26, Blocks.stone, 0);
        this.setBlock(world, i + 11, j + 37, k + 27, Blocks.stone, 0);
        this.setBlock(world, i + 11, j + 37, k + 28, Blocks.stone, 0);
        this.setBlock(world, i + 11, j + 37, k + 29, Blocks.cobblestone, 0);
        this.setBlock(world, i + 11, j + 37, k + 30, Blocks.stone, 0);
        this.setBlock(world, i + 11, j + 37, k + 31, Blocks.stone, 0);
        this.setBlock(world, i + 11, j + 37, k + 32, Blocks.bedrock, 0);
        this.setBlock(world, i + 11, j + 37, k + 33, Blocks.cobblestone, 0);
        this.setBlock(world, i + 11, j + 37, k + 34, Blocks.stone, 0);
        this.setBlock(world, i + 11, j + 37, k + 35, Blocks.stone, 0);
        this.setBlock(world, i + 11, j + 38, k + 17, Blocks.stone, 0);
        this.setBlock(world, i + 11, j + 38, k + 18, Blocks.stone, 0);
        this.setBlock(world, i + 11, j + 38, k + 19, Blocks.stone, 0);
        this.setBlock(world, i + 11, j + 38, k + 20, Blocks.stone, 0);
        this.setBlock(world, i + 11, j + 38, k + 21, Blocks.stone, 0);
        this.setBlock(world, i + 11, j + 38, k + 22, Blocks.stone, 0);
        this.setBlock(world, i + 11, j + 38, k + 23, Blocks.stone, 0);
        this.setBlock(world, i + 11, j + 38, k + 24, Blocks.stone, 0);
        this.setBlock(world, i + 11, j + 38, k + 25, Blocks.stone, 0);
        this.setBlock(world, i + 11, j + 38, k + 26, Blocks.stone, 0);
        this.setBlock(world, i + 11, j + 38, k + 27, Blocks.stone, 0);
        this.setBlock(world, i + 11, j + 38, k + 28, Blocks.stone, 0);
        this.setBlock(world, i + 11, j + 38, k + 29, Blocks.stone, 0);
        this.setBlock(world, i + 11, j + 38, k + 30, Blocks.bedrock, 0);
        this.setBlock(world, i + 11, j + 38, k + 31, Blocks.stone, 0);
        this.setBlock(world, i + 11, j + 38, k + 32, Blocks.stone, 0);
        this.setBlock(world, i + 11, j + 38, k + 33, Blocks.stone, 0);
        this.setBlock(world, i + 11, j + 39, k + 18, Blocks.stone, 0);
        this.setBlock(world, i + 11, j + 39, k + 19, Blocks.cobblestone, 0);
        this.setBlock(world, i + 11, j + 39, k + 20, Blocks.stone, 0);
        this.setBlock(world, i + 11, j + 39, k + 21, Blocks.stone, 0);
        this.setBlock(world, i + 11, j + 39, k + 22, Blocks.stone, 0);
        this.setBlock(world, i + 11, j + 39, k + 23, Blocks.stone, 0);
        this.setBlock(world, i + 11, j + 39, k + 24, Blocks.stone, 0);
        this.setBlock(world, i + 11, j + 39, k + 25, Blocks.stone, 0);
        this.setBlock(world, i + 11, j + 39, k + 26, Blocks.cobblestone, 0);
        this.setBlock(world, i + 11, j + 39, k + 27, Blocks.bedrock, 0);
        this.setBlock(world, i + 11, j + 39, k + 28, Blocks.stone, 0);
        this.setBlock(world, i + 11, j + 39, k + 29, Blocks.stone, 0);
        this.setBlock(world, i + 11, j + 39, k + 30, Blocks.stone, 0);
        this.setBlock(world, i + 11, j + 39, k + 31, Blocks.stone, 0);
        this.setBlock(world, i + 11, j + 39, k + 32, Blocks.stone, 0);
        this.setBlock(world, i + 11, j + 40, k + 19, Blocks.stone, 0);
        this.setBlock(world, i + 11, j + 40, k + 20, Blocks.stone, 0);
        this.setBlock(world, i + 11, j + 40, k + 21, Blocks.bedrock, 0);
        this.setBlock(world, i + 11, j + 40, k + 22, Blocks.cobblestone, 0);
        this.setBlock(world, i + 11, j + 40, k + 23, Blocks.stone, 0);
        this.setBlock(world, i + 11, j + 40, k + 24, Blocks.stone, 0);
        this.setBlock(world, i + 11, j + 40, k + 25, Blocks.stone, 0);
        this.setBlock(world, i + 11, j + 40, k + 26, Blocks.stone, 0);
        this.setBlock(world, i + 11, j + 40, k + 27, Blocks.stone, 0);
        this.setBlock(world, i + 11, j + 40, k + 28, Blocks.bedrock, 0);
        this.setBlock(world, i + 11, j + 40, k + 29, Blocks.stone, 0);
        this.setBlock(world, i + 11, j + 40, k + 30, Blocks.stone, 0);
        this.setBlock(world, i + 11, j + 40, k + 31, Blocks.stone, 0);
        this.setBlock(world, i + 11, j + 40, k + 32, Blocks.stone, 0);
        this.setBlock(world, i + 11, j + 41, k + 19, Blocks.cobblestone, 0);
        this.setBlock(world, i + 11, j + 41, k + 20, Blocks.stone, 0);
        this.setBlock(world, i + 11, j + 41, k + 21, Blocks.stone, 0);
        this.setBlock(world, i + 11, j + 41, k + 22, Blocks.cobblestone, 0);
        this.setBlock(world, i + 11, j + 41, k + 23, Blocks.bedrock, 0);
        this.setBlock(world, i + 11, j + 41, k + 24, Blocks.stone, 0);
        this.setBlock(world, i + 11, j + 41, k + 25, Blocks.stone, 0);
        this.setBlock(world, i + 11, j + 41, k + 26, Blocks.stone, 0);
        this.setBlock(world, i + 11, j + 41, k + 27, Blocks.stone, 0);
        this.setBlock(world, i + 11, j + 41, k + 28, Blocks.bedrock, 0);
        this.setBlock(world, i + 11, j + 41, k + 29, Blocks.cobblestone, 0);
        this.setBlock(world, i + 11, j + 41, k + 30, Blocks.stone, 0);
        this.setBlock(world, i + 11, j + 41, k + 31, Blocks.stone, 0);
        this.setBlock(world, i + 11, j + 42, k + 19, Blocks.bedrock, 0);
        this.setBlock(world, i + 11, j + 42, k + 20, Blocks.cobblestone, 0);
        this.setBlock(world, i + 11, j + 42, k + 21, Blocks.bedrock, 0);
        this.setBlock(world, i + 11, j + 42, k + 22, Blocks.stone, 0);
        this.setBlock(world, i + 11, j + 42, k + 23, Blocks.stone, 0);
        this.setBlock(world, i + 11, j + 42, k + 24, Blocks.bedrock, 0);
        this.setBlock(world, i + 11, j + 42, k + 25, Blocks.cobblestone, 0);
        this.setBlock(world, i + 11, j + 42, k + 26, Blocks.bedrock, 0);
        this.setBlock(world, i + 11, j + 42, k + 27, Blocks.stone, 0);
        this.setBlock(world, i + 11, j + 42, k + 28, Blocks.stone, 0);
        this.setBlock(world, i + 11, j + 42, k + 29, Blocks.stone, 0);
        this.setBlock(world, i + 11, j + 42, k + 30, Blocks.stone, 0);
        this.setBlock(world, i + 11, j + 43, k + 22, Blocks.stone, 0);
        this.setBlock(world, i + 11, j + 43, k + 23, Blocks.stone, 0);
        this.setBlock(world, i + 12, j + 28, k + 20, Blocks.stone, 0);
        this.setBlock(world, i + 12, j + 28, k + 21, Blocks.stone, 0);
        this.setBlock(world, i + 12, j + 28, k + 22, Blocks.stone, 0);
        this.setBlock(world, i + 12, j + 28, k + 23, Blocks.stone, 0);
        this.setBlock(world, i + 12, j + 28, k + 24, Blocks.stone, 0);
        this.setBlock(world, i + 12, j + 28, k + 25, Blocks.stone, 0);
        this.setBlock(world, i + 12, j + 29, k + 20, Blocks.stone, 0);
        this.setBlock(world, i + 12, j + 29, k + 21, Blocks.stone, 0);
        this.setBlock(world, i + 12, j + 29, k + 22, Blocks.stone, 0);
        this.setBlock(world, i + 12, j + 29, k + 23, Blocks.cobblestone, 0);
        this.setBlock(world, i + 12, j + 29, k + 24, Blocks.stone, 0);
        this.setBlock(world, i + 12, j + 29, k + 25, Blocks.stone, 0);
        this.setBlock(world, i + 12, j + 30, k + 20, Blocks.stone, 0);
        this.setBlock(world, i + 12, j + 30, k + 21, Blocks.stone, 0);
        this.setBlock(world, i + 12, j + 30, k + 22, Blocks.stone, 0);
        this.setBlock(world, i + 12, j + 30, k + 23, Blocks.cobblestone, 0);
        this.setBlock(world, i + 12, j + 30, k + 24, Blocks.cobblestone, 0);
        this.setBlock(world, i + 12, j + 30, k + 25, Blocks.cobblestone, 0);
        this.setBlock(world, i + 12, j + 30, k + 26, Blocks.stone, 0);
        this.setBlock(world, i + 12, j + 30, k + 27, Blocks.stone, 0);
        this.setBlock(world, i + 12, j + 30, k + 28, Blocks.stone, 0);
        this.setBlock(world, i + 12, j + 30, k + 29, Blocks.stone, 0);
        this.setBlock(world, i + 12, j + 30, k + 30, Blocks.stone, 0);
        this.setBlock(world, i + 12, j + 30, k + 31, Blocks.stone, 0);
        this.setBlock(world, i + 12, j + 30, k + 32, Blocks.stone, 0);
        this.setBlock(world, i + 12, j + 31, k + 20, Blocks.stone, 0);
        this.setBlock(world, i + 12, j + 31, k + 21, Blocks.stone, 0);
        this.setBlock(world, i + 12, j + 31, k + 22, Blocks.bedrock, 0);
        this.setBlock(world, i + 12, j + 31, k + 23, Blocks.stone, 0);
        this.setBlock(world, i + 12, j + 31, k + 24, Blocks.stone, 0);
        this.setBlock(world, i + 12, j + 31, k + 25, Blocks.cobblestone, 0);
        this.setBlock(world, i + 12, j + 31, k + 26, Blocks.stone, 0);
        this.setBlock(world, i + 12, j + 31, k + 27, Blocks.stone, 0);
        this.setBlock(world, i + 12, j + 31, k + 28, Blocks.stone, 0);
        this.setBlock(world, i + 12, j + 31, k + 29, Blocks.bedrock, 0);
        this.setBlock(world, i + 12, j + 31, k + 30, Blocks.stone, 0);
        this.setBlock(world, i + 12, j + 31, k + 31, Blocks.stone, 0);
        this.setBlock(world, i + 12, j + 31, k + 32, Blocks.stone, 0);
        this.setBlock(world, i + 12, j + 31, k + 33, Blocks.bedrock, 0);
        this.setBlock(world, i + 12, j + 31, k + 34, Blocks.stone, 0);
        this.setBlock(world, i + 12, j + 32, k + 20, Blocks.stone, 0);
        this.setBlock(world, i + 12, j + 32, k + 21, Blocks.stone, 0);
        this.setBlock(world, i + 12, j + 32, k + 22, Blocks.stone, 0);
        this.setBlock(world, i + 12, j + 32, k + 23, Blocks.stone, 0);
        this.setBlock(world, i + 12, j + 32, k + 24, Blocks.stone, 0);
        this.setBlock(world, i + 12, j + 32, k + 25, Blocks.stone, 0);
        this.setBlock(world, i + 12, j + 32, k + 26, Blocks.stone, 0);
        this.setBlock(world, i + 12, j + 32, k + 27, Blocks.stone, 0);
        this.setBlock(world, i + 12, j + 32, k + 28, Blocks.stone, 0);
        this.setBlock(world, i + 12, j + 32, k + 29, Blocks.stone, 0);
        this.setBlock(world, i + 12, j + 32, k + 30, Blocks.stone, 0);
        this.setBlock(world, i + 12, j + 32, k + 31, Blocks.cobblestone, 0);
        this.setBlock(world, i + 12, j + 32, k + 32, Blocks.cobblestone, 0);
        this.setBlock(world, i + 12, j + 32, k + 33, Blocks.stone, 0);
        this.setBlock(world, i + 12, j + 32, k + 34, Blocks.bedrock, 0);
        this.setBlock(world, i + 12, j + 32, k + 35, Blocks.bedrock, 0);
        this.setBlock(world, i + 12, j + 33, k + 16, Blocks.stone, 0);
        this.setBlock(world, i + 12, j + 33, k + 17, Blocks.stone, 0);
        this.setBlock(world, i + 12, j + 33, k + 18, Blocks.stone, 0);
        this.setBlock(world, i + 12, j + 33, k + 19, Blocks.stone, 0);
        this.setBlock(world, i + 12, j + 33, k + 20, Blocks.stone, 0);
        this.setBlock(world, i + 12, j + 33, k + 21, Blocks.stone, 0);
        this.setBlock(world, i + 12, j + 33, k + 22, Blocks.stone, 0);
        this.setBlock(world, i + 12, j + 33, k + 23, Blocks.stone, 0);
        this.setBlock(world, i + 12, j + 33, k + 24, Blocks.stone, 0);
        this.setBlock(world, i + 12, j + 33, k + 25, Blocks.stone, 0);
        this.setBlock(world, i + 12, j + 33, k + 26, Blocks.stone, 0);
        this.setBlock(world, i + 12, j + 33, k + 27, Blocks.stone, 0);
        this.setBlock(world, i + 12, j + 33, k + 28, Blocks.stone, 0);
        this.setBlock(world, i + 12, j + 33, k + 29, Blocks.stone, 0);
        this.setBlock(world, i + 12, j + 33, k + 30, Blocks.stone, 0);
        this.setBlock(world, i + 12, j + 33, k + 31, Blocks.stone, 0);
        this.setBlock(world, i + 12, j + 33, k + 32, Blocks.stone, 0);
        this.setBlock(world, i + 12, j + 33, k + 33, Blocks.stone, 0);
        this.setBlock(world, i + 12, j + 33, k + 34, Blocks.stone, 0);
        this.setBlock(world, i + 12, j + 33, k + 35, Blocks.stone, 0);
        this.setBlock(world, i + 12, j + 33, k + 36, Blocks.stone, 0);
        this.setBlock(world, i + 12, j + 34, k + 15, Blocks.stone, 0);
        this.setBlock(world, i + 12, j + 34, k + 16, Blocks.stone, 0);
        this.setBlock(world, i + 12, j + 34, k + 17, Blocks.stone, 0);
        this.setBlock(world, i + 12, j + 34, k + 18, Blocks.stone, 0);
        this.setBlock(world, i + 12, j + 34, k + 19, Blocks.stone, 0);
        this.setBlock(world, i + 12, j + 34, k + 20, Blocks.stone, 0);
        this.setBlock(world, i + 12, j + 34, k + 21, Blocks.stone, 0);
        this.setBlock(world, i + 12, j + 34, k + 22, Blocks.stone, 0);
        this.setBlock(world, i + 12, j + 34, k + 23, Blocks.stone, 0);
        this.setBlock(world, i + 12, j + 34, k + 24, Blocks.stone, 0);
        this.setBlock(world, i + 12, j + 34, k + 25, Blocks.stone, 0);
        this.setBlock(world, i + 12, j + 34, k + 26, Blocks.stone, 0);
        this.setBlock(world, i + 12, j + 34, k + 27, Blocks.stone, 0);
        this.setBlock(world, i + 12, j + 34, k + 28, Blocks.stone, 0);
        this.setBlock(world, i + 12, j + 34, k + 29, Blocks.stone, 0);
        this.setBlock(world, i + 12, j + 34, k + 30, Blocks.stone, 0);
        this.setBlock(world, i + 12, j + 34, k + 31, Blocks.stone, 0);
        this.setBlock(world, i + 12, j + 34, k + 32, Blocks.stone, 0);
        this.setBlock(world, i + 12, j + 34, k + 33, Blocks.stone, 0);
        this.setBlock(world, i + 12, j + 34, k + 34, Blocks.stone, 0);
        this.setBlock(world, i + 12, j + 34, k + 35, Blocks.stone, 0);
        this.setBlock(world, i + 12, j + 34, k + 36, Blocks.stone, 0);
        this.setBlock(world, i + 12, j + 34, k + 37, Blocks.cobblestone, 0);
        this.setBlock(world, i + 12, j + 35, k + 13, Blocks.dirt, 0);
        this.setBlock(world, i + 12, j + 35, k + 14, Blocks.dirt, 0);
        this.setBlock(world, i + 12, j + 35, k + 15, Blocks.dirt, 0);
        this.setBlock(world, i + 12, j + 35, k + 16, Blocks.dirt, 0);
        this.setBlock(world, i + 12, j + 35, k + 17, Blocks.dirt, 0);
        this.setBlock(world, i + 12, j + 35, k + 18, Blocks.dirt, 0);
        this.setBlock(world, i + 12, j + 35, k + 19, Blocks.dirt, 0);
        this.setBlock(world, i + 12, j + 35, k + 20, Blocks.dirt, 0);
        this.setBlock(world, i + 12, j + 35, k + 21, Blocks.dirt, 0);
        this.setBlock(world, i + 12, j + 35, k + 22, Blocks.dirt, 0);
        this.setBlock(world, i + 12, j + 35, k + 23, Blocks.dirt, 0);
        this.setBlock(world, i + 12, j + 35, k + 24, Blocks.dirt, 0);
        this.setBlock(world, i + 12, j + 35, k + 25, Blocks.dirt, 0);
        this.setBlock(world, i + 12, j + 35, k + 26, Blocks.dirt, 0);
        this.setBlock(world, i + 12, j + 35, k + 27, Blocks.dirt, 0);
        this.setBlock(world, i + 12, j + 35, k + 28, Blocks.dirt, 0);
        this.setBlock(world, i + 12, j + 35, k + 29, Blocks.dirt, 0);
        this.setBlock(world, i + 12, j + 35, k + 30, Blocks.dirt, 0);
        this.setBlock(world, i + 12, j + 35, k + 31, Blocks.dirt, 0);
        this.setBlock(world, i + 12, j + 35, k + 32, Blocks.dirt, 0);
        this.setBlock(world, i + 12, j + 35, k + 33, Blocks.dirt, 0);
        this.setBlock(world, i + 12, j + 35, k + 34, Blocks.dirt, 0);
        this.setBlock(world, i + 12, j + 35, k + 35, Blocks.dirt, 0);
        this.setBlock(world, i + 12, j + 35, k + 36, Blocks.dirt, 0);
        this.setBlock(world, i + 12, j + 35, k + 37, Blocks.dirt, 0);
        this.setBlock(world, i + 12, j + 35, k + 38, Blocks.dirt, 0);
        this.setBlock(world, i + 12, j + 35, k + 39, Blocks.dirt, 0);
        this.setBlock(world, i + 12, j + 35, k + 40, Blocks.dirt, 0);
        this.setBlock(world, i + 12, j + 36, k + 13, Blocks.bedrock, 0);
        this.setBlock(world, i + 12, j + 36, k + 14, Blocks.stone, 0);
        this.setBlock(world, i + 12, j + 36, k + 15, Blocks.cobblestone, 0);
        this.setBlock(world, i + 12, j + 36, k + 16, Blocks.stone, 0);
        this.setBlock(world, i + 12, j + 36, k + 17, Blocks.stone, 0);
        this.setBlock(world, i + 12, j + 36, k + 18, Blocks.bedrock, 0);
        this.setBlock(world, i + 12, j + 36, k + 19, Blocks.stone, 0);
        this.setBlock(world, i + 12, j + 36, k + 20, Blocks.stone, 0);
        this.setBlock(world, i + 12, j + 36, k + 21, Blocks.cobblestone, 0);
        this.setBlock(world, i + 12, j + 36, k + 22, Blocks.stone, 0);
        this.setBlock(world, i + 12, j + 36, k + 23, Blocks.stone, 0);
        this.setBlock(world, i + 12, j + 36, k + 24, Blocks.stone, 0);
        this.setBlock(world, i + 12, j + 36, k + 25, Blocks.stone, 0);
        this.setBlock(world, i + 12, j + 36, k + 26, Blocks.cobblestone, 0);
        this.setBlock(world, i + 12, j + 36, k + 27, Blocks.stone, 0);
        this.setBlock(world, i + 12, j + 36, k + 28, Blocks.bedrock, 0);
        this.setBlock(world, i + 12, j + 36, k + 29, Blocks.stone, 0);
        this.setBlock(world, i + 12, j + 36, k + 30, Blocks.cobblestone, 0);
        this.setBlock(world, i + 12, j + 36, k + 31, Blocks.stone, 0);
        this.setBlock(world, i + 12, j + 36, k + 32, Blocks.stone, 0);
        this.setBlock(world, i + 12, j + 36, k + 33, Blocks.stone, 0);
        this.setBlock(world, i + 12, j + 36, k + 34, Blocks.stone, 0);
        this.setBlock(world, i + 12, j + 36, k + 35, Blocks.cobblestone, 0);
        this.setBlock(world, i + 12, j + 36, k + 36, Blocks.stone, 0);
        this.setBlock(world, i + 12, j + 36, k + 37, Blocks.stone, 0);
        this.setBlock(world, i + 12, j + 36, k + 38, Blocks.stone, 0);
        this.setBlock(world, i + 12, j + 36, k + 39, Blocks.cobblestone, 0);
        this.setBlock(world, i + 12, j + 36, k + 40, Blocks.cobblestone, 0);
        this.setBlock(world, i + 12, j + 37, k + 14, Blocks.stone, 0);
        this.setBlock(world, i + 12, j + 37, k + 15, Blocks.stone, 0);
        this.setBlock(world, i + 12, j + 37, k + 16, Blocks.stone, 0);
        this.setBlock(world, i + 12, j + 37, k + 17, Blocks.stone, 0);
        this.setBlock(world, i + 12, j + 37, k + 18, Blocks.stone, 0);
        this.setBlock(world, i + 12, j + 37, k + 19, Blocks.stone, 0);
        this.setBlock(world, i + 12, j + 37, k + 20, Blocks.stone, 0);
        this.setBlock(world, i + 12, j + 37, k + 21, Blocks.stone, 0);
        this.setBlock(world, i + 12, j + 37, k + 22, Blocks.stone, 0);
        this.setBlock(world, i + 12, j + 37, k + 23, Blocks.stone, 0);
        this.setBlock(world, i + 12, j + 37, k + 24, Blocks.stone, 0);
        this.setBlock(world, i + 12, j + 37, k + 25, Blocks.stone, 0);
        this.setBlock(world, i + 12, j + 37, k + 26, Blocks.stone, 0);
        this.setBlock(world, i + 12, j + 37, k + 27, Blocks.stone, 0);
        this.setBlock(world, i + 12, j + 37, k + 28, Blocks.cobblestone, 0);
        this.setBlock(world, i + 12, j + 37, k + 29, Blocks.stone, 0);
        this.setBlock(world, i + 12, j + 37, k + 30, Blocks.cobblestone, 0);
        this.setBlock(world, i + 12, j + 37, k + 31, Blocks.cobblestone, 0);
        this.setBlock(world, i + 12, j + 37, k + 32, Blocks.stone, 0);
        this.setBlock(world, i + 12, j + 37, k + 33, Blocks.cobblestone, 0);
        this.setBlock(world, i + 12, j + 37, k + 34, Blocks.stone, 0);
        this.setBlock(world, i + 12, j + 37, k + 35, Blocks.cobblestone, 0);
        this.setBlock(world, i + 12, j + 38, k + 16, Blocks.stone, 0);
        this.setBlock(world, i + 12, j + 38, k + 17, Blocks.stone, 0);
        this.setBlock(world, i + 12, j + 38, k + 18, Blocks.stone, 0);
        this.setBlock(world, i + 12, j + 38, k + 19, Blocks.cobblestone, 0);
        this.setBlock(world, i + 12, j + 38, k + 20, Blocks.stone, 0);
        this.setBlock(world, i + 12, j + 38, k + 21, Blocks.stone, 0);
        this.setBlock(world, i + 12, j + 38, k + 22, Blocks.stone, 0);
        this.setBlock(world, i + 12, j + 38, k + 23, Blocks.stone, 0);
        this.setBlock(world, i + 12, j + 38, k + 24, Blocks.cobblestone, 0);
        this.setBlock(world, i + 12, j + 38, k + 25, Blocks.stone, 0);
        this.setBlock(world, i + 12, j + 38, k + 26, Blocks.stone, 0);
        this.setBlock(world, i + 12, j + 38, k + 27, Blocks.stone, 0);
        this.setBlock(world, i + 12, j + 38, k + 28, Blocks.stone, 0);
        this.setBlock(world, i + 12, j + 38, k + 29, Blocks.stone, 0);
        this.setBlock(world, i + 12, j + 38, k + 30, Blocks.stone, 0);
        this.setBlock(world, i + 12, j + 38, k + 31, Blocks.stone, 0);
        this.setBlock(world, i + 12, j + 38, k + 32, Blocks.stone, 0);
        this.setBlock(world, i + 12, j + 38, k + 33, Blocks.bedrock, 0);
        this.setBlock(world, i + 12, j + 38, k + 34, Blocks.stone, 0);
        this.setBlock(world, i + 12, j + 39, k + 18, Blocks.stone, 0);
        this.setBlock(world, i + 12, j + 39, k + 19, Blocks.cobblestone, 0);
        this.setBlock(world, i + 12, j + 39, k + 20, Blocks.stone, 0);
        this.setBlock(world, i + 12, j + 39, k + 21, Blocks.stone, 0);
        this.setBlock(world, i + 12, j + 39, k + 22, Blocks.stone, 0);
        this.setBlock(world, i + 12, j + 39, k + 23, Blocks.stone, 0);
        this.setBlock(world, i + 12, j + 39, k + 24, Blocks.bedrock, 0);
        this.setBlock(world, i + 12, j + 39, k + 25, Blocks.bedrock, 0);
        this.setBlock(world, i + 12, j + 39, k + 26, Blocks.stone, 0);
        this.setBlock(world, i + 12, j + 39, k + 27, Blocks.stone, 0);
        this.setBlock(world, i + 12, j + 39, k + 28, Blocks.stone, 0);
        this.setBlock(world, i + 12, j + 39, k + 29, Blocks.stone, 0);
        this.setBlock(world, i + 12, j + 39, k + 30, Blocks.cobblestone, 0);
        this.setBlock(world, i + 12, j + 39, k + 31, Blocks.stone, 0);
        this.setBlock(world, i + 12, j + 39, k + 32, Blocks.stone, 0);
        this.setBlock(world, i + 12, j + 39, k + 33, Blocks.stone, 0);
        this.setBlock(world, i + 12, j + 40, k + 18, Blocks.stone, 0);
        this.setBlock(world, i + 12, j + 40, k + 19, Blocks.stone, 0);
        this.setBlock(world, i + 12, j + 40, k + 20, Blocks.stone, 0);
        this.setBlock(world, i + 12, j + 40, k + 21, Blocks.stone, 0);
        this.setBlock(world, i + 12, j + 40, k + 22, Blocks.stone, 0);
        this.setBlock(world, i + 12, j + 40, k + 23, Blocks.stone, 0);
        this.setBlock(world, i + 12, j + 40, k + 24, Blocks.stone, 0);
        this.setBlock(world, i + 12, j + 40, k + 25, Blocks.stone, 0);
        this.setBlock(world, i + 12, j + 40, k + 26, Blocks.stone, 0);
        this.setBlock(world, i + 12, j + 40, k + 27, Blocks.stone, 0);
        this.setBlock(world, i + 12, j + 40, k + 28, Blocks.stone, 0);
        this.setBlock(world, i + 12, j + 40, k + 29, Blocks.stone, 0);
        this.setBlock(world, i + 12, j + 40, k + 30, Blocks.stone, 0);
        this.setBlock(world, i + 12, j + 40, k + 31, Blocks.bedrock, 0);
        this.setBlock(world, i + 12, j + 40, k + 32, Blocks.stone, 0);
        this.setBlock(world, i + 12, j + 41, k + 19, Blocks.stone, 0);
        this.setBlock(world, i + 12, j + 41, k + 20, Blocks.stone, 0);
        this.setBlock(world, i + 12, j + 41, k + 21, Blocks.cobblestone, 0);
        this.setBlock(world, i + 12, j + 41, k + 22, Blocks.stone, 0);
        this.setBlock(world, i + 12, j + 41, k + 23, Blocks.stone, 0);
        this.setBlock(world, i + 12, j + 41, k + 24, Blocks.stone, 0);
        this.setBlock(world, i + 12, j + 41, k + 25, Blocks.stone, 0);
        this.setBlock(world, i + 12, j + 41, k + 26, Blocks.stone, 0);
        this.setBlock(world, i + 12, j + 41, k + 27, Blocks.stone, 0);
        this.setBlock(world, i + 12, j + 41, k + 28, Blocks.stone, 0);
        this.setBlock(world, i + 12, j + 41, k + 29, Blocks.stone, 0);
        this.setBlock(world, i + 12, j + 41, k + 30, Blocks.cobblestone, 0);
        this.setBlock(world, i + 12, j + 41, k + 31, Blocks.bedrock, 0);
        this.setBlock(world, i + 12, j + 42, k + 19, Blocks.stone, 0);
        this.setBlock(world, i + 12, j + 42, k + 20, Blocks.stone, 0);
        this.setBlock(world, i + 12, j + 42, k + 21, Blocks.stone, 0);
        this.setBlock(world, i + 12, j + 42, k + 29, Blocks.stone, 0);
        this.setBlock(world, i + 12, j + 42, k + 30, Blocks.stone, 0);
        this.setBlock(world, i + 13, j + 26, k + 22, Blocks.stone, 0);
        this.setBlock(world, i + 13, j + 26, k + 23, Blocks.stone, 0);
        this.setBlock(world, i + 13, j + 26, k + 24, Blocks.stone, 0);
        this.setBlock(world, i + 13, j + 26, k + 25, Blocks.stone, 0);
        this.setBlock(world, i + 13, j + 26, k + 26, Blocks.stone, 0);
        this.setBlock(world, i + 13, j + 27, k + 21, Blocks.stone, 0);
        this.setBlock(world, i + 13, j + 27, k + 22, Blocks.stone, 0);
        this.setBlock(world, i + 13, j + 27, k + 23, Blocks.stone, 0);
        this.setBlock(world, i + 13, j + 27, k + 24, Blocks.bedrock, 0);
        this.setBlock(world, i + 13, j + 27, k + 25, Blocks.bedrock, 0);
        this.setBlock(world, i + 13, j + 27, k + 26, Blocks.stone, 0);
        this.setBlock(world, i + 13, j + 28, k + 20, Blocks.stone, 0);
        this.setBlock(world, i + 13, j + 28, k + 21, Blocks.stone, 0);
        this.setBlock(world, i + 13, j + 28, k + 22, Blocks.stone, 0);
        this.setBlock(world, i + 13, j + 28, k + 23, Blocks.cobblestone, 0);
        this.setBlock(world, i + 13, j + 28, k + 24, Blocks.stone, 0);
        this.setBlock(world, i + 13, j + 28, k + 25, Blocks.stone, 0);
        this.setBlock(world, i + 13, j + 28, k + 26, Blocks.stone, 0);
        this.setBlock(world, i + 13, j + 29, k + 20, Blocks.stone, 0);
        this.setBlock(world, i + 13, j + 29, k + 21, Blocks.bedrock, 0);
        this.setBlock(world, i + 13, j + 29, k + 22, Blocks.stone, 0);
        this.setBlock(world, i + 13, j + 29, k + 23, Blocks.stone, 0);
        this.setBlock(world, i + 13, j + 29, k + 24, Blocks.stone, 0);
        this.setBlock(world, i + 13, j + 29, k + 25, Blocks.stone, 0);
        this.setBlock(world, i + 13, j + 29, k + 26, Blocks.stone, 0);
        this.setBlock(world, i + 13, j + 29, k + 27, Blocks.stone, 0);
        this.setBlock(world, i + 13, j + 29, k + 28, Blocks.stone, 0);
        this.setBlock(world, i + 13, j + 29, k + 29, Blocks.stone, 0);
        this.setBlock(world, i + 13, j + 29, k + 30, Blocks.cobblestone, 0);
        this.setBlock(world, i + 13, j + 29, k + 31, Blocks.stone, 0);
        this.setBlock(world, i + 13, j + 30, k + 19, Blocks.stone, 0);
        this.setBlock(world, i + 13, j + 30, k + 20, Blocks.stone, 0);
        this.setBlock(world, i + 13, j + 30, k + 21, Blocks.stone, 0);
        this.setBlock(world, i + 13, j + 30, k + 22, Blocks.stone, 0);
        this.setBlock(world, i + 13, j + 30, k + 23, Blocks.stone, 0);
        this.setBlock(world, i + 13, j + 30, k + 24, Blocks.stone, 0);
        this.setBlock(world, i + 13, j + 30, k + 25, Blocks.stone, 0);
        this.setBlock(world, i + 13, j + 30, k + 26, Blocks.stone, 0);
        this.setBlock(world, i + 13, j + 30, k + 27, Blocks.bedrock, 0);
        this.setBlock(world, i + 13, j + 30, k + 28, Blocks.stone, 0);
        this.setBlock(world, i + 13, j + 30, k + 29, Blocks.stone, 0);
        this.setBlock(world, i + 13, j + 30, k + 30, Blocks.bedrock, 0);
        this.setBlock(world, i + 13, j + 30, k + 31, Blocks.stone, 0);
        this.setBlock(world, i + 13, j + 30, k + 32, Blocks.stone, 0);
        this.setBlock(world, i + 13, j + 31, k + 18, Blocks.stone, 0);
        this.setBlock(world, i + 13, j + 31, k + 19, Blocks.stone, 0);
        this.setBlock(world, i + 13, j + 31, k + 20, Blocks.stone, 0);
        this.setBlock(world, i + 13, j + 31, k + 21, Blocks.stone, 0);
        this.setBlock(world, i + 13, j + 31, k + 22, Blocks.stone, 0);
        this.setBlock(world, i + 13, j + 31, k + 23, Blocks.bedrock, 0);
        this.setBlock(world, i + 13, j + 31, k + 24, Blocks.stone, 0);
        this.setBlock(world, i + 13, j + 31, k + 25, Blocks.stone, 0);
        this.setBlock(world, i + 13, j + 31, k + 26, Blocks.bedrock, 0);
        this.setBlock(world, i + 13, j + 31, k + 27, Blocks.stone, 0);
        this.setBlock(world, i + 13, j + 31, k + 28, Blocks.bedrock, 0);
        this.setBlock(world, i + 13, j + 31, k + 29, Blocks.stone, 0);
        this.setBlock(world, i + 13, j + 31, k + 30, Blocks.stone, 0);
        this.setBlock(world, i + 13, j + 31, k + 31, Blocks.cobblestone, 0);
        this.setBlock(world, i + 13, j + 31, k + 32, Blocks.stone, 0);
        this.setBlock(world, i + 13, j + 31, k + 33, Blocks.cobblestone, 0);
        this.setBlock(world, i + 13, j + 31, k + 34, Blocks.stone, 0);
        this.setBlock(world, i + 13, j + 32, k + 17, Blocks.stone, 0);
        this.setBlock(world, i + 13, j + 32, k + 18, Blocks.stone, 0);
        this.setBlock(world, i + 13, j + 32, k + 19, Blocks.stone, 0);
        this.setBlock(world, i + 13, j + 32, k + 20, Blocks.stone, 0);
        this.setBlock(world, i + 13, j + 32, k + 21, Blocks.stone, 0);
        this.setBlock(world, i + 13, j + 32, k + 22, Blocks.stone, 0);
        this.setBlock(world, i + 13, j + 32, k + 23, Blocks.stone, 0);
        this.setBlock(world, i + 13, j + 32, k + 24, Blocks.stone, 0);
        this.setBlock(world, i + 13, j + 32, k + 25, Blocks.cobblestone, 0);
        this.setBlock(world, i + 13, j + 32, k + 26, Blocks.cobblestone, 0);
        this.setBlock(world, i + 13, j + 32, k + 27, Blocks.stone, 0);
        this.setBlock(world, i + 13, j + 32, k + 28, Blocks.stone, 0);
        this.setBlock(world, i + 13, j + 32, k + 29, Blocks.stone, 0);
        this.setBlock(world, i + 13, j + 32, k + 30, Blocks.stone, 0);
        this.setBlock(world, i + 13, j + 32, k + 31, Blocks.stone, 0);
        this.setBlock(world, i + 13, j + 32, k + 32, Blocks.stone, 0);
        this.setBlock(world, i + 13, j + 32, k + 33, Blocks.stone, 0);
        this.setBlock(world, i + 13, j + 32, k + 34, Blocks.stone, 0);
        this.setBlock(world, i + 13, j + 32, k + 35, Blocks.stone, 0);
        this.setBlock(world, i + 13, j + 33, k + 14, Blocks.stone, 0);
        this.setBlock(world, i + 13, j + 33, k + 15, Blocks.stone, 0);
        this.setBlock(world, i + 13, j + 33, k + 16, Blocks.stone, 0);
        this.setBlock(world, i + 13, j + 33, k + 17, Blocks.stone, 0);
        this.setBlock(world, i + 13, j + 33, k + 18, Blocks.stone, 0);
        this.setBlock(world, i + 13, j + 33, k + 19, Blocks.stone, 0);
        this.setBlock(world, i + 13, j + 33, k + 20, Blocks.stone, 0);
        this.setBlock(world, i + 13, j + 33, k + 21, Blocks.stone, 0);
        this.setBlock(world, i + 13, j + 33, k + 22, Blocks.stone, 0);
        this.setBlock(world, i + 13, j + 33, k + 23, Blocks.stone, 0);
        this.setBlock(world, i + 13, j + 33, k + 24, Blocks.stone, 0);
        this.setBlock(world, i + 13, j + 33, k + 25, Blocks.stone, 0);
        this.setBlock(world, i + 13, j + 33, k + 26, Blocks.stone, 0);
        this.setBlock(world, i + 13, j + 33, k + 27, Blocks.stone, 0);
        this.setBlock(world, i + 13, j + 33, k + 28, Blocks.stone, 0);
        this.setBlock(world, i + 13, j + 33, k + 29, Blocks.stone, 0);
        this.setBlock(world, i + 13, j + 33, k + 30, Blocks.stone, 0);
        this.setBlock(world, i + 13, j + 33, k + 31, Blocks.stone, 0);
        this.setBlock(world, i + 13, j + 33, k + 32, Blocks.stone, 0);
        this.setBlock(world, i + 13, j + 33, k + 33, Blocks.stone, 0);
        this.setBlock(world, i + 13, j + 33, k + 34, Blocks.stone, 0);
        this.setBlock(world, i + 13, j + 33, k + 35, Blocks.stone, 0);
        this.setBlock(world, i + 13, j + 33, k + 36, Blocks.stone, 0);
        this.setBlock(world, i + 13, j + 34, k + 14, Blocks.stone, 0);
        this.setBlock(world, i + 13, j + 34, k + 15, Blocks.stone, 0);
        this.setBlock(world, i + 13, j + 34, k + 16, Blocks.stone, 0);
        this.setBlock(world, i + 13, j + 34, k + 17, Blocks.stone, 0);
        this.setBlock(world, i + 13, j + 34, k + 18, Blocks.stone, 0);
        this.setBlock(world, i + 13, j + 34, k + 19, Blocks.stone, 0);
        this.setBlock(world, i + 13, j + 34, k + 20, Blocks.stone, 0);
        this.setBlock(world, i + 13, j + 34, k + 21, Blocks.stone, 0);
        this.setBlock(world, i + 13, j + 34, k + 22, Blocks.stone, 0);
        this.setBlock(world, i + 13, j + 34, k + 23, Blocks.stone, 0);
        this.setBlock(world, i + 13, j + 34, k + 24, Blocks.stone, 0);
        this.setBlock(world, i + 13, j + 34, k + 25, Blocks.stone, 0);
        this.setBlock(world, i + 13, j + 34, k + 26, Blocks.stone, 0);
        this.setBlock(world, i + 13, j + 34, k + 27, Blocks.stone, 0);
        this.setBlock(world, i + 13, j + 34, k + 28, Blocks.stone, 0);
        this.setBlock(world, i + 13, j + 34, k + 29, Blocks.stone, 0);
        this.setBlock(world, i + 13, j + 34, k + 30, Blocks.stone, 0);
        this.setBlock(world, i + 13, j + 34, k + 31, Blocks.stone, 0);
        this.setBlock(world, i + 13, j + 34, k + 32, Blocks.stone, 0);
        this.setBlock(world, i + 13, j + 34, k + 33, Blocks.stone, 0);
        this.setBlock(world, i + 13, j + 34, k + 34, Blocks.stone, 0);
        this.setBlock(world, i + 13, j + 34, k + 35, Blocks.stone, 0);
        this.setBlock(world, i + 13, j + 34, k + 36, Blocks.stone, 0);
        this.setBlock(world, i + 13, j + 34, k + 37, Blocks.stone, 0);
        this.setBlock(world, i + 13, j + 34, k + 38, Blocks.stone, 0);
        this.setBlock(world, i + 13, j + 34, k + 39, Blocks.stone, 0);
        this.setBlock(world, i + 13, j + 34, k + 40, Blocks.stone, 0);
        this.setBlock(world, i + 13, j + 35, k + 12, Blocks.mycelium, 0);
        this.setBlock(world, i + 13, j + 35, k + 13, Blocks.dirt, 0);
        this.setBlock(world, i + 13, j + 35, k + 14, Blocks.dirt, 0);
        this.setBlock(world, i + 13, j + 35, k + 15, Blocks.dirt, 0);
        this.setBlock(world, i + 13, j + 35, k + 16, Blocks.dirt, 0);
        this.setBlock(world, i + 13, j + 35, k + 17, Blocks.dirt, 0);
        this.setBlock(world, i + 13, j + 35, k + 18, Blocks.dirt, 0);
        this.setBlock(world, i + 13, j + 35, k + 19, Blocks.dirt, 0);
        this.setBlock(world, i + 13, j + 35, k + 20, Blocks.dirt, 0);
        this.setBlock(world, i + 13, j + 35, k + 21, Blocks.dirt, 0);
        this.setBlock(world, i + 13, j + 35, k + 22, Blocks.dirt, 0);
        this.setBlock(world, i + 13, j + 35, k + 23, Blocks.dirt, 0);
        this.setBlock(world, i + 13, j + 35, k + 24, Blocks.dirt, 0);
        this.setBlock(world, i + 13, j + 35, k + 25, Blocks.dirt, 0);
        this.setBlock(world, i + 13, j + 35, k + 26, Blocks.dirt, 0);
        this.setBlock(world, i + 13, j + 35, k + 27, Blocks.dirt, 0);
        this.setBlock(world, i + 13, j + 35, k + 28, Blocks.dirt, 0);
        this.setBlock(world, i + 13, j + 35, k + 29, Blocks.dirt, 0);
        this.setBlock(world, i + 13, j + 35, k + 30, Blocks.dirt, 0);
        this.setBlock(world, i + 13, j + 35, k + 31, Blocks.dirt, 0);
        this.setBlock(world, i + 13, j + 35, k + 32, Blocks.dirt, 0);
        this.setBlock(world, i + 13, j + 35, k + 33, Blocks.dirt, 0);
        this.setBlock(world, i + 13, j + 35, k + 34, Blocks.dirt, 0);
        this.setBlock(world, i + 13, j + 35, k + 35, Blocks.dirt, 0);
        this.setBlock(world, i + 13, j + 35, k + 36, Blocks.dirt, 0);
        this.setBlock(world, i + 13, j + 35, k + 37, Blocks.dirt, 0);
        this.setBlock(world, i + 13, j + 35, k + 38, Blocks.dirt, 0);
        this.setBlock(world, i + 13, j + 35, k + 39, Blocks.dirt, 0);
        this.setBlock(world, i + 13, j + 35, k + 40, Blocks.dirt, 0);
        this.setBlock(world, i + 13, j + 35, k + 41, Blocks.mycelium, 0);
        this.setBlock(world, i + 13, j + 36, k + 13, Blocks.stone, 0);
        this.setBlock(world, i + 13, j + 36, k + 14, Blocks.bedrock, 0);
        this.setBlock(world, i + 13, j + 36, k + 15, Blocks.stone, 0);
        this.setBlock(world, i + 13, j + 36, k + 16, Blocks.stone, 0);
        this.setBlock(world, i + 13, j + 36, k + 17, Blocks.stone, 0);
        this.setBlock(world, i + 13, j + 36, k + 18, Blocks.bedrock, 0);
        this.setBlock(world, i + 13, j + 36, k + 19, Blocks.stone, 0);
        this.setBlock(world, i + 13, j + 36, k + 20, Blocks.stone, 0);
        this.setBlock(world, i + 13, j + 36, k + 21, Blocks.stone, 0);
        this.setBlock(world, i + 13, j + 36, k + 22, Blocks.stone, 0);
        this.setBlock(world, i + 13, j + 36, k + 23, Blocks.stone, 0);
        this.setBlock(world, i + 13, j + 36, k + 24, Blocks.stone, 0);
        this.setBlock(world, i + 13, j + 36, k + 25, Blocks.stone, 0);
        this.setBlock(world, i + 13, j + 36, k + 26, Blocks.stone, 0);
        this.setBlock(world, i + 13, j + 36, k + 27, Blocks.bedrock, 0);
        this.setBlock(world, i + 13, j + 36, k + 28, Blocks.stone, 0);
        this.setBlock(world, i + 13, j + 36, k + 29, Blocks.bedrock, 0);
        this.setBlock(world, i + 13, j + 36, k + 30, Blocks.stone, 0);
        this.setBlock(world, i + 13, j + 36, k + 31, Blocks.stone, 0);
        this.setBlock(world, i + 13, j + 36, k + 32, Blocks.stone, 0);
        this.setBlock(world, i + 13, j + 36, k + 33, Blocks.stone, 0);
        this.setBlock(world, i + 13, j + 36, k + 34, Blocks.cobblestone, 0);
        this.setBlock(world, i + 13, j + 36, k + 35, Blocks.stone, 0);
        this.setBlock(world, i + 13, j + 36, k + 36, Blocks.stone, 0);
        this.setBlock(world, i + 13, j + 36, k + 37, Blocks.stone, 0);
        this.setBlock(world, i + 13, j + 36, k + 38, Blocks.stone, 0);
        this.setBlock(world, i + 13, j + 36, k + 39, Blocks.stone, 0);
        this.setBlock(world, i + 13, j + 36, k + 40, Blocks.stone, 0);
        this.setBlock(world, i + 13, j + 37, k + 14, Blocks.cobblestone, 0);
        this.setBlock(world, i + 13, j + 37, k + 15, Blocks.stone, 0);
        this.setBlock(world, i + 13, j + 37, k + 16, Blocks.stone, 0);
        this.setBlock(world, i + 13, j + 37, k + 17, Blocks.stone, 0);
        this.setBlock(world, i + 13, j + 37, k + 18, Blocks.bedrock, 0);
        this.setBlock(world, i + 13, j + 37, k + 19, Blocks.stone, 0);
        this.setBlock(world, i + 13, j + 37, k + 20, Blocks.stone, 0);
        this.setBlock(world, i + 13, j + 37, k + 21, Blocks.stone, 0);
        this.setBlock(world, i + 13, j + 37, k + 22, Blocks.stone, 0);
        this.setBlock(world, i + 13, j + 37, k + 23, Blocks.stone, 0);
        this.setBlock(world, i + 13, j + 37, k + 24, Blocks.bedrock, 0);
        this.setBlock(world, i + 13, j + 37, k + 25, Blocks.stone, 0);
        this.setBlock(world, i + 13, j + 37, k + 26, Blocks.cobblestone, 0);
        this.setBlock(world, i + 13, j + 37, k + 27, Blocks.stone, 0);
        this.setBlock(world, i + 13, j + 37, k + 28, Blocks.bedrock, 0);
        this.setBlock(world, i + 13, j + 37, k + 29, Blocks.cobblestone, 0);
        this.setBlock(world, i + 13, j + 37, k + 30, Blocks.bedrock, 0);
        this.setBlock(world, i + 13, j + 37, k + 31, Blocks.cobblestone, 0);
        this.setBlock(world, i + 13, j + 37, k + 32, Blocks.stone, 0);
        this.setBlock(world, i + 13, j + 37, k + 33, Blocks.stone, 0);
        this.setBlock(world, i + 13, j + 37, k + 34, Blocks.stone, 0);
        this.setBlock(world, i + 13, j + 37, k + 35, Blocks.stone, 0);
        this.setBlock(world, i + 13, j + 37, k + 36, Blocks.stone, 0);
        this.setBlock(world, i + 13, j + 38, k + 16, Blocks.stone, 0);
        this.setBlock(world, i + 13, j + 38, k + 17, Blocks.stone, 0);
