

package com.gibby.dungeon.gen;

import net.minecraft.world.gen.feature.*;
import net.minecraft.world.*;
import java.util.*;
import net.minecraft.init.*;

public class WorldGenObelisk extends WorldGenerator
{
    public boolean generate(final World world, final Random rand, final int i, final int j, final int k) {
        if (world.getBlock(i, j, k) != Blocks.sand || world.getBlock(i + 10, j, k) != Blocks.sand || world.getBlock(i + 10, j, k + 10) != Blocks.sand || world.getBlock(i, j, k + 10) != Blocks.sand || world.getBlock(i, j + 1, k) != Blocks.air || world.getBlock(i + 10, j + 1, k) != Blocks.air || world.getBlock(i + 10, j + 1, k + 10) != Blocks.air || world.getBlock(i, j + 1, k + 10) != Blocks.air) {
            return false;
        }
        world.setBlock(i + 2, j + 0, k + 2, Blocks.sandstone);
        world.setBlock(i + 2, j + 0, k + 3, Blocks.sandstone);
        world.setBlock(i + 2, j + 0, k + 4, Blocks.sandstone);
        world.setBlock(i + 2, j + 0, k + 5, Blocks.sandstone);
        world.setBlock(i + 2, j + 0, k + 6, Blocks.sandstone);
        world.setBlock(i + 2, j + 0, k + 7, Blocks.sandstone);
        world.setBlock(i + 2, j + 0, k + 8, Blocks.sandstone);
        world.setBlock(i + 2, j + 1, k + 2, Blocks.sandstone);
        world.setBlock(i + 2, j + 1, k + 3, Blocks.sandstone);
        world.setBlock(i + 2, j + 1, k + 4, Blocks.sandstone);
        world.setBlock(i + 2, j + 1, k + 5, Blocks.sandstone);
        world.setBlock(i + 2, j + 1, k + 6, Blocks.sandstone);
        world.setBlock(i + 2, j + 1, k + 7, Blocks.sandstone);
        world.setBlock(i + 2, j + 1, k + 8, Blocks.sandstone);
        world.setBlock(i + 2, j + 2, k + 2, Blocks.sandstone);
        world.setBlock(i + 2, j + 2, k + 3, Blocks.sandstone);
        world.setBlock(i + 2, j + 2, k + 4, Blocks.sandstone);
        world.setBlock(i + 2, j + 2, k + 5, Blocks.sandstone);
        world.setBlock(i + 2, j + 2, k + 6, Blocks.sandstone);
        world.setBlock(i + 2, j + 2, k + 7, Blocks.sandstone);
        world.setBlock(i + 2, j + 2, k + 8, Blocks.sandstone);
        world.setBlock(i + 2, j + 3, k + 2, Blocks.sandstone);
        world.setBlock(i + 2, j + 3, k + 3, Blocks.sandstone);
        world.setBlock(i + 2, j + 3, k + 4, Blocks.sandstone);
        world.setBlock(i + 2, j + 3, k + 5, Blocks.sandstone);
        world.setBlock(i + 2, j + 3, k + 6, Blocks.sandstone);
        world.setBlock(i + 2, j + 3, k + 7, Blocks.sandstone);
        world.setBlock(i + 2, j + 3, k + 8, Blocks.sandstone);
        world.setBlock(i + 2, j + 4, k + 2, Blocks.sandstone);
        world.setBlock(i + 2, j + 4, k + 3, Blocks.sandstone);
        world.setBlock(i + 2, j + 4, k + 4, Blocks.sandstone);
        world.setBlock(i + 2, j + 4, k + 5, Blocks.sandstone);
        world.setBlock(i + 2, j + 4, k + 6, Blocks.sandstone);
        world.setBlock(i + 2, j + 4, k + 7, Blocks.sandstone);
        world.setBlock(i + 2, j + 4, k + 8, Blocks.sandstone);
        world.setBlock(i + 2, j + 5, k + 2, Blocks.sandstone);
        world.setBlock(i + 2, j + 5, k + 3, Blocks.sandstone);
        world.setBlock(i + 2, j + 5, k + 4, Blocks.sandstone);
        world.setBlock(i + 2, j + 5, k + 5, Blocks.sandstone);
        world.setBlock(i + 2, j + 5, k + 6, Blocks.sandstone);
        world.setBlock(i + 2, j + 5, k + 7, Blocks.sandstone);
        world.setBlock(i + 2, j + 5, k + 8, Blocks.sandstone);
        world.setBlock(i + 2, j + 6, k + 2, Blocks.sandstone);
        world.setBlock(i + 2, j + 6, k + 3, Blocks.sandstone);
        world.setBlock(i + 2, j + 6, k + 4, Blocks.sandstone);
        world.setBlock(i + 2, j + 6, k + 5, Blocks.sandstone);
        world.setBlock(i + 2, j + 6, k + 6, Blocks.sandstone);
        world.setBlock(i + 2, j + 6, k + 7, Blocks.sandstone);
        world.setBlock(i + 2, j + 6, k + 8, Blocks.sandstone);
        world.setBlock(i + 2, j + 7, k + 2, Blocks.sandstone);
        world.setBlock(i + 2, j + 7, k + 3, Blocks.sandstone);
        world.setBlock(i + 2, j + 7, k + 4, Blocks.sandstone);
        world.setBlock(i + 2, j + 7, k + 5, Blocks.sandstone);
        world.setBlock(i + 2, j + 7, k + 6, Blocks.sandstone);
        world.setBlock(i + 2, j + 7, k + 7, Blocks.sandstone);
        world.setBlock(i + 2, j + 7, k + 8, Blocks.sandstone);
        world.setBlock(i + 2, j + 8, k + 2, Blocks.sandstone);
        world.setBlock(i + 2, j + 8, k + 3, Blocks.sandstone);
        world.setBlock(i + 2, j + 8, k + 4, Blocks.sandstone);
        world.setBlock(i + 2, j + 8, k + 5, Blocks.sandstone);
        world.setBlock(i + 2, j + 8, k + 6, Blocks.sandstone);
        world.setBlock(i + 2, j + 8, k + 7, Blocks.sandstone);
        world.setBlock(i + 2, j + 8, k + 8, Blocks.sandstone);
        world.setBlock(i + 2, j + 9, k + 2, Blocks.sandstone);
        world.setBlock(i + 2, j + 9, k + 3, Blocks.sandstone);
        world.setBlock(i + 2, j + 9, k + 4, Blocks.sandstone);
        world.setBlock(i + 2, j + 9, k + 5, Blocks.wool, 4, 0);
        world.setBlock(i + 2, j + 9, k + 6, Blocks.sandstone);
        world.setBlock(i + 2, j + 9, k + 7, Blocks.sandstone);
        world.setBlock(i + 2, j + 9, k + 8, Blocks.sandstone);
        world.setBlock(i + 2, j + 10, k + 2, Blocks.sandstone);
        world.setBlock(i + 2, j + 10, k + 3, Blocks.sandstone);
        world.setBlock(i + 2, j + 10, k + 4, Blocks.wool, 4, 0);
        world.setBlock(i + 2, j + 10, k + 5, Blocks.wool, 4, 0);
        world.setBlock(i + 2, j + 10, k + 6, Blocks.wool, 4, 0);
        world.setBlock(i + 2, j + 10, k + 7, Blocks.sandstone);
        world.setBlock(i + 2, j + 10, k + 8, Blocks.sandstone);
        world.setBlock(i + 2, j + 11, k + 2, Blocks.sandstone);
        world.setBlock(i + 2, j + 11, k + 3, Blocks.sandstone);
        world.setBlock(i + 2, j + 11, k + 4, Blocks.wool, 4, 0);
        world.setBlock(i + 2, j + 11, k + 5, Blocks.wool, 4, 0);
        world.setBlock(i + 2, j + 11, k + 6, Blocks.wool, 4, 0);
        world.setBlock(i + 2, j + 11, k + 7, Blocks.sandstone);
        world.setBlock(i + 2, j + 11, k + 8, Blocks.sandstone);
        world.setBlock(i + 2, j + 12, k + 2, Blocks.sandstone);
        world.setBlock(i + 2, j + 12, k + 3, Blocks.sandstone);
        world.setBlock(i + 2, j + 12, k + 4, Blocks.wool, 4, 0);
        world.setBlock(i + 2, j + 12, k + 5, Blocks.wool, 4, 0);
        world.setBlock(i + 2, j + 12, k + 6, Blocks.wool, 4, 0);
        world.setBlock(i + 2, j + 12, k + 7, Blocks.sandstone);
        world.setBlock(i + 2, j + 12, k + 8, Blocks.sandstone);
        world.setBlock(i + 2, j + 13, k + 2, Blocks.sandstone);
        world.setBlock(i + 2, j + 13, k + 3, Blocks.sandstone);
        world.setBlock(i + 2, j + 13, k + 4, Blocks.wool, 4, 0);
        world.setBlock(i + 2, j + 13, k + 5, Blocks.wool, 4, 0);
        world.setBlock(i + 2, j + 13, k + 6, Blocks.wool, 4, 0);
        world.setBlock(i + 2, j + 13, k + 7, Blocks.sandstone);
        world.setBlock(i + 2, j + 13, k + 8, Blocks.sandstone);
        world.setBlock(i + 2, j + 14, k + 2, Blocks.sandstone);
        world.setBlock(i + 2, j + 14, k + 3, Blocks.sandstone);
        world.setBlock(i + 2, j + 14, k + 4, Blocks.sandstone);
        world.setBlock(i + 2, j + 14, k + 5, Blocks.wool, 4, 0);
        world.setBlock(i + 2, j + 14, k + 6, Blocks.sandstone);
        world.setBlock(i + 2, j + 14, k + 7, Blocks.sandstone);
        world.setBlock(i + 2, j + 14, k + 8, Blocks.sandstone);
        world.setBlock(i + 2, j + 15, k + 2, Blocks.sandstone);
        world.setBlock(i + 2, j + 15, k + 3, Blocks.sandstone);
        world.setBlock(i + 2, j + 15, k + 4, Blocks.sandstone);
        world.setBlock(i + 2, j + 15, k + 5, Blocks.sandstone);
        world.setBlock(i + 2, j + 15, k + 6, Blocks.sandstone);
        world.setBlock(i + 2, j + 15, k + 7, Blocks.sandstone);
        world.setBlock(i + 2, j + 15, k + 8, Blocks.sandstone);
        world.setBlock(i + 2, j + 16, k + 2, Blocks.sandstone);
        world.setBlock(i + 2, j + 16, k + 3, Blocks.sandstone);
        world.setBlock(i + 2, j + 16, k + 4, Blocks.sandstone);
        world.setBlock(i + 2, j + 16, k + 5, Blocks.wool, 4, 0);
        world.setBlock(i + 2, j + 16, k + 6, Blocks.sandstone);
        world.setBlock(i + 2, j + 16, k + 7, Blocks.sandstone);
        world.setBlock(i + 2, j + 16, k + 8, Blocks.sandstone);
        world.setBlock(i + 2, j + 17, k + 2, Blocks.sandstone);
        world.setBlock(i + 2, j + 17, k + 3, Blocks.sandstone);
        world.setBlock(i + 2, j + 17, k + 4, Blocks.wool, 4, 0);
        world.setBlock(i + 2, j + 17, k + 5, Blocks.wool, 4, 0);
        world.setBlock(i + 2, j + 17, k + 6, Blocks.wool, 4, 0);
        world.setBlock(i + 2, j + 17, k + 7, Blocks.sandstone);
        world.setBlock(i + 2, j + 17, k + 8, Blocks.sandstone);
        world.setBlock(i + 2, j + 18, k + 2, Blocks.sandstone);
        world.setBlock(i + 2, j + 18, k + 3, Blocks.sandstone);
        world.setBlock(i + 2, j + 18, k + 4, Blocks.wool, 4, 0);
        world.setBlock(i + 2, j + 18, k + 5, Blocks.wool, 4, 0);
        world.setBlock(i + 2, j + 18, k + 6, Blocks.wool, 4, 0);
        world.setBlock(i + 2, j + 18, k + 7, Blocks.sandstone);
        world.setBlock(i + 2, j + 18, k + 8, Blocks.sandstone);
        world.setBlock(i + 2, j + 19, k + 2, Blocks.sandstone);
        world.setBlock(i + 2, j + 19, k + 3, Blocks.sandstone);
        world.setBlock(i + 2, j + 19, k + 4, Blocks.wool, 4, 0);
        world.setBlock(i + 2, j + 19, k + 5, Blocks.wool, 4, 0);
        world.setBlock(i + 2, j + 19, k + 6, Blocks.wool, 4, 0);
        world.setBlock(i + 2, j + 19, k + 7, Blocks.sandstone);
        world.setBlock(i + 2, j + 19, k + 8, Blocks.sandstone);
        world.setBlock(i + 2, j + 20, k + 2, Blocks.sandstone);
        world.setBlock(i + 2, j + 20, k + 3, Blocks.sandstone);
        world.setBlock(i + 2, j + 20, k + 4, Blocks.wool, 4, 0);
        world.setBlock(i + 2, j + 20, k + 5, Blocks.wool, 4, 0);
        world.setBlock(i + 2, j + 20, k + 6, Blocks.wool, 4, 0);
        world.setBlock(i + 2, j + 20, k + 7, Blocks.sandstone);
        world.setBlock(i + 2, j + 20, k + 8, Blocks.sandstone);
        world.setBlock(i + 2, j + 21, k + 2, Blocks.sandstone);
        world.setBlock(i + 2, j + 21, k + 3, Blocks.sandstone);
        world.setBlock(i + 2, j + 21, k + 4, Blocks.sandstone);
        world.setBlock(i + 2, j + 21, k + 5, Blocks.wool, 4, 0);
        world.setBlock(i + 2, j + 21, k + 6, Blocks.sandstone);
        world.setBlock(i + 2, j + 21, k + 7, Blocks.sandstone);
        world.setBlock(i + 2, j + 21, k + 8, Blocks.sandstone);
        world.setBlock(i + 2, j + 22, k + 2, Blocks.sandstone);
        world.setBlock(i + 2, j + 22, k + 3, Blocks.sandstone);
        world.setBlock(i + 2, j + 22, k + 4, Blocks.sandstone);
        world.setBlock(i + 2, j + 22, k + 5, Blocks.sandstone);
        world.setBlock(i + 2, j + 22, k + 6, Blocks.sandstone);
        world.setBlock(i + 2, j + 22, k + 7, Blocks.sandstone);
        world.setBlock(i + 2, j + 22, k + 8, Blocks.sandstone);
        world.setBlock(i + 2, j + 23, k + 2, Blocks.sandstone);
        world.setBlock(i + 2, j + 23, k + 3, Blocks.sandstone);
        world.setBlock(i + 2, j + 23, k + 4, Blocks.sandstone);
        world.setBlock(i + 2, j + 23, k + 5, Blocks.sandstone);
        world.setBlock(i + 2, j + 23, k + 6, Blocks.sandstone);
        world.setBlock(i + 2, j + 23, k + 7, Blocks.sandstone);
        world.setBlock(i + 2, j + 23, k + 8, Blocks.sandstone);
        world.setBlock(i + 2, j + 24, k + 2, Blocks.sandstone);
        world.setBlock(i + 2, j + 24, k + 3, Blocks.sandstone);
        world.setBlock(i + 2, j + 24, k + 4, Blocks.sandstone);
        world.setBlock(i + 2, j + 24, k + 5, Blocks.sandstone);
        world.setBlock(i + 2, j + 24, k + 6, Blocks.sandstone);
        world.setBlock(i + 2, j + 24, k + 7, Blocks.sandstone);
        world.setBlock(i + 2, j + 24, k + 8, Blocks.sandstone);
        world.setBlock(i + 2, j + 25, k + 2, Blocks.sandstone);
        world.setBlock(i + 2, j + 25, k + 3, Blocks.sandstone);
        world.setBlock(i + 2, j + 25, k + 4, Blocks.sandstone);
        world.setBlock(i + 2, j + 25, k + 5, Blocks.sandstone);
        world.setBlock(i + 2, j + 25, k + 6, Blocks.sandstone);
        world.setBlock(i + 2, j + 25, k + 7, Blocks.sandstone);
        world.setBlock(i + 2, j + 25, k + 8, Blocks.sandstone);
        world.setBlock(i + 2, j + 26, k + 2, Blocks.sandstone);
        world.setBlock(i + 2, j + 26, k + 3, Blocks.sandstone);
        world.setBlock(i + 2, j + 26, k + 4, Blocks.sandstone);
        world.setBlock(i + 2, j + 26, k + 5, Blocks.sandstone);
        world.setBlock(i + 2, j + 26, k + 6, Blocks.sandstone);
        world.setBlock(i + 2, j + 26, k + 7, Blocks.sandstone);
        world.setBlock(i + 2, j + 26, k + 8, Blocks.sandstone);
        world.setBlock(i + 2, j + 27, k + 2, Blocks.sandstone);
        world.setBlock(i + 2, j + 27, k + 3, Blocks.sandstone);
        world.setBlock(i + 2, j + 27, k + 4, Blocks.sandstone);
        world.setBlock(i + 2, j + 27, k + 5, Blocks.sandstone);
        world.setBlock(i + 2, j + 27, k + 6, Blocks.sandstone);
        world.setBlock(i + 2, j + 27, k + 7, Blocks.sandstone);
        world.setBlock(i + 2, j + 27, k + 8, Blocks.sandstone);
        world.setBlock(i + 3, j + 0, k + 2, Blocks.sandstone);
        world.setBlock(i + 3, j + 0, k + 3, Blocks.sandstone);
        world.setBlock(i + 3, j + 0, k + 4, Blocks.sandstone);
        world.setBlock(i + 3, j + 0, k + 5, Blocks.sandstone);
        world.setBlock(i + 3, j + 0, k + 6, Blocks.sandstone);
        world.setBlock(i + 3, j + 0, k + 7, Blocks.sandstone);
        world.setBlock(i + 3, j + 0, k + 8, Blocks.sandstone);
        world.setBlock(i + 3, j + 1, k + 2, Blocks.sandstone);
        world.setBlock(i + 3, j + 1, k + 8, Blocks.sandstone);
        world.setBlock(i + 3, j + 2, k + 2, Blocks.sandstone);
        world.setBlock(i + 3, j + 2, k + 8, Blocks.sandstone);
        world.setBlock(i + 3, j + 3, k + 2, Blocks.sandstone);
        world.setBlock(i + 3, j + 3, k + 8, Blocks.sandstone);
        world.setBlock(i + 3, j + 4, k + 2, Blocks.sandstone);
        world.setBlock(i + 3, j + 4, k + 8, Blocks.sandstone);
        world.setBlock(i + 3, j + 5, k + 2, Blocks.sandstone);
        world.setBlock(i + 3, j + 5, k + 8, Blocks.sandstone);
        world.setBlock(i + 3, j + 6, k + 2, Blocks.sandstone);
        world.setBlock(i + 3, j + 6, k + 8, Blocks.sandstone);
        world.setBlock(i + 3, j + 7, k + 2, Blocks.sandstone);
        world.setBlock(i + 3, j + 7, k + 3, Blocks.sandstone);
        world.setBlock(i + 3, j + 7, k + 4, Blocks.sandstone);
        world.setBlock(i + 3, j + 7, k + 8, Blocks.sandstone);
        world.setBlock(i + 3, j + 8, k + 2, Blocks.sandstone);
        world.setBlock(i + 3, j + 8, k + 5, Blocks.sandstone);
        world.setBlock(i + 3, j + 8, k + 8, Blocks.sandstone);
        world.setBlock(i + 3, j + 9, k + 2, Blocks.sandstone);
        world.setBlock(i + 3, j + 9, k + 6, Blocks.sandstone);
        world.setBlock(i + 3, j + 9, k + 7, Blocks.sandstone);
        world.setBlock(i + 3, j + 9, k + 8, Blocks.sandstone);
        world.setBlock(i + 3, j + 10, k + 2, Blocks.sandstone);
        world.setBlock(i + 3, j + 10, k + 8, Blocks.sandstone);
        world.setBlock(i + 3, j + 11, k + 2, Blocks.sandstone);
        world.setBlock(i + 3, j + 11, k + 8, Blocks.sandstone);
        world.setBlock(i + 3, j + 12, k + 2, Blocks.sandstone);
        world.setBlock(i + 3, j + 12, k + 8, Blocks.sandstone);
        world.setBlock(i + 3, j + 13, k + 2, Blocks.sandstone);
        world.setBlock(i + 3, j + 13, k + 8, Blocks.sandstone);
        world.setBlock(i + 3, j + 14, k + 2, Blocks.sandstone);
        world.setBlock(i + 3, j + 14, k + 8, Blocks.sandstone);
        world.setBlock(i + 3, j + 15, k + 2, Blocks.sandstone);
        world.setBlock(i + 3, j + 15, k + 3, Blocks.sandstone);
        world.setBlock(i + 3, j + 15, k + 4, Blocks.sandstone);
        world.setBlock(i + 3, j + 15, k + 8, Blocks.sandstone);
        world.setBlock(i + 3, j + 16, k + 2, Blocks.sandstone);
        world.setBlock(i + 3, j + 16, k + 5, Blocks.sandstone);
        world.setBlock(i + 3, j + 16, k + 8, Blocks.sandstone);
        world.setBlock(i + 3, j + 17, k + 2, Blocks.sandstone);
        world.setBlock(i + 3, j + 17, k + 6, Blocks.sandstone);
        world.setBlock(i + 3, j + 17, k + 7, Blocks.sandstone);
        world.setBlock(i + 3, j + 17, k + 8, Blocks.sandstone);
        world.setBlock(i + 3, j + 18, k + 2, Blocks.sandstone);
        world.setBlock(i + 3, j + 18, k + 8, Blocks.sandstone);
        world.setBlock(i + 3, j + 19, k + 2, Blocks.sandstone);
        world.setBlock(i + 3, j + 19, k + 8, Blocks.sandstone);
        world.setBlock(i + 3, j + 20, k + 2, Blocks.sandstone);
        world.setBlock(i + 3, j + 20, k + 8, Blocks.sandstone);
        world.setBlock(i + 3, j + 21, k + 2, Blocks.sandstone);
        world.setBlock(i + 3, j + 21, k + 8, Blocks.sandstone);
        world.setBlock(i + 3, j + 22, k + 2, Blocks.sandstone);
        world.setBlock(i + 3, j + 22, k + 8, Blocks.sandstone);
        world.setBlock(i + 3, j + 23, k + 2, Blocks.sandstone);
        world.setBlock(i + 3, j + 23, k + 3, Blocks.sandstone);
        world.setBlock(i + 3, j + 23, k + 4, Blocks.sandstone);
        world.setBlock(i + 3, j + 23, k + 8, Blocks.sandstone);
        world.setBlock(i + 3, j + 24, k + 2, Blocks.sandstone);
        world.setBlock(i + 3, j + 24, k + 5, Blocks.sandstone);
        world.setBlock(i + 3, j + 24, k + 8, Blocks.sandstone);
        world.setBlock(i + 3, j + 25, k + 2, Blocks.sandstone);
        world.setBlock(i + 3, j + 25, k + 6, Blocks.sandstone);
        world.setBlock(i + 3, j + 25, k + 7, Blocks.sandstone);
        world.setBlock(i + 3, j + 25, k + 8, Blocks.sandstone);
        world.setBlock(i + 3, j + 26, k + 2, Blocks.sandstone);
        world.setBlock(i + 3, j + 26, k + 8, Blocks.sandstone);
        world.setBlock(i + 3, j + 27, k + 2, Blocks.sandstone);
        world.setBlock(i + 3, j + 27, k + 3, Blocks.sandstone);
        world.setBlock(i + 3, j + 27, k + 4, Blocks.sandstone);
        world.setBlock(i + 3, j + 27, k + 8, Blocks.sandstone);
        world.setBlock(i + 3, j + 28, k + 3, Blocks.sandstone);
        world.setBlock(i + 3, j + 28, k + 4, Blocks.sandstone);
        world.setBlock(i + 3, j + 28, k + 5, Blocks.sandstone);
        world.setBlock(i + 3, j + 28, k + 6, Blocks.sandstone);
        world.setBlock(i + 3, j + 28, k + 7, Blocks.sandstone);
        world.setBlock(i + 3, j + 29, k + 3, Blocks.sandstone);
        world.setBlock(i + 3, j + 29, k + 4, Blocks.sandstone);
        world.setBlock(i + 3, j + 29, k + 5, Blocks.sandstone);
        world.setBlock(i + 3, j + 29, k + 6, Blocks.sandstone);
        world.setBlock(i + 3, j + 29, k + 7, Blocks.sandstone);
        world.setBlock(i + 3, j + 30, k + 3, Blocks.sandstone);
        world.setBlock(i + 3, j + 30, k + 4, Blocks.sandstone);
        world.setBlock(i + 3, j + 30, k + 5, Blocks.sandstone);
        world.setBlock(i + 3, j + 30, k + 6, Blocks.sandstone);
        world.setBlock(i + 3, j + 30, k + 7, Blocks.sandstone);
        world.setBlock(i + 4, j + 0, k + 2, Blocks.sandstone);
        world.setBlock(i + 4, j + 0, k + 3, Blocks.sandstone);
        world.setBlock(i + 4, j + 0, k + 4, Blocks.sandstone);
        world.setBlock(i + 4, j + 0, k + 5, Blocks.sandstone);
        world.setBlock(i + 4, j + 0, k + 6, Blocks.sandstone);
        world.setBlock(i + 4, j + 0, k + 7, Blocks.sandstone);
        world.setBlock(i + 4, j + 0, k + 8, Blocks.sandstone);
        world.setBlock(i + 4, j + 1, k + 2, Blocks.sandstone);
        world.setBlock(i + 4, j + 1, k + 6, Blocks.sandstone);
        world.setBlock(i + 4, j + 1, k + 7, Blocks.sandstone);
        world.setBlock(i + 4, j + 1, k + 8, Blocks.sandstone);
        world.setBlock(i + 4, j + 2, k + 2, Blocks.sandstone);
        world.setBlock(i + 4, j + 2, k + 8, Blocks.sandstone);
        world.setBlock(i + 4, j + 3, k + 2, Blocks.sandstone);
        world.setBlock(i + 4, j + 3, k + 8, Blocks.sandstone);
        world.setBlock(i + 4, j + 4, k + 2, Blocks.sandstone);
        world.setBlock(i + 4, j + 4, k + 8, Blocks.sandstone);
        world.setBlock(i + 4, j + 5, k + 2, Blocks.sandstone);
        world.setBlock(i + 4, j + 5, k + 8, Blocks.sandstone);
        world.setBlock(i + 4, j + 6, k + 2, Blocks.sandstone);
        world.setBlock(i + 4, j + 6, k + 8, Blocks.sandstone);
        world.setBlock(i + 4, j + 7, k + 2, Blocks.sandstone);
        world.setBlock(i + 4, j + 7, k + 3, Blocks.sandstone);
        world.setBlock(i + 4, j + 7, k + 4, Blocks.sandstone);
        world.setBlock(i + 4, j + 7, k + 8, Blocks.sandstone);
        world.setBlock(i + 4, j + 8, k + 2, Blocks.sandstone);
        world.setBlock(i + 4, j + 8, k + 5, Blocks.sandstone);
        world.setBlock(i + 4, j + 8, k + 8, Blocks.sandstone);
        world.setBlock(i + 4, j + 9, k + 2, Blocks.sandstone);
        world.setBlock(i + 4, j + 9, k + 6, Blocks.sandstone);
        world.setBlock(i + 4, j + 9, k + 7, Blocks.sandstone);
        world.setBlock(i + 4, j + 9, k + 8, Blocks.sandstone);
        world.setBlock(i + 4, j + 10, k + 2, Blocks.wool, 4, 0);
        world.setBlock(i + 4, j + 10, k + 8, Blocks.wool, 4, 0);
        world.setBlock(i + 4, j + 11, k + 2, Blocks.wool, 4, 0);
        world.setBlock(i + 4, j + 11, k + 8, Blocks.wool, 4, 0);
        world.setBlock(i + 4, j + 12, k + 2, Blocks.wool, 4, 0);
        world.setBlock(i + 4, j + 12, k + 8, Blocks.wool, 4, 0);
        world.setBlock(i + 4, j + 13, k + 2, Blocks.wool, 4, 0);
        world.setBlock(i + 4, j + 13, k + 8, Blocks.wool, 4, 0);
        world.setBlock(i + 4, j + 14, k + 2, Blocks.sandstone);
        world.setBlock(i + 4, j + 14, k + 8, Blocks.sandstone);
        world.setBlock(i + 4, j + 15, k + 2, Blocks.sandstone);
        world.setBlock(i + 4, j + 15, k + 3, Blocks.sandstone);
        world.setBlock(i + 4, j + 15, k + 4, Blocks.sandstone);
        world.setBlock(i + 4, j + 15, k + 8, Blocks.sandstone);
        world.setBlock(i + 4, j + 16, k + 2, Blocks.sandstone);
        world.setBlock(i + 4, j + 16, k + 5, Blocks.sandstone);
        world.setBlock(i + 4, j + 16, k + 8, Blocks.sandstone);
        world.setBlock(i + 4, j + 17, k + 2, Blocks.wool, 4, 0);
        world.setBlock(i + 4, j + 17, k + 6, Blocks.sandstone);
        world.setBlock(i + 4, j + 17, k + 7, Blocks.sandstone);
        world.setBlock(i + 4, j + 17, k + 8, Blocks.wool, 4, 0);
        world.setBlock(i + 4, j + 18, k + 2, Blocks.wool, 4, 0);
        world.setBlock(i + 4, j + 18, k + 8, Blocks.wool, 4, 0);
        world.setBlock(i + 4, j + 19, k + 2, Blocks.wool, 4, 0);
        world.setBlock(i + 4, j + 19, k + 8, Blocks.wool, 4, 0);
        world.setBlock(i + 4, j + 20, k + 2, Blocks.wool, 4, 0);
        world.setBlock(i + 4, j + 20, k + 8, Blocks.wool, 4, 0);
        world.setBlock(i + 4, j + 21, k + 2, Blocks.sandstone);
        world.setBlock(i + 4, j + 21, k + 8, Blocks.sandstone);
        world.setBlock(i + 4, j + 22, k + 2, Blocks.sandstone);
        world.setBlock(i + 4, j + 22, k + 8, Blocks.sandstone);
        world.setBlock(i + 4, j + 23, k + 2, Blocks.sandstone);
        world.setBlock(i + 4, j + 23, k + 3, Blocks.sandstone);
        world.setBlock(i + 4, j + 23, k + 4, Blocks.sandstone);
        world.setBlock(i + 4, j + 23, k + 8, Blocks.sandstone);
        world.setBlock(i + 4, j + 24, k + 2, Blocks.sandstone);
        world.setBlock(i + 4, j + 24, k + 5, Blocks.sandstone);
        world.setBlock(i + 4, j + 24, k + 8, Blocks.sandstone);
        world.setBlock(i + 4, j + 25, k + 2, Blocks.sandstone);
        world.setBlock(i + 4, j + 25, k + 6, Blocks.sandstone);
        world.setBlock(i + 4, j + 25, k + 7, Blocks.sandstone);
        world.setBlock(i + 4, j + 25, k + 8, Blocks.sandstone);
        world.setBlock(i + 4, j + 26, k + 2, Blocks.sandstone);
        world.setBlock(i + 4, j + 26, k + 8, Blocks.sandstone);
        world.setBlock(i + 4, j + 27, k + 2, Blocks.sandstone);
        world.setBlock(i + 4, j + 27, k + 3, Blocks.sandstone);
        world.setBlock(i + 4, j + 27, k + 4, Blocks.sandstone);
        world.setBlock(i + 4, j + 27, k + 8, Blocks.sandstone);
        world.setBlock(i + 4, j + 28, k + 3, Blocks.sandstone);
        world.setBlock(i + 4, j + 28, k + 4, Blocks.skull, 1, 1);
        world.setBlock(i + 4, j + 28, k + 7, Blocks.sandstone);
        world.setBlock(i + 4, j + 29, k + 3, Blocks.sandstone);
        world.setBlock(i + 4, j + 29, k + 7, Blocks.sandstone);
        world.setBlock(i + 4, j + 30, k + 3, Blocks.sandstone);
        world.setBlock(i + 4, j + 30, k + 4, Blocks.sandstone);
        world.setBlock(i + 4, j + 30, k + 5, Blocks.sandstone);
        world.setBlock(i + 4, j + 30, k + 6, Blocks.sandstone);
        world.setBlock(i + 4, j + 30, k + 7, Blocks.sandstone);
        world.setBlock(i + 4, j + 31, k + 4, Blocks.sandstone);
        world.setBlock(i + 4, j + 31, k + 5, Blocks.sandstone);
        world.setBlock(i + 4, j + 31, k + 6, Blocks.sandstone);
        world.setBlock(i + 4, j + 32, k + 4, Blocks.sandstone);
        world.setBlock(i + 4, j + 32, k + 5, Blocks.sandstone);
        world.setBlock(i + 4, j + 32, k + 6, Blocks.sandstone);
        world.setBlock(i + 4, j + 33, k + 4, Blocks.sandstone);
        world.setBlock(i + 4, j + 33, k + 5, Blocks.sandstone);
        world.setBlock(i + 4, j + 33, k + 6, Blocks.sandstone);
        world.setBlock(i + 5, j + 0, k + 2, Blocks.sandstone);
        world.setBlock(i + 5, j + 0, k + 3, Blocks.sandstone);
        world.setBlock(i + 5, j + 0, k + 4, Blocks.sandstone);
        world.setBlock(i + 5, j + 0, k + 5, Blocks.sandstone);
        world.setBlock(i + 5, j + 0, k + 6, Blocks.sandstone);
        world.setBlock(i + 5, j + 0, k + 7, Blocks.sandstone);
        world.setBlock(i + 5, j + 0, k + 8, Blocks.sandstone);
        world.setBlock(i + 5, j + 1, k + 2, Blocks.sandstone);
        world.setBlock(i + 5, j + 1, k + 5, Blocks.sandstone);
        world.setBlock(i + 5, j + 1, k + 7, Blocks.skull, 1, 1);
        world.setBlock(i + 5, j + 1, k + 8, Blocks.sandstone);
        world.setBlock(i + 5, j + 2, k + 2, Blocks.sandstone);
        world.setBlock(i + 5, j + 2, k + 5, Blocks.sandstone);
        world.setBlock(i + 5, j + 2, k + 6, Blocks.sandstone);
        world.setBlock(i + 5, j + 2, k + 7, Blocks.sandstone);
        world.setBlock(i + 5, j + 2, k + 8, Blocks.sandstone);
        world.setBlock(i + 5, j + 3, k + 2, Blocks.sandstone);
        world.setBlock(i + 5, j + 3, k + 5, Blocks.sandstone);
        world.setBlock(i + 5, j + 3, k + 8, Blocks.sandstone);
        world.setBlock(i + 5, j + 4, k + 2, Blocks.sandstone);
        world.setBlock(i + 5, j + 4, k + 5, Blocks.sandstone);
        world.setBlock(i + 5, j + 4, k + 8, Blocks.sandstone);
        world.setBlock(i + 5, j + 5, k + 2, Blocks.sandstone);
        world.setBlock(i + 5, j + 5, k + 5, Blocks.sandstone);
        world.setBlock(i + 5, j + 5, k + 8, Blocks.sandstone);
        world.setBlock(i + 5, j + 6, k + 2, Blocks.sandstone);
        world.setBlock(i + 5, j + 6, k + 3, Blocks.sandstone);
        world.setBlock(i + 5, j + 6, k + 4, Blocks.sandstone);
        world.setBlock(i + 5, j + 6, k + 5, Blocks.sandstone);
        world.setBlock(i + 5, j + 6, k + 8, Blocks.sandstone);
        world.setBlock(i + 5, j + 7, k + 2, Blocks.sandstone);
        world.setBlock(i + 5, j + 7, k + 5, Blocks.sandstone);
        world.setBlock(i + 5, j + 7, k + 8, Blocks.sandstone);
        world.setBlock(i + 5, j + 8, k + 2, Blocks.sandstone);
        world.setBlock(i + 5, j + 8, k + 5, Blocks.sandstone);
        world.setBlock(i + 5, j + 8, k + 8, Blocks.sandstone);
        world.setBlock(i + 5, j + 9, k + 2, Blocks.wool, 4, 0);
        world.setBlock(i + 5, j + 9, k + 5, Blocks.sandstone);
        world.setBlock(i + 5, j + 9, k + 8, Blocks.wool, 4, 0);
        world.setBlock(i + 5, j + 10, k + 2, Blocks.wool, 4, 0);
        world.setBlock(i + 5, j + 10, k + 5, Blocks.sandstone);
        world.setBlock(i + 5, j + 10, k + 6, Blocks.sandstone);
        world.setBlock(i + 5, j + 10, k + 7, Blocks.sandstone);
        world.setBlock(i + 5, j + 10, k + 8, Blocks.wool, 4, 0);
        world.setBlock(i + 5, j + 11, k + 2, Blocks.wool, 4, 0);
        world.setBlock(i + 5, j + 11, k + 5, Blocks.sandstone);
        world.setBlock(i + 5, j + 11, k + 8, Blocks.wool, 4, 0);
        world.setBlock(i + 5, j + 12, k + 2, Blocks.wool, 4, 0);
        world.setBlock(i + 5, j + 12, k + 5, Blocks.sandstone);
        world.setBlock(i + 5, j + 12, k + 8, Blocks.wool, 4, 0);
        world.setBlock(i + 5, j + 13, k + 2, Blocks.wool, 4, 0);
        world.setBlock(i + 5, j + 13, k + 5, Blocks.sandstone);
        world.setBlock(i + 5, j + 13, k + 8, Blocks.wool, 4, 0);
        world.setBlock(i + 5, j + 14, k + 2, Blocks.wool, 4, 0);
        world.setBlock(i + 5, j + 14, k + 3, Blocks.sandstone);
        world.setBlock(i + 5, j + 14, k + 4, Blocks.sandstone);
        world.setBlock(i + 5, j + 14, k + 5, Blocks.sandstone);
        world.setBlock(i + 5, j + 14, k + 8, Blocks.wool, 4, 0);
        world.setBlock(i + 5, j + 15, k + 2, Blocks.sandstone);
        world.setBlock(i + 5, j + 15, k + 5, Blocks.sandstone);
        world.setBlock(i + 5, j + 15, k + 8, Blocks.sandstone);
        world.setBlock(i + 5, j + 16, k + 2, Blocks.wool, 4, 0);
        world.setBlock(i + 5, j + 16, k + 5, Blocks.sandstone);
        world.setBlock(i + 5, j + 16, k + 8, Blocks.wool, 4, 0);
        world.setBlock(i + 5, j + 17, k + 2, Blocks.wool, 4, 0);
        world.setBlock(i + 5, j + 17, k + 5, Blocks.sandstone);
        world.setBlock(i + 5, j + 17, k + 8, Blocks.wool, 4, 0);
        world.setBlock(i + 5, j + 18, k + 2, Blocks.wool, 4, 0);
        world.setBlock(i + 5, j + 18, k + 5, Blocks.sandstone);
        world.setBlock(i + 5, j + 18, k + 6, Blocks.sandstone);
        world.setBlock(i + 5, j + 18, k + 7, Blocks.sandstone);
        world.setBlock(i + 5, j + 18, k + 8, Blocks.wool, 4, 0);
        world.setBlock(i + 5, j + 19, k + 2, Blocks.wool, 4, 0);
        world.setBlock(i + 5, j + 19, k + 5, Blocks.sandstone);
        world.setBlock(i + 5, j + 19, k + 8, Blocks.wool, 4, 0);
        world.setBlock(i + 5, j + 20, k + 2, Blocks.wool, 4, 0);
        world.setBlock(i + 5, j + 20, k + 5, Blocks.sandstone);
        world.setBlock(i + 5, j + 20, k + 8, Blocks.wool, 4, 0);
        world.setBlock(i + 5, j + 21, k + 2, Blocks.wool, 4, 0);
        world.setBlock(i + 5, j + 21, k + 5, Blocks.sandstone);
        world.setBlock(i + 5, j + 21, k + 8, Blocks.wool, 4, 0);
        world.setBlock(i + 5, j + 22, k + 2, Blocks.sandstone);
        world.setBlock(i + 5, j + 22, k + 3, Blocks.sandstone);
        world.setBlock(i + 5, j + 22, k + 4, Blocks.sandstone);
        world.setBlock(i + 5, j + 22, k + 5, Blocks.sandstone);
        world.setBlock(i + 5, j + 22, k + 8, Blocks.sandstone);
        world.setBlock(i + 5, j + 23, k + 2, Blocks.sandstone);
        world.setBlock(i + 5, j + 23, k + 5, Blocks.sandstone);
        world.setBlock(i + 5, j + 23, k + 8, Blocks.sandstone);
        world.setBlock(i + 5, j + 24, k + 2, Blocks.sandstone);
        world.setBlock(i + 5, j + 24, k + 5, Blocks.sandstone);
        world.setBlock(i + 5, j + 24, k + 8, Blocks.sandstone);
        world.setBlock(i + 5, j + 25, k + 2, Blocks.sandstone);
        world.setBlock(i + 5, j + 25, k + 5, Blocks.sandstone);
        world.setBlock(i + 5, j + 25, k + 8, Blocks.sandstone);
        world.setBlock(i + 5, j + 26, k + 2, Blocks.sandstone);
        world.setBlock(i + 5, j + 26, k + 5, Blocks.sandstone);
        world.setBlock(i + 5, j + 26, k + 6, Blocks.sandstone);
        world.setBlock(i + 5, j + 26, k + 7, Blocks.sandstone);
        world.setBlock(i + 5, j + 26, k + 8, Blocks.sandstone);
        world.setBlock(i + 5, j + 27, k + 2, Blocks.sandstone);
        world.setBlock(i + 5, j + 27, k + 3, Blocks.sandstone);
        world.setBlock(i + 5, j + 27, k + 4, Blocks.sandstone);
        world.setBlock(i + 5, j + 27, k + 5, Blocks.sandstone);
        world.setBlock(i + 5, j + 27, k + 8, Blocks.sandstone);
        world.setBlock(i + 5, j + 28, k + 3, Blocks.sandstone);
        WorldGenWarlordDungeon.chest(world, rand, i + 5, j + 28, k + 4, "dungeonChest", 5);
        world.setBlock(i + 5, j + 28, k + 7, Blocks.sandstone);
        world.setBlock(i + 5, j + 29, k + 3, Blocks.sandstone);
        world.setBlock(i + 5, j + 29, k + 7, Blocks.sandstone);
        world.setBlock(i + 5, j + 30, k + 3, Blocks.sandstone);
        world.setBlock(i + 5, j + 30, k + 4, Blocks.sandstone);
        world.setBlock(i + 5, j + 30, k + 6, Blocks.sandstone);
        world.setBlock(i + 5, j + 30, k + 7, Blocks.sandstone);
        world.setBlock(i + 5, j + 31, k + 4, Blocks.sandstone);
        world.setBlock(i + 5, j + 31, k + 6, Blocks.sandstone);
        world.setBlock(i + 5, j + 32, k + 4, Blocks.sandstone);
        world.setBlock(i + 5, j + 32, k + 5, Blocks.sandstone);
        world.setBlock(i + 5, j + 32, k + 6, Blocks.sandstone);
        world.setBlock(i + 5, j + 33, k + 4, Blocks.sandstone);
        world.setBlock(i + 5, j + 33, k + 5, Blocks.sandstone);
        world.setBlock(i + 5, j + 33, k + 6, Blocks.sandstone);
        world.setBlock(i + 5, j + 34, k + 5, Blocks.sandstone);
        world.setBlock(i + 5, j + 35, k + 5, Blocks.sandstone);
        world.setBlock(i + 6, j + 0, k + 2, Blocks.sandstone);
        world.setBlock(i + 6, j + 0, k + 3, Blocks.sandstone);
        world.setBlock(i + 6, j + 0, k + 4, Blocks.sandstone);
        world.setBlock(i + 6, j + 0, k + 5, Blocks.sandstone);
        world.setBlock(i + 6, j + 0, k + 6, Blocks.sandstone);
        world.setBlock(i + 6, j + 0, k + 7, Blocks.sandstone);
        world.setBlock(i + 6, j + 0, k + 8, Blocks.sandstone);
        world.setBlock(i + 6, j + 1, k + 2, Blocks.sandstone);
        world.setBlock(i + 6, j + 1, k + 8, Blocks.sandstone);
        world.setBlock(i + 6, j + 2, k + 2, Blocks.sandstone);
        world.setBlock(i + 6, j + 2, k + 8, Blocks.sandstone);
        world.setBlock(i + 6, j + 3, k + 2, Blocks.sandstone);
        world.setBlock(i + 6, j + 3, k + 6, Blocks.sandstone);
        world.setBlock(i + 6, j + 3, k + 7, Blocks.sandstone);
        world.setBlock(i + 6, j + 3, k + 8, Blocks.sandstone);
        world.setBlock(i + 6, j + 4, k + 2, Blocks.sandstone);
        world.setBlock(i + 6, j + 4, k + 5, Blocks.sandstone);
        world.setBlock(i + 6, j + 4, k + 8, Blocks.sandstone);
        world.setBlock(i + 6, j + 5, k + 2, Blocks.sandstone);
        world.setBlock(i + 6, j + 5, k + 3, Blocks.sandstone);
        world.setBlock(i + 6, j + 5, k + 4, Blocks.sandstone);
        world.setBlock(i + 6, j + 5, k + 8, Blocks.sandstone);
        world.setBlock(i + 6, j + 6, k + 2, Blocks.sandstone);
        world.setBlock(i + 6, j + 6, k + 8, Blocks.sandstone);
        world.setBlock(i + 6, j + 7, k + 2, Blocks.sandstone);
        world.setBlock(i + 6, j + 7, k + 8, Blocks.sandstone);
        world.setBlock(i + 6, j + 8, k + 2, Blocks.sandstone);
        world.setBlock(i + 6, j + 8, k + 8, Blocks.sandstone);
        world.setBlock(i + 6, j + 9, k + 2, Blocks.sandstone);
        world.setBlock(i + 6, j + 9, k + 8, Blocks.sandstone);
        world.setBlock(i + 6, j + 10, k + 2, Blocks.wool, 4, 0);
        world.setBlock(i + 6, j + 10, k + 8, Blocks.wool, 4, 0);
        world.setBlock(i + 6, j + 11, k + 2, Blocks.wool, 4, 0);
        world.setBlock(i + 6, j + 11, k + 6, Blocks.sandstone);
        world.setBlock(i + 6, j + 11, k + 7, Blocks.sandstone);
        world.setBlock(i + 6, j + 11, k + 8, Blocks.wool, 4, 0);
        world.setBlock(i + 6, j + 12, k + 2, Blocks.wool, 4, 0);
        world.setBlock(i + 6, j + 12, k + 5, Blocks.sandstone);
        world.setBlock(i + 6, j + 12, k + 8, Blocks.wool, 4, 0);
        world.setBlock(i + 6, j + 13, k + 2, Blocks.wool, 4, 0);
        world.setBlock(i + 6, j + 13, k + 3, Blocks.sandstone);
        world.setBlock(i + 6, j + 13, k + 4, Blocks.sandstone);
        world.setBlock(i + 6, j + 13, k + 8, Blocks.wool, 4, 0);
        world.setBlock(i + 6, j + 14, k + 2, Blocks.sandstone);
        world.setBlock(i + 6, j + 14, k + 8, Blocks.sandstone);
        world.setBlock(i + 6, j + 15, k + 2, Blocks.sandstone);
        world.setBlock(i + 6, j + 15, k + 8, Blocks.sandstone);
        world.setBlock(i + 6, j + 16, k + 2, Blocks.sandstone);
        world.setBlock(i + 6, j + 16, k + 8, Blocks.sandstone);
        world.setBlock(i + 6, j + 17, k + 2, Blocks.wool, 4, 0);
        world.setBlock(i + 6, j + 17, k + 8, Blocks.wool, 4, 0);
        world.setBlock(i + 6, j + 18, k + 2, Blocks.wool, 4, 0);
        world.setBlock(i + 6, j + 18, k + 8, Blocks.wool, 4, 0);
        world.setBlock(i + 6, j + 19, k + 2, Blocks.wool, 4, 0);
        world.setBlock(i + 6, j + 19, k + 6, Blocks.sandstone);
        world.setBlock(i + 6, j + 19, k + 7, Blocks.sandstone);
        world.setBlock(i + 6, j + 19, k + 8, Blocks.wool, 4, 0);
        world.setBlock(i + 6, j + 20, k + 2, Blocks.wool, 4, 0);
        world.setBlock(i + 6, j + 20, k + 5, Blocks.sandstone);
        world.setBlock(i + 6, j + 20, k + 8, Blocks.wool, 4, 0);
        world.setBlock(i + 6, j + 21, k + 2, Blocks.sandstone);
        world.setBlock(i + 6, j + 21, k + 3, Blocks.sandstone);
        world.setBlock(i + 6, j + 21, k + 4, Blocks.sandstone);
        world.setBlock(i + 6, j + 21, k + 8, Blocks.sandstone);
        world.setBlock(i + 6, j + 22, k + 2, Blocks.sandstone);
        world.setBlock(i + 6, j + 22, k + 8, Blocks.sandstone);
        world.setBlock(i + 6, j + 23, k + 2, Blocks.sandstone);
        world.setBlock(i + 6, j + 23, k + 8, Blocks.sandstone);
        world.setBlock(i + 6, j + 24, k + 2, Blocks.sandstone);
        world.setBlock(i + 6, j + 24, k + 8, Blocks.sandstone);
        world.setBlock(i + 6, j + 25, k + 2, Blocks.sandstone);
        world.setBlock(i + 6, j + 25, k + 8, Blocks.sandstone);
        world.setBlock(i + 6, j + 26, k + 2, Blocks.sandstone);
        world.setBlock(i + 6, j + 26, k + 8, Blocks.sandstone);
        world.setBlock(i + 6, j + 27, k + 2, Blocks.sandstone);
        world.setBlock(i + 6, j + 27, k + 3, Blocks.sandstone);
        world.setBlock(i + 6, j + 27, k + 4, Blocks.sandstone);
        world.setBlock(i + 6, j + 27, k + 5, Blocks.sandstone);
        world.setBlock(i + 6, j + 27, k + 6, Blocks.sandstone);
        world.setBlock(i + 6, j + 27, k + 7, Blocks.sandstone);
        world.setBlock(i + 6, j + 27, k + 8, Blocks.sandstone);
        world.setBlock(i + 6, j + 28, k + 3, Blocks.sandstone);
        world.setBlock(i + 6, j + 28, k + 4, Blocks.sandstone);
        world.setBlock(i + 6, j + 28, k + 7, Blocks.sandstone);
        world.setBlock(i + 6, j + 29, k + 3, Blocks.sandstone);
        world.setBlock(i + 6, j + 29, k + 7, Blocks.sandstone);
        world.setBlock(i + 6, j + 30, k + 3, Blocks.sandstone);
        world.setBlock(i + 6, j + 30, k + 4, Blocks.sandstone);
        world.setBlock(i + 6, j + 30, k + 5, Blocks.sandstone);
        world.setBlock(i + 6, j + 30, k + 6, Blocks.sandstone);
        world.setBlock(i + 6, j + 30, k + 7, Blocks.sandstone);
        world.setBlock(i + 6, j + 31, k + 4, Blocks.sandstone);
        world.setBlock(i + 6, j + 31, k + 5, Blocks.sandstone);
        world.setBlock(i + 6, j + 31, k + 6, Blocks.sandstone);
        world.setBlock(i + 6, j + 32, k + 4, Blocks.sandstone);
        world.setBlock(i + 6, j + 32, k + 5, Blocks.sandstone);
        world.setBlock(i + 6, j + 32, k + 6, Blocks.sandstone);
        world.setBlock(i + 6, j + 33, k + 4, Blocks.sandstone);
        world.setBlock(i + 6, j + 33, k + 5, Blocks.sandstone);
        world.setBlock(i + 6, j + 33, k + 6, Blocks.sandstone);
        world.setBlock(i + 7, j + 0, k + 2, Blocks.sandstone);
        world.setBlock(i + 7, j + 0, k + 3, Blocks.sandstone);
        world.setBlock(i + 7, j + 0, k + 4, Blocks.sandstone);
        world.setBlock(i + 7, j + 0, k + 5, Blocks.sandstone);
        world.setBlock(i + 7, j + 0, k + 6, Blocks.sandstone);
        world.setBlock(i + 7, j + 0, k + 7, Blocks.sandstone);
        world.setBlock(i + 7, j + 0, k + 8, Blocks.sandstone);
        world.setBlock(i + 7, j + 1, k + 2, Blocks.sandstone);
        world.setBlock(i + 7, j + 1, k + 8, Blocks.sandstone);
        world.setBlock(i + 7, j + 2, k + 2, Blocks.sandstone);
        world.setBlock(i + 7, j + 2, k + 8, Blocks.sandstone);
        world.setBlock(i + 7, j + 3, k + 2, Blocks.sandstone);
        world.setBlock(i + 7, j + 3, k + 6, Blocks.sandstone);
        world.setBlock(i + 7, j + 3, k + 7, Blocks.sandstone);
        world.setBlock(i + 7, j + 3, k + 8, Blocks.sandstone);
        world.setBlock(i + 7, j + 4, k + 2, Blocks.sandstone);
        world.setBlock(i + 7, j + 4, k + 5, Blocks.sandstone);
        world.setBlock(i + 7, j + 4, k + 8, Blocks.sandstone);
        world.setBlock(i + 7, j + 5, k + 2, Blocks.sandstone);
        world.setBlock(i + 7, j + 5, k + 3, Blocks.sandstone);
        world.setBlock(i + 7, j + 5, k + 4, Blocks.sandstone);
        world.setBlock(i + 7, j + 5, k + 8, Blocks.sandstone);
        world.setBlock(i + 7, j + 6, k + 2, Blocks.sandstone);
        world.setBlock(i + 7, j + 6, k + 8, Blocks.sandstone);
        world.setBlock(i + 7, j + 7, k + 2, Blocks.sandstone);
        world.setBlock(i + 7, j + 7, k + 8, Blocks.sandstone);
        world.setBlock(i + 7, j + 8, k + 2, Blocks.sandstone);
        world.setBlock(i + 7, j + 8, k + 8, Blocks.sandstone);
        world.setBlock(i + 7, j + 9, k + 2, Blocks.sandstone);
        world.setBlock(i + 7, j + 9, k + 8, Blocks.sandstone);
        world.setBlock(i + 7, j + 10, k + 2, Blocks.sandstone);
        world.setBlock(i + 7, j + 10, k + 8, Blocks.sandstone);
        world.setBlock(i + 7, j + 11, k + 2, Blocks.sandstone);
        world.setBlock(i + 7, j + 11, k + 6, Blocks.sandstone);
        world.setBlock(i + 7, j + 11, k + 7, Blocks.sandstone);
        world.setBlock(i + 7, j + 11, k + 8, Blocks.sandstone);
        world.setBlock(i + 7, j + 12, k + 2, Blocks.sandstone);
        world.setBlock(i + 7, j + 12, k + 5, Blocks.sandstone);
        world.setBlock(i + 7, j + 12, k + 8, Blocks.sandstone);
        world.setBlock(i + 7, j + 13, k + 2, Blocks.sandstone);
        world.setBlock(i + 7, j + 13, k + 3, Blocks.sandstone);
        world.setBlock(i + 7, j + 13, k + 4, Blocks.sandstone);
        world.setBlock(i + 7, j + 13, k + 8, Blocks.sandstone);
        world.setBlock(i + 7, j + 14, k + 2, Blocks.sandstone);
        world.setBlock(i + 7, j + 14, k + 8, Blocks.sandstone);
        world.setBlock(i + 7, j + 15, k + 2, Blocks.sandstone);
        world.setBlock(i + 7, j + 15, k + 8, Blocks.sandstone);
        world.setBlock(i + 7, j + 16, k + 2, Blocks.sandstone);
        world.setBlock(i + 7, j + 16, k + 8, Blocks.sandstone);
        world.setBlock(i + 7, j + 17, k + 2, Blocks.sandstone);
        world.setBlock(i + 7, j + 17, k + 8, Blocks.sandstone);
        world.setBlock(i + 7, j + 18, k + 2, Blocks.sandstone);
        world.setBlock(i + 7, j + 18, k + 8, Blocks.sandstone);
        world.setBlock(i + 7, j + 19, k + 2, Blocks.sandstone);
        world.setBlock(i + 7, j + 19, k + 6, Blocks.sandstone);
        world.setBlock(i + 7, j + 19, k + 7, Blocks.sandstone);
        world.setBlock(i + 7, j + 19, k + 8, Blocks.sandstone);
        world.setBlock(i + 7, j + 20, k + 2, Blocks.sandstone);
        world.setBlock(i + 7, j + 20, k + 5, Blocks.sandstone);
        world.setBlock(i + 7, j + 20, k + 8, Blocks.sandstone);
        world.setBlock(i + 7, j + 21, k + 2, Blocks.sandstone);
        world.setBlock(i + 7, j + 21, k + 3, Blocks.sandstone);
        world.setBlock(i + 7, j + 21, k + 4, Blocks.sandstone);
        world.setBlock(i + 7, j + 21, k + 8, Blocks.sandstone);
        world.setBlock(i + 7, j + 22, k + 2, Blocks.sandstone);
        world.setBlock(i + 7, j + 22, k + 8, Blocks.sandstone);
        world.setBlock(i + 7, j + 23, k + 2, Blocks.sandstone);
        world.setBlock(i + 7, j + 23, k + 8, Blocks.sandstone);
        world.setBlock(i + 7, j + 24, k + 2, Blocks.sandstone);
        world.setBlock(i + 7, j + 24, k + 8, Blocks.sandstone);
        world.setBlock(i + 7, j + 25, k + 2, Blocks.sandstone);
        world.setBlock(i + 7, j + 25, k + 8, Blocks.sandstone);
        world.setBlock(i + 7, j + 26, k + 2, Blocks.sandstone);
        world.setBlock(i + 7, j + 26, k + 8, Blocks.sandstone);
        world.setBlock(i + 7, j + 27, k + 2, Blocks.sandstone);
        world.setBlock(i + 7, j + 27, k + 3, Blocks.sandstone);
        world.setBlock(i + 7, j + 27, k + 4, Blocks.sandstone);
        world.setBlock(i + 7, j + 27, k + 5, Blocks.sandstone);
        world.setBlock(i + 7, j + 27, k + 6, Blocks.sandstone);
        world.setBlock(i + 7, j + 27, k + 7, Blocks.sandstone);
        world.setBlock(i + 7, j + 27, k + 8, Blocks.sandstone);
        world.setBlock(i + 7, j + 28, k + 3, Blocks.sandstone);
        world.setBlock(i + 7, j + 28, k + 4, Blocks.sandstone);
        world.setBlock(i + 7, j + 28, k + 5, Blocks.sandstone);
        world.setBlock(i + 7, j + 28, k + 6, Blocks.sandstone);
        world.setBlock(i + 7, j + 28, k + 7, Blocks.sandstone);
        world.setBlock(i + 7, j + 29, k + 3, Blocks.sandstone);
        world.setBlock(i + 7, j + 29, k + 4, Blocks.sandstone);
        world.setBlock(i + 7, j + 29, k + 5, Blocks.sandstone);
        world.setBlock(i + 7, j + 29, k + 6, Blocks.sandstone);
        world.setBlock(i + 7, j + 29, k + 7, Blocks.sandstone);
        world.setBlock(i + 7, j + 30, k + 3, Blocks.sandstone);
        world.setBlock(i + 7, j + 30, k + 4, Blocks.sandstone);
        world.setBlock(i + 7, j + 30, k + 5, Blocks.sandstone);
        world.setBlock(i + 7, j + 30, k + 6, Blocks.sandstone);
        world.setBlock(i + 7, j + 30, k + 7, Blocks.sandstone);
        world.setBlock(i + 8, j + 0, k + 2, Blocks.sandstone);
        world.setBlock(i + 8, j + 0, k + 3, Blocks.sandstone);
        world.setBlock(i + 8, j + 0, k + 4, Blocks.sandstone);
        world.setBlock(i + 8, j + 0, k + 5, Blocks.sandstone);
        world.setBlock(i + 8, j + 0, k + 6, Blocks.sandstone);
        world.setBlock(i + 8, j + 0, k + 7, Blocks.sandstone);
        world.setBlock(i + 8, j + 0, k + 8, Blocks.sandstone);
        world.setBlock(i + 8, j + 1, k + 2, Blocks.sandstone);
        world.setBlock(i + 8, j + 1, k + 3, Blocks.sandstone);
        world.setBlock(i + 8, j + 1, k + 4, Blocks.sandstone);
        world.setBlock(i + 8, j + 1, k + 5, Blocks.sandstone);
        world.setBlock(i + 8, j + 1, k + 6, Blocks.sandstone);
        world.setBlock(i + 8, j + 1, k + 7, Blocks.sandstone);
        world.setBlock(i + 8, j + 1, k + 8, Blocks.sandstone);
        world.setBlock(i + 8, j + 2, k + 2, Blocks.sandstone);
        world.setBlock(i + 8, j + 2, k + 3, Blocks.sandstone);
        world.setBlock(i + 8, j + 2, k + 4, Blocks.sandstone);
        world.setBlock(i + 8, j + 2, k + 5, Blocks.sandstone);
        world.setBlock(i + 8, j + 2, k + 6, Blocks.sandstone);
        world.setBlock(i + 8, j + 2, k + 7, Blocks.sandstone);
        world.setBlock(i + 8, j + 2, k + 8, Blocks.sandstone);
        world.setBlock(i + 8, j + 3, k + 2, Blocks.sandstone);
        world.setBlock(i + 8, j + 3, k + 3, Blocks.sandstone);
        world.setBlock(i + 8, j + 3, k + 4, Blocks.sandstone);
        world.setBlock(i + 8, j + 3, k + 5, Blocks.sandstone);
        world.setBlock(i + 8, j + 3, k + 6, Blocks.sandstone);
        world.setBlock(i + 8, j + 3, k + 7, Blocks.sandstone);
        world.setBlock(i + 8, j + 3, k + 8, Blocks.sandstone);
        world.setBlock(i + 8, j + 4, k + 2, Blocks.sandstone);
        world.setBlock(i + 8, j + 4, k + 3, Blocks.sandstone);
        world.setBlock(i + 8, j + 4, k + 4, Blocks.sandstone);
        world.setBlock(i + 8, j + 4, k + 5, Blocks.sandstone);
        world.setBlock(i + 8, j + 4, k + 6, Blocks.sandstone);
        world.setBlock(i + 8, j + 4, k + 7, Blocks.sandstone);
        world.setBlock(i + 8, j + 4, k + 8, Blocks.sandstone);
        world.setBlock(i + 8, j + 5, k + 2, Blocks.sandstone);
        world.setBlock(i + 8, j + 5, k + 3, Blocks.sandstone);
        world.setBlock(i + 8, j + 5, k + 4, Blocks.sandstone);
        world.setBlock(i + 8, j + 5, k + 5, Blocks.sandstone);
        world.setBlock(i + 8, j + 5, k + 6, Blocks.sandstone);
        world.setBlock(i + 8, j + 5, k + 7, Blocks.sandstone);
        world.setBlock(i + 8, j + 5, k + 8, Blocks.sandstone);
        world.setBlock(i + 8, j + 6, k + 2, Blocks.sandstone);
        world.setBlock(i + 8, j + 6, k + 3, Blocks.sandstone);
        world.setBlock(i + 8, j + 6, k + 4, Blocks.sandstone);
        world.setBlock(i + 8, j + 6, k + 5, Blocks.sandstone);
        world.setBlock(i + 8, j + 6, k + 6, Blocks.sandstone);
        world.setBlock(i + 8, j + 6, k + 7, Blocks.sandstone);
        world.setBlock(i + 8, j + 6, k + 8, Blocks.sandstone);
        world.setBlock(i + 8, j + 7, k + 2, Blocks.sandstone);
        world.setBlock(i + 8, j + 7, k + 3, Blocks.sandstone);
        world.setBlock(i + 8, j + 7, k + 4, Blocks.sandstone);
        world.setBlock(i + 8, j + 7, k + 5, Blocks.sandstone);
        world.setBlock(i + 8, j + 7, k + 6, Blocks.sandstone);
        world.setBlock(i + 8, j + 7, k + 7, Blocks.sandstone);
        world.setBlock(i + 8, j + 7, k + 8, Blocks.sandstone);
        world.setBlock(i + 8, j + 8, k + 2, Blocks.sandstone);
        world.setBlock(i + 8, j + 8, k + 3, Blocks.sandstone);
        world.setBlock(i + 8, j + 8, k + 4, Blocks.sandstone);
        world.setBlock(i + 8, j + 8, k + 5, Blocks.sandstone);
        world.setBlock(i + 8, j + 8, k + 6, Blocks.sandstone);
        world.setBlock(i + 8, j + 8, k + 7, Blocks.sandstone);
        world.setBlock(i + 8, j + 8, k + 8, Blocks.sandstone);
        world.setBlock(i + 8, j + 9, k + 2, Blocks.sandstone);
        world.setBlock(i + 8, j + 9, k + 3, Blocks.sandstone);
        world.setBlock(i + 8, j + 9, k + 4, Blocks.sandstone);
        world.setBlock(i + 8, j + 9, k + 5, Blocks.wool, 4, 0);
        world.setBlock(i + 8, j + 9, k + 6, Blocks.sandstone);
        world.setBlock(i + 8, j + 9, k + 7, Blocks.sandstone);
        world.setBlock(i + 8, j + 9, k + 8, Blocks.sandstone);
        world.setBlock(i + 8, j + 10, k + 2, Blocks.sandstone);
        world.setBlock(i + 8, j + 10, k + 3, Blocks.sandstone);
        world.setBlock(i + 8, j + 10, k + 4, Blocks.wool, 4, 0);
        world.setBlock(i + 8, j + 10, k + 5, Blocks.wool, 4, 0);
        world.setBlock(i + 8, j + 10, k + 6, Blocks.wool, 4, 0);
        world.setBlock(i + 8, j + 10, k + 7, Blocks.sandstone);
        world.setBlock(i + 8, j + 10, k + 8, Blocks.sandstone);
        world.setBlock(i + 8, j + 11, k + 2, Blocks.sandstone);
        world.setBlock(i + 8, j + 11, k + 3, Blocks.sandstone);
        world.setBlock(i + 8, j + 11, k + 4, Blocks.wool, 4, 0);
        world.setBlock(i + 8, j + 11, k + 5, Blocks.wool, 4, 0);
        world.setBlock(i + 8, j + 11, k + 6, Blocks.wool, 4, 0);
        world.setBlock(i + 8, j + 11, k + 7, Blocks.sandstone);
        world.setBlock(i + 8, j + 11, k + 8, Blocks.sandstone);
        world.setBlock(i + 8, j + 12, k + 2, Blocks.sandstone);
        world.setBlock(i + 8, j + 12, k + 3, Blocks.sandstone);
        world.setBlock(i + 8, j + 12, k + 4, Blocks.wool, 4, 0);
        world.setBlock(i + 8, j + 12, k + 5, Blocks.wool, 4, 0);
        world.setBlock(i + 8, j + 12, k + 6, Blocks.wool, 4, 0);
        world.setBlock(i + 8, j + 12, k + 7, Blocks.sandstone);
        world.setBlock(i + 8, j + 12, k + 8, Blocks.sandstone);
        world.setBlock(i + 8, j + 13, k + 2, Blocks.sandstone);
        world.setBlock(i + 8, j + 13, k + 3, Blocks.sandstone);
        world.setBlock(i + 8, j + 13, k + 4, Blocks.wool, 4, 0);
        world.setBlock(i + 8, j + 13, k + 5, Blocks.wool, 4, 0);
        world.setBlock(i + 8, j + 13, k + 6, Blocks.wool, 4, 0);
        world.setBlock(i + 8, j + 13, k + 7, Blocks.sandstone);
        world.setBlock(i + 8, j + 13, k + 8, Blocks.sandstone);
        world.setBlock(i + 8, j + 14, k + 2, Blocks.sandstone);
        world.setBlock(i + 8, j + 14, k + 3, Blocks.sandstone);
        world.setBlock(i + 8, j + 14, k + 4, Blocks.sandstone);
        world.setBlock(i + 8, j + 14, k + 5, Blocks.wool, 4, 0);
        world.setBlock(i + 8, j + 14, k + 6, Blocks.sandstone);
        world.setBlock(i + 8, j + 14, k + 7, Blocks.sandstone);
        world.setBlock(i + 8, j + 14, k + 8, Blocks.sandstone);
        world.setBlock(i + 8, j + 15, k + 2, Blocks.sandstone);
        world.setBlock(i + 8, j + 15, k + 3, Blocks.sandstone);
        world.setBlock(i + 8, j + 15, k + 4, Blocks.sandstone);
        world.setBlock(i + 8, j + 15, k + 5, Blocks.sandstone);
        world.setBlock(i + 8, j + 15, k + 6, Blocks.sandstone);
        world.setBlock(i + 8, j + 15, k + 7, Blocks.sandstone);
        world.setBlock(i + 8, j + 15, k + 8, Blocks.sandstone);
        world.setBlock(i + 8, j + 16, k + 2, Blocks.sandstone);
        world.setBlock(i + 8, j + 16, k + 3, Blocks.sandstone);
        world.setBlock(i + 8, j + 16, k + 4, Blocks.sandstone);
        world.setBlock(i + 8, j + 16, k + 5, Blocks.wool, 4, 0);
        world.setBlock(i + 8, j + 16, k + 6, Blocks.sandstone);
        world.setBlock(i + 8, j + 16, k + 7, Blocks.sandstone);
        world.setBlock(i + 8, j + 16, k + 8, Blocks.sandstone);
        world.setBlock(i + 8, j + 17, k + 2, Blocks.sandstone);
        world.setBlock(i + 8, j + 17, k + 3, Blocks.sandstone);
        world.setBlock(i + 8, j + 17, k + 4, Blocks.wool, 4, 0);
        world.setBlock(i + 8, j + 17, k + 5, Blocks.wool, 4, 0);
        world.setBlock(i + 8, j + 17, k + 6, Blocks.wool, 4, 0);
        world.setBlock(i + 8, j + 17, k + 7, Blocks.sandstone);
        world.setBlock(i + 8, j + 17, k + 8, Blocks.sandstone);
        world.setBlock(i + 8, j + 18, k + 2, Blocks.sandstone);
        world.setBlock(i + 8, j + 18, k + 3, Blocks.sandstone);
        world.setBlock(i + 8, j + 18, k + 4, Blocks.wool, 4, 0);
        world.setBlock(i + 8, j + 18, k + 5, Blocks.wool, 4, 0);
        world.setBlock(i + 8, j + 18, k + 6, Blocks.wool, 4, 0);
        world.setBlock(i + 8, j + 18, k + 7, Blocks.sandstone);
        world.setBlock(i + 8, j + 18, k + 8, Blocks.sandstone);
        world.setBlock(i + 8, j + 19, k + 2, Blocks.sandstone);
        world.setBlock(i + 8, j + 19, k + 3, Blocks.sandstone);
        world.setBlock(i + 8, j + 19, k + 4, Blocks.wool, 4, 0);
        world.setBlock(i + 8, j + 19, k + 5, Blocks.wool, 4, 0);
        world.setBlock(i + 8, j + 19, k + 6, Blocks.wool, 4, 0);
        world.setBlock(i + 8, j + 19, k + 7, Blocks.sandstone);
        world.setBlock(i + 8, j + 19, k + 8, Blocks.sandstone);
        world.setBlock(i + 8, j + 20, k + 2, Blocks.sandstone);
        world.setBlock(i + 8, j + 20, k + 3, Blocks.sandstone);
        world.setBlock(i + 8, j + 20, k + 4, Blocks.wool, 4, 0);
        world.setBlock(i + 8, j + 20, k + 5, Blocks.wool, 4, 0);
        world.setBlock(i + 8, j + 20, k + 6, Blocks.wool, 4, 0);
        world.setBlock(i + 8, j + 20, k + 7, Blocks.sandstone);
        world.setBlock(i + 8, j + 20, k + 8, Blocks.sandstone);
        world.setBlock(i + 8, j + 21, k + 2, Blocks.sandstone);
        world.setBlock(i + 8, j + 21, k + 3, Blocks.sandstone);
        world.setBlock(i + 8, j + 21, k + 4, Blocks.sandstone);
        world.setBlock(i + 8, j + 21, k + 5, Blocks.wool, 4, 0);
        world.setBlock(i + 8, j + 21, k + 6, Blocks.sandstone);
        world.setBlock(i + 8, j + 21, k + 7, Blocks.sandstone);
        world.setBlock(i + 8, j + 21, k + 8, Blocks.sandstone);
        world.setBlock(i + 8, j + 22, k + 2, Blocks.sandstone);
        world.setBlock(i + 8, j + 22, k + 3, Blocks.sandstone);
        world.setBlock(i + 8, j + 22, k + 4, Blocks.sandstone);
        world.setBlock(i + 8, j + 22, k + 5, Blocks.sandstone);
        world.setBlock(i + 8, j + 22, k + 6, Blocks.sandstone);
        world.setBlock(i + 8, j + 22, k + 7, Blocks.sandstone);
        world.setBlock(i + 8, j + 22, k + 8, Blocks.sandstone);
        world.setBlock(i + 8, j + 23, k + 2, Blocks.sandstone);
        world.setBlock(i + 8, j + 23, k + 3, Blocks.sandstone);
        world.setBlock(i + 8, j + 23, k + 4, Blocks.sandstone);
        world.setBlock(i + 8, j + 23, k + 5, Blocks.sandstone);
        world.setBlock(i + 8, j + 23, k + 6, Blocks.sandstone);
        world.setBlock(i + 8, j + 23, k + 7, Blocks.sandstone);
        world.setBlock(i + 8, j + 23, k + 8, Blocks.sandstone);
        world.setBlock(i + 8, j + 24, k + 2, Blocks.sandstone);
        world.setBlock(i + 8, j + 24, k + 3, Blocks.sandstone);
        world.setBlock(i + 8, j + 24, k + 4, Blocks.sandstone);
        world.setBlock(i + 8, j + 24, k + 5, Blocks.sandstone);
        world.setBlock(i + 8, j + 24, k + 6, Blocks.sandstone);
        world.setBlock(i + 8, j + 24, k + 7, Blocks.sandstone);
        world.setBlock(i + 8, j + 24, k + 8, Blocks.sandstone);
        world.setBlock(i + 8, j + 25, k + 2, Blocks.sandstone);
        world.setBlock(i + 8, j + 25, k + 3, Blocks.sandstone);
        world.setBlock(i + 8, j + 25, k + 4, Blocks.sandstone);
        world.setBlock(i + 8, j + 25, k + 5, Blocks.sandstone);
        world.setBlock(i + 8, j + 25, k + 6, Blocks.sandstone);
        world.setBlock(i + 8, j + 25, k + 7, Blocks.sandstone);
        world.setBlock(i + 8, j + 25, k + 8, Blocks.sandstone);
        world.setBlock(i + 8, j + 26, k + 2, Blocks.sandstone);
        world.setBlock(i + 8, j + 26, k + 3, Blocks.sandstone);
        world.setBlock(i + 8, j + 26, k + 4, Blocks.sandstone);
        world.setBlock(i + 8, j + 26, k + 5, Blocks.sandstone);
        world.setBlock(i + 8, j + 26, k + 6, Blocks.sandstone);
        world.setBlock(i + 8, j + 26, k + 7, Blocks.sandstone);
        world.setBlock(i + 8, j + 26, k + 8, Blocks.sandstone);
        world.setBlock(i + 8, j + 27, k + 2, Blocks.sandstone);
        world.setBlock(i + 8, j + 27, k + 3, Blocks.sandstone);
        world.setBlock(i + 8, j + 27, k + 4, Blocks.sandstone);
        world.setBlock(i + 8, j + 27, k + 5, Blocks.sandstone);
        world.setBlock(i + 8, j + 27, k + 6, Blocks.sandstone);
        world.setBlock(i + 8, j + 27, k + 7, Blocks.sandstone);
        world.setBlock(i + 8, j + 27, k + 8, Blocks.sandstone);
        world.setBlock(i + 5, j + 21, k + 6, Blocks.torch, 3, 0);
        return true;
    }
}
