

package com.gibby.dungeon.gen;

import net.minecraft.world.gen.feature.*;
import cpw.mods.fml.common.*;
import java.util.*;
import net.minecraft.world.chunk.*;
import net.minecraft.block.*;
import net.minecraft.world.*;
import net.minecraft.init.*;
import com.gibby.dungeon.*;
import net.minecraft.entity.*;
import com.gibby.dungeon.mobs.*;

public class WorldGenMontaneDungeon_4 extends WorldGenerator implements IWorldGenerator
{
    public void generate(final Random random, final int chunkX, final int chunkZ, final World world, final IChunkProvider chunkGenerator, final IChunkProvider chunkProvider) {
    }
    
    public void setBlock(final World world, final int x, final int y, final int z, final Block block, final int metadata) {
        final Block b1 = world.getBlock(x, y, z);
        if (b1.isAir((IBlockAccess)world, x, y, z) || b1.isLeaves((IBlockAccess)world, x, y, z)) {
            world.setBlock(x, y, z, block, metadata, 2);
        }
    }
    
    public boolean generate(final World world, final Random rand, final int i, final int j, final int k) {
        this.setBlock(world, i, j + 1, k + 58, Blocks.air, 4);
        this.setBlock(world, i, j + 2, k + 58, Blocks.air, 4);
        this.setBlock(world, i, j + 3, k + 58, Blocks.air, 4);
        this.setBlock(world, i, j + 4, k + 58, Blocks.air, 4);
        this.setBlock(world, i, j + 38, k + 100, Blocks.cobblestone_wall, 0);
        this.setBlock(world, i, j + 38, k + 101, Blocks.stonebrick, 0);
        this.setBlock(world, i, j + 38, k + 102, Blocks.stonebrick, 0);
        this.setBlock(world, i, j + 38, k + 103, Blocks.stonebrick, 0);
        this.setBlock(world, i, j + 38, k + 104, Blocks.stonebrick, 0);
        this.setBlock(world, i, j + 38, k + 105, Blocks.stonebrick, 0);
        this.setBlock(world, i, j + 38, k + 106, Blocks.stonebrick, 0);
        this.setBlock(world, i, j + 38, k + 107, Blocks.stonebrick, 0);
        this.setBlock(world, i, j + 38, k + 108, Blocks.cobblestone_wall, 0);
        this.setBlock(world, i, j + 39, k + 100, Blocks.cobblestone_wall, 0);
        this.setBlock(world, i, j + 39, k + 101, Blocks.stonebrick, 0);
        this.setBlock(world, i, j + 39, k + 102, Blocks.stonebrick, 0);
        this.setBlock(world, i, j + 39, k + 103, Blocks.stonebrick, 0);
        this.setBlock(world, i, j + 39, k + 104, Blocks.stonebrick, 0);
        this.setBlock(world, i, j + 39, k + 105, Blocks.stonebrick, 0);
        this.setBlock(world, i, j + 39, k + 106, Blocks.stonebrick, 0);
        this.setBlock(world, i, j + 39, k + 107, Blocks.stonebrick, 0);
        this.setBlock(world, i, j + 39, k + 108, Blocks.cobblestone_wall, 0);
        this.setBlock(world, i + 1, j + 38, k + 100, Blocks.cobblestone_wall, 0);
        this.setBlock(world, i + 1, j + 38, k + 101, Blocks.stonebrick, 0);
        this.setBlock(world, i + 1, j + 38, k + 102, Blocks.stonebrick, 0);
        this.setBlock(world, i + 1, j + 38, k + 103, Blocks.stonebrick, 0);
        this.setBlock(world, i + 1, j + 38, k + 104, Blocks.stonebrick, 0);
        this.setBlock(world, i + 1, j + 38, k + 105, Blocks.stonebrick, 0);
        this.setBlock(world, i + 1, j + 38, k + 106, Blocks.stonebrick, 0);
        this.setBlock(world, i + 1, j + 38, k + 107, Blocks.stonebrick, 0);
        this.setBlock(world, i + 1, j + 38, k + 108, Blocks.cobblestone_wall, 0);
        this.setBlock(world, i + 1, j + 39, k + 100, Blocks.cobblestone_wall, 0);
        this.setBlock(world, i + 1, j + 39, k + 101, Blocks.stonebrick, 0);
        this.setBlock(world, i + 1, j + 39, k + 102, Blocks.stonebrick, 0);
        this.setBlock(world, i + 1, j + 39, k + 103, Blocks.stonebrick, 0);
        this.setBlock(world, i + 1, j + 39, k + 104, Blocks.stonebrick, 0);
        this.setBlock(world, i + 1, j + 39, k + 105, Blocks.stonebrick, 0);
        this.setBlock(world, i + 1, j + 39, k + 106, Blocks.stonebrick, 0);
        this.setBlock(world, i + 1, j + 39, k + 107, Blocks.stonebrick, 0);
        this.setBlock(world, i + 1, j + 39, k + 108, Blocks.cobblestone_wall, 0);
        this.setBlock(world, i + 2, j + 38, k + 100, Blocks.cobblestone_wall, 0);
        this.setBlock(world, i + 2, j + 38, k + 101, Blocks.stonebrick, 0);
        this.setBlock(world, i + 2, j + 38, k + 102, Blocks.stonebrick, 0);
        this.setBlock(world, i + 2, j + 38, k + 103, Blocks.stonebrick, 0);
        this.setBlock(world, i + 2, j + 38, k + 104, Blocks.stonebrick, 0);
        this.setBlock(world, i + 2, j + 38, k + 105, Blocks.stonebrick, 0);
        this.setBlock(world, i + 2, j + 38, k + 106, Blocks.stonebrick, 0);
        this.setBlock(world, i + 2, j + 38, k + 107, Blocks.stonebrick, 0);
        this.setBlock(world, i + 2, j + 38, k + 108, Blocks.cobblestone_wall, 0);
        this.setBlock(world, i + 2, j + 39, k + 100, Blocks.cobblestone_wall, 0);
        this.setBlock(world, i + 2, j + 39, k + 101, Blocks.stonebrick, 0);
        this.setBlock(world, i + 2, j + 39, k + 102, Blocks.stonebrick, 0);
        this.setBlock(world, i + 2, j + 39, k + 103, Blocks.stonebrick, 0);
        this.setBlock(world, i + 2, j + 39, k + 104, Blocks.stonebrick, 0);
        this.setBlock(world, i + 2, j + 39, k + 105, Blocks.stonebrick, 0);
        this.setBlock(world, i + 2, j + 39, k + 106, Blocks.stonebrick, 0);
        this.setBlock(world, i + 2, j + 39, k + 107, Blocks.stonebrick, 0);
        this.setBlock(world, i + 2, j + 39, k + 108, Blocks.cobblestone_wall, 0);
        this.setBlock(world, i + 3, j + 38, k + 100, Blocks.stonebrick, 0);
        this.setBlock(world, i + 3, j + 38, k + 101, Blocks.stonebrick, 0);
        this.setBlock(world, i + 3, j + 38, k + 102, Blocks.stonebrick, 0);
        this.setBlock(world, i + 3, j + 38, k + 103, Blocks.stonebrick, 0);
        this.setBlock(world, i + 3, j + 38, k + 104, Blocks.stonebrick, 0);
        this.setBlock(world, i + 3, j + 38, k + 105, Blocks.stonebrick, 0);
        this.setBlock(world, i + 3, j + 38, k + 106, Blocks.stonebrick, 0);
        this.setBlock(world, i + 3, j + 38, k + 107, Blocks.stonebrick, 0);
        this.setBlock(world, i + 3, j + 38, k + 108, Blocks.stonebrick, 0);
        this.setBlock(world, i + 3, j + 39, k + 100, Blocks.stonebrick, 0);
        this.setBlock(world, i + 3, j + 39, k + 101, Blocks.stonebrick, 0);
        this.setBlock(world, i + 3, j + 39, k + 102, Blocks.stonebrick, 0);
        this.setBlock(world, i + 3, j + 39, k + 103, Blocks.stonebrick, 0);
        this.setBlock(world, i + 3, j + 39, k + 104, Blocks.stonebrick, 0);
        this.setBlock(world, i + 3, j + 39, k + 105, Blocks.stonebrick, 0);
        this.setBlock(world, i + 3, j + 39, k + 106, Blocks.stonebrick, 0);
        this.setBlock(world, i + 3, j + 39, k + 107, Blocks.stonebrick, 0);
        this.setBlock(world, i + 3, j + 39, k + 108, Blocks.stonebrick, 0);
        this.setBlock(world, i + 3, j + 40, k + 100, Blocks.stonebrick, 0);
        this.setBlock(world, i + 3, j + 40, k + 108, Blocks.stonebrick, 0);
        this.setBlock(world, i + 3, j + 41, k + 100, Blocks.stonebrick, 0);
        this.setBlock(world, i + 3, j + 41, k + 108, Blocks.stonebrick, 0);
        this.setBlock(world, i + 3, j + 56, k + 40, Blocks.bedrock, 0);
        this.setBlock(world, i + 3, j + 56, k + 41, Blocks.stone, 0);
        this.setBlock(world, i + 4, j + 38, k + 100, Blocks.stonebrick, 0);
        this.setBlock(world, i + 4, j + 38, k + 101, Blocks.stonebrick, 0);
        this.setBlock(world, i + 4, j + 38, k + 102, Blocks.stonebrick, 0);
        this.setBlock(world, i + 4, j + 38, k + 103, Blocks.stonebrick, 0);
        this.setBlock(world, i + 4, j + 38, k + 104, Blocks.stonebrick, 0);
        this.setBlock(world, i + 4, j + 38, k + 105, Blocks.stonebrick, 0);
        this.setBlock(world, i + 4, j + 38, k + 106, Blocks.stonebrick, 0);
        this.setBlock(world, i + 4, j + 38, k + 107, Blocks.stonebrick, 0);
        this.setBlock(world, i + 4, j + 38, k + 108, Blocks.stonebrick, 0);
        this.setBlock(world, i + 4, j + 39, k + 100, Blocks.stonebrick, 0);
        this.setBlock(world, i + 4, j + 39, k + 101, Blocks.stonebrick, 0);
        this.setBlock(world, i + 4, j + 39, k + 102, Blocks.stonebrick, 0);
        this.setBlock(world, i + 4, j + 39, k + 103, Blocks.stonebrick, 0);
        this.setBlock(world, i + 4, j + 39, k + 104, Blocks.stonebrick, 0);
        this.setBlock(world, i + 4, j + 39, k + 105, Blocks.stonebrick, 0);
        this.setBlock(world, i + 4, j + 39, k + 106, Blocks.stonebrick, 0);
        this.setBlock(world, i + 4, j + 39, k + 107, Blocks.stonebrick, 0);
        this.setBlock(world, i + 4, j + 39, k + 108, Blocks.stonebrick, 0);
        this.setBlock(world, i + 4, j + 40, k + 100, Blocks.stonebrick, 0);
        this.setBlock(world, i + 4, j + 40, k + 108, Blocks.stonebrick, 0);
        this.setBlock(world, i + 4, j + 41, k + 100, Blocks.stonebrick, 0);
        this.setBlock(world, i + 4, j + 41, k + 108, Blocks.stonebrick, 0);
        this.setBlock(world, i + 4, j + 55, k + 41, Blocks.bedrock, 0);
        this.setBlock(world, i + 4, j + 55, k + 42, Blocks.stone, 0);
        this.setBlock(world, i + 4, j + 56, k + 39, Blocks.cobblestone, 0);
        this.setBlock(world, i + 4, j + 56, k + 40, Blocks.stone, 0);
        this.setBlock(world, i + 4, j + 56, k + 41, Blocks.bedrock, 0);
        this.setBlock(world, i + 4, j + 56, k + 42, Blocks.cobblestone, 0);
        this.setBlock(world, i + 4, j + 63, k + 26, Blocks.planks, 1);
        this.setBlock(world, i + 5, j + 38, k + 100, Blocks.cobblestone_wall, 0);
        this.setBlock(world, i + 5, j + 38, k + 101, Blocks.stonebrick, 0);
        this.setBlock(world, i + 5, j + 38, k + 102, Blocks.stonebrick, 0);
        this.setBlock(world, i + 5, j + 38, k + 103, Blocks.stonebrick, 0);
        this.setBlock(world, i + 5, j + 38, k + 104, Blocks.stonebrick, 0);
        this.setBlock(world, i + 5, j + 38, k + 105, Blocks.stonebrick, 0);
        this.setBlock(world, i + 5, j + 38, k + 106, Blocks.stonebrick, 0);
        this.setBlock(world, i + 5, j + 38, k + 107, Blocks.stonebrick, 0);
        this.setBlock(world, i + 5, j + 38, k + 108, Blocks.cobblestone_wall, 0);
        this.setBlock(world, i + 5, j + 39, k + 100, Blocks.cobblestone_wall, 0);
        this.setBlock(world, i + 5, j + 39, k + 101, Blocks.stonebrick, 0);
        this.setBlock(world, i + 5, j + 39, k + 102, Blocks.stonebrick, 0);
        this.setBlock(world, i + 5, j + 39, k + 103, Blocks.stonebrick, 0);
        this.setBlock(world, i + 5, j + 39, k + 104, Blocks.stonebrick, 0);
        this.setBlock(world, i + 5, j + 39, k + 105, Blocks.stonebrick, 0);
        this.setBlock(world, i + 5, j + 39, k + 106, Blocks.stonebrick, 0);
        this.setBlock(world, i + 5, j + 39, k + 107, Blocks.stonebrick, 0);
        this.setBlock(world, i + 5, j + 39, k + 108, Blocks.cobblestone_wall, 0);
        this.setBlock(world, i + 5, j + 55, k + 26, Blocks.stone, 0);
        this.setBlock(world, i + 5, j + 55, k + 27, Blocks.stone, 0);
        this.setBlock(world, i + 5, j + 55, k + 28, Blocks.stone, 0);
        this.setBlock(world, i + 5, j + 55, k + 40, Blocks.stone, 0);
        this.setBlock(world, i + 5, j + 55, k + 41, Blocks.stone, 0);
        this.setBlock(world, i + 5, j + 55, k + 42, Blocks.stone, 0);
        this.setBlock(world, i + 5, j + 55, k + 43, Blocks.stone, 0);
        this.setBlock(world, i + 5, j + 55, k + 44, Blocks.stone, 0);
        this.setBlock(world, i + 5, j + 56, k + 26, Blocks.stone, 0);
        this.setBlock(world, i + 5, j + 56, k + 27, Blocks.bedrock, 0);
        this.setBlock(world, i + 5, j + 56, k + 28, Blocks.stone, 0);
        this.setBlock(world, i + 5, j + 56, k + 29, Blocks.stone, 0);
        this.setBlock(world, i + 5, j + 56, k + 30, Blocks.stone, 0);
        this.setBlock(world, i + 5, j + 56, k + 38, Blocks.stone, 0);
        this.setBlock(world, i + 5, j + 56, k + 39, Blocks.stone, 0);
        this.setBlock(world, i + 5, j + 56, k + 40, Blocks.cobblestone, 0);
        this.setBlock(world, i + 5, j + 56, k + 41, Blocks.stone, 0);
        this.setBlock(world, i + 5, j + 56, k + 42, Blocks.stone, 0);
        this.setBlock(world, i + 5, j + 56, k + 43, Blocks.stone, 0);
        this.setBlock(world, i + 5, j + 56, k + 44, Blocks.bedrock, 0);
        this.setBlock(world, i + 5, j + 56, k + 45, Blocks.stone, 0);
        this.setBlock(world, i + 5, j + 56, k + 46, Blocks.bedrock, 0);
        this.setBlock(world, i + 5, j + 56, k + 47, Blocks.stone, 0);
        this.setBlock(world, i + 5, j + 56, k + 48, Blocks.stone, 0);
        this.setBlock(world, i + 5, j + 57, k + 41, Blocks.stone, 0);
        this.setBlock(world, i + 5, j + 57, k + 42, Blocks.stone, 0);
        this.setBlock(world, i + 5, j + 57, k + 43, Blocks.stone, 0);
        this.setBlock(world, i + 5, j + 57, k + 44, Blocks.bedrock, 0);
        this.setBlock(world, i + 5, j + 57, k + 45, Blocks.stone, 0);
        this.setBlock(world, i + 5, j + 57, k + 46, Blocks.bedrock, 0);
        this.setBlock(world, i + 5, j + 57, k + 47, Blocks.stone, 0);
        this.setBlock(world, i + 5, j + 62, k + 25, Blocks.planks, 1);
        this.setBlock(world, i + 5, j + 62, k + 27, Blocks.planks, 1);
        this.setBlock(world, i + 5, j + 63, k + 26, Blocks.planks, 1);
        this.setBlock(world, i + 6, j + 38, k + 100, Blocks.cobblestone_wall, 0);
        this.setBlock(world, i + 6, j + 38, k + 101, Blocks.stonebrick, 0);
        this.setBlock(world, i + 6, j + 38, k + 102, Blocks.stonebrick, 0);
        this.setBlock(world, i + 6, j + 38, k + 103, Blocks.stonebrick, 0);
        this.setBlock(world, i + 6, j + 38, k + 104, Blocks.stonebrick, 0);
        this.setBlock(world, i + 6, j + 38, k + 105, Blocks.stonebrick, 0);
        this.setBlock(world, i + 6, j + 38, k + 106, Blocks.stonebrick, 0);
        this.setBlock(world, i + 6, j + 38, k + 107, Blocks.stonebrick, 0);
        this.setBlock(world, i + 6, j + 38, k + 108, Blocks.cobblestone_wall, 0);
        this.setBlock(world, i + 6, j + 39, k + 100, Blocks.cobblestone_wall, 0);
        this.setBlock(world, i + 6, j + 39, k + 101, Blocks.stonebrick, 0);
        this.setBlock(world, i + 6, j + 39, k + 102, Blocks.stonebrick, 0);
        this.setBlock(world, i + 6, j + 39, k + 103, Blocks.stonebrick, 0);
        this.setBlock(world, i + 6, j + 39, k + 104, Blocks.stonebrick, 0);
        this.setBlock(world, i + 6, j + 39, k + 105, Blocks.stonebrick, 0);
        this.setBlock(world, i + 6, j + 39, k + 106, Blocks.stonebrick, 0);
        this.setBlock(world, i + 6, j + 39, k + 107, Blocks.stonebrick, 0);
        this.setBlock(world, i + 6, j + 39, k + 108, Blocks.cobblestone_wall, 0);
        this.setBlock(world, i + 6, j + 54, k + 41, Blocks.stone, 0);
        this.setBlock(world, i + 6, j + 54, k + 42, Blocks.stone, 0);
        this.setBlock(world, i + 6, j + 54, k + 43, Blocks.stone, 0);
        this.setBlock(world, i + 6, j + 54, k + 44, Blocks.cobblestone, 0);
        this.setBlock(world, i + 6, j + 54, k + 45, Blocks.stone, 0);
        this.setBlock(world, i + 6, j + 55, k + 24, Blocks.stone, 0);
        this.setBlock(world, i + 6, j + 55, k + 25, Blocks.stone, 0);
        this.setBlock(world, i + 6, j + 55, k + 26, Blocks.cobblestone, 0);
        this.setBlock(world, i + 6, j + 55, k + 27, Blocks.stone, 0);
        this.setBlock(world, i + 6, j + 55, k + 28, Blocks.stone, 0);
        this.setBlock(world, i + 6, j + 55, k + 29, Blocks.bedrock, 0);
        this.setBlock(world, i + 6, j + 55, k + 39, Blocks.bedrock, 0);
        this.setBlock(world, i + 6, j + 55, k + 40, Blocks.stone, 0);
        this.setBlock(world, i + 6, j + 55, k + 41, Blocks.stone, 0);
        this.setBlock(world, i + 6, j + 55, k + 42, Blocks.bedrock, 0);
        this.setBlock(world, i + 6, j + 55, k + 43, Blocks.stone, 0);
        this.setBlock(world, i + 6, j + 55, k + 44, Blocks.stone, 0);
        this.setBlock(world, i + 6, j + 55, k + 45, Blocks.stone, 0);
        this.setBlock(world, i + 6, j + 55, k + 46, Blocks.stone, 0);
        this.setBlock(world, i + 6, j + 55, k + 47, Blocks.stone, 0);
        this.setBlock(world, i + 6, j + 55, k + 48, Blocks.cobblestone, 0);
        this.setBlock(world, i + 6, j + 56, k + 24, Blocks.cobblestone, 0);
        this.setBlock(world, i + 6, j + 56, k + 25, Blocks.stone, 0);
        this.setBlock(world, i + 6, j + 56, k + 26, Blocks.stone, 0);
        this.setBlock(world, i + 6, j + 56, k + 27, Blocks.stone, 0);
        this.setBlock(world, i + 6, j + 56, k + 28, Blocks.stone, 0);
        this.setBlock(world, i + 6, j + 56, k + 29, Blocks.stone, 0);
        this.setBlock(world, i + 6, j + 56, k + 30, Blocks.stone, 0);
        this.setBlock(world, i + 6, j + 56, k + 31, Blocks.stone, 0);
        this.setBlock(world, i + 6, j + 56, k + 35, Blocks.stone, 0);
        this.setBlock(world, i + 6, j + 56, k + 36, Blocks.stone, 0);
        this.setBlock(world, i + 6, j + 56, k + 37, Blocks.bedrock, 0);
        this.setBlock(world, i + 6, j + 56, k + 38, Blocks.stone, 0);
        this.setBlock(world, i + 6, j + 56, k + 39, Blocks.stone, 0);
        this.setBlock(world, i + 6, j + 56, k + 40, Blocks.stone, 0);
        this.setBlock(world, i + 6, j + 56, k + 41, Blocks.stone, 0);
        this.setBlock(world, i + 6, j + 56, k + 42, Blocks.stone, 0);
        this.setBlock(world, i + 6, j + 56, k + 43, Blocks.stone, 0);
        this.setBlock(world, i + 6, j + 56, k + 44, Blocks.stone, 0);
        this.setBlock(world, i + 6, j + 56, k + 45, Blocks.stone, 0);
        this.setBlock(world, i + 6, j + 56, k + 46, Blocks.stone, 0);
        this.setBlock(world, i + 6, j + 56, k + 47, Blocks.stone, 0);
        this.setBlock(world, i + 6, j + 56, k + 48, Blocks.stone, 0);
        this.setBlock(world, i + 6, j + 57, k + 41, Blocks.stone, 0);
        this.setBlock(world, i + 6, j + 57, k + 42, Blocks.stone, 0);
        this.setBlock(world, i + 6, j + 57, k + 43, Blocks.stone, 0);
        this.setBlock(world, i + 6, j + 57, k + 44, Blocks.stone, 0);
        this.setBlock(world, i + 6, j + 57, k + 45, Blocks.stone, 0);
        this.setBlock(world, i + 6, j + 57, k + 46, Blocks.stone, 0);
        this.setBlock(world, i + 6, j + 57, k + 47, Blocks.stone, 0);
        this.setBlock(world, i + 6, j + 57, k + 48, Blocks.stone, 0);
        this.setBlock(world, i + 6, j + 58, k + 41, Blocks.stone, 0);
        this.setBlock(world, i + 6, j + 58, k + 42, Blocks.stone, 0);
        this.setBlock(world, i + 6, j + 58, k + 43, Blocks.stone, 0);
        this.setBlock(world, i + 6, j + 58, k + 44, Blocks.stone, 0);
        this.setBlock(world, i + 6, j + 58, k + 45, Blocks.stone, 0);
        this.setBlock(world, i + 6, j + 58, k + 46, Blocks.stone, 0);
        this.setBlock(world, i + 6, j + 61, k + 24, Blocks.planks, 1);
        this.setBlock(world, i + 6, j + 61, k + 28, Blocks.planks, 1);
        this.setBlock(world, i + 6, j + 62, k + 25, Blocks.planks, 1);
        this.setBlock(world, i + 6, j + 62, k + 27, Blocks.planks, 1);
        this.setBlock(world, i + 6, j + 63, k + 26, Blocks.planks, 1);
        this.setBlock(world, i + 7, j + 38, k + 100, Blocks.cobblestone_wall, 0);
        this.setBlock(world, i + 7, j + 38, k + 101, Blocks.stonebrick, 0);
        this.setBlock(world, i + 7, j + 38, k + 102, Blocks.stonebrick, 0);
        this.setBlock(world, i + 7, j + 38, k + 103, Blocks.stonebrick, 0);
        this.setBlock(world, i + 7, j + 38, k + 104, Blocks.stonebrick, 0);
        this.setBlock(world, i + 7, j + 38, k + 105, Blocks.stonebrick, 0);
        this.setBlock(world, i + 7, j + 38, k + 106, Blocks.stonebrick, 0);
        this.setBlock(world, i + 7, j + 38, k + 107, Blocks.stonebrick, 0);
        this.setBlock(world, i + 7, j + 38, k + 108, Blocks.cobblestone_wall, 0);
        this.setBlock(world, i + 7, j + 39, k + 100, Blocks.cobblestone_wall, 0);
        this.setBlock(world, i + 7, j + 39, k + 101, Blocks.stonebrick, 0);
        this.setBlock(world, i + 7, j + 39, k + 102, Blocks.stonebrick, 0);
        this.setBlock(world, i + 7, j + 39, k + 103, Blocks.stonebrick, 0);
        this.setBlock(world, i + 7, j + 39, k + 104, Blocks.stonebrick, 0);
        this.setBlock(world, i + 7, j + 39, k + 105, Blocks.stonebrick, 0);
        this.setBlock(world, i + 7, j + 39, k + 106, Blocks.stonebrick, 0);
        this.setBlock(world, i + 7, j + 39, k + 107, Blocks.stonebrick, 0);
        this.setBlock(world, i + 7, j + 39, k + 108, Blocks.cobblestone_wall, 0);
        this.setBlock(world, i + 7, j + 54, k + 25, Blocks.stone, 0);
        this.setBlock(world, i + 7, j + 54, k + 26, Blocks.bedrock, 0);
        this.setBlock(world, i + 7, j + 54, k + 27, Blocks.cobblestone, 0);
        this.setBlock(world, i + 7, j + 54, k + 28, Blocks.stone, 0);
        this.setBlock(world, i + 7, j + 54, k + 40, Blocks.stone, 0);
        this.setBlock(world, i + 7, j + 54, k + 41, Blocks.bedrock, 0);
        this.setBlock(world, i + 7, j + 54, k + 42, Blocks.bedrock, 0);
        this.setBlock(world, i + 7, j + 54, k + 43, Blocks.stone, 0);
        this.setBlock(world, i + 7, j + 54, k + 44, Blocks.stone, 0);
        this.setBlock(world, i + 7, j + 54, k + 45, Blocks.stone, 0);
        this.setBlock(world, i + 7, j + 54, k + 46, Blocks.cobblestone, 0);
        this.setBlock(world, i + 7, j + 55, k + 24, Blocks.stone, 0);
        this.setBlock(world, i + 7, j + 55, k + 25, Blocks.cobblestone, 0);
        this.setBlock(world, i + 7, j + 55, k + 26, Blocks.bedrock, 0);
        this.setBlock(world, i + 7, j + 55, k + 27, Blocks.cobblestone, 0);
        this.setBlock(world, i + 7, j + 55, k + 28, Blocks.stone, 0);
        this.setBlock(world, i + 7, j + 55, k + 29, Blocks.bedrock, 0);
        this.setBlock(world, i + 7, j + 55, k + 30, Blocks.cobblestone, 0);
        this.setBlock(world, i + 7, j + 55, k + 35, Blocks.stone, 0);
        this.setBlock(world, i + 7, j + 55, k + 36, Blocks.stone, 0);
        this.setBlock(world, i + 7, j + 55, k + 37, Blocks.stone, 0);
        this.setBlock(world, i + 7, j + 55, k + 38, Blocks.stone, 0);
        this.setBlock(world, i + 7, j + 55, k + 39, Blocks.stone, 0);
        this.setBlock(world, i + 7, j + 55, k + 40, Blocks.stone, 0);
        this.setBlock(world, i + 7, j + 55, k + 41, Blocks.stone, 0);
        this.setBlock(world, i + 7, j + 55, k + 42, Blocks.stone, 0);
        this.setBlock(world, i + 7, j + 55, k + 43, Blocks.stone, 0);
        this.setBlock(world, i + 7, j + 55, k + 44, Blocks.cobblestone, 0);
        this.setBlock(world, i + 7, j + 55, k + 45, Blocks.bedrock, 0);
        this.setBlock(world, i + 7, j + 55, k + 46, Blocks.stone, 0);
        this.setBlock(world, i + 7, j + 55, k + 47, Blocks.stone, 0);
        this.setBlock(world, i + 7, j + 55, k + 48, Blocks.stone, 0);
        this.setBlock(world, i + 7, j + 55, k + 49, Blocks.bedrock, 0);
        this.setBlock(world, i + 7, j + 55, k + 50, Blocks.cobblestone, 0);
        this.setBlock(world, i + 7, j + 55, k + 51, Blocks.cobblestone, 0);
        this.setBlock(world, i + 7, j + 55, k + 53, Blocks.stone, 0);
        this.setBlock(world, i + 7, j + 56, k + 24, Blocks.stone, 0);
        this.setBlock(world, i + 7, j + 56, k + 25, Blocks.cobblestone, 0);
        this.setBlock(world, i + 7, j + 56, k + 26, Blocks.cobblestone, 0);
        this.setBlock(world, i + 7, j + 56, k + 27, Blocks.bedrock, 0);
        this.setBlock(world, i + 7, j + 56, k + 28, Blocks.stone, 0);
        this.setBlock(world, i + 7, j + 56, k + 29, Blocks.cobblestone, 0);
        this.setBlock(world, i + 7, j + 56, k + 30, Blocks.stone, 0);
        this.setBlock(world, i + 7, j + 56, k + 31, Blocks.cobblestone, 0);
        this.setBlock(world, i + 7, j + 56, k + 35, Blocks.stone, 0);
        this.setBlock(world, i + 7, j + 56, k + 36, Blocks.stone, 0);
        this.setBlock(world, i + 7, j + 56, k + 37, Blocks.stone, 0);
        this.setBlock(world, i + 7, j + 56, k + 38, Blocks.stone, 0);
        this.setBlock(world, i + 7, j + 56, k + 39, Blocks.stone, 0);
        this.setBlock(world, i + 7, j + 56, k + 40, Blocks.stone, 0);
        this.setBlock(world, i + 7, j + 56, k + 41, Blocks.cobblestone, 0);
        this.setBlock(world, i + 7, j + 56, k + 42, Blocks.stone, 0);
        this.setBlock(world, i + 7, j + 56, k + 43, Blocks.stone, 0);
        this.setBlock(world, i + 7, j + 56, k + 44, Blocks.stone, 0);
        this.setBlock(world, i + 7, j + 56, k + 45, Blocks.stone, 0);
        this.setBlock(world, i + 7, j + 56, k + 46, Blocks.stone, 0);
        this.setBlock(world, i + 7, j + 56, k + 47, Blocks.stone, 0);
        this.setBlock(world, i + 7, j + 56, k + 48, Blocks.stone, 0);
        this.setBlock(world, i + 7, j + 56, k + 49, Blocks.stone, 0);
        this.setBlock(world, i + 7, j + 56, k + 50, Blocks.stone, 0);
        this.setBlock(world, i + 7, j + 56, k + 51, Blocks.cobblestone, 0);
        this.setBlock(world, i + 7, j + 56, k + 52, Blocks.stone, 0);
        this.setBlock(world, i + 7, j + 56, k + 53, Blocks.stone, 0);
        this.setBlock(world, i + 7, j + 57, k + 31, Blocks.cobblestone, 0);
        this.setBlock(world, i + 7, j + 57, k + 32, Blocks.stone, 0);
        this.setBlock(world, i + 7, j + 57, k + 33, Blocks.stone, 0);
        this.setBlock(world, i + 7, j + 57, k + 34, Blocks.stone, 0);
        this.setBlock(world, i + 7, j + 57, k + 35, Blocks.bedrock, 0);
        this.setBlock(world, i + 7, j + 57, k + 36, Blocks.stone, 0);
        this.setBlock(world, i + 7, j + 57, k + 38, Blocks.stone, 0);
        this.setBlock(world, i + 7, j + 57, k + 39, Blocks.stone, 0);
        this.setBlock(world, i + 7, j + 57, k + 40, Blocks.stone, 0);
        this.setBlock(world, i + 7, j + 57, k + 41, Blocks.cobblestone, 0);
        this.setBlock(world, i + 7, j + 57, k + 42, Blocks.stone, 0);
        this.setBlock(world, i + 7, j + 57, k + 43, Blocks.stone, 0);
        this.setBlock(world, i + 7, j + 57, k + 44, Blocks.stone, 0);
        this.setBlock(world, i + 7, j + 57, k + 45, Blocks.stone, 0);
        this.setBlock(world, i + 7, j + 57, k + 46, Blocks.stone, 0);
        this.setBlock(world, i + 7, j + 57, k + 47, Blocks.stone, 0);
        this.setBlock(world, i + 7, j + 57, k + 48, Blocks.stone, 0);
        this.setBlock(world, i + 7, j + 57, k + 49, Blocks.stone, 0);
        this.setBlock(world, i + 7, j + 57, k + 50, Blocks.stone, 0);
        this.setBlock(world, i + 7, j + 57, k + 52, Blocks.stone, 0);
        this.setBlock(world, i + 7, j + 58, k + 38, Blocks.stone, 0);
        this.setBlock(world, i + 7, j + 58, k + 39, Blocks.stone, 0);
        this.setBlock(world, i + 7, j + 58, k + 40, Blocks.stone, 0);
        this.setBlock(world, i + 7, j + 58, k + 41, Blocks.cobblestone, 0);
        this.setBlock(world, i + 7, j + 58, k + 42, Blocks.stone, 0);
        this.setBlock(world, i + 7, j + 58, k + 43, Blocks.stone, 0);
        this.setBlock(world, i + 7, j + 58, k + 44, Blocks.stone, 0);
        this.setBlock(world, i + 7, j + 58, k + 45, Blocks.stone, 0);
        this.setBlock(world, i + 7, j + 58, k + 46, Blocks.stone, 0);
        this.setBlock(world, i + 7, j + 58, k + 47, Blocks.stone, 0);
        this.setBlock(world, i + 7, j + 58, k + 48, Blocks.stone, 0);
        this.setBlock(world, i + 7, j + 58, k + 49, Blocks.stone, 0);
        this.setBlock(world, i + 7, j + 59, k + 38, Blocks.stone, 0);
        this.setBlock(world, i + 7, j + 59, k + 39, Blocks.stone, 0);
        this.setBlock(world, i + 7, j + 59, k + 40, Blocks.stone, 0);
        this.setBlock(world, i + 7, j + 59, k + 41, Blocks.cobblestone, 0);
        this.setBlock(world, i + 7, j + 59, k + 42, Blocks.stone, 0);
        this.setBlock(world, i + 7, j + 59, k + 43, Blocks.stone, 0);
        this.setBlock(world, i + 7, j + 59, k + 44, Blocks.stone, 0);
        this.setBlock(world, i + 7, j + 59, k + 45, Blocks.stone, 0);
        this.setBlock(world, i + 7, j + 60, k + 23, Blocks.planks, 1);
        this.setBlock(world, i + 7, j + 60, k + 29, Blocks.planks, 1);
        this.setBlock(world, i + 7, j + 61, k + 24, Blocks.planks, 1);
        this.setBlock(world, i + 7, j + 61, k + 28, Blocks.planks, 1);
        this.setBlock(world, i + 7, j + 62, k + 25, Blocks.planks, 1);
        this.setBlock(world, i + 7, j + 62, k + 27, Blocks.planks, 1);
        this.setBlock(world, i + 7, j + 63, k + 26, Blocks.planks, 1);
        this.setBlock(world, i + 8, j + 38, k + 100, Blocks.stonebrick, 0);
        this.setBlock(world, i + 8, j + 38, k + 101, Blocks.stonebrick, 0);
        this.setBlock(world, i + 8, j + 38, k + 102, Blocks.stonebrick, 0);
        this.setBlock(world, i + 8, j + 38, k + 103, Blocks.stonebrick, 0);
        this.setBlock(world, i + 8, j + 38, k + 104, Blocks.stonebrick, 0);
        this.setBlock(world, i + 8, j + 38, k + 105, Blocks.stonebrick, 0);
        this.setBlock(world, i + 8, j + 38, k + 106, Blocks.stonebrick, 0);
        this.setBlock(world, i + 8, j + 38, k + 107, Blocks.stonebrick, 0);
        this.setBlock(world, i + 8, j + 38, k + 108, Blocks.stonebrick, 0);
        this.setBlock(world, i + 8, j + 39, k + 100, Blocks.stonebrick, 0);
        this.setBlock(world, i + 8, j + 39, k + 101, Blocks.stonebrick, 0);
        this.setBlock(world, i + 8, j + 39, k + 102, Blocks.stonebrick, 0);
        this.setBlock(world, i + 8, j + 39, k + 103, Blocks.stonebrick, 0);
        this.setBlock(world, i + 8, j + 39, k + 104, Blocks.stonebrick, 0);
        this.setBlock(world, i + 8, j + 39, k + 105, Blocks.stonebrick, 0);
        this.setBlock(world, i + 8, j + 39, k + 106, Blocks.stonebrick, 0);
        this.setBlock(world, i + 8, j + 39, k + 107, Blocks.stonebrick, 0);
        this.setBlock(world, i + 8, j + 39, k + 108, Blocks.stonebrick, 0);
        this.setBlock(world, i + 8, j + 40, k + 100, Blocks.stonebrick, 0);
        this.setBlock(world, i + 8, j + 40, k + 108, Blocks.stonebrick, 0);
        this.setBlock(world, i + 8, j + 41, k + 100, Blocks.stonebrick, 0);
        this.setBlock(world, i + 8, j + 41, k + 108, Blocks.stonebrick, 0);
        this.setBlock(world, i + 8, j + 53, k + 41, Blocks.stone, 0);
        this.setBlock(world, i + 8, j + 53, k + 42, Blocks.stone, 0);
        this.setBlock(world, i + 8, j + 53, k + 43, Blocks.bedrock, 0);
        this.setBlock(world, i + 8, j + 53, k + 44, Blocks.stone, 0);
        this.setBlock(world, i + 8, j + 53, k + 45, Blocks.stone, 0);
        this.setBlock(world, i + 8, j + 54, k + 24, Blocks.cobblestone, 0);
        this.setBlock(world, i + 8, j + 54, k + 25, Blocks.stone, 0);
        this.setBlock(world, i + 8, j + 54, k + 26, Blocks.stone, 0);
        this.setBlock(world, i + 8, j + 54, k + 27, Blocks.stone, 0);
        this.setBlock(world, i + 8, j + 54, k + 28, Blocks.stone, 0);
        this.setBlock(world, i + 8, j + 54, k + 29, Blocks.stone, 0);
        this.setBlock(world, i + 8, j + 54, k + 39, Blocks.cobblestone, 0);
        this.setBlock(world, i + 8, j + 54, k + 40, Blocks.stone, 0);
        this.setBlock(world, i + 8, j + 54, k + 41, Blocks.stone, 0);
        this.setBlock(world, i + 8, j + 54, k + 42, Blocks.stone, 0);
        this.setBlock(world, i + 8, j + 54, k + 43, Blocks.bedrock, 0);
        this.setBlock(world, i + 8, j + 54, k + 44, Blocks.cobblestone, 0);
        this.setBlock(world, i + 8, j + 54, k + 45, Blocks.stone, 0);
        this.setBlock(world, i + 8, j + 54, k + 46, Blocks.stone, 0);
        this.setBlock(world, i + 8, j + 54, k + 47, Blocks.bedrock, 0);
        this.setBlock(world, i + 8, j + 54, k + 48, Blocks.stone, 0);
        this.setBlock(world, i + 8, j + 55, k + 24, Blocks.stone, 0);
        this.setBlock(world, i + 8, j + 55, k + 25, Blocks.stone, 0);
        this.setBlock(world, i + 8, j + 55, k + 26, Blocks.stone, 0);
        this.setBlock(world, i + 8, j + 55, k + 27, Blocks.stone, 0);
        this.setBlock(world, i + 8, j + 55, k + 28, Blocks.bedrock, 0);
        this.setBlock(world, i + 8, j + 55, k + 29, Blocks.stone, 0);
        this.setBlock(world, i + 8, j + 55, k + 31, Blocks.stone, 0);
        this.setBlock(world, i + 8, j + 55, k + 34, Blocks.stone, 0);
        this.setBlock(world, i + 8, j + 55, k + 35, Blocks.bedrock, 0);
        this.setBlock(world, i + 8, j + 55, k + 36, Blocks.bedrock, 0);
        this.setBlock(world, i + 8, j + 55, k + 37, Blocks.stone, 0);
        this.setBlock(world, i + 8, j + 55, k + 38, Blocks.stone, 0);
        this.setBlock(world, i + 8, j + 55, k + 39, Blocks.stone, 0);
        this.setBlock(world, i + 8, j + 55, k + 40, Blocks.stone, 0);
        this.setBlock(world, i + 8, j + 55, k + 41, Blocks.stone, 0);
        this.setBlock(world, i + 8, j + 55, k + 42, Blocks.stone, 0);
        this.setBlock(world, i + 8, j + 55, k + 43, Blocks.bedrock, 0);
        this.setBlock(world, i + 8, j + 55, k + 44, Blocks.stone, 0);
        this.setBlock(world, i + 8, j + 55, k + 45, Blocks.stone, 0);
        this.setBlock(world, i + 8, j + 55, k + 46, Blocks.stone, 0);
        this.setBlock(world, i + 8, j + 55, k + 47, Blocks.stone, 0);
        this.setBlock(world, i + 8, j + 55, k + 48, Blocks.bedrock, 0);
        this.setBlock(world, i + 8, j + 55, k + 49, Blocks.stone, 0);
        this.setBlock(world, i + 8, j + 55, k + 50, Blocks.cobblestone, 0);
        this.setBlock(world, i + 8, j + 55, k + 51, Blocks.stone, 0);
        this.setBlock(world, i + 8, j + 55, k + 52, Blocks.stone, 0);
        this.setBlock(world, i + 8, j + 55, k + 53, Blocks.stone, 0);
        this.setBlock(world, i + 8, j + 56, k + 23, Blocks.stone, 0);
        this.setBlock(world, i + 8, j + 56, k + 24, Blocks.stone, 0);
        this.setBlock(world, i + 8, j + 56, k + 25, Blocks.stone, 0);
        this.setBlock(world, i + 8, j + 56, k + 26, Blocks.stone, 0);
        this.setBlock(world, i + 8, j + 56, k + 27, Blocks.stone, 0);
        this.setBlock(world, i + 8, j + 56, k + 28, Blocks.stone, 0);
        this.setBlock(world, i + 8, j + 56, k + 29, Blocks.stone, 0);
        this.setBlock(world, i + 8, j + 56, k + 30, Blocks.stone, 0);
        this.setBlock(world, i + 8, j + 56, k + 31, Blocks.stone, 0);
        this.setBlock(world, i + 8, j + 56, k + 34, Blocks.stone, 0);
        this.setBlock(world, i + 8, j + 56, k + 35, Blocks.stone, 0);
        this.setBlock(world, i + 8, j + 56, k + 36, Blocks.stone, 0);
        this.setBlock(world, i + 8, j + 56, k + 37, Blocks.stone, 0);
        this.setBlock(world, i + 8, j + 56, k + 38, Blocks.stone, 0);
        this.setBlock(world, i + 8, j + 56, k + 39, Blocks.stone, 0);
        this.setBlock(world, i + 8, j + 56, k + 40, Blocks.stone, 0);
        this.setBlock(world, i + 8, j + 56, k + 41, Blocks.stone, 0);
        this.setBlock(world, i + 8, j + 56, k + 42, Blocks.stone, 0);
        this.setBlock(world, i + 8, j + 56, k + 43, Blocks.stone, 0);
        this.setBlock(world, i + 8, j + 56, k + 44, Blocks.stone, 0);
        this.setBlock(world, i + 8, j + 56, k + 45, Blocks.stone, 0);
        this.setBlock(world, i + 8, j + 56, k + 46, Blocks.stone, 0);
        this.setBlock(world, i + 8, j + 56, k + 47, Blocks.stone, 0);
        this.setBlock(world, i + 8, j + 56, k + 48, Blocks.stone, 0);
        this.setBlock(world, i + 8, j + 56, k + 49, Blocks.stone, 0);
        this.setBlock(world, i + 8, j + 56, k + 50, Blocks.stone, 0);
        this.setBlock(world, i + 8, j + 56, k + 51, Blocks.stone, 0);
        this.setBlock(world, i + 8, j + 56, k + 52, Blocks.stone, 0);
        this.setBlock(world, i + 8, j + 56, k + 53, Blocks.stone, 0);
        this.setBlock(world, i + 8, j + 56, k + 54, Blocks.stone, 0);
        this.setBlock(world, i + 8, j + 56, k + 55, Blocks.stone, 0);
        this.setBlock(world, i + 8, j + 56, k + 56, Blocks.cobblestone, 0);
        this.setBlock(world, i + 8, j + 56, k + 57, Blocks.stone, 0);
        this.setBlock(world, i + 8, j + 56, k + 58, Blocks.bedrock, 0);
        this.setBlock(world, i + 8, j + 57, k + 23, Blocks.log, 1);
        this.setBlock(world, i + 8, j + 57, k + 24, Blocks.planks, 1);
        this.setBlock(world, i + 8, j + 57, k + 25, Blocks.planks, 1);
        this.setBlock(world, i + 8, j + 57, k + 26, Blocks.planks, 1);
        this.setBlock(world, i + 8, j + 57, k + 27, Blocks.planks, 1);
        this.setBlock(world, i + 8, j + 57, k + 28, Blocks.planks, 1);
        this.setBlock(world, i + 8, j + 57, k + 29, Blocks.log, 1);
        this.setBlock(world, i + 8, j + 57, k + 30, Blocks.stone, 0);
        this.setBlock(world, i + 8, j + 57, k + 31, Blocks.stone, 0);
        this.setBlock(world, i + 8, j + 57, k + 34, Blocks.stone, 0);
        this.setBlock(world, i + 8, j + 57, k + 35, Blocks.stone, 0);
        this.setBlock(world, i + 8, j + 57, k + 36, Blocks.stone, 0);
        this.setBlock(world, i + 8, j + 57, k + 37, Blocks.stone, 0);
        this.setBlock(world, i + 8, j + 57, k + 38, Blocks.stone, 0);
        this.setBlock(world, i + 8, j + 57, k + 39, Blocks.stone, 0);
        this.setBlock(world, i + 8, j + 57, k + 40, Blocks.stone, 0);
        this.setBlock(world, i + 8, j + 57, k + 41, Blocks.stone, 0);
        this.setBlock(world, i + 8, j + 57, k + 42, Blocks.stone, 0);
        this.setBlock(world, i + 8, j + 57, k + 43, Blocks.stone, 0);
        this.setBlock(world, i + 8, j + 57, k + 44, Blocks.stone, 0);
        this.setBlock(world, i + 8, j + 57, k + 45, Blocks.stone, 0);
        this.setBlock(world, i + 8, j + 57, k + 46, Blocks.stone, 0);
        this.setBlock(world, i + 8, j + 57, k + 47, Blocks.stone, 0);
        this.setBlock(world, i + 8, j + 57, k + 48, Blocks.stone, 0);
        this.setBlock(world, i + 8, j + 57, k + 49, Blocks.stone, 0);
        this.setBlock(world, i + 8, j + 57, k + 50, Blocks.stone, 0);
        this.setBlock(world, i + 8, j + 57, k + 51, Blocks.stone, 0);
        this.setBlock(world, i + 8, j + 57, k + 52, Blocks.stone, 0);
        this.setBlock(world, i + 8, j + 57, k + 53, Blocks.stone, 0);
        this.setBlock(world, i + 8, j + 57, k + 54, Blocks.bedrock, 0);
        this.setBlock(world, i + 8, j + 58, k + 23, Blocks.log, 1);
        this.setBlock(world, i + 8, j + 58, k + 24, Blocks.glass_pane, 0);
        this.setBlock(world, i + 8, j + 58, k + 25, Blocks.planks, 1);
        this.setBlock(world, i + 8, j + 58, k + 26, Blocks.planks, 0);
        this.setBlock(world, i + 8, j + 58, k + 27, Blocks.planks, 1);
        this.setBlock(world, i + 8, j + 58, k + 28, Blocks.glass_pane, 0);
        this.setBlock(world, i + 8, j + 58, k + 29, Blocks.log, 1);
        this.setBlock(world, i + 8, j + 58, k + 31, Blocks.stone, 0);
        this.setBlock(world, i + 8, j + 58, k + 32, Blocks.stone, 0);
        this.setBlock(world, i + 8, j + 58, k + 33, Blocks.bedrock, 0);
        this.setBlock(world, i + 8, j + 58, k + 34, Blocks.stone, 0);
        this.setBlock(world, i + 8, j + 58, k + 35, Blocks.stone, 0);
        this.setBlock(world, i + 8, j + 58, k + 36, Blocks.stone, 0);
        this.setBlock(world, i + 8, j + 58, k + 37, Blocks.stone, 0);
        this.setBlock(world, i + 8, j + 58, k + 38, Blocks.stone, 0);
        this.setBlock(world, i + 8, j + 58, k + 39, Blocks.stone, 0);
        this.setBlock(world, i + 8, j + 58, k + 40, Blocks.stone, 0);
        this.setBlock(world, i + 8, j + 58, k + 41, Blocks.stone, 0);
        this.setBlock(world, i + 8, j + 58, k + 42, Blocks.stone, 0);
        this.setBlock(world, i + 8, j + 58, k + 43, Blocks.stone, 0);
        this.setBlock(world, i + 8, j + 58, k + 44, Blocks.stone, 0);
        this.setBlock(world, i + 8, j + 58, k + 45, Blocks.stone, 0);
        this.setBlock(world, i + 8, j + 58, k + 46, Blocks.stone, 0);
        this.setBlock(world, i + 8, j + 58, k + 47, Blocks.stone, 0);
        this.setBlock(world, i + 8, j + 58, k + 48, Blocks.stone, 0);
        this.setBlock(world, i + 8, j + 58, k + 49, Blocks.stone, 0);
        this.setBlock(world, i + 8, j + 58, k + 51, Blocks.stone, 0);
        this.setBlock(world, i + 8, j + 59, k + 23, Blocks.log, 1);
        this.setBlock(world, i + 8, j + 59, k + 24, Blocks.glass_pane, 0);
        this.setBlock(world, i + 8, j + 59, k + 25, Blocks.planks, 1);
        this.setBlock(world, i + 8, j + 59, k + 26, Blocks.planks, 1);
        this.setBlock(world, i + 8, j + 59, k + 27, Blocks.planks, 1);
        this.setBlock(world, i + 8, j + 59, k + 28, Blocks.glass_pane, 0);
        this.setBlock(world, i + 8, j + 59, k + 29, Blocks.log, 1);
        this.setBlock(world, i + 8, j + 59, k + 35, Blocks.stone, 0);
        this.setBlock(world, i + 8, j + 59, k + 36, Blocks.stone, 0);
        this.setBlock(world, i + 8, j + 59, k + 37, Blocks.stone, 0);
        this.setBlock(world, i + 8, j + 59, k + 38, Blocks.stone, 0);
        this.setBlock(world, i + 8, j + 59, k + 39, Blocks.stone, 0);
        this.setBlock(world, i + 8, j + 59, k + 40, Blocks.stone, 0);
        this.setBlock(world, i + 8, j + 59, k + 41, Blocks.stone, 0);
        this.setBlock(world, i + 8, j + 59, k + 42, Blocks.stone, 0);
        this.setBlock(world, i + 8, j + 59, k + 43, Blocks.stone, 0);
        this.setBlock(world, i + 8, j + 59, k + 44, Blocks.stone, 0);
        this.setBlock(world, i + 8, j + 59, k + 45, Blocks.stone, 0);
        this.setBlock(world, i + 8, j + 59, k + 46, Blocks.stone, 0);
        this.setBlock(world, i + 8, j + 59, k + 47, Blocks.stone, 0);
        this.setBlock(world, i + 8, j + 59, k + 48, Blocks.stone, 0);
        this.setBlock(world, i + 8, j + 59, k + 49, Blocks.stone, 0);
        this.setBlock(world, i + 8, j + 59, k + 51, Blocks.stone, 0);
        this.setBlock(world, i + 8, j + 60, k + 23, Blocks.planks, 1);
        this.setBlock(world, i + 8, j + 60, k + 24, Blocks.planks, 1);
        this.setBlock(world, i + 8, j + 60, k + 25, Blocks.planks, 1);
        this.setBlock(world, i + 8, j + 60, k + 26, Blocks.planks, 1);
        this.setBlock(world, i + 8, j + 60, k + 27, Blocks.planks, 1);
        this.setBlock(world, i + 8, j + 60, k + 28, Blocks.planks, 1);
        this.setBlock(world, i + 8, j + 60, k + 29, Blocks.planks, 1);
        this.setBlock(world, i + 8, j + 60, k + 38, Blocks.stone, 0);
        this.setBlock(world, i + 8, j + 60, k + 39, Blocks.stone, 0);
        this.setBlock(world, i + 8, j + 60, k + 40, Blocks.stone, 0);
        this.setBlock(world, i + 8, j + 60, k + 41, Blocks.stone, 0);
        this.setBlock(world, i + 8, j + 60, k + 42, Blocks.stone, 0);
        this.setBlock(world, i + 8, j + 60, k + 43, Blocks.stone, 0);
        this.setBlock(world, i + 8, j + 60, k + 44, Blocks.stone, 0);
        this.setBlock(world, i + 8, j + 61, k + 24, Blocks.planks, 1);
        this.setBlock(world, i + 8, j + 61, k + 25, Blocks.planks, 1);
        this.setBlock(world, i + 8, j + 61, k + 26, Blocks.glass_pane, 0);
        this.setBlock(world, i + 8, j + 61, k + 27, Blocks.planks, 1);
        this.setBlock(world, i + 8, j + 61, k + 28, Blocks.planks, 1);
        this.setBlock(world, i + 8, j + 62, k + 25, Blocks.planks, 1);
        this.setBlock(world, i + 8, j + 62, k + 26, Blocks.planks, 1);
        this.setBlock(world, i + 8, j + 62, k + 27, Blocks.planks, 0);
        this.setBlock(world, i + 8, j + 63, k + 26, Blocks.planks, 1);
        this.setBlock(world, i + 9, j + 38, k + 100, Blocks.stonebrick, 0);
        this.setBlock(world, i + 9, j + 38, k + 101, Blocks.stonebrick, 0);
        this.setBlock(world, i + 9, j + 38, k + 102, Blocks.stonebrick, 0);
        this.setBlock(world, i + 9, j + 38, k + 103, Blocks.stonebrick, 0);
        this.setBlock(world, i + 9, j + 38, k + 104, Blocks.stonebrick, 0);
        this.setBlock(world, i + 9, j + 38, k + 105, Blocks.stonebrick, 0);
        this.setBlock(world, i + 9, j + 38, k + 106, Blocks.stonebrick, 0);
        this.setBlock(world, i + 9, j + 38, k + 107, Blocks.stonebrick, 0);
        this.setBlock(world, i + 9, j + 38, k + 108, Blocks.stonebrick, 0);
        this.setBlock(world, i + 9, j + 39, k + 100, Blocks.stonebrick, 0);
        this.setBlock(world, i + 9, j + 39, k + 101, Blocks.stonebrick, 0);
        this.setBlock(world, i + 9, j + 39, k + 102, Blocks.stonebrick, 0);
        this.setBlock(world, i + 9, j + 39, k + 103, Blocks.stonebrick, 0);
        this.setBlock(world, i + 9, j + 39, k + 104, Blocks.stonebrick, 0);
        this.setBlock(world, i + 9, j + 39, k + 105, Blocks.stonebrick, 0);
        this.setBlock(world, i + 9, j + 39, k + 106, Blocks.stonebrick, 0);
        this.setBlock(world, i + 9, j + 39, k + 107, Blocks.stonebrick, 0);
        this.setBlock(world, i + 9, j + 39, k + 108, Blocks.stonebrick, 0);
        this.setBlock(world, i + 9, j + 40, k + 100, Blocks.stonebrick, 0);
        this.setBlock(world, i + 9, j + 40, k + 108, Blocks.stonebrick, 0);
        this.setBlock(world, i + 9, j + 41, k + 100, Blocks.stonebrick, 0);
        this.setBlock(world, i + 9, j + 41, k + 108, Blocks.stonebrick, 0);
        this.setBlock(world, i + 9, j + 53, k + 26, Blocks.cobblestone, 0);
        this.setBlock(world, i + 9, j + 53, k + 27, Blocks.stone, 0);
        this.setBlock(world, i + 9, j + 53, k + 28, Blocks.stone, 0);
        this.setBlock(world, i + 9, j + 53, k + 29, Blocks.cobblestone, 0);
        this.setBlock(world, i + 9, j + 53, k + 30, Blocks.bedrock, 0);
        this.setBlock(world, i + 9, j + 53, k + 34, Blocks.stone, 0);
        this.setBlock(world, i + 9, j + 53, k + 35, Blocks.stone, 0);
        this.setBlock(world, i + 9, j + 53, k + 40, Blocks.stone, 0);
        this.setBlock(world, i + 9, j + 53, k + 41, Blocks.stone, 0);
        this.setBlock(world, i + 9, j + 53, k + 42, Blocks.stone, 0);
        this.setBlock(world, i + 9, j + 53, k + 43, Blocks.stone, 0);
        this.setBlock(world, i + 9, j + 53, k + 44, Blocks.bedrock, 0);
        this.setBlock(world, i + 9, j + 53, k + 45, Blocks.stone, 0);
        this.setBlock(world, i + 9, j + 53, k + 46, Blocks.stone, 0);
        this.setBlock(world, i + 9, j + 53, k + 47, Blocks.cobblestone, 0);
        this.setBlock(world, i + 9, j + 53, k + 48, Blocks.stone, 0);
        this.setBlock(world, i + 9, j + 53, k + 49, Blocks.stone, 0);
        this.setBlock(world, i + 9, j + 53, k + 50, Blocks.stone, 0);
        this.setBlock(world, i + 9, j + 54, k + 24, Blocks.stone, 0);
        this.setBlock(world, i + 9, j + 54, k + 25, Blocks.stone, 0);
        this.setBlock(world, i + 9, j + 54, k + 26, Blocks.stone, 0);
        this.setBlock(world, i + 9, j + 54, k + 27, Blocks.bedrock, 0);
        this.setBlock(world, i + 9, j + 54, k + 28, Blocks.bedrock, 0);
        this.setBlock(world, i + 9, j + 54, k + 29, Blocks.stone, 0);
        this.setBlock(world, i + 9, j + 54, k + 30, Blocks.stone, 0);
        this.setBlock(world, i + 9, j + 54, k + 34, Blocks.stone, 0);
        this.setBlock(world, i + 9, j + 54, k + 35, Blocks.stone, 0);
        this.setBlock(world, i + 9, j + 54, k + 36, Blocks.stone, 0);
        this.setBlock(world, i + 9, j + 54, k + 37, Blocks.cobblestone, 0);
        this.setBlock(world, i + 9, j + 54, k + 38, Blocks.stone, 0);
        this.setBlock(world, i + 9, j + 54, k + 39, Blocks.stone, 0);
        this.setBlock(world, i + 9, j + 54, k + 40, Blocks.stone, 0);
        this.setBlock(world, i + 9, j + 54, k + 41, Blocks.cobblestone, 0);
        this.setBlock(world, i + 9, j + 54, k + 42, Blocks.stone, 0);
        this.setBlock(world, i + 9, j + 54, k + 43, Blocks.stone, 0);
        this.setBlock(world, i + 9, j + 54, k + 44, Blocks.stone, 0);
        this.setBlock(world, i + 9, j + 54, k + 45, Blocks.stone, 0);
        this.setBlock(world, i + 9, j + 54, k + 46, Blocks.stone, 0);
        this.setBlock(world, i + 9, j + 54, k + 47, Blocks.stone, 0);
        this.setBlock(world, i + 9, j + 54, k + 48, Blocks.bedrock, 0);
        this.setBlock(world, i + 9, j + 54, k + 49, Blocks.stone, 0);
        this.setBlock(world, i + 9, j + 54, k + 50, Blocks.bedrock, 0);
        this.setBlock(world, i + 9, j + 54, k + 51, Blocks.stone, 0);
        this.setBlock(world, i + 9, j + 54, k + 52, Blocks.stone, 0);
        this.setBlock(world, i + 9, j + 54, k + 53, Blocks.cobblestone, 0);
        this.setBlock(world, i + 9, j + 55, k + 22, Blocks.bedrock, 0);
        this.setBlock(world, i + 9, j + 55, k + 23, Blocks.stone, 0);
        this.setBlock(world, i + 9, j + 55, k + 24, Blocks.stone, 0);
        this.setBlock(world, i + 9, j + 55, k + 25, Blocks.bedrock, 0);
        this.setBlock(world, i + 9, j + 55, k + 26, Blocks.stone, 0);
        this.setBlock(world, i + 9, j + 55, k + 27, Blocks.bedrock, 0);
        this.setBlock(world, i + 9, j + 55, k + 28, Blocks.stone, 0);
        this.setBlock(world, i + 9, j + 55, k + 29, Blocks.stone, 0);
        this.setBlock(world, i + 9, j + 55, k + 30, Blocks.stone, 0);
        this.setBlock(world, i + 9, j + 55, k + 31, Blocks.stone, 0);
        this.setBlock(world, i + 9, j + 55, k + 32, Blocks.bedrock, 0);
        this.setBlock(world, i + 9, j + 55, k + 33, Blocks.stone, 0);
        this.setBlock(world, i + 9, j + 55, k + 34, Blocks.stone, 0);
        this.setBlock(world, i + 9, j + 55, k + 35, Blocks.stone, 0);
        this.setBlock(world, i + 9, j + 55, k + 36, Blocks.bedrock, 0);
        this.setBlock(world, i + 9, j + 55, k + 37, Blocks.stone, 0);
        this.setBlock(world, i + 9, j + 55, k + 38, Blocks.stone, 0);
        this.setBlock(world, i + 9, j + 55, k + 39, Blocks.stone, 0);
        this.setBlock(world, i + 9, j + 55, k + 40, Blocks.stone, 0);
        this.setBlock(world, i + 9, j + 55, k + 41, Blocks.stone, 0);
        this.setBlock(world, i + 9, j + 55, k + 42, Blocks.stone, 0);
        this.setBlock(world, i + 9, j + 55, k + 43, Blocks.stone, 0);
        this.setBlock(world, i + 9, j + 55, k + 44, Blocks.stone, 0);
        this.setBlock(world, i + 9, j + 55, k + 45, Blocks.bedrock, 0);
        this.setBlock(world, i + 9, j + 55, k + 46, Blocks.stone, 0);
        this.setBlock(world, i + 9, j + 55, k + 47, Blocks.stone, 0);
        this.setBlock(world, i + 9, j + 55, k + 48, Blocks.cobblestone, 0);
        this.setBlock(world, i + 9, j + 55, k + 49, Blocks.stone, 0);
        this.setBlock(world, i + 9, j + 55, k + 50, Blocks.stone, 0);
        this.setBlock(world, i + 9, j + 55, k + 51, Blocks.stone, 0);
        this.setBlock(world, i + 9, j + 55, k + 52, Blocks.stone, 0);
        this.setBlock(world, i + 9, j + 55, k + 53, Blocks.stone, 0);
        this.setBlock(world, i + 9, j + 55, k + 54, Blocks.stone, 0);
        this.setBlock(world, i + 9, j + 55, k + 55, Blocks.stone, 0);
        this.setBlock(world, i + 9, j + 56, k + 21, Blocks.bedrock, 0);
        this.setBlock(world, i + 9, j + 56, k + 22, Blocks.bedrock, 0);
        this.setBlock(world, i + 9, j + 56, k + 23, Blocks.stone, 0);
        this.setBlock(world, i + 9, j + 56, k + 24, Blocks.wool, 6);
        this.setBlock(world, i + 9, j + 56, k + 25, Blocks.wool, 6);
        this.setBlock(world, i + 9, j + 56, k + 26, Blocks.wool, 6);
        this.setBlock(world, i + 9, j + 56, k + 27, Blocks.wool, 6);
        this.setBlock(world, i + 9, j + 56, k + 28, Blocks.wool, 6);
        this.setBlock(world, i + 9, j + 56, k + 29, Blocks.stone, 0);
        this.setBlock(world, i + 9, j + 56, k + 30, Blocks.stone, 0);
        this.setBlock(world, i + 9, j + 56, k + 31, Blocks.stone, 0);
        this.setBlock(world, i + 9, j + 56, k + 32, Blocks.stone, 0);
        this.setBlock(world, i + 9, j + 56, k + 33, Blocks.stone, 0);
        this.setBlock(world, i + 9, j + 56, k + 34, Blocks.stone, 0);
        this.setBlock(world, i + 9, j + 56, k + 35, Blocks.stone, 0);
        this.setBlock(world, i + 9, j + 56, k + 36, Blocks.stone, 0);
        this.setBlock(world, i + 9, j + 56, k + 37, Blocks.stone, 0);
        this.setBlock(world, i + 9, j + 56, k + 38, Blocks.stone, 0);
        this.setBlock(world, i + 9, j + 56, k + 39, Blocks.stone, 0);
        this.setBlock(world, i + 9, j + 56, k + 40, Blocks.stone, 0);
        this.setBlock(world, i + 9, j + 56, k + 41, Blocks.stone, 0);
        this.setBlock(world, i + 9, j + 56, k + 42, Blocks.stone, 0);
        this.setBlock(world, i + 9, j + 56, k + 43, Blocks.stone, 0);
        this.setBlock(world, i + 9, j + 56, k + 44, Blocks.stone, 0);
        this.setBlock(world, i + 9, j + 56, k + 45, Blocks.stone, 0);
        this.setBlock(world, i + 9, j + 56, k + 46, Blocks.stone, 0);
        this.setBlock(world, i + 9, j + 56, k + 47, Blocks.stone, 0);
        this.setBlock(world, i + 9, j + 56, k + 48, Blocks.stone, 0);
        this.setBlock(world, i + 9, j + 56, k + 49, Blocks.stone, 0);
        this.setBlock(world, i + 9, j + 56, k + 50, Blocks.stone, 0);
        this.setBlock(world, i + 9, j + 56, k + 51, Blocks.stone, 0);
        this.setBlock(world, i + 9, j + 56, k + 52, Blocks.stone, 0);
        this.setBlock(world, i + 9, j + 56, k + 53, Blocks.stone, 0);
        this.setBlock(world, i + 9, j + 56, k + 54, Blocks.stone, 0);
        this.setBlock(world, i + 9, j + 56, k + 55, Blocks.bedrock, 0);
        this.setBlock(world, i + 9, j + 56, k + 56, Blocks.stone, 0);
        this.setBlock(world, i + 9, j + 56, k + 57, Blocks.stone, 0);
        this.setBlock(world, i + 9, j + 56, k + 58, Blocks.bedrock, 0);
        this.setBlock(world, i + 9, j + 56, k + 59, Blocks.stone, 0);
        this.setBlock(world, i + 9, j + 57, k + 23, Blocks.planks, 1);
        this.setBlock(world, i + 9, j + 57, k + 24, Blocks.crafting_table, 0);
        this.setBlock(world, i + 9, j + 57, k + 26, Blocks.wool, 0);
        this.setBlock(world, i + 9, j + 57, k + 28, Blocks.wool, 0);
        this.setBlock(world, i + 9, j + 57, k + 29, Blocks.planks, 1);
        this.setBlock(world, i + 9, j + 57, k + 30, Blocks.stone, 0);
        this.setBlock(world, i + 9, j + 57, k + 31, Blocks.stone, 0);
        this.setBlock(world, i + 9, j + 57, k + 32, Blocks.stone, 0);
        this.setBlock(world, i + 9, j + 57, k + 33, Blocks.stone, 0);
        this.setBlock(world, i + 9, j + 57, k + 34, Blocks.stone, 0);
        this.setBlock(world, i + 9, j + 57, k + 35, Blocks.stone, 0);
        this.setBlock(world, i + 9, j + 57, k + 36, Blocks.stone, 0);
        this.setBlock(world, i + 9, j + 57, k + 37, Blocks.stone, 0);
        this.setBlock(world, i + 9, j + 57, k + 38, Blocks.stone, 0);
        this.setBlock(world, i + 9, j + 57, k + 39, Blocks.stone, 0);
        this.setBlock(world, i + 9, j + 57, k + 40, Blocks.stone, 0);
        this.setBlock(world, i + 9, j + 57, k + 41, Blocks.stone, 0);
        this.setBlock(world, i + 9, j + 57, k + 42, Blocks.stone, 0);
        this.setBlock(world, i + 9, j + 57, k + 43, Blocks.stone, 0);
        this.setBlock(world, i + 9, j + 57, k + 44, Blocks.stone, 0);
        this.setBlock(world, i + 9, j + 57, k + 45, Blocks.stone, 0);
        this.setBlock(world, i + 9, j + 57, k + 46, Blocks.stone, 0);
        this.setBlock(world, i + 9, j + 57, k + 47, Blocks.stone, 0);
        this.setBlock(world, i + 9, j + 57, k + 48, Blocks.stone, 0);
        this.setBlock(world, i + 9, j + 57, k + 49, Blocks.stone, 0);
        this.setBlock(world, i + 9, j + 57, k + 50, Blocks.stone, 0);
        this.setBlock(world, i + 9, j + 57, k + 51, Blocks.stone, 0);
        this.setBlock(world, i + 9, j + 57, k + 52, Blocks.stone, 0);
        this.setBlock(world, i + 9, j + 57, k + 53, Blocks.stone, 0);
        this.setBlock(world, i + 9, j + 57, k + 54, Blocks.stone, 0);
        this.setBlock(world, i + 9, j + 57, k + 55, Blocks.bedrock, 0);
        this.setBlock(world, i + 9, j + 58, k + 23, Blocks.planks, 0);
        this.setBlock(world, i + 9, j + 58, k + 29, Blocks.planks, 1);
        this.setBlock(world, i + 9, j + 58, k + 30, Blocks.stone, 0);
        this.setBlock(world, i + 9, j + 58, k + 31, Blocks.stone, 0);
        this.setBlock(world, i + 9, j + 58, k + 32, Blocks.stone, 0);
        this.setBlock(world, i + 9, j + 58, k + 33, Blocks.stone, 0);
        this.setBlock(world, i + 9, j + 58, k + 34, Blocks.stone, 0);
        this.setBlock(world, i + 9, j + 58, k + 35, Blocks.stone, 0);
        this.setBlock(world, i + 9, j + 58, k + 36, Blocks.stone, 0);
        this.setBlock(world, i + 9, j + 58, k + 37, Blocks.stone, 0);
        this.setBlock(world, i + 9, j + 58, k + 38, Blocks.stone, 0);
        this.setBlock(world, i + 9, j + 58, k + 39, Blocks.stone, 0);
        this.setBlock(world, i + 9, j + 58, k + 40, Blocks.stone, 0);
        this.setBlock(world, i + 9, j + 58, k + 41, Blocks.stone, 0);
        this.setBlock(world, i + 9, j + 58, k + 42, Blocks.stone, 0);
        this.setBlock(world, i + 9, j + 58, k + 43, Blocks.stone, 0);
        this.setBlock(world, i + 9, j + 58, k + 44, Blocks.stone, 0);
        this.setBlock(world, i + 9, j + 58, k + 45, Blocks.stone, 0);
        this.setBlock(world, i + 9, j + 58, k + 46, Blocks.stone, 0);
        this.setBlock(world, i + 9, j + 58, k + 47, Blocks.stone, 0);
        this.setBlock(world, i + 9, j + 58, k + 48, Blocks.stone, 0);
        this.setBlock(world, i + 9, j + 58, k + 49, Blocks.stone, 0);
        this.setBlock(world, i + 9, j + 58, k + 50, Blocks.stone, 0);
        this.setBlock(world, i + 9, j + 58, k + 51, Blocks.stone, 0);
        this.setBlock(world, i + 9, j + 58, k + 52, Blocks.stone, 0);
        this.setBlock(world, i + 9, j + 58, k + 53, Blocks.stone, 0);
        this.setBlock(world, i + 9, j + 59, k + 23, Blocks.planks, 1);
        this.setBlock(world, i + 9, j + 59, k + 29, Blocks.planks, 1);
        this.setBlock(world, i + 9, j + 59, k + 32, Blocks.stone, 0);
        this.setBlock(world, i + 9, j + 59, k + 33, Blocks.stone, 0);
        this.setBlock(world, i + 9, j + 59, k + 34, Blocks.stone, 0);
        this.setBlock(world, i + 9, j + 59, k + 35, Blocks.stone, 0);
        this.setBlock(world, i + 9, j + 59, k + 36, Blocks.stone, 0);
        this.setBlock(world, i + 9, j + 59, k + 37, Blocks.stone, 0);
        this.setBlock(world, i + 9, j + 59, k + 38, Blocks.stone, 0);
        this.setBlock(world, i + 9, j + 59, k + 39, Blocks.stone, 0);
        this.setBlock(world, i + 9, j + 59, k + 40, Blocks.stone, 0);
        this.setBlock(world, i + 9, j + 59, k + 41, Blocks.stone, 0);
        this.setBlock(world, i + 9, j + 59, k + 42, Blocks.stone, 0);
        this.setBlock(world, i + 9, j + 59, k + 43, Blocks.stone, 0);
        this.setBlock(world, i + 9, j + 59, k + 44, Blocks.stone, 0);
        this.setBlock(world, i + 9, j + 59, k + 45, Blocks.stone, 0);
        this.setBlock(world, i + 9, j + 59, k + 46, Blocks.stone, 0);
        this.setBlock(world, i + 9, j + 59, k + 47, Blocks.stone, 0);
        this.setBlock(world, i + 9, j + 59, k + 48, Blocks.stone, 0);
        this.setBlock(world, i + 9, j + 59, k + 49, Blocks.stone, 0);
        this.setBlock(world, i + 9, j + 59, k + 50, Blocks.stone, 0);
        this.setBlock(world, i + 9, j + 59, k + 51, Blocks.stone, 0);
        this.setBlock(world, i + 9, j + 59, k + 52, Blocks.stone, 0);
        this.setBlock(world, i + 9, j + 60, k + 23, Blocks.planks, 1);
        this.setBlock(world, i + 9, j + 60, k + 29, Blocks.planks, 1);
        this.setBlock(world, i + 9, j + 60, k + 32, Blocks.stone, 0);
        this.setBlock(world, i + 9, j + 60, k + 33, Blocks.stone, 0);
        this.setBlock(world, i + 9, j + 60, k + 34, Blocks.stone, 0);
        this.setBlock(world, i + 9, j + 60, k + 35, Blocks.stone, 0);
        this.setBlock(world, i + 9, j + 60, k + 36, Blocks.stone, 0);
        this.setBlock(world, i + 9, j + 60, k + 37, Blocks.stone, 0);
        this.setBlock(world, i + 9, j + 60, k + 38, Blocks.stone, 0);
        this.setBlock(world, i + 9, j + 60, k + 39, Blocks.stone, 0);
        this.setBlock(world, i + 9, j + 60, k + 40, Blocks.stone, 0);
        this.setBlock(world, i + 9, j + 60, k + 41, Blocks.stone, 0);
        this.setBlock(world, i + 9, j + 60, k + 42, Blocks.stone, 0);
        this.setBlock(world, i + 9, j + 60, k + 43, Blocks.stone, 0);
        this.setBlock(world, i + 9, j + 60, k + 44, Blocks.stone, 0);
        this.setBlock(world, i + 9, j + 60, k + 45, Blocks.stone, 0);
        this.setBlock(world, i + 9, j + 60, k + 46, Blocks.stone, 0);
        this.setBlock(world, i + 9, j + 60, k + 47, Blocks.stone, 0);
        this.setBlock(world, i + 9, j + 60, k + 48, Blocks.stone, 0);
        this.setBlock(world, i + 9, j + 60, k + 49, Blocks.stone, 0);
        this.setBlock(world, i + 9, j + 61, k + 24, Blocks.planks, 1);
        this.setBlock(world, i + 9, j + 61, k + 28, Blocks.planks, 1);
        this.setBlock(world, i + 9, j + 62, k + 25, Blocks.planks, 1);
        this.setBlock(world, i + 9, j + 62, k + 27, Blocks.planks, 1);
        this.setBlock(world, i + 9, j + 63, k + 26, Blocks.planks, 0);
        this.setBlock(world, i + 10, j + 38, k + 100, Blocks.cobblestone_wall, 0);
        this.setBlock(world, i + 10, j + 38, k + 101, Blocks.stonebrick, 0);
        this.setBlock(world, i + 10, j + 38, k + 102, Blocks.stonebrick, 0);
        this.setBlock(world, i + 10, j + 38, k + 103, Blocks.stonebrick, 0);
        this.setBlock(world, i + 10, j + 38, k + 104, Blocks.stonebrick, 0);
        this.setBlock(world, i + 10, j + 38, k + 105, Blocks.stonebrick, 0);
        this.setBlock(world, i + 10, j + 38, k + 106, Blocks.stonebrick, 0);
        this.setBlock(world, i + 10, j + 38, k + 107, Blocks.stonebrick, 0);
        this.setBlock(world, i + 10, j + 38, k + 108, Blocks.cobblestone_wall, 0);
        this.setBlock(world, i + 10, j + 39, k + 100, Blocks.cobblestone_wall, 0);
        this.setBlock(world, i + 10, j + 39, k + 101, Blocks.stonebrick, 0);
        this.setBlock(world, i + 10, j + 39, k + 102, Blocks.stonebrick, 0);
        this.setBlock(world, i + 10, j + 39, k + 103, Blocks.stonebrick, 0);
        this.setBlock(world, i + 10, j + 39, k + 104, Blocks.stonebrick, 0);
        this.setBlock(world, i + 10, j + 39, k + 105, Blocks.stonebrick, 0);
        this.setBlock(world, i + 10, j + 39, k + 106, Blocks.stonebrick, 0);
        this.setBlock(world, i + 10, j + 39, k + 107, Blocks.stonebrick, 0);
        this.setBlock(world, i + 10, j + 39, k + 108, Blocks.cobblestone_wall, 0);
        this.setBlock(world, i + 10, j + 52, k + 30, Blocks.cobblestone, 0);
        this.setBlock(world, i + 10, j + 52, k + 31, Blocks.stone, 0);
        this.setBlock(world, i + 10, j + 52, k + 32, Blocks.stone, 0);
        this.setBlock(world, i + 10, j + 52, k + 33, Blocks.stone, 0);
        this.setBlock(world, i + 10, j + 52, k + 34, Blocks.stone, 0);
        this.setBlock(world, i + 10, j + 52, k + 35, Blocks.stone, 0);
        this.setBlock(world, i + 10, j + 52, k + 36, Blocks.stone, 0);
        this.setBlock(world, i + 10, j + 52, k + 37, Blocks.bedrock, 0);
        this.setBlock(world, i + 10, j + 52, k + 38, Blocks.stone, 0);
        this.setBlock(world, i + 10, j + 52, k + 39, Blocks.cobblestone, 0);
        this.setBlock(world, i + 10, j + 52, k + 40, Blocks.cobblestone, 0);
        this.setBlock(world, i + 10, j + 52, k + 41, Blocks.stone, 0);
        this.setBlock(world, i + 10, j + 52, k + 42, Blocks.stone, 0);
        this.setBlock(world, i + 10, j + 52, k + 43, Blocks.stone, 0);
        this.setBlock(world, i + 10, j + 52, k + 44, Blocks.stone, 0);
        this.setBlock(world, i + 10, j + 53, k + 26, Blocks.stone, 0);
        this.setBlock(world, i + 10, j + 53, k + 27, Blocks.stone, 0);
        this.setBlock(world, i + 10, j + 53, k + 28, Blocks.stone, 0);
        this.setBlock(world, i + 10, j + 53, k + 29, Blocks.stone, 0);
        this.setBlock(world, i + 10, j + 53, k + 30, Blocks.stone, 0);
        this.setBlock(world, i + 10, j + 53, k + 31, Blocks.stone, 0);
        this.setBlock(world, i + 10, j + 53, k + 32, Blocks.stone, 0);
        this.setBlock(world, i + 10, j + 53, k + 33, Blocks.stone, 0);
        this.setBlock(world, i + 10, j + 53, k + 34, Blocks.stone, 0);
        this.setBlock(world, i + 10, j + 53, k + 35, Blocks.stone, 0);
        this.setBlock(world, i + 10, j + 53, k + 36, Blocks.stone, 0);
        this.setBlock(world, i + 10, j + 53, k + 37, Blocks.stone, 0);
        this.setBlock(world, i + 10, j + 53, k + 38, Blocks.stone, 0);
        this.setBlock(world, i + 10, j + 53, k + 39, Blocks.bedrock, 0);
        this.setBlock(world, i + 10, j + 53, k + 40, Blocks.stone, 0);
        this.setBlock(world, i + 10, j + 53, k + 41, Blocks.stone, 0);
        this.setBlock(world, i + 10, j + 53, k + 42, Blocks.stone, 0);
        this.setBlock(world, i + 10, j + 53, k + 43, Blocks.cobblestone, 0);
        this.setBlock(world, i + 10, j + 53, k + 44, Blocks.stone, 0);
        this.setBlock(world, i + 10, j + 53, k + 45, Blocks.stone, 0);
        this.setBlock(world, i + 10, j + 53, k + 46, Blocks.cobblestone, 0);
        this.setBlock(world, i + 10, j + 53, k + 47, Blocks.bedrock, 0);
        this.setBlock(world, i + 10, j + 53, k + 48, Blocks.stone, 0);
        this.setBlock(world, i + 10, j + 53, k + 49, Blocks.stone, 0);
        this.setBlock(world, i + 10, j + 53, k + 50, Blocks.stone, 0);
        this.setBlock(world, i + 10, j + 53, k + 51, Blocks.stone, 0);
        this.setBlock(world, i + 10, j + 53, k + 52, Blocks.stone, 0);
        this.setBlock(world, i + 10, j + 53, k + 53, Blocks.stone, 0);
        this.setBlock(world, i + 10, j + 54, k + 21, Blocks.stone, 0);
        this.setBlock(world, i + 10, j + 54, k + 22, Blocks.stone, 0);
        this.setBlock(world, i + 10, j + 54, k + 23, Blocks.bedrock, 0);
        this.setBlock(world, i + 10, j + 54, k + 24, Blocks.stone, 0);
        this.setBlock(world, i + 10, j + 54, k + 25, Blocks.stone, 0);
        this.setBlock(world, i + 10, j + 54, k + 26, Blocks.stone, 0);
        this.setBlock(world, i + 10, j + 54, k + 27, Blocks.stone, 0);
        this.setBlock(world, i + 10, j + 54, k + 28, Blocks.cobblestone, 0);
        this.setBlock(world, i + 10, j + 54, k + 29, Blocks.bedrock, 0);
        this.setBlock(world, i + 10, j + 54, k + 30, Blocks.stone, 0);
        this.setBlock(world, i + 10, j + 54, k + 31, Blocks.stone, 0);
        this.setBlock(world, i + 10, j + 54, k + 32, Blocks.cobblestone, 0);
        this.setBlock(world, i + 10, j + 54, k + 33, Blocks.stone, 0);
        this.setBlock(world, i + 10, j + 54, k + 34, Blocks.stone, 0);
        this.setBlock(world, i + 10, j + 54, k + 35, Blocks.cobblestone, 0);
        this.setBlock(world, i + 10, j + 54, k + 36, Blocks.stone, 0);
        this.setBlock(world, i + 10, j + 54, k + 37, Blocks.stone, 0);
        this.setBlock(world, i + 10, j + 54, k + 38, Blocks.stone, 0);
        this.setBlock(world, i + 10, j + 54, k + 39, Blocks.stone, 0);
        this.setBlock(world, i + 10, j + 54, k + 40, Blocks.bedrock, 0);
        this.setBlock(world, i + 10, j + 54, k + 41, Blocks.stone, 0);
        this.setBlock(world, i + 10, j + 54, k + 42, Blocks.cobblestone, 0);
        this.setBlock(world, i + 10, j + 54, k + 43, Blocks.stone, 0);
        this.setBlock(world, i + 10, j + 54, k + 44, Blocks.stone, 0);
        this.setBlock(world, i + 10, j + 54, k + 45, Blocks.cobblestone, 0);
        this.setBlock(world, i + 10, j + 54, k + 46, Blocks.stone, 0);
        this.setBlock(world, i + 10, j + 54, k + 47, Blocks.stone, 0);
        this.setBlock(world, i + 10, j + 54, k + 48, Blocks.stone, 0);
        this.setBlock(world, i + 10, j + 54, k + 49, Blocks.stone, 0);
        this.setBlock(world, i + 10, j + 54, k + 50, Blocks.stone, 0);
        this.setBlock(world, i + 10, j + 54, k + 51, Blocks.stone, 0);
        this.setBlock(world, i + 10, j + 54, k + 52, Blocks.stone, 0);
        this.setBlock(world, i + 10, j + 54, k + 53, Blocks.stone, 0);
        this.setBlock(world, i + 10, j + 54, k + 54, Blocks.stone, 0);
        this.setBlock(world, i + 10, j + 55, k + 20, Blocks.stone, 0);
        this.setBlock(world, i + 10, j + 55, k + 21, Blocks.stone, 0);
        this.setBlock(world, i + 10, j + 55, k + 22, Blocks.stone, 0);
        this.setBlock(world, i + 10, j + 55, k + 23, Blocks.stone, 0);
        this.setBlock(world, i + 10, j + 55, k + 24, Blocks.stone, 0);
        this.setBlock(world, i + 10, j + 55, k + 25, Blocks.stone, 0);
        this.setBlock(world, i + 10, j + 55, k + 26, Blocks.stone, 0);
        this.setBlock(world, i + 10, j + 55, k + 27, Blocks.cobblestone, 0);
        this.setBlock(world, i + 10, j + 55, k + 28, Blocks.stone, 0);
        this.setBlock(world, i + 10, j + 55, k + 29, Blocks.bedrock, 0);
        this.setBlock(world, i + 10, j + 55, k + 30, Blocks.cobblestone, 0);
        this.setBlock(world, i + 10, j + 55, k + 31, Blocks.bedrock, 0);
        this.setBlock(world, i + 10, j + 55, k + 32, Blocks.stone, 0);
        this.setBlock(world, i + 10, j + 55, k + 33, Blocks.cobblestone, 0);
        this.setBlock(world, i + 10, j + 55, k + 34, Blocks.stone, 0);
        this.setBlock(world, i + 10, j + 55, k + 35, Blocks.stone, 0);
        this.setBlock(world, i + 10, j + 55, k + 36, Blocks.stone, 0);
        this.setBlock(world, i + 10, j + 55, k + 37, Blocks.stone, 0);
        this.setBlock(world, i + 10, j + 55, k + 38, Blocks.stone, 0);
        this.setBlock(world, i + 10, j + 55, k + 39, Blocks.stone, 0);
        this.setBlock(world, i + 10, j + 55, k + 40, Blocks.stone, 0);
        this.setBlock(world, i + 10, j + 55, k + 41, Blocks.cobblestone, 0);
        this.setBlock(world, i + 10, j + 55, k + 42, Blocks.stone, 0);
        this.setBlock(world, i + 10, j + 55, k + 43, Blocks.stone, 0);
        this.setBlock(world, i + 10, j + 55, k + 44, Blocks.stone, 0);
        this.setBlock(world, i + 10, j + 55, k + 45, Blocks.stone, 0);
        this.setBlock(world, i + 10, j + 55, k + 46, Blocks.stone, 0);
        this.setBlock(world, i + 10, j + 55, k + 47, Blocks.bedrock, 0);
        this.setBlock(world, i + 10, j + 55, k + 48, Blocks.bedrock, 0);
        this.setBlock(world, i + 10, j + 55, k + 49, Blocks.cobblestone, 0);
        this.setBlock(world, i + 10, j + 55, k + 50, Blocks.stone, 0);
        this.setBlock(world, i + 10, j + 55, k + 51, Blocks.cobblestone, 0);
        this.setBlock(world, i + 10, j + 55, k + 52, Blocks.stone, 0);
        this.setBlock(world, i + 10, j + 55, k + 53, Blocks.stone, 0);
        this.setBlock(world, i + 10, j + 55, k + 54, Blocks.stone, 0);
        this.setBlock(world, i + 10, j + 55, k + 55, Blocks.stone, 0);
        this.setBlock(world, i + 10, j + 55, k + 56, Blocks.stone, 0);
        this.setBlock(world, i + 10, j + 55, k + 57, Blocks.stone, 0);
        this.setBlock(world, i + 10, j + 55, k + 58, Blocks.stone, 0);
        this.setBlock(world, i + 10, j + 55, k + 59, Blocks.stone, 0);
        this.setBlock(world, i + 10, j + 56, k + 19, Blocks.stone, 0);
        this.setBlock(world, i + 10, j + 56, k + 20, Blocks.stone, 0);
        this.setBlock(world, i + 10, j + 56, k + 21, Blocks.stone, 0);
        this.setBlock(world, i + 10, j + 56, k + 22, Blocks.bedrock, 0);
        this.setBlock(world, i + 10, j + 56, k + 23, Blocks.stone, 0);
        this.setBlock(world, i + 10, j + 56, k + 24, Blocks.wool, 6);
        this.setBlock(world, i + 10, j + 56, k + 25, Blocks.wool, 6);
        this.setBlock(world, i + 10, j + 56, k + 26, Blocks.wool, 6);
        this.setBlock(world, i + 10, j + 56, k + 27, Blocks.wool, 6);
        this.setBlock(world, i + 10, j + 56, k + 28, Blocks.wool, 6);
        this.setBlock(world, i + 10, j + 56, k + 29, Blocks.stone, 0);
        this.setBlock(world, i + 10, j + 56, k + 30, Blocks.stone, 0);
        this.setBlock(world, i + 10, j + 56, k + 31, Blocks.stone, 0);
        this.setBlock(world, i + 10, j + 56, k + 32, Blocks.stone, 0);
        this.setBlock(world, i + 10, j + 56, k + 33, Blocks.stone, 0);
        this.setBlock(world, i + 10, j + 56, k + 34, Blocks.stone, 0);
        this.setBlock(world, i + 10, j + 56, k + 35, Blocks.stone, 0);
        this.setBlock(world, i + 10, j + 56, k + 36, Blocks.stone, 0);
        this.setBlock(world, i + 10, j + 56, k + 37, Blocks.stone, 0);
        this.setBlock(world, i + 10, j + 56, k + 38, Blocks.stone, 0);
        this.setBlock(world, i + 10, j + 56, k + 39, Blocks.stone, 0);
        this.setBlock(world, i + 10, j + 56, k + 40, Blocks.stone, 0);
        this.setBlock(world, i + 10, j + 56, k + 41, Blocks.stone, 0);
        this.setBlock(world, i + 10, j + 56, k + 42, Blocks.stone, 0);
        this.setBlock(world, i + 10, j + 56, k + 43, Blocks.stone, 0);
        this.setBlock(world, i + 10, j + 56, k + 44, Blocks.stone, 0);
        this.setBlock(world, i + 10, j + 56, k + 45, Blocks.stone, 0);
        this.setBlock(world, i + 10, j + 56, k + 46, Blocks.stone, 0);
        this.setBlock(world, i + 10, j + 56, k + 47, Blocks.stone, 0);
        this.setBlock(world, i + 10, j + 56, k + 48, Blocks.stone, 0);
        this.setBlock(world, i + 10, j + 56, k + 49, Blocks.stone, 0);
        this.setBlock(world, i + 10, j + 56, k + 50, Blocks.stone, 0);
        this.setBlock(world, i + 10, j + 56, k + 51, Blocks.stone, 0);
        this.setBlock(world, i + 10, j + 56, k + 52, Blocks.stone, 0);
        this.setBlock(world, i + 10, j + 56, k + 53, Blocks.stone, 0);
        this.setBlock(world, i + 10, j + 56, k + 54, Blocks.stone, 0);
        this.setBlock(world, i + 10, j + 56, k + 55, Blocks.stone, 0);
        this.setBlock(world, i + 10, j + 56, k + 56, Blocks.stone, 0);
        this.setBlock(world, i + 10, j + 56, k + 57, Blocks.stone, 0);
        this.setBlock(world, i + 10, j + 56, k + 58, Blocks.stone, 0);
        this.setBlock(world, i + 10, j + 56, k + 59, Blocks.cobblestone, 0);
        this.setBlock(world, i + 10, j + 56, k + 60, Blocks.stone, 0);
        this.setBlock(world, i + 10, j + 57, k + 23, Blocks.planks, 1);
        this.setBlock(world, i + 10, j + 57, k + 24, Blocks.crafting_table, 0);
        this.setBlock(world, i + 10, j + 57, k + 26, Blocks.wool, 14);
        this.setBlock(world, i + 10, j + 57, k + 28, Blocks.wool, 14);
        this.setBlock(world, i + 10, j + 57, k + 29, Blocks.planks, 1);
        this.setBlock(world, i + 10, j + 57, k + 30, Blocks.stone, 0);
        this.setBlock(world, i + 10, j + 57, k + 31, Blocks.stone, 0);
        this.setBlock(world, i + 10, j + 57, k + 32, Blocks.stone, 0);
        this.setBlock(world, i + 10, j + 57, k + 33, Blocks.stone, 0);
        this.setBlock(world, i + 10, j + 57, k + 34, Blocks.stone, 0);
        this.setBlock(world, i + 10, j + 57, k + 35, Blocks.stone, 0);
        this.setBlock(world, i + 10, j + 57, k + 36, Blocks.stone, 0);
        this.setBlock(world, i + 10, j + 57, k + 37, Blocks.stone, 0);
        this.setBlock(world, i + 10, j + 57, k + 38, Blocks.stone, 0);
        this.setBlock(world, i + 10, j + 57, k + 39, Blocks.stone, 0);
        this.setBlock(world, i + 10, j + 57, k + 40, Blocks.stone, 0);
        this.setBlock(world, i + 10, j + 57, k + 41, Blocks.stone, 0);
        this.setBlock(world, i + 10, j + 57, k + 42, Blocks.stone, 0);
        this.setBlock(world, i + 10, j + 57, k + 43, Blocks.stone, 0);
        this.setBlock(world, i + 10, j + 57, k + 44, Blocks.stone, 0);
        this.setBlock(world, i + 10, j + 57, k + 45, Blocks.stone, 0);
        this.setBlock(world, i + 10, j + 57, k + 46, Blocks.stone, 0);
        this.setBlock(world, i + 10, j + 57, k + 47, Blocks.stone, 0);
        this.setBlock(world, i + 10, j + 57, k + 48, Blocks.stone, 0);
        this.setBlock(world, i + 10, j + 57, k + 49, Blocks.stone, 0);
        this.setBlock(world, i + 10, j + 57, k + 50, Blocks.stone, 0);
        this.setBlock(world, i + 10, j + 57, k + 51, Blocks.stone, 0);
        this.setBlock(world, i + 10, j + 57, k + 52, Blocks.stone, 0);
        this.setBlock(world, i + 10, j + 57, k + 53, Blocks.stone, 0);
        this.setBlock(world, i + 10, j + 57, k + 54, Blocks.stone, 0);
        this.setBlock(world, i + 10, j + 57, k + 55, Blocks.stone, 0);
        this.setBlock(world, i + 10, j + 58, k + 23, Blocks.planks, 1);
        this.setBlock(world, i + 10, j + 58, k + 29, Blocks.planks, 1);
        this.setBlock(world, i + 10, j + 58, k + 30, Blocks.stone, 0);
        this.setBlock(world, i + 10, j + 58, k + 31, Blocks.stone, 0);
        this.setBlock(world, i + 10, j + 58, k + 32, Blocks.stone, 0);
        this.setBlock(world, i + 10, j + 58, k + 33, Blocks.stone, 0);
        this.setBlock(world, i + 10, j + 58, k + 34, Blocks.stone, 0);
        this.setBlock(world, i + 10, j + 58, k + 35, Blocks.stone, 0);
        this.setBlock(world, i + 10, j + 58, k + 36, Blocks.stone, 0);
        this.setBlock(world, i + 10, j + 58, k + 37, Blocks.stone, 0);
        this.setBlock(world, i + 10, j + 58, k + 38, Blocks.stone, 0);
        this.setBlock(world, i + 10, j + 58, k + 39, Blocks.stone, 0);
        this.setBlock(world, i + 10, j + 58, k + 40, Blocks.stone, 0);
        this.setBlock(world, i + 10, j + 58, k + 41, Blocks.stone, 0);
        this.setBlock(world, i + 10, j + 58, k + 42, Blocks.stone, 0);
        this.setBlock(world, i + 10, j + 58, k + 43, Blocks.stone, 0);
        this.setBlock(world, i + 10, j + 58, k + 44, Blocks.stone, 0);
        this.setBlock(world, i + 10, j + 58, k + 45, Blocks.stone, 0);
        this.setBlock(world, i + 10, j + 58, k + 46, Blocks.stone, 0);
        this.setBlock(world, i + 10, j + 58, k + 47, Blocks.stone, 0);
        this.setBlock(world, i + 10, j + 58, k + 48, Blocks.stone, 0);
        this.setBlock(world, i + 10, j + 58, k + 49, Blocks.stone, 0);
        this.setBlock(world, i + 10, j + 58, k + 50, Blocks.stone, 0);
        this.setBlock(world, i + 10, j + 58, k + 51, Blocks.stone, 0);
        this.setBlock(world, i + 10, j + 58, k + 52, Blocks.stone, 0);
        this.setBlock(world, i + 10, j + 58, k + 53, Blocks.stone, 0);
        this.setBlock(world, i + 10, j + 58, k + 54, Blocks.stone, 0);
        this.setBlock(world, i + 10, j + 59, k + 23, Blocks.planks, 1);
        this.setBlock(world, i + 10, j + 59, k + 29, Blocks.planks, 1);
        this.setBlock(world, i + 10, j + 59, k + 32, Blocks.stone, 0);
        this.setBlock(world, i + 10, j + 59, k + 33, Blocks.stone, 0);
        this.setBlock(world, i + 10, j + 59, k + 34, Blocks.stone, 0);
        this.setBlock(world, i + 10, j + 59, k + 35, Blocks.stone, 0);
        this.setBlock(world, i + 10, j + 59, k + 36, Blocks.stone, 0);
        this.setBlock(world, i + 10, j + 59, k + 37, Blocks.stone, 0);
        this.setBlock(world, i + 10, j + 59, k + 38, Blocks.stone, 0);
        this.setBlock(world, i + 10, j + 59, k + 39, Blocks.stone, 0);
        this.setBlock(world, i + 10, j + 59, k + 40, Blocks.stone, 0);
        this.setBlock(world, i + 10, j + 59, k + 41, Blocks.stone, 0);
        this.setBlock(world, i + 10, j + 59, k + 42, Blocks.stone, 0);
        this.setBlock(world, i + 10, j + 59, k + 43, Blocks.stone, 0);
        this.setBlock(world, i + 10, j + 59, k + 44, Blocks.stone, 0);
        this.setBlock(world, i + 10, j + 59, k + 45, Blocks.stone, 0);
        this.setBlock(world, i + 10, j + 59, k + 46, Blocks.stone, 0);
        this.setBlock(world, i + 10, j + 59, k + 47, Blocks.stone, 0);
        this.setBlock(world, i + 10, j + 59, k + 48, Blocks.stone, 0);
        this.setBlock(world, i + 10, j + 59, k + 49, Blocks.stone, 0);
        this.setBlock(world, i + 10, j + 59, k + 50, Blocks.stone, 0);
        this.setBlock(world, i + 10, j + 59, k + 51, Blocks.stone, 0);
        this.setBlock(world, i + 10, j + 59, k + 52, Blocks.stone, 0);
        this.setBlock(world, i + 10, j + 60, k + 23, Blocks.planks, 0);
        this.setBlock(world, i + 10, j + 60, k + 29, Blocks.planks, 1);
        this.setBlock(world, i + 10, j + 60, k + 32, Blocks.stone, 0);
        this.setBlock(world, i + 10, j + 60, k + 33, Blocks.stone, 0);
        this.setBlock(world, i + 10, j + 60, k + 34, Blocks.stone, 0);
        this.setBlock(world, i + 10, j + 60, k + 35, Blocks.stone, 0);
        this.setBlock(world, i + 10, j + 60, k + 36, Blocks.stone, 0);
        this.setBlock(world, i + 10, j + 60, k + 37, Blocks.stone, 0);
        this.setBlock(world, i + 10, j + 60, k + 38, Blocks.stone, 0);
        this.setBlock(world, i + 10, j + 60, k + 39, Blocks.stone, 0);
        this.setBlock(world, i + 10, j + 60, k + 42, Blocks.stone, 0);
        this.setBlock(world, i + 10, j + 60, k + 43, Blocks.stone, 0);
        this.setBlock(world, i + 10, j + 60, k + 44, Blocks.stone, 0);
        this.setBlock(world, i + 10, j + 60, k + 45, Blocks.stone, 0);
        this.setBlock(world, i + 10, j + 60, k + 46, Blocks.stone, 0);
        this.setBlock(world, i + 10, j + 60, k + 47, Blocks.stone, 0);
        this.setBlock(world, i + 10, j + 60, k + 48, Blocks.stone, 0);
        this.setBlock(world, i + 10, j + 60, k + 49, Blocks.stone, 0);
        this.setBlock(world, i + 10, j + 60, k + 50, Blocks.stone, 0);
        this.setBlock(world, i + 10, j + 60, k + 51, Blocks.stone, 0);
        this.setBlock(world, i + 10, j + 61, k + 24, Blocks.planks, 1);
        this.setBlock(world, i + 10, j + 61, k + 28, Blocks.planks, 0);
        this.setBlock(world, i + 10, j + 61, k + 32, Blocks.stone, 0);
        this.setBlock(world, i + 10, j + 61, k + 33, Blocks.stone, 0);
        this.setBlock(world, i + 10, j + 61, k + 34, Blocks.stone, 0);
        this.setBlock(world, i + 10, j + 61, k + 35, Blocks.stone, 0);
        this.setBlock(world, i + 10, j + 61, k + 36, Blocks.stone, 0);
        this.setBlock(world, i + 10, j + 61, k + 37, Blocks.stone, 0);
        this.setBlock(world, i + 10, j + 61, k + 38, Blocks.stone, 0);
        this.setBlock(world, i + 10, j + 61, k + 39, Blocks.stone, 0);
        this.setBlock(world, i + 10, j + 61, k + 45, Blocks.stone, 0);
        this.setBlock(world, i + 10, j + 61, k + 46, Blocks.stone, 0);
        this.setBlock(world, i + 10, j + 61, k + 47, Blocks.stone, 0);
        this.setBlock(world, i + 10, j + 62, k + 25, Blocks.planks, 1);
        this.setBlock(world, i + 10, j + 62, k + 27, Blocks.planks, 1);
        this.setBlock(world, i + 10, j + 63, k + 26, Blocks.planks, 0);
        this.setBlock(world, i + 11, j + 38, k + 100, Blocks.cobblestone_wall, 0);
        this.setBlock(world, i + 11, j + 38, k + 101, Blocks.stonebrick, 0);
        this.setBlock(world, i + 11, j + 38, k + 102, Blocks.stonebrick, 0);
        this.setBlock(world, i + 11, j + 38, k + 103, Blocks.stonebrick, 0);
        this.setBlock(world, i + 11, j + 38, k + 104, Blocks.stonebrick, 0);
        this.setBlock(world, i + 11, j + 38, k + 105, Blocks.stonebrick, 0);
        this.setBlock(world, i + 11, j + 38, k + 106, Blocks.stonebrick, 0);
        this.setBlock(world, i + 11, j + 38, k + 107, Blocks.stonebrick, 0);
        this.setBlock(world, i + 11, j + 38, k + 108, Blocks.cobblestone_wall, 0);
        this.setBlock(world, i + 11, j + 39, k + 100, Blocks.cobblestone_wall, 0);
        this.setBlock(world, i + 11, j + 39, k + 101, Blocks.stonebrick, 0);
        this.setBlock(world, i + 11, j + 39, k + 102, Blocks.stonebrick, 0);
        this.setBlock(world, i + 11, j + 39, k + 103, Blocks.stonebrick, 0);
        this.setBlock(world, i + 11, j + 39, k + 104, Blocks.stonebrick, 0);
        this.setBlock(world, i + 11, j + 39, k + 105, Blocks.stonebrick, 0);
        this.setBlock(world, i + 11, j + 39, k + 106, Blocks.stonebrick, 0);
        this.setBlock(world, i + 11, j + 39, k + 107, Blocks.stonebrick, 0);
        this.setBlock(world, i + 11, j + 39, k + 108, Blocks.cobblestone_wall, 0);
        this.setBlock(world, i + 11, j + 51, k + 29, Blocks.stone, 0);
        this.setBlock(world, i + 11, j + 51, k + 30, Blocks.stone, 0);
        this.setBlock(world, i + 11, j + 51, k + 31, Blocks.stone, 0);
        this.setBlock(world, i + 11, j + 51, k + 32, Blocks.stone, 0);
        this.setBlock(world, i + 11, j + 51, k + 33, Blocks.stone, 0);
        this.setBlock(world, i + 11, j + 52, k + 27, Blocks.cobblestone, 0);
        this.setBlock(world, i + 11, j + 52, k + 28, Blocks.stone, 0);
        this.setBlock(world, i + 11, j + 52, k + 29, Blocks.stone, 0);
        this.setBlock(world, i + 11, j + 52, k + 30, Blocks.stone, 0);
        this.setBlock(world, i + 11, j + 52, k + 31, Blocks.cobblestone, 0);
        this.setBlock(world, i + 11, j + 52, k + 32, Blocks.stone, 0);
        this.setBlock(world, i + 11, j + 52, k + 33, Blocks.stone, 0);
        this.setBlock(world, i + 11, j + 52, k + 34, Blocks.stone, 0);
        this.setBlock(world, i + 11, j + 52, k + 35, Blocks.stone, 0);
        this.setBlock(world, i + 11, j + 52, k + 36, Blocks.stone, 0);
        this.setBlock(world, i + 11, j + 52, k + 37, Blocks.stone, 0);
        this.setBlock(world, i + 11, j + 52, k + 38, Blocks.stone, 0);
        this.setBlock(world, i + 11, j + 52, k + 39, Blocks.stone, 0);
        this.setBlock(world, i + 11, j + 52, k + 40, Blocks.stone, 0);
        this.setBlock(world, i + 11, j + 52, k + 41, Blocks.stone, 0);
        this.setBlock(world, i + 11, j + 52, k + 42, Blocks.stone, 0);
        this.setBlock(world, i + 11, j + 52, k + 43, Blocks.stone, 0);
        this.setBlock(world, i + 11, j + 52, k + 44, Blocks.stone, 0);
        this.setBlock(world, i + 11, j + 52, k + 45, Blocks.cobblestone, 0);
        this.setBlock(world, i + 11, j + 52, k + 46, Blocks.stone, 0);
        this.setBlock(world, i + 11, j + 52, k + 47, Blocks.stone, 0);
        this.setBlock(world, i + 11, j + 52, k + 48, Blocks.stone, 0);
        this.setBlock(world, i + 11, j + 52, k + 49, Blocks.stone, 0);
        this.setBlock(world, i + 11, j + 53, k + 22, Blocks.stone, 0);
        this.setBlock(world, i + 11, j + 53, k + 26, Blocks.stone, 0);
        this.setBlock(world, i + 11, j + 53, k + 27, Blocks.stone, 0);
        this.setBlock(world, i + 11, j + 53, k + 28, Blocks.stone, 0);
        this.setBlock(world, i + 11, j + 53, k + 29, Blocks.stone, 0);
        this.setBlock(world, i + 11, j + 53, k + 30, Blocks.stone, 0);
        this.setBlock(world, i + 11, j + 53, k + 31, Blocks.stone, 0);
        this.setBlock(world, i + 11, j + 53, k + 32, Blocks.cobblestone, 0);
        this.setBlock(world, i + 11, j + 53, k + 33, Blocks.stone, 0);
        this.setBlock(world, i + 11, j + 53, k + 34, Blocks.stone, 0);
        this.setBlock(world, i + 11, j + 53, k + 35, Blocks.bedrock, 0);
        this.setBlock(world, i + 11, j + 53, k + 36, Blocks.bedrock, 0);
        this.setBlock(world, i + 11, j + 53, k + 37, Blocks.stone, 0);
        this.setBlock(world, i + 11, j + 53, k + 38, Blocks.bedrock, 0);
        this.setBlock(world, i + 11, j + 53, k + 39, Blocks.stone, 0);
        this.setBlock(world, i + 11, j + 53, k + 40, Blocks.stone, 0);
        this.setBlock(world, i + 11, j + 53, k + 41, Blocks.stone, 0);
        this.setBlock(world, i + 11, j + 53, k + 42, Blocks.stone, 0);
        this.setBlock(world, i + 11, j + 53, k + 43, Blocks.stone, 0);
        this.setBlock(world, i + 11, j + 53, k + 44, Blocks.stone, 0);
        this.setBlock(world, i + 11, j + 53, k + 45, Blocks.stone, 0);
        this.setBlock(world, i + 11, j + 53, k + 46, Blocks.stone, 0);
        this.setBlock(world, i + 11, j + 53, k + 47, Blocks.stone, 0);
        this.setBlock(world, i + 11, j + 53, k + 48, Blocks.stone, 0);
        this.setBlock(world, i + 11, j + 53, k + 49, Blocks.stone, 0);
        this.setBlock(world, i + 11, j + 53, k + 50, Blocks.stone, 0);
        this.setBlock(world, i + 11, j + 53, k + 51, Blocks.stone, 0);
        this.setBlock(world, i + 11, j + 53, k + 52, Blocks.bedrock, 0);
        this.setBlock(world, i + 11, j + 53, k + 53, Blocks.cobblestone, 0);
        this.setBlock(world, i + 11, j + 53, k + 54, Blocks.stone, 0);
        this.setBlock(world, i + 11, j + 53, k + 55, Blocks.bedrock, 0);
        this.setBlock(world, i + 11, j + 53, k + 56, Blocks.bedrock, 0);
        this.setBlock(world, i + 11, j + 54, k + 20, Blocks.stone, 0);
        this.setBlock(world, i + 11, j + 54, k + 21, Blocks.stone, 0);
        this.setBlock(world, i + 11, j + 54, k + 22, Blocks.stone, 0);
        this.setBlock(world, i + 11, j + 54, k + 23, Blocks.stone, 0);
        this.setBlock(world, i + 11, j + 54, k + 24, Blocks.stone, 0);
        this.setBlock(world, i + 11, j + 54, k + 25, Blocks.cobblestone, 0);
        this.setBlock(world, i + 11, j + 54, k + 26, Blocks.stone, 0);
        this.setBlock(world, i + 11, j + 54, k + 27, Blocks.stone, 0);
        this.setBlock(world, i + 11, j + 54, k + 28, Blocks.bedrock, 0);
        this.setBlock(world, i + 11, j + 54, k + 29, Blocks.stone, 0);
        this.setBlock(world, i + 11, j + 54, k + 30, Blocks.stone, 0);
        this.setBlock(world, i + 11, j + 54, k + 31, Blocks.stone, 0);
        this.setBlock(world, i + 11, j + 54, k + 32, Blocks.stone, 0);
        this.setBlock(world, i + 11, j + 54, k + 33, Blocks.stone, 0);
        this.setBlock(world, i + 11, j + 54, k + 34, Blocks.stone, 0);
        this.setBlock(world, i + 11, j + 54, k + 35, Blocks.stone, 0);
        this.setBlock(world, i + 11, j + 54, k + 36, Blocks.stone, 0);
        this.setBlock(world, i + 11, j + 54, k + 37, Blocks.stone, 0);
        this.setBlock(world, i + 11, j + 54, k + 38, Blocks.stone, 0);
        this.setBlock(world, i + 11, j + 54, k + 39, Blocks.stone, 0);
        this.setBlock(world, i + 11, j + 54, k + 40, Blocks.stone, 0);
        this.setBlock(world, i + 11, j + 54, k + 41, Blocks.stone, 0);
        this.setBlock(world, i + 11, j + 54, k + 42, Blocks.stone, 0);
        this.setBlock(world, i + 11, j + 54, k + 43, Blocks.stone, 0);
        this.setBlock(world, i + 11, j + 54, k + 44, Blocks.stone, 0);
        this.setBlock(world, i + 11, j + 54, k + 45, Blocks.stone, 0);
        this.setBlock(world, i + 11, j + 54, k + 46, Blocks.stone, 0);
        this.setBlock(world, i + 11, j + 54, k + 47, Blocks.stone, 0);
        this.setBlock(world, i + 11, j + 54, k + 48, Blocks.cobblestone, 0);
        this.setBlock(world, i + 11, j + 54, k + 49, Blocks.cobblestone, 0);
        this.setBlock(world, i + 11, j + 54, k + 50, Blocks.stone, 0);
        this.setBlock(world, i + 11, j + 54, k + 51, Blocks.cobblestone, 0);
        this.setBlock(world, i + 11, j + 54, k + 52, Blocks.stone, 0);
        this.setBlock(world, i + 11, j + 54, k + 53, Blocks.stone, 0);
        this.setBlock(world, i + 11, j + 54, k + 54, Blocks.stone, 0);
        this.setBlock(world, i + 11, j + 54, k + 55, Blocks.stone, 0);
        this.setBlock(world, i + 11, j + 54, k + 56, Blocks.cobblestone, 0);
        this.setBlock(world, i + 11, j + 54, k + 57, Blocks.bedrock, 0);
        this.setBlock(world, i + 11, j + 54, k + 58, Blocks.stone, 0);
        this.setBlock(world, i + 11, j + 54, k + 59, Blocks.stone, 0);
        this.setBlock(world, i + 11, j + 55, k + 19, Blocks.stone, 0);
        this.setBlock(world, i + 11, j + 55, k + 20, Blocks.stone, 0);
        this.setBlock(world, i + 11, j + 55, k + 21, Blocks.stone, 0);
        this.setBlock(world, i + 11, j + 55, k + 22, Blocks.stone, 0);
        this.setBlock(world, i + 11, j + 55, k + 23, Blocks.stone, 0);
        this.setBlock(world, i + 11, j + 55, k + 24, Blocks.stone, 0);
        this.setBlock(world, i + 11, j + 55, k + 25, Blocks.stone, 0);
        this.setBlock(world, i + 11, j + 55, k + 26, Blocks.bedrock, 0);
        this.setBlock(world, i + 11, j + 55, k + 27, Blocks.stone, 0);
        this.setBlock(world, i + 11, j + 55, k + 28, Blocks.stone, 0);
        this.setBlock(world, i + 11, j + 55, k + 29, Blocks.stone, 0);
        this.setBlock(world, i + 11, j + 55, k + 30, Blocks.stone, 0);
        this.setBlock(world, i + 11, j + 55, k + 31, Blocks.stone, 0);
        this.setBlock(world, i + 11, j + 55, k + 32, Blocks.stone, 0);
        this.setBlock(world, i + 11, j + 55, k + 33, Blocks.stone, 0);
        this.setBlock(world, i + 11, j + 55, k + 34, Blocks.stone, 0);
        this.setBlock(world, i + 11, j + 55, k + 35, Blocks.stone, 0);
        this.setBlock(world, i + 11, j + 55, k + 36, Blocks.cobblestone, 0);
        this.setBlock(world, i + 11, j + 55, k + 37, Blocks.stone, 0);
        this.setBlock(world, i + 11, j + 55, k + 38, Blocks.stone, 0);
        this.setBlock(world, i + 11, j + 55, k + 39, Blocks.stone, 0);
        this.setBlock(world, i + 11, j + 55, k + 40, Blocks.stone, 0);
        this.setBlock(world, i + 11, j + 55, k + 41, Blocks.stone, 0);
        this.setBlock(world, i + 11, j + 55, k + 42, Blocks.stone, 0);
        this.setBlock(world, i + 11, j + 55, k + 43, Blocks.stone, 0);
        this.setBlock(world, i + 11, j + 55, k + 44, Blocks.bedrock, 0);
        this.setBlock(world, i + 11, j + 55, k + 45, Blocks.stone, 0);
        this.setBlock(world, i + 11, j + 55, k + 46, Blocks.stone, 0);
        this.setBlock(world, i + 11, j + 55, k + 47, Blocks.stone, 0);
        this.setBlock(world, i + 11, j + 55, k + 48, Blocks.stone, 0);
        this.setBlock(world, i + 11, j + 55, k + 49, Blocks.stone, 0);
        this.setBlock(world, i + 11, j + 55, k + 50, Blocks.stone, 0);
        this.setBlock(world, i + 11, j + 55, k + 51, Blocks.stone, 0);
        this.setBlock(world, i + 11, j + 55, k + 52, Blocks.bedrock, 0);
        this.setBlock(world, i + 11, j + 55, k + 53, Blocks.stone, 0);
        this.setBlock(world, i + 11, j + 55, k + 54, Blocks.stone, 0);
        this.setBlock(world, i + 11, j + 55, k + 55, Blocks.stone, 0);
        this.setBlock(world, i + 11, j + 55, k + 56, Blocks.bedrock, 0);
        this.setBlock(world, i + 11, j + 55, k + 57, Blocks.cobblestone, 0);
        this.setBlock(world, i + 11, j + 55, k + 58, Blocks.stone, 0);
        this.setBlock(world, i + 11, j + 55, k + 59, Blocks.stone, 0);
        this.setBlock(world, i + 11, j + 55, k + 60, Blocks.stone, 0);
        this.setBlock(world, i + 11, j + 55, k + 61, Blocks.cobblestone, 0);
        this.setBlock(world, i + 11, j + 56, k + 19, Blocks.stone, 0);
        this.setBlock(world, i + 11, j + 56, k + 20, Blocks.stone, 0);
        this.setBlock(world, i + 11, j + 56, k + 21, Blocks.stone, 0);
        this.setBlock(world, i + 11, j + 56, k + 22, Blocks.cobblestone, 0);
        this.setBlock(world, i + 11, j + 56, k + 23, Blocks.stone, 0);
        this.setBlock(world, i + 11, j + 56, k + 24, Blocks.wool, 6);
        this.setBlock(world, i + 11, j + 56, k + 25, Blocks.wool, 6);
        this.setBlock(world, i + 11, j + 56, k + 26, Blocks.wool, 6);
        this.setBlock(world, i + 11, j + 56, k + 27, Blocks.wool, 14);
        this.setBlock(world, i + 11, j + 56, k + 28, Blocks.wool, 6);
        this.setBlock(world, i + 11, j + 56, k + 29, Blocks.bedrock, 0);
        this.setBlock(world, i + 11, j + 56, k + 30, Blocks.stone, 0);
        this.setBlock(world, i + 11, j + 56, k + 31, Blocks.stone, 0);
        this.setBlock(world, i + 11, j + 56, k + 32, Blocks.stone, 0);
        this.setBlock(world, i + 11, j + 56, k + 33, Blocks.stone, 0);
        this.setBlock(world, i + 11, j + 56, k + 34, Blocks.stone, 0);
        this.setBlock(world, i + 11, j + 56, k + 35, Blocks.stone, 0);
        this.setBlock(world, i + 11, j + 56, k + 36, Blocks.stone, 0);
        this.setBlock(world, i + 11, j + 56, k + 37, Blocks.stone, 0);
        this.setBlock(world, i + 11, j + 56, k + 38, Blocks.stone, 0);
        this.setBlock(world, i + 11, j + 56, k + 39, Blocks.stone, 0);
        this.setBlock(world, i + 11, j + 56, k + 40, Blocks.stone, 0);
        this.setBlock(world, i + 11, j + 56, k + 41, Blocks.stone, 0);
        this.setBlock(world, i + 11, j + 56, k + 42, Blocks.stone, 0);
        this.setBlock(world, i + 11, j + 56, k + 43, Blocks.stone, 0);
        this.setBlock(world, i + 11, j + 56, k + 44, Blocks.stone, 0);
        this.setBlock(world, i + 11, j + 56, k + 45, Blocks.stone, 0);
        this.setBlock(world, i + 11, j + 56, k + 46, Blocks.stone, 0);
        this.setBlock(world, i + 11, j + 56, k + 47, Blocks.stone, 0);
        this.setBlock(world, i + 11, j + 56, k + 48, Blocks.stone, 0);
        this.setBlock(world, i + 11, j + 56, k + 49, Blocks.stone, 0);
        this.setBlock(world, i + 11, j + 56, k + 50, Blocks.stone, 0);
        this.setBlock(world, i + 11, j + 56, k + 51, Blocks.stone, 0);
        this.setBlock(world, i + 11, j + 56, k + 52, Blocks.stone, 0);
        this.setBlock(world, i + 11, j + 56, k + 53, Blocks.stone, 0);
        this.setBlock(world, i + 11, j + 56, k + 54, Blocks.stone, 0);
        this.setBlock(world, i + 11, j + 56, k + 55, Blocks.stone, 0);
        this.setBlock(world, i + 11, j + 56, k + 56, Blocks.stone, 0);
        this.setBlock(world, i + 11, j + 56, k + 57, Blocks.stone, 0);
        this.setBlock(world, i + 11, j + 56, k + 58, Blocks.stone, 0);
        this.setBlock(world, i + 11, j + 56, k + 59, Blocks.stone, 0);
        this.setBlock(world, i + 11, j + 56, k + 60, Blocks.stone, 0);
        this.setBlock(world, i + 11, j + 56, k + 61, Blocks.stone, 0);
        this.setBlock(world, i + 11, j + 56, k + 62, Blocks.stone, 0);
        this.setBlock(world, i + 11, j + 57, k + 23, Blocks.planks, 1);
        this.setBlock(world, i + 11, j + 57, k + 29, Blocks.planks, 1);
        this.setBlock(world, i + 11, j + 57, k + 30, Blocks.stone, 0);
        this.setBlock(world, i + 11, j + 57, k + 31, Blocks.stone, 0);
        this.setBlock(world, i + 11, j + 57, k + 32, Blocks.stone, 0);
        this.setBlock(world, i + 11, j + 57, k + 33, Blocks.stone, 0);
        this.setBlock(world, i + 11, j + 57, k + 34, Blocks.stone, 0);
        this.setBlock(world, i + 11, j + 57, k + 35, Blocks.stone, 0);
        this.setBlock(world, i + 11, j + 57, k + 36, Blocks.stone, 0);
        this.setBlock(world, i + 11, j + 57, k + 37, Blocks.stone, 0);
        this.setBlock(world, i + 11, j + 57, k + 38, Blocks.stone, 0);
        this.setBlock(world, i + 11, j + 57, k + 39, Blocks.stone, 0);
        this.setBlock(world, i + 11, j + 57, k + 40, Blocks.stone, 0);
        this.setBlock(world, i + 11, j + 57, k + 41, Blocks.stone, 0);
        this.setBlock(world, i + 11, j + 57, k + 42, Blocks.stone, 0);
        this.setBlock(world, i + 11, j + 57, k + 43, Blocks.stone, 0);
        this.setBlock(world, i + 11, j + 57, k + 44, Blocks.stone, 0);
        this.setBlock(world, i + 11, j + 57, k + 45, Blocks.stone, 0);
        this.setBlock(world, i + 11, j + 57, k + 46, Blocks.stone, 0);
        this.setBlock(world, i + 11, j + 57, k + 47, Blocks.stone, 0);
        this.setBlock(world, i + 11, j + 57, k + 48, Blocks.stone, 0);
        this.setBlock(world, i + 11, j + 57, k + 49, Blocks.stone, 0);
        this.setBlock(world, i + 11, j + 57, k + 50, Blocks.stone, 0);
        this.setBlock(world, i + 11, j + 57, k + 51, Blocks.stone, 0);
        this.setBlock(world, i + 11, j + 57, k + 52, Blocks.stone, 0);
        this.setBlock(world, i + 11, j + 57, k + 53, Blocks.stone, 0);
        this.setBlock(world, i + 11, j + 57, k + 54, Blocks.stone, 0);
        this.setBlock(world, i + 11, j + 57, k + 55, Blocks.cobblestone, 0);
        this.setBlock(world, i + 11, j + 58, k + 23, Blocks.glass_pane, 0);
        this.setBlock(world, i + 11, j + 58, k + 29, Blocks.glass_pane, 0);
        this.setBlock(world, i + 11, j + 58, k + 30, Blocks.stone, 0);
        this.setBlock(world, i + 11, j + 58, k + 31, Blocks.stone, 0);
        this.setBlock(world, i + 11, j + 58, k + 32, Blocks.stone, 0);
        this.setBlock(world, i + 11, j + 58, k + 33, Blocks.stone, 0);
        this.setBlock(world, i + 11, j + 58, k + 34, Blocks.stone, 0);
        this.setBlock(world, i + 11, j + 58, k + 35, Blocks.stone, 0);
        this.setBlock(world, i + 11, j + 58, k + 36, Blocks.stone, 0);
        this.setBlock(world, i + 11, j + 58, k + 37, Blocks.stone, 0);
        this.setBlock(world, i + 11, j + 58, k + 38, Blocks.stone, 0);
        this.setBlock(world, i + 11, j + 58, k + 39, Blocks.stone, 0);
        this.setBlock(world, i + 11, j + 58, k + 40, Blocks.stone, 0);
        this.setBlock(world, i + 11, j + 58, k + 41, Blocks.stone, 0);
        this.setBlock(world, i + 11, j + 58, k + 42, Blocks.stone, 0);
        this.setBlock(world, i + 11, j + 58, k + 43, Blocks.stone, 0);
        this.setBlock(world, i + 11, j + 58, k + 44, Blocks.stone, 0);
        this.setBlock(world, i + 11, j + 58, k + 45, Blocks.stone, 0);
        this.setBlock(world, i + 11, j + 58, k + 46, Blocks.stone, 0);
        this.setBlock(world, i + 11, j + 58, k + 47, Blocks.stone, 0);
        this.setBlock(world, i + 11, j + 58, k + 48, Blocks.stone, 0);
        this.setBlock(world, i + 11, j + 58, k + 49, Blocks.stone, 0);
        this.setBlock(world, i + 11, j + 58, k + 50, Blocks.stone, 0);
        this.setBlock(world, i + 11, j + 58, k + 51, Blocks.stone, 0);
