

package com.gibby.dungeon.gen;

import com.gibby.dungeon.Dungeons;
import cpw.mods.fml.common.IWorldGenerator;
import net.minecraft.block.Block;
import net.minecraft.init.Blocks;
import net.minecraft.world.IBlockAccess;
import net.minecraft.world.World;
import net.minecraft.world.chunk.IChunkProvider;
import net.minecraft.world.gen.feature.WorldGenerator;

import java.util.Random;

public class WorldGenMontaneDungeon_6 extends WorldGenerator implements IWorldGenerator
{
    public void generate(final Random random, final int chunkX, final int chunkZ, final World world, final IChunkProvider chunkGenerator, final IChunkProvider chunkProvider) {
    }

    public void setBlock(final World world, final int x, final int y, final int z, final Block block, final int metadata) {
        final Block b1 = world.getBlock(x, y, z);
        if (b1.isAir((IBlockAccess)world, x, y, z) || b1.isLeaves((IBlockAccess)world, x, y, z)) {
            world.setBlock(x, y, z, block, metadata, 2);
        }
    }

    public boolean generate(final World world, final Random rand, final int i, final int j, final int k) {
        this.setBlock(world, i, j + 39, k + 96, Dungeons.blockUnbreableStone, 0);
        this.setBlock(world, i, j + 39, k + 97, Dungeons.blockUnbreableStone, 0);
        this.setBlock(world, i, j + 39, k + 98, Dungeons.blockUnbreableStone, 0);
        this.setBlock(world, i, j + 39, k + 99, Dungeons.blockUnbreableStone, 0);
        this.setBlock(world, i, j + 39, k + 100, Dungeons.blockUnbreableCobbleStone, 0);
        this.setBlock(world, i, j + 39, k + 101, Dungeons.blockUnbreableStone, 0);
        this.setBlock(world, i, j + 39, k + 102, Dungeons.blockUnbreableStone, 0);
        this.setBlock(world, i, j + 39, k + 103, Dungeons.blockUnbreableStone, 0);
        this.setBlock(world, i, j + 39, k + 104, Blocks.bedrock, 0);
        this.setBlock(world, i, j + 39, k + 105, Dungeons.blockUnbreableStone, 0);
        this.setBlock(world, i, j + 39, k + 106, Dungeons.blockUnbreableStone, 0);
        this.setBlock(world, i, j + 39, k + 107, Dungeons.blockUnbreableStone, 0);
        this.setBlock(world, i, j + 39, k + 108, Dungeons.blockUnbreableStone, 0);
        this.setBlock(world, i, j + 39, k + 109, Dungeons.blockUnbreableStone, 0);
        this.setBlock(world, i, j + 39, k + 110, Dungeons.blockUnbreableStone, 0);
        this.setBlock(world, i, j + 39, k + 111, Blocks.bedrock, 0);
        this.setBlock(world, i, j + 39, k + 112, Dungeons.blockUnbreableStone, 0);
        this.setBlock(world, i, j + 39, k + 116, Dungeons.blockUnbreableStone, 0);
        this.setBlock(world, i, j + 39, k + 117, Blocks.bedrock, 0);
        this.setBlock(world, i, j + 40, k + 96, Dungeons.blockUnbreableCobbleStone, 0);
        this.setBlock(world, i, j + 40, k + 97, Dungeons.blockUnbreableStone, 0);
        this.setBlock(world, i, j + 40, k + 98, Dungeons.blockUnbreableCobbleStone, 0);
        this.setBlock(world, i, j + 40, k + 99, Blocks.bedrock, 0);
        this.setBlock(world, i, j + 40, k + 100, Dungeons.blockUnbreableStone, 0);
        this.setBlock(world, i, j + 40, k + 101, Blocks.bedrock, 0);
        this.setBlock(world, i, j + 40, k + 102, Dungeons.blockUnbreableStone, 0);
        this.setBlock(world, i, j + 40, k + 103, Dungeons.blockUnbreableStone, 0);
        this.setBlock(world, i, j + 40, k + 104, Dungeons.blockUnbreableStone, 0);
        this.setBlock(world, i, j + 40, k + 105, Dungeons.blockUnbreableStone, 0);
        this.setBlock(world, i, j + 40, k + 106, Dungeons.blockUnbreableStone, 0);
        this.setBlock(world, i, j + 40, k + 107, Dungeons.blockUnbreableStone, 0);
        this.setBlock(world, i, j + 40, k + 108, Blocks.bedrock, 0);
        this.setBlock(world, i, j + 40, k + 109, Dungeons.blockUnbreableStone, 0);
        this.setBlock(world, i, j + 40, k + 110, Dungeons.blockUnbreableStone, 0);
        this.setBlock(world, i, j + 40, k + 111, Dungeons.blockUnbreableStone, 0);
        this.setBlock(world, i, j + 40, k + 112, Dungeons.blockUnbreableStone, 0);
        this.setBlock(world, i, j + 40, k + 113, Dungeons.blockUnbreableStone, 0);
        this.setBlock(world, i, j + 40, k + 115, Dungeons.blockUnbreableStone, 0);
        this.setBlock(world, i, j + 40, k + 116, Dungeons.blockUnbreableStone, 0);
        this.setBlock(world, i, j + 40, k + 117, Blocks.bedrock, 0);
        this.setBlock(world, i, j + 40, k + 118, Dungeons.blockUnbreableStone, 0);
        this.setBlock(world, i, j + 40, k + 119, Dungeons.blockUnbreableStone, 0);
        this.setBlock(world, i, j + 41, k + 83, Dungeons.blockUnbreableStone, 0);
        this.setBlock(world, i, j + 41, k + 84, Dungeons.blockUnbreableStone, 0);
        this.setBlock(world, i, j + 41, k + 85, Dungeons.blockUnbreableCobbleStone, 0);
        this.setBlock(world, i, j + 41, k + 86, Dungeons.blockUnbreableStone, 0);
        this.setBlock(world, i, j + 41, k + 87, Dungeons.blockUnbreableStone, 0);
        this.setBlock(world, i, j + 41, k + 88, Dungeons.blockUnbreableStone, 0);
        this.setBlock(world, i, j + 41, k + 89, Dungeons.blockUnbreableStone, 0);
        this.setBlock(world, i, j + 41, k + 90, Dungeons.blockUnbreableStone, 0);
        this.setBlock(world, i, j + 41, k + 91, Dungeons.blockUnbreableStone, 0);
        this.setBlock(world, i, j + 41, k + 92, Blocks.bedrock, 0);
        this.setBlock(world, i, j + 41, k + 93, Dungeons.blockUnbreableCobbleStone, 0);
        this.setBlock(world, i, j + 41, k + 94, Dungeons.blockUnbreableStone, 0);
        this.setBlock(world, i, j + 41, k + 95, Dungeons.blockUnbreableStone, 0);
        this.setBlock(world, i, j + 41, k + 96, Blocks.bedrock, 0);
        this.setBlock(world, i, j + 41, k + 97, Dungeons.blockUnbreableCobbleStone, 0);
        this.setBlock(world, i, j + 41, k + 98, Dungeons.blockUnbreableStone, 0);
        this.setBlock(world, i, j + 41, k + 99, Dungeons.blockUnbreableStone, 0);
        this.setBlock(world, i, j + 41, k + 100, Dungeons.blockUnbreableCobbleStone, 0);
        this.setBlock(world, i, j + 41, k + 101, Dungeons.blockUnbreableStone, 0);
        this.setBlock(world, i, j + 41, k + 102, Dungeons.blockUnbreableStone, 0);
        this.setBlock(world, i, j + 41, k + 103, Dungeons.blockUnbreableCobbleStone, 0);
        this.setBlock(world, i, j + 41, k + 104, Dungeons.blockUnbreableStone, 0);
        this.setBlock(world, i, j + 41, k + 105, Dungeons.blockUnbreableStone, 0);
        this.setBlock(world, i, j + 41, k + 106, Dungeons.blockUnbreableCobbleStone, 0);
        this.setBlock(world, i, j + 41, k + 107, Dungeons.blockUnbreableStone, 0);
        this.setBlock(world, i, j + 41, k + 108, Blocks.bedrock, 0);
        this.setBlock(world, i, j + 41, k + 109, Dungeons.blockUnbreableStone, 0);
        this.setBlock(world, i, j + 41, k + 110, Dungeons.blockUnbreableStone, 0);
        this.setBlock(world, i, j + 41, k + 111, Dungeons.blockUnbreableStone, 0);
        this.setBlock(world, i, j + 41, k + 112, Dungeons.blockUnbreableStone, 0);
        this.setBlock(world, i, j + 41, k + 113, Dungeons.blockUnbreableStone, 0);
        this.setBlock(world, i, j + 41, k + 114, Dungeons.blockUnbreableStone, 0);
        this.setBlock(world, i, j + 41, k + 115, Blocks.bedrock, 0);
        this.setBlock(world, i, j + 41, k + 116, Dungeons.blockUnbreableStone, 0);
        this.setBlock(world, i, j + 41, k + 117, Dungeons.blockUnbreableStone, 0);
        this.setBlock(world, i, j + 41, k + 118, Dungeons.blockUnbreableStone, 0);
        this.setBlock(world, i, j + 41, k + 119, Dungeons.blockUnbreableStone, 0);
        this.setBlock(world, i, j + 41, k + 120, Dungeons.blockUnbreableStone, 0);
        this.setBlock(world, i, j + 41, k + 121, Dungeons.blockUnbreableStone, 0);
        this.setBlock(world, i, j + 42, k + 80, Dungeons.blockUnbreableStone, 0);
        this.setBlock(world, i, j + 42, k + 81, Dungeons.blockUnbreableStone, 0);
        this.setBlock(world, i, j + 42, k + 82, Dungeons.blockUnbreableCobbleStone, 0);
        this.setBlock(world, i, j + 42, k + 83, Dungeons.blockUnbreableStone, 0);
        this.setBlock(world, i, j + 42, k + 84, Dungeons.blockUnbreableStone, 0);
        this.setBlock(world, i, j + 42, k + 85, Dungeons.blockUnbreableStone, 0);
        this.setBlock(world, i, j + 42, k + 86, Dungeons.blockUnbreableCobbleStone, 0);
        this.setBlock(world, i, j + 42, k + 87, Dungeons.blockUnbreableStone, 0);
        this.setBlock(world, i, j + 42, k + 88, Dungeons.blockUnbreableCobbleStone, 0);
        this.setBlock(world, i, j + 42, k + 89, Dungeons.blockUnbreableStone, 0);
        this.setBlock(world, i, j + 42, k + 90, Dungeons.blockUnbreableStone, 0);
        this.setBlock(world, i, j + 42, k + 91, Blocks.bedrock, 0);
        this.setBlock(world, i, j + 42, k + 92, Dungeons.blockUnbreableStone, 0);
        this.setBlock(world, i, j + 42, k + 93, Dungeons.blockUnbreableStone, 0);
        this.setBlock(world, i, j + 42, k + 94, Dungeons.blockUnbreableStone, 0);
        this.setBlock(world, i, j + 42, k + 95, Dungeons.blockUnbreableStone, 0);
        this.setBlock(world, i, j + 42, k + 96, Dungeons.blockUnbreableStone, 0);
        this.setBlock(world, i, j + 42, k + 97, Dungeons.blockUnbreableStone, 0);
        this.setBlock(world, i, j + 42, k + 98, Blocks.bedrock, 0);
        this.setBlock(world, i, j + 42, k + 99, Dungeons.blockUnbreableStone, 0);
        this.setBlock(world, i, j + 42, k + 100, Dungeons.blockUnbreableStone, 0);
        this.setBlock(world, i, j + 42, k + 101, Dungeons.blockUnbreableStone, 0);
        this.setBlock(world, i, j + 42, k + 102, Dungeons.blockUnbreableStone, 0);
        this.setBlock(world, i, j + 42, k + 103, Dungeons.blockUnbreableStone, 0);
        this.setBlock(world, i, j + 42, k + 104, Dungeons.blockUnbreableCobbleStone, 0);
        this.setBlock(world, i, j + 42, k + 105, Blocks.bedrock, 0);
        this.setBlock(world, i, j + 42, k + 106, Blocks.bedrock, 0);
        this.setBlock(world, i, j + 42, k + 107, Dungeons.blockUnbreableStone, 0);
        this.setBlock(world, i, j + 42, k + 108, Dungeons.blockUnbreableStone, 0);
        this.setBlock(world, i, j + 42, k + 109, Dungeons.blockUnbreableStone, 0);
        this.setBlock(world, i, j + 42, k + 110, Dungeons.blockUnbreableStone, 0);
        this.setBlock(world, i, j + 42, k + 111, Dungeons.blockUnbreableStone, 0);
        this.setBlock(world, i, j + 42, k + 112, Blocks.bedrock, 0);
        this.setBlock(world, i, j + 42, k + 113, Blocks.bedrock, 0);
        this.setBlock(world, i, j + 42, k + 114, Dungeons.blockUnbreableStone, 0);
        this.setBlock(world, i, j + 42, k + 115, Dungeons.blockUnbreableStone, 0);
        this.setBlock(world, i, j + 42, k + 116, Dungeons.blockUnbreableStone, 0);
        this.setBlock(world, i, j + 42, k + 117, Dungeons.blockUnbreableStone, 0);
        this.setBlock(world, i, j + 42, k + 118, Dungeons.blockUnbreableStone, 0);
        this.setBlock(world, i, j + 42, k + 119, Dungeons.blockUnbreableStone, 0);
        this.setBlock(world, i, j + 42, k + 120, Dungeons.blockUnbreableStone, 0);
        this.setBlock(world, i, j + 42, k + 121, Dungeons.blockUnbreableStone, 0);
        this.setBlock(world, i, j + 42, k + 122, Blocks.bedrock, 0);
        this.setBlock(world, i, j + 42, k + 123, Dungeons.blockUnbreableStone, 0);
        this.setBlock(world, i, j + 43, k + 93, Dungeons.blockUnbreableStonebrick, 0);
        this.setBlock(world, i, j + 43, k + 94, Dungeons.blockUnbreableStonebrick, 0);
        this.setBlock(world, i, j + 43, k + 95, Blocks.obsidian, 0);
        this.setBlock(world, i, j + 43, k + 96, Dungeons.blockUnbreableStonebrick, 0);
        this.setBlock(world, i, j + 43, k + 97, Dungeons.blockUnbreableStonebrick, 0);
        this.setBlock(world, i, j + 43, k + 98, Dungeons.blockUnbreableStone, 0);
        this.setBlock(world, i, j + 43, k + 99, Dungeons.blockUnbreableStone, 0);
        this.setBlock(world, i, j + 43, k + 100, Dungeons.blockUnbreableStone, 0);
        this.setBlock(world, i, j + 43, k + 101, Dungeons.blockUnbreableStone, 0);
        this.setBlock(world, i, j + 43, k + 102, Dungeons.blockUnbreableStone, 0);
        this.setBlock(world, i, j + 43, k + 103, Dungeons.blockUnbreableStone, 0);
        this.setBlock(world, i, j + 43, k + 104, Dungeons.blockUnbreableStone, 0);
        this.setBlock(world, i, j + 43, k + 105, Dungeons.blockUnbreableStone, 0);
        this.setBlock(world, i, j + 43, k + 106, Dungeons.blockUnbreableStone, 0);
        this.setBlock(world, i, j + 43, k + 107, Dungeons.blockUnbreableStone, 0);
        this.setBlock(world, i, j + 43, k + 108, Dungeons.blockUnbreableStone, 0);
        this.setBlock(world, i, j + 43, k + 109, Dungeons.blockUnbreableStone, 0);
        this.setBlock(world, i, j + 43, k + 110, Dungeons.blockUnbreableStone, 0);
        this.setBlock(world, i, j + 43, k + 111, Dungeons.blockUnbreableStone, 0);
        this.setBlock(world, i, j + 43, k + 112, Dungeons.blockUnbreableStone, 0);
        this.setBlock(world, i, j + 43, k + 113, Dungeons.blockUnbreableStone, 0);
        this.setBlock(world, i, j + 43, k + 114, Blocks.bedrock, 0);
        this.setBlock(world, i, j + 43, k + 115, Dungeons.blockUnbreableStone, 0);
        this.setBlock(world, i, j + 43, k + 116, Dungeons.blockUnbreableStone, 0);
        this.setBlock(world, i, j + 44, k + 83, Blocks.leaves, 1);
        this.setBlock(world, i, j + 44, k + 93, Dungeons.blockUnbreableStonebrick, 0);
        this.setBlock(world, i, j + 44, k + 94, Dungeons.blockUnbreableStonebrick, 0);
        this.setBlock(world, i, j + 44, k + 95, Blocks.obsidian, 0);
        this.setBlock(world, i, j + 44, k + 101, Dungeons.blockUnbreableStone, 0);
        this.setBlock(world, i, j + 44, k + 102, Dungeons.blockUnbreableCobbleStone, 0);
        this.setBlock(world, i, j + 44, k + 103, Blocks.bedrock, 0);
        this.setBlock(world, i, j + 44, k + 104, Dungeons.blockUnbreableStone, 0);
        this.setBlock(world, i, j + 44, k + 105, Dungeons.blockUnbreableStone, 0);
        this.setBlock(world, i, j + 44, k + 106, Dungeons.blockUnbreableStone, 0);
        this.setBlock(world, i, j + 44, k + 109, Dungeons.blockUnbreableCobbleStone, 0);
        this.setBlock(world, i, j + 44, k + 110, Dungeons.blockUnbreableCobbleStone, 0);
        this.setBlock(world, i, j + 44, k + 111, Dungeons.blockUnbreableStone, 0);
        this.setBlock(world, i, j + 44, k + 112, Dungeons.blockUnbreableStone, 0);
        this.setBlock(world, i, j + 44, k + 113, Blocks.obsidian, 0);
        this.setBlock(world, i, j + 44, k + 114, Blocks.bedrock, 0);
        this.setBlock(world, i, j + 44, k + 115, Dungeons.blockUnbreableStone, 0);
        this.setBlock(world, i, j + 44, k + 116, Blocks.bedrock, 0);
        this.setBlock(world, i, j + 45, k + 81, Blocks.leaves, 1);
        this.setBlock(world, i, j + 45, k + 82, Blocks.leaves, 1);
        this.setBlock(world, i, j + 45, k + 83, Blocks.leaves, 1);
        this.setBlock(world, i, j + 45, k + 84, Blocks.leaves, 1);
        this.setBlock(world, i, j + 45, k + 85, Blocks.leaves, 1);
        this.setBlock(world, i, j + 45, k + 93, Dungeons.blockUnbreableStonebrick, 0);
        this.setBlock(world, i, j + 45, k + 94, Dungeons.blockUnbreableStonebrick, 0);
        this.setBlock(world, i, j + 45, k + 95, Blocks.obsidian, 0);
        this.setBlock(world, i, j + 45, k + 102, Dungeons.blockUnbreableStonebrick, 0);
        this.setBlock(world, i, j + 45, k + 103, Dungeons.blockUnbreableStonebrick, 0);
        this.setBlock(world, i, j + 45, k + 104, Dungeons.blockUnbreableStonebrick, 0);
        this.setBlock(world, i, j + 45, k + 105, Dungeons.blockUnbreableStonebrick, 0);
        this.setBlock(world, i, j + 45, k + 106, Dungeons.blockUnbreableStonebrick, 0);
        this.setBlock(world, i, j + 45, k + 113, Blocks.obsidian, 0);
        this.setBlock(world, i, j + 45, k + 114, Dungeons.blockUnbreableStone, 0);
        this.setBlock(world, i, j + 45, k + 115, Dungeons.blockUnbreableCobbleStone, 0);
        this.setBlock(world, i, j + 45, k + 116, Dungeons.blockUnbreableStone, 0);
        this.setBlock(world, i, j + 46, k + 83, Blocks.leaves, 1);
        this.setBlock(world, i, j + 46, k + 93, Dungeons.blockUnbreableStonebrick, 0);
        this.setBlock(world, i, j + 46, k + 94, Dungeons.blockUnbreableStonebrick, 0);
        this.setBlock(world, i, j + 46, k + 95, Blocks.obsidian, 0);
        this.setBlock(world, i, j + 46, k + 102, Dungeons.blockUnbreableStonebrick, 0);
        this.setBlock(world, i, j + 46, k + 103, Dungeons.blockUnbreableStonebrick, 0);
        this.setBlock(world, i, j + 46, k + 104, Dungeons.blockUnbreableStonebrick, 0);
        this.setBlock(world, i, j + 46, k + 105, Dungeons.blockUnbreableStonebrick, 0);
        this.setBlock(world, i, j + 46, k + 106, Dungeons.blockUnbreableStonebrick, 0);
        this.setBlock(world, i, j + 46, k + 113, Blocks.obsidian, 0);
        this.setBlock(world, i, j + 46, k + 114, Dungeons.blockUnbreableStonebrick, 0);
        this.setBlock(world, i, j + 46, k + 115, Dungeons.blockUnbreableStonebrick, 0);
        this.setBlock(world, i, j + 47, k + 81, Blocks.leaves, 1);
        this.setBlock(world, i, j + 47, k + 82, Blocks.leaves, 1);
        this.setBlock(world, i, j + 47, k + 83, Blocks.leaves, 1);
        this.setBlock(world, i, j + 47, k + 84, Blocks.leaves, 1);
        this.setBlock(world, i, j + 47, k + 85, Blocks.leaves, 1);
        this.setBlock(world, i, j + 47, k + 93, Dungeons.blockUnbreableStonebrick, 0);
        this.setBlock(world, i, j + 47, k + 94, Dungeons.blockUnbreableStonebrick, 0);
        this.setBlock(world, i, j + 47, k + 95, Blocks.obsidian, 0);
        this.setBlock(world, i, j + 47, k + 102, Dungeons.blockUnbreableStonebrick, 0);
        this.setBlock(world, i, j + 47, k + 103, Dungeons.blockUnbreableStonebrick, 0);
        this.setBlock(world, i, j + 47, k + 104, Dungeons.blockUnbreableStonebrick, 0);
        this.setBlock(world, i, j + 47, k + 105, Dungeons.blockUnbreableStonebrick, 0);
        this.setBlock(world, i, j + 47, k + 106, Dungeons.blockUnbreableStonebrick, 0);
        this.setBlock(world, i, j + 47, k + 113, Blocks.obsidian, 0);
        this.setBlock(world, i, j + 47, k + 114, Dungeons.blockUnbreableStonebrick, 0);
        this.setBlock(world, i, j + 47, k + 115, Dungeons.blockUnbreableStonebrick, 0);
        this.setBlock(world, i, j + 48, k + 83, Blocks.leaves, 1);
        this.setBlock(world, i, j + 48, k + 95, Dungeons.blockUnbreableStonebrick, 0);
        this.setBlock(world, i, j + 48, k + 96, Blocks.bedrock, 0);
        this.setBlock(world, i, j + 48, k + 112, Blocks.bedrock, 0);
        this.setBlock(world, i, j + 48, k + 113, Dungeons.blockUnbreableStonebrick, 0);
        this.setBlock(world, i, j + 49, k + 95, Dungeons.blockUnbreableStonebrick, 0);
        this.setBlock(world, i, j + 49, k + 96, Blocks.bedrock, 0);
        this.setBlock(world, i, j + 49, k + 112, Blocks.bedrock, 0);
        this.setBlock(world, i, j + 49, k + 113, Dungeons.blockUnbreableStonebrick, 0);
        this.setBlock(world, i, j + 50, k + 83, Blocks.leaves, 1);
        this.setBlock(world, i, j + 50, k + 95, Dungeons.blockUnbreableStonebrick, 0);
        this.setBlock(world, i, j + 50, k + 96, Blocks.bedrock, 0);
        this.setBlock(world, i, j + 50, k + 112, Blocks.bedrock, 0);
        this.setBlock(world, i, j + 50, k + 113, Dungeons.blockUnbreableStonebrick, 0);
        this.setBlock(world, i, j + 51, k + 95, Dungeons.blockUnbreableStonebrick, 0);
        this.setBlock(world, i, j + 51, k + 96, Dungeons.blockUnbreableStonebrick, 0);
        this.setBlock(world, i, j + 51, k + 97, Blocks.obsidian, 0);
        this.setBlock(world, i, j + 51, k + 111, Blocks.obsidian, 0);
        this.setBlock(world, i, j + 51, k + 112, Dungeons.blockUnbreableStonebrick, 0);
        this.setBlock(world, i, j + 51, k + 113, Dungeons.blockUnbreableStonebrick, 0);
        this.setBlock(world, i, j + 52, k + 95, Dungeons.blockUnbreableStonebrick, 0);
        this.setBlock(world, i, j + 52, k + 96, Dungeons.blockUnbreableStonebrick, 0);
        this.setBlock(world, i, j + 52, k + 97, Blocks.obsidian, 0);
        this.setBlock(world, i, j + 52, k + 111, Blocks.obsidian, 0);
        this.setBlock(world, i, j + 52, k + 112, Dungeons.blockUnbreableStonebrick, 0);
        this.setBlock(world, i, j + 52, k + 113, Dungeons.blockUnbreableStonebrick, 0);
        this.setBlock(world, i, j + 53, k + 95, Dungeons.blockUnbreableStonebrick, 0);
        this.setBlock(world, i, j + 53, k + 96, Dungeons.blockUnbreableStonebrick, 0);
        this.setBlock(world, i, j + 53, k + 97, Blocks.obsidian, 0);
        this.setBlock(world, i, j + 53, k + 111, Blocks.obsidian, 0);
        this.setBlock(world, i, j + 53, k + 112, Dungeons.blockUnbreableStonebrick, 0);
        this.setBlock(world, i, j + 53, k + 113, Dungeons.blockUnbreableStonebrick, 0);
        this.setBlock(world, i, j + 54, k + 95, Dungeons.blockUnbreableStonebrick, 0);
        this.setBlock(world, i, j + 54, k + 96, Dungeons.blockUnbreableStonebrick, 0);
        this.setBlock(world, i, j + 54, k + 97, Dungeons.blockUnbreableStonebrick, 0);
        this.setBlock(world, i, j + 54, k + 98, Blocks.bedrock, 0);
        this.setBlock(world, i, j + 54, k + 110, Blocks.bedrock, 0);
        this.setBlock(world, i, j + 54, k + 111, Dungeons.blockUnbreableStonebrick, 0);
        this.setBlock(world, i, j + 54, k + 112, Dungeons.blockUnbreableStonebrick, 0);
        this.setBlock(world, i, j + 54, k + 113, Dungeons.blockUnbreableStonebrick, 0);
        this.setBlock(world, i, j + 55, k + 93, Dungeons.blockUnbreableStonebrick, 0);
        this.setBlock(world, i, j + 55, k + 94, Dungeons.blockUnbreableStonebrick, 0);
        this.setBlock(world, i, j + 55, k + 95, Dungeons.blockUnbreableStonebrick, 0);
        this.setBlock(world, i, j + 55, k + 96, Dungeons.blockUnbreableStonebrick, 0);
        this.setBlock(world, i, j + 55, k + 97, Dungeons.blockUnbreableStonebrick, 0);
        this.setBlock(world, i, j + 55, k + 98, Blocks.bedrock, 0);
        this.setBlock(world, i, j + 55, k + 110, Blocks.bedrock, 0);
        this.setBlock(world, i, j + 55, k + 111, Dungeons.blockUnbreableStonebrick, 0);
        this.setBlock(world, i, j + 55, k + 112, Dungeons.blockUnbreableStonebrick, 0);
        this.setBlock(world, i, j + 55, k + 113, Dungeons.blockUnbreableStonebrick, 0);
        this.setBlock(world, i, j + 56, k + 93, Dungeons.blockUnbreableStonebrick, 0);
        this.setBlock(world, i, j + 56, k + 94, Dungeons.blockUnbreableStonebrick, 0);
        this.setBlock(world, i, j + 56, k + 95, Dungeons.blockUnbreableStonebrick, 0);
        this.setBlock(world, i, j + 56, k + 96, Dungeons.blockUnbreableStonebrick, 0);
        this.setBlock(world, i, j + 56, k + 97, Dungeons.blockUnbreableStonebrick, 0);
        this.setBlock(world, i, j + 56, k + 98, Dungeons.blockUnbreableStonebrick, 0);
        this.setBlock(world, i, j + 56, k + 99, Blocks.obsidian, 0);
        this.setBlock(world, i, j + 56, k + 109, Blocks.obsidian, 0);
        this.setBlock(world, i, j + 56, k + 110, Dungeons.blockUnbreableStonebrick, 0);
        this.setBlock(world, i, j + 56, k + 111, Dungeons.blockUnbreableStonebrick, 0);
        this.setBlock(world, i, j + 56, k + 112, Dungeons.blockUnbreableStonebrick, 0);
        this.setBlock(world, i, j + 56, k + 113, Dungeons.blockUnbreableStonebrick, 0);
        this.setBlock(world, i, j + 56, k + 114, Dungeons.blockUnbreableStonebrick, 0);
        this.setBlock(world, i, j + 56, k + 115, Dungeons.blockUnbreableStonebrick, 0);
        this.setBlock(world, i, j + 57, k + 93, Dungeons.blockUnbreableStonebrick, 0);
        this.setBlock(world, i, j + 57, k + 94, Dungeons.blockUnbreableStonebrick, 0);
        this.setBlock(world, i, j + 57, k + 95, Dungeons.blockUnbreableStonebrick, 0);
        this.setBlock(world, i, j + 57, k + 96, Dungeons.blockUnbreableStonebrick, 0);
        this.setBlock(world, i, j + 57, k + 97, Dungeons.blockUnbreableStonebrick, 0);
        this.setBlock(world, i, j + 57, k + 98, Dungeons.blockUnbreableStonebrick, 0);
        this.setBlock(world, i, j + 57, k + 99, Blocks.obsidian, 0);
        this.setBlock(world, i, j + 57, k + 109, Blocks.obsidian, 0);
        this.setBlock(world, i, j + 57, k + 110, Dungeons.blockUnbreableStonebrick, 0);
        this.setBlock(world, i, j + 57, k + 111, Dungeons.blockUnbreableStonebrick, 0);
        this.setBlock(world, i, j + 57, k + 112, Dungeons.blockUnbreableStonebrick, 0);
        this.setBlock(world, i, j + 57, k + 113, Dungeons.blockUnbreableStonebrick, 0);
        this.setBlock(world, i, j + 57, k + 114, Dungeons.blockUnbreableStonebrick, 0);
        this.setBlock(world, i, j + 57, k + 115, Dungeons.blockUnbreableStonebrick, 0);
        this.setBlock(world, i, j + 58, k + 95, Dungeons.blockUnbreableStonebrick, 0);
        this.setBlock(world, i, j + 58, k + 96, Dungeons.blockUnbreableStonebrick, 0);
        this.setBlock(world, i, j + 58, k + 97, Dungeons.blockUnbreableStonebrick, 0);
        this.setBlock(world, i, j + 58, k + 98, Dungeons.blockUnbreableStonebrick, 0);
        this.setBlock(world, i, j + 58, k + 99, Dungeons.blockUnbreableStonebrick, 0);
        this.setBlock(world, i, j + 58, k + 100, Blocks.bedrock, 0);
        this.setBlock(world, i, j + 58, k + 108, Blocks.bedrock, 0);
        this.setBlock(world, i, j + 58, k + 109, Dungeons.blockUnbreableStonebrick, 0);
        this.setBlock(world, i, j + 58, k + 110, Dungeons.blockUnbreableStonebrick, 0);
        this.setBlock(world, i, j + 58, k + 111, Dungeons.blockUnbreableStonebrick, 0);
        this.setBlock(world, i, j + 58, k + 112, Dungeons.blockUnbreableStonebrick, 0);
        this.setBlock(world, i, j + 58, k + 113, Dungeons.blockUnbreableStonebrick, 0);
        this.setBlock(world, i, j + 59, k + 96, Dungeons.blockUnbreableStonebrick, 0);
        this.setBlock(world, i, j + 59, k + 97, Dungeons.blockUnbreableStonebrick, 0);
        this.setBlock(world, i, j + 59, k + 98, Dungeons.blockUnbreableStonebrick, 0);
        this.setBlock(world, i, j + 59, k + 99, Dungeons.blockUnbreableStonebrick, 0);
        this.setBlock(world, i, j + 59, k + 100, Dungeons.blockUnbreableStonebrick, 0);
        this.setBlock(world, i, j + 59, k + 101, Blocks.obsidian, 0);
        this.setBlock(world, i, j + 59, k + 107, Blocks.obsidian, 0);
        this.setBlock(world, i, j + 59, k + 108, Dungeons.blockUnbreableStonebrick, 0);
        this.setBlock(world, i, j + 59, k + 109, Dungeons.blockUnbreableStonebrick, 0);
        this.setBlock(world, i, j + 59, k + 110, Dungeons.blockUnbreableStonebrick, 0);
        this.setBlock(world, i, j + 59, k + 111, Dungeons.blockUnbreableStonebrick, 0);
        this.setBlock(world, i, j + 60, k + 96, Dungeons.blockUnbreableStonebrick, 0);
        this.setBlock(world, i, j + 60, k + 97, Dungeons.blockUnbreableStonebrick, 0);
        this.setBlock(world, i, j + 60, k + 98, Dungeons.blockUnbreableStonebrick, 0);
        this.setBlock(world, i, j + 60, k + 99, Dungeons.blockUnbreableStonebrick, 0);
        this.setBlock(world, i, j + 60, k + 100, Dungeons.blockUnbreableStonebrick, 0);
        this.setBlock(world, i, j + 60, k + 101, Dungeons.blockUnbreableStonebrick, 0);
        this.setBlock(world, i, j + 60, k + 102, Blocks.bedrock, 0);
        this.setBlock(world, i, j + 60, k + 106, Blocks.bedrock, 0);
        this.setBlock(world, i, j + 60, k + 107, Dungeons.blockUnbreableStonebrick, 0);
        this.setBlock(world, i, j + 60, k + 108, Dungeons.blockUnbreableStonebrick, 0);
        this.setBlock(world, i, j + 60, k + 109, Dungeons.blockUnbreableStonebrick, 0);
        this.setBlock(world, i, j + 60, k + 110, Dungeons.blockUnbreableStonebrick, 0);
        this.setBlock(world, i, j + 60, k + 111, Dungeons.blockUnbreableStonebrick, 0);
        this.setBlock(world, i, j + 60, k + 114, Blocks.bedrock, 0);
        this.setBlock(world, i, j + 61, k + 94, Blocks.bedrock, 0);
        this.setBlock(world, i, j + 61, k + 95, Dungeons.blockUnbreableStonebrick, 0);
        this.setBlock(world, i, j + 61, k + 97, Dungeons.blockUnbreableStonebrick, 0);
        this.setBlock(world, i, j + 61, k + 98, Dungeons.blockUnbreableStonebrick, 0);
        this.setBlock(world, i, j + 61, k + 99, Dungeons.blockUnbreableStonebrick, 0);
        this.setBlock(world, i, j + 61, k + 100, Dungeons.blockUnbreableStonebrick, 0);
        this.setBlock(world, i, j + 61, k + 101, Dungeons.blockUnbreableStonebrick, 0);
        this.setBlock(world, i, j + 61, k + 102, Dungeons.blockUnbreableStonebrick, 0);
        this.setBlock(world, i, j + 61, k + 103, Blocks.obsidian, 0);
        this.setBlock(world, i, j + 61, k + 104, Blocks.obsidian, 0);
        this.setBlock(world, i, j + 61, k + 105, Blocks.obsidian, 0);
        this.setBlock(world, i, j + 61, k + 106, Dungeons.blockUnbreableStonebrick, 0);
        this.setBlock(world, i, j + 61, k + 107, Dungeons.blockUnbreableStonebrick, 0);
        this.setBlock(world, i, j + 61, k + 108, Dungeons.blockUnbreableStonebrick, 0);
        this.setBlock(world, i, j + 61, k + 109, Dungeons.blockUnbreableStonebrick, 0);
        this.setBlock(world, i, j + 61, k + 110, Dungeons.blockUnbreableStonebrick, 0);
        this.setBlock(world, i, j + 61, k + 111, Dungeons.blockUnbreableStonebrick, 0);
        this.setBlock(world, i, j + 61, k + 112, Dungeons.blockUnbreableStonebrick, 0);
        this.setBlock(world, i, j + 61, k + 113, Blocks.bedrock, 0);
        this.setBlock(world, i, j + 61, k + 114, Blocks.obsidian, 0);
        this.setBlock(world, i, j + 62, k + 93, Blocks.obsidian, 0);
        this.setBlock(world, i, j + 62, k + 94, Blocks.bedrock, 0);
        this.setBlock(world, i, j + 62, k + 97, Dungeons.blockUnbreableStonebrick, 0);
        this.setBlock(world, i, j + 62, k + 98, Dungeons.blockUnbreableStonebrick, 0);
        this.setBlock(world, i, j + 62, k + 99, Dungeons.blockUnbreableStonebrick, 0);
        this.setBlock(world, i, j + 62, k + 100, Dungeons.blockUnbreableStonebrick, 0);
        this.setBlock(world, i, j + 62, k + 101, Dungeons.blockUnbreableStonebrick, 0);
        this.setBlock(world, i, j + 62, k + 102, Dungeons.blockUnbreableStonebrick, 0);
        this.setBlock(world, i, j + 62, k + 103, Dungeons.blockUnbreableStonebrick, 0);
        this.setBlock(world, i, j + 62, k + 104, Dungeons.blockUnbreableStonebrick, 0);
        this.setBlock(world, i, j + 62, k + 105, Dungeons.blockUnbreableStonebrick, 0);
        this.setBlock(world, i, j + 62, k + 106, Dungeons.blockUnbreableStonebrick, 0);
        this.setBlock(world, i, j + 62, k + 107, Dungeons.blockUnbreableStonebrick, 0);
        this.setBlock(world, i, j + 62, k + 108, Dungeons.blockUnbreableStonebrick, 0);
        this.setBlock(world, i, j + 62, k + 109, Dungeons.blockUnbreableStonebrick, 0);
        this.setBlock(world, i, j + 62, k + 112, Blocks.bedrock, 0);
        this.setBlock(world, i, j + 62, k + 113, Blocks.bedrock, 0);
        this.setBlock(world, i, j + 62, k + 114, Blocks.bedrock, 0);
        this.setBlock(world, i, j + 62, k + 115, Blocks.bedrock, 0);
        this.setBlock(world, i, j + 63, k + 92, Blocks.bedrock, 0);
        this.setBlock(world, i, j + 63, k + 93, Blocks.bedrock, 0);
        this.setBlock(world, i, j + 63, k + 94, Blocks.bedrock, 0);
        this.setBlock(world, i, j + 63, k + 95, Dungeons.blockUnbreableStonebrick, 0);
        this.setBlock(world, i, j + 63, k + 96, Dungeons.blockUnbreableStonebrick, 0);
        this.setBlock(world, i, j + 63, k + 97, Dungeons.blockUnbreableStonebrick, 0);
        this.setBlock(world, i, j + 63, k + 98, Dungeons.blockUnbreableStonebrick, 0);
        this.setBlock(world, i, j + 63, k + 99, Dungeons.blockUnbreableStonebrick, 0);
        this.setBlock(world, i, j + 63, k + 100, Dungeons.blockUnbreableStonebrick, 0);
        this.setBlock(world, i, j + 63, k + 101, Dungeons.blockUnbreableStonebrick, 0);
        this.setBlock(world, i, j + 63, k + 102, Dungeons.blockUnbreableStonebrick, 0);
        this.setBlock(world, i, j + 63, k + 103, Dungeons.blockUnbreableStonebrick, 0);
        this.setBlock(world, i, j + 63, k + 104, Dungeons.blockUnbreableStonebrick, 0);
        this.setBlock(world, i, j + 63, k + 105, Dungeons.blockUnbreableStonebrick, 0);
        this.setBlock(world, i, j + 63, k + 106, Dungeons.blockUnbreableStonebrick, 0);
        this.setBlock(world, i, j + 63, k + 107, Dungeons.blockUnbreableStonebrick, 0);
        this.setBlock(world, i, j + 63, k + 108, Dungeons.blockUnbreableStonebrick, 0);
        this.setBlock(world, i, j + 63, k + 109, Dungeons.blockUnbreableStonebrick, 0);
        this.setBlock(world, i, j + 63, k + 110, Dungeons.blockUnbreableStonebrick, 0);
        this.setBlock(world, i, j + 63, k + 111, Dungeons.blockUnbreableStonebrick, 0);
        this.setBlock(world, i, j + 63, k + 112, Dungeons.blockUnbreableStonebrick, 0);
        this.setBlock(world, i, j + 63, k + 113, Blocks.bedrock, 0);
        this.setBlock(world, i, j + 63, k + 114, Blocks.bedrock, 0);
        this.setBlock(world, i, j + 63, k + 115, Blocks.bedrock, 0);
        this.setBlock(world, i, j + 63, k + 116, Dungeons.blockUnbreableStonebrick, 0);
        this.setBlock(world, i, j + 64, k + 91, Dungeons.blockUnbreableStonebrick, 0);
        this.setBlock(world, i, j + 64, k + 92, Blocks.bedrock, 0);
        this.setBlock(world, i, j + 64, k + 93, Blocks.bedrock, 0);
        this.setBlock(world, i, j + 64, k + 94, Blocks.bedrock, 0);
        this.setBlock(world, i, j + 64, k + 114, Blocks.bedrock, 0);
        this.setBlock(world, i, j + 64, k + 115, Blocks.bedrock, 0);
        this.setBlock(world, i, j + 64, k + 116, Dungeons.blockUnbreableStonebrick, 0);
        this.setBlock(world, i, j + 65, k + 92, Dungeons.blockUnbreableStonebrick, 0);
        this.setBlock(world, i, j + 65, k + 93, Blocks.bedrock, 0);
        WorldGenWarlordDungeon.chest(world, rand, i, j + 65, k + 114, "MontaneDungeon", 6);
        this.setBlock(world, i, j + 65, k + 115, Blocks.bedrock, 0);
        this.setBlock(world, i, j + 66, k + 92, Dungeons.blockUnbreableStonebrick, 0);
        WorldGenWarlordDungeon.chest(world, rand, i, j + 66, k + 93, "MontaneDungeon", 6);
        this.setBlock(world, i, j + 66, k + 115, Dungeons.blockUnbreableStonebrick, 0);
        this.setBlock(world, i + 1, j + 38, k + 101, Dungeons.blockUnbreableCobbleStone, 0);
        this.setBlock(world, i + 1, j + 38, k + 102, Dungeons.blockUnbreableStone, 0);
        this.setBlock(world, i + 1, j + 38, k + 103, Dungeons.blockUnbreableStone, 0);
        this.setBlock(world, i + 1, j + 38, k + 104, Dungeons.blockUnbreableCobbleStone, 0);
        this.setBlock(world, i + 1, j + 38, k + 105, Dungeons.blockUnbreableStone, 0);
        this.setBlock(world, i + 1, j + 38, k + 106, Dungeons.blockUnbreableStone, 0);
        this.setBlock(world, i + 1, j + 38, k + 107, Dungeons.blockUnbreableStone, 0);
        this.setBlock(world, i + 1, j + 38, k + 108, Dungeons.blockUnbreableStone, 0);
        this.setBlock(world, i + 1, j + 38, k + 109, Dungeons.blockUnbreableStone, 0);
        this.setBlock(world, i + 1, j + 38, k + 110, Dungeons.blockUnbreableStone, 0);
        this.setBlock(world, i + 1, j + 38, k + 111, Blocks.bedrock, 0);
        this.setBlock(world, i + 1, j + 38, k + 116, Dungeons.blockUnbreableCobbleStone, 0);
        this.setBlock(world, i + 1, j + 39, k + 90, Dungeons.blockUnbreableStone, 0);
        this.setBlock(world, i + 1, j + 39, k + 96, Blocks.bedrock, 0);
        this.setBlock(world, i + 1, j + 39, k + 97, Blocks.bedrock, 0);
        this.setBlock(world, i + 1, j + 39, k + 98, Dungeons.blockUnbreableStone, 0);
        this.setBlock(world, i + 1, j + 39, k + 99, Dungeons.blockUnbreableCobbleStone, 0);
        this.setBlock(world, i + 1, j + 39, k + 100, Dungeons.blockUnbreableStone, 0);
        this.setBlock(world, i + 1, j + 39, k + 101, Dungeons.blockUnbreableStone, 0);
        this.setBlock(world, i + 1, j + 39, k + 102, Dungeons.blockUnbreableStone, 0);
        this.setBlock(world, i + 1, j + 39, k + 103, Dungeons.blockUnbreableStone, 0);
        this.setBlock(world, i + 1, j + 39, k + 104, Blocks.bedrock, 0);
        this.setBlock(world, i + 1, j + 39, k + 105, Dungeons.blockUnbreableStone, 0);
        this.setBlock(world, i + 1, j + 39, k + 106, Dungeons.blockUnbreableStone, 0);
        this.setBlock(world, i + 1, j + 39, k + 107, Dungeons.blockUnbreableStone, 0);
        this.setBlock(world, i + 1, j + 39, k + 108, Dungeons.blockUnbreableCobbleStone, 0);
        this.setBlock(world, i + 1, j + 39, k + 109, Dungeons.blockUnbreableCobbleStone, 0);
        this.setBlock(world, i + 1, j + 39, k + 110, Dungeons.blockUnbreableStone, 0);
        this.setBlock(world, i + 1, j + 39, k + 111, Dungeons.blockUnbreableCobbleStone, 0);
        this.setBlock(world, i + 1, j + 39, k + 112, Dungeons.blockUnbreableStone, 0);
        this.setBlock(world, i + 1, j + 39, k + 113, Dungeons.blockUnbreableStone, 0);
        this.setBlock(world, i + 1, j + 39, k + 114, Dungeons.blockUnbreableCobbleStone, 0);
        this.setBlock(world, i + 1, j + 39, k + 115, Dungeons.blockUnbreableStone, 0);
        this.setBlock(world, i + 1, j + 39, k + 116, Dungeons.blockUnbreableStone, 0);
        this.setBlock(world, i + 1, j + 39, k + 117, Blocks.bedrock, 0);
        this.setBlock(world, i + 1, j + 39, k + 118, Blocks.bedrock, 0);
        this.setBlock(world, i + 1, j + 40, k + 83, Dungeons.blockUnbreableStone, 0);
        this.setBlock(world, i + 1, j + 40, k + 84, Dungeons.blockUnbreableStone, 0);
        this.setBlock(world, i + 1, j + 40, k + 85, Dungeons.blockUnbreableStone, 0);
        this.setBlock(world, i + 1, j + 40, k + 86, Dungeons.blockUnbreableStone, 0);
        this.setBlock(world, i + 1, j + 40, k + 87, Dungeons.blockUnbreableCobbleStone, 0);
        this.setBlock(world, i + 1, j + 40, k + 88, Dungeons.blockUnbreableStone, 0);
        this.setBlock(world, i + 1, j + 40, k + 89, Dungeons.blockUnbreableStone, 0);
        this.setBlock(world, i + 1, j + 40, k + 90, Dungeons.blockUnbreableCobbleStone, 0);
        this.setBlock(world, i + 1, j + 40, k + 91, Dungeons.blockUnbreableStone, 0);
        this.setBlock(world, i + 1, j + 40, k + 92, Dungeons.blockUnbreableCobbleStone, 0);
        this.setBlock(world, i + 1, j + 40, k + 93, Dungeons.blockUnbreableStone, 0);
        this.setBlock(world, i + 1, j + 40, k + 94, Dungeons.blockUnbreableStone, 0);
        this.setBlock(world, i + 1, j + 40, k + 95, Dungeons.blockUnbreableStone, 0);
        this.setBlock(world, i + 1, j + 40, k + 96, Dungeons.blockUnbreableStone, 0);
        this.setBlock(world, i + 1, j + 40, k + 97, Dungeons.blockUnbreableCobbleStone, 0);
        this.setBlock(world, i + 1, j + 40, k + 98, Dungeons.blockUnbreableStone, 0);
        this.setBlock(world, i + 1, j + 40, k + 99, Dungeons.blockUnbreableStone, 0);
        this.setBlock(world, i + 1, j + 40, k + 100, Dungeons.blockUnbreableStone, 0);
        this.setBlock(world, i + 1, j + 40, k + 101, Blocks.bedrock, 0);
        this.setBlock(world, i + 1, j + 40, k + 102, Dungeons.blockUnbreableStone, 0);
        this.setBlock(world, i + 1, j + 40, k + 103, Dungeons.blockUnbreableStone, 0);
        this.setBlock(world, i + 1, j + 40, k + 104, Dungeons.blockUnbreableCobbleStone, 0);
        this.setBlock(world, i + 1, j + 40, k + 105, Dungeons.blockUnbreableStone, 0);
        this.setBlock(world, i + 1, j + 40, k + 106, Dungeons.blockUnbreableStone, 0);
        this.setBlock(world, i + 1, j + 40, k + 107, Blocks.bedrock, 0);
        this.setBlock(world, i + 1, j + 40, k + 108, Dungeons.blockUnbreableStone, 0);
        this.setBlock(world, i + 1, j + 40, k + 109, Dungeons.blockUnbreableStone, 0);
        this.setBlock(world, i + 1, j + 40, k + 110, Dungeons.blockUnbreableStone, 0);
        this.setBlock(world, i + 1, j + 40, k + 111, Dungeons.blockUnbreableStone, 0);
        this.setBlock(world, i + 1, j + 40, k + 112, Dungeons.blockUnbreableStone, 0);
        this.setBlock(world, i + 1, j + 40, k + 113, Blocks.bedrock, 0);
        this.setBlock(world, i + 1, j + 40, k + 114, Dungeons.blockUnbreableStone, 0);
        this.setBlock(world, i + 1, j + 40, k + 115, Dungeons.blockUnbreableCobbleStone, 0);
        this.setBlock(world, i + 1, j + 40, k + 116, Dungeons.blockUnbreableStone, 0);
        this.setBlock(world, i + 1, j + 40, k + 117, Dungeons.blockUnbreableStone, 0);
        this.setBlock(world, i + 1, j + 40, k + 118, Dungeons.blockUnbreableCobbleStone, 0);
        this.setBlock(world, i + 1, j + 40, k + 119, Dungeons.blockUnbreableStone, 0);
        this.setBlock(world, i + 1, j + 40, k + 120, Dungeons.blockUnbreableStone, 0);
        this.setBlock(world, i + 1, j + 41, k + 81, Blocks.bedrock, 0);
        this.setBlock(world, i + 1, j + 41, k + 82, Dungeons.blockUnbreableCobbleStone, 0);
        this.setBlock(world, i + 1, j + 41, k + 83, Dungeons.blockUnbreableStone, 0);
        this.setBlock(world, i + 1, j + 41, k + 84, Dungeons.blockUnbreableCobbleStone, 0);
        this.setBlock(world, i + 1, j + 41, k + 85, Dungeons.blockUnbreableStone, 0);
        this.setBlock(world, i + 1, j + 41, k + 86, Dungeons.blockUnbreableStone, 0);
        this.setBlock(world, i + 1, j + 41, k + 87, Dungeons.blockUnbreableCobbleStone, 0);
        this.setBlock(world, i + 1, j + 41, k + 88, Dungeons.blockUnbreableStone, 0);
        this.setBlock(world, i + 1, j + 41, k + 89, Blocks.bedrock, 0);
        this.setBlock(world, i + 1, j + 41, k + 90, Dungeons.blockUnbreableCobbleStone, 0);
        this.setBlock(world, i + 1, j + 41, k + 91, Dungeons.blockUnbreableStone, 0);
        this.setBlock(world, i + 1, j + 41, k + 92, Dungeons.blockUnbreableStone, 0);
        this.setBlock(world, i + 1, j + 41, k + 93, Dungeons.blockUnbreableCobbleStone, 0);
        this.setBlock(world, i + 1, j + 41, k + 94, Dungeons.blockUnbreableStone, 0);
        this.setBlock(world, i + 1, j + 41, k + 95, Blocks.bedrock, 0);
        this.setBlock(world, i + 1, j + 41, k + 96, Dungeons.blockUnbreableStone, 0);
        this.setBlock(world, i + 1, j + 41, k + 97, Dungeons.blockUnbreableStone, 0);
        this.setBlock(world, i + 1, j + 41, k + 98, Dungeons.blockUnbreableStone, 0);
        this.setBlock(world, i + 1, j + 41, k + 99, Dungeons.blockUnbreableStone, 0);
        this.setBlock(world, i + 1, j + 41, k + 100, Dungeons.blockUnbreableStone, 0);
        this.setBlock(world, i + 1, j + 41, k + 101, Dungeons.blockUnbreableStone, 0);
        this.setBlock(world, i + 1, j + 41, k + 102, Dungeons.blockUnbreableStone, 0);
        this.setBlock(world, i + 1, j + 41, k + 103, Dungeons.blockUnbreableStone, 0);
        this.setBlock(world, i + 1, j + 41, k + 104, Dungeons.blockUnbreableStone, 0);
        this.setBlock(world, i + 1, j + 41, k + 105, Dungeons.blockUnbreableStone, 0);
        this.setBlock(world, i + 1, j + 41, k + 106, Dungeons.blockUnbreableStone, 0);
        this.setBlock(world, i + 1, j + 41, k + 107, Dungeons.blockUnbreableStone, 0);
        this.setBlock(world, i + 1, j + 41, k + 108, Dungeons.blockUnbreableStone, 0);
        this.setBlock(world, i + 1, j + 41, k + 109, Dungeons.blockUnbreableStone, 0);
        this.setBlock(world, i + 1, j + 41, k + 110, Dungeons.blockUnbreableStone, 0);
        this.setBlock(world, i + 1, j + 41, k + 111, Dungeons.blockUnbreableStone, 0);
        this.setBlock(world, i + 1, j + 41, k + 112, Blocks.bedrock, 0);
        this.setBlock(world, i + 1, j + 41, k + 113, Dungeons.blockUnbreableStone, 0);
        this.setBlock(world, i + 1, j + 41, k + 114, Dungeons.blockUnbreableStone, 0);
        this.setBlock(world, i + 1, j + 41, k + 115, Dungeons.blockUnbreableStone, 0);
        this.setBlock(world, i + 1, j + 41, k + 116, Dungeons.blockUnbreableStone, 0);
        this.setBlock(world, i + 1, j + 41, k + 117, Dungeons.blockUnbreableStone, 0);
        this.setBlock(world, i + 1, j + 41, k + 118, Dungeons.blockUnbreableCobbleStone, 0);
        this.setBlock(world, i + 1, j + 41, k + 119, Dungeons.blockUnbreableStone, 0);
        this.setBlock(world, i + 1, j + 41, k + 120, Dungeons.blockUnbreableStone, 0);
        this.setBlock(world, i + 1, j + 41, k + 121, Dungeons.blockUnbreableStone, 0);
        this.setBlock(world, i + 1, j + 41, k + 122, Dungeons.blockUnbreableStone, 0);
        this.setBlock(world, i + 1, j + 42, k + 78, Dungeons.blockUnbreableStone, 0);
        this.setBlock(world, i + 1, j + 42, k + 79, Dungeons.blockUnbreableStone, 0);
        this.setBlock(world, i + 1, j + 42, k + 80, Dungeons.blockUnbreableStone, 0);
        this.setBlock(world, i + 1, j + 42, k + 81, Dungeons.blockUnbreableStone, 0);
        this.setBlock(world, i + 1, j + 42, k + 82, Blocks.bedrock, 0);
        this.setBlock(world, i + 1, j + 42, k + 83, Blocks.dirt, 0);
        this.setBlock(world, i + 1, j + 42, k + 84, Dungeons.blockUnbreableStone, 0);
        this.setBlock(world, i + 1, j + 42, k + 85, Dungeons.blockUnbreableStone, 0);
        this.setBlock(world, i + 1, j + 42, k + 86, Dungeons.blockUnbreableStone, 0);
        this.setBlock(world, i + 1, j + 42, k + 87, Dungeons.blockUnbreableStone, 0);
        this.setBlock(world, i + 1, j + 42, k + 88, Dungeons.blockUnbreableStone, 0);
        this.setBlock(world, i + 1, j + 42, k + 89, Dungeons.blockUnbreableStone, 0);
        this.setBlock(world, i + 1, j + 42, k + 90, Dungeons.blockUnbreableStone, 0);
        this.setBlock(world, i + 1, j + 42, k + 91, Dungeons.blockUnbreableCobbleStone, 0);
        this.setBlock(world, i + 1, j + 42, k + 92, Dungeons.blockUnbreableStone, 0);
        this.setBlock(world, i + 1, j + 42, k + 93, Dungeons.blockUnbreableStone, 0);
        this.setBlock(world, i + 1, j + 42, k + 94, Dungeons.blockUnbreableStone, 0);
        this.setBlock(world, i + 1, j + 42, k + 95, Dungeons.blockUnbreableStone, 0);
        this.setBlock(world, i + 1, j + 42, k + 96, Dungeons.blockUnbreableStone, 0);
        this.setBlock(world, i + 1, j + 42, k + 97, Blocks.bedrock, 0);
        this.setBlock(world, i + 1, j + 42, k + 98, Dungeons.blockUnbreableCobbleStone, 0);
        this.setBlock(world, i + 1, j + 42, k + 99, Dungeons.blockUnbreableStone, 0);
        this.setBlock(world, i + 1, j + 42, k + 100, Dungeons.blockUnbreableStone, 0);
        this.setBlock(world, i + 1, j + 42, k + 101, Dungeons.blockUnbreableStone, 0);
        this.setBlock(world, i + 1, j + 42, k + 102, Dungeons.blockUnbreableStone, 0);
        this.setBlock(world, i + 1, j + 42, k + 103, Dungeons.blockUnbreableStone, 0);
        this.setBlock(world, i + 1, j + 42, k + 104, Dungeons.blockUnbreableStone, 0);
        this.setBlock(world, i + 1, j + 42, k + 105, Dungeons.blockUnbreableStone, 0);
        this.setBlock(world, i + 1, j + 42, k + 106, Dungeons.blockUnbreableStone, 0);
        this.setBlock(world, i + 1, j + 42, k + 107, Dungeons.blockUnbreableStone, 0);
        this.setBlock(world, i + 1, j + 42, k + 108, Dungeons.blockUnbreableStone, 0);
        this.setBlock(world, i + 1, j + 42, k + 109, Dungeons.blockUnbreableStone, 0);
        this.setBlock(world, i + 1, j + 42, k + 110, Dungeons.blockUnbreableStone, 0);
        this.setBlock(world, i + 1, j + 42, k + 111, Dungeons.blockUnbreableStone, 0);
        this.setBlock(world, i + 1, j + 42, k + 112, Dungeons.blockUnbreableStone, 0);
        this.setBlock(world, i + 1, j + 42, k + 113, Dungeons.blockUnbreableStone, 0);
        this.setBlock(world, i + 1, j + 42, k + 114, Blocks.bedrock, 0);
        this.setBlock(world, i + 1, j + 42, k + 115, Dungeons.blockUnbreableStone, 0);
        this.setBlock(world, i + 1, j + 42, k + 116, Dungeons.blockUnbreableStone, 0);
        this.setBlock(world, i + 1, j + 42, k + 117, Dungeons.blockUnbreableStone, 0);
        this.setBlock(world, i + 1, j + 42, k + 118, Dungeons.blockUnbreableStone, 0);
        this.setBlock(world, i + 1, j + 42, k + 119, Dungeons.blockUnbreableStone, 0);
        this.setBlock(world, i + 1, j + 42, k + 120, Dungeons.blockUnbreableStone, 0);
        this.setBlock(world, i + 1, j + 42, k + 121, Dungeons.blockUnbreableStone, 0);
        this.setBlock(world, i + 1, j + 42, k + 122, Dungeons.blockUnbreableStone, 0);
        this.setBlock(world, i + 1, j + 42, k + 123, Dungeons.blockUnbreableStone, 0);
        this.setBlock(world, i + 1, j + 42, k + 124, Dungeons.blockUnbreableStone, 0);
        this.setBlock(world, i + 1, j + 42, k + 125, Dungeons.blockUnbreableCobbleStone, 0);
        this.setBlock(world, i + 1, j + 43, k + 83, Blocks.log, 1);
        this.setBlock(world, i + 1, j + 43, k + 89, Dungeons.blockUnbreableStone, 0);
        this.setBlock(world, i + 1, j + 43, k + 90, Dungeons.blockUnbreableStone, 0);
        this.setBlock(world, i + 1, j + 43, k + 91, Dungeons.blockUnbreableStone, 0);
        this.setBlock(world, i + 1, j + 43, k + 92, Dungeons.blockUnbreableStone, 0);
        this.setBlock(world, i + 1, j + 43, k + 93, Dungeons.blockUnbreableCobbleStone, 0);
        this.setBlock(world, i + 1, j + 43, k + 94, Dungeons.blockUnbreableStone, 0);
        this.setBlock(world, i + 1, j + 43, k + 95, Dungeons.blockUnbreableStone, 0);
        this.setBlock(world, i + 1, j + 43, k + 96, Dungeons.blockUnbreableStone, 0);
        this.setBlock(world, i + 1, j + 43, k + 97, Dungeons.blockUnbreableStone, 0);
        this.setBlock(world, i + 1, j + 43, k + 98, Dungeons.blockUnbreableStone, 0);
        this.setBlock(world, i + 1, j + 43, k + 99, Dungeons.blockUnbreableStone, 0);
        this.setBlock(world, i + 1, j + 43, k + 100, Dungeons.blockUnbreableStone, 0);
        this.setBlock(world, i + 1, j + 43, k + 101, Blocks.bedrock, 0);
        this.setBlock(world, i + 1, j + 43, k + 102, Dungeons.blockUnbreableStone, 0);
        this.setBlock(world, i + 1, j + 43, k + 103, Dungeons.blockUnbreableStone, 0);
        this.setBlock(world, i + 1, j + 43, k + 104, Dungeons.blockUnbreableStone, 0);
        this.setBlock(world, i + 1, j + 43, k + 105, Dungeons.blockUnbreableStone, 0);
        this.setBlock(world, i + 1, j + 43, k + 106, Dungeons.blockUnbreableStone, 0);
        this.setBlock(world, i + 1, j + 43, k + 107, Dungeons.blockUnbreableStone, 0);
        this.setBlock(world, i + 1, j + 43, k + 108, Dungeons.blockUnbreableStone, 0);
        this.setBlock(world, i + 1, j + 43, k + 109, Dungeons.blockUnbreableStone, 0);
        this.setBlock(world, i + 1, j + 43, k + 110, Dungeons.blockUnbreableStone, 0);
        this.setBlock(world, i + 1, j + 43, k + 111, Dungeons.blockUnbreableCobbleStone, 0);
        this.setBlock(world, i + 1, j + 43, k + 112, Dungeons.blockUnbreableStone, 0);
        this.setBlock(world, i + 1, j + 43, k + 113, Dungeons.blockUnbreableStone, 0);
        this.setBlock(world, i + 1, j + 43, k + 114, Blocks.bedrock, 0);
        this.setBlock(world, i + 1, j + 43, k + 115, Dungeons.blockUnbreableStone, 0);
        this.setBlock(world, i + 1, j + 43, k + 116, Dungeons.blockUnbreableStone, 0);
        this.setBlock(world, i + 1, j + 43, k + 117, Blocks.bedrock, 0);
        this.setBlock(world, i + 1, j + 43, k + 118, Dungeons.blockUnbreableStone, 0);
        this.setBlock(world, i + 1, j + 44, k + 82, Blocks.leaves, 1);
        this.setBlock(world, i + 1, j + 44, k + 83, Blocks.log, 1);
        this.setBlock(world, i + 1, j + 44, k + 84, Blocks.leaves, 1);
        this.setBlock(world, i + 1, j + 44, k + 92, Blocks.cobblestone_wall, 0);
        this.setBlock(world, i + 1, j + 44, k + 93, Dungeons.blockUnbreableStonebrick, 0);
        this.setBlock(world, i + 1, j + 44, k + 95, Dungeons.blockUnbreableStonebrick, 0);
        this.setBlock(world, i + 1, j + 44, k + 99, Dungeons.blockUnbreableCobbleStone, 0);
        this.setBlock(world, i + 1, j + 44, k + 100, Blocks.bedrock, 0);
        this.setBlock(world, i + 1, j + 44, k + 101, Dungeons.blockUnbreableCobbleStone, 0);
        this.setBlock(world, i + 1, j + 44, k + 102, Dungeons.blockUnbreableCobbleStone, 0);
        this.setBlock(world, i + 1, j + 44, k + 103, Dungeons.blockUnbreableStone, 0);
        this.setBlock(world, i + 1, j + 44, k + 104, Dungeons.blockUnbreableStone, 0);
        this.setBlock(world, i + 1, j + 44, k + 105, Dungeons.blockUnbreableStone, 0);
        this.setBlock(world, i + 1, j + 44, k + 106, Blocks.bedrock, 0);
        this.setBlock(world, i + 1, j + 44, k + 107, Dungeons.blockUnbreableStone, 0);
        this.setBlock(world, i + 1, j + 44, k + 108, Dungeons.blockUnbreableStone, 0);
        this.setBlock(world, i + 1, j + 44, k + 109, Dungeons.blockUnbreableCobbleStone, 0);
        this.setBlock(world, i + 1, j + 44, k + 110, Dungeons.blockUnbreableStone, 0);
        this.setBlock(world, i + 1, j + 44, k + 111, Dungeons.blockUnbreableStone, 0);
        this.setBlock(world, i + 1, j + 44, k + 112, Blocks.bedrock, 0);
        this.setBlock(world, i + 1, j + 44, k + 113, Dungeons.blockUnbreableStone, 0);
        this.setBlock(world, i + 1, j + 44, k + 114, Dungeons.blockUnbreableCobbleStone, 0);
        this.setBlock(world, i + 1, j + 44, k + 115, Dungeons.blockUnbreableStone, 0);
        this.setBlock(world, i + 1, j + 44, k + 116, Dungeons.blockUnbreableStone, 0);
        this.setBlock(world, i + 1, j + 44, k + 117, Dungeons.blockUnbreableStone, 0);
        this.setBlock(world, i + 1, j + 44, k + 118, Dungeons.blockUnbreableCobbleStone, 0);
        this.setBlock(world, i + 1, j + 45, k + 81, Blocks.leaves, 1);
        this.setBlock(world, i + 1, j + 45, k + 82, Blocks.leaves, 1);
        this.setBlock(world, i + 1, j + 45, k + 83, Blocks.log, 1);
        this.setBlock(world, i + 1, j + 45, k + 84, Blocks.leaves, 1);
        this.setBlock(world, i + 1, j + 45, k + 85, Blocks.leaves, 1);
        this.setBlock(world, i + 1, j + 45, k + 92, Blocks.cobblestone_wall, 0);
        this.setBlock(world, i + 1, j + 45, k + 93, Dungeons.blockUnbreableStonebrick, 0);
        this.setBlock(world, i + 1, j + 45, k + 95, Dungeons.blockUnbreableStonebrick, 0);
        this.setBlock(world, i + 1, j + 45, k + 102, Dungeons.blockUnbreableStone, 0);
        this.setBlock(world, i + 1, j + 45, k + 103, Dungeons.blockUnbreableStone, 0);
        this.setBlock(world, i + 1, j + 45, k + 104, Dungeons.blockUnbreableStone, 0);
        this.setBlock(world, i + 1, j + 45, k + 105, Dungeons.blockUnbreableStone, 0);
        this.setBlock(world, i + 1, j + 45, k + 106, Dungeons.blockUnbreableStone, 0);
        this.setBlock(world, i + 1, j + 45, k + 110, Dungeons.blockUnbreableCobbleStone, 0);
        this.setBlock(world, i + 1, j + 45, k + 111, Dungeons.blockUnbreableStone, 0);
        this.setBlock(world, i + 1, j + 45, k + 112, Dungeons.blockUnbreableStone, 0);
        this.setBlock(world, i + 1, j + 45, k + 113, Dungeons.blockUnbreableStone, 0);
        this.setBlock(world, i + 1, j + 45, k + 114, Dungeons.blockUnbreableStone, 0);
        this.setBlock(world, i + 1, j + 45, k + 115, Dungeons.blockUnbreableStone, 0);
        this.setBlock(world, i + 1, j + 45, k + 116, Dungeons.blockUnbreableStone, 0);
        this.setBlock(world, i + 1, j + 45, k + 117, Dungeons.blockUnbreableStone, 0);
        this.setBlock(world, i + 1, j + 45, k + 128, Blocks.leaves, 1);
        this.setBlock(world, i + 1, j + 45, k + 129, Blocks.leaves, 1);
        this.setBlock(world, i + 1, j + 45, k + 130, Blocks.leaves, 1);
        this.setBlock(world, i + 1, j + 46, k + 82, Blocks.leaves, 1);
        this.setBlock(world, i + 1, j + 46, k + 83, Blocks.log, 1);
        this.setBlock(world, i + 1, j + 46, k + 84, Blocks.leaves, 1);
        this.setBlock(world, i + 1, j + 46, k + 92, Blocks.cobblestone_wall, 0);
        this.setBlock(world, i + 1, j + 46, k + 93, Dungeons.blockUnbreableStonebrick, 0);
        this.setBlock(world, i + 1, j + 46, k + 95, Dungeons.blockUnbreableStonebrick, 0);
        this.setBlock(world, i + 1, j + 46, k + 102, Dungeons.blockUnbreableStonebrick, 0);
        this.setBlock(world, i + 1, j + 46, k + 103, Dungeons.blockUnbreableStonebrick, 0);
        this.setBlock(world, i + 1, j + 46, k + 104, Dungeons.blockUnbreableStonebrick, 0);
        this.setBlock(world, i + 1, j + 46, k + 105, Dungeons.blockUnbreableStonebrick, 0);
        this.setBlock(world, i + 1, j + 46, k + 106, Dungeons.blockUnbreableStonebrick, 0);
        this.setBlock(world, i + 1, j + 46, k + 114, Dungeons.blockUnbreableStone, 0);
        this.setBlock(world, i + 1, j + 46, k + 115, Dungeons.blockUnbreableStone, 0);
        this.setBlock(world, i + 1, j + 47, k + 81, Blocks.leaves, 1);
        this.setBlock(world, i + 1, j + 47, k + 82, Blocks.leaves, 1);
        this.setBlock(world, i + 1, j + 47, k + 83, Blocks.log, 1);
        this.setBlock(world, i + 1, j + 47, k + 84, Blocks.leaves, 1);
        this.setBlock(world, i + 1, j + 47, k + 85, Blocks.leaves, 1);
        this.setBlock(world, i + 1, j + 47, k + 92, Blocks.cobblestone_wall, 0);
        this.setBlock(world, i + 1, j + 47, k + 93, Dungeons.blockUnbreableStonebrick, 0);
        this.setBlock(world, i + 1, j + 47, k + 95, Dungeons.blockUnbreableStonebrick, 0);
        this.setBlock(world, i + 1, j + 47, k + 102, Dungeons.blockUnbreableStonebrick, 0);
        this.setBlock(world, i + 1, j + 47, k + 103, Dungeons.blockUnbreableStonebrick, 0);
        this.setBlock(world, i + 1, j + 47, k + 104, Dungeons.blockUnbreableStonebrick, 0);
        this.setBlock(world, i + 1, j + 47, k + 105, Dungeons.blockUnbreableStonebrick, 0);
        this.setBlock(world, i + 1, j + 47, k + 106, Dungeons.blockUnbreableStonebrick, 0);
        this.setBlock(world, i + 1, j + 47, k + 113, Dungeons.blockUnbreableStonebrick, 0);
        this.setBlock(world, i + 1, j + 47, k + 114, Blocks.bedrock, 0);
        this.setBlock(world, i + 1, j + 47, k + 115, Dungeons.blockUnbreableStonebrick, 0);
        this.setBlock(world, i + 1, j + 47, k + 128, Blocks.leaves, 1);
        this.setBlock(world, i + 1, j + 47, k + 129, Blocks.leaves, 1);
        this.setBlock(world, i + 1, j + 47, k + 130, Blocks.leaves, 1);
        this.setBlock(world, i + 1, j + 48, k + 82, Blocks.leaves, 1);
        this.setBlock(world, i + 1, j + 48, k + 83, Blocks.log, 1);
        this.setBlock(world, i + 1, j + 48, k + 84, Blocks.leaves, 1);
        this.setBlock(world, i + 1, j + 48, k + 92, Blocks.cobblestone_wall, 0);
        this.setBlock(world, i + 1, j + 48, k + 94, Blocks.bedrock, 0);
        this.setBlock(world, i + 1, j + 48, k + 95, Dungeons.blockUnbreableStonebrick, 0);
        this.setBlock(world, i + 1, j + 48, k + 102, Dungeons.blockUnbreableStone_slab, 5);
        this.setBlock(world, i + 1, j + 48, k + 103, Dungeons.blockUnbreableStone_slab, 5);
        this.setBlock(world, i + 1, j + 48, k + 104, Dungeons.blockUnbreableStone_slab, 5);
        this.setBlock(world, i + 1, j + 48, k + 105, Dungeons.blockUnbreableStone_slab, 5);
        this.setBlock(world, i + 1, j + 48, k + 106, Dungeons.blockUnbreableStone_slab, 5);
        this.setBlock(world, i + 1, j + 48, k + 113, Dungeons.blockUnbreableStonebrick, 0);
        this.setBlock(world, i + 1, j + 48, k + 114, Blocks.bedrock, 0);
        this.setBlock(world, i + 1, j + 49, k + 83, Blocks.log, 1);
        this.setBlock(world, i + 1, j + 49, k + 92, Blocks.cobblestone_wall, 0);
        this.setBlock(world, i + 1, j + 49, k + 94, Blocks.bedrock, 0);
        this.setBlock(world, i + 1, j + 49, k + 95, Dungeons.blockUnbreableStonebrick, 0);
        this.setBlock(world, i + 1, j + 49, k + 113, Dungeons.blockUnbreableStonebrick, 0);
        this.setBlock(world, i + 1, j + 49, k + 114, Blocks.bedrock, 0);
        this.setBlock(world, i + 1, j + 50, k + 82, Blocks.leaves, 1);
        this.setBlock(world, i + 1, j + 50, k + 83, Blocks.leaves, 1);
        this.setBlock(world, i + 1, j + 50, k + 84, Blocks.leaves, 1);
        this.setBlock(world, i + 1, j + 50, k + 92, Blocks.cobblestone_wall, 0);
        this.setBlock(world, i + 1, j + 50, k + 94, Blocks.bedrock, 0);
        this.setBlock(world, i + 1, j + 50, k + 95, Dungeons.blockUnbreableStonebrick, 0);
        this.setBlock(world, i + 1, j + 50, k + 113, Dungeons.blockUnbreableStonebrick, 0);
        this.setBlock(world, i + 1, j + 50, k + 114, Blocks.bedrock, 0);
        this.setBlock(world, i + 1, j + 51, k + 92, Blocks.cobblestone_wall, 0);
        this.setBlock(world, i + 1, j + 51, k + 94, Blocks.bedrock, 0);
        this.setBlock(world, i + 1, j + 51, k + 95, Dungeons.blockUnbreableStonebrick, 0);
        this.setBlock(world, i + 1, j + 51, k + 113, Dungeons.blockUnbreableStonebrick, 0);
        this.setBlock(world, i + 1, j + 51, k + 114, Blocks.bedrock, 0);
        this.setBlock(world, i + 1, j + 52, k + 92, Blocks.cobblestone_wall, 0);
        this.setBlock(world, i + 1, j + 52, k + 94, Blocks.bedrock, 0);
        this.setBlock(world, i + 1, j + 52, k + 95, Dungeons.blockUnbreableStonebrick, 0);
        this.setBlock(world, i + 1, j + 52, k + 113, Dungeons.blockUnbreableStonebrick, 0);
        this.setBlock(world, i + 1, j + 52, k + 114, Blocks.bedrock, 0);
        this.setBlock(world, i + 1, j + 53, k + 92, Blocks.cobblestone_wall, 0);
        this.setBlock(world, i + 1, j + 53, k + 94, Blocks.bedrock, 0);
        this.setBlock(world, i + 1, j + 53, k + 95, Dungeons.blockUnbreableStonebrick, 0);
        this.setBlock(world, i + 1, j + 53, k + 113, Dungeons.blockUnbreableStonebrick, 0);
        this.setBlock(world, i + 1, j + 53, k + 114, Blocks.bedrock, 0);
        this.setBlock(world, i + 1, j + 54, k + 92, Blocks.cobblestone_wall, 0);
        this.setBlock(world, i + 1, j + 54, k + 94, Blocks.bedrock, 0);
        this.setBlock(world, i + 1, j + 54, k + 95, Dungeons.blockUnbreableStonebrick, 0);
        this.setBlock(world, i + 1, j + 54, k + 113, Dungeons.blockUnbreableStonebrick, 0);
        this.setBlock(world, i + 1, j + 54, k + 114, Blocks.bedrock, 0);
        this.setBlock(world, i + 1, j + 55, k + 92, Blocks.cobblestone_wall, 0);
        this.setBlock(world, i + 1, j + 55, k + 93, Dungeons.blockUnbreableStonebrick, 0);
        this.setBlock(world, i + 1, j + 55, k + 94, Blocks.bedrock, 0);
        this.setBlock(world, i + 1, j + 55, k + 95, Dungeons.blockUnbreableStonebrick, 0);
        this.setBlock(world, i + 1, j + 55, k + 113, Dungeons.blockUnbreableStonebrick, 0);
        this.setBlock(world, i + 1, j + 55, k + 114, Blocks.bedrock, 0);
        this.setBlock(world, i + 1, j + 56, k + 92, Blocks.cobblestone_wall, 0);
        this.setBlock(world, i + 1, j + 56, k + 93, Dungeons.blockUnbreableStonebrick, 0);
        this.setBlock(world, i + 1, j + 56, k + 95, Dungeons.blockUnbreableStonebrick, 0);
        this.setBlock(world, i + 1, j + 56, k + 113, Dungeons.blockUnbreableStonebrick, 0);
        this.setBlock(world, i + 1, j + 56, k + 115, Dungeons.blockUnbreableStonebrick, 0);
        this.setBlock(world, i + 1, j + 57, k + 92, Blocks.cobblestone_wall, 0);
        this.setBlock(world, i + 1, j + 57, k + 93, Dungeons.blockUnbreableStonebrick, 0);
        this.setBlock(world, i + 1, j + 57, k + 95, Dungeons.blockUnbreableStonebrick, 0);
        this.setBlock(world, i + 1, j + 57, k + 113, Dungeons.blockUnbreableStonebrick, 0);
        this.setBlock(world, i + 1, j + 57, k + 114, Blocks.bedrock, 0);
        this.setBlock(world, i + 1, j + 57, k + 115, Dungeons.blockUnbreableStonebrick, 0);
        this.setBlock(world, i + 1, j + 58, k + 92, Blocks.cobblestone_wall, 0);
        this.setBlock(world, i + 1, j + 58, k + 94, Blocks.bedrock, 0);
        this.setBlock(world, i + 1, j + 58, k + 95, Blocks.bedrock, 0);
        this.setBlock(world, i + 1, j + 58, k + 112, Blocks.bedrock, 0);
        this.setBlock(world, i + 1, j + 58, k + 113, Blocks.bedrock, 0);
        this.setBlock(world, i + 1, j + 58, k + 114, Blocks.obsidian, 0);
        this.setBlock(world, i + 1, j + 59, k + 92, Blocks.cobblestone_wall, 0);
        this.setBlock(world, i + 1, j + 59, k + 94, Blocks.bedrock, 0);
        this.setBlock(world, i + 1, j + 59, k + 95, Blocks.bedrock, 0);
        this.setBlock(world, i + 1, j + 59, k + 96, Blocks.bedrock, 0);
        this.setBlock(world, i + 1, j + 59, k + 111, Blocks.bedrock, 0);
        this.setBlock(world, i + 1, j + 59, k + 112, Blocks.bedrock, 0);
        this.setBlock(world, i + 1, j + 59, k + 113, Blocks.bedrock, 0);
        this.setBlock(world, i + 1, j + 59, k + 114, Blocks.bedrock, 0);
        this.setBlock(world, i + 1, j + 60, k + 92, Blocks.cobblestone_wall, 0);
        this.setBlock(world, i + 1, j + 60, k + 94, Blocks.bedrock, 0);
        this.setBlock(world, i + 1, j + 60, k + 95, Blocks.bedrock, 0);
        this.setBlock(world, i + 1, j + 60, k + 96, Blocks.bedrock, 0);
        this.setBlock(world, i + 1, j + 60, k + 97, Blocks.bedrock, 0);
        this.setBlock(world, i + 1, j + 60, k + 111, Blocks.bedrock, 0);
        this.setBlock(world, i + 1, j + 60, k + 112, Blocks.bedrock, 0);
        this.setBlock(world, i + 1, j + 60, k + 113, Blocks.bedrock, 0);
        this.setBlock(world, i + 1, j + 60, k + 114, Blocks.bedrock, 0);
        this.setBlock(world, i + 1, j + 61, k + 92, Blocks.cobblestone_wall, 0);
        this.setBlock(world, i + 1, j + 61, k + 93, Blocks.bedrock, 0);
        this.setBlock(world, i + 1, j + 61, k + 94, Blocks.bedrock, 0);
        this.setBlock(world, i + 1, j + 61, k + 95, Blocks.bedrock, 0);
        this.setBlock(world, i + 1, j + 61, k + 96, Blocks.bedrock, 0);
        this.setBlock(world, i + 1, j + 61, k + 97, Blocks.bedrock, 0);
        this.setBlock(world, i + 1, j + 61, k + 110, Blocks.bedrock, 0);
        this.setBlock(world, i + 1, j + 61, k + 111, Blocks.bedrock, 0);
        this.setBlock(world, i + 1, j + 61, k + 112, Blocks.bedrock, 0);
        this.setBlock(world, i + 1, j + 61, k + 113, Blocks.bedrock, 0);
        this.setBlock(world, i + 1, j + 61, k + 114, Blocks.bedrock, 0);
        this.setBlock(world, i + 1, j + 61, k + 115, Blocks.bedrock, 0);
        this.setBlock(world, i + 1, j + 62, k + 92, Blocks.cobblestone_wall, 0);
        this.setBlock(world, i + 1, j + 62, k + 93, Blocks.bedrock, 0);
        this.setBlock(world, i + 1, j + 62, k + 94, Blocks.bedrock, 0);
        this.setBlock(world, i + 1, j + 62, k + 95, Blocks.bedrock, 0);
        this.setBlock(world, i + 1, j + 62, k + 96, Blocks.bedrock, 0);
        this.setBlock(world, i + 1, j + 62, k + 97, Blocks.bedrock, 0);
        this.setBlock(world, i + 1, j + 62, k + 98, Dungeons.blockUnbreableStonebrick, 0);
        this.setBlock(world, i + 1, j + 62, k + 99, Dungeons.blockUnbreableStonebrick, 0);
        this.setBlock(world, i + 1, j + 62, k + 100, Dungeons.blockUnbreableStonebrick, 0);
        this.setBlock(world, i + 1, j + 62, k + 101, Dungeons.blockUnbreableStonebrick, 0);
        this.setBlock(world, i + 1, j + 62, k + 102, Dungeons.blockUnbreableStonebrick, 0);
        this.setBlock(world, i + 1, j + 62, k + 103, Dungeons.blockUnbreableStonebrick, 0);
        this.setBlock(world, i + 1, j + 62, k + 104, Dungeons.blockUnbreableStonebrick, 0);
        this.setBlock(world, i + 1, j + 62, k + 105, Dungeons.blockUnbreableStonebrick, 0);
        this.setBlock(world, i + 1, j + 62, k + 106, Dungeons.blockUnbreableStonebrick, 0);
        this.setBlock(world, i + 1, j + 62, k + 107, Dungeons.blockUnbreableStonebrick, 0);
        this.setBlock(world, i + 1, j + 62, k + 108, Dungeons.blockUnbreableStonebrick, 0);
        this.setBlock(world, i + 1, j + 62, k + 109, Blocks.bedrock, 0);
        this.setBlock(world, i + 1, j + 62, k + 110, Blocks.bedrock, 0);
        this.setBlock(world, i + 1, j + 62, k + 111, Blocks.bedrock, 0);
        this.setBlock(world, i + 1, j + 62, k + 112, Blocks.bedrock, 0);
        this.setBlock(world, i + 1, j + 62, k + 113, Blocks.bedrock, 0);
        this.setBlock(world, i + 1, j + 62, k + 114, Blocks.bedrock, 0);
        this.setBlock(world, i + 1, j + 62, k + 115, Blocks.bedrock, 0);
        this.setBlock(world, i + 1, j + 62, k + 116, Dungeons.blockUnbreableStonebrick, 0);
        this.setBlock(world, i + 1, j + 63, k + 92, Dungeons.blockUnbreableStonebrick, 0);
        this.setBlock(world, i + 1, j + 63, k + 93, Blocks.bedrock, 0);
        this.setBlock(world, i + 1, j + 63, k + 94, Blocks.bedrock, 0);
        this.setBlock(world, i + 1, j + 63, k + 95, Blocks.bedrock, 0);
        this.setBlock(world, i + 1, j + 63, k + 96, Dungeons.blockUnbreableStonebrick, 0);
        this.setBlock(world, i + 1, j + 63, k + 97, Dungeons.blockUnbreableStonebrick, 0);
        this.setBlock(world, i + 1, j + 63, k + 98, Blocks.bedrock, 0);
        this.setBlock(world, i + 1, j + 63, k + 99, Dungeons.blockUnbreableStonebrick, 0);
        this.setBlock(world, i + 1, j + 63, k + 100, Dungeons.blockUnbreableStonebrick, 0);
        this.setBlock(world, i + 1, j + 63, k + 101, Dungeons.blockUnbreableStonebrick, 0);
        this.setBlock(world, i + 1, j + 63, k + 102, Dungeons.blockUnbreableStonebrick, 0);
        this.setBlock(world, i + 1, j + 63, k + 103, Dungeons.blockUnbreableStonebrick, 0);
        this.setBlock(world, i + 1, j + 63, k + 104, Dungeons.blockUnbreableStonebrick, 0);
        this.setBlock(world, i + 1, j + 63, k + 105, Dungeons.blockUnbreableStonebrick, 0);
        this.setBlock(world, i + 1, j + 63, k + 106, Dungeons.blockUnbreableStonebrick, 0);
        this.setBlock(world, i + 1, j + 63, k + 107, Dungeons.blockUnbreableStonebrick, 0);
        this.setBlock(world, i + 1, j + 63, k + 108, Dungeons.blockUnbreableStonebrick, 0);
        this.setBlock(world, i + 1, j + 63, k + 109, Dungeons.blockUnbreableStonebrick, 0);
        this.setBlock(world, i + 1, j + 63, k + 110, Blocks.bedrock, 0);
        this.setBlock(world, i + 1, j + 63, k + 111, Dungeons.blockUnbreableStonebrick, 0);
        this.setBlock(world, i + 1, j + 63, k + 112, Blocks.bedrock, 0);
        this.setBlock(world, i + 1, j + 63, k + 113, Blocks.bedrock, 0);
        this.setBlock(world, i + 1, j + 63, k + 114, Blocks.bedrock, 0);
        this.setBlock(world, i + 1, j + 63, k + 115, Blocks.bedrock, 0);
        this.setBlock(world, i + 1, j + 63, k + 116, Dungeons.blockUnbreableStonebrick, 0);
        this.setBlock(world, i + 1, j + 64, k + 92, Blocks.stained_hardened_clay, 9);
        this.setBlock(world, i + 1, j + 64, k + 93, Blocks.bedrock, 0);
        this.setBlock(world, i + 1, j + 64, k + 94, Blocks.bedrock, 0);
        this.setBlock(world, i + 1, j + 64, k + 113, Blocks.bedrock, 0);
        this.setBlock(world, i + 1, j + 64, k + 114, Blocks.bedrock, 0);
        this.setBlock(world, i + 1, j + 64, k + 115, Blocks.bedrock, 0);
        this.setBlock(world, i + 1, j + 64, k + 116, Blocks.bedrock, 0);
        this.setBlock(world, i + 1, j + 65, k + 92, Blocks.cobblestone_wall, 0);
        this.setBlock(world, i + 1, j + 65, k + 114, Dungeons.blockUnbreableStonebrick, 0);
        this.setBlock(world, i + 1, j + 65, k + 116, Blocks.bedrock, 0);
        this.setBlock(world, i + 2, j + 37, k + 103, Dungeons.blockUnbreableStone, 0);
        this.setBlock(world, i + 2, j + 37, k + 104, Dungeons.blockUnbreableStone, 0);
        this.setBlock(world, i + 2, j + 37, k + 105, Dungeons.blockUnbreableStone, 0);
        this.setBlock(world, i + 2, j + 37, k + 106, Dungeons.blockUnbreableStone, 0);
        this.setBlock(world, i + 2, j + 37, k + 107, Dungeons.blockUnbreableCobbleStone, 0);
        this.setBlock(world, i + 2, j + 37, k + 108, Dungeons.blockUnbreableStone, 0);
        this.setBlock(world, i + 2, j + 37, k + 109, Blocks.bedrock, 0);
        this.setBlock(world, i + 2, j + 37, k + 110, Dungeons.blockUnbreableStone, 0);
        this.setBlock(world, i + 2, j + 38, k + 97, Dungeons.blockUnbreableStone, 0);
        this.setBlock(world, i + 2, j + 38, k + 98, Dungeons.blockUnbreableStone, 0);
        this.setBlock(world, i + 2, j + 38, k + 99, Dungeons.blockUnbreableStone, 0);
        this.setBlock(world, i + 2, j + 38, k + 100, Dungeons.blockUnbreableStone, 0);
        this.setBlock(world, i + 2, j + 38, k + 101, Blocks.bedrock, 0);
        this.setBlock(world, i + 2, j + 38, k + 102, Blocks.bedrock, 0);
        this.setBlock(world, i + 2, j + 38, k + 103, Dungeons.blockUnbreableStone, 0);
        this.setBlock(world, i + 2, j + 38, k + 104, Dungeons.blockUnbreableStone, 0);
        this.setBlock(world, i + 2, j + 38, k + 105, Dungeons.blockUnbreableStone, 0);
        this.setBlock(world, i + 2, j + 38, k + 106, Dungeons.blockUnbreableStone, 0);
        this.setBlock(world, i + 2, j + 38, k + 107, Dungeons.blockUnbreableCobbleStone, 0);
        this.setBlock(world, i + 2, j + 38, k + 108, Dungeons.blockUnbreableStone, 0);
        this.setBlock(world, i + 2, j + 38, k + 109, Dungeons.blockUnbreableStone, 0);
        this.setBlock(world, i + 2, j + 38, k + 110, Dungeons.blockUnbreableStone, 0);
        this.setBlock(world, i + 2, j + 38, k + 111, Dungeons.blockUnbreableStone, 0);
        this.setBlock(world, i + 2, j + 38, k + 112, Dungeons.blockUnbreableStone, 0);
        this.setBlock(world, i + 2, j + 38, k + 115, Dungeons.blockUnbreableStone, 0);
        this.setBlock(world, i + 2, j + 38, k + 116, Dungeons.blockUnbreableStone, 0);
        this.setBlock(world, i + 2, j + 38, k + 117, Dungeons.blockUnbreableStone, 0);
        this.setBlock(world, i + 2, j + 39, k + 83, Dungeons.blockUnbreableCobbleStone, 0);
        this.setBlock(world, i + 2, j + 39, k + 84, Dungeons.blockUnbreableStone, 0);
        this.setBlock(world, i + 2, j + 39, k + 85, Blocks.bedrock, 0);
        this.setBlock(world, i + 2, j + 39, k + 86, Blocks.bedrock, 0);
        this.setBlock(world, i + 2, j + 39, k + 87, Dungeons.blockUnbreableStone, 0);
        this.setBlock(world, i + 2, j + 39, k + 88, Dungeons.blockUnbreableCobbleStone, 0);
        this.setBlock(world, i + 2, j + 39, k + 89, Dungeons.blockUnbreableStone, 0);
        this.setBlock(world, i + 2, j + 39, k + 90, Dungeons.blockUnbreableStone, 0);
        this.setBlock(world, i + 2, j + 39, k + 91, Dungeons.blockUnbreableStone, 0);
        this.setBlock(world, i + 2, j + 39, k + 92, Dungeons.blockUnbreableStone, 0);
        this.setBlock(world, i + 2, j + 39, k + 93, Dungeons.blockUnbreableStone, 0);
        this.setBlock(world, i + 2, j + 39, k + 94, Dungeons.blockUnbreableStone, 0);
        this.setBlock(world, i + 2, j + 39, k + 95, Dungeons.blockUnbreableStone, 0);
        this.setBlock(world, i + 2, j + 39, k + 96, Dungeons.blockUnbreableStone, 0);
        this.setBlock(world, i + 2, j + 39, k + 97, Dungeons.blockUnbreableCobbleStone, 0);
        this.setBlock(world, i + 2, j + 39, k + 98, Dungeons.blockUnbreableStone, 0);
        this.setBlock(world, i + 2, j + 39, k + 99, Dungeons.blockUnbreableCobbleStone, 0);
        this.setBlock(world, i + 2, j + 39, k + 100, Dungeons.blockUnbreableStone, 0);
        this.setBlock(world, i + 2, j + 39, k + 101, Dungeons.blockUnbreableStone, 0);
        this.setBlock(world, i + 2, j + 39, k + 102, Dungeons.blockUnbreableStone, 0);
        this.setBlock(world, i + 2, j + 39, k + 103, Dungeons.blockUnbreableStone, 0);
        this.setBlock(world, i + 2, j + 39, k + 104, Dungeons.blockUnbreableStone, 0);
        this.setBlock(world, i + 2, j + 39, k + 105, Dungeons.blockUnbreableStone, 0);
        this.setBlock(world, i + 2, j + 39, k + 106, Dungeons.blockUnbreableStone, 0);
        this.setBlock(world, i + 2, j + 39, k + 107, Dungeons.blockUnbreableStone, 0);
        this.setBlock(world, i + 2, j + 39, k + 108, Dungeons.blockUnbreableStone, 0);
        this.setBlock(world, i + 2, j + 39, k + 109, Blocks.bedrock, 0);
        this.setBlock(world, i + 2, j + 39, k + 110, Dungeons.blockUnbreableStone, 0);
        this.setBlock(world, i + 2, j + 39, k + 111, Dungeons.blockUnbreableStone, 0);
        this.setBlock(world, i + 2, j + 39, k + 112, Dungeons.blockUnbreableStone, 0);
        this.setBlock(world, i + 2, j + 39, k + 113, Dungeons.blockUnbreableStone, 0);
        this.setBlock(world, i + 2, j + 39, k + 114, Dungeons.blockUnbreableStone, 0);
        this.setBlock(world, i + 2, j + 39, k + 115, Dungeons.blockUnbreableStone, 0);
        this.setBlock(world, i + 2, j + 39, k + 116, Dungeons.blockUnbreableStone, 0);
        this.setBlock(world, i + 2, j + 39, k + 117, Dungeons.blockUnbreableStone, 0);
        this.setBlock(world, i + 2, j + 39, k + 118, Dungeons.blockUnbreableCobbleStone, 0);
        this.setBlock(world, i + 2, j + 39, k + 119, Dungeons.blockUnbreableStone, 0);
        this.setBlock(world, i + 2, j + 39, k + 120, Dungeons.blockUnbreableStone, 0);
        this.setBlock(world, i + 2, j + 40, k + 81, Blocks.bedrock, 0);
        this.setBlock(world, i + 2, j + 40, k + 82, Dungeons.blockUnbreableStone, 0);
        this.setBlock(world, i + 2, j + 40, k + 83, Dungeons.blockUnbreableCobbleStone, 0);
        this.setBlock(world, i + 2, j + 40, k + 84, Blocks.bedrock, 0);
        this.setBlock(world, i + 2, j + 40, k + 85, Dungeons.blockUnbreableStone, 0);
        this.setBlock(world, i + 2, j + 40, k + 86, Dungeons.blockUnbreableStone, 0);
        this.setBlock(world, i + 2, j + 40, k + 87, Dungeons.blockUnbreableStone, 0);
        this.setBlock(world, i + 2, j + 40, k + 88, Dungeons.blockUnbreableStone, 0);
        this.setBlock(world, i + 2, j + 40, k + 89, Dungeons.blockUnbreableStone, 0);
        this.setBlock(world, i + 2, j + 40, k + 90, Dungeons.blockUnbreableStone, 0);
        this.setBlock(world, i + 2, j + 40, k + 91, Dungeons.blockUnbreableStone, 0);
        this.setBlock(world, i + 2, j + 40, k + 92, Dungeons.blockUnbreableCobbleStone, 0);
        this.setBlock(world, i + 2, j + 40, k + 93, Dungeons.blockUnbreableStone, 0);
        this.setBlock(world, i + 2, j + 40, k + 94, Dungeons.blockUnbreableCobbleStone, 0);
        this.setBlock(world, i + 2, j + 40, k + 95, Dungeons.blockUnbreableStone, 0);
        this.setBlock(world, i + 2, j + 40, k + 96, Dungeons.blockUnbreableStone, 0);
        this.setBlock(world, i + 2, j + 40, k + 97, Dungeons.blockUnbreableStone, 0);
        this.setBlock(world, i + 2, j + 40, k + 98, Dungeons.blockUnbreableStone, 0);
        this.setBlock(world, i + 2, j + 40, k + 99, Dungeons.blockUnbreableStone, 0);
        this.setBlock(world, i + 2, j + 40, k + 100, Dungeons.blockUnbreableStone, 0);
        this.setBlock(world, i + 2, j + 40, k + 101, Dungeons.blockUnbreableCobbleStone, 0);
        this.setBlock(world, i + 2, j + 40, k + 102, Dungeons.blockUnbreableStone, 0);
        this.setBlock(world, i + 2, j + 40, k + 103, Dungeons.blockUnbreableStone, 0);
        this.setBlock(world, i + 2, j + 40, k + 104, Dungeons.blockUnbreableStone, 0);
        this.setBlock(world, i + 2, j + 40, k + 105, Dungeons.blockUnbreableStone, 0);
        this.setBlock(world, i + 2, j + 40, k + 106, Blocks.bedrock, 0);
        this.setBlock(world, i + 2, j + 40, k + 107, Dungeons.blockUnbreableStone, 0);
        this.setBlock(world, i + 2, j + 40, k + 108, Dungeons.blockUnbreableStone, 0);
        this.setBlock(world, i + 2, j + 40, k + 109, Dungeons.blockUnbreableCobbleStone, 0);
        this.setBlock(world, i + 2, j + 40, k + 110, Dungeons.blockUnbreableStone, 0);
        this.setBlock(world, i + 2, j + 40, k + 111, Dungeons.blockUnbreableStone, 0);
        this.setBlock(world, i + 2, j + 40, k + 112, Dungeons.blockUnbreableStone, 0);
        this.setBlock(world, i + 2, j + 40, k + 113, Dungeons.blockUnbreableStone, 0);
        this.setBlock(world, i + 2, j + 40, k + 114, Dungeons.blockUnbreableCobbleStone, 0);
        this.setBlock(world, i + 2, j + 40, k + 115, Dungeons.blockUnbreableStone, 0);
        this.setBlock(world, i + 2, j + 40, k + 116, Dungeons.blockUnbreableStone, 0);
        this.setBlock(world, i + 2, j + 40, k + 117, Dungeons.blockUnbreableStone, 0);
        this.setBlock(world, i + 2, j + 40, k + 118, Blocks.bedrock, 0);
        this.setBlock(world, i + 2, j + 40, k + 119, Dungeons.blockUnbreableStone, 0);
        this.setBlock(world, i + 2, j + 40, k + 120, Dungeons.blockUnbreableStone, 0);
        this.setBlock(world, i + 2, j + 40, k + 121, Dungeons.blockUnbreableStone, 0);
        this.setBlock(world, i + 2, j + 41, k + 79, Dungeons.blockUnbreableCobbleStone, 0);
        this.setBlock(world, i + 2, j + 41, k + 80, Dungeons.blockUnbreableStone, 0);
        this.setBlock(world, i + 2, j + 41, k + 81, Blocks.bedrock, 0);
        this.setBlock(world, i + 2, j + 41, k + 82, Blocks.bedrock, 0);
        this.setBlock(world, i + 2, j + 41, k + 83, Dungeons.blockUnbreableStone, 0);
        this.setBlock(world, i + 2, j + 41, k + 84, Dungeons.blockUnbreableStone, 0);
        this.setBlock(world, i + 2, j + 41, k + 85, Blocks.bedrock, 0);
        this.setBlock(world, i + 2, j + 41, k + 86, Dungeons.blockUnbreableCobbleStone, 0);
        this.setBlock(world, i + 2, j + 41, k + 87, Blocks.bedrock, 0);
        this.setBlock(world, i + 2, j + 41, k + 88, Dungeons.blockUnbreableStone, 0);
        this.setBlock(world, i + 2, j + 41, k + 89, Dungeons.blockUnbreableStone, 0);
        this.setBlock(world, i + 2, j + 41, k + 90, Dungeons.blockUnbreableStone, 0);
        this.setBlock(world, i + 2, j + 41, k + 91, Dungeons.blockUnbreableStone, 0);
        this.setBlock(world, i + 2, j + 41, k + 92, Dungeons.blockUnbreableStone, 0);
        this.setBlock(world, i + 2, j + 41, k + 93, Dungeons.blockUnbreableStone, 0);
        this.setBlock(world, i + 2, j + 41, k + 94, Dungeons.blockUnbreableStone, 0);
        this.setBlock(world, i + 2, j + 41, k + 95, Dungeons.blockUnbreableStone, 0);
        this.setBlock(world, i + 2, j + 41, k + 96, Dungeons.blockUnbreableStone, 0);
        this.setBlock(world, i + 2, j + 41, k + 97, Dungeons.blockUnbreableStone, 0);
        this.setBlock(world, i + 2, j + 41, k + 98, Dungeons.blockUnbreableStone, 0);
        this.setBlock(world, i + 2, j + 41, k + 99, Dungeons.blockUnbreableCobbleStone, 0);
        this.setBlock(world, i + 2, j + 41, k + 100, Dungeons.blockUnbreableStone, 0);
        this.setBlock(world, i + 2, j + 41, k + 101, Dungeons.blockUnbreableStone, 0);
        this.setBlock(world, i + 2, j + 41, k + 102, Dungeons.blockUnbreableStone, 0);
        this.setBlock(world, i + 2, j + 41, k + 103, Dungeons.blockUnbreableCobbleStone, 0);
        this.setBlock(world, i + 2, j + 41, k + 104, Dungeons.blockUnbreableStone, 0);
        this.setBlock(world, i + 2, j + 41, k + 105, Dungeons.blockUnbreableStone, 0);
        this.setBlock(world, i + 2, j + 41, k + 106, Dungeons.blockUnbreableStone, 0);
        this.setBlock(world, i + 2, j + 41, k + 107, Dungeons.blockUnbreableStone, 0);
        this.setBlock(world, i + 2, j + 41, k + 108, Dungeons.blockUnbreableStone, 0);
        this.setBlock(world, i + 2, j + 41, k + 109, Dungeons.blockUnbreableStone, 0);
        this.setBlock(world, i + 2, j + 41, k + 110, Dungeons.blockUnbreableStone, 0);
        this.setBlock(world, i + 2, j + 41, k + 111, Dungeons.blockUnbreableStone, 0);
        this.setBlock(world, i + 2, j + 41, k + 112, Dungeons.blockUnbreableStone, 0);
        this.setBlock(world, i + 2, j + 41, k + 113, Dungeons.blockUnbreableStone, 0);
        this.setBlock(world, i + 2, j + 41, k + 114, Dungeons.blockUnbreableStone, 0);
        this.setBlock(world, i + 2, j + 41, k + 115, Dungeons.blockUnbreableCobbleStone, 0);
        this.setBlock(world, i + 2, j + 41, k + 116, Dungeons.blockUnbreableStone, 0);
        this.setBlock(world, i + 2, j + 41, k + 117, Dungeons.blockUnbreableCobbleStone, 0);
        this.setBlock(world, i + 2, j + 41, k + 118, Dungeons.blockUnbreableStone, 0);
        this.setBlock(world, i + 2, j + 41, k + 119, Dungeons.blockUnbreableStone, 0);
        this.setBlock(world, i + 2, j + 41, k + 120, Dungeons.blockUnbreableStone, 0);
        this.setBlock(world, i + 2, j + 41, k + 121, Dungeons.blockUnbreableStone, 0);
        this.setBlock(world, i + 2, j + 41, k + 122, Dungeons.blockUnbreableStone, 0);
        this.setBlock(world, i + 2, j + 41, k + 123, Dungeons.blockUnbreableStone, 0);
        this.setBlock(world, i + 2, j + 42, k + 77, Dungeons.blockUnbreableStone, 0);
        this.setBlock(world, i + 2, j + 42, k + 78, Dungeons.blockUnbreableStone, 0);
        this.setBlock(world, i + 2, j + 42, k + 79, Dungeons.blockUnbreableStone, 0);
        this.setBlock(world, i + 2, j + 42, k + 80, Dungeons.blockUnbreableStone, 0);
        this.setBlock(world, i + 2, j + 42, k + 81, Dungeons.blockUnbreableStone, 0);
        this.setBlock(world, i + 2, j + 42, k + 82, Dungeons.blockUnbreableStone, 0);
        this.setBlock(world, i + 2, j + 42, k + 83, Dungeons.blockUnbreableStone, 0);
        this.setBlock(world, i + 2, j + 42, k + 84, Dungeons.blockUnbreableStone, 0);
        this.setBlock(world, i + 2, j + 42, k + 85, Dungeons.blockUnbreableCobbleStone, 0);
        this.setBlock(world, i + 2, j + 42, k + 86, Dungeons.blockUnbreableCobbleStone, 0);
        this.setBlock(world, i + 2, j + 42, k + 87, Blocks.bedrock, 0);
        this.setBlock(world, i + 2, j + 42, k + 88, Dungeons.blockUnbreableStone, 0);
        this.setBlock(world, i + 2, j + 42, k + 89, Dungeons.blockUnbreableStone, 0);
        this.setBlock(world, i + 2, j + 42, k + 90, Dungeons.blockUnbreableStone, 0);
        this.setBlock(world, i + 2, j + 42, k + 91, Dungeons.blockUnbreableStone, 0);
        this.setBlock(world, i + 2, j + 42, k + 92, Dungeons.blockUnbreableStone, 0);
        this.setBlock(world, i + 2, j + 42, k + 93, Blocks.bedrock, 0);
        this.setBlock(world, i + 2, j + 42, k + 94, Dungeons.blockUnbreableStone, 0);
        this.setBlock(world, i + 2, j + 42, k + 95, Dungeons.blockUnbreableStone, 0);
        this.setBlock(world, i + 2, j + 42, k + 96, Dungeons.blockUnbreableCobbleStone, 0);
        this.setBlock(world, i + 2, j + 42, k + 97, Blocks.bedrock, 0);
        this.setBlock(world, i + 2, j + 42, k + 98, Dungeons.blockUnbreableStone, 0);
        this.setBlock(world, i + 2, j + 42, k + 99, Dungeons.blockUnbreableStone, 0);
        this.setBlock(world, i + 2, j + 42, k + 100, Dungeons.blockUnbreableCobbleStone, 0);
        this.setBlock(world, i + 2, j + 42, k + 101, Dungeons.blockUnbreableStone, 0);
        this.setBlock(world, i + 2, j + 42, k + 102, Dungeons.blockUnbreableStone, 0);
        this.setBlock(world, i + 2, j + 42, k + 103, Dungeons.blockUnbreableStone, 0);
        this.setBlock(world, i + 2, j + 42, k + 104, Dungeons.blockUnbreableStone, 0);
        this.setBlock(world, i + 2, j + 42, k + 105, Dungeons.blockUnbreableStone, 0);
        this.setBlock(world, i + 2, j + 42, k + 106, Dungeons.blockUnbreableStone, 0);
        this.setBlock(world, i + 2, j + 42, k + 107, Dungeons.blockUnbreableStone, 0);
        this.setBlock(world, i + 2, j + 42, k + 108, Dungeons.blockUnbreableStone, 0);
        this.setBlock(world, i + 2, j + 42, k + 109, Dungeons.blockUnbreableStone, 0);
        this.setBlock(world, i + 2, j + 42, k + 110, Dungeons.blockUnbreableStone, 0);
        this.setBlock(world, i + 2, j + 42, k + 111, Dungeons.blockUnbreableStone, 0);
        this.setBlock(world, i + 2, j + 42, k + 112, Dungeons.blockUnbreableStone, 0);
        this.setBlock(world, i + 2, j + 42, k + 113, Dungeons.blockUnbreableStone, 0);
        this.setBlock(world, i + 2, j + 42, k + 114, Dungeons.blockUnbreableStone, 0);
        this.setBlock(world, i + 2, j + 42, k + 115, Dungeons.blockUnbreableStone, 0);
        this.setBlock(world, i + 2, j + 42, k + 116, Dungeons.blockUnbreableStone, 0);
        this.setBlock(world, i + 2, j + 42, k + 117, Dungeons.blockUnbreableStone, 0);
        this.setBlock(world, i + 2, j + 42, k + 118, Dungeons.blockUnbreableStone, 0);
        this.setBlock(world, i + 2, j + 42, k + 119, Dungeons.blockUnbreableStone, 0);
        this.setBlock(world, i + 2, j + 42, k + 120, Dungeons.blockUnbreableStone, 0);
        this.setBlock(world, i + 2, j + 42, k + 121, Dungeons.blockUnbreableStone, 0);
        this.setBlock(world, i + 2, j + 42, k + 122, Dungeons.blockUnbreableStone, 0);
        this.setBlock(world, i + 2, j + 42, k + 123, Dungeons.blockUnbreableCobbleStone, 0);
        this.setBlock(world, i + 2, j + 42, k + 124, Dungeons.blockUnbreableStone, 0);
        this.setBlock(world, i + 2, j + 42, k + 125, Dungeons.blockUnbreableCobbleStone, 0);
        this.setBlock(world, i + 2, j + 42, k + 126, Dungeons.blockUnbreableStone, 0);
        this.setBlock(world, i + 2, j + 42, k + 127, Dungeons.blockUnbreableStone, 0);
        this.setBlock(world, i + 2, j + 42, k + 128, Blocks.bedrock, 0);
        this.setBlock(world, i + 2, j + 42, k + 129, Dungeons.blockUnbreableStone, 0);
        this.setBlock(world, i + 2, j + 42, k + 130, Dungeons.blockUnbreableStone, 0);
        this.setBlock(world, i + 2, j + 42, k + 131, Dungeons.blockUnbreableStone, 0);
        this.setBlock(world, i + 2, j + 43, k + 87, Dungeons.blockUnbreableStone, 0);
        this.setBlock(world, i + 2, j + 43, k + 88, Dungeons.blockUnbreableStone, 0);
        this.setBlock(world, i + 2, j + 43, k + 89, Blocks.bedrock, 0);
        this.setBlock(world, i + 2, j + 43, k + 90, Dungeons.blockUnbreableStone, 0);
        this.setBlock(world, i + 2, j + 43, k + 91, Dungeons.blockUnbreableStone, 0);
        this.setBlock(world, i + 2, j + 43, k + 92, Dungeons.blockUnbreableCobbleStone, 0);
        this.setBlock(world, i + 2, j + 43, k + 93, Dungeons.blockUnbreableStone, 0);
        this.setBlock(world, i + 2, j + 43, k + 94, Dungeons.blockUnbreableStone, 0);
        this.setBlock(world, i + 2, j + 43, k + 95, Dungeons.blockUnbreableStone, 0);
        this.setBlock(world, i + 2, j + 43, k + 96, Dungeons.blockUnbreableStone, 0);
        this.setBlock(world, i + 2, j + 43, k + 97, Dungeons.blockUnbreableStone, 0);
        this.setBlock(world, i + 2, j + 43, k + 98, Dungeons.blockUnbreableStone, 0);
        this.setBlock(world, i + 2, j + 43, k + 99, Blocks.bedrock, 0);
        this.setBlock(world, i + 2, j + 43, k + 100, Dungeons.blockUnbreableStone, 0);
        this.setBlock(world, i + 2, j + 43, k + 101, Dungeons.blockUnbreableStone, 0);
        this.setBlock(world, i + 2, j + 43, k + 102, Dungeons.blockUnbreableStone, 0);
        this.setBlock(world, i + 2, j + 43, k + 103, Dungeons.blockUnbreableStone, 0);
        this.setBlock(world, i + 2, j + 43, k + 104, Blocks.bedrock, 0);
        this.setBlock(world, i + 2, j + 43, k + 105, Dungeons.blockUnbreableStone, 0);
        this.setBlock(world, i + 2, j + 43, k + 106, Dungeons.blockUnbreableStone, 0);
        this.setBlock(world, i + 2, j + 43, k + 107, Dungeons.blockUnbreableStone, 0);
        this.setBlock(world, i + 2, j + 43, k + 108, Dungeons.blockUnbreableCobbleStone, 0);
        this.setBlock(world, i + 2, j + 43, k + 109, Dungeons.blockUnbreableStone, 0);
        this.setBlock(world, i + 2, j + 43, k + 110, Dungeons.blockUnbreableStone, 0);
        this.setBlock(world, i + 2, j + 43, k + 111, Dungeons.blockUnbreableStone, 0);
        this.setBlock(world, i + 2, j + 43, k + 112, Dungeons.blockUnbreableStone, 0);
        this.setBlock(world, i + 2, j + 43, k + 113, Dungeons.blockUnbreableStone, 0);
        this.setBlock(world, i + 2, j + 43, k + 114, Dungeons.blockUnbreableStone, 0);
        this.setBlock(world, i + 2, j + 43, k + 115, Dungeons.blockUnbreableStone, 0);
        this.setBlock(world, i + 2, j + 43, k + 116, Dungeons.blockUnbreableStone, 0);
        this.setBlock(world, i + 2, j + 43, k + 117, Dungeons.blockUnbreableStone, 0);
        this.setBlock(world, i + 2, j + 43, k + 118, Dungeons.blockUnbreableStone, 0);
        this.setBlock(world, i + 2, j + 43, k + 119, Dungeons.blockUnbreableStone, 0);
        this.setBlock(world, i + 2, j + 44, k + 83, Blocks.leaves, 1);
        this.setBlock(world, i + 2, j + 44, k + 90, Dungeons.blockUnbreableStone, 0);
        this.setBlock(world, i + 2, j + 44, k + 91, Blocks.bedrock, 0);
        this.setBlock(world, i + 2, j + 44, k + 92, Dungeons.blockUnbreableStone, 0);
        this.setBlock(world, i + 2, j + 44, k + 93, Dungeons.blockUnbreableStone, 0);
        this.setBlock(world, i + 2, j + 44, k + 94, Dungeons.blockUnbreableStone, 0);
        this.setBlock(world, i + 2, j + 44, k + 95, Dungeons.blockUnbreableStonebrick, 0);
        this.setBlock(world, i + 2, j + 44, k + 96, Blocks.stained_hardened_clay, 9);
        this.setBlock(world, i + 2, j + 44, k + 97, Blocks.stained_hardened_clay, 9);
        this.setBlock(world, i + 2, j + 44, k + 98, Dungeons.blockUnbreableStone, 0);
        this.setBlock(world, i + 2, j + 44, k + 99, Dungeons.blockUnbreableStone, 0);
        this.setBlock(world, i + 2, j + 44, k + 100, Dungeons.blockUnbreableStone, 0);
        this.setBlock(world, i + 2, j + 44, k + 101, Dungeons.blockUnbreableStone, 0);
        this.setBlock(world, i + 2, j + 44, k + 102, Dungeons.blockUnbreableStone, 0);
        this.setBlock(world, i + 2, j + 44, k + 103, Dungeons.blockUnbreableStone, 0);
        this.setBlock(world, i + 2, j + 44, k + 104, Blocks.bedrock, 0);
        this.setBlock(world, i + 2, j + 44, k + 105, Dungeons.blockUnbreableStone, 0);
        this.setBlock(world, i + 2, j + 44, k + 106, Dungeons.blockUnbreableStone, 0);
        this.setBlock(world, i + 2, j + 44, k + 107, Dungeons.blockUnbreableStone, 0);
        this.setBlock(world, i + 2, j + 44, k + 108, Dungeons.blockUnbreableCobbleStone, 0);
        this.setBlock(world, i + 2, j + 44, k + 109, Blocks.bedrock, 0);
        this.setBlock(world, i + 2, j + 44, k + 110, Dungeons.blockUnbreableCobbleStone, 0);
        this.setBlock(world, i + 2, j + 44, k + 111, Dungeons.blockUnbreableStone, 0);
        this.setBlock(world, i + 2, j + 44, k + 112, Dungeons.blockUnbreableStone, 0);
        this.setBlock(world, i + 2, j + 44, k + 113, Dungeons.blockUnbreableStone, 0);
        this.setBlock(world, i + 2, j + 44, k + 114, Dungeons.blockUnbreableStone, 0);
        this.setBlock(world, i + 2, j + 44, k + 115, Dungeons.blockUnbreableStone, 0);
        this.setBlock(world, i + 2, j + 44, k + 116, Dungeons.blockUnbreableCobbleStone, 0);
        this.setBlock(world, i + 2, j + 44, k + 117, Dungeons.blockUnbreableStone, 0);
        this.setBlock(world, i + 2, j + 44, k + 118, Dungeons.blockUnbreableStone, 0);
        this.setBlock(world, i + 2, j + 44, k + 119, Dungeons.blockUnbreableStone, 0);
        this.setBlock(world, i + 2, j + 44, k + 129, Blocks.leaves, 1);
        this.setBlock(world, i + 2, j + 45, k + 81, Blocks.leaves, 1);
        this.setBlock(world, i + 2, j + 45, k + 82, Blocks.leaves, 1);
        this.setBlock(world, i + 2, j + 45, k + 83, Blocks.leaves, 1);
        this.setBlock(world, i + 2, j + 45, k + 84, Blocks.leaves, 1);
        this.setBlock(world, i + 2, j + 45, k + 85, Blocks.leaves, 1);
        this.setBlock(world, i + 2, j + 45, k + 93, Dungeons.blockUnbreableStonebrick, 0);
        this.setBlock(world, i + 2, j + 45, k + 95, Dungeons.blockUnbreableStonebrick, 0);
        this.setBlock(world, i + 2, j + 45, k + 96, Blocks.stained_hardened_clay, 9);
        this.setBlock(world, i + 2, j + 45, k + 97, Blocks.stained_hardened_clay, 9);
        this.setBlock(world, i + 2, j + 45, k + 98, Blocks.stained_hardened_clay, 9);
        this.setBlock(world, i + 2, j + 45, k + 99, Blocks.stained_hardened_clay, 9);
        this.setBlock(world, i + 2, j + 45, k + 100, Blocks.bedrock, 0);
        this.setBlock(world, i + 2, j + 45, k + 101, Dungeons.blockUnbreableStone, 0);
        this.setBlock(world, i + 2, j + 45, k + 102, Dungeons.blockUnbreableStone, 0);
        this.setBlock(world, i + 2, j + 45, k + 103, Dungeons.blockUnbreableStone, 0);
        this.setBlock(world, i + 2, j + 45, k + 104, Dungeons.blockUnbreableStone, 0);
        this.setBlock(world, i + 2, j + 45, k + 105, Dungeons.blockUnbreableStone, 0);
        this.setBlock(world, i + 2, j + 45, k + 106, Dungeons.blockUnbreableCobbleStone, 0);
        this.setBlock(world, i + 2, j + 45, k + 107, Dungeons.blockUnbreableStone, 0);
        this.setBlock(world, i + 2, j + 45, k + 108, Dungeons.blockUnbreableStone, 0);
        this.setBlock(world, i + 2, j + 45, k + 109, Dungeons.blockUnbreableStone, 0);
        this.setBlock(world, i + 2, j + 45, k + 110, Dungeons.blockUnbreableStone, 0);
        this.setBlock(world, i + 2, j + 45, k + 111, Dungeons.blockUnbreableStone, 0);
        this.setBlock(world, i + 2, j + 45, k + 112, Dungeons.blockUnbreableStone, 0);
        this.setBlock(world, i + 2, j + 45, k + 113, Dungeons.blockUnbreableStone, 0);
        this.setBlock(world, i + 2, j + 45, k + 114, Dungeons.blockUnbreableStone, 0);
        this.setBlock(world, i + 2, j + 45, k + 115, Dungeons.blockUnbreableCobbleStone, 0);
        this.setBlock(world, i + 2, j + 45, k + 116, Dungeons.blockUnbreableStone, 0);
        this.setBlock(world, i + 2, j + 45, k + 117, Dungeons.blockUnbreableStone, 0);
        this.setBlock(world, i + 2, j + 45, k + 118, Dungeons.blockUnbreableStone, 0);
        this.setBlock(world, i + 2, j + 45, k + 127, Blocks.leaves, 1);
        this.setBlock(world, i + 2, j + 45, k + 128, Blocks.leaves, 1);
        this.setBlock(world, i + 2, j + 45, k + 129, Blocks.leaves, 1);
        this.setBlock(world, i + 2, j + 45, k + 130, Blocks.leaves, 1);
        this.setBlock(world, i + 2, j + 45, k + 131, Blocks.leaves, 1);
        this.setBlock(world, i + 2, j + 46, k + 83, Blocks.leaves, 1);
        this.setBlock(world, i + 2, j + 46, k + 93, Dungeons.blockUnbreableStonebrick, 0);
        this.setBlock(world, i + 2, j + 46, k + 95, Dungeons.blockUnbreableStonebrick, 0);
        this.setBlock(world, i + 2, j + 46, k + 96, Blocks.stained_hardened_clay, 9);
        this.setBlock(world, i + 2, j + 46, k + 97, Blocks.stained_hardened_clay, 9);
        this.setBlock(world, i + 2, j + 46, k + 98, Blocks.stained_hardened_clay, 9);
        this.setBlock(world, i + 2, j + 46, k + 99, Blocks.stained_hardened_clay, 9);
        this.setBlock(world, i + 2, j + 46, k + 100, Blocks.stained_hardened_clay, 9);
        this.setBlock(world, i + 2, j + 46, k + 102, Dungeons.blockUnbreableStonebrick, 0);
        this.setBlock(world, i + 2, j + 46, k + 103, Dungeons.blockUnbreableStone, 0);
        this.setBlock(world, i + 2, j + 46, k + 104, Dungeons.blockUnbreableStone, 0);
        this.setBlock(world, i + 2, j + 46, k + 105, Dungeons.blockUnbreableStone, 0);
        this.setBlock(world, i + 2, j + 46, k + 106, Dungeons.blockUnbreableStonebrick, 0);
        this.setBlock(world, i + 2, j + 46, k + 108, Blocks.stained_hardened_clay, 9);
        this.setBlock(world, i + 2, j + 46, k + 109, Blocks.stained_hardened_clay, 9);
        this.setBlock(world, i + 2, j + 46, k + 110, Dungeons.blockUnbreableStone, 0);
        this.setBlock(world, i + 2, j + 46, k + 111, Dungeons.blockUnbreableStone, 0);
        this.setBlock(world, i + 2, j + 46, k + 112, Dungeons.blockUnbreableStone, 0);
        this.setBlock(world, i + 2, j + 46, k + 113, Dungeons.blockUnbreableStone, 0);
        this.setBlock(world, i + 2, j + 46, k + 114, Dungeons.blockUnbreableStone, 0);
        this.setBlock(world, i + 2, j + 46, k + 115, Blocks.bedrock, 0);
        this.setBlock(world, i + 2, j + 46, k + 116, Dungeons.blockUnbreableStone, 0);
        this.setBlock(world, i + 2, j + 46, k + 117, Dungeons.blockUnbreableStone, 0);
        this.setBlock(world, i + 2, j + 46, k + 129, Blocks.leaves, 1);
        this.setBlock(world, i + 2, j + 47, k + 81, Blocks.leaves, 1);
        this.setBlock(world, i + 2, j + 47, k + 82, Blocks.leaves, 1);
        this.setBlock(world, i + 2, j + 47, k + 83, Blocks.leaves, 1);
        this.setBlock(world, i + 2, j + 47, k + 84, Blocks.leaves, 1);
        this.setBlock(world, i + 2, j + 47, k + 85, Blocks.leaves, 1);
        this.setBlock(world, i + 2, j + 47, k + 93, Dungeons.blockUnbreableStonebrick, 0);
        this.setBlock(world, i + 2, j + 47, k + 95, Dungeons.blockUnbreableStonebrick, 0);
        this.setBlock(world, i + 2, j + 47, k + 96, Blocks.stained_hardened_clay, 9);
        this.setBlock(world, i + 2, j + 47, k + 97, Blocks.stained_hardened_clay, 9);
        this.setBlock(world, i + 2, j + 47, k + 98, Blocks.stained_hardened_clay, 9);
        this.setBlock(world, i + 2, j + 47, k + 99, Blocks.stained_hardened_clay, 9);
        this.setBlock(world, i + 2, j + 47, k + 100, Blocks.stained_hardened_clay, 9);
        this.setBlock(world, i + 2, j + 47, k + 102, Dungeons.blockUnbreableStonebrick, 0);
        this.setBlock(world, i + 2, j + 47, k + 103, Dungeons.blockUnbreableStonebrick, 0);
