

package com.gibby.dungeon.gen;

import com.gibby.dungeon.Dungeons;
import cpw.mods.fml.common.IWorldGenerator;
import net.minecraft.block.Block;
import net.minecraft.init.Blocks;
import net.minecraft.world.IBlockAccess;
import net.minecraft.world.World;
import net.minecraft.world.chunk.IChunkProvider;
import net.minecraft.world.gen.feature.WorldGenerator;

import java.util.Random;

public class WorldGenCrystalliumTemple extends WorldGenerator implements IWorldGenerator
{
    public void generate(final Random random, final int chunkX, final int chunkZ, final World world, final IChunkProvider chunkGenerator, final IChunkProvider chunkProvider) {
    }

    public void setBlock(final World world, final int x, final int y, final int z, final Block block, final int metadata) {
        final Block b1 = world.getBlock(x, y, z);
        if (b1.isAir((IBlockAccess)world, x, y, z) || b1.isLeaves((IBlockAccess)world, x, y, z)) {
            world.setBlock(x, y, z, block, metadata, 2);
        }
    }

    public boolean generate(final World world, final Random rand, final int i, final int j, final int k) {
        if (world.getBlock(i, j - 1, k) != Dungeons.crystalliumDirt || world.getBlock(i + 21, j - 1, k + 21) != Dungeons.crystalliumDirt || world.getBlock(i, j, k) != Dungeons.crystalliumGrass || world.getBlock(i + 21, j, k + 1) != Dungeons.crystalliumGrass || world.getBlock(i, j + 21, k) != Blocks.air || world.getBlock(i + 21, j + 21, k + 21) != Blocks.air) {
            return false;
        }
        this.setBlock(world, i, j, k + 11, Dungeons.purpleBrick, 0);
        this.setBlock(world, i, j, k + 12, Dungeons.purpleBrick, 0);
        this.setBlock(world, i, j, k + 13, Dungeons.purpleBrick, 0);
        this.setBlock(world, i + 1, j, k + 11, Dungeons.purpleBrick, 0);
        this.setBlock(world, i + 1, j, k + 12, Dungeons.purpleBrick, 0);
        this.setBlock(world, i + 1, j, k + 13, Dungeons.purpleBrick, 0);
        this.setBlock(world, i + 1, j + 1, k + 11, Dungeons.purpleBrick, 0);
        this.setBlock(world, i + 1, j + 1, k + 12, Dungeons.purpleBrick, 0);
        this.setBlock(world, i + 1, j + 1, k + 13, Dungeons.purpleBrick, 0);
        this.setBlock(world, i + 2, j, k + 3, Dungeons.purpleBrick, 0);
        this.setBlock(world, i + 2, j, k + 4, Dungeons.purpleBrick, 0);
        this.setBlock(world, i + 2, j, k + 5, Dungeons.purpleBrick, 0);
        this.setBlock(world, i + 2, j, k + 6, Dungeons.purpleBrick, 0);
        this.setBlock(world, i + 2, j, k + 7, Dungeons.purpleBrick, 0);
        this.setBlock(world, i + 2, j, k + 8, Dungeons.purpleBrick, 0);
        this.setBlock(world, i + 2, j, k + 9, Dungeons.purpleBrick, 0);
        this.setBlock(world, i + 2, j, k + 10, Dungeons.purpleBrick, 0);
        this.setBlock(world, i + 2, j, k + 11, Dungeons.purpleBrick, 0);
        this.setBlock(world, i + 2, j, k + 12, Dungeons.purpleBrick, 0);
        this.setBlock(world, i + 2, j, k + 13, Dungeons.purpleBrick, 0);
        this.setBlock(world, i + 2, j, k + 14, Dungeons.purpleBrick, 0);
        this.setBlock(world, i + 2, j, k + 15, Dungeons.purpleBrick, 0);
        this.setBlock(world, i + 2, j, k + 16, Dungeons.purpleBrick, 0);
        this.setBlock(world, i + 2, j, k + 17, Dungeons.purpleBrick, 0);
        this.setBlock(world, i + 2, j, k + 18, Dungeons.purpleBrick, 0);
        this.setBlock(world, i + 2, j, k + 19, Dungeons.purpleBrick, 0);
        this.setBlock(world, i + 2, j, k + 20, Dungeons.purpleBrick, 0);
        this.setBlock(world, i + 2, j, k + 21, Dungeons.purpleBrick, 0);
        this.setBlock(world, i + 2, j + 1, k + 3, Dungeons.purpleBrick, 0);
        this.setBlock(world, i + 2, j + 1, k + 4, Dungeons.purpleBrick, 0);
        this.setBlock(world, i + 2, j + 1, k + 5, Dungeons.purpleBrick, 0);
        this.setBlock(world, i + 2, j + 1, k + 6, Dungeons.purpleBrick, 0);
        this.setBlock(world, i + 2, j + 1, k + 7, Dungeons.purpleBrick, 0);
        this.setBlock(world, i + 2, j + 1, k + 8, Dungeons.purpleBrick, 0);
        this.setBlock(world, i + 2, j + 1, k + 9, Dungeons.purpleBrick, 0);
        this.setBlock(world, i + 2, j + 1, k + 10, Dungeons.purpleBrick, 0);
        this.setBlock(world, i + 2, j + 1, k + 11, Dungeons.purpleBrick, 0);
        this.setBlock(world, i + 2, j + 1, k + 12, Dungeons.purpleBrick, 0);
        this.setBlock(world, i + 2, j + 1, k + 13, Dungeons.purpleBrick, 0);
        this.setBlock(world, i + 2, j + 1, k + 14, Dungeons.purpleBrick, 0);
        this.setBlock(world, i + 2, j + 1, k + 15, Dungeons.purpleBrick, 0);
        this.setBlock(world, i + 2, j + 1, k + 16, Dungeons.purpleBrick, 0);
        this.setBlock(world, i + 2, j + 1, k + 17, Dungeons.purpleBrick, 0);
        this.setBlock(world, i + 2, j + 1, k + 18, Dungeons.purpleBrick, 0);
        this.setBlock(world, i + 2, j + 1, k + 19, Dungeons.purpleBrick, 0);
        this.setBlock(world, i + 2, j + 1, k + 20, Dungeons.purpleBrick, 0);
        this.setBlock(world, i + 2, j + 1, k + 21, Dungeons.purpleBrick, 0);
        this.setBlock(world, i + 2, j + 2, k + 3, Dungeons.purpleBrick, 0);
        this.setBlock(world, i + 2, j + 2, k + 4, Dungeons.purpleBrick, 0);
        this.setBlock(world, i + 2, j + 2, k + 5, Dungeons.purpleBrick, 0);
        this.setBlock(world, i + 2, j + 2, k + 6, Dungeons.purpleBrick, 0);
        this.setBlock(world, i + 2, j + 2, k + 7, Dungeons.purpleBrick, 0);
        this.setBlock(world, i + 2, j + 2, k + 8, Dungeons.purpleBrick, 0);
        this.setBlock(world, i + 2, j + 2, k + 9, Dungeons.purpleBrick, 0);
        this.setBlock(world, i + 2, j + 2, k + 10, Dungeons.purpleBrick, 0);
        this.setBlock(world, i + 2, j + 2, k + 11, Dungeons.purpleBrick, 0);
        this.setBlock(world, i + 2, j + 2, k + 12, Dungeons.purpleBrick, 0);
        this.setBlock(world, i + 2, j + 2, k + 13, Dungeons.purpleBrick, 0);
        this.setBlock(world, i + 2, j + 2, k + 14, Dungeons.purpleBrick, 0);
        this.setBlock(world, i + 2, j + 2, k + 15, Dungeons.purpleBrick, 0);
        this.setBlock(world, i + 2, j + 2, k + 16, Dungeons.purpleBrick, 0);
        this.setBlock(world, i + 2, j + 2, k + 17, Dungeons.purpleBrick, 0);
        this.setBlock(world, i + 2, j + 2, k + 18, Dungeons.purpleBrick, 0);
        this.setBlock(world, i + 2, j + 2, k + 19, Dungeons.purpleBrick, 0);
        this.setBlock(world, i + 2, j + 2, k + 20, Dungeons.purpleBrick, 0);
        this.setBlock(world, i + 2, j + 2, k + 21, Dungeons.purpleBrick, 0);
        this.setBlock(world, i + 2, j + 3, k + 5, Dungeons.purpleBrick, 0);
        this.setBlock(world, i + 2, j + 3, k + 19, Dungeons.purpleBrick, 0);
        this.setBlock(world, i + 2, j + 4, k + 6, Dungeons.purpleBrick, 0);
        this.setBlock(world, i + 2, j + 4, k + 18, Dungeons.purpleBrick, 0);
        this.setBlock(world, i + 2, j + 8, k + 6, Dungeons.purpleBrick, 0);
        this.setBlock(world, i + 2, j + 8, k + 7, Dungeons.purpleBrick, 0);
        this.setBlock(world, i + 2, j + 8, k + 8, Dungeons.purpleBrick, 0);
        this.setBlock(world, i + 2, j + 8, k + 9, Dungeons.purpleBrick, 0);
        this.setBlock(world, i + 2, j + 8, k + 10, Dungeons.purpleBrick, 0);
        this.setBlock(world, i + 2, j + 8, k + 11, Dungeons.purpleBrick, 0);
        this.setBlock(world, i + 2, j + 8, k + 12, Dungeons.purpleBrick, 0);
        this.setBlock(world, i + 2, j + 8, k + 13, Dungeons.purpleBrick, 0);
        this.setBlock(world, i + 2, j + 8, k + 14, Dungeons.purpleBrick, 0);
        this.setBlock(world, i + 2, j + 8, k + 15, Dungeons.purpleBrick, 0);
        this.setBlock(world, i + 2, j + 8, k + 16, Dungeons.purpleBrick, 0);
        this.setBlock(world, i + 2, j + 8, k + 17, Dungeons.purpleBrick, 0);
        this.setBlock(world, i + 2, j + 8, k + 18, Dungeons.purpleBrick, 0);
        this.setBlock(world, i + 2, j + 9, k + 5, Dungeons.purpleBrick, 0);
        this.setBlock(world, i + 2, j + 9, k + 19, Dungeons.purpleBrick, 0);
        this.setBlock(world, i + 2, j + 10, k + 4, Dungeons.purpleBrick, 0);
        this.setBlock(world, i + 2, j + 10, k + 20, Dungeons.purpleBrick, 0);
        this.setBlock(world, i + 2, j + 11, k + 3, Dungeons.purpleBrick, 0);
        this.setBlock(world, i + 2, j + 11, k + 21, Dungeons.purpleBrick, 0);
        this.setBlock(world, i + 3, j, k + 3, Dungeons.purpleBrick, 0);
        this.setBlock(world, i + 3, j, k + 4, Dungeons.purpleBrick, 0);
        this.setBlock(world, i + 3, j, k + 5, Dungeons.purpleBrick, 0);
        this.setBlock(world, i + 3, j, k + 6, Dungeons.purpleBrick, 0);
        this.setBlock(world, i + 3, j, k + 7, Dungeons.purpleBrick, 0);
        this.setBlock(world, i + 3, j, k + 8, Dungeons.purpleBrick, 0);
        this.setBlock(world, i + 3, j, k + 9, Dungeons.purpleBrick, 0);
        this.setBlock(world, i + 3, j, k + 10, Dungeons.purpleBrick, 0);
        this.setBlock(world, i + 3, j, k + 11, Dungeons.purpleBrick, 0);
        this.setBlock(world, i + 3, j, k + 12, Dungeons.purpleBrick, 0);
        this.setBlock(world, i + 3, j, k + 13, Dungeons.purpleBrick, 0);
        this.setBlock(world, i + 3, j, k + 14, Dungeons.purpleBrick, 0);
        this.setBlock(world, i + 3, j, k + 15, Dungeons.purpleBrick, 0);
        this.setBlock(world, i + 3, j, k + 16, Dungeons.purpleBrick, 0);
        this.setBlock(world, i + 3, j, k + 17, Dungeons.purpleBrick, 0);
        this.setBlock(world, i + 3, j, k + 18, Dungeons.purpleBrick, 0);
        this.setBlock(world, i + 3, j, k + 19, Dungeons.purpleBrick, 0);
        this.setBlock(world, i + 3, j, k + 20, Dungeons.purpleBrick, 0);
        this.setBlock(world, i + 3, j, k + 21, Dungeons.purpleBrick, 0);
        this.setBlock(world, i + 3, j + 1, k + 3, Dungeons.purpleBrick, 0);
        this.setBlock(world, i + 3, j + 1, k + 4, Dungeons.purpleBrick, 0);
        this.setBlock(world, i + 3, j + 1, k + 5, Dungeons.purpleBrick, 0);
        this.setBlock(world, i + 3, j + 1, k + 6, Dungeons.purpleBrick, 0);
        this.setBlock(world, i + 3, j + 1, k + 7, Dungeons.purpleBrick, 0);
        this.setBlock(world, i + 3, j + 1, k + 8, Dungeons.purpleBrick, 0);
        this.setBlock(world, i + 3, j + 1, k + 9, Dungeons.purpleBrick, 0);
        this.setBlock(world, i + 3, j + 1, k + 10, Dungeons.purpleBrick, 0);
        this.setBlock(world, i + 3, j + 1, k + 11, Dungeons.purpleBrick, 0);
        this.setBlock(world, i + 3, j + 1, k + 12, Dungeons.purpleBrick, 0);
        this.setBlock(world, i + 3, j + 1, k + 13, Dungeons.purpleBrick, 0);
        this.setBlock(world, i + 3, j + 1, k + 14, Dungeons.purpleBrick, 0);
        this.setBlock(world, i + 3, j + 1, k + 15, Dungeons.purpleBrick, 0);
        this.setBlock(world, i + 3, j + 1, k + 16, Dungeons.purpleBrick, 0);
        this.setBlock(world, i + 3, j + 1, k + 17, Dungeons.purpleBrick, 0);
        this.setBlock(world, i + 3, j + 1, k + 18, Dungeons.purpleBrick, 0);
        this.setBlock(world, i + 3, j + 1, k + 19, Dungeons.purpleBrick, 0);
        this.setBlock(world, i + 3, j + 1, k + 20, Dungeons.purpleBrick, 0);
        this.setBlock(world, i + 3, j + 1, k + 21, Dungeons.purpleBrick, 0);
        this.setBlock(world, i + 3, j + 2, k + 3, Dungeons.purpleBrick, 0);
        this.setBlock(world, i + 3, j + 2, k + 4, Dungeons.purpleBrick, 0);
        this.setBlock(world, i + 3, j + 2, k + 5, Dungeons.purpleBrick, 0);
        this.setBlock(world, i + 3, j + 2, k + 6, Dungeons.purpleBrick, 0);
        this.setBlock(world, i + 3, j + 2, k + 7, Dungeons.purpleBrick, 0);
        this.setBlock(world, i + 3, j + 2, k + 8, Dungeons.purpleBrick, 0);
        this.setBlock(world, i + 3, j + 2, k + 9, Dungeons.purpleBrick, 0);
        this.setBlock(world, i + 3, j + 2, k + 10, Dungeons.purpleBrick, 0);
        this.setBlock(world, i + 3, j + 2, k + 11, Dungeons.purpleBrick, 0);
        this.setBlock(world, i + 3, j + 2, k + 12, Dungeons.purpleBrick, 0);
        this.setBlock(world, i + 3, j + 2, k + 13, Dungeons.purpleBrick, 0);
        this.setBlock(world, i + 3, j + 2, k + 14, Dungeons.purpleBrick, 0);
        this.setBlock(world, i + 3, j + 2, k + 15, Dungeons.purpleBrick, 0);
        this.setBlock(world, i + 3, j + 2, k + 16, Dungeons.purpleBrick, 0);
        this.setBlock(world, i + 3, j + 2, k + 17, Dungeons.purpleBrick, 0);
        this.setBlock(world, i + 3, j + 2, k + 18, Dungeons.purpleBrick, 0);
        this.setBlock(world, i + 3, j + 2, k + 19, Dungeons.purpleBrick, 0);
        this.setBlock(world, i + 3, j + 2, k + 20, Dungeons.purpleBrick, 0);
        this.setBlock(world, i + 3, j + 2, k + 21, Dungeons.purpleBrick, 0);
        this.setBlock(world, i + 3, j + 3, k + 4, Dungeons.carvedCrystalliumBrick, 0);
        this.setBlock(world, i + 3, j + 3, k + 5, Dungeons.carvedCrystalliumBrick, 0);
        this.setBlock(world, i + 3, j + 3, k + 6, Dungeons.purpleBrick, 0);
        this.setBlock(world, i + 3, j + 3, k + 7, Dungeons.purpleBrick, 0);
        this.setBlock(world, i + 3, j + 3, k + 8, Dungeons.purpleBrick, 0);
        this.setBlock(world, i + 3, j + 3, k + 9, Dungeons.purpleBrick, 0);
        this.setBlock(world, i + 3, j + 3, k + 10, Dungeons.purpleBrick, 0);
        this.setBlock(world, i + 3, j + 3, k + 11, Dungeons.purpleBrick, 0);
        this.setBlock(world, i + 3, j + 3, k + 13, Dungeons.purpleBrick, 0);
        this.setBlock(world, i + 3, j + 3, k + 14, Dungeons.purpleBrick, 0);
        this.setBlock(world, i + 3, j + 3, k + 15, Dungeons.purpleBrick, 0);
        this.setBlock(world, i + 3, j + 3, k + 16, Dungeons.purpleBrick, 0);
        this.setBlock(world, i + 3, j + 3, k + 17, Dungeons.purpleBrick, 0);
        this.setBlock(world, i + 3, j + 3, k + 18, Dungeons.purpleBrick, 0);
        this.setBlock(world, i + 3, j + 3, k + 19, Dungeons.carvedCrystalliumBrick, 0);
        this.setBlock(world, i + 3, j + 3, k + 20, Dungeons.carvedCrystalliumBrick, 0);
        this.setBlock(world, i + 3, j + 4, k + 4, Dungeons.carvedCrystalliumBrick, 0);
        this.setBlock(world, i + 3, j + 4, k + 5, Dungeons.carvedCrystalliumBrick, 0);
        this.setBlock(world, i + 3, j + 4, k + 6, Dungeons.purpleBrick, 0);
        this.setBlock(world, i + 3, j + 4, k + 7, Dungeons.purpleBrick, 0);
        this.setBlock(world, i + 3, j + 4, k + 8, Dungeons.purpleBrick, 0);
        this.setBlock(world, i + 3, j + 4, k + 9, Dungeons.purpleBrick, 0);
        this.setBlock(world, i + 3, j + 4, k + 10, Dungeons.purpleBrick, 0);
        this.setBlock(world, i + 3, j + 4, k + 14, Dungeons.purpleBrick, 0);
        this.setBlock(world, i + 3, j + 4, k + 15, Dungeons.purpleBrick, 0);
        this.setBlock(world, i + 3, j + 4, k + 16, Dungeons.purpleBrick, 0);
        this.setBlock(world, i + 3, j + 4, k + 17, Dungeons.purpleBrick, 0);
        this.setBlock(world, i + 3, j + 4, k + 18, Dungeons.purpleBrick, 0);
        this.setBlock(world, i + 3, j + 4, k + 19, Dungeons.carvedCrystalliumBrick, 0);
        this.setBlock(world, i + 3, j + 4, k + 20, Dungeons.carvedCrystalliumBrick, 0);
        this.setBlock(world, i + 3, j + 5, k + 4, Dungeons.carvedCrystalliumBrick, 0);
        this.setBlock(world, i + 3, j + 5, k + 5, Dungeons.carvedCrystalliumBrick, 0);
        this.setBlock(world, i + 3, j + 5, k + 6, Dungeons.purpleBrick, 0);
        this.setBlock(world, i + 3, j + 5, k + 7, Dungeons.purpleBrick, 0);
        this.setBlock(world, i + 3, j + 5, k + 8, Dungeons.purpleBrick, 0);
        this.setBlock(world, i + 3, j + 5, k + 9, Dungeons.purpleBrick, 0);
        this.setBlock(world, i + 3, j + 5, k + 15, Dungeons.purpleBrick, 0);
        this.setBlock(world, i + 3, j + 5, k + 16, Dungeons.purpleBrick, 0);
        this.setBlock(world, i + 3, j + 5, k + 17, Dungeons.purpleBrick, 0);
        this.setBlock(world, i + 3, j + 5, k + 18, Dungeons.purpleBrick, 0);
        this.setBlock(world, i + 3, j + 5, k + 19, Dungeons.carvedCrystalliumBrick, 0);
        this.setBlock(world, i + 3, j + 5, k + 20, Dungeons.carvedCrystalliumBrick, 0);
        this.setBlock(world, i + 3, j + 6, k + 4, Dungeons.carvedCrystalliumBrick, 0);
        this.setBlock(world, i + 3, j + 6, k + 5, Dungeons.carvedCrystalliumBrick, 0);
        this.setBlock(world, i + 3, j + 6, k + 6, Dungeons.purpleBrick, 0);
        this.setBlock(world, i + 3, j + 6, k + 7, Dungeons.purpleBrick, 0);
        this.setBlock(world, i + 3, j + 6, k + 8, Dungeons.purpleBrick, 0);
        this.setBlock(world, i + 3, j + 6, k + 9, Dungeons.purpleBrick, 0);
        this.setBlock(world, i + 3, j + 6, k + 10, Dungeons.purpleBrick, 0);
        this.setBlock(world, i + 3, j + 6, k + 14, Dungeons.purpleBrick, 0);
        this.setBlock(world, i + 3, j + 6, k + 15, Dungeons.purpleBrick, 0);
        this.setBlock(world, i + 3, j + 6, k + 16, Dungeons.purpleBrick, 0);
        this.setBlock(world, i + 3, j + 6, k + 17, Dungeons.purpleBrick, 0);
        this.setBlock(world, i + 3, j + 6, k + 18, Dungeons.carvedCrystalliumBrick, 0);
        this.setBlock(world, i + 3, j + 6, k + 19, Dungeons.carvedCrystalliumBrick, 0);
        this.setBlock(world, i + 3, j + 6, k + 20, Dungeons.carvedCrystalliumBrick, 0);
        this.setBlock(world, i + 3, j + 7, k + 4, Dungeons.carvedCrystalliumBrick, 0);
        this.setBlock(world, i + 3, j + 7, k + 5, Dungeons.carvedCrystalliumBrick, 0);
        this.setBlock(world, i + 3, j + 7, k + 6, Dungeons.purpleBrick, 0);
        this.setBlock(world, i + 3, j + 7, k + 7, Dungeons.purpleBrick, 0);
        this.setBlock(world, i + 3, j + 7, k + 8, Dungeons.purpleBrick, 0);
        this.setBlock(world, i + 3, j + 7, k + 9, Dungeons.purpleBrick, 0);
        this.setBlock(world, i + 3, j + 7, k + 10, Dungeons.purpleBrick, 0);
        this.setBlock(world, i + 3, j + 7, k + 11, Dungeons.purpleBrick, 0);
        this.setBlock(world, i + 3, j + 7, k + 13, Dungeons.purpleBrick, 0);
        this.setBlock(world, i + 3, j + 7, k + 14, Dungeons.purpleBrick, 0);
        this.setBlock(world, i + 3, j + 7, k + 15, Dungeons.purpleBrick, 0);
        this.setBlock(world, i + 3, j + 7, k + 16, Dungeons.purpleBrick, 0);
        this.setBlock(world, i + 3, j + 7, k + 17, Dungeons.purpleBrick, 0);
        this.setBlock(world, i + 3, j + 7, k + 18, Dungeons.purpleBrick, 0);
        this.setBlock(world, i + 3, j + 7, k + 19, Dungeons.carvedCrystalliumBrick, 0);
        this.setBlock(world, i + 3, j + 7, k + 20, Dungeons.carvedCrystalliumBrick, 0);
        this.setBlock(world, i + 3, j + 8, k + 4, Dungeons.carvedCrystalliumBrick, 0);
        this.setBlock(world, i + 3, j + 8, k + 5, Dungeons.carvedCrystalliumBrick, 0);
        this.setBlock(world, i + 3, j + 8, k + 6, Dungeons.purpleBrick, 0);
        this.setBlock(world, i + 3, j + 8, k + 7, Dungeons.purpleBrick, 0);
        this.setBlock(world, i + 3, j + 8, k + 8, Dungeons.purpleBrick, 0);
        this.setBlock(world, i + 3, j + 8, k + 9, Dungeons.purpleBrick, 0);
        this.setBlock(world, i + 3, j + 8, k + 10, Dungeons.purpleBrick, 0);
        this.setBlock(world, i + 3, j + 8, k + 11, Dungeons.purpleBrick, 0);
        this.setBlock(world, i + 3, j + 8, k + 12, Dungeons.purpleBrick, 0);
        this.setBlock(world, i + 3, j + 8, k + 13, Dungeons.purpleBrick, 0);
        this.setBlock(world, i + 3, j + 8, k + 14, Dungeons.purpleBrick, 0);
        this.setBlock(world, i + 3, j + 8, k + 15, Dungeons.purpleBrick, 0);
        this.setBlock(world, i + 3, j + 8, k + 16, Dungeons.purpleBrick, 0);
        this.setBlock(world, i + 3, j + 8, k + 17, Dungeons.purpleBrick, 0);
        this.setBlock(world, i + 3, j + 8, k + 18, Dungeons.purpleBrick, 0);
        this.setBlock(world, i + 3, j + 8, k + 19, Dungeons.carvedCrystalliumBrick, 0);
        this.setBlock(world, i + 3, j + 8, k + 20, Dungeons.carvedCrystalliumBrick, 0);
        this.setBlock(world, i + 3, j + 9, k + 4, Dungeons.carvedCrystalliumBrick, 0);
        this.setBlock(world, i + 3, j + 9, k + 5, Dungeons.carvedCrystalliumBrick, 0);
        this.setBlock(world, i + 3, j + 9, k + 19, Dungeons.carvedCrystalliumBrick, 0);
        this.setBlock(world, i + 3, j + 9, k + 20, Dungeons.carvedCrystalliumBrick, 0);
        this.setBlock(world, i + 3, j + 10, k + 3, Dungeons.purpleBrick, 0);
        this.setBlock(world, i + 3, j + 10, k + 21, Dungeons.purpleBrick, 0);
        this.setBlock(world, i + 4, j, k + 3, Dungeons.purpleBrick, 0);
        this.setBlock(world, i + 4, j, k + 4, Dungeons.purpleBrick, 0);
        this.setBlock(world, i + 4, j, k + 5, Dungeons.purpleBrick, 0);
        this.setBlock(world, i + 4, j, k + 6, Dungeons.purpleBrick, 0);
        this.setBlock(world, i + 4, j, k + 7, Dungeons.purpleBrick, 0);
        this.setBlock(world, i + 4, j, k + 8, Dungeons.purpleBrick, 0);
        this.setBlock(world, i + 4, j, k + 9, Dungeons.purpleBrick, 0);
        this.setBlock(world, i + 4, j, k + 10, Dungeons.purpleBrick, 0);
        this.setBlock(world, i + 4, j, k + 11, Dungeons.purpleBrick, 0);
        this.setBlock(world, i + 4, j, k + 12, Dungeons.purpleBrick, 0);
        this.setBlock(world, i + 4, j, k + 13, Dungeons.purpleBrick, 0);
        this.setBlock(world, i + 4, j, k + 14, Dungeons.purpleBrick, 0);
        this.setBlock(world, i + 4, j, k + 15, Dungeons.purpleBrick, 0);
        this.setBlock(world, i + 4, j, k + 16, Dungeons.purpleBrick, 0);
        this.setBlock(world, i + 4, j, k + 17, Dungeons.purpleBrick, 0);
        this.setBlock(world, i + 4, j, k + 18, Dungeons.purpleBrick, 0);
        this.setBlock(world, i + 4, j, k + 19, Dungeons.purpleBrick, 0);
        this.setBlock(world, i + 4, j, k + 20, Dungeons.purpleBrick, 0);
        this.setBlock(world, i + 4, j, k + 21, Dungeons.purpleBrick, 0);
        this.setBlock(world, i + 4, j + 1, k + 3, Dungeons.purpleBrick, 0);
        this.setBlock(world, i + 4, j + 1, k + 4, Dungeons.purpleBrick, 0);
        this.setBlock(world, i + 4, j + 1, k + 5, Dungeons.purpleBrick, 0);
        this.setBlock(world, i + 4, j + 1, k + 6, Dungeons.purpleBrick, 0);
        this.setBlock(world, i + 4, j + 1, k + 7, Dungeons.purpleBrick, 0);
        this.setBlock(world, i + 4, j + 1, k + 8, Dungeons.purpleBrick, 0);
        this.setBlock(world, i + 4, j + 1, k + 9, Dungeons.purpleBrick, 0);
        this.setBlock(world, i + 4, j + 1, k + 10, Dungeons.purpleBrick, 0);
        this.setBlock(world, i + 4, j + 1, k + 11, Dungeons.purpleBrick, 0);
        this.setBlock(world, i + 4, j + 1, k + 12, Dungeons.purpleBrick, 0);
        this.setBlock(world, i + 4, j + 1, k + 13, Dungeons.purpleBrick, 0);
        this.setBlock(world, i + 4, j + 1, k + 14, Dungeons.purpleBrick, 0);
        this.setBlock(world, i + 4, j + 1, k + 15, Dungeons.purpleBrick, 0);
        this.setBlock(world, i + 4, j + 1, k + 16, Dungeons.purpleBrick, 0);
        this.setBlock(world, i + 4, j + 1, k + 17, Dungeons.purpleBrick, 0);
        this.setBlock(world, i + 4, j + 1, k + 18, Dungeons.purpleBrick, 0);
        this.setBlock(world, i + 4, j + 1, k + 19, Dungeons.purpleBrick, 0);
        this.setBlock(world, i + 4, j + 1, k + 20, Dungeons.purpleBrick, 0);
        this.setBlock(world, i + 4, j + 1, k + 21, Dungeons.purpleBrick, 0);
        this.setBlock(world, i + 4, j + 2, k + 3, Dungeons.purpleBrick, 0);
        this.setBlock(world, i + 4, j + 2, k + 4, Dungeons.purpleBrick, 0);
        this.setBlock(world, i + 4, j + 2, k + 5, Dungeons.purpleBrick, 0);
        this.setBlock(world, i + 4, j + 2, k + 6, Dungeons.purpleBrick, 0);
        this.setBlock(world, i + 4, j + 2, k + 7, Dungeons.purpleBrick, 0);
        this.setBlock(world, i + 4, j + 2, k + 8, Dungeons.purpleBrick, 0);
        this.setBlock(world, i + 4, j + 2, k + 9, Dungeons.purpleBrick, 0);
        this.setBlock(world, i + 4, j + 2, k + 10, Dungeons.purpleBrick, 0);
        this.setBlock(world, i + 4, j + 2, k + 11, Dungeons.purpleBrick, 0);
        this.setBlock(world, i + 4, j + 2, k + 12, Dungeons.purpleBrick, 0);
        this.setBlock(world, i + 4, j + 2, k + 13, Dungeons.purpleBrick, 0);
        this.setBlock(world, i + 4, j + 2, k + 14, Dungeons.purpleBrick, 0);
        this.setBlock(world, i + 4, j + 2, k + 15, Dungeons.purpleBrick, 0);
        this.setBlock(world, i + 4, j + 2, k + 16, Dungeons.purpleBrick, 0);
        this.setBlock(world, i + 4, j + 2, k + 17, Dungeons.purpleBrick, 0);
        this.setBlock(world, i + 4, j + 2, k + 18, Dungeons.purpleBrick, 0);
        this.setBlock(world, i + 4, j + 2, k + 19, Dungeons.purpleBrick, 0);
        this.setBlock(world, i + 4, j + 2, k + 20, Dungeons.purpleBrick, 0);
        this.setBlock(world, i + 4, j + 2, k + 21, Dungeons.purpleBrick, 0);
        this.setBlock(world, i + 4, j + 3, k + 3, Dungeons.purpleBrick, 0);
        this.setBlock(world, i + 4, j + 3, k + 4, Dungeons.carvedCrystalliumBrick, 0);
        this.setBlock(world, i + 4, j + 3, k + 5, Dungeons.carvedCrystalliumBrick, 0);
        this.setBlock(world, i + 4, j + 3, k + 19, Dungeons.carvedCrystalliumBrick, 0);
        this.setBlock(world, i + 4, j + 3, k + 20, Dungeons.carvedCrystalliumBrick, 0);
        this.setBlock(world, i + 4, j + 3, k + 21, Dungeons.purpleBrick, 0);
        this.setBlock(world, i + 4, j + 4, k + 4, Dungeons.carvedCrystalliumBrick, 0);
        this.setBlock(world, i + 4, j + 4, k + 5, Dungeons.carvedCrystalliumBrick, 0);
        this.setBlock(world, i + 4, j + 4, k + 19, Dungeons.carvedCrystalliumBrick, 0);
        this.setBlock(world, i + 4, j + 4, k + 20, Dungeons.carvedCrystalliumBrick, 0);
        this.setBlock(world, i + 4, j + 5, k + 4, Dungeons.carvedCrystalliumBrick, 0);
        this.setBlock(world, i + 4, j + 5, k + 5, Dungeons.carvedCrystalliumBrick, 0);
        this.setBlock(world, i + 4, j + 5, k + 6, Dungeons.carvedCrystalliumBrick, 0);
        this.setBlock(world, i + 4, j + 5, k + 18, Dungeons.carvedCrystalliumBrick, 0);
        this.setBlock(world, i + 4, j + 5, k + 19, Dungeons.carvedCrystalliumBrick, 0);
        this.setBlock(world, i + 4, j + 5, k + 20, Dungeons.carvedCrystalliumBrick, 0);
        this.setBlock(world, i + 4, j + 6, k + 4, Dungeons.carvedCrystalliumBrick, 0);
        this.setBlock(world, i + 4, j + 6, k + 5, Dungeons.carvedCrystalliumBrick, 0);
        this.setBlock(world, i + 4, j + 6, k + 6, Dungeons.crystalliumLamp, 0);
        this.setBlock(world, i + 4, j + 6, k + 18, Dungeons.crystalliumLamp, 0);
        this.setBlock(world, i + 4, j + 6, k + 19, Dungeons.carvedCrystalliumBrick, 0);
        this.setBlock(world, i + 4, j + 6, k + 20, Dungeons.carvedCrystalliumBrick, 0);
        this.setBlock(world, i + 4, j + 7, k + 4, Dungeons.carvedCrystalliumBrick, 0);
        this.setBlock(world, i + 4, j + 7, k + 5, Dungeons.carvedCrystalliumBrick, 0);
        this.setBlock(world, i + 4, j + 7, k + 6, Dungeons.carvedCrystalliumBrick, 0);
        this.setBlock(world, i + 4, j + 7, k + 18, Dungeons.carvedCrystalliumBrick, 0);
        this.setBlock(world, i + 4, j + 7, k + 19, Dungeons.carvedCrystalliumBrick, 0);
        this.setBlock(world, i + 4, j + 7, k + 20, Dungeons.carvedCrystalliumBrick, 0);
        this.setBlock(world, i + 4, j + 8, k + 4, Dungeons.carvedCrystalliumBrick, 0);
        this.setBlock(world, i + 4, j + 8, k + 5, Dungeons.carvedCrystalliumBrick, 0);
        this.setBlock(world, i + 4, j + 8, k + 19, Dungeons.carvedCrystalliumBrick, 0);
        this.setBlock(world, i + 4, j + 8, k + 20, Dungeons.carvedCrystalliumBrick, 0);
        this.setBlock(world, i + 4, j + 9, k + 3, Dungeons.purpleBrick, 0);
        this.setBlock(world, i + 4, j + 9, k + 4, Dungeons.carvedCrystalliumBrick, 0);
        this.setBlock(world, i + 4, j + 9, k + 5, Dungeons.carvedCrystalliumBrick, 0);
        this.setBlock(world, i + 4, j + 9, k + 6, Dungeons.purpleBrick, 0);
        this.setBlock(world, i + 4, j + 9, k + 7, Dungeons.purpleBrick, 0);
        this.setBlock(world, i + 4, j + 9, k + 8, Dungeons.purpleBrick, 0);
        this.setBlock(world, i + 4, j + 9, k + 9, Dungeons.purpleBrick, 0);
        this.setBlock(world, i + 4, j + 9, k + 10, Dungeons.purpleBrick, 0);
        this.setBlock(world, i + 4, j + 9, k + 11, Dungeons.purpleBrick, 0);
        this.setBlock(world, i + 4, j + 9, k + 12, Dungeons.purpleBrick, 0);
        this.setBlock(world, i + 4, j + 9, k + 13, Dungeons.purpleBrick, 0);
        this.setBlock(world, i + 4, j + 9, k + 14, Dungeons.purpleBrick, 0);
        this.setBlock(world, i + 4, j + 9, k + 15, Dungeons.purpleBrick, 0);
        this.setBlock(world, i + 4, j + 9, k + 16, Dungeons.purpleBrick, 0);
        this.setBlock(world, i + 4, j + 9, k + 17, Dungeons.purpleBrick, 0);
        this.setBlock(world, i + 4, j + 9, k + 18, Dungeons.purpleBrick, 0);
        this.setBlock(world, i + 4, j + 9, k + 19, Dungeons.carvedCrystalliumBrick, 0);
        this.setBlock(world, i + 4, j + 9, k + 20, Dungeons.carvedCrystalliumBrick, 0);
        this.setBlock(world, i + 4, j + 9, k + 21, Dungeons.purpleBrick, 0);
        this.setBlock(world, i + 5, j, k + 3, Dungeons.purpleBrick, 0);
        this.setBlock(world, i + 5, j, k + 4, Dungeons.purpleBrick, 0);
        this.setBlock(world, i + 5, j, k + 5, Dungeons.purpleBrick, 0);
        this.setBlock(world, i + 5, j, k + 6, Dungeons.purpleBrick, 0);
        this.setBlock(world, i + 5, j, k + 7, Dungeons.purpleBrick, 0);
        this.setBlock(world, i + 5, j, k + 8, Dungeons.purpleBrick, 0);
        this.setBlock(world, i + 5, j, k + 9, Dungeons.purpleBrick, 0);
        this.setBlock(world, i + 5, j, k + 10, Dungeons.purpleBrick, 0);
        this.setBlock(world, i + 5, j, k + 11, Dungeons.purpleBrick, 0);
        this.setBlock(world, i + 5, j, k + 12, Dungeons.purpleBrick, 0);
        this.setBlock(world, i + 5, j, k + 13, Dungeons.purpleBrick, 0);
        this.setBlock(world, i + 5, j, k + 14, Dungeons.purpleBrick, 0);
        this.setBlock(world, i + 5, j, k + 15, Dungeons.purpleBrick, 0);
        this.setBlock(world, i + 5, j, k + 16, Dungeons.purpleBrick, 0);
        this.setBlock(world, i + 5, j, k + 17, Dungeons.purpleBrick, 0);
        this.setBlock(world, i + 5, j, k + 18, Dungeons.purpleBrick, 0);
        this.setBlock(world, i + 5, j, k + 19, Dungeons.purpleBrick, 0);
        this.setBlock(world, i + 5, j, k + 20, Dungeons.purpleBrick, 0);
        this.setBlock(world, i + 5, j, k + 21, Dungeons.purpleBrick, 0);
        this.setBlock(world, i + 5, j + 1, k + 3, Dungeons.purpleBrick, 0);
        this.setBlock(world, i + 5, j + 1, k + 4, Dungeons.purpleBrick, 0);
        this.setBlock(world, i + 5, j + 1, k + 5, Dungeons.purpleBrick, 0);
        this.setBlock(world, i + 5, j + 1, k + 6, Dungeons.purpleBrick, 0);
        this.setBlock(world, i + 5, j + 1, k + 7, Dungeons.purpleBrick, 0);
        this.setBlock(world, i + 5, j + 1, k + 8, Dungeons.purpleBrick, 0);
        this.setBlock(world, i + 5, j + 1, k + 9, Dungeons.purpleBrick, 0);
        this.setBlock(world, i + 5, j + 1, k + 10, Dungeons.purpleBrick, 0);
        this.setBlock(world, i + 5, j + 1, k + 11, Dungeons.purpleBrick, 0);
        this.setBlock(world, i + 5, j + 1, k + 12, Dungeons.purpleBrick, 0);
        this.setBlock(world, i + 5, j + 1, k + 13, Dungeons.purpleBrick, 0);
        this.setBlock(world, i + 5, j + 1, k + 14, Dungeons.purpleBrick, 0);
        this.setBlock(world, i + 5, j + 1, k + 15, Dungeons.purpleBrick, 0);
        this.setBlock(world, i + 5, j + 1, k + 16, Dungeons.purpleBrick, 0);
        this.setBlock(world, i + 5, j + 1, k + 17, Dungeons.purpleBrick, 0);
        this.setBlock(world, i + 5, j + 1, k + 18, Dungeons.purpleBrick, 0);
        this.setBlock(world, i + 5, j + 1, k + 19, Dungeons.purpleBrick, 0);
        this.setBlock(world, i + 5, j + 1, k + 20, Dungeons.purpleBrick, 0);
        this.setBlock(world, i + 5, j + 1, k + 21, Dungeons.purpleBrick, 0);
        this.setBlock(world, i + 5, j + 2, k + 3, Dungeons.purpleBrick, 0);
        this.setBlock(world, i + 5, j + 2, k + 4, Dungeons.purpleBrick, 0);
        this.setBlock(world, i + 5, j + 2, k + 5, Dungeons.purpleBrick, 0);
        this.setBlock(world, i + 5, j + 2, k + 6, Dungeons.purpleBrick, 0);
        this.setBlock(world, i + 5, j + 2, k + 7, Dungeons.purpleBrick, 0);
        this.setBlock(world, i + 5, j + 2, k + 8, Dungeons.purpleBrick, 0);
        this.setBlock(world, i + 5, j + 2, k + 9, Dungeons.purpleBrick, 0);
        this.setBlock(world, i + 5, j + 2, k + 10, Dungeons.purpleBrick, 0);
        this.setBlock(world, i + 5, j + 2, k + 11, Dungeons.purpleBrick, 0);
        this.setBlock(world, i + 5, j + 2, k + 12, Dungeons.purpleBrick, 0);
        this.setBlock(world, i + 5, j + 2, k + 13, Dungeons.purpleBrick, 0);
        this.setBlock(world, i + 5, j + 2, k + 14, Dungeons.purpleBrick, 0);
        this.setBlock(world, i + 5, j + 2, k + 15, Dungeons.purpleBrick, 0);
        this.setBlock(world, i + 5, j + 2, k + 16, Dungeons.purpleBrick, 0);
        this.setBlock(world, i + 5, j + 2, k + 17, Dungeons.purpleBrick, 0);
        this.setBlock(world, i + 5, j + 2, k + 18, Dungeons.purpleBrick, 0);
        this.setBlock(world, i + 5, j + 2, k + 19, Dungeons.purpleBrick, 0);
        this.setBlock(world, i + 5, j + 2, k + 20, Dungeons.purpleBrick, 0);
        this.setBlock(world, i + 5, j + 2, k + 21, Dungeons.purpleBrick, 0);
        this.setBlock(world, i + 5, j + 3, k + 4, Dungeons.purpleBrick, 0);
        this.setBlock(world, i + 5, j + 3, k + 20, Dungeons.purpleBrick, 0);
        this.setBlock(world, i + 5, j + 4, k + 3, Dungeons.purpleBrick, 0);
        this.setBlock(world, i + 5, j + 4, k + 4, Dungeons.purpleBrick, 0);
        this.setBlock(world, i + 5, j + 4, k + 20, Dungeons.purpleBrick, 0);
        this.setBlock(world, i + 5, j + 4, k + 21, Dungeons.purpleBrick, 0);
        this.setBlock(world, i + 5, j + 5, k + 4, Dungeons.purpleBrick, 0);
        this.setBlock(world, i + 5, j + 5, k + 5, Dungeons.carvedCrystalliumBrick, 0);
        this.setBlock(world, i + 5, j + 5, k + 19, Dungeons.carvedCrystalliumBrick, 0);
        this.setBlock(world, i + 5, j + 5, k + 20, Dungeons.purpleBrick, 0);
        this.setBlock(world, i + 5, j + 6, k + 4, Dungeons.purpleBrick, 0);
        this.setBlock(world, i + 5, j + 6, k + 5, Dungeons.crystalliumLamp, 0);
        this.setBlock(world, i + 5, j + 6, k + 19, Dungeons.crystalliumLamp, 0);
        this.setBlock(world, i + 5, j + 6, k + 20, Dungeons.purpleBrick, 0);
        this.setBlock(world, i + 5, j + 7, k + 4, Dungeons.purpleBrick, 0);
        this.setBlock(world, i + 5, j + 7, k + 5, Dungeons.carvedCrystalliumBrick, 0);
        this.setBlock(world, i + 5, j + 7, k + 19, Dungeons.carvedCrystalliumBrick, 0);
        this.setBlock(world, i + 5, j + 7, k + 20, Dungeons.purpleBrick, 0);
        this.setBlock(world, i + 5, j + 8, k + 3, Dungeons.purpleBrick, 0);
        this.setBlock(world, i + 5, j + 8, k + 4, Dungeons.purpleBrick, 0);
        this.setBlock(world, i + 5, j + 8, k + 20, Dungeons.purpleBrick, 0);
        this.setBlock(world, i + 5, j + 8, k + 21, Dungeons.purpleBrick, 0);
        this.setBlock(world, i + 5, j + 9, k + 5, Dungeons.purpleBrick, 0);
        this.setBlock(world, i + 5, j + 9, k + 6, Dungeons.purpleBrick, 0);
        this.setBlock(world, i + 5, j + 9, k + 7, Dungeons.purpleBrick, 0);
        this.setBlock(world, i + 5, j + 9, k + 8, Dungeons.purpleBrick, 0);
        this.setBlock(world, i + 5, j + 9, k + 9, Dungeons.purpleBrick, 0);
        this.setBlock(world, i + 5, j + 9, k + 10, Dungeons.purpleBrick, 0);
        this.setBlock(world, i + 5, j + 9, k + 11, Dungeons.purpleBrick, 0);
        this.setBlock(world, i + 5, j + 9, k + 12, Dungeons.purpleBrick, 0);
        this.setBlock(world, i + 5, j + 9, k + 13, Dungeons.purpleBrick, 0);
        this.setBlock(world, i + 5, j + 9, k + 14, Dungeons.purpleBrick, 0);
        this.setBlock(world, i + 5, j + 9, k + 15, Dungeons.purpleBrick, 0);
        this.setBlock(world, i + 5, j + 9, k + 16, Dungeons.purpleBrick, 0);
        this.setBlock(world, i + 5, j + 9, k + 17, Dungeons.purpleBrick, 0);
        this.setBlock(world, i + 5, j + 9, k + 18, Dungeons.purpleBrick, 0);
        this.setBlock(world, i + 5, j + 9, k + 19, Dungeons.purpleBrick, 0);
        this.setBlock(world, i + 5, j + 15, k + 8, Dungeons.purpleBrick, 0);
        this.setBlock(world, i + 5, j + 15, k + 9, Dungeons.purpleBrick, 0);
        this.setBlock(world, i + 5, j + 15, k + 10, Dungeons.purpleBrick, 0);
        this.setBlock(world, i + 5, j + 15, k + 11, Dungeons.purpleBrick, 0);
        this.setBlock(world, i + 5, j + 15, k + 12, Dungeons.purpleBrick, 0);
        this.setBlock(world, i + 5, j + 15, k + 13, Dungeons.purpleBrick, 0);
        this.setBlock(world, i + 5, j + 15, k + 14, Dungeons.purpleBrick, 0);
        this.setBlock(world, i + 5, j + 15, k + 15, Dungeons.purpleBrick, 0);
        this.setBlock(world, i + 5, j + 15, k + 16, Dungeons.purpleBrick, 0);
        this.setBlock(world, i + 5, j + 16, k + 7, Dungeons.purpleBrick, 0);
        this.setBlock(world, i + 5, j + 16, k + 17, Dungeons.purpleBrick, 0);
        this.setBlock(world, i + 5, j + 17, k + 6, Dungeons.purpleBrick, 0);
        this.setBlock(world, i + 5, j + 17, k + 18, Dungeons.purpleBrick, 0);
        this.setBlock(world, i + 6, j, k + 3, Dungeons.purpleBrick, 0);
        this.setBlock(world, i + 6, j, k + 4, Dungeons.purpleBrick, 0);
        this.setBlock(world, i + 6, j, k + 5, Dungeons.purpleBrick, 0);
        this.setBlock(world, i + 6, j, k + 6, Dungeons.purpleBrick, 0);
        this.setBlock(world, i + 6, j, k + 7, Dungeons.purpleBrick, 0);
        this.setBlock(world, i + 6, j, k + 8, Dungeons.purpleBrick, 0);
        this.setBlock(world, i + 6, j, k + 9, Dungeons.purpleBrick, 0);
        this.setBlock(world, i + 6, j, k + 10, Dungeons.purpleBrick, 0);
        this.setBlock(world, i + 6, j, k + 11, Dungeons.purpleBrick, 0);
        this.setBlock(world, i + 6, j, k + 12, Dungeons.purpleBrick, 0);
        this.setBlock(world, i + 6, j, k + 13, Dungeons.purpleBrick, 0);
        this.setBlock(world, i + 6, j, k + 14, Dungeons.purpleBrick, 0);
        this.setBlock(world, i + 6, j, k + 15, Dungeons.purpleBrick, 0);
        this.setBlock(world, i + 6, j, k + 16, Dungeons.purpleBrick, 0);
        this.setBlock(world, i + 6, j, k + 17, Dungeons.purpleBrick, 0);
        this.setBlock(world, i + 6, j, k + 18, Dungeons.purpleBrick, 0);
        this.setBlock(world, i + 6, j, k + 19, Dungeons.purpleBrick, 0);
        this.setBlock(world, i + 6, j, k + 20, Dungeons.purpleBrick, 0);
        this.setBlock(world, i + 6, j, k + 21, Dungeons.purpleBrick, 0);
        this.setBlock(world, i + 6, j + 1, k + 3, Dungeons.purpleBrick, 0);
        this.setBlock(world, i + 6, j + 1, k + 4, Dungeons.purpleBrick, 0);
        this.setBlock(world, i + 6, j + 1, k + 5, Dungeons.purpleBrick, 0);
        this.setBlock(world, i + 6, j + 1, k + 6, Dungeons.purpleBrick, 0);
        this.setBlock(world, i + 6, j + 1, k + 7, Dungeons.purpleBrick, 0);
        this.setBlock(world, i + 6, j + 1, k + 8, Dungeons.purpleBrick, 0);
        this.setBlock(world, i + 6, j + 1, k + 9, Dungeons.purpleBrick, 0);
        this.setBlock(world, i + 6, j + 1, k + 10, Dungeons.purpleBrick, 0);
        this.setBlock(world, i + 6, j + 1, k + 11, Dungeons.purpleBrick, 0);
        this.setBlock(world, i + 6, j + 1, k + 12, Dungeons.purpleBrick, 0);
        this.setBlock(world, i + 6, j + 1, k + 13, Dungeons.purpleBrick, 0);
        this.setBlock(world, i + 6, j + 1, k + 14, Dungeons.purpleBrick, 0);
        this.setBlock(world, i + 6, j + 1, k + 15, Dungeons.purpleBrick, 0);
        this.setBlock(world, i + 6, j + 1, k + 16, Dungeons.purpleBrick, 0);
        this.setBlock(world, i + 6, j + 1, k + 17, Dungeons.purpleBrick, 0);
        this.setBlock(world, i + 6, j + 1, k + 18, Dungeons.purpleBrick, 0);
        this.setBlock(world, i + 6, j + 1, k + 19, Dungeons.purpleBrick, 0);
        this.setBlock(world, i + 6, j + 1, k + 20, Dungeons.purpleBrick, 0);
        this.setBlock(world, i + 6, j + 1, k + 21, Dungeons.purpleBrick, 0);
        this.setBlock(world, i + 6, j + 2, k + 3, Dungeons.purpleBrick, 0);
        this.setBlock(world, i + 6, j + 2, k + 4, Dungeons.purpleBrick, 0);
        this.setBlock(world, i + 6, j + 2, k + 5, Dungeons.purpleBrick, 0);
        this.setBlock(world, i + 6, j + 2, k + 6, Dungeons.purpleBrick, 0);
        this.setBlock(world, i + 6, j + 2, k + 7, Dungeons.purpleBrick, 0);
        this.setBlock(world, i + 6, j + 2, k + 8, Dungeons.purpleBrick, 0);
        this.setBlock(world, i + 6, j + 2, k + 9, Dungeons.purpleBrick, 0);
        this.setBlock(world, i + 6, j + 2, k + 10, Dungeons.purpleBrick, 0);
        this.setBlock(world, i + 6, j + 2, k + 11, Dungeons.purpleBrick, 0);
        this.setBlock(world, i + 6, j + 2, k + 12, Dungeons.purpleBrick, 0);
        this.setBlock(world, i + 6, j + 2, k + 13, Dungeons.purpleBrick, 0);
        this.setBlock(world, i + 6, j + 2, k + 14, Dungeons.purpleBrick, 0);
        this.setBlock(world, i + 6, j + 2, k + 15, Dungeons.purpleBrick, 0);
        this.setBlock(world, i + 6, j + 2, k + 16, Dungeons.purpleBrick, 0);
        this.setBlock(world, i + 6, j + 2, k + 17, Dungeons.purpleBrick, 0);
        this.setBlock(world, i + 6, j + 2, k + 18, Dungeons.purpleBrick, 0);
        this.setBlock(world, i + 6, j + 2, k + 19, Dungeons.purpleBrick, 0);
        this.setBlock(world, i + 6, j + 2, k + 20, Dungeons.purpleBrick, 0);
        this.setBlock(world, i + 6, j + 2, k + 21, Dungeons.purpleBrick, 0);
        this.setBlock(world, i + 6, j + 3, k + 4, Dungeons.purpleBrick, 0);
        Dungeons.spawner(world, i + 6, j + 3, k + 7, 14, 2);
        this.setBlock(world, i + 6, j + 3, k + 12, Dungeons.carvedCrystalliumBrick, 0);
        this.setBlock(world, i + 6, j + 3, k + 20, Dungeons.purpleBrick, 0);
        this.setBlock(world, i + 6, j + 4, k + 4, Dungeons.purpleBrick, 0);
        this.setBlock(world, i + 6, j + 4, k + 12, Dungeons.crystalliumLamp, 0);
        this.setBlock(world, i + 6, j + 4, k + 20, Dungeons.purpleBrick, 0);
        this.setBlock(world, i + 6, j + 5, k + 4, Dungeons.purpleBrick, 0);
        this.setBlock(world, i + 6, j + 5, k + 20, Dungeons.purpleBrick, 0);
        this.setBlock(world, i + 6, j + 6, k + 4, Dungeons.purpleBrick, 0);
        this.setBlock(world, i + 6, j + 6, k + 20, Dungeons.purpleBrick, 0);
        this.setBlock(world, i + 6, j + 7, k + 4, Dungeons.purpleBrick, 0);
        this.setBlock(world, i + 6, j + 7, k + 20, Dungeons.purpleBrick, 0);
        this.setBlock(world, i + 6, j + 8, k + 3, Dungeons.purpleBrick, 0);
        this.setBlock(world, i + 6, j + 8, k + 4, Dungeons.purpleBrick, 0);
        this.setBlock(world, i + 6, j + 8, k + 20, Dungeons.purpleBrick, 0);
        this.setBlock(world, i + 6, j + 8, k + 21, Dungeons.purpleBrick, 0);
        this.setBlock(world, i + 6, j + 9, k + 5, Dungeons.purpleBrick, 0);
        this.setBlock(world, i + 6, j + 9, k + 6, Dungeons.purpleBrick, 0);
        this.setBlock(world, i + 6, j + 9, k + 7, Dungeons.purpleBrick, 0);
        this.setBlock(world, i + 6, j + 9, k + 8, Dungeons.purpleBrick, 0);
        this.setBlock(world, i + 6, j + 9, k + 9, Dungeons.purpleBrick, 0);
        this.setBlock(world, i + 6, j + 9, k + 10, Dungeons.purpleBrick, 0);
        this.setBlock(world, i + 6, j + 9, k + 11, Dungeons.purpleBrick, 0);
        this.setBlock(world, i + 6, j + 9, k + 12, Dungeons.purpleBrick, 0);
        this.setBlock(world, i + 6, j + 9, k + 13, Dungeons.purpleBrick, 0);
        this.setBlock(world, i + 6, j + 9, k + 14, Dungeons.purpleBrick, 0);
        this.setBlock(world, i + 6, j + 9, k + 15, Dungeons.purpleBrick, 0);
        this.setBlock(world, i + 6, j + 9, k + 16, Dungeons.purpleBrick, 0);
        this.setBlock(world, i + 6, j + 9, k + 17, Dungeons.purpleBrick, 0);
        this.setBlock(world, i + 6, j + 9, k + 18, Dungeons.purpleBrick, 0);
        this.setBlock(world, i + 6, j + 9, k + 19, Dungeons.purpleBrick, 0);
        this.setBlock(world, i + 6, j + 10, k + 7, Dungeons.carvedCrystalliumBrick, 0);
        this.setBlock(world, i + 6, j + 10, k + 8, Dungeons.purpleBrick, 0);
        this.setBlock(world, i + 6, j + 10, k + 9, Dungeons.purpleBrick, 0);
        this.setBlock(world, i + 6, j + 10, k + 10, Dungeons.purpleBrick, 0);
        this.setBlock(world, i + 6, j + 10, k + 11, Dungeons.purpleBrick, 0);
        this.setBlock(world, i + 6, j + 10, k + 13, Dungeons.purpleBrick, 0);
        this.setBlock(world, i + 6, j + 10, k + 14, Dungeons.purpleBrick, 0);
        this.setBlock(world, i + 6, j + 10, k + 15, Dungeons.purpleBrick, 0);
        this.setBlock(world, i + 6, j + 10, k + 16, Dungeons.purpleBrick, 0);
        this.setBlock(world, i + 6, j + 10, k + 17, Dungeons.carvedCrystalliumBrick, 0);
        this.setBlock(world, i + 6, j + 11, k + 7, Dungeons.carvedCrystalliumBrick, 0);
        this.setBlock(world, i + 6, j + 11, k + 8, Dungeons.purpleBrick, 0);
        this.setBlock(world, i + 6, j + 11, k + 9, Dungeons.purpleBrick, 0);
        this.setBlock(world, i + 6, j + 11, k + 10, Dungeons.purpleBrick, 0);
        this.setBlock(world, i + 6, j + 11, k + 14, Dungeons.purpleBrick, 0);
        this.setBlock(world, i + 6, j + 11, k + 15, Dungeons.purpleBrick, 0);
        this.setBlock(world, i + 6, j + 11, k + 16, Dungeons.purpleBrick, 0);
        this.setBlock(world, i + 6, j + 11, k + 17, Dungeons.carvedCrystalliumBrick, 0);
        this.setBlock(world, i + 6, j + 12, k + 7, Dungeons.carvedCrystalliumBrick, 0);
        this.setBlock(world, i + 6, j + 12, k + 8, Dungeons.purpleBrick, 0);
        this.setBlock(world, i + 6, j + 12, k + 9, Dungeons.purpleBrick, 0);
        this.setBlock(world, i + 6, j + 12, k + 15, Dungeons.purpleBrick, 0);
        this.setBlock(world, i + 6, j + 12, k + 16, Dungeons.purpleBrick, 0);
        this.setBlock(world, i + 6, j + 12, k + 17, Dungeons.carvedCrystalliumBrick, 0);
        this.setBlock(world, i + 6, j + 13, k + 7, Dungeons.carvedCrystalliumBrick, 0);
        this.setBlock(world, i + 6, j + 13, k + 8, Dungeons.purpleBrick, 0);
        this.setBlock(world, i + 6, j + 13, k + 9, Dungeons.purpleBrick, 0);
        this.setBlock(world, i + 6, j + 13, k + 10, Dungeons.purpleBrick, 0);
        this.setBlock(world, i + 6, j + 13, k + 14, Dungeons.purpleBrick, 0);
        this.setBlock(world, i + 6, j + 13, k + 15, Dungeons.purpleBrick, 0);
        this.setBlock(world, i + 6, j + 13, k + 16, Dungeons.purpleBrick, 0);
        this.setBlock(world, i + 6, j + 13, k + 17, Dungeons.carvedCrystalliumBrick, 0);
        this.setBlock(world, i + 6, j + 14, k + 7, Dungeons.carvedCrystalliumBrick, 0);
        this.setBlock(world, i + 6, j + 14, k + 8, Dungeons.purpleBrick, 0);
        this.setBlock(world, i + 6, j + 14, k + 9, Dungeons.purpleBrick, 0);
        this.setBlock(world, i + 6, j + 14, k + 10, Dungeons.purpleBrick, 0);
        this.setBlock(world, i + 6, j + 14, k + 11, Dungeons.purpleBrick, 0);
        this.setBlock(world, i + 6, j + 14, k + 13, Dungeons.purpleBrick, 0);
        this.setBlock(world, i + 6, j + 14, k + 14, Dungeons.purpleBrick, 0);
        this.setBlock(world, i + 6, j + 14, k + 15, Dungeons.purpleBrick, 0);
        this.setBlock(world, i + 6, j + 14, k + 16, Dungeons.purpleBrick, 0);
        this.setBlock(world, i + 6, j + 14, k + 17, Dungeons.carvedCrystalliumBrick, 0);
        this.setBlock(world, i + 6, j + 15, k + 7, Dungeons.carvedCrystalliumBrick, 0);
        this.setBlock(world, i + 6, j + 15, k + 8, Dungeons.purpleBrick, 0);
        this.setBlock(world, i + 6, j + 15, k + 9, Dungeons.purpleBrick, 0);
        this.setBlock(world, i + 6, j + 15, k + 10, Dungeons.purpleBrick, 0);
        this.setBlock(world, i + 6, j + 15, k + 11, Dungeons.purpleBrick, 0);
        this.setBlock(world, i + 6, j + 15, k + 12, Dungeons.purpleBrick, 0);
        this.setBlock(world, i + 6, j + 15, k + 13, Dungeons.purpleBrick, 0);
        this.setBlock(world, i + 6, j + 15, k + 14, Dungeons.purpleBrick, 0);
        this.setBlock(world, i + 6, j + 15, k + 15, Dungeons.purpleBrick, 0);
        this.setBlock(world, i + 6, j + 15, k + 16, Dungeons.purpleBrick, 0);
        this.setBlock(world, i + 6, j + 15, k + 17, Dungeons.carvedCrystalliumBrick, 0);
        this.setBlock(world, i + 6, j + 16, k + 6, Dungeons.purpleBrick, 0);
        this.setBlock(world, i + 6, j + 16, k + 7, Dungeons.carvedCrystalliumBrick, 0);
        this.setBlock(world, i + 6, j + 16, k + 17, Dungeons.carvedCrystalliumBrick, 0);
        this.setBlock(world, i + 6, j + 16, k + 18, Dungeons.purpleBrick, 0);
        this.setBlock(world, i + 7, j, k + 3, Dungeons.purpleBrick, 0);
        this.setBlock(world, i + 7, j, k + 4, Dungeons.purpleBrick, 0);
        this.setBlock(world, i + 7, j, k + 5, Dungeons.purpleBrick, 0);
        this.setBlock(world, i + 7, j, k + 6, Dungeons.purpleBrick, 0);
        this.setBlock(world, i + 7, j, k + 7, Dungeons.purpleBrick, 0);
        this.setBlock(world, i + 7, j, k + 8, Dungeons.purpleBrick, 0);
        this.setBlock(world, i + 7, j, k + 9, Dungeons.purpleBrick, 0);
        this.setBlock(world, i + 7, j, k + 10, Dungeons.purpleBrick, 0);
        this.setBlock(world, i + 7, j, k + 11, Dungeons.purpleBrick, 0);
        this.setBlock(world, i + 7, j, k + 12, Dungeons.purpleBrick, 0);
        this.setBlock(world, i + 7, j, k + 13, Dungeons.purpleBrick, 0);
        this.setBlock(world, i + 7, j, k + 14, Dungeons.purpleBrick, 0);
        this.setBlock(world, i + 7, j, k + 15, Dungeons.purpleBrick, 0);
        this.setBlock(world, i + 7, j, k + 16, Dungeons.purpleBrick, 0);
        this.setBlock(world, i + 7, j, k + 17, Dungeons.purpleBrick, 0);
        this.setBlock(world, i + 7, j, k + 18, Dungeons.purpleBrick, 0);
        this.setBlock(world, i + 7, j, k + 19, Dungeons.purpleBrick, 0);
        this.setBlock(world, i + 7, j, k + 20, Dungeons.purpleBrick, 0);
        this.setBlock(world, i + 7, j, k + 21, Dungeons.purpleBrick, 0);
        this.setBlock(world, i + 7, j + 1, k + 3, Dungeons.purpleBrick, 0);
        this.setBlock(world, i + 7, j + 1, k + 4, Dungeons.purpleBrick, 0);
        this.setBlock(world, i + 7, j + 1, k + 5, Dungeons.purpleBrick, 0);
        this.setBlock(world, i + 7, j + 1, k + 6, Dungeons.purpleBrick, 0);
        this.setBlock(world, i + 7, j + 1, k + 7, Dungeons.purpleBrick, 0);
        this.setBlock(world, i + 7, j + 1, k + 8, Dungeons.purpleBrick, 0);
        this.setBlock(world, i + 7, j + 1, k + 9, Dungeons.purpleBrick, 0);
        this.setBlock(world, i + 7, j + 1, k + 10, Dungeons.purpleBrick, 0);
        this.setBlock(world, i + 7, j + 1, k + 11, Dungeons.purpleBrick, 0);
        this.setBlock(world, i + 7, j + 1, k + 12, Dungeons.purpleBrick, 0);
        this.setBlock(world, i + 7, j + 1, k + 13, Dungeons.purpleBrick, 0);
        this.setBlock(world, i + 7, j + 1, k + 14, Dungeons.purpleBrick, 0);
        this.setBlock(world, i + 7, j + 1, k + 15, Dungeons.purpleBrick, 0);
        this.setBlock(world, i + 7, j + 1, k + 16, Dungeons.purpleBrick, 0);
        this.setBlock(world, i + 7, j + 1, k + 17, Dungeons.purpleBrick, 0);
        this.setBlock(world, i + 7, j + 1, k + 18, Dungeons.purpleBrick, 0);
        this.setBlock(world, i + 7, j + 1, k + 19, Dungeons.purpleBrick, 0);
        this.setBlock(world, i + 7, j + 1, k + 20, Dungeons.purpleBrick, 0);
        this.setBlock(world, i + 7, j + 1, k + 21, Dungeons.purpleBrick, 0);
        this.setBlock(world, i + 7, j + 2, k + 3, Dungeons.purpleBrick, 0);
        this.setBlock(world, i + 7, j + 2, k + 4, Dungeons.purpleBrick, 0);
        this.setBlock(world, i + 7, j + 2, k + 5, Dungeons.purpleBrick, 0);
        this.setBlock(world, i + 7, j + 2, k + 6, Dungeons.purpleBrick, 0);
        this.setBlock(world, i + 7, j + 2, k + 7, Dungeons.purpleBrick, 0);
        this.setBlock(world, i + 7, j + 2, k + 8, Dungeons.purpleBrick, 0);
        this.setBlock(world, i + 7, j + 2, k + 9, Dungeons.purpleBrick, 0);
        this.setBlock(world, i + 7, j + 2, k + 10, Dungeons.purpleBrick, 0);
        this.setBlock(world, i + 7, j + 2, k + 11, Dungeons.purpleBrick, 0);
        this.setBlock(world, i + 7, j + 2, k + 12, Dungeons.purpleBrick, 0);
        this.setBlock(world, i + 7, j + 2, k + 13, Dungeons.purpleBrick, 0);
        this.setBlock(world, i + 7, j + 2, k + 14, Dungeons.purpleBrick, 0);
        this.setBlock(world, i + 7, j + 2, k + 15, Dungeons.purpleBrick, 0);
        this.setBlock(world, i + 7, j + 2, k + 16, Dungeons.purpleBrick, 0);
        this.setBlock(world, i + 7, j + 2, k + 17, Dungeons.purpleBrick, 0);
        this.setBlock(world, i + 7, j + 2, k + 18, Dungeons.purpleBrick, 0);
        this.setBlock(world, i + 7, j + 2, k + 19, Dungeons.purpleBrick, 0);
        this.setBlock(world, i + 7, j + 2, k + 20, Dungeons.purpleBrick, 0);
        this.setBlock(world, i + 7, j + 2, k + 21, Dungeons.purpleBrick, 0);
        this.setBlock(world, i + 7, j + 3, k + 4, Dungeons.purpleBrick, 0);
        this.setBlock(world, i + 7, j + 3, k + 20, Dungeons.purpleBrick, 0);
        this.setBlock(world, i + 7, j + 4, k + 4, Dungeons.purpleBrick, 0);
        this.setBlock(world, i + 7, j + 4, k + 20, Dungeons.purpleBrick, 0);
        this.setBlock(world, i + 7, j + 5, k + 4, Dungeons.purpleBrick, 0);
        this.setBlock(world, i + 7, j + 5, k + 20, Dungeons.purpleBrick, 0);
        this.setBlock(world, i + 7, j + 6, k + 4, Dungeons.purpleBrick, 0);
        this.setBlock(world, i + 7, j + 6, k + 20, Dungeons.purpleBrick, 0);
        this.setBlock(world, i + 7, j + 7, k + 4, Dungeons.purpleBrick, 0);
        this.setBlock(world, i + 7, j + 7, k + 20, Dungeons.purpleBrick, 0);
        this.setBlock(world, i + 7, j + 8, k + 3, Dungeons.purpleBrick, 0);
        this.setBlock(world, i + 7, j + 8, k + 4, Dungeons.purpleBrick, 0);
        this.setBlock(world, i + 7, j + 8, k + 20, Dungeons.purpleBrick, 0);
        this.setBlock(world, i + 7, j + 8, k + 21, Dungeons.purpleBrick, 0);
        this.setBlock(world, i + 7, j + 9, k + 5, Dungeons.purpleBrick, 0);
        this.setBlock(world, i + 7, j + 9, k + 6, Dungeons.purpleBrick, 0);
        this.setBlock(world, i + 7, j + 9, k + 7, Dungeons.purpleBrick, 0);
        this.setBlock(world, i + 7, j + 9, k + 8, Dungeons.purpleBrick, 0);
        this.setBlock(world, i + 7, j + 9, k + 9, Dungeons.purpleBrick, 0);
        this.setBlock(world, i + 7, j + 9, k + 10, Dungeons.purpleBrick, 0);
        this.setBlock(world, i + 7, j + 9, k + 11, Dungeons.purpleBrick, 0);
        this.setBlock(world, i + 7, j + 9, k + 12, Dungeons.purpleBrick, 0);
        this.setBlock(world, i + 7, j + 9, k + 13, Dungeons.purpleBrick, 0);
        this.setBlock(world, i + 7, j + 9, k + 14, Dungeons.purpleBrick, 0);
        this.setBlock(world, i + 7, j + 9, k + 15, Dungeons.purpleBrick, 0);
        this.setBlock(world, i + 7, j + 9, k + 16, Dungeons.purpleBrick, 0);
        this.setBlock(world, i + 7, j + 9, k + 17, Dungeons.purpleBrick, 0);
        this.setBlock(world, i + 7, j + 9, k + 18, Dungeons.purpleBrick, 0);
        this.setBlock(world, i + 7, j + 9, k + 19, Dungeons.purpleBrick, 0);
        this.setBlock(world, i + 7, j + 10, k + 7, Dungeons.purpleBrick, 0);
        this.setBlock(world, i + 7, j + 10, k + 17, Dungeons.purpleBrick, 0);
        this.setBlock(world, i + 7, j + 11, k + 7, Dungeons.purpleBrick, 0);
        this.setBlock(world, i + 7, j + 11, k + 17, Dungeons.purpleBrick, 0);
        this.setBlock(world, i + 7, j + 12, k + 7, Dungeons.purpleBrick, 0);
        this.setBlock(world, i + 7, j + 12, k + 17, Dungeons.purpleBrick, 0);
        this.setBlock(world, i + 7, j + 13, k + 7, Dungeons.purpleBrick, 0);
        this.setBlock(world, i + 7, j + 13, k + 17, Dungeons.purpleBrick, 0);
        this.setBlock(world, i + 7, j + 14, k + 7, Dungeons.purpleBrick, 0);
        this.setBlock(world, i + 7, j + 14, k + 17, Dungeons.purpleBrick, 0);
        this.setBlock(world, i + 7, j + 15, k + 6, Dungeons.purpleBrick, 0);
        this.setBlock(world, i + 7, j + 15, k + 7, Dungeons.purpleBrick, 0);
        this.setBlock(world, i + 7, j + 15, k + 16, Dungeons.purpleBrick, 0);
        this.setBlock(world, i + 7, j + 15, k + 17, Dungeons.purpleBrick, 0);
        this.setBlock(world, i + 7, j + 15, k + 18, Dungeons.purpleBrick, 0);
        this.setBlock(world, i + 7, j + 16, k + 8, Dungeons.purpleBrick, 0);
        this.setBlock(world, i + 7, j + 16, k + 9, Dungeons.purpleBrick, 0);
        this.setBlock(world, i + 7, j + 16, k + 10, Dungeons.purpleBrick, 0);
        this.setBlock(world, i + 7, j + 16, k + 11, Dungeons.purpleBrick, 0);
        this.setBlock(world, i + 7, j + 16, k + 12, Dungeons.purpleBrick, 0);
        this.setBlock(world, i + 7, j + 16, k + 13, Dungeons.purpleBrick, 0);
        this.setBlock(world, i + 7, j + 16, k + 14, Dungeons.purpleBrick, 0);
        this.setBlock(world, i + 7, j + 16, k + 15, Dungeons.purpleBrick, 0);
        this.setBlock(world, i + 7, j + 16, k + 16, Dungeons.purpleBrick, 0);
        this.setBlock(world, i + 7, j + 21, k + 9, Dungeons.purpleBrick, 0);
        this.setBlock(world, i + 7, j + 21, k + 10, Dungeons.purpleBrick, 0);
        this.setBlock(world, i + 7, j + 21, k + 11, Dungeons.purpleBrick, 0);
        this.setBlock(world, i + 7, j + 21, k + 12, Dungeons.purpleBrick, 0);
        this.setBlock(world, i + 7, j + 21, k + 13, Dungeons.purpleBrick, 0);
        this.setBlock(world, i + 7, j + 21, k + 14, Dungeons.purpleBrick, 0);
        this.setBlock(world, i + 7, j + 21, k + 15, Dungeons.purpleBrick, 0);
        this.setBlock(world, i + 7, j + 22, k + 8, Dungeons.purpleBrick, 0);
        this.setBlock(world, i + 7, j + 22, k + 16, Dungeons.purpleBrick, 0);
        this.setBlock(world, i + 8, j, k + 3, Dungeons.purpleBrick, 0);
        this.setBlock(world, i + 8, j, k + 4, Dungeons.purpleBrick, 0);
        this.setBlock(world, i + 8, j, k + 5, Dungeons.purpleBrick, 0);
        this.setBlock(world, i + 8, j, k + 6, Dungeons.purpleBrick, 0);
        this.setBlock(world, i + 8, j, k + 7, Dungeons.purpleBrick, 0);
        this.setBlock(world, i + 8, j, k + 8, Dungeons.purpleBrick, 0);
        this.setBlock(world, i + 8, j, k + 9, Dungeons.purpleBrick, 0);
        this.setBlock(world, i + 8, j, k + 10, Dungeons.purpleBrick, 0);
        this.setBlock(world, i + 8, j, k + 11, Dungeons.purpleBrick, 0);
        this.setBlock(world, i + 8, j, k + 12, Dungeons.purpleBrick, 0);
        this.setBlock(world, i + 8, j, k + 13, Dungeons.purpleBrick, 0);
        this.setBlock(world, i + 8, j, k + 14, Dungeons.purpleBrick, 0);
        this.setBlock(world, i + 8, j, k + 15, Dungeons.purpleBrick, 0);
        this.setBlock(world, i + 8, j, k + 16, Dungeons.purpleBrick, 0);
        this.setBlock(world, i + 8, j, k + 17, Dungeons.purpleBrick, 0);
        this.setBlock(world, i + 8, j, k + 18, Dungeons.purpleBrick, 0);
        this.setBlock(world, i + 8, j, k + 19, Dungeons.purpleBrick, 0);
        this.setBlock(world, i + 8, j, k + 20, Dungeons.purpleBrick, 0);
        this.setBlock(world, i + 8, j, k + 21, Dungeons.purpleBrick, 0);
        this.setBlock(world, i + 8, j + 1, k + 3, Dungeons.purpleBrick, 0);
        this.setBlock(world, i + 8, j + 1, k + 4, Dungeons.purpleBrick, 0);
        this.setBlock(world, i + 8, j + 1, k + 5, Dungeons.purpleBrick, 0);
        this.setBlock(world, i + 8, j + 1, k + 6, Dungeons.purpleBrick, 0);
        this.setBlock(world, i + 8, j + 1, k + 7, Dungeons.purpleBrick, 0);
        this.setBlock(world, i + 8, j + 1, k + 8, Dungeons.purpleBrick, 0);
        this.setBlock(world, i + 8, j + 1, k + 9, Dungeons.purpleBrick, 0);
        this.setBlock(world, i + 8, j + 1, k + 10, Dungeons.purpleBrick, 0);
        this.setBlock(world, i + 8, j + 1, k + 11, Dungeons.purpleBrick, 0);
        this.setBlock(world, i + 8, j + 1, k + 12, Dungeons.purpleBrick, 0);
        this.setBlock(world, i + 8, j + 1, k + 13, Dungeons.purpleBrick, 0);
        this.setBlock(world, i + 8, j + 1, k + 14, Dungeons.purpleBrick, 0);
        this.setBlock(world, i + 8, j + 1, k + 15, Dungeons.purpleBrick, 0);
        this.setBlock(world, i + 8, j + 1, k + 16, Dungeons.purpleBrick, 0);
        this.setBlock(world, i + 8, j + 1, k + 17, Dungeons.purpleBrick, 0);
        this.setBlock(world, i + 8, j + 1, k + 18, Dungeons.purpleBrick, 0);
        this.setBlock(world, i + 8, j + 1, k + 19, Dungeons.purpleBrick, 0);
        this.setBlock(world, i + 8, j + 1, k + 20, Dungeons.purpleBrick, 0);
        this.setBlock(world, i + 8, j + 1, k + 21, Dungeons.purpleBrick, 0);
        this.setBlock(world, i + 8, j + 2, k + 3, Dungeons.purpleBrick, 0);
        this.setBlock(world, i + 8, j + 2, k + 4, Dungeons.purpleBrick, 0);
        this.setBlock(world, i + 8, j + 2, k + 5, Dungeons.purpleBrick, 0);
        this.setBlock(world, i + 8, j + 2, k + 6, Dungeons.purpleBrick, 0);
        this.setBlock(world, i + 8, j + 2, k + 7, Dungeons.purpleBrick, 0);
        this.setBlock(world, i + 8, j + 2, k + 8, Dungeons.purpleBrick, 0);
        this.setBlock(world, i + 8, j + 2, k + 9, Dungeons.purpleBrick, 0);
        this.setBlock(world, i + 8, j + 2, k + 10, Dungeons.purpleBrick, 0);
        this.setBlock(world, i + 8, j + 2, k + 11, Dungeons.purpleBrick, 0);
        this.setBlock(world, i + 8, j + 2, k + 12, Dungeons.purpleBrick, 0);
        this.setBlock(world, i + 8, j + 2, k + 13, Dungeons.purpleBrick, 0);
        this.setBlock(world, i + 8, j + 2, k + 14, Dungeons.purpleBrick, 0);
        this.setBlock(world, i + 8, j + 2, k + 15, Dungeons.purpleBrick, 0);
        this.setBlock(world, i + 8, j + 2, k + 16, Dungeons.purpleBrick, 0);
        this.setBlock(world, i + 8, j + 2, k + 17, Dungeons.purpleBrick, 0);
        this.setBlock(world, i + 8, j + 2, k + 18, Dungeons.purpleBrick, 0);
        this.setBlock(world, i + 8, j + 2, k + 19, Dungeons.purpleBrick, 0);
        this.setBlock(world, i + 8, j + 2, k + 20, Dungeons.purpleBrick, 0);
        this.setBlock(world, i + 8, j + 2, k + 21, Dungeons.purpleBrick, 0);
        this.setBlock(world, i + 8, j + 3, k + 4, Dungeons.purpleBrick, 0);
        this.setBlock(world, i + 8, j + 3, k + 20, Dungeons.purpleBrick, 0);
        this.setBlock(world, i + 8, j + 4, k + 4, Dungeons.purpleBrick, 0);
        this.setBlock(world, i + 8, j + 4, k + 20, Dungeons.purpleBrick, 0);
        this.setBlock(world, i + 8, j + 5, k + 4, Dungeons.purpleBrick, 0);
        this.setBlock(world, i + 8, j + 5, k + 20, Dungeons.purpleBrick, 0);
        this.setBlock(world, i + 8, j + 6, k + 4, Dungeons.purpleBrick, 0);
        this.setBlock(world, i + 8, j + 6, k + 20, Dungeons.purpleBrick, 0);
        this.setBlock(world, i + 8, j + 7, k + 4, Dungeons.purpleBrick, 0);
        this.setBlock(world, i + 8, j + 7, k + 20, Dungeons.purpleBrick, 0);
        this.setBlock(world, i + 8, j + 8, k + 3, Dungeons.purpleBrick, 0);
        this.setBlock(world, i + 8, j + 8, k + 4, Dungeons.purpleBrick, 0);
        this.setBlock(world, i + 8, j + 8, k + 20, Dungeons.purpleBrick, 0);
        this.setBlock(world, i + 8, j + 8, k + 21, Dungeons.purpleBrick, 0);
        this.setBlock(world, i + 8, j + 9, k + 5, Dungeons.purpleBrick, 0);
        this.setBlock(world, i + 8, j + 9, k + 6, Dungeons.purpleBrick, 0);
        this.setBlock(world, i + 8, j + 9, k + 7, Dungeons.purpleBrick, 0);
        this.setBlock(world, i + 8, j + 9, k + 8, Dungeons.purpleBrick, 0);
        this.setBlock(world, i + 8, j + 9, k + 9, Dungeons.purpleBrick, 0);
        this.setBlock(world, i + 8, j + 9, k + 10, Dungeons.purpleBrick, 0);
        this.setBlock(world, i + 8, j + 9, k + 11, Dungeons.purpleBrick, 0);
        this.setBlock(world, i + 8, j + 9, k + 12, Dungeons.purpleBrick, 0);
        this.setBlock(world, i + 8, j + 9, k + 13, Dungeons.purpleBrick, 0);
        this.setBlock(world, i + 8, j + 9, k + 14, Dungeons.purpleBrick, 0);
        this.setBlock(world, i + 8, j + 9, k + 15, Dungeons.purpleBrick, 0);
        this.setBlock(world, i + 8, j + 9, k + 16, Dungeons.purpleBrick, 0);
        this.setBlock(world, i + 8, j + 9, k + 17, Dungeons.purpleBrick, 0);
        this.setBlock(world, i + 8, j + 9, k + 18, Dungeons.purpleBrick, 0);
        this.setBlock(world, i + 8, j + 9, k + 19, Dungeons.purpleBrick, 0);
        this.setBlock(world, i + 8, j + 10, k + 7, Dungeons.purpleBrick, 0);
        this.setBlock(world, i + 8, j + 10, k + 17, Dungeons.purpleBrick, 0);
        this.setBlock(world, i + 8, j + 11, k + 7, Dungeons.purpleBrick, 0);
        this.setBlock(world, i + 8, j + 11, k + 17, Dungeons.purpleBrick, 0);
        this.setBlock(world, i + 8, j + 12, k + 7, Dungeons.purpleBrick, 0);
        this.setBlock(world, i + 8, j + 12, k + 17, Dungeons.purpleBrick, 0);
        this.setBlock(world, i + 8, j + 13, k + 7, Dungeons.purpleBrick, 0);
        this.setBlock(world, i + 8, j + 13, k + 17, Dungeons.purpleBrick, 0);
        this.setBlock(world, i + 8, j + 14, k + 7, Dungeons.purpleBrick, 0);
        this.setBlock(world, i + 8, j + 14, k + 17, Dungeons.purpleBrick, 0);
        this.setBlock(world, i + 8, j + 15, k + 6, Dungeons.purpleBrick, 0);
        this.setBlock(world, i + 8, j + 15, k + 7, Dungeons.purpleBrick, 0);
        this.setBlock(world, i + 8, j + 15, k + 17, Dungeons.purpleBrick, 0);
        this.setBlock(world, i + 8, j + 15, k + 18, Dungeons.purpleBrick, 0);
        this.setBlock(world, i + 8, j + 16, k + 8, Dungeons.purpleBrick, 0);
        this.setBlock(world, i + 8, j + 16, k + 9, Dungeons.purpleBrick, 0);
        this.setBlock(world, i + 8, j + 16, k + 10, Dungeons.purpleBrick, 0);
        this.setBlock(world, i + 8, j + 16, k + 11, Dungeons.purpleBrick, 0);
        this.setBlock(world, i + 8, j + 16, k + 12, Dungeons.purpleBrick, 0);
        this.setBlock(world, i + 8, j + 16, k + 13, Dungeons.purpleBrick, 0);
        this.setBlock(world, i + 8, j + 16, k + 14, Dungeons.purpleBrick, 0);
        this.setBlock(world, i + 8, j + 16, k + 15, Dungeons.purpleBrick, 0);
        this.setBlock(world, i + 8, j + 16, k + 16, Dungeons.purpleBrick, 0);
        this.setBlock(world, i + 8, j + 17, k + 9, Dungeons.carvedCrystalliumBrick, 0);
        this.setBlock(world, i + 8, j + 17, k + 10, Dungeons.purpleBrick, 0);
        this.setBlock(world, i + 8, j + 17, k + 11, Dungeons.purpleBrick, 0);
        this.setBlock(world, i + 8, j + 17, k + 12, Dungeons.purpleBrick, 0);
        this.setBlock(world, i + 8, j + 17, k + 13, Dungeons.purpleBrick, 0);
        this.setBlock(world, i + 8, j + 17, k + 14, Dungeons.purpleBrick, 0);
        this.setBlock(world, i + 8, j + 17, k + 15, Dungeons.carvedCrystalliumBrick, 0);
        this.setBlock(world, i + 8, j + 18, k + 9, Dungeons.carvedCrystalliumBrick, 0);
        this.setBlock(world, i + 8, j + 18, k + 10, Dungeons.purpleBrick, 0);
        this.setBlock(world, i + 8, j + 18, k + 11, Dungeons.purpleBrick, 0);
        this.setBlock(world, i + 8, j + 18, k + 13, Dungeons.purpleBrick, 0);
        this.setBlock(world, i + 8, j + 18, k + 14, Dungeons.purpleBrick, 0);
        this.setBlock(world, i + 8, j + 18, k + 15, Dungeons.carvedCrystalliumBrick, 0);
        this.setBlock(world, i + 8, j + 19, k + 9, Dungeons.carvedCrystalliumBrick, 0);
        this.setBlock(world, i + 8, j + 19, k + 10, Dungeons.purpleBrick, 0);
        this.setBlock(world, i + 8, j + 19, k + 14, Dungeons.purpleBrick, 0);
        this.setBlock(world, i + 8, j + 19, k + 15, Dungeons.carvedCrystalliumBrick, 0);
        this.setBlock(world, i + 8, j + 20, k + 9, Dungeons.carvedCrystalliumBrick, 0);
        this.setBlock(world, i + 8, j + 20, k + 10, Dungeons.purpleBrick, 0);
        this.setBlock(world, i + 8, j + 20, k + 11, Dungeons.purpleBrick, 0);
        this.setBlock(world, i + 8, j + 20, k + 13, Dungeons.purpleBrick, 0);
        this.setBlock(world, i + 8, j + 20, k + 14, Dungeons.purpleBrick, 0);
        this.setBlock(world, i + 8, j + 20, k + 15, Dungeons.carvedCrystalliumBrick, 0);
        this.setBlock(world, i + 8, j + 21, k + 8, Dungeons.purpleBrick, 0);
        this.setBlock(world, i + 8, j + 21, k + 9, Dungeons.carvedCrystalliumBrick, 0);
        this.setBlock(world, i + 8, j + 21, k + 10, Dungeons.purpleBrick, 0);
        this.setBlock(world, i + 8, j + 21, k + 11, Dungeons.purpleBrick, 0);
        this.setBlock(world, i + 8, j + 21, k + 12, Dungeons.purpleBrick, 0);
        this.setBlock(world, i + 8, j + 21, k + 13, Dungeons.purpleBrick, 0);
        this.setBlock(world, i + 8, j + 21, k + 14, Dungeons.purpleBrick, 0);
        this.setBlock(world, i + 8, j + 21, k + 15, Dungeons.carvedCrystalliumBrick, 0);
        this.setBlock(world, i + 8, j + 21, k + 16, Dungeons.purpleBrick, 0);
        this.setBlock(world, i + 9, j, k + 3, Dungeons.purpleBrick, 0);
        this.setBlock(world, i + 9, j, k + 4, Dungeons.purpleBrick, 0);
        this.setBlock(world, i + 9, j, k + 5, Dungeons.purpleBrick, 0);
        this.setBlock(world, i + 9, j, k + 6, Dungeons.purpleBrick, 0);
        this.setBlock(world, i + 9, j, k + 7, Dungeons.purpleBrick, 0);
        this.setBlock(world, i + 9, j, k + 8, Dungeons.purpleBrick, 0);
        this.setBlock(world, i + 9, j, k + 9, Dungeons.purpleBrick, 0);
        this.setBlock(world, i + 9, j, k + 10, Dungeons.purpleBrick, 0);
        this.setBlock(world, i + 9, j, k + 11, Dungeons.purpleBrick, 0);
        this.setBlock(world, i + 9, j, k + 12, Dungeons.purpleBrick, 0);
        this.setBlock(world, i + 9, j, k + 13, Dungeons.purpleBrick, 0);
        this.setBlock(world, i + 9, j, k + 14, Dungeons.purpleBrick, 0);
        this.setBlock(world, i + 9, j, k + 15, Dungeons.purpleBrick, 0);
        this.setBlock(world, i + 9, j, k + 16, Dungeons.purpleBrick, 0);
        this.setBlock(world, i + 9, j, k + 17, Dungeons.purpleBrick, 0);
        this.setBlock(world, i + 9, j, k + 18, Dungeons.purpleBrick, 0);
        this.setBlock(world, i + 9, j, k + 19, Dungeons.purpleBrick, 0);
        this.setBlock(world, i + 9, j, k + 20, Dungeons.purpleBrick, 0);
        this.setBlock(world, i + 9, j, k + 21, Dungeons.purpleBrick, 0);
        this.setBlock(world, i + 9, j + 1, k + 3, Dungeons.purpleBrick, 0);
        this.setBlock(world, i + 9, j + 1, k + 4, Dungeons.purpleBrick, 0);
        this.setBlock(world, i + 9, j + 1, k + 5, Dungeons.purpleBrick, 0);
        this.setBlock(world, i + 9, j + 1, k + 6, Dungeons.purpleBrick, 0);
        this.setBlock(world, i + 9, j + 1, k + 7, Dungeons.purpleBrick, 0);
        this.setBlock(world, i + 9, j + 1, k + 8, Dungeons.purpleBrick, 0);
        this.setBlock(world, i + 9, j + 1, k + 9, Dungeons.purpleBrick, 0);
        this.setBlock(world, i + 9, j + 1, k + 10, Dungeons.purpleBrick, 0);
        this.setBlock(world, i + 9, j + 1, k + 11, Dungeons.purpleBrick, 0);
        this.setBlock(world, i + 9, j + 1, k + 12, Dungeons.purpleBrick, 0);
        this.setBlock(world, i + 9, j + 1, k + 13, Dungeons.purpleBrick, 0);
        this.setBlock(world, i + 9, j + 1, k + 14, Dungeons.purpleBrick, 0);
        this.setBlock(world, i + 9, j + 1, k + 15, Dungeons.purpleBrick, 0);
        this.setBlock(world, i + 9, j + 1, k + 16, Dungeons.purpleBrick, 0);
        this.setBlock(world, i + 9, j + 1, k + 17, Dungeons.purpleBrick, 0);
        this.setBlock(world, i + 9, j + 1, k + 18, Dungeons.purpleBrick, 0);
        this.setBlock(world, i + 9, j + 1, k + 19, Dungeons.purpleBrick, 0);
        this.setBlock(world, i + 9, j + 1, k + 20, Dungeons.purpleBrick, 0);
        this.setBlock(world, i + 9, j + 1, k + 21, Dungeons.purpleBrick, 0);
        this.setBlock(world, i + 9, j + 2, k + 3, Dungeons.purpleBrick, 0);
        this.setBlock(world, i + 9, j + 2, k + 4, Dungeons.purpleBrick, 0);
        this.setBlock(world, i + 9, j + 2, k + 5, Dungeons.purpleBrick, 0);
        this.setBlock(world, i + 9, j + 2, k + 6, Dungeons.purpleBrick, 0);
        this.setBlock(world, i + 9, j + 2, k + 7, Dungeons.purpleBrick, 0);
        this.setBlock(world, i + 9, j + 2, k + 8, Dungeons.purpleBrick, 0);
        this.setBlock(world, i + 9, j + 2, k + 9, Dungeons.purpleBrick, 0);
        this.setBlock(world, i + 9, j + 2, k + 10, Dungeons.purpleBrick, 0);
        this.setBlock(world, i + 9, j + 2, k + 11, Dungeons.purpleBrick, 0);
        this.setBlock(world, i + 9, j + 2, k + 12, Dungeons.purpleBrick, 0);
        this.setBlock(world, i + 9, j + 2, k + 13, Dungeons.purpleBrick, 0);
        this.setBlock(world, i + 9, j + 2, k + 14, Dungeons.purpleBrick, 0);
        this.setBlock(world, i + 9, j + 2, k + 15, Dungeons.purpleBrick, 0);
        this.setBlock(world, i + 9, j + 2, k + 16, Dungeons.purpleBrick, 0);
        this.setBlock(world, i + 9, j + 2, k + 17, Dungeons.purpleBrick, 0);
        this.setBlock(world, i + 9, j + 2, k + 18, Dungeons.purpleBrick, 0);
        this.setBlock(world, i + 9, j + 2, k + 19, Dungeons.purpleBrick, 0);
        this.setBlock(world, i + 9, j + 2, k + 20, Dungeons.purpleBrick, 0);
        this.setBlock(world, i + 9, j + 2, k + 21, Dungeons.purpleBrick, 0);
        this.setBlock(world, i + 9, j + 3, k + 4, Dungeons.purpleBrick, 0);
        this.setBlock(world, i + 9, j + 3, k + 20, Dungeons.purpleBrick, 0);
        this.setBlock(world, i + 9, j + 4, k + 4, Dungeons.purpleBrick, 0);
        this.setBlock(world, i + 9, j + 4, k + 20, Dungeons.purpleBrick, 0);
        this.setBlock(world, i + 9, j + 6, k + 4, Dungeons.purpleBrick, 0);
        this.setBlock(world, i + 9, j + 6, k + 20, Dungeons.purpleBrick, 0);
        this.setBlock(world, i + 9, j + 7, k + 4, Dungeons.purpleBrick, 0);
        this.setBlock(world, i + 9, j + 7, k + 20, Dungeons.purpleBrick, 0);
        this.setBlock(world, i + 9, j + 8, k + 3, Dungeons.purpleBrick, 0);
        this.setBlock(world, i + 9, j + 8, k + 4, Dungeons.purpleBrick, 0);
        this.setBlock(world, i + 9, j + 8, k + 20, Dungeons.purpleBrick, 0);
        this.setBlock(world, i + 9, j + 8, k + 21, Dungeons.purpleBrick, 0);
        this.setBlock(world, i + 9, j + 9, k + 5, Dungeons.purpleBrick, 0);
        this.setBlock(world, i + 9, j + 9, k + 6, Dungeons.purpleBrick, 0);
        this.setBlock(world, i + 9, j + 9, k + 7, Dungeons.purpleBrick, 0);
        this.setBlock(world, i + 9, j + 9, k + 8, Dungeons.purpleBrick, 0);
        this.setBlock(world, i + 9, j + 9, k + 9, Dungeons.purpleBrick, 0);
        this.setBlock(world, i + 9, j + 9, k + 10, Dungeons.purpleBrick, 0);
        this.setBlock(world, i + 9, j + 9, k + 11, Dungeons.purpleBrick, 0);
        this.setBlock(world, i + 9, j + 9, k + 12, Dungeons.purpleBrick, 0);
        this.setBlock(world, i + 9, j + 9, k + 13, Dungeons.purpleBrick, 0);
        this.setBlock(world, i + 9, j + 9, k + 14, Dungeons.purpleBrick, 0);
        this.setBlock(world, i + 9, j + 9, k + 15, Dungeons.purpleBrick, 0);
        this.setBlock(world, i + 9, j + 9, k + 16, Dungeons.purpleBrick, 0);
        this.setBlock(world, i + 9, j + 9, k + 17, Dungeons.purpleBrick, 0);
        this.setBlock(world, i + 9, j + 9, k + 18, Dungeons.purpleBrick, 0);
        this.setBlock(world, i + 9, j + 9, k + 19, Dungeons.purpleBrick, 0);
        this.setBlock(world, i + 9, j + 10, k + 7, Dungeons.purpleBrick, 0);
        this.setBlock(world, i + 9, j + 10, k + 17, Dungeons.purpleBrick, 0);
        this.setBlock(world, i + 9, j + 11, k + 7, Dungeons.purpleBrick, 0);
        this.setBlock(world, i + 9, j + 11, k + 17, Dungeons.purpleBrick, 0);
        this.setBlock(world, i + 9, j + 13, k + 7, Dungeons.purpleBrick, 0);
        this.setBlock(world, i + 9, j + 13, k + 17, Dungeons.purpleBrick, 0);
        this.setBlock(world, i + 9, j + 14, k + 7, Dungeons.purpleBrick, 0);
        this.setBlock(world, i + 9, j + 14, k + 17, Dungeons.purpleBrick, 0);
        this.setBlock(world, i + 9, j + 15, k + 6, Dungeons.purpleBrick, 0);
        this.setBlock(world, i + 9, j + 15, k + 7, Dungeons.purpleBrick, 0);
        this.setBlock(world, i + 9, j + 15, k + 17, Dungeons.purpleBrick, 0);
        this.setBlock(world, i + 9, j + 15, k + 18, Dungeons.purpleBrick, 0);
        this.setBlock(world, i + 9, j + 16, k + 8, Dungeons.purpleBrick, 0);
        this.setBlock(world, i + 9, j + 16, k + 9, Dungeons.purpleBrick, 0);
        this.setBlock(world, i + 9, j + 16, k + 10, Dungeons.purpleBrick, 0);
        this.setBlock(world, i + 9, j + 16, k + 11, Dungeons.purpleBrick, 0);
        this.setBlock(world, i + 9, j + 16, k + 12, Dungeons.purpleBrick, 0);
        this.setBlock(world, i + 9, j + 16, k + 13, Dungeons.purpleBrick, 0);
        this.setBlock(world, i + 9, j + 16, k + 14, Dungeons.purpleBrick, 0);
        this.setBlock(world, i + 9, j + 16, k + 15, Dungeons.purpleBrick, 0);
        this.setBlock(world, i + 9, j + 16, k + 16, Dungeons.purpleBrick, 0);
        this.setBlock(world, i + 9, j + 17, k + 9, Dungeons.purpleBrick, 0);
        this.setBlock(world, i + 9, j + 17, k + 14, Dungeons.carvedCrystalliumBrick, 0);
        this.setBlock(world, i + 9, j + 17, k + 15, Dungeons.purpleBrick, 0);
        this.setBlock(world, i + 9, j + 18, k + 9, Dungeons.purpleBrick, 0);
        this.setBlock(world, i + 9, j + 18, k + 14, Dungeons.crystalliumLamp, 0);
        this.setBlock(world, i + 9, j + 18, k + 15, Dungeons.purpleBrick, 0);
        this.setBlock(world, i + 9, j + 19, k + 9, Dungeons.purpleBrick, 0);
        this.setBlock(world, i + 9, j + 19, k + 15, Dungeons.purpleBrick, 0);
        this.setBlock(world, i + 9, j + 20, k + 9, Dungeons.purpleBrick, 0);
        this.setBlock(world, i + 9, j + 20, k + 15, Dungeons.purpleBrick, 0);
        this.setBlock(world, i + 9, j + 21, k + 8, Dungeons.purpleBrick, 0);
        this.setBlock(world, i + 9, j + 21, k + 9, Dungeons.purpleBrick, 0);
        this.setBlock(world, i + 9, j + 21, k + 15, Dungeons.purpleBrick, 0);
        this.setBlock(world, i + 9, j + 21, k + 16, Dungeons.purpleBrick, 0);
        this.setBlock(world, i + 9, j + 22, k + 10, Dungeons.purpleBrick, 0);
        this.setBlock(world, i + 9, j + 22, k + 11, Dungeons.purpleBrick, 0);
        this.setBlock(world, i + 9, j + 22, k + 12, Dungeons.purpleBrick, 0);
        this.setBlock(world, i + 9, j + 22, k + 13, Dungeons.purpleBrick, 0);
        this.setBlock(world, i + 9, j + 22, k + 14, Dungeons.purpleBrick, 0);
        this.setBlock(world, i + 10, j, k + 1, Dungeons.purpleBrick, 0);
        this.setBlock(world, i + 10, j, k + 2, Dungeons.purpleBrick, 0);
        this.setBlock(world, i + 10, j, k + 3, Dungeons.purpleBrick, 0);
        this.setBlock(world, i + 10, j, k + 4, Dungeons.purpleBrick, 0);
        this.setBlock(world, i + 10, j, k + 5, Dungeons.purpleBrick, 0);
        this.setBlock(world, i + 10, j, k + 6, Dungeons.purpleBrick, 0);
        this.setBlock(world, i + 10, j, k + 7, Dungeons.purpleBrick, 0);
        this.setBlock(world, i + 10, j, k + 8, Dungeons.purpleBrick, 0);
        this.setBlock(world, i + 10, j, k + 9, Dungeons.purpleBrick, 0);
        this.setBlock(world, i + 10, j, k + 10, Dungeons.purpleBrick, 0);
        this.setBlock(world, i + 10, j, k + 11, Dungeons.purpleBrick, 0);
        this.setBlock(world, i + 10, j, k + 12, Dungeons.purpleBrick, 0);
        this.setBlock(world, i + 10, j, k + 13, Dungeons.purpleBrick, 0);
        this.setBlock(world, i + 10, j, k + 14, Dungeons.purpleBrick, 0);
        this.setBlock(world, i + 10, j, k + 15, Dungeons.purpleBrick, 0);
        this.setBlock(world, i + 10, j, k + 16, Dungeons.purpleBrick, 0);
        this.setBlock(world, i + 10, j, k + 17, Dungeons.purpleBrick, 0);
        this.setBlock(world, i + 10, j, k + 18, Dungeons.purpleBrick, 0);
        this.setBlock(world, i + 10, j, k + 19, Dungeons.purpleBrick, 0);
        this.setBlock(world, i + 10, j, k + 20, Dungeons.purpleBrick, 0);
        this.setBlock(world, i + 10, j, k + 21, Dungeons.purpleBrick, 0);
        this.setBlock(world, i + 10, j, k + 22, Dungeons.purpleBrick, 0);
        this.setBlock(world, i + 10, j, k + 23, Dungeons.purpleBrick, 0);
        this.setBlock(world, i + 10, j + 1, k + 2, Dungeons.purpleBrick, 0);
        this.setBlock(world, i + 10, j + 1, k + 3, Dungeons.purpleBrick, 0);
        this.setBlock(world, i + 10, j + 1, k + 4, Dungeons.purpleBrick, 0);
        this.setBlock(world, i + 10, j + 1, k + 5, Dungeons.purpleBrick, 0);
        this.setBlock(world, i + 10, j + 1, k + 6, Dungeons.purpleBrick, 0);
        this.setBlock(world, i + 10, j + 1, k + 7, Dungeons.purpleBrick, 0);
        this.setBlock(world, i + 10, j + 1, k + 8, Dungeons.purpleBrick, 0);
        this.setBlock(world, i + 10, j + 1, k + 9, Dungeons.purpleBrick, 0);
        this.setBlock(world, i + 10, j + 1, k + 10, Dungeons.purpleBrick, 0);
        this.setBlock(world, i + 10, j + 1, k + 11, Dungeons.purpleBrick, 0);
        this.setBlock(world, i + 10, j + 1, k + 12, Dungeons.purpleBrick, 0);
        this.setBlock(world, i + 10, j + 1, k + 13, Dungeons.purpleBrick, 0);
        this.setBlock(world, i + 10, j + 1, k + 14, Dungeons.purpleBrick, 0);
        this.setBlock(world, i + 10, j + 1, k + 15, Dungeons.purpleBrick, 0);
        this.setBlock(world, i + 10, j + 1, k + 16, Dungeons.purpleBrick, 0);
        this.setBlock(world, i + 10, j + 1, k + 17, Dungeons.purpleBrick, 0);
        this.setBlock(world, i + 10, j + 1, k + 18, Dungeons.purpleBrick, 0);
        this.setBlock(world, i + 10, j + 1, k + 19, Dungeons.purpleBrick, 0);
        this.setBlock(world, i + 10, j + 1, k + 20, Dungeons.purpleBrick, 0);
        this.setBlock(world, i + 10, j + 1, k + 21, Dungeons.purpleBrick, 0);
        this.setBlock(world, i + 10, j + 1, k + 22, Dungeons.purpleBrick, 0);
        this.setBlock(world, i + 10, j + 2, k + 3, Dungeons.purpleBrick, 0);
        this.setBlock(world, i + 10, j + 2, k + 4, Dungeons.purpleBrick, 0);
        this.setBlock(world, i + 10, j + 2, k + 5, Dungeons.purpleBrick, 0);
        this.setBlock(world, i + 10, j + 2, k + 6, Dungeons.purpleBrick, 0);
        this.setBlock(world, i + 10, j + 2, k + 7, Dungeons.purpleBrick, 0);
        this.setBlock(world, i + 10, j + 2, k + 8, Dungeons.purpleBrick, 0);
        this.setBlock(world, i + 10, j + 2, k + 9, Dungeons.purpleBrick, 0);
        this.setBlock(world, i + 10, j + 2, k + 10, Dungeons.purpleBrick, 0);
        this.setBlock(world, i + 10, j + 2, k + 11, Dungeons.purpleBrick, 0);
        this.setBlock(world, i + 10, j + 2, k + 12, Dungeons.purpleBrick, 0);
        this.setBlock(world, i + 10, j + 2, k + 13, Dungeons.purpleBrick, 0);
        this.setBlock(world, i + 10, j + 2, k + 14, Dungeons.purpleBrick, 0);
        this.setBlock(world, i + 10, j + 2, k + 15, Dungeons.purpleBrick, 0);
        this.setBlock(world, i + 10, j + 2, k + 16, Dungeons.purpleBrick, 0);
        this.setBlock(world, i + 10, j + 2, k + 17, Dungeons.purpleBrick, 0);
        this.setBlock(world, i + 10, j + 2, k + 18, Dungeons.purpleBrick, 0);
        this.setBlock(world, i + 10, j + 2, k + 19, Dungeons.purpleBrick, 0);
        this.setBlock(world, i + 10, j + 2, k + 20, Dungeons.purpleBrick, 0);
        this.setBlock(world, i + 10, j + 2, k + 21, Dungeons.purpleBrick, 0);
        this.setBlock(world, i + 10, j + 3, k + 4, Dungeons.purpleBrick, 0);
        this.setBlock(world, i + 10, j + 3, k + 20, Dungeons.purpleBrick, 0);
        this.setBlock(world, i + 10, j + 7, k + 4, Dungeons.purpleBrick, 0);
        this.setBlock(world, i + 10, j + 7, k + 11, Dungeons.purpleBrick, 0);
        this.setBlock(world, i + 10, j + 7, k + 20, Dungeons.purpleBrick, 0);
        this.setBlock(world, i + 10, j + 8, k + 3, Dungeons.purpleBrick, 0);
        this.setBlock(world, i + 10, j + 8, k + 4, Dungeons.purpleBrick, 0);
        this.setBlock(world, i + 10, j + 8, k + 11, Dungeons.crystalliumStairs, 1);
        this.setBlock(world, i + 10, j + 8, k + 12, Dungeons.purpleBrick, 0);
        this.setBlock(world, i + 10, j + 8, k + 20, Dungeons.purpleBrick, 0);
        this.setBlock(world, i + 10, j + 8, k + 21, Dungeons.purpleBrick, 0);
        this.setBlock(world, i + 10, j + 9, k + 5, Dungeons.purpleBrick, 0);
        this.setBlock(world, i + 10, j + 9, k + 6, Dungeons.purpleBrick, 0);
        this.setBlock(world, i + 10, j + 9, k + 7, Dungeons.purpleBrick, 0);
        this.setBlock(world, i + 10, j + 9, k + 8, Dungeons.purpleBrick, 0);
        this.setBlock(world, i + 10, j + 9, k + 9, Dungeons.purpleBrick, 0);
        this.setBlock(world, i + 10, j + 9, k + 10, Dungeons.purpleBrick, 0);
        this.setBlock(world, i + 10, j + 9, k + 12, Dungeons.crystalliumStairs, 2);
        this.setBlock(world, i + 10, j + 9, k + 13, Dungeons.purpleBrick, 0);
        this.setBlock(world, i + 10, j + 9, k + 14, Dungeons.purpleBrick, 0);
        this.setBlock(world, i + 10, j + 9, k + 15, Dungeons.purpleBrick, 0);
        this.setBlock(world, i + 10, j + 9, k + 16, Dungeons.purpleBrick, 0);
        this.setBlock(world, i + 10, j + 9, k + 17, Dungeons.purpleBrick, 0);
        this.setBlock(world, i + 10, j + 9, k + 18, Dungeons.purpleBrick, 0);
        this.setBlock(world, i + 10, j + 9, k + 19, Dungeons.purpleBrick, 0);
        this.setBlock(world, i + 10, j + 10, k + 7, Dungeons.purpleBrick, 0);
        this.setBlock(world, i + 10, j + 10, k + 13, Dungeons.crystalliumStairs, 0);
        this.setBlock(world, i + 10, j + 10, k + 17, Dungeons.purpleBrick, 0);
        this.setBlock(world, i + 10, j + 14, k + 7, Dungeons.purpleBrick, 0);
        this.setBlock(world, i + 10, j + 14, k + 17, Dungeons.purpleBrick, 0);
        this.setBlock(world, i + 10, j + 15, k + 6, Dungeons.purpleBrick, 0);
        this.setBlock(world, i + 10, j + 15, k + 7, Dungeons.purpleBrick, 0);
        this.setBlock(world, i + 10, j + 15, k + 11, Dungeons.purpleBrick, 0);
        this.setBlock(world, i + 10, j + 15, k + 17, Dungeons.purpleBrick, 0);
        this.setBlock(world, i + 10, j + 15, k + 18, Dungeons.purpleBrick, 0);
        this.setBlock(world, i + 10, j + 16, k + 8, Dungeons.purpleBrick, 0);
        this.setBlock(world, i + 10, j + 16, k + 9, Dungeons.purpleBrick, 0);
        this.setBlock(world, i + 10, j + 16, k + 10, Dungeons.purpleBrick, 0);
        this.setBlock(world, i + 10, j + 16, k + 11, Dungeons.crystalliumStairs, 1);
        this.setBlock(world, i + 10, j + 16, k + 12, Dungeons.purpleBrick, 0);
        this.setBlock(world, i + 10, j + 16, k + 13, Dungeons.purpleBrick, 0);
        this.setBlock(world, i + 10, j + 16, k + 14, Dungeons.purpleBrick, 0);
        this.setBlock(world, i + 10, j + 16, k + 15, Dungeons.purpleBrick, 0);
        this.setBlock(world, i + 10, j + 16, k + 16, Dungeons.purpleBrick, 0);
        this.setBlock(world, i + 10, j + 17, k + 9, Dungeons.purpleBrick, 0);
        this.setBlock(world, i + 10, j + 17, k + 15, Dungeons.purpleBrick, 0);
        this.setBlock(world, i + 10, j + 18, k + 9, Dungeons.purpleBrick, 0);
        this.setBlock(world, i + 10, j + 18, k + 15, Dungeons.purpleBrick, 0);
        this.setBlock(world, i + 10, j + 19, k + 15, Dungeons.purpleBrick, 0);
        this.setBlock(world, i + 10, j + 20, k + 9, Dungeons.purpleBrick, 0);
        this.setBlock(world, i + 10, j + 20, k + 15, Dungeons.purpleBrick, 0);
        this.setBlock(world, i + 10, j + 21, k + 8, Dungeons.purpleBrick, 0);
        this.setBlock(world, i + 10, j + 21, k + 9, Dungeons.purpleBrick, 0);
        this.setBlock(world, i + 10, j + 21, k + 15, Dungeons.purpleBrick, 0);
        this.setBlock(world, i + 10, j + 21, k + 16, Dungeons.purpleBrick, 0);
        this.setBlock(world, i + 10, j + 22, k + 10, Dungeons.purpleBrick, 0);
        this.setBlock(world, i + 10, j + 22, k + 14, Dungeons.purpleBrick, 0);
        this.setBlock(world, i + 10, j + 23, k + 11, Dungeons.purpleBrick, 0);
        this.setBlock(world, i + 10, j + 23, k + 12, Dungeons.purpleBrick, 0);
        this.setBlock(world, i + 10, j + 23, k + 13, Dungeons.purpleBrick, 0);
        this.setBlock(world, i + 11, j, k + 1, Dungeons.purpleBrick, 0);
        this.setBlock(world, i + 11, j, k + 2, Dungeons.purpleBrick, 0);
        this.setBlock(world, i + 11, j, k + 3, Dungeons.purpleBrick, 0);
        this.setBlock(world, i + 11, j, k + 4, Dungeons.purpleBrick, 0);
        this.setBlock(world, i + 11, j, k + 5, Dungeons.purpleBrick, 0);
        this.setBlock(world, i + 11, j, k + 6, Dungeons.purpleBrick, 0);
        this.setBlock(world, i + 11, j, k + 7, Dungeons.purpleBrick, 0);
        this.setBlock(world, i + 11, j, k + 8, Dungeons.purpleBrick, 0);
        this.setBlock(world, i + 11, j, k + 9, Dungeons.purpleBrick, 0);
        this.setBlock(world, i + 11, j, k + 10, Dungeons.purpleBrick, 0);
        this.setBlock(world, i + 11, j, k + 11, Dungeons.purpleBrick, 0);
        this.setBlock(world, i + 11, j, k + 12, Dungeons.purpleBrick, 0);
        this.setBlock(world, i + 11, j, k + 13, Dungeons.purpleBrick, 0);
        this.setBlock(world, i + 11, j, k + 14, Dungeons.purpleBrick, 0);
        this.setBlock(world, i + 11, j, k + 15, Dungeons.purpleBrick, 0);
        this.setBlock(world, i + 11, j, k + 16, Dungeons.purpleBrick, 0);
        this.setBlock(world, i + 11, j, k + 17, Dungeons.purpleBrick, 0);
        this.setBlock(world, i + 11, j, k + 18, Dungeons.purpleBrick, 0);
        this.setBlock(world, i + 11, j, k + 19, Dungeons.purpleBrick, 0);
        this.setBlock(world, i + 11, j, k + 20, Dungeons.purpleBrick, 0);
        this.setBlock(world, i + 11, j, k + 21, Dungeons.purpleBrick, 0);
        this.setBlock(world, i + 11, j, k + 22, Dungeons.purpleBrick, 0);
        this.setBlock(world, i + 11, j, k + 23, Dungeons.purpleBrick, 0);
        this.setBlock(world, i + 11, j + 1, k + 2, Dungeons.purpleBrick, 0);
        this.setBlock(world, i + 11, j + 1, k + 3, Dungeons.purpleBrick, 0);
        this.setBlock(world, i + 11, j + 1, k + 4, Dungeons.purpleBrick, 0);
        this.setBlock(world, i + 11, j + 1, k + 5, Dungeons.purpleBrick, 0);
        this.setBlock(world, i + 11, j + 1, k + 6, Dungeons.purpleBrick, 0);
        this.setBlock(world, i + 11, j + 1, k + 7, Dungeons.purpleBrick, 0);
        this.setBlock(world, i + 11, j + 1, k + 8, Dungeons.purpleBrick, 0);
        this.setBlock(world, i + 11, j + 1, k + 9, Dungeons.purpleBrick, 0);
        this.setBlock(world, i + 11, j + 1, k + 10, Dungeons.purpleBrick, 0);
        this.setBlock(world, i + 11, j + 1, k + 11, Dungeons.purpleBrick, 0);
        this.setBlock(world, i + 11, j + 1, k + 12, Dungeons.purpleBrick, 0);
        this.setBlock(world, i + 11, j + 1, k + 13, Dungeons.purpleBrick, 0);
        this.setBlock(world, i + 11, j + 1, k + 14, Dungeons.purpleBrick, 0);
        this.setBlock(world, i + 11, j + 1, k + 15, Dungeons.purpleBrick, 0);
        this.setBlock(world, i + 11, j + 1, k + 16, Dungeons.purpleBrick, 0);
        this.setBlock(world, i + 11, j + 1, k + 17, Dungeons.purpleBrick, 0);
        this.setBlock(world, i + 11, j + 1, k + 18, Dungeons.purpleBrick, 0);
        this.setBlock(world, i + 11, j + 1, k + 19, Dungeons.purpleBrick, 0);
        this.setBlock(world, i + 11, j + 1, k + 20, Dungeons.purpleBrick, 0);
        this.setBlock(world, i + 11, j + 1, k + 21, Dungeons.purpleBrick, 0);
        this.setBlock(world, i + 11, j + 1, k + 22, Dungeons.purpleBrick, 0);
        this.setBlock(world, i + 11, j + 2, k + 3, Dungeons.purpleBrick, 0);
        this.setBlock(world, i + 11, j + 2, k + 4, Dungeons.purpleBrick, 0);
        this.setBlock(world, i + 11, j + 2, k + 5, Dungeons.purpleBrick, 0);
        this.setBlock(world, i + 11, j + 2, k + 6, Dungeons.purpleBrick, 0);
        this.setBlock(world, i + 11, j + 2, k + 7, Dungeons.purpleBrick, 0);
        this.setBlock(world, i + 11, j + 2, k + 8, Dungeons.purpleBrick, 0);
        this.setBlock(world, i + 11, j + 2, k + 9, Dungeons.purpleBrick, 0);
        this.setBlock(world, i + 11, j + 2, k + 10, Dungeons.purpleBrick, 0);
        this.setBlock(world, i + 11, j + 2, k + 11, Dungeons.purpleBrick, 0);
        this.setBlock(world, i + 11, j + 2, k + 12, Dungeons.purpleBrick, 0);
        this.setBlock(world, i + 11, j + 2, k + 13, Dungeons.purpleBrick, 0);
        this.setBlock(world, i + 11, j + 2, k + 14, Dungeons.purpleBrick, 0);
        this.setBlock(world, i + 11, j + 2, k + 15, Dungeons.purpleBrick, 0);
        this.setBlock(world, i + 11, j + 2, k + 16, Dungeons.purpleBrick, 0);
        this.setBlock(world, i + 11, j + 2, k + 17, Dungeons.purpleBrick, 0);
        this.setBlock(world, i + 11, j + 2, k + 18, Dungeons.purpleBrick, 0);
        this.setBlock(world, i + 11, j + 2, k + 19, Dungeons.purpleBrick, 0);
        this.setBlock(world, i + 11, j + 2, k + 20, Dungeons.purpleBrick, 0);
        this.setBlock(world, i + 11, j + 2, k + 21, Dungeons.purpleBrick, 0);
        this.setBlock(world, i + 11, j + 3, k + 12, Dungeons.carvedCrystalliumBrick, 0);
        this.setBlock(world, i + 11, j + 3, k + 13, Dungeons.crystalliumStairs, 0);
        this.setBlock(world, i + 11, j + 4, k + 12, Dungeons.carvedCrystalliumBrick, 0);
        this.setBlock(world, i + 11, j + 5, k + 12, Dungeons.carvedCrystalliumBrick, 0);
        this.setBlock(world, i + 11, j + 6, k + 11, Dungeons.purpleBrick, 0);
        this.setBlock(world, i + 11, j + 6, k + 12, Dungeons.carvedCrystalliumBrick, 0);
        this.setBlock(world, i + 11, j + 7, k + 11, Dungeons.crystalliumStairs, 1);
        this.setBlock(world, i + 11, j + 7, k + 12, Dungeons.carvedCrystalliumBrick, 0);
        this.setBlock(world, i + 11, j + 8, k + 3, Dungeons.purpleBrick, 0);
        this.setBlock(world, i + 11, j + 8, k + 4, Dungeons.purpleBrick, 0);
        this.setBlock(world, i + 11, j + 8, k + 12, Dungeons.carvedCrystalliumBrick, 0);
        this.setBlock(world, i + 11, j + 8, k + 20, Dungeons.purpleBrick, 0);
        this.setBlock(world, i + 11, j + 8, k + 21, Dungeons.purpleBrick, 0);
        this.setBlock(world, i + 11, j + 9, k + 5, Dungeons.purpleBrick, 0);
        this.setBlock(world, i + 11, j + 9, k + 6, Dungeons.purpleBrick, 0);
        this.setBlock(world, i + 11, j + 9, k + 7, Dungeons.purpleBrick, 0);
        this.setBlock(world, i + 11, j + 9, k + 8, Dungeons.purpleBrick, 0);
        this.setBlock(world, i + 11, j + 9, k + 9, Dungeons.purpleBrick, 0);
        this.setBlock(world, i + 11, j + 9, k + 10, Dungeons.purpleBrick, 0);
        this.setBlock(world, i + 11, j + 9, k + 12, Dungeons.carvedCrystalliumBrick, 0);
        this.setBlock(world, i + 11, j + 9, k + 14, Dungeons.purpleBrick, 0);
        this.setBlock(world, i + 11, j + 9, k + 15, Dungeons.purpleBrick, 0);
        this.setBlock(world, i + 11, j + 9, k + 16, Dungeons.purpleBrick, 0);
        this.setBlock(world, i + 11, j + 9, k + 17, Dungeons.purpleBrick, 0);
        this.setBlock(world, i + 11, j + 9, k + 18, Dungeons.purpleBrick, 0);
        this.setBlock(world, i + 11, j + 9, k + 19, Dungeons.purpleBrick, 0);
        this.setBlock(world, i + 11, j + 10, k + 9, Dungeons.carvedCrystalliumBrick, 0);
        this.setBlock(world, i + 11, j + 10, k + 12, Dungeons.carvedCrystalliumBrick, 0);
        this.setBlock(world, i + 11, j + 10, k + 13, Dungeons.purpleBrick, 0);
        this.setBlock(world, i + 11, j + 11, k + 9, Dungeons.crystalliumLamp, 0);
        this.setBlock(world, i + 11, j + 11, k + 12, Dungeons.carvedCrystalliumBrick, 0);
        this.setBlock(world, i + 11, j + 11, k + 13, Dungeons.crystalliumStairs, 0);
        this.setBlock(world, i + 11, j + 12, k + 12, Dungeons.carvedCrystalliumBrick, 0);
        this.setBlock(world, i + 11, j + 13, k + 12, Dungeons.carvedCrystalliumBrick, 0);
        this.setBlock(world, i + 11, j + 14, k + 11, Dungeons.purpleBrick, 0);
        this.setBlock(world, i + 11, j + 14, k + 12, Dungeons.carvedCrystalliumBrick, 0);
        this.setBlock(world, i + 11, j + 15, k + 6, Dungeons.purpleBrick, 0);
        this.setBlock(world, i + 11, j + 15, k + 7, Dungeons.purpleBrick, 0);
        this.setBlock(world, i + 11, j + 15, k + 11, Dungeons.crystalliumStairs, 1);
        this.setBlock(world, i + 11, j + 15, k + 12, Dungeons.carvedCrystalliumBrick, 0);
        this.setBlock(world, i + 11, j + 15, k + 17, Dungeons.purpleBrick, 0);
        this.setBlock(world, i + 11, j + 15, k + 18, Dungeons.purpleBrick, 0);
        this.setBlock(world, i + 11, j + 16, k + 8, Dungeons.purpleBrick, 0);
        this.setBlock(world, i + 11, j + 16, k + 9, Dungeons.purpleBrick, 0);
        this.setBlock(world, i + 11, j + 16, k + 10, Dungeons.purpleBrick, 0);
        this.setBlock(world, i + 11, j + 16, k + 12, Dungeons.carvedCrystalliumBrick, 0);
        this.setBlock(world, i + 11, j + 16, k + 13, Dungeons.purpleBrick, 0);
        this.setBlock(world, i + 11, j + 16, k + 14, Dungeons.purpleBrick, 0);
        this.setBlock(world, i + 11, j + 16, k + 15, Dungeons.purpleBrick, 0);
        this.setBlock(world, i + 11, j + 16, k + 16, Dungeons.purpleBrick, 0);
        this.setBlock(world, i + 11, j + 17, k + 9, Dungeons.purpleBrick, 0);
        this.setBlock(world, i + 11, j + 17, k + 13, Dungeons.magitable, 0);
        this.setBlock(world, i + 11, j + 17, k + 15, Dungeons.purpleBrick, 0);
        this.setBlock(world, i + 11, j + 18, k + 15, Dungeons.purpleBrick, 0);
        this.setBlock(world, i + 11, j + 19, k + 15, Dungeons.purpleBrick, 0);
        this.setBlock(world, i + 11, j + 20, k + 15, Dungeons.purpleBrick, 0);
        this.setBlock(world, i + 11, j + 21, k + 8, Dungeons.purpleBrick, 0);
        this.setBlock(world, i + 11, j + 21, k + 9, Dungeons.purpleBrick, 0);
        this.setBlock(world, i + 11, j + 21, k + 15, Dungeons.purpleBrick, 0);
        this.setBlock(world, i + 11, j + 21, k + 16, Dungeons.purpleBrick, 0);
        this.setBlock(world, i + 11, j + 22, k + 10, Dungeons.purpleBrick, 0);
        this.setBlock(world, i + 11, j + 22, k + 14, Dungeons.purpleBrick, 0);
        this.setBlock(world, i + 11, j + 23, k + 11, Dungeons.purpleBrick, 0);
        this.setBlock(world, i + 11, j + 23, k + 12, Dungeons.purpleBrick, 0);
        this.setBlock(world, i + 11, j + 23, k + 13, Dungeons.purpleBrick, 0);
        this.setBlock(world, i + 11, j + 24, k + 12, Dungeons.purpleBrick, 0);
        this.setBlock(world, i + 11, j + 25, k + 12, Dungeons.purpleBrick, 0);
        this.setBlock(world, i + 12, j, k + 1, Dungeons.purpleBrick, 0);
        this.setBlock(world, i + 12, j, k + 2, Dungeons.purpleBrick, 0);
        this.setBlock(world, i + 12, j, k + 3, Dungeons.purpleBrick, 0);
        this.setBlock(world, i + 12, j, k + 4, Dungeons.purpleBrick, 0);
        this.setBlock(world, i + 12, j, k + 5, Dungeons.purpleBrick, 0);
        this.setBlock(world, i + 12, j, k + 6, Dungeons.purpleBrick, 0);
        this.setBlock(world, i + 12, j, k + 7, Dungeons.purpleBrick, 0);
        this.setBlock(world, i + 12, j, k + 8, Dungeons.purpleBrick, 0);
        this.setBlock(world, i + 12, j, k + 9, Dungeons.purpleBrick, 0);
        this.setBlock(world, i + 12, j, k + 10, Dungeons.purpleBrick, 0);
        this.setBlock(world, i + 12, j, k + 11, Dungeons.purpleBrick, 0);
        this.setBlock(world, i + 12, j, k + 12, Dungeons.purpleBrick, 0);
        this.setBlock(world, i + 12, j, k + 13, Dungeons.purpleBrick, 0);
        this.setBlock(world, i + 12, j, k + 14, Dungeons.purpleBrick, 0);
        this.setBlock(world, i + 12, j, k + 15, Dungeons.purpleBrick, 0);
        this.setBlock(world, i + 12, j, k + 16, Dungeons.purpleBrick, 0);
        this.setBlock(world, i + 12, j, k + 17, Dungeons.purpleBrick, 0);
        this.setBlock(world, i + 12, j, k + 18, Dungeons.purpleBrick, 0);
        this.setBlock(world, i + 12, j, k + 19, Dungeons.purpleBrick, 0);
        this.setBlock(world, i + 12, j, k + 20, Dungeons.purpleBrick, 0);
        this.setBlock(world, i + 12, j, k + 21, Dungeons.purpleBrick, 0);
        this.setBlock(world, i + 12, j, k + 22, Dungeons.purpleBrick, 0);
        this.setBlock(world, i + 12, j, k + 23, Dungeons.purpleBrick, 0);
        this.setBlock(world, i + 12, j + 1, k + 2, Dungeons.purpleBrick, 0);
        this.setBlock(world, i + 12, j + 1, k + 3, Dungeons.purpleBrick, 0);
        this.setBlock(world, i + 12, j + 1, k + 4, Dungeons.purpleBrick, 0);
        this.setBlock(world, i + 12, j + 1, k + 5, Dungeons.purpleBrick, 0);
        this.setBlock(world, i + 12, j + 1, k + 6, Dungeons.purpleBrick, 0);
        this.setBlock(world, i + 12, j + 1, k + 7, Dungeons.purpleBrick, 0);
        this.setBlock(world, i + 12, j + 1, k + 8, Dungeons.purpleBrick, 0);
        this.setBlock(world, i + 12, j + 1, k + 9, Dungeons.purpleBrick, 0);
        this.setBlock(world, i + 12, j + 1, k + 10, Dungeons.purpleBrick, 0);
        this.setBlock(world, i + 12, j + 1, k + 11, Dungeons.purpleBrick, 0);
        this.setBlock(world, i + 12, j + 1, k + 12, Dungeons.purpleBrick, 0);
