

package com.gibby.dungeon.gen;

import com.gibby.dungeon.Dungeons;
import cpw.mods.fml.common.IWorldGenerator;
import net.minecraft.block.Block;
import net.minecraft.world.IBlockAccess;
import net.minecraft.world.World;
import net.minecraft.world.chunk.IChunkProvider;
import net.minecraft.world.gen.feature.WorldGenerator;

import java.util.Random;

public class WorldGenLargeCrystalTree extends WorldGenerator implements IWorldGenerator
{
    public void generate(final Random random, final int chunkX, final int chunkZ, final World world, final IChunkProvider chunkGenerator, final IChunkProvider chunkProvider) {
    }

    public void setBlock(final World world, final int x, final int y, final int z, final Block block, final int metadata) {
        final Block b1 = world.getBlock(x, y, z);
        if (b1.isAir(world, x, y, z) || b1.isLeaves(world, x, y, z)) {
            world.setBlock(x, y, z, block, metadata, 2);
        }
    }

    public boolean generate(final World world, final Random rand, final int i, final int j, final int k) {
        if (world.getBlock(i + 11, j - 1, k + 9) != Dungeons.crystalliumGrass) {
            return false;
        }
        for (int c = 0; c < 30; ++c) {
            if (!world.isAirBlock(i + 11, j + i, k + 9)) {
                return false;
            }
            if (!world.isAirBlock(i + 3, j + i, k + 3)) {
                return false;
            }
            if (!world.isAirBlock(i + 3, j + i, k + 14)) {
                return false;
            }
            if (!world.isAirBlock(i + 14, j + i, k + 3)) {
                return false;
            }
            if (!world.isAirBlock(i + 14, j + i, k + 14)) {
                return false;
            }
        }
        this.setBlock(world, i + 1, j + 9, k + 9, Dungeons.crystalliumLeaves, 0);
        this.setBlock(world, i + 2, j + 8, k + 9, Dungeons.crystalliumLeaves, 0);
        this.setBlock(world, i + 2, j + 9, k + 8, Dungeons.crystalliumLeaves, 0);
        this.setBlock(world, i + 2, j + 9, k + 9, Dungeons.crystalliumLeaves, 0);
        this.setBlock(world, i + 2, j + 9, k + 10, Dungeons.crystalliumLeaves, 0);
        this.setBlock(world, i + 2, j + 10, k + 9, Dungeons.crystalliumLeaves, 0);
        this.setBlock(world, i + 3, j + 8, k + 8, Dungeons.crystalliumLeaves, 0);
        this.setBlock(world, i + 3, j + 8, k + 9, Dungeons.crystalWood, 0);
        this.setBlock(world, i + 3, j + 8, k + 10, Dungeons.crystalliumLeaves, 0);
        this.setBlock(world, i + 3, j + 9, k + 7, Dungeons.crystalliumLeaves, 0);
        this.setBlock(world, i + 3, j + 9, k + 8, Dungeons.crystalliumLeaves, 0);
        this.setBlock(world, i + 3, j + 9, k + 9, Dungeons.crystalWood, 0);
        this.setBlock(world, i + 3, j + 9, k + 10, Dungeons.crystalliumLeaves, 0);
        this.setBlock(world, i + 3, j + 9, k + 11, Dungeons.crystalliumLeaves, 0);
        this.setBlock(world, i + 3, j + 10, k + 8, Dungeons.crystalliumLeaves, 0);
        this.setBlock(world, i + 3, j + 10, k + 9, Dungeons.crystalliumLeaves, 0);
        this.setBlock(world, i + 3, j + 10, k + 10, Dungeons.crystalliumLeaves, 0);
        this.setBlock(world, i + 4, j + 7, k + 8, Dungeons.crystalliumLeaves, 0);
        this.setBlock(world, i + 4, j + 7, k + 9, Dungeons.crystalWood, 0);
        this.setBlock(world, i + 4, j + 8, k + 9, Dungeons.crystalWood, 0);
        this.setBlock(world, i + 4, j + 9, k + 8, Dungeons.crystalliumLeaves, 0);
        this.setBlock(world, i + 4, j + 9, k + 9, Dungeons.crystalliumLeaves, 0);
        this.setBlock(world, i + 4, j + 9, k + 10, Dungeons.crystalliumLeaves, 0);
        this.setBlock(world, i + 4, j + 10, k + 9, Dungeons.crystalliumLeaves, 0);
        this.setBlock(world, i + 5, j + 6, k + 8, Dungeons.crystalliumLeaves, 0);
        this.setBlock(world, i + 5, j + 7, k + 7, Dungeons.crystalliumLeaves, 0);
        this.setBlock(world, i + 5, j + 7, k + 8, Dungeons.crystalliumLeaves, 0);
        this.setBlock(world, i + 5, j + 7, k + 9, Dungeons.crystalWood, 0);
        this.setBlock(world, i + 5, j + 8, k + 8, Dungeons.crystalliumLeaves, 0);
        this.setBlock(world, i + 5, j + 9, k + 9, Dungeons.crystalliumLeaves, 0);
        this.setBlock(world, i + 6, j + 6, k + 9, Dungeons.crystalWood, 0);
        this.setBlock(world, i + 6, j + 6, k + 10, Dungeons.crystalliumLeaves, 0);
        this.setBlock(world, i + 6, j + 7, k + 8, Dungeons.crystalliumLeaves, 0);
        this.setBlock(world, i + 6, j + 7, k + 9, Dungeons.crystalWood, 0);
        this.setBlock(world, i + 6, j + 18, k + 6, Dungeons.crystalliumLeaves, 0);
        this.setBlock(world, i + 6, j + 18, k + 12, Dungeons.crystalliumLeaves, 0);
        this.setBlock(world, i + 6, j + 26, k + 9, Dungeons.crystalliumLeaves, 0);
        this.setBlock(world, i + 7, j + 5, k + 10, Dungeons.crystalliumLeaves, 0);
        this.setBlock(world, i + 7, j + 6, k + 9, Dungeons.crystalWood, 0);
        this.setBlock(world, i + 7, j + 6, k + 10, Dungeons.crystalliumLeaves, 0);
        this.setBlock(world, i + 7, j + 6, k + 11, Dungeons.crystalliumLeaves, 0);
        this.setBlock(world, i + 7, j + 7, k + 10, Dungeons.crystalliumLeaves, 0);
        this.setBlock(world, i + 7, j + 14, k + 7, Dungeons.crystalliumLeaves, 0);
        this.setBlock(world, i + 7, j + 17, k + 6, Dungeons.crystalliumLeaves, 0);
        this.setBlock(world, i + 7, j + 17, k + 12, Dungeons.crystalliumLeaves, 0);
        this.setBlock(world, i + 7, j + 18, k + 5, Dungeons.crystalliumLeaves, 0);
        this.setBlock(world, i + 7, j + 18, k + 6, Dungeons.crystalliumLeaves, 0);
        this.setBlock(world, i + 7, j + 18, k + 7, Dungeons.crystalliumLeaves, 0);
        this.setBlock(world, i + 7, j + 18, k + 11, Dungeons.crystalliumLeaves, 0);
        this.setBlock(world, i + 7, j + 18, k + 12, Dungeons.crystalliumLeaves, 0);
        this.setBlock(world, i + 7, j + 18, k + 13, Dungeons.crystalliumLeaves, 0);
        this.setBlock(world, i + 7, j + 19, k + 6, Dungeons.crystalliumLeaves, 0);
        this.setBlock(world, i + 7, j + 19, k + 12, Dungeons.crystalliumLeaves, 0);
        this.setBlock(world, i + 7, j + 25, k + 9, Dungeons.crystalliumLeaves, 0);
        this.setBlock(world, i + 7, j + 26, k + 8, Dungeons.crystalliumLeaves, 0);
        this.setBlock(world, i + 7, j + 26, k + 9, Dungeons.crystalWood, 0);
        this.setBlock(world, i + 7, j + 26, k + 10, Dungeons.crystalliumLeaves, 0);
        this.setBlock(world, i + 7, j + 27, k + 9, Dungeons.crystalliumLeaves, 0);
        this.setBlock(world, i + 8, j + 5, k + 9, Dungeons.crystalWood, 0);
        this.setBlock(world, i + 8, j + 6, k + 9, Dungeons.crystalWood, 0);
        this.setBlock(world, i + 8, j + 6, k + 10, Dungeons.crystalliumLeaves, 0);
        this.setBlock(world, i + 8, j + 13, k + 7, Dungeons.crystalliumLeaves, 0);
        this.setBlock(world, i + 8, j + 14, k + 6, Dungeons.crystalliumLeaves, 0);
        this.setBlock(world, i + 8, j + 14, k + 7, Dungeons.crystalWood, 0);
        this.setBlock(world, i + 8, j + 14, k + 8, Dungeons.crystalliumLeaves, 0);
        this.setBlock(world, i + 8, j + 15, k + 7, Dungeons.crystalliumLeaves, 0);
        this.setBlock(world, i + 8, j + 17, k + 5, Dungeons.crystalliumLeaves, 0);
        this.setBlock(world, i + 8, j + 17, k + 6, Dungeons.crystalliumLeaves, 0);
        this.setBlock(world, i + 8, j + 17, k + 7, Dungeons.crystalliumLeaves, 0);
        this.setBlock(world, i + 8, j + 17, k + 11, Dungeons.crystalliumLeaves, 0);
        this.setBlock(world, i + 8, j + 17, k + 12, Dungeons.crystalliumLeaves, 0);
        this.setBlock(world, i + 8, j + 17, k + 13, Dungeons.crystalliumLeaves, 0);
        this.setBlock(world, i + 8, j + 18, k + 4, Dungeons.crystalliumLeaves, 0);
        this.setBlock(world, i + 8, j + 18, k + 5, Dungeons.crystalliumLeaves, 0);
        this.setBlock(world, i + 8, j + 18, k + 6, Dungeons.crystalWood, 0);
        this.setBlock(world, i + 8, j + 18, k + 7, Dungeons.crystalliumLeaves, 0);
        this.setBlock(world, i + 8, j + 18, k + 8, Dungeons.crystalliumLeaves, 0);
        this.setBlock(world, i + 8, j + 18, k + 10, Dungeons.crystalliumLeaves, 0);
        this.setBlock(world, i + 8, j + 18, k + 11, Dungeons.crystalliumLeaves, 0);
        this.setBlock(world, i + 8, j + 18, k + 12, Dungeons.crystalWood, 0);
        this.setBlock(world, i + 8, j + 18, k + 13, Dungeons.crystalliumLeaves, 0);
        this.setBlock(world, i + 8, j + 18, k + 14, Dungeons.crystalliumLeaves, 0);
        this.setBlock(world, i + 8, j + 19, k + 5, Dungeons.crystalliumLeaves, 0);
        this.setBlock(world, i + 8, j + 19, k + 6, Dungeons.crystalliumLeaves, 0);
        this.setBlock(world, i + 8, j + 19, k + 7, Dungeons.crystalliumLeaves, 0);
        this.setBlock(world, i + 8, j + 19, k + 11, Dungeons.crystalliumLeaves, 0);
        this.setBlock(world, i + 8, j + 19, k + 12, Dungeons.crystalliumLeaves, 0);
        this.setBlock(world, i + 8, j + 19, k + 13, Dungeons.crystalliumLeaves, 0);
        this.setBlock(world, i + 8, j + 26, k + 8, Dungeons.crystalliumLeaves, 0);
        this.setBlock(world, i + 8, j + 26, k + 9, Dungeons.crystalWood, 0);
        this.setBlock(world, i + 9, j + 5, k + 9, Dungeons.crystalWood, 0);
        this.setBlock(world, i + 9, j + 7, k + 13, Dungeons.crystalliumLeaves, 0);
        this.setBlock(world, i + 9, j + 8, k + 6, Dungeons.crystalliumLeaves, 0);
        this.setBlock(world, i + 9, j + 10, k + 16, Dungeons.crystalliumLeaves, 0);
        this.setBlock(world, i + 9, j + 11, k + 3, Dungeons.crystalliumLeaves, 0);
        this.setBlock(world, i + 9, j + 12, k + 10, Dungeons.crystalliumLeaves, 0);
        this.setBlock(world, i + 9, j + 13, k + 7, Dungeons.crystalWood, 0);
        this.setBlock(world, i + 9, j + 13, k + 8, Dungeons.crystalWood, 0);
        this.setBlock(world, i + 9, j + 14, k + 7, Dungeons.crystalliumLeaves, 0);
        this.setBlock(world, i + 9, j + 17, k + 6, Dungeons.crystalliumLeaves, 0);
        this.setBlock(world, i + 9, j + 17, k + 12, Dungeons.crystalliumLeaves, 0);
        this.setBlock(world, i + 9, j + 18, k + 5, Dungeons.crystalliumLeaves, 0);
        this.setBlock(world, i + 9, j + 18, k + 6, Dungeons.crystalliumLeaves, 0);
        this.setBlock(world, i + 9, j + 18, k + 7, Dungeons.crystalWood, 0);
        this.setBlock(world, i + 9, j + 18, k + 11, Dungeons.crystalWood, 0);
        this.setBlock(world, i + 9, j + 18, k + 12, Dungeons.crystalliumLeaves, 0);
        this.setBlock(world, i + 9, j + 18, k + 13, Dungeons.crystalliumLeaves, 0);
        this.setBlock(world, i + 9, j + 19, k + 6, Dungeons.crystalliumLeaves, 0);
        this.setBlock(world, i + 9, j + 19, k + 11, Dungeons.crystalliumLeaves, 0);
        this.setBlock(world, i + 9, j + 19, k + 12, Dungeons.crystalliumLeaves, 0);
        this.setBlock(world, i + 9, j + 25, k + 8, Dungeons.crystalliumLeaves, 0);
        this.setBlock(world, i + 9, j + 26, k + 7, Dungeons.crystalliumLeaves, 0);
        this.setBlock(world, i + 9, j + 26, k + 8, Dungeons.crystalliumLeaves, 0);
        this.setBlock(world, i + 9, j + 26, k + 9, Dungeons.crystalWood, 0);
        this.setBlock(world, i + 9, j + 27, k + 8, Dungeons.crystalliumLeaves, 0);
        this.setBlock(world, i + 10, j, k + 8, Dungeons.crystalWood, 0);
        this.setBlock(world, i + 10, j, k + 9, Dungeons.crystalWood, 0);
        this.setBlock(world, i + 10, j, k + 10, Dungeons.crystalWood, 0);
        this.setBlock(world, i + 10, j + 1, k + 8, Dungeons.crystalWood, 0);
        this.setBlock(world, i + 10, j + 1, k + 9, Dungeons.crystalWood, 0);
        this.setBlock(world, i + 10, j + 1, k + 10, Dungeons.crystalWood, 0);
        this.setBlock(world, i + 10, j + 2, k + 8, Dungeons.crystalWood, 0);
        this.setBlock(world, i + 10, j + 2, k + 9, Dungeons.crystalWood, 0);
        this.setBlock(world, i + 10, j + 2, k + 10, Dungeons.crystalWood, 0);
        this.setBlock(world, i + 10, j + 3, k + 8, Dungeons.crystalWood, 0);
        this.setBlock(world, i + 10, j + 3, k + 9, Dungeons.crystalWood, 0);
        this.setBlock(world, i + 10, j + 3, k + 10, Dungeons.crystalWood, 0);
        this.setBlock(world, i + 10, j + 3, k + 11, Dungeons.crystalliumLeaves, 0);
        this.setBlock(world, i + 10, j + 4, k + 7, Dungeons.crystalliumLeaves, 0);
        this.setBlock(world, i + 10, j + 4, k + 8, Dungeons.crystalWood, 0);
        this.setBlock(world, i + 10, j + 4, k + 9, Dungeons.crystalWood, 0);
        this.setBlock(world, i + 10, j + 4, k + 10, Dungeons.crystalWood, 0);
        this.setBlock(world, i + 10, j + 5, k + 8, Dungeons.crystalWood, 0);
        this.setBlock(world, i + 10, j + 5, k + 9, Dungeons.crystalWood, 0);
        this.setBlock(world, i + 10, j + 5, k + 10, Dungeons.crystalWood, 0);
        this.setBlock(world, i + 10, j + 6, k + 8, Dungeons.crystalWood, 0);
        this.setBlock(world, i + 10, j + 6, k + 9, Dungeons.crystalWood, 0);
        this.setBlock(world, i + 10, j + 6, k + 10, Dungeons.crystalWood, 0);
        this.setBlock(world, i + 10, j + 6, k + 13, Dungeons.crystalliumLeaves, 0);
        this.setBlock(world, i + 10, j + 7, k + 6, Dungeons.crystalliumLeaves, 0);
        this.setBlock(world, i + 10, j + 7, k + 8, Dungeons.crystalWood, 0);
        this.setBlock(world, i + 10, j + 7, k + 9, Dungeons.crystalWood, 0);
        this.setBlock(world, i + 10, j + 7, k + 10, Dungeons.crystalWood, 0);
        this.setBlock(world, i + 10, j + 7, k + 12, Dungeons.crystalliumLeaves, 0);
        this.setBlock(world, i + 10, j + 7, k + 13, Dungeons.crystalliumLeaves, 0);
        this.setBlock(world, i + 10, j + 7, k + 14, Dungeons.crystalliumLeaves, 0);
        this.setBlock(world, i + 10, j + 8, k + 5, Dungeons.crystalliumLeaves, 0);
        this.setBlock(world, i + 10, j + 8, k + 6, Dungeons.crystalliumLeaves, 0);
        this.setBlock(world, i + 10, j + 8, k + 7, Dungeons.crystalliumLeaves, 0);
        this.setBlock(world, i + 10, j + 8, k + 8, Dungeons.crystalWood, 0);
        this.setBlock(world, i + 10, j + 8, k + 9, Dungeons.crystalWood, 0);
        this.setBlock(world, i + 10, j + 8, k + 10, Dungeons.crystalWood, 0);
        this.setBlock(world, i + 10, j + 8, k + 13, Dungeons.crystalliumLeaves, 0);
        this.setBlock(world, i + 10, j + 9, k + 6, Dungeons.crystalliumLeaves, 0);
        this.setBlock(world, i + 10, j + 9, k + 8, Dungeons.crystalWood, 0);
        this.setBlock(world, i + 10, j + 9, k + 9, Dungeons.crystalWood, 0);
        this.setBlock(world, i + 10, j + 9, k + 10, Dungeons.crystalWood, 0);
        this.setBlock(world, i + 10, j + 9, k + 16, Dungeons.crystalliumLeaves, 0);
        this.setBlock(world, i + 10, j + 10, k + 3, Dungeons.crystalliumLeaves, 0);
        this.setBlock(world, i + 10, j + 10, k + 8, Dungeons.crystalWood, 0);
        this.setBlock(world, i + 10, j + 10, k + 9, Dungeons.crystalWood, 0);
        this.setBlock(world, i + 10, j + 10, k + 15, Dungeons.crystalliumLeaves, 0);
        this.setBlock(world, i + 10, j + 10, k + 16, Dungeons.crystalliumLeaves, 0);
        this.setBlock(world, i + 10, j + 10, k + 17, Dungeons.crystalliumLeaves, 0);
        this.setBlock(world, i + 10, j + 11, k + 2, Dungeons.crystalliumLeaves, 0);
        this.setBlock(world, i + 10, j + 11, k + 3, Dungeons.crystalliumLeaves, 0);
        this.setBlock(world, i + 10, j + 11, k + 4, Dungeons.crystalliumLeaves, 0);
        this.setBlock(world, i + 10, j + 11, k + 9, Dungeons.crystalWood, 0);
        this.setBlock(world, i + 10, j + 11, k + 10, Dungeons.crystalliumLeaves, 0);
        this.setBlock(world, i + 10, j + 11, k + 16, Dungeons.crystalliumLeaves, 0);
        this.setBlock(world, i + 10, j + 12, k + 3, Dungeons.crystalliumLeaves, 0);
        this.setBlock(world, i + 10, j + 12, k + 9, Dungeons.crystalWood, 0);
        this.setBlock(world, i + 10, j + 12, k + 10, Dungeons.crystalliumLeaves, 0);
        this.setBlock(world, i + 10, j + 12, k + 11, Dungeons.crystalliumLeaves, 0);
        this.setBlock(world, i + 10, j + 13, k + 8, Dungeons.crystalWood, 0);
        this.setBlock(world, i + 10, j + 13, k + 9, Dungeons.crystalWood, 0);
        this.setBlock(world, i + 10, j + 13, k + 10, Dungeons.crystalliumLeaves, 0);
        this.setBlock(world, i + 10, j + 14, k + 9, Dungeons.crystalWood, 0);
        this.setBlock(world, i + 10, j + 15, k + 9, Dungeons.crystalWood, 0);
        this.setBlock(world, i + 10, j + 16, k + 9, Dungeons.crystalWood, 0);
        this.setBlock(world, i + 10, j + 17, k + 8, Dungeons.crystalWood, 0);
        this.setBlock(world, i + 10, j + 17, k + 9, Dungeons.crystalWood, 0);
        this.setBlock(world, i + 10, j + 17, k + 10, Dungeons.crystalWood, 0);
        this.setBlock(world, i + 10, j + 18, k + 6, Dungeons.crystalliumLeaves, 0);
        this.setBlock(world, i + 10, j + 18, k + 7, Dungeons.crystalliumLeaves, 0);
        this.setBlock(world, i + 10, j + 18, k + 8, Dungeons.crystalliumLeaves, 0);
        this.setBlock(world, i + 10, j + 18, k + 9, Dungeons.crystalliumLeaves, 0);
        this.setBlock(world, i + 10, j + 18, k + 10, Dungeons.crystalliumLeaves, 0);
        this.setBlock(world, i + 10, j + 18, k + 12, Dungeons.crystalliumLeaves, 0);
        this.setBlock(world, i + 10, j + 19, k + 8, Dungeons.crystalliumLeaves, 0);
        this.setBlock(world, i + 10, j + 24, k + 13, Dungeons.crystalliumLeaves, 0);
        this.setBlock(world, i + 10, j + 25, k + 5, Dungeons.crystalliumLeaves, 0);
        this.setBlock(world, i + 10, j + 25, k + 9, Dungeons.crystalWood, 0);
        this.setBlock(world, i + 10, j + 25, k + 10, Dungeons.crystalliumLeaves, 0);
        this.setBlock(world, i + 10, j + 26, k + 8, Dungeons.crystalliumLeaves, 0);
        this.setBlock(world, i + 10, j + 26, k + 9, Dungeons.crystalWood, 0);
        this.setBlock(world, i + 10, j + 26, k + 10, Dungeons.crystalliumLeaves, 0);
        this.setBlock(world, i + 10, j + 27, k + 9, Dungeons.crystalliumLeaves, 0);
        this.setBlock(world, i + 11, j, k + 8, Dungeons.crystalWood, 0);
        this.setBlock(world, i + 11, j, k + 9, Dungeons.crystalWood, 0);
        this.setBlock(world, i + 11, j, k + 10, Dungeons.crystalWood, 0);
        this.setBlock(world, i + 11, j + 1, k + 8, Dungeons.crystalWood, 0);
        this.setBlock(world, i + 11, j + 1, k + 9, Dungeons.crystalWood, 0);
        this.setBlock(world, i + 11, j + 1, k + 10, Dungeons.crystalWood, 0);
        this.setBlock(world, i + 11, j + 2, k + 8, Dungeons.crystalWood, 0);
        this.setBlock(world, i + 11, j + 2, k + 9, Dungeons.crystalWood, 0);
        this.setBlock(world, i + 11, j + 2, k + 10, Dungeons.crystalWood, 0);
        this.setBlock(world, i + 11, j + 2, k + 11, Dungeons.crystalliumLeaves, 0);
        this.setBlock(world, i + 11, j + 3, k + 7, Dungeons.crystalliumLeaves, 0);
        this.setBlock(world, i + 11, j + 3, k + 8, Dungeons.crystalWood, 0);
        this.setBlock(world, i + 11, j + 3, k + 9, Dungeons.crystalWood, 0);
        this.setBlock(world, i + 11, j + 3, k + 10, Dungeons.crystalWood, 0);
        this.setBlock(world, i + 11, j + 3, k + 11, Dungeons.crystalliumLeaves, 0);
        this.setBlock(world, i + 11, j + 3, k + 12, Dungeons.crystalliumLeaves, 0);
        this.setBlock(world, i + 11, j + 4, k + 6, Dungeons.crystalliumLeaves, 0);
        this.setBlock(world, i + 11, j + 4, k + 7, Dungeons.crystalliumLeaves, 0);
        this.setBlock(world, i + 11, j + 4, k + 8, Dungeons.crystalWood, 0);
        this.setBlock(world, i + 11, j + 4, k + 9, Dungeons.crystalWood, 0);
        this.setBlock(world, i + 11, j + 4, k + 10, Dungeons.crystalWood, 0);
        this.setBlock(world, i + 11, j + 4, k + 11, Dungeons.crystalliumLeaves, 0);
        this.setBlock(world, i + 11, j + 5, k + 7, Dungeons.crystalliumLeaves, 0);
        this.setBlock(world, i + 11, j + 5, k + 8, Dungeons.crystalWood, 0);
        this.setBlock(world, i + 11, j + 5, k + 9, Dungeons.crystalWood, 0);
        this.setBlock(world, i + 11, j + 5, k + 10, Dungeons.crystalWood, 0);
        this.setBlock(world, i + 11, j + 6, k + 8, Dungeons.crystalWood, 0);
        this.setBlock(world, i + 11, j + 6, k + 9, Dungeons.crystalWood, 0);
        this.setBlock(world, i + 11, j + 6, k + 10, Dungeons.crystalWood, 0);
        this.setBlock(world, i + 11, j + 6, k + 11, Dungeons.crystalWood, 0);
        this.setBlock(world, i + 11, j + 6, k + 12, Dungeons.crystalWood, 0);
        this.setBlock(world, i + 11, j + 7, k + 8, Dungeons.crystalWood, 0);
        this.setBlock(world, i + 11, j + 7, k + 9, Dungeons.crystalWood, 0);
        this.setBlock(world, i + 11, j + 7, k + 10, Dungeons.crystalWood, 0);
        this.setBlock(world, i + 11, j + 7, k + 12, Dungeons.crystalWood, 0);
        this.setBlock(world, i + 11, j + 7, k + 13, Dungeons.crystalWood, 0);
        this.setBlock(world, i + 11, j + 7, k + 14, Dungeons.crystalWood, 0);
        this.setBlock(world, i + 11, j + 8, k + 5, Dungeons.crystalWood, 0);
        this.setBlock(world, i + 11, j + 8, k + 6, Dungeons.crystalWood, 0);
        this.setBlock(world, i + 11, j + 8, k + 7, Dungeons.crystalWood, 0);
        this.setBlock(world, i + 11, j + 8, k + 8, Dungeons.crystalWood, 0);
        this.setBlock(world, i + 11, j + 8, k + 9, Dungeons.crystalWood, 0);
        this.setBlock(world, i + 11, j + 8, k + 10, Dungeons.crystalWood, 0);
        this.setBlock(world, i + 11, j + 8, k + 14, Dungeons.crystalWood, 0);
        this.setBlock(world, i + 11, j + 8, k + 15, Dungeons.crystalWood, 0);
        this.setBlock(world, i + 11, j + 9, k + 4, Dungeons.crystalWood, 0);
        this.setBlock(world, i + 11, j + 9, k + 5, Dungeons.crystalWood, 0);
        this.setBlock(world, i + 11, j + 9, k + 8, Dungeons.crystalWood, 0);
        this.setBlock(world, i + 11, j + 9, k + 9, Dungeons.crystalWood, 0);
        this.setBlock(world, i + 11, j + 9, k + 10, Dungeons.crystalWood, 0);
        this.setBlock(world, i + 11, j + 9, k + 15, Dungeons.crystalWood, 0);
        this.setBlock(world, i + 11, j + 9, k + 16, Dungeons.crystalWood, 0);
        this.setBlock(world, i + 11, j + 9, k + 17, Dungeons.crystalliumLeaves, 0);
        this.setBlock(world, i + 11, j + 10, k + 2, Dungeons.crystalliumLeaves, 0);
        this.setBlock(world, i + 11, j + 10, k + 3, Dungeons.crystalWood, 0);
        this.setBlock(world, i + 11, j + 10, k + 4, Dungeons.crystalWood, 0);
        this.setBlock(world, i + 11, j + 10, k + 8, Dungeons.crystalWood, 0);
        this.setBlock(world, i + 11, j + 10, k + 9, Dungeons.crystalWood, 0);
        this.setBlock(world, i + 11, j + 10, k + 10, Dungeons.crystalWood, 0);
        this.setBlock(world, i + 11, j + 10, k + 14, Dungeons.crystalliumLeaves, 0);
        this.setBlock(world, i + 11, j + 10, k + 15, Dungeons.crystalliumLeaves, 0);
        this.setBlock(world, i + 11, j + 10, k + 16, Dungeons.crystalWood, 0);
        this.setBlock(world, i + 11, j + 10, k + 17, Dungeons.crystalliumLeaves, 0);
        this.setBlock(world, i + 11, j + 10, k + 18, Dungeons.crystalliumLeaves, 0);
        this.setBlock(world, i + 11, j + 11, k + 1, Dungeons.crystalliumLeaves, 0);
        this.setBlock(world, i + 11, j + 11, k + 2, Dungeons.crystalliumLeaves, 0);
        this.setBlock(world, i + 11, j + 11, k + 3, Dungeons.crystalWood, 0);
        this.setBlock(world, i + 11, j + 11, k + 4, Dungeons.crystalliumLeaves, 0);
        this.setBlock(world, i + 11, j + 11, k + 5, Dungeons.crystalliumLeaves, 0);
        this.setBlock(world, i + 11, j + 11, k + 8, Dungeons.crystalWood, 0);
        this.setBlock(world, i + 11, j + 11, k + 9, Dungeons.crystalWood, 0);
        this.setBlock(world, i + 11, j + 11, k + 10, Dungeons.crystalWood, 0);
        this.setBlock(world, i + 11, j + 11, k + 15, Dungeons.crystalliumLeaves, 0);
        this.setBlock(world, i + 11, j + 11, k + 16, Dungeons.crystalliumLeaves, 0);
        this.setBlock(world, i + 11, j + 11, k + 17, Dungeons.crystalliumLeaves, 0);
        this.setBlock(world, i + 11, j + 12, k + 2, Dungeons.crystalliumLeaves, 0);
        this.setBlock(world, i + 11, j + 12, k + 3, Dungeons.crystalliumLeaves, 0);
        this.setBlock(world, i + 11, j + 12, k + 4, Dungeons.crystalliumLeaves, 0);
        this.setBlock(world, i + 11, j + 12, k + 8, Dungeons.crystalWood, 0);
        this.setBlock(world, i + 11, j + 12, k + 9, Dungeons.crystalWood, 0);
        this.setBlock(world, i + 11, j + 12, k + 10, Dungeons.crystalWood, 0);
        this.setBlock(world, i + 11, j + 13, k + 8, Dungeons.crystalWood, 0);
        this.setBlock(world, i + 11, j + 13, k + 9, Dungeons.crystalWood, 0);
        this.setBlock(world, i + 11, j + 13, k + 10, Dungeons.crystalWood, 0);
        this.setBlock(world, i + 11, j + 14, k + 8, Dungeons.crystalWood, 0);
        this.setBlock(world, i + 11, j + 14, k + 9, Dungeons.crystalWood, 0);
        this.setBlock(world, i + 11, j + 14, k + 10, Dungeons.crystalWood, 0);
        this.setBlock(world, i + 11, j + 15, k + 8, Dungeons.crystalWood, 0);
        this.setBlock(world, i + 11, j + 15, k + 9, Dungeons.crystalWood, 0);
        this.setBlock(world, i + 11, j + 15, k + 10, Dungeons.crystalWood, 0);
        this.setBlock(world, i + 11, j + 16, k + 8, Dungeons.crystalWood, 0);
        this.setBlock(world, i + 11, j + 16, k + 9, Dungeons.crystalWood, 0);
        this.setBlock(world, i + 11, j + 16, k + 10, Dungeons.crystalWood, 0);
        this.setBlock(world, i + 11, j + 17, k + 7, Dungeons.crystalliumLeaves, 0);
        this.setBlock(world, i + 11, j + 17, k + 8, Dungeons.crystalWood, 0);
        this.setBlock(world, i + 11, j + 17, k + 9, Dungeons.crystalWood, 0);
        this.setBlock(world, i + 11, j + 17, k + 10, Dungeons.crystalWood, 0);
        this.setBlock(world, i + 11, j + 18, k + 6, Dungeons.crystalliumLeaves, 0);
        this.setBlock(world, i + 11, j + 18, k + 7, Dungeons.crystalliumLeaves, 0);
        this.setBlock(world, i + 11, j + 18, k + 8, Dungeons.crystalWood, 0);
        this.setBlock(world, i + 11, j + 18, k + 9, Dungeons.crystalWood, 0);
        this.setBlock(world, i + 11, j + 18, k + 10, Dungeons.crystalliumLeaves, 0);
        this.setBlock(world, i + 11, j + 19, k + 7, Dungeons.crystalliumLeaves, 0);
        this.setBlock(world, i + 11, j + 19, k + 8, Dungeons.crystalliumLeaves, 0);
        this.setBlock(world, i + 11, j + 19, k + 9, Dungeons.crystalWood, 0);
        this.setBlock(world, i + 11, j + 20, k + 8, Dungeons.crystalliumLeaves, 0);
        this.setBlock(world, i + 11, j + 20, k + 9, Dungeons.crystalWood, 0);
        this.setBlock(world, i + 11, j + 21, k + 9, Dungeons.crystalWood, 0);
        this.setBlock(world, i + 11, j + 22, k + 9, Dungeons.crystalWood, 0);
        this.setBlock(world, i + 11, j + 23, k + 9, Dungeons.crystalWood, 0);
        this.setBlock(world, i + 11, j + 23, k + 10, Dungeons.crystalWood, 0);
        this.setBlock(world, i + 11, j + 23, k + 13, Dungeons.crystalliumLeaves, 0);
        this.setBlock(world, i + 11, j + 24, k + 5, Dungeons.crystalliumLeaves, 0);
        this.setBlock(world, i + 11, j + 24, k + 8, Dungeons.crystalWood, 0);
        this.setBlock(world, i + 11, j + 24, k + 9, Dungeons.crystalWood, 0);
        this.setBlock(world, i + 11, j + 24, k + 10, Dungeons.crystalWood, 0);
        this.setBlock(world, i + 11, j + 24, k + 11, Dungeons.crystalWood, 0);
        this.setBlock(world, i + 11, j + 24, k + 12, Dungeons.crystalWood, 0);
        this.setBlock(world, i + 11, j + 24, k + 13, Dungeons.crystalWood, 0);
        this.setBlock(world, i + 11, j + 24, k + 14, Dungeons.crystalliumLeaves, 0);
        this.setBlock(world, i + 11, j + 25, k + 4, Dungeons.crystalliumLeaves, 0);
        this.setBlock(world, i + 11, j + 25, k + 5, Dungeons.crystalWood, 0);
        this.setBlock(world, i + 11, j + 25, k + 6, Dungeons.crystalWood, 0);
        this.setBlock(world, i + 11, j + 25, k + 7, Dungeons.crystalWood, 0);
        this.setBlock(world, i + 11, j + 25, k + 8, Dungeons.crystalWood, 0);
        this.setBlock(world, i + 11, j + 25, k + 9, Dungeons.crystalWood, 0);
        this.setBlock(world, i + 11, j + 25, k + 10, Dungeons.crystalliumLeaves, 0);
        this.setBlock(world, i + 11, j + 25, k + 11, Dungeons.crystalliumLeaves, 0);
        this.setBlock(world, i + 11, j + 25, k + 13, Dungeons.crystalliumLeaves, 0);
        this.setBlock(world, i + 11, j + 26, k + 5, Dungeons.crystalliumLeaves, 0);
        this.setBlock(world, i + 11, j + 26, k + 7, Dungeons.crystalliumLeaves, 0);
        this.setBlock(world, i + 11, j + 26, k + 8, Dungeons.crystalliumLeaves, 0);
        this.setBlock(world, i + 11, j + 26, k + 9, Dungeons.crystalliumLeaves, 0);
        this.setBlock(world, i + 11, j + 26, k + 10, Dungeons.crystalliumLeaves, 0);
        this.setBlock(world, i + 11, j + 26, k + 11, Dungeons.crystalliumLeaves, 0);
        this.setBlock(world, i + 11, j + 27, k + 8, Dungeons.crystalliumLeaves, 0);
        this.setBlock(world, i + 11, j + 27, k + 9, Dungeons.crystalliumLeaves, 0);
        this.setBlock(world, i + 11, j + 27, k + 10, Dungeons.crystalliumLeaves, 0);
        this.setBlock(world, i + 11, j + 28, k + 9, Dungeons.crystalliumLeaves, 0);
        this.setBlock(world, i + 12, j, k + 8, Dungeons.crystalWood, 0);
        this.setBlock(world, i + 12, j, k + 9, Dungeons.crystalWood, 0);
        this.setBlock(world, i + 12, j, k + 10, Dungeons.crystalWood, 0);
        this.setBlock(world, i + 12, j + 1, k + 8, Dungeons.crystalWood, 0);
        this.setBlock(world, i + 12, j + 1, k + 9, Dungeons.crystalWood, 0);
        this.setBlock(world, i + 12, j + 1, k + 10, Dungeons.crystalWood, 0);
        this.setBlock(world, i + 12, j + 2, k + 8, Dungeons.crystalWood, 0);
        this.setBlock(world, i + 12, j + 2, k + 9, Dungeons.crystalWood, 0);
        this.setBlock(world, i + 12, j + 2, k + 10, Dungeons.crystalWood, 0);
        this.setBlock(world, i + 12, j + 3, k + 8, Dungeons.crystalWood, 0);
        this.setBlock(world, i + 12, j + 3, k + 9, Dungeons.crystalWood, 0);
        this.setBlock(world, i + 12, j + 3, k + 10, Dungeons.crystalWood, 0);
        this.setBlock(world, i + 12, j + 3, k + 11, Dungeons.crystalliumLeaves, 0);
        this.setBlock(world, i + 12, j + 4, k + 7, Dungeons.crystalliumLeaves, 0);
        this.setBlock(world, i + 12, j + 4, k + 8, Dungeons.crystalWood, 0);
        this.setBlock(world, i + 12, j + 4, k + 9, Dungeons.crystalWood, 0);
        this.setBlock(world, i + 12, j + 4, k + 10, Dungeons.crystalWood, 0);
        this.setBlock(world, i + 12, j + 5, k + 8, Dungeons.crystalWood, 0);
        this.setBlock(world, i + 12, j + 5, k + 9, Dungeons.crystalWood, 0);
        this.setBlock(world, i + 12, j + 5, k + 10, Dungeons.crystalWood, 0);
        this.setBlock(world, i + 12, j + 6, k + 8, Dungeons.crystalWood, 0);
        this.setBlock(world, i + 12, j + 6, k + 9, Dungeons.crystalWood, 0);
        this.setBlock(world, i + 12, j + 6, k + 10, Dungeons.crystalWood, 0);
        this.setBlock(world, i + 12, j + 6, k + 14, Dungeons.crystalliumLeaves, 0);
        this.setBlock(world, i + 12, j + 7, k + 6, Dungeons.crystalliumLeaves, 0);
        this.setBlock(world, i + 12, j + 7, k + 8, Dungeons.crystalWood, 0);
        this.setBlock(world, i + 12, j + 7, k + 9, Dungeons.crystalWood, 0);
        this.setBlock(world, i + 12, j + 7, k + 10, Dungeons.crystalWood, 0);
        this.setBlock(world, i + 12, j + 7, k + 13, Dungeons.crystalliumLeaves, 0);
        this.setBlock(world, i + 12, j + 7, k + 14, Dungeons.crystalliumLeaves, 0);
        this.setBlock(world, i + 12, j + 7, k + 15, Dungeons.crystalliumLeaves, 0);
        this.setBlock(world, i + 12, j + 8, k + 5, Dungeons.crystalliumLeaves, 0);
        this.setBlock(world, i + 12, j + 8, k + 6, Dungeons.crystalliumLeaves, 0);
        this.setBlock(world, i + 12, j + 8, k + 7, Dungeons.crystalliumLeaves, 0);
        this.setBlock(world, i + 12, j + 8, k + 8, Dungeons.crystalWood, 0);
        this.setBlock(world, i + 12, j + 8, k + 9, Dungeons.crystalWood, 0);
        this.setBlock(world, i + 12, j + 8, k + 10, Dungeons.crystalWood, 0);
        this.setBlock(world, i + 12, j + 8, k + 14, Dungeons.crystalliumLeaves, 0);
        this.setBlock(world, i + 12, j + 9, k + 6, Dungeons.crystalliumLeaves, 0);
        this.setBlock(world, i + 12, j + 9, k + 9, Dungeons.crystalWood, 0);
        this.setBlock(world, i + 12, j + 9, k + 10, Dungeons.crystalWood, 0);
        this.setBlock(world, i + 12, j + 9, k + 16, Dungeons.crystalliumLeaves, 0);
        this.setBlock(world, i + 12, j + 10, k + 3, Dungeons.crystalliumLeaves, 0);
        this.setBlock(world, i + 12, j + 10, k + 9, Dungeons.crystalWood, 0);
        this.setBlock(world, i + 12, j + 10, k + 15, Dungeons.crystalliumLeaves, 0);
        this.setBlock(world, i + 12, j + 10, k + 16, Dungeons.crystalliumLeaves, 0);
        this.setBlock(world, i + 12, j + 10, k + 17, Dungeons.crystalliumLeaves, 0);
        this.setBlock(world, i + 12, j + 11, k + 2, Dungeons.crystalliumLeaves, 0);
        this.setBlock(world, i + 12, j + 11, k + 3, Dungeons.crystalliumLeaves, 0);
        this.setBlock(world, i + 12, j + 11, k + 4, Dungeons.crystalliumLeaves, 0);
        this.setBlock(world, i + 12, j + 11, k + 9, Dungeons.crystalWood, 0);
        this.setBlock(world, i + 12, j + 11, k + 16, Dungeons.crystalliumLeaves, 0);
        this.setBlock(world, i + 12, j + 12, k + 3, Dungeons.crystalliumLeaves, 0);
        this.setBlock(world, i + 12, j + 12, k + 9, Dungeons.crystalWood, 0);
        this.setBlock(world, i + 12, j + 13, k + 8, Dungeons.crystalliumLeaves, 0);
        this.setBlock(world, i + 12, j + 13, k + 9, Dungeons.crystalWood, 0);
        this.setBlock(world, i + 12, j + 14, k + 7, Dungeons.crystalliumLeaves, 0);
        this.setBlock(world, i + 12, j + 14, k + 8, Dungeons.crystalliumLeaves, 0);
        this.setBlock(world, i + 12, j + 14, k + 9, Dungeons.crystalWood, 0);
        this.setBlock(world, i + 12, j + 14, k + 10, Dungeons.crystalWood, 0);
        this.setBlock(world, i + 12, j + 14, k + 11, Dungeons.crystalWood, 0);
        this.setBlock(world, i + 12, j + 14, k + 12, Dungeons.crystalliumLeaves, 0);
        this.setBlock(world, i + 12, j + 15, k + 8, Dungeons.crystalliumLeaves, 0);
        this.setBlock(world, i + 12, j + 15, k + 9, Dungeons.crystalWood, 0);
        this.setBlock(world, i + 12, j + 16, k + 9, Dungeons.crystalWood, 0);
        this.setBlock(world, i + 12, j + 17, k + 9, Dungeons.crystalWood, 0);
        this.setBlock(world, i + 12, j + 17, k + 10, Dungeons.crystalWood, 0);
        this.setBlock(world, i + 12, j + 18, k + 7, Dungeons.crystalliumLeaves, 0);
        this.setBlock(world, i + 12, j + 18, k + 8, Dungeons.crystalWood, 0);
        this.setBlock(world, i + 12, j + 18, k + 9, Dungeons.crystalWood, 0);
        this.setBlock(world, i + 12, j + 18, k + 10, Dungeons.crystalliumLeaves, 0);
        this.setBlock(world, i + 12, j + 18, k + 12, Dungeons.crystalliumLeaves, 0);
        this.setBlock(world, i + 12, j + 19, k + 6, Dungeons.crystalliumLeaves, 0);
        this.setBlock(world, i + 12, j + 19, k + 8, Dungeons.crystalliumLeaves, 0);
        this.setBlock(world, i + 12, j + 19, k + 9, Dungeons.crystalliumLeaves, 0);
        this.setBlock(world, i + 12, j + 24, k + 8, Dungeons.crystalliumLeaves, 0);
        this.setBlock(world, i + 12, j + 24, k + 13, Dungeons.crystalliumLeaves, 0);
        this.setBlock(world, i + 12, j + 25, k + 5, Dungeons.crystalliumLeaves, 0);
        this.setBlock(world, i + 12, j + 25, k + 7, Dungeons.crystalliumLeaves, 0);
        this.setBlock(world, i + 12, j + 25, k + 8, Dungeons.crystalliumLeaves, 0);
        this.setBlock(world, i + 12, j + 25, k + 9, Dungeons.crystalWood, 0);
        this.setBlock(world, i + 12, j + 26, k + 8, Dungeons.crystalliumLeaves, 0);
        this.setBlock(world, i + 12, j + 26, k + 9, Dungeons.crystalWood, 0);
        this.setBlock(world, i + 12, j + 26, k + 10, Dungeons.crystalliumLeaves, 0);
        this.setBlock(world, i + 12, j + 27, k + 9, Dungeons.crystalliumLeaves, 0);
        this.setBlock(world, i + 13, j + 5, k + 9, Dungeons.crystalWood, 0);
        this.setBlock(world, i + 13, j + 7, k + 14, Dungeons.crystalliumLeaves, 0);
        this.setBlock(world, i + 13, j + 8, k + 6, Dungeons.crystalliumLeaves, 0);
        this.setBlock(world, i + 13, j + 10, k + 16, Dungeons.crystalliumLeaves, 0);
        this.setBlock(world, i + 13, j + 11, k + 3, Dungeons.crystalliumLeaves, 0);
        this.setBlock(world, i + 13, j + 13, k + 12, Dungeons.crystalliumLeaves, 0);
        this.setBlock(world, i + 13, j + 14, k + 8, Dungeons.crystalliumLeaves, 0);
        this.setBlock(world, i + 13, j + 14, k + 11, Dungeons.crystalliumLeaves, 0);
        this.setBlock(world, i + 13, j + 14, k + 12, Dungeons.crystalWood, 0);
        this.setBlock(world, i + 13, j + 14, k + 13, Dungeons.crystalliumLeaves, 0);
        this.setBlock(world, i + 13, j + 15, k + 12, Dungeons.crystalliumLeaves, 0);
        this.setBlock(world, i + 13, j + 17, k + 11, Dungeons.crystalWood, 0);
        this.setBlock(world, i + 13, j + 17, k + 12, Dungeons.crystalliumLeaves, 0);
        this.setBlock(world, i + 13, j + 18, k + 6, Dungeons.crystalliumLeaves, 0);
        this.setBlock(world, i + 13, j + 18, k + 11, Dungeons.crystalliumLeaves, 0);
        this.setBlock(world, i + 13, j + 18, k + 12, Dungeons.crystalliumLeaves, 0);
        this.setBlock(world, i + 13, j + 18, k + 13, Dungeons.crystalliumLeaves, 0);
        this.setBlock(world, i + 13, j + 19, k + 5, Dungeons.crystalliumLeaves, 0);
        this.setBlock(world, i + 13, j + 19, k + 6, Dungeons.crystalliumLeaves, 0);
        this.setBlock(world, i + 13, j + 19, k + 7, Dungeons.crystalWood, 0);
        this.setBlock(world, i + 13, j + 19, k + 12, Dungeons.crystalliumLeaves, 0);
        this.setBlock(world, i + 13, j + 20, k + 6, Dungeons.crystalliumLeaves, 0);
        this.setBlock(world, i + 13, j + 25, k + 8, Dungeons.crystalliumLeaves, 0);
        this.setBlock(world, i + 13, j + 25, k + 10, Dungeons.crystalliumLeaves, 0);
        this.setBlock(world, i + 13, j + 26, k + 9, Dungeons.crystalWood, 0);
        this.setBlock(world, i + 13, j + 26, k + 10, Dungeons.crystalliumLeaves, 0);
        this.setBlock(world, i + 13, j + 26, k + 11, Dungeons.crystalliumLeaves, 0);
        this.setBlock(world, i + 13, j + 27, k + 10, Dungeons.crystalliumLeaves, 0);
        this.setBlock(world, i + 14, j + 5, k + 9, Dungeons.crystalWood, 0);
        this.setBlock(world, i + 14, j + 6, k + 8, Dungeons.crystalliumLeaves, 0);
        this.setBlock(world, i + 14, j + 6, k + 9, Dungeons.crystalWood, 0);
        this.setBlock(world, i + 14, j + 6, k + 10, Dungeons.crystalliumLeaves, 0);
        this.setBlock(world, i + 14, j + 14, k + 12, Dungeons.crystalliumLeaves, 0);
        this.setBlock(world, i + 14, j + 17, k + 11, Dungeons.crystalliumLeaves, 0);
        this.setBlock(world, i + 14, j + 17, k + 12, Dungeons.crystalliumLeaves, 0);
        this.setBlock(world, i + 14, j + 17, k + 13, Dungeons.crystalliumLeaves, 0);
        this.setBlock(world, i + 14, j + 18, k + 5, Dungeons.crystalliumLeaves, 0);
        this.setBlock(world, i + 14, j + 18, k + 6, Dungeons.crystalliumLeaves, 0);
        this.setBlock(world, i + 14, j + 18, k + 7, Dungeons.crystalliumLeaves, 0);
        this.setBlock(world, i + 14, j + 18, k + 10, Dungeons.crystalliumLeaves, 0);
        this.setBlock(world, i + 14, j + 18, k + 11, Dungeons.crystalliumLeaves, 0);
        this.setBlock(world, i + 14, j + 18, k + 12, Dungeons.crystalWood, 0);
        this.setBlock(world, i + 14, j + 18, k + 13, Dungeons.crystalliumLeaves, 0);
        this.setBlock(world, i + 14, j + 18, k + 14, Dungeons.crystalliumLeaves, 0);
        this.setBlock(world, i + 14, j + 19, k + 4, Dungeons.crystalliumLeaves, 0);
        this.setBlock(world, i + 14, j + 19, k + 5, Dungeons.crystalliumLeaves, 0);
        this.setBlock(world, i + 14, j + 19, k + 6, Dungeons.crystalWood, 0);
        this.setBlock(world, i + 14, j + 19, k + 7, Dungeons.crystalliumLeaves, 0);
        this.setBlock(world, i + 14, j + 19, k + 8, Dungeons.crystalliumLeaves, 0);
        this.setBlock(world, i + 14, j + 19, k + 11, Dungeons.crystalliumLeaves, 0);
        this.setBlock(world, i + 14, j + 19, k + 12, Dungeons.crystalliumLeaves, 0);
        this.setBlock(world, i + 14, j + 19, k + 13, Dungeons.crystalliumLeaves, 0);
        this.setBlock(world, i + 14, j + 20, k + 5, Dungeons.crystalliumLeaves, 0);
        this.setBlock(world, i + 14, j + 20, k + 6, Dungeons.crystalliumLeaves, 0);
        this.setBlock(world, i + 14, j + 20, k + 7, Dungeons.crystalliumLeaves, 0);
        this.setBlock(world, i + 14, j + 26, k + 9, Dungeons.crystalWood, 0);
        this.setBlock(world, i + 14, j + 26, k + 10, Dungeons.crystalliumLeaves, 0);
        this.setBlock(world, i + 15, j + 5, k + 8, Dungeons.crystalliumLeaves, 0);
        this.setBlock(world, i + 15, j + 5, k + 10, Dungeons.crystalliumLeaves, 0);
        this.setBlock(world, i + 15, j + 6, k + 7, Dungeons.crystalliumLeaves, 0);
        this.setBlock(world, i + 15, j + 6, k + 8, Dungeons.crystalliumLeaves, 0);
        this.setBlock(world, i + 15, j + 6, k + 9, Dungeons.crystalWood, 0);
        this.setBlock(world, i + 15, j + 6, k + 10, Dungeons.crystalliumLeaves, 0);
        this.setBlock(world, i + 15, j + 6, k + 11, Dungeons.crystalliumLeaves, 0);
        this.setBlock(world, i + 15, j + 7, k + 8, Dungeons.crystalliumLeaves, 0);
        this.setBlock(world, i + 15, j + 7, k + 10, Dungeons.crystalliumLeaves, 0);
        this.setBlock(world, i + 15, j + 8, k + 9, Dungeons.crystalliumLeaves, 0);
        this.setBlock(world, i + 15, j + 17, k + 12, Dungeons.crystalliumLeaves, 0);
        this.setBlock(world, i + 15, j + 18, k + 6, Dungeons.crystalliumLeaves, 0);
        this.setBlock(world, i + 15, j + 18, k + 11, Dungeons.crystalliumLeaves, 0);
        this.setBlock(world, i + 15, j + 18, k + 12, Dungeons.crystalliumLeaves, 0);
        this.setBlock(world, i + 15, j + 18, k + 13, Dungeons.crystalliumLeaves, 0);
        this.setBlock(world, i + 15, j + 19, k + 5, Dungeons.crystalliumLeaves, 0);
        this.setBlock(world, i + 15, j + 19, k + 6, Dungeons.crystalliumLeaves, 0);
        this.setBlock(world, i + 15, j + 19, k + 7, Dungeons.crystalliumLeaves, 0);
        this.setBlock(world, i + 15, j + 19, k + 12, Dungeons.crystalliumLeaves, 0);
        this.setBlock(world, i + 15, j + 20, k + 6, Dungeons.crystalliumLeaves, 0);
        this.setBlock(world, i + 15, j + 25, k + 9, Dungeons.crystalliumLeaves, 0);
        this.setBlock(world, i + 15, j + 26, k + 8, Dungeons.crystalliumLeaves, 0);
        this.setBlock(world, i + 15, j + 26, k + 9, Dungeons.crystalWood, 0);
        this.setBlock(world, i + 15, j + 26, k + 10, Dungeons.crystalliumLeaves, 0);
        this.setBlock(world, i + 15, j + 27, k + 9, Dungeons.crystalliumLeaves, 0);
        this.setBlock(world, i + 16, j + 6, k + 8, Dungeons.crystalliumLeaves, 0);
        this.setBlock(world, i + 16, j + 6, k + 9, Dungeons.crystalWood, 0);
        this.setBlock(world, i + 16, j + 6, k + 10, Dungeons.crystalliumLeaves, 0);
        this.setBlock(world, i + 16, j + 7, k + 9, Dungeons.crystalWood, 0);
        this.setBlock(world, i + 16, j + 8, k + 8, Dungeons.crystalliumLeaves, 0);
        this.setBlock(world, i + 16, j + 8, k + 9, Dungeons.crystalliumLeaves, 0);
        this.setBlock(world, i + 16, j + 8, k + 10, Dungeons.crystalliumLeaves, 0);
        this.setBlock(world, i + 16, j + 9, k + 9, Dungeons.crystalliumLeaves, 0);
        this.setBlock(world, i + 16, j + 18, k + 12, Dungeons.crystalliumLeaves, 0);
        this.setBlock(world, i + 16, j + 19, k + 6, Dungeons.crystalliumLeaves, 0);
        this.setBlock(world, i + 16, j + 26, k + 9, Dungeons.crystalliumLeaves, 0);
        this.setBlock(world, i + 17, j + 7, k + 8, Dungeons.crystalliumLeaves, 0);
        this.setBlock(world, i + 17, j + 7, k + 9, Dungeons.crystalWood, 0);
        this.setBlock(world, i + 17, j + 7, k + 10, Dungeons.crystalliumLeaves, 0);
        this.setBlock(world, i + 17, j + 8, k + 7, Dungeons.crystalliumLeaves, 0);
        this.setBlock(world, i + 17, j + 8, k + 8, Dungeons.crystalliumLeaves, 0);
        this.setBlock(world, i + 17, j + 8, k + 9, Dungeons.crystalWood, 0);
        this.setBlock(world, i + 17, j + 8, k + 10, Dungeons.crystalliumLeaves, 0);
        this.setBlock(world, i + 17, j + 8, k + 11, Dungeons.crystalliumLeaves, 0);
        this.setBlock(world, i + 17, j + 9, k + 8, Dungeons.crystalliumLeaves, 0);
        this.setBlock(world, i + 17, j + 9, k + 9, Dungeons.crystalliumLeaves, 0);
        this.setBlock(world, i + 17, j + 9, k + 10, Dungeons.crystalliumLeaves, 0);
        this.setBlock(world, i + 18, j + 7, k + 9, Dungeons.crystalliumLeaves, 0);
        this.setBlock(world, i + 18, j + 8, k + 8, Dungeons.crystalliumLeaves, 0);
        this.setBlock(world, i + 18, j + 8, k + 9, Dungeons.crystalliumLeaves, 0);
        this.setBlock(world, i + 18, j + 8, k + 10, Dungeons.crystalliumLeaves, 0);
        this.setBlock(world, i + 18, j + 9, k + 9, Dungeons.crystalliumLeaves, 0);
        this.setBlock(world, i + 19, j + 8, k + 9, Dungeons.crystalliumLeaves, 0);
        return true;
    }
}
