package com.gibby.dungeon.gen;


import com.gibby.dungeon.Dungeons;
import net.minecraft.init.Blocks;
import net.minecraft.world.gen.feature.WorldGenerator;
import cpw.mods.fml.common.IWorldGenerator;
import net.minecraft.world.gen.structure.*;
import net.minecraft.world.biome.*;
import net.minecraft.world.gen.*;
import com.gibby.dungeon.*;
import net.minecraft.init.*;
import net.minecraftforge.common.*;
import cpw.mods.fml.common.eventhandler.*;
import net.minecraft.world.chunk.*;
import net.minecraft.block.*;
import net.minecraftforge.event.terraingen.*;
import net.minecraft.world.gen.feature.*;
import net.minecraft.util.*;
import net.minecraft.entity.*;
import java.util.*;
import net.minecraft.world.*;
public class WorldGenCrystalliumVillage extends WorldGenerator implements IWorldGenerator
{
    public void generate(final Random random, final int chunkX, final int chunkZ, final World world, final IChunkProvider chunkGenerator, final IChunkProvider chunkProvider) {
    }

    public void setBlock(final World world, final int x, final int y, final int z, final Block block, final int metadata) {
        final Block b1 = world.getBlock(x, y, z);
        if (b1.isAir(world, x, y, z) || b1.isLeaves(world, x, y, z)) {
            world.setBlock(x, y, z, block, metadata, 2);
        }
    }

    public boolean generate(final World world, final Random rand, final int i, final int j, final int k) {
        this.setBlock(world, i + 7, j + 52, k + 30, Dungeons.crystalliumDirt, 0);
        this.setBlock(world, i + 7, j + 52, k + 31, Dungeons.crystalliumDirt, 0);
        this.setBlock(world, i + 7, j + 52, k + 32, Dungeons.crystalliumGrass, 0);
        this.setBlock(world, i + 7, j + 52, k + 33, Dungeons.crystalliumGrass, 0);
        this.setBlock(world, i + 5, j + 24, k + 28, Dungeons.crystalliumDirt, 0);
        this.setBlock(world, i + 5, j + 24, k + 29, Dungeons.crystalliumDirt, 0);
        this.setBlock(world, i + 5, j + 25, k + 26, Dungeons.crystalliumLamp, 0);
        this.setBlock(world, i + 5, j + 25, k + 27, Dungeons.crystalliumDirt, 0);
        this.setBlock(world, i + 5, j + 25, k + 28, Dungeons.crystalliumDirt, 0);
        this.setBlock(world, i + 5, j + 25, k + 29, Dungeons.crystalliumDirt, 0);
        this.setBlock(world, i + 5, j + 25, k + 30, Dungeons.crystalliumDirt, 0);
        this.setBlock(world, i + 5, j + 26, k + 26, Dungeons.crystalliumGrass, 0);
        this.setBlock(world, i + 5, j + 26, k + 27, Dungeons.crystalliumGrass, 0);
        this.setBlock(world, i + 5, j + 26, k + 28, Dungeons.crystalliumGrass, 0);
        this.setBlock(world, i + 5, j + 26, k + 29, Dungeons.crystalliumGrass, 0);
        this.setBlock(world, i + 5, j + 26, k + 30, Dungeons.crystalliumGrass, 0);
        this.setBlock(world, i + 5, j + 51, k + 32, Dungeons.crystalliumGrass, 0);
        this.setBlock(world, i + 5, j + 51, k + 33, Dungeons.crystalliumGrass, 0);
        this.setBlock(world, i + 5, j + 51, k + 34, Dungeons.crystalliumGrass, 0);
        this.setBlock(world, i + 6, j + 24, k + 26, Dungeons.crystalliumDirt, 0);
        this.setBlock(world, i + 6, j + 24, k + 27, Dungeons.crystalliumDirt, 0);
        this.setBlock(world, i + 6, j + 24, k + 28, Dungeons.crystalliumDirt, 0);
        this.setBlock(world, i + 6, j + 24, k + 29, Dungeons.crystalliumDirt, 0);
        this.setBlock(world, i + 6, j + 24, k + 30, Dungeons.crystalliumDirt, 0);
        this.setBlock(world, i + 6, j + 24, k + 31, Dungeons.crystalliumDirt, 0);
        this.setBlock(world, i + 6, j + 24, k + 32, Dungeons.crystalliumDirt, 0);
        this.setBlock(world, i + 6, j + 24, k + 33, Dungeons.crystalliumDirt, 0);
        this.setBlock(world, i + 6, j + 25, k + 25, Dungeons.crystalliumDirt, 0);
        this.setBlock(world, i + 6, j + 25, k + 26, Dungeons.crystalliumDirt, 0);
        this.setBlock(world, i + 6, j + 25, k + 27, Dungeons.crystalliumDirt, 0);
        this.setBlock(world, i + 6, j + 25, k + 28, Blocks.obsidian, 0);
        this.setBlock(world, i + 6, j + 25, k + 29, Dungeons.crystalliumDirt, 0);
        this.setBlock(world, i + 6, j + 25, k + 30, Dungeons.crystalliumDirt, 0);
        this.setBlock(world, i + 6, j + 25, k + 31, Dungeons.crystalliumDirt, 0);
        this.setBlock(world, i + 6, j + 25, k + 32, Dungeons.crystalliumDirt, 0);
        this.setBlock(world, i + 6, j + 25, k + 33, Dungeons.crystalliumDirt, 0);
        this.setBlock(world, i + 6, j + 25, k + 34, Dungeons.crystalliumDirt, 0);
        this.setBlock(world, i + 6, j + 26, k + 24, Dungeons.crystalliumGrass, 0);
        this.setBlock(world, i + 6, j + 26, k + 25, Dungeons.crystalliumGrass, 0);
        this.setBlock(world, i + 6, j + 26, k + 26, Dungeons.crystalliumGrass, 0);
        this.setBlock(world, i + 6, j + 26, k + 27, Dungeons.crystalliumGrass, 0);
        this.setBlock(world, i + 6, j + 26, k + 28, Blocks.obsidian, 0);
        this.setBlock(world, i + 6, j + 26, k + 29, Dungeons.crystalliumGrass, 0);
        this.setBlock(world, i + 6, j + 26, k + 30, Dungeons.crystalliumGrass, 0);
        this.setBlock(world, i + 6, j + 26, k + 31, Dungeons.crystalliumGrass, 0);
        this.setBlock(world, i + 6, j + 26, k + 32, Dungeons.crystalliumGrass, 0);
        this.setBlock(world, i + 6, j + 26, k + 33, Dungeons.crystalliumGrass, 0);
        this.setBlock(world, i + 6, j + 26, k + 34, Dungeons.crystalliumGrass, 0);
        this.setBlock(world, i + 6, j + 26, k + 35, Dungeons.crystalliumGrass, 0);
        this.setBlock(world, i + 6, j + 27, k + 28, Blocks.obsidian, 0);
        this.setBlock(world, i + 6, j + 28, k + 28, Blocks.obsidian, 0);
        this.setBlock(world, i + 6, j + 29, k + 28, Blocks.obsidian, 0);
        this.setBlock(world, i + 6, j + 30, k + 28, Blocks.obsidian, 0);
        this.setBlock(world, i + 6, j + 35, k + 28, Blocks.obsidian, 0);
        this.setBlock(world, i + 6, j + 36, k + 28, Blocks.obsidian, 0);
        this.setBlock(world, i + 6, j + 37, k + 28, Blocks.obsidian, 0);
        this.setBlock(world, i + 6, j + 38, k + 28, Blocks.obsidian, 0);
        this.setBlock(world, i + 6, j + 39, k + 28, Blocks.obsidian, 0);
        this.setBlock(world, i + 6, j + 40, k + 28, Blocks.obsidian, 0);
        this.setBlock(world, i + 6, j + 45, k + 28, Blocks.obsidian, 0);
        this.setBlock(world, i + 6, j + 51, k + 32, Dungeons.crystalliumDirt, 0);
        this.setBlock(world, i + 6, j + 51, k + 33, Dungeons.crystalliumGrass, 0);
        this.setBlock(world, i + 6, j + 51, k + 34, Dungeons.crystalliumGrass, 0);
        this.setBlock(world, i + 6, j + 51, k + 35, Dungeons.crystalliumGrass, 0);
        this.setBlock(world, i + 6, j + 52, k + 30, Dungeons.crystalliumGrass, 0);
        this.setBlock(world, i + 6, j + 52, k + 31, Dungeons.crystalliumGrass, 0);
        this.setBlock(world, i + 6, j + 52, k + 32, Dungeons.crystalliumGrass, 0);
        this.setBlock(world, i + 6, j + 46, k + 28, Blocks.obsidian, 0);
        this.setBlock(world, i + 7, j + 24, k + 23, Dungeons.crystalliumDirt, 0);
        this.setBlock(world, i + 7, j + 24, k + 24, Dungeons.crystalliumDirt, 0);
        this.setBlock(world, i + 7, j + 24, k + 25, Dungeons.crystalliumDirt, 0);
        this.setBlock(world, i + 7, j + 24, k + 26, Dungeons.crystalliumDirt, 0);
        this.setBlock(world, i + 7, j + 24, k + 27, Dungeons.crystalliumDirt, 0);
        this.setBlock(world, i + 7, j + 24, k + 28, Dungeons.crystalliumDirt, 0);
        this.setBlock(world, i + 7, j + 24, k + 29, Dungeons.crystalliumDirt, 0);
        this.setBlock(world, i + 7, j + 24, k + 30, Dungeons.crystalliumDirt, 0);
        this.setBlock(world, i + 7, j + 24, k + 31, Dungeons.crystalliumDirt, 0);
        this.setBlock(world, i + 7, j + 24, k + 32, Dungeons.crystalliumDirt, 0);
        this.setBlock(world, i + 7, j + 24, k + 33, Dungeons.crystalliumDirt, 0);
        this.setBlock(world, i + 7, j + 24, k + 34, Dungeons.crystalliumDirt, 0);
        this.setBlock(world, i + 7, j + 24, k + 35, Dungeons.crystalliumDirt, 0);
        this.setBlock(world, i + 7, j + 25, k + 23, Dungeons.crystalliumDirt, 0);
        this.setBlock(world, i + 7, j + 25, k + 24, Dungeons.crystalliumDirt, 0);
        this.setBlock(world, i + 7, j + 25, k + 25, Dungeons.crystalliumDirt, 0);
        this.setBlock(world, i + 7, j + 25, k + 26, Dungeons.crystalliumDirt, 0);
        this.setBlock(world, i + 7, j + 25, k + 27, Dungeons.crystalliumDirt, 0);
        this.setBlock(world, i + 7, j + 25, k + 28, Blocks.obsidian, 0);
        this.setBlock(world, i + 7, j + 25, k + 29, Dungeons.crystalliumDirt, 0);
        this.setBlock(world, i + 7, j + 25, k + 30, Dungeons.crystalliumDirt, 0);
        this.setBlock(world, i + 7, j + 25, k + 31, Dungeons.crystalliumDirt, 0);
        this.setBlock(world, i + 7, j + 25, k + 32, Dungeons.crystalliumDirt, 0);
        this.setBlock(world, i + 7, j + 25, k + 33, Dungeons.crystalliumDirt, 0);
        this.setBlock(world, i + 7, j + 25, k + 34, Dungeons.crystalliumDirt, 0);
        this.setBlock(world, i + 7, j + 25, k + 35, Dungeons.crystalliumDirt, 0);
        this.setBlock(world, i + 7, j + 25, k + 36, Dungeons.crystalliumDirt, 0);
        this.setBlock(world, i + 7, j + 26, k + 22, Dungeons.crystalliumGrass, 0);
        this.setBlock(world, i + 7, j + 26, k + 23, Dungeons.crystalliumGrass, 0);
        this.setBlock(world, i + 7, j + 26, k + 24, Dungeons.crystalliumGrass, 0);
        this.setBlock(world, i + 7, j + 26, k + 25, Dungeons.crystalliumGrass, 0);
        this.setBlock(world, i + 7, j + 26, k + 26, Dungeons.crystalliumGrass, 0);
        this.setBlock(world, i + 7, j + 26, k + 27, Dungeons.crystalliumGrass, 0);
        this.setBlock(world, i + 7, j + 26, k + 28, Dungeons.crystalliumGrass, 0);
        this.setBlock(world, i + 7, j + 26, k + 29, Dungeons.crystalliumGrass, 0);
        this.setBlock(world, i + 7, j + 26, k + 30, Dungeons.crystalliumGrass, 0);
        this.setBlock(world, i + 7, j + 26, k + 31, Dungeons.crystalliumGrass, 0);
        this.setBlock(world, i + 7, j + 26, k + 32, Dungeons.crystalliumGrass, 0);
        this.setBlock(world, i + 7, j + 26, k + 33, Dungeons.crystalliumGrass, 0);
        this.setBlock(world, i + 7, j + 26, k + 34, Dungeons.crystalliumGrass, 0);
        this.setBlock(world, i + 7, j + 26, k + 35, Dungeons.crystalliumGrass, 0);
        this.setBlock(world, i + 7, j + 26, k + 36, Dungeons.crystalliumGrass, 0);
        this.setBlock(world, i + 7, j + 26, k + 37, Dungeons.crystalliumGrass, 0);
        this.setBlock(world, i + 7, j + 45, k + 27, Blocks.obsidian, 0);
        this.setBlock(world, i + 7, j + 45, k + 28, Blocks.obsidian, 0);
        this.setBlock(world, i + 7, j + 30, k + 27, Blocks.obsidian, 0);
        this.setBlock(world, i + 7, j + 30, k + 28, Blocks.obsidian, 0);
        this.setBlock(world, i + 7, j + 30, k + 29, Blocks.obsidian, 0);
        this.setBlock(world, i + 7, j + 31, k + 27, Blocks.obsidian, 0);
        this.setBlock(world, i + 7, j + 31, k + 29, Blocks.obsidian, 0);
        this.setBlock(world, i + 7, j + 32, k + 27, Blocks.obsidian, 0);
        this.setBlock(world, i + 7, j + 32, k + 29, Blocks.obsidian, 0);
        this.setBlock(world, i + 7, j + 33, k + 27, Blocks.obsidian, 0);
        this.setBlock(world, i + 7, j + 33, k + 29, Blocks.obsidian, 0);
        this.setBlock(world, i + 7, j + 34, k + 27, Blocks.obsidian, 0);
        this.setBlock(world, i + 7, j + 34, k + 29, Blocks.obsidian, 0);
        this.setBlock(world, i + 7, j + 35, k + 27, Blocks.obsidian, 0);
        this.setBlock(world, i + 7, j + 35, k + 28, Blocks.obsidian, 0);
        this.setBlock(world, i + 7, j + 35, k + 29, Blocks.obsidian, 0);
        this.setBlock(world, i + 7, j + 40, k + 27, Blocks.obsidian, 0);
        this.setBlock(world, i + 7, j + 40, k + 28, Blocks.obsidian, 0);
        this.setBlock(world, i + 7, j + 40, k + 29, Blocks.obsidian, 0);
        this.setBlock(world, i + 7, j + 41, k + 27, Blocks.obsidian, 0);
        this.setBlock(world, i + 7, j + 41, k + 29, Blocks.obsidian, 0);
        this.setBlock(world, i + 7, j + 42, k + 27, Blocks.obsidian, 0);
        this.setBlock(world, i + 7, j + 42, k + 29, Blocks.obsidian, 0);
        this.setBlock(world, i + 7, j + 43, k + 27, Blocks.obsidian, 0);
        this.setBlock(world, i + 7, j + 43, k + 29, Blocks.obsidian, 0);
        this.setBlock(world, i + 7, j + 44, k + 27, Blocks.obsidian, 0);
        this.setBlock(world, i + 7, j + 44, k + 29, Blocks.obsidian, 0);
        this.setBlock(world, i + 7, j + 52, k + 24, Dungeons.amethystStone, 0);
        this.setBlock(world, i + 7, j + 52, k + 25, Dungeons.amethystStone, 0);
        this.setBlock(world, i + 7, j + 52, k + 26, Dungeons.amethystStone, 0);
        this.setBlock(world, i + 7, j + 52, k + 27, Dungeons.amethystStone, 0);
        this.setBlock(world, i + 7, j + 52, k + 28, Dungeons.amethystStone, 0);
        this.setBlock(world, i + 7, j + 52, k + 29, Dungeons.amethystStone, 0);
        this.setBlock(world, i + 7, j + 53, k + 27, Dungeons.amethystStone, 0);
        this.setBlock(world, i + 3, j + 47, k + 31, Dungeons.amethystStone, 0);
        this.setBlock(world, i + 3, j + 47, k + 32, Dungeons.amethystStone, 0);
        this.setBlock(world, i + 3, j + 47, k + 33, Dungeons.amethystStone, 0);
        this.setBlock(world, i + 3, j + 48, k + 30, Dungeons.amethystStone, 0);
        this.setBlock(world, i + 3, j + 48, k + 31, Dungeons.amethystStone, 0);
        this.setBlock(world, i + 3, j + 48, k + 32, Dungeons.amethystStone, 0);
        this.setBlock(world, i + 3, j + 48, k + 33, Dungeons.amethystStone, 0);
        this.setBlock(world, i + 3, j + 49, k + 30, Dungeons.amethystStone, 0);
        this.setBlock(world, i + 3, j + 49, k + 31, Dungeons.amethystStone, 0);
        this.setBlock(world, i + 3, j + 49, k + 32, Dungeons.amethystStone, 0);
        this.setBlock(world, i + 3, j + 49, k + 33, Dungeons.amethystStone, 0);
        this.setBlock(world, i + 3, j + 49, k + 34, Dungeons.amethystStone, 0);
        this.setBlock(world, i + 4, j + 46, k + 29, Dungeons.amethystStone, 0);
        this.setBlock(world, i + 4, j + 46, k + 30, Dungeons.amethystStone, 0);
        this.setBlock(world, i + 4, j + 46, k + 31, Dungeons.amethystStone, 0);
        this.setBlock(world, i + 4, j + 46, k + 32, Dungeons.amethystStone, 0);
        this.setBlock(world, i + 4, j + 46, k + 33, Dungeons.amethystStone, 0);
        this.setBlock(world, i + 4, j + 46, k + 34, Dungeons.amethystStone, 0);
        this.setBlock(world, i + 4, j + 46, k + 35, Dungeons.amethystStone, 0);
        this.setBlock(world, i + 4, j + 47, k + 29, Dungeons.amethystStone, 0);
        this.setBlock(world, i + 4, j + 47, k + 30, Dungeons.amethystStone, 0);
        this.setBlock(world, i + 4, j + 47, k + 31, Dungeons.amethystStone, 0);
        this.setBlock(world, i + 4, j + 47, k + 32, Dungeons.amethystStone, 0);
        this.setBlock(world, i + 4, j + 47, k + 33, Dungeons.amethystStone, 0);
        this.setBlock(world, i + 4, j + 47, k + 34, Dungeons.amethystStone, 0);
        this.setBlock(world, i + 4, j + 47, k + 35, Dungeons.amethystStone, 0);
        this.setBlock(world, i + 4, j + 48, k + 29, Dungeons.amethystStone, 0);
        this.setBlock(world, i + 4, j + 48, k + 30, Dungeons.amethystStone, 0);
        this.setBlock(world, i + 4, j + 48, k + 31, Dungeons.amethystStone, 0);
        this.setBlock(world, i + 4, j + 48, k + 32, Dungeons.amethystStone, 0);
        this.setBlock(world, i + 4, j + 48, k + 33, Dungeons.amethystStone, 0);
        this.setBlock(world, i + 4, j + 48, k + 34, Dungeons.amethystStone, 0);
        this.setBlock(world, i + 4, j + 48, k + 35, Dungeons.amethystStone, 0);
        this.setBlock(world, i + 4, j + 49, k + 29, Dungeons.amethystStone, 0);
        this.setBlock(world, i + 4, j + 49, k + 30, Dungeons.amethystStone, 0);
        this.setBlock(world, i + 4, j + 49, k + 31, Dungeons.amethystStone, 0);
        this.setBlock(world, i + 4, j + 49, k + 32, Dungeons.amethystStone, 0);
        this.setBlock(world, i + 4, j + 49, k + 33, Dungeons.amethystStone, 0);
        this.setBlock(world, i + 4, j + 49, k + 34, Dungeons.amethystStone, 0);
        this.setBlock(world, i + 4, j + 49, k + 35, Dungeons.amethystStone, 0);
        this.setBlock(world, i + 4, j + 50, k + 29, Dungeons.amethystStone, 0);
        this.setBlock(world, i + 4, j + 50, k + 30, Dungeons.amethystStone, 0);
        this.setBlock(world, i + 4, j + 50, k + 31, Dungeons.amethystStone, 0);
        this.setBlock(world, i + 5, j + 45, k + 30, Dungeons.amethystStone, 0);
        this.setBlock(world, i + 5, j + 45, k + 31, Dungeons.amethystStone, 0);
        this.setBlock(world, i + 5, j + 45, k + 32, Dungeons.amethystStone, 0);
        this.setBlock(world, i + 5, j + 45, k + 33, Dungeons.amethystStone, 0);
        this.setBlock(world, i + 5, j + 45, k + 34, Dungeons.amethystStone, 0);
        this.setBlock(world, i + 5, j + 45, k + 35, Dungeons.amethystStone, 0);
        this.setBlock(world, i + 5, j + 46, k + 28, Dungeons.amethystStone, 0);
        this.setBlock(world, i + 5, j + 46, k + 29, Dungeons.amethystStone, 0);
        this.setBlock(world, i + 5, j + 46, k + 30, Dungeons.amethystStone, 0);
        this.setBlock(world, i + 5, j + 46, k + 31, Dungeons.amethystStone, 0);
        this.setBlock(world, i + 5, j + 46, k + 32, Dungeons.amethystStone, 0);
        this.setBlock(world, i + 5, j + 46, k + 33, Dungeons.amethystStone, 0);
        this.setBlock(world, i + 5, j + 46, k + 34, Dungeons.amethystStone, 0);
        this.setBlock(world, i + 5, j + 46, k + 35, Dungeons.amethystStone, 0);
        this.setBlock(world, i + 5, j + 46, k + 36, Dungeons.amethystStone, 0);
        this.setBlock(world, i + 5, j + 47, k + 28, Dungeons.amethystStone, 0);
        this.setBlock(world, i + 5, j + 47, k + 29, Dungeons.amethystStone, 0);
        this.setBlock(world, i + 5, j + 47, k + 30, Dungeons.amethystStone, 0);
        this.setBlock(world, i + 5, j + 47, k + 31, Dungeons.amethystStone, 0);
        this.setBlock(world, i + 5, j + 47, k + 32, Dungeons.amethystStone, 0);
        this.setBlock(world, i + 5, j + 47, k + 33, Dungeons.amethystStone, 0);
        this.setBlock(world, i + 5, j + 47, k + 34, Dungeons.amethystStone, 0);
        this.setBlock(world, i + 5, j + 47, k + 35, Dungeons.amethystStone, 0);
        this.setBlock(world, i + 5, j + 47, k + 36, Dungeons.amethystStone, 0);
        this.setBlock(world, i + 5, j + 48, k + 25, Dungeons.amethystStone, 0);
        this.setBlock(world, i + 5, j + 48, k + 26, Dungeons.amethystStone, 0);
        this.setBlock(world, i + 5, j + 48, k + 28, Dungeons.amethystStone, 0);
        this.setBlock(world, i + 5, j + 48, k + 29, Dungeons.amethystStone, 0);
        this.setBlock(world, i + 5, j + 48, k + 30, Dungeons.amethystStone, 0);
        this.setBlock(world, i + 5, j + 48, k + 31, Dungeons.amethystStone, 0);
        this.setBlock(world, i + 5, j + 48, k + 32, Dungeons.amethystStone, 0);
        this.setBlock(world, i + 5, j + 48, k + 33, Dungeons.amethystStone, 0);
        this.setBlock(world, i + 5, j + 48, k + 34, Dungeons.amethystStone, 0);
        this.setBlock(world, i + 5, j + 48, k + 35, Dungeons.amethystStone, 0);
        this.setBlock(world, i + 5, j + 48, k + 36, Dungeons.amethystStone, 0);
        this.setBlock(world, i + 5, j + 49, k + 23, Dungeons.amethystStone, 0);
        this.setBlock(world, i + 5, j + 49, k + 24, Dungeons.amethystStone, 0);
        this.setBlock(world, i + 5, j + 49, k + 25, Dungeons.amethystStone, 0);
        this.setBlock(world, i + 5, j + 49, k + 26, Dungeons.amethystStone, 0);
        this.setBlock(world, i + 5, j + 49, k + 27, Dungeons.amethystStone, 0);
        this.setBlock(world, i + 5, j + 49, k + 28, Dungeons.amethystStone, 0);
        this.setBlock(world, i + 5, j + 49, k + 29, Dungeons.amethystStone, 0);
        this.setBlock(world, i + 5, j + 49, k + 30, Dungeons.amethystStone, 0);
        this.setBlock(world, i + 5, j + 49, k + 31, Dungeons.amethystStone, 0);
        this.setBlock(world, i + 5, j + 49, k + 32, Dungeons.amethystStone, 0);
        this.setBlock(world, i + 5, j + 49, k + 33, Dungeons.amethystStone, 0);
        this.setBlock(world, i + 5, j + 49, k + 34, Dungeons.amethystStone, 0);
        this.setBlock(world, i + 5, j + 49, k + 35, Dungeons.amethystStone, 0);
        this.setBlock(world, i + 5, j + 49, k + 36, Dungeons.amethystStone, 0);
        this.setBlock(world, i + 5, j + 50, k + 23, Dungeons.amethystStone, 0);
        this.setBlock(world, i + 5, j + 50, k + 24, Dungeons.amethystStone, 0);
        this.setBlock(world, i + 5, j + 50, k + 25, Dungeons.amethystStone, 0);
        this.setBlock(world, i + 5, j + 50, k + 26, Dungeons.amethystStone, 0);
        this.setBlock(world, i + 5, j + 50, k + 27, Dungeons.amethystStone, 0);
        this.setBlock(world, i + 5, j + 50, k + 28, Dungeons.amethystStone, 0);
        this.setBlock(world, i + 5, j + 50, k + 29, Dungeons.amethystStone, 0);
        this.setBlock(world, i + 5, j + 50, k + 30, Dungeons.amethystStone, 0);
        this.setBlock(world, i + 5, j + 50, k + 31, Dungeons.amethystStone, 0);
        this.setBlock(world, i + 5, j + 50, k + 32, Dungeons.amethystStone, 0);
        this.setBlock(world, i + 5, j + 50, k + 33, Dungeons.amethystStone, 0);
        this.setBlock(world, i + 5, j + 50, k + 34, Dungeons.amethystStone, 0);
        this.setBlock(world, i + 5, j + 50, k + 35, Dungeons.amethystStone, 0);
        this.setBlock(world, i + 5, j + 51, k + 23, Dungeons.amethystStone, 0);
        this.setBlock(world, i + 5, j + 51, k + 24, Dungeons.amethystStone, 0);
        this.setBlock(world, i + 5, j + 51, k + 25, Dungeons.amethystStone, 0);
        this.setBlock(world, i + 6, j + 23, k + 27, Dungeons.amethystStone, 0);
        this.setBlock(world, i + 6, j + 23, k + 28, Dungeons.amethystStone, 0);
        this.setBlock(world, i + 6, j + 23, k + 29, Dungeons.amethystStone, 0);
        this.setBlock(world, i + 6, j + 23, k + 30, Dungeons.amethystStone, 0);
        this.setBlock(world, i + 6, j + 23, k + 31, Dungeons.amethystStone, 0);
        this.setBlock(world, i + 6, j + 23, k + 32, Dungeons.amethystStone, 0);
        this.setBlock(world, i + 6, j + 45, k + 29, Dungeons.amethystStone, 0);
        this.setBlock(world, i + 6, j + 45, k + 30, Dungeons.amethystStone, 0);
        this.setBlock(world, i + 6, j + 45, k + 31, Dungeons.amethystStone, 0);
        this.setBlock(world, i + 6, j + 45, k + 32, Dungeons.amethystStone, 0);
        this.setBlock(world, i + 6, j + 45, k + 33, Dungeons.amethystStone, 0);
        this.setBlock(world, i + 6, j + 45, k + 34, Dungeons.amethystStone, 0);
        this.setBlock(world, i + 6, j + 45, k + 35, Dungeons.amethystStone, 0);
        this.setBlock(world, i + 6, j + 45, k + 36, Dungeons.amethystStone, 0);
        this.setBlock(world, i + 6, j + 46, k + 29, Dungeons.amethystStone, 0);
        this.setBlock(world, i + 6, j + 46, k + 30, Dungeons.amethystStone, 0);
        this.setBlock(world, i + 6, j + 46, k + 31, Dungeons.amethystStone, 0);
        this.setBlock(world, i + 6, j + 46, k + 32, Dungeons.amethystStone, 0);
        this.setBlock(world, i + 6, j + 46, k + 33, Dungeons.amethystStone, 0);
        this.setBlock(world, i + 6, j + 46, k + 34, Dungeons.amethystStone, 0);
        this.setBlock(world, i + 6, j + 46, k + 35, Dungeons.amethystStone, 0);
        this.setBlock(world, i + 6, j + 46, k + 36, Dungeons.amethystStone, 0);
        this.setBlock(world, i + 6, j + 47, k + 25, Dungeons.amethystStone, 0);
        this.setBlock(world, i + 6, j + 47, k + 26, Dungeons.amethystStone, 0);
        this.setBlock(world, i + 6, j + 47, k + 27, Dungeons.amethystStone, 0);
        this.setBlock(world, i + 6, j + 47, k + 28, Dungeons.amethystStone, 0);
        this.setBlock(world, i + 6, j + 47, k + 29, Dungeons.amethystStone, 0);
        this.setBlock(world, i + 6, j + 47, k + 30, Dungeons.amethystStone, 0);
        this.setBlock(world, i + 6, j + 47, k + 31, Dungeons.amethystStone, 0);
        this.setBlock(world, i + 6, j + 47, k + 32, Dungeons.amethystStone, 0);
        this.setBlock(world, i + 6, j + 47, k + 33, Dungeons.amethystStone, 0);
        this.setBlock(world, i + 6, j + 47, k + 34, Dungeons.amethystStone, 0);
        this.setBlock(world, i + 6, j + 47, k + 35, Dungeons.amethystStone, 0);
        this.setBlock(world, i + 6, j + 47, k + 36, Dungeons.amethystStone, 0);
        this.setBlock(world, i + 6, j + 47, k + 37, Dungeons.amethystStone, 0);
        this.setBlock(world, i + 6, j + 48, k + 24, Dungeons.amethystStone, 0);
        this.setBlock(world, i + 6, j + 48, k + 25, Dungeons.amethystStone, 0);
        this.setBlock(world, i + 6, j + 48, k + 26, Dungeons.amethystStone, 0);
        this.setBlock(world, i + 6, j + 48, k + 27, Dungeons.amethystStone, 0);
        this.setBlock(world, i + 6, j + 48, k + 28, Dungeons.amethystStone, 0);
        this.setBlock(world, i + 6, j + 48, k + 29, Dungeons.amethystStone, 0);
        this.setBlock(world, i + 6, j + 48, k + 30, Dungeons.amethystStone, 0);
        this.setBlock(world, i + 6, j + 48, k + 31, Dungeons.amethystStone, 0);
        this.setBlock(world, i + 6, j + 48, k + 32, Dungeons.amethystStone, 0);
        this.setBlock(world, i + 6, j + 48, k + 33, Dungeons.amethystStone, 0);
        this.setBlock(world, i + 6, j + 48, k + 34, Dungeons.amethystStone, 0);
        this.setBlock(world, i + 6, j + 48, k + 35, Dungeons.amethystStone, 0);
        this.setBlock(world, i + 6, j + 48, k + 36, Dungeons.amethystStone, 0);
        this.setBlock(world, i + 6, j + 48, k + 37, Dungeons.amethystStone, 0);
        this.setBlock(world, i + 6, j + 49, k + 22, Dungeons.amethystStone, 0);
        this.setBlock(world, i + 6, j + 49, k + 23, Dungeons.amethystStone, 0);
        this.setBlock(world, i + 6, j + 49, k + 24, Dungeons.amethystStone, 0);
        this.setBlock(world, i + 6, j + 49, k + 25, Dungeons.amethystStone, 0);
        this.setBlock(world, i + 6, j + 49, k + 26, Dungeons.amethystStone, 0);
        this.setBlock(world, i + 6, j + 49, k + 27, Dungeons.amethystStone, 0);
        this.setBlock(world, i + 6, j + 49, k + 28, Dungeons.amethystStone, 0);
        this.setBlock(world, i + 6, j + 49, k + 29, Dungeons.amethystStone, 0);
        this.setBlock(world, i + 6, j + 49, k + 30, Dungeons.amethystStone, 0);
        this.setBlock(world, i + 6, j + 49, k + 31, Dungeons.amethystStone, 0);
        this.setBlock(world, i + 6, j + 49, k + 32, Dungeons.amethystStone, 0);
        this.setBlock(world, i + 6, j + 49, k + 33, Dungeons.amethystStone, 0);
        this.setBlock(world, i + 6, j + 49, k + 34, Dungeons.amethystStone, 0);
        this.setBlock(world, i + 6, j + 49, k + 35, Dungeons.amethystStone, 0);
        this.setBlock(world, i + 6, j + 49, k + 36, Dungeons.amethystStone, 0);
        this.setBlock(world, i + 6, j + 49, k + 37, Dungeons.amethystStone, 0);
        this.setBlock(world, i + 6, j + 50, k + 22, Dungeons.amethystStone, 0);
        this.setBlock(world, i + 6, j + 50, k + 23, Dungeons.amethystStone, 0);
        this.setBlock(world, i + 6, j + 50, k + 24, Dungeons.amethystStone, 0);
        this.setBlock(world, i + 6, j + 50, k + 25, Dungeons.amethystStone, 0);
        this.setBlock(world, i + 6, j + 50, k + 26, Dungeons.amethystStone, 0);
        this.setBlock(world, i + 6, j + 50, k + 27, Dungeons.amethystStone, 0);
        this.setBlock(world, i + 6, j + 50, k + 28, Dungeons.amethystStone, 0);
        this.setBlock(world, i + 6, j + 50, k + 29, Dungeons.amethystStone, 0);
        this.setBlock(world, i + 6, j + 50, k + 30, Dungeons.amethystStone, 0);
        this.setBlock(world, i + 6, j + 50, k + 31, Dungeons.amethystStone, 0);
        this.setBlock(world, i + 6, j + 50, k + 32, Dungeons.amethystStone, 0);
        this.setBlock(world, i + 6, j + 50, k + 33, Dungeons.amethystStone, 0);
        this.setBlock(world, i + 6, j + 50, k + 34, Dungeons.amethystStone, 0);
        this.setBlock(world, i + 6, j + 50, k + 35, Dungeons.amethystStone, 0);
        this.setBlock(world, i + 6, j + 50, k + 36, Dungeons.amethystStone, 0);
        this.setBlock(world, i + 6, j + 51, k + 22, Dungeons.amethystStone, 0);
        this.setBlock(world, i + 6, j + 51, k + 23, Dungeons.amethystStone, 0);
        this.setBlock(world, i + 6, j + 51, k + 24, Dungeons.amethystStone, 0);
        this.setBlock(world, i + 6, j + 51, k + 25, Dungeons.amethystStone, 0);
        this.setBlock(world, i + 6, j + 51, k + 26, Dungeons.amethystStone, 0);
        this.setBlock(world, i + 6, j + 51, k + 27, Dungeons.amethystStone, 0);
        this.setBlock(world, i + 6, j + 51, k + 28, Dungeons.amethystStone, 0);
        this.setBlock(world, i + 6, j + 51, k + 29, Dungeons.amethystStone, 0);
        this.setBlock(world, i + 6, j + 51, k + 30, Dungeons.amethystStone, 0);
        this.setBlock(world, i + 6, j + 51, k + 31, Dungeons.amethystStone, 0);
        this.setBlock(world, i + 7, j + 22, k + 27, Dungeons.amethystStone, 0);
        this.setBlock(world, i + 7, j + 22, k + 28, Dungeons.amethystStone, 0);
        this.setBlock(world, i + 7, j + 22, k + 29, Dungeons.amethystStone, 0);
        this.setBlock(world, i + 7, j + 22, k + 30, Dungeons.amethystStone, 0);
        this.setBlock(world, i + 7, j + 22, k + 31, Dungeons.amethystStone, 0);
        this.setBlock(world, i + 7, j + 22, k + 32, Dungeons.amethystStone, 0);
        this.setBlock(world, i + 7, j + 23, k + 24, Dungeons.amethystStone, 0);
        this.setBlock(world, i + 7, j + 23, k + 25, Dungeons.amethystStone, 0);
        this.setBlock(world, i + 7, j + 23, k + 26, Dungeons.amethystStone, 0);
        this.setBlock(world, i + 7, j + 23, k + 27, Dungeons.amethystStone, 0);
        this.setBlock(world, i + 7, j + 23, k + 28, Dungeons.amethystStone, 0);
        this.setBlock(world, i + 7, j + 23, k + 29, Dungeons.amethystStone, 0);
        this.setBlock(world, i + 7, j + 23, k + 30, Dungeons.amethystStone, 0);
        this.setBlock(world, i + 7, j + 23, k + 31, Dungeons.amethystStone, 0);
        this.setBlock(world, i + 7, j + 23, k + 32, Dungeons.amethystStone, 0);
        this.setBlock(world, i + 7, j + 23, k + 33, Dungeons.amethystStone, 0);
        this.setBlock(world, i + 7, j + 23, k + 34, Dungeons.amethystStone, 0);
        this.setBlock(world, i + 7, j + 44, k + 31, Dungeons.amethystStone, 0);
        this.setBlock(world, i + 7, j + 44, k + 32, Dungeons.amethystStone, 0);
        this.setBlock(world, i + 7, j + 45, k + 29, Dungeons.amethystStone, 0);
        this.setBlock(world, i + 7, j + 45, k + 30, Dungeons.amethystStone, 0);
        this.setBlock(world, i + 7, j + 45, k + 31, Dungeons.amethystStone, 0);
        this.setBlock(world, i + 7, j + 45, k + 32, Dungeons.amethystStone, 0);
        this.setBlock(world, i + 7, j + 45, k + 33, Dungeons.amethystStone, 0);
        this.setBlock(world, i + 7, j + 45, k + 34, Dungeons.amethystStone, 0);
        this.setBlock(world, i + 7, j + 45, k + 35, Dungeons.amethystStone, 0);
        this.setBlock(world, i + 7, j + 45, k + 36, Dungeons.amethystStone, 0);
        this.setBlock(world, i + 7, j + 46, k + 26, Dungeons.amethystStone, 0);
        this.setBlock(world, i + 7, j + 46, k + 27, Dungeons.amethystStone, 0);
        this.setBlock(world, i + 7, j + 46, k + 28, Dungeons.amethystStone, 0);
        this.setBlock(world, i + 7, j + 46, k + 29, Dungeons.amethystStone, 0);
        this.setBlock(world, i + 7, j + 46, k + 30, Dungeons.amethystStone, 0);
        this.setBlock(world, i + 7, j + 46, k + 31, Dungeons.amethystStone, 0);
        this.setBlock(world, i + 7, j + 46, k + 32, Dungeons.amethystStone, 0);
        this.setBlock(world, i + 7, j + 46, k + 33, Dungeons.amethystStone, 0);
        this.setBlock(world, i + 7, j + 46, k + 34, Dungeons.amethystStone, 0);
        this.setBlock(world, i + 7, j + 46, k + 35, Dungeons.amethystStone, 0);
        this.setBlock(world, i + 7, j + 46, k + 36, Dungeons.amethystStone, 0);
        this.setBlock(world, i + 7, j + 46, k + 37, Dungeons.amethystStone, 0);
        this.setBlock(world, i + 7, j + 47, k + 23, Dungeons.amethystStone, 0);
        this.setBlock(world, i + 7, j + 47, k + 24, Dungeons.amethystStone, 0);
        this.setBlock(world, i + 7, j + 47, k + 25, Dungeons.amethystStone, 0);
        this.setBlock(world, i + 7, j + 47, k + 26, Dungeons.amethystStone, 0);
        this.setBlock(world, i + 7, j + 47, k + 27, Dungeons.amethystStone, 0);
        this.setBlock(world, i + 7, j + 47, k + 28, Dungeons.amethystStone, 0);
        this.setBlock(world, i + 7, j + 47, k + 29, Dungeons.amethystStone, 0);
        this.setBlock(world, i + 7, j + 47, k + 30, Dungeons.amethystStone, 0);
        this.setBlock(world, i + 7, j + 47, k + 31, Dungeons.amethystStone, 0);
        this.setBlock(world, i + 7, j + 47, k + 32, Dungeons.amethystStone, 0);
        this.setBlock(world, i + 7, j + 47, k + 33, Dungeons.amethystStone, 0);
        this.setBlock(world, i + 7, j + 47, k + 34, Dungeons.amethystStone, 0);
        this.setBlock(world, i + 7, j + 47, k + 35, Dungeons.amethystStone, 0);
        this.setBlock(world, i + 7, j + 47, k + 36, Dungeons.amethystStone, 0);
        this.setBlock(world, i + 7, j + 47, k + 37, Dungeons.amethystStone, 0);
        this.setBlock(world, i + 7, j + 48, k + 23, Dungeons.amethystStone, 0);
        this.setBlock(world, i + 7, j + 48, k + 24, Dungeons.amethystStone, 0);
        this.setBlock(world, i + 7, j + 48, k + 25, Dungeons.amethystStone, 0);
        this.setBlock(world, i + 7, j + 48, k + 26, Dungeons.amethystStone, 0);
        this.setBlock(world, i + 7, j + 48, k + 27, Dungeons.amethystStone, 0);
        this.setBlock(world, i + 7, j + 48, k + 28, Dungeons.amethystStone, 0);
        this.setBlock(world, i + 7, j + 48, k + 29, Dungeons.amethystStone, 0);
        this.setBlock(world, i + 7, j + 48, k + 30, Dungeons.amethystStone, 0);
        this.setBlock(world, i + 7, j + 48, k + 31, Dungeons.amethystStone, 0);
        this.setBlock(world, i + 7, j + 48, k + 32, Dungeons.amethystStone, 0);
        this.setBlock(world, i + 7, j + 48, k + 33, Dungeons.amethystStone, 0);
        this.setBlock(world, i + 7, j + 48, k + 34, Dungeons.amethystStone, 0);
        this.setBlock(world, i + 7, j + 48, k + 35, Dungeons.amethystStone, 0);
        this.setBlock(world, i + 7, j + 48, k + 36, Dungeons.amethystStone, 0);
        this.setBlock(world, i + 7, j + 48, k + 37, Dungeons.amethystStone, 0);
        this.setBlock(world, i + 7, j + 49, k + 21, Dungeons.amethystStone, 0);
        this.setBlock(world, i + 7, j + 49, k + 22, Dungeons.amethystStone, 0);
        this.setBlock(world, i + 7, j + 49, k + 23, Dungeons.amethystStone, 0);
        this.setBlock(world, i + 7, j + 49, k + 24, Dungeons.amethystStone, 0);
        this.setBlock(world, i + 7, j + 49, k + 25, Dungeons.amethystStone, 0);
        this.setBlock(world, i + 7, j + 49, k + 26, Dungeons.amethystStone, 0);
        this.setBlock(world, i + 7, j + 49, k + 27, Dungeons.amethystStone, 0);
        this.setBlock(world, i + 7, j + 49, k + 28, Dungeons.amethystStone, 0);
        this.setBlock(world, i + 7, j + 49, k + 29, Dungeons.amethystStone, 0);
        this.setBlock(world, i + 7, j + 49, k + 30, Dungeons.amethystStone, 0);
        this.setBlock(world, i + 7, j + 49, k + 31, Dungeons.amethystStone, 0);
        this.setBlock(world, i + 7, j + 49, k + 32, Dungeons.amethystStone, 0);
        this.setBlock(world, i + 7, j + 49, k + 33, Dungeons.amethystStone, 0);
        this.setBlock(world, i + 7, j + 49, k + 34, Dungeons.amethystStone, 0);
        this.setBlock(world, i + 7, j + 49, k + 35, Dungeons.amethystStone, 0);
        this.setBlock(world, i + 7, j + 49, k + 36, Dungeons.amethystStone, 0);
        this.setBlock(world, i + 7, j + 49, k + 37, Dungeons.amethystStone, 0);
        this.setBlock(world, i + 7, j + 50, k + 21, Dungeons.amethystStone, 0);
        this.setBlock(world, i + 7, j + 50, k + 22, Dungeons.amethystStone, 0);
        this.setBlock(world, i + 7, j + 50, k + 23, Dungeons.amethystStone, 0);
        this.setBlock(world, i + 7, j + 50, k + 24, Dungeons.amethystStone, 0);
        this.setBlock(world, i + 7, j + 50, k + 25, Dungeons.amethystStone, 0);
        this.setBlock(world, i + 7, j + 50, k + 26, Dungeons.amethystStone, 0);
        this.setBlock(world, i + 7, j + 50, k + 27, Dungeons.amethystStone, 0);
        this.setBlock(world, i + 7, j + 50, k + 28, Dungeons.amethystStone, 0);
        this.setBlock(world, i + 7, j + 50, k + 29, Dungeons.amethystStone, 0);
        this.setBlock(world, i + 7, j + 50, k + 30, Dungeons.amethystStone, 0);
        this.setBlock(world, i + 7, j + 50, k + 31, Dungeons.amethystStone, 0);
        this.setBlock(world, i + 7, j + 50, k + 32, Dungeons.amethystStone, 0);
        this.setBlock(world, i + 7, j + 50, k + 33, Dungeons.amethystStone, 0);
        this.setBlock(world, i + 7, j + 50, k + 34, Dungeons.amethystStone, 0);
        this.setBlock(world, i + 7, j + 50, k + 35, Dungeons.amethystStone, 0);
        this.setBlock(world, i + 7, j + 50, k + 36, Dungeons.amethystStone, 0);
        this.setBlock(world, i + 7, j + 50, k + 37, Dungeons.amethystStone, 0);
        this.setBlock(world, i + 7, j + 51, k + 21, Dungeons.amethystStone, 0);
        this.setBlock(world, i + 7, j + 51, k + 22, Dungeons.amethystStone, 0);
        this.setBlock(world, i + 7, j + 51, k + 23, Dungeons.amethystStone, 0);
        this.setBlock(world, i + 7, j + 51, k + 24, Dungeons.amethystStone, 0);
        this.setBlock(world, i + 7, j + 51, k + 25, Dungeons.amethystStone, 0);
        this.setBlock(world, i + 7, j + 51, k + 26, Dungeons.amethystStone, 0);
        this.setBlock(world, i + 7, j + 51, k + 27, Dungeons.amethystStone, 0);
        this.setBlock(world, i + 7, j + 51, k + 28, Dungeons.amethystStone, 0);
        this.setBlock(world, i + 7, j + 51, k + 29, Dungeons.amethystStone, 0);
        this.setBlock(world, i + 7, j + 51, k + 30, Dungeons.amethystStone, 0);
        this.setBlock(world, i + 7, j + 51, k + 31, Dungeons.amethystStone, 0);
        this.setBlock(world, i + 7, j + 51, k + 32, Dungeons.crystalliumDirt, 0);
        this.setBlock(world, i + 7, j + 51, k + 33, Dungeons.crystalliumDirt, 0);
        this.setBlock(world, i + 7, j + 51, k + 34, Dungeons.crystalliumGrass, 0);
        this.setBlock(world, i + 7, j + 51, k + 35, Dungeons.crystalliumGrass, 0);
        this.setBlock(world, i + 7, j + 53, k + 28, Dungeons.crystalliumGrass, 0);
        this.setBlock(world, i + 7, j + 53, k + 29, Dungeons.crystalliumGrass, 0);
        this.setBlock(world, i + 7, j + 53, k + 30, Dungeons.crystalliumGrass, 0);
        this.setBlock(world, i + 7, j + 53, k + 31, Dungeons.crystalliumGrass, 0);
        this.setBlock(world, i + 8, j + 22, k + 26, Dungeons.amethystStone, 0);
        this.setBlock(world, i + 8, j + 22, k + 27, Dungeons.amethystStone, 0);
        this.setBlock(world, i + 8, j + 22, k + 28, Dungeons.amethystStone, 0);
        this.setBlock(world, i + 8, j + 22, k + 29, Dungeons.amethystStone, 0);
        this.setBlock(world, i + 8, j + 22, k + 30, Dungeons.amethystStone, 0);
        this.setBlock(world, i + 8, j + 22, k + 31, Dungeons.amethystStone, 0);
        this.setBlock(world, i + 8, j + 22, k + 32, Dungeons.amethystStone, 0);
        this.setBlock(world, i + 8, j + 22, k + 33, Dungeons.amethystStone, 0);
        this.setBlock(world, i + 8, j + 22, k + 34, Dungeons.amethystStone, 0);
        this.setBlock(world, i + 8, j + 23, k + 21, Dungeons.amethystStone, 0);
        this.setBlock(world, i + 8, j + 23, k + 22, Dungeons.amethystStone, 0);
        this.setBlock(world, i + 8, j + 23, k + 23, Dungeons.amethystStone, 0);
        this.setBlock(world, i + 8, j + 23, k + 24, Dungeons.amethystStone, 0);
        this.setBlock(world, i + 8, j + 23, k + 25, Dungeons.amethystStone, 0);
        this.setBlock(world, i + 8, j + 23, k + 26, Dungeons.amethystStone, 0);
        this.setBlock(world, i + 8, j + 23, k + 27, Dungeons.amethystStone, 0);
        this.setBlock(world, i + 8, j + 23, k + 28, Dungeons.amethystStone, 0);
        this.setBlock(world, i + 8, j + 23, k + 29, Dungeons.amethystStone, 0);
        this.setBlock(world, i + 8, j + 23, k + 30, Dungeons.amethystStone, 0);
        this.setBlock(world, i + 8, j + 23, k + 31, Dungeons.amethystStone, 0);
        this.setBlock(world, i + 8, j + 23, k + 32, Dungeons.amethystStone, 0);
        this.setBlock(world, i + 8, j + 23, k + 33, Dungeons.amethystStone, 0);
        this.setBlock(world, i + 8, j + 23, k + 34, Dungeons.amethystStone, 0);
        this.setBlock(world, i + 8, j + 23, k + 35, Dungeons.amethystStone, 0);
        this.setBlock(world, i + 8, j + 23, k + 36, Dungeons.amethystStone, 0);
        this.setBlock(world, i + 8, j + 23, k + 37, Dungeons.amethystStone, 0);
        this.setBlock(world, i + 8, j + 23, k + 38, Dungeons.amethystStone, 0);
        this.setBlock(world, i + 8, j + 23, k + 39, Dungeons.amethystStone, 0);
        this.setBlock(world, i + 8, j + 24, k + 19, Dungeons.crystalliumLamp, 0);
        this.setBlock(world, i + 8, j + 24, k + 20, Dungeons.crystalliumDirt, 0);
        this.setBlock(world, i + 8, j + 24, k + 21, Dungeons.crystalliumDirt, 0);
        this.setBlock(world, i + 8, j + 24, k + 22, Dungeons.crystalliumDirt, 0);
        this.setBlock(world, i + 8, j + 24, k + 23, Dungeons.crystalliumDirt, 0);
        this.setBlock(world, i + 8, j + 24, k + 24, Dungeons.crystalliumDirt, 0);
        this.setBlock(world, i + 8, j + 24, k + 25, Dungeons.crystalliumDirt, 0);
        this.setBlock(world, i + 8, j + 24, k + 26, Dungeons.crystalliumDirt, 0);
        this.setBlock(world, i + 8, j + 24, k + 27, Dungeons.crystalliumDirt, 0);
        this.setBlock(world, i + 8, j + 24, k + 28, Dungeons.crystalliumDirt, 0);
        this.setBlock(world, i + 8, j + 24, k + 29, Dungeons.crystalliumDirt, 0);
        this.setBlock(world, i + 8, j + 24, k + 30, Dungeons.crystalliumDirt, 0);
        this.setBlock(world, i + 8, j + 24, k + 31, Dungeons.crystalliumDirt, 0);
        this.setBlock(world, i + 8, j + 24, k + 32, Dungeons.crystalliumDirt, 0);
        this.setBlock(world, i + 8, j + 24, k + 33, Dungeons.crystalliumDirt, 0);
        this.setBlock(world, i + 8, j + 24, k + 34, Dungeons.crystalliumDirt, 0);
        this.setBlock(world, i + 8, j + 24, k + 35, Dungeons.crystalliumDirt, 0);
        this.setBlock(world, i + 8, j + 24, k + 36, Dungeons.crystalliumDirt, 0);
        this.setBlock(world, i + 8, j + 24, k + 37, Dungeons.crystalliumDirt, 0);
        this.setBlock(world, i + 8, j + 24, k + 38, Dungeons.crystalliumDirt, 0);
        this.setBlock(world, i + 8, j + 24, k + 39, Dungeons.crystalliumDirt, 0);
        this.setBlock(world, i + 8, j + 25, k + 19, Dungeons.crystalliumDirt, 0);
        this.setBlock(world, i + 8, j + 25, k + 20, Dungeons.crystalliumDirt, 0);
        this.setBlock(world, i + 8, j + 25, k + 21, Dungeons.crystalliumDirt, 0);
        this.setBlock(world, i + 8, j + 25, k + 22, Dungeons.crystalliumDirt, 0);
        this.setBlock(world, i + 8, j + 25, k + 23, Dungeons.crystalliumDirt, 0);
        this.setBlock(world, i + 8, j + 25, k + 24, Dungeons.crystalliumDirt, 0);
        this.setBlock(world, i + 8, j + 25, k + 25, Dungeons.crystalliumDirt, 0);
        this.setBlock(world, i + 8, j + 25, k + 26, Dungeons.crystalliumDirt, 0);
        this.setBlock(world, i + 8, j + 25, k + 27, Dungeons.crystalliumDirt, 0);
        this.setBlock(world, i + 8, j + 25, k + 28, Blocks.obsidian, 0);
        this.setBlock(world, i + 8, j + 25, k + 29, Dungeons.crystalliumDirt, 0);
        this.setBlock(world, i + 8, j + 25, k + 30, Dungeons.crystalliumDirt, 0);
        this.setBlock(world, i + 8, j + 25, k + 31, Dungeons.crystalliumDirt, 0);
        this.setBlock(world, i + 8, j + 25, k + 32, Dungeons.crystalliumDirt, 0);
        this.setBlock(world, i + 8, j + 25, k + 33, Dungeons.crystalliumDirt, 0);
        this.setBlock(world, i + 8, j + 25, k + 34, Dungeons.crystalliumDirt, 0);
        this.setBlock(world, i + 8, j + 25, k + 35, Dungeons.crystalliumDirt, 0);
        this.setBlock(world, i + 8, j + 25, k + 36, Dungeons.crystalliumDirt, 0);
        this.setBlock(world, i + 8, j + 25, k + 37, Dungeons.crystalliumDirt, 0);
        this.setBlock(world, i + 8, j + 25, k + 38, Dungeons.crystalliumDirt, 0);
        this.setBlock(world, i + 8, j + 25, k + 39, Dungeons.crystalliumDirt, 0);
        this.setBlock(world, i + 8, j + 26, k + 19, Dungeons.crystalliumGrass, 0);
        this.setBlock(world, i + 8, j + 26, k + 20, Dungeons.crystalliumGrass, 0);
        this.setBlock(world, i + 8, j + 26, k + 21, Dungeons.crystalliumGrass, 0);
        this.setBlock(world, i + 8, j + 26, k + 22, Dungeons.crystalliumGrass, 0);
        this.setBlock(world, i + 8, j + 26, k + 23, Dungeons.crystalliumGrass, 0);
        this.setBlock(world, i + 8, j + 26, k + 24, Dungeons.crystalliumGrass, 0);
        this.setBlock(world, i + 8, j + 26, k + 25, Dungeons.crystalliumGrass, 0);
        this.setBlock(world, i + 8, j + 26, k + 26, Dungeons.crystalliumGrass, 0);
        this.setBlock(world, i + 8, j + 26, k + 27, Dungeons.crystalliumGrass, 0);
        this.setBlock(world, i + 8, j + 26, k + 28, Blocks.obsidian, 0);
        this.setBlock(world, i + 8, j + 26, k + 29, Dungeons.crystalliumGrass, 0);
        this.setBlock(world, i + 8, j + 26, k + 30, Dungeons.crystalliumGrass, 0);
        this.setBlock(world, i + 8, j + 26, k + 31, Dungeons.crystalliumGrass, 0);
        this.setBlock(world, i + 8, j + 26, k + 32, Dungeons.crystalliumGrass, 0);
        this.setBlock(world, i + 8, j + 26, k + 33, Dungeons.crystalliumGrass, 0);
        this.setBlock(world, i + 8, j + 26, k + 34, Dungeons.crystalliumGrass, 0);
        this.setBlock(world, i + 8, j + 26, k + 35, Dungeons.crystalliumGrass, 0);
        this.setBlock(world, i + 8, j + 26, k + 36, Dungeons.crystalliumGrass, 0);
        this.setBlock(world, i + 8, j + 26, k + 37, Dungeons.crystalliumGrass, 0);
        this.setBlock(world, i + 8, j + 26, k + 38, Dungeons.crystalliumGrass, 0);
        this.setBlock(world, i + 8, j + 26, k + 39, Dungeons.crystalliumGrass, 0);
        this.setBlock(world, i + 8, j + 27, k + 28, Blocks.obsidian, 0);
        this.setBlock(world, i + 8, j + 28, k + 28, Blocks.obsidian, 0);
        this.setBlock(world, i + 8, j + 29, k + 28, Blocks.obsidian, 0);
        this.setBlock(world, i + 8, j + 30, k + 28, Blocks.obsidian, 0);
        this.setBlock(world, i + 8, j + 35, k + 28, Blocks.obsidian, 0);
        this.setBlock(world, i + 8, j + 36, k + 28, Blocks.obsidian, 0);
        this.setBlock(world, i + 8, j + 37, k + 28, Blocks.obsidian, 0);
        this.setBlock(world, i + 8, j + 38, k + 28, Blocks.obsidian, 0);
        this.setBlock(world, i + 8, j + 39, k + 28, Blocks.obsidian, 0);
        this.setBlock(world, i + 8, j + 40, k + 28, Blocks.obsidian, 0);
        this.setBlock(world, i + 8, j + 44, k + 31, Dungeons.amethystStone, 0);
        this.setBlock(world, i + 8, j + 44, k + 32, Dungeons.amethystStone, 0);
        this.setBlock(world, i + 8, j + 44, k + 33, Dungeons.amethystStone, 0);
        this.setBlock(world, i + 8, j + 44, k + 34, Dungeons.amethystStone, 0);
        this.setBlock(world, i + 8, j + 45, k + 28, Blocks.obsidian, 0);
        this.setBlock(world, i + 8, j + 45, k + 29, Dungeons.amethystStone, 0);
        this.setBlock(world, i + 8, j + 45, k + 30, Dungeons.amethystStone, 0);
        this.setBlock(world, i + 8, j + 45, k + 31, Dungeons.amethystStone, 0);
        this.setBlock(world, i + 8, j + 45, k + 32, Dungeons.amethystStone, 0);
        this.setBlock(world, i + 8, j + 45, k + 33, Dungeons.amethystStone, 0);
        this.setBlock(world, i + 8, j + 45, k + 34, Dungeons.amethystStone, 0);
        this.setBlock(world, i + 8, j + 45, k + 35, Dungeons.amethystStone, 0);
        this.setBlock(world, i + 8, j + 45, k + 36, Dungeons.amethystStone, 0);
        this.setBlock(world, i + 8, j + 46, k + 24, Dungeons.amethystStone, 0);
        this.setBlock(world, i + 8, j + 46, k + 25, Dungeons.amethystStone, 0);
        this.setBlock(world, i + 8, j + 46, k + 26, Dungeons.amethystStone, 0);
        this.setBlock(world, i + 8, j + 46, k + 27, Dungeons.amethystStone, 0);
        this.setBlock(world, i + 8, j + 46, k + 28, Dungeons.amethystStone, 0);
        this.setBlock(world, i + 8, j + 46, k + 29, Dungeons.amethystStone, 0);
        this.setBlock(world, i + 8, j + 46, k + 30, Dungeons.amethystStone, 0);
        this.setBlock(world, i + 8, j + 46, k + 31, Dungeons.amethystStone, 0);
        this.setBlock(world, i + 8, j + 46, k + 32, Dungeons.amethystStone, 0);
        this.setBlock(world, i + 8, j + 46, k + 33, Dungeons.amethystStone, 0);
        this.setBlock(world, i + 8, j + 46, k + 34, Dungeons.amethystStone, 0);
        this.setBlock(world, i + 8, j + 46, k + 35, Dungeons.amethystStone, 0);
        this.setBlock(world, i + 8, j + 46, k + 36, Dungeons.amethystStone, 0);
        this.setBlock(world, i + 8, j + 46, k + 37, Dungeons.amethystStone, 0);
        this.setBlock(world, i + 8, j + 47, k + 22, Dungeons.amethystStone, 0);
        this.setBlock(world, i + 8, j + 47, k + 23, Dungeons.amethystStone, 0);
        this.setBlock(world, i + 8, j + 47, k + 24, Dungeons.amethystStone, 0);
        this.setBlock(world, i + 8, j + 47, k + 25, Dungeons.amethystStone, 0);
        this.setBlock(world, i + 8, j + 47, k + 26, Dungeons.amethystStone, 0);
        this.setBlock(world, i + 8, j + 47, k + 27, Dungeons.amethystStone, 0);
        this.setBlock(world, i + 8, j + 47, k + 28, Dungeons.amethystStone, 0);
        this.setBlock(world, i + 8, j + 47, k + 29, Dungeons.amethystStone, 0);
        this.setBlock(world, i + 8, j + 47, k + 30, Dungeons.amethystStone, 0);
        this.setBlock(world, i + 8, j + 47, k + 31, Dungeons.amethystStone, 0);
        this.setBlock(world, i + 8, j + 47, k + 32, Dungeons.amethystStone, 0);
        this.setBlock(world, i + 8, j + 47, k + 33, Dungeons.amethystStone, 0);
        this.setBlock(world, i + 8, j + 47, k + 34, Dungeons.amethystStone, 0);
        this.setBlock(world, i + 8, j + 47, k + 35, Dungeons.amethystStone, 0);
        this.setBlock(world, i + 8, j + 47, k + 36, Dungeons.amethystStone, 0);
        this.setBlock(world, i + 8, j + 47, k + 37, Dungeons.amethystStone, 0);
        this.setBlock(world, i + 8, j + 48, k + 21, Dungeons.amethystStone, 0);
        this.setBlock(world, i + 8, j + 48, k + 22, Dungeons.amethystStone, 0);
        this.setBlock(world, i + 8, j + 48, k + 23, Dungeons.amethystStone, 0);
        this.setBlock(world, i + 8, j + 48, k + 24, Dungeons.amethystStone, 0);
        this.setBlock(world, i + 8, j + 48, k + 25, Dungeons.amethystStone, 0);
        this.setBlock(world, i + 8, j + 48, k + 26, Dungeons.amethystStone, 0);
        this.setBlock(world, i + 8, j + 48, k + 27, Dungeons.amethystStone, 0);
        this.setBlock(world, i + 8, j + 48, k + 28, Dungeons.amethystStone, 0);
        this.setBlock(world, i + 8, j + 48, k + 29, Dungeons.amethystStone, 0);
        this.setBlock(world, i + 8, j + 48, k + 30, Dungeons.amethystStone, 0);
        this.setBlock(world, i + 8, j + 48, k + 31, Dungeons.amethystStone, 0);
        this.setBlock(world, i + 8, j + 48, k + 32, Dungeons.amethystStone, 0);
        this.setBlock(world, i + 8, j + 48, k + 33, Dungeons.amethystStone, 0);
        this.setBlock(world, i + 8, j + 48, k + 34, Dungeons.amethystStone, 0);
        this.setBlock(world, i + 8, j + 48, k + 35, Dungeons.amethystStone, 0);
        this.setBlock(world, i + 8, j + 48, k + 36, Dungeons.amethystStone, 0);
        this.setBlock(world, i + 8, j + 48, k + 37, Dungeons.amethystStone, 0);
        this.setBlock(world, i + 8, j + 49, k + 20, Dungeons.amethystStone, 0);
        this.setBlock(world, i + 8, j + 49, k + 21, Dungeons.amethystStone, 0);
        this.setBlock(world, i + 8, j + 49, k + 22, Dungeons.amethystStone, 0);
        this.setBlock(world, i + 8, j + 49, k + 23, Dungeons.amethystStone, 0);
        this.setBlock(world, i + 8, j + 49, k + 24, Dungeons.amethystStone, 0);
        this.setBlock(world, i + 8, j + 49, k + 25, Dungeons.amethystStone, 0);
        this.setBlock(world, i + 8, j + 49, k + 26, Dungeons.amethystStone, 0);
        this.setBlock(world, i + 8, j + 49, k + 27, Dungeons.amethystStone, 0);
        this.setBlock(world, i + 8, j + 49, k + 28, Dungeons.amethystStone, 0);
        this.setBlock(world, i + 8, j + 49, k + 29, Dungeons.amethystStone, 0);
        this.setBlock(world, i + 8, j + 49, k + 30, Dungeons.amethystStone, 0);
        this.setBlock(world, i + 8, j + 49, k + 31, Dungeons.amethystStone, 0);
        this.setBlock(world, i + 8, j + 49, k + 32, Dungeons.amethystStone, 0);
        this.setBlock(world, i + 8, j + 49, k + 33, Dungeons.amethystStone, 0);
        this.setBlock(world, i + 8, j + 49, k + 34, Dungeons.amethystStone, 0);
        this.setBlock(world, i + 8, j + 49, k + 35, Dungeons.amethystStone, 0);
        this.setBlock(world, i + 8, j + 49, k + 36, Dungeons.amethystStone, 0);
        this.setBlock(world, i + 8, j + 49, k + 37, Dungeons.amethystStone, 0);
        this.setBlock(world, i + 8, j + 50, k + 20, Dungeons.amethystStone, 0);
        this.setBlock(world, i + 8, j + 50, k + 21, Dungeons.amethystStone, 0);
        this.setBlock(world, i + 8, j + 50, k + 22, Dungeons.amethystStone, 0);
        this.setBlock(world, i + 8, j + 50, k + 23, Dungeons.amethystStone, 0);
        this.setBlock(world, i + 8, j + 50, k + 24, Dungeons.amethystStone, 0);
        this.setBlock(world, i + 8, j + 50, k + 25, Dungeons.amethystStone, 0);
        this.setBlock(world, i + 8, j + 50, k + 26, Dungeons.amethystStone, 0);
        this.setBlock(world, i + 8, j + 50, k + 27, Dungeons.amethystStone, 0);
        this.setBlock(world, i + 8, j + 50, k + 28, Dungeons.amethystStone, 0);
        this.setBlock(world, i + 8, j + 50, k + 29, Dungeons.amethystStone, 0);
        this.setBlock(world, i + 8, j + 50, k + 30, Dungeons.amethystStone, 0);
        this.setBlock(world, i + 8, j + 50, k + 31, Dungeons.amethystStone, 0);
        this.setBlock(world, i + 8, j + 50, k + 32, Dungeons.amethystStone, 0);
        this.setBlock(world, i + 8, j + 50, k + 33, Dungeons.amethystStone, 0);
        this.setBlock(world, i + 8, j + 50, k + 34, Dungeons.amethystStone, 0);
        this.setBlock(world, i + 8, j + 50, k + 35, Dungeons.amethystStone, 0);
        this.setBlock(world, i + 8, j + 50, k + 36, Dungeons.amethystStone, 0);
        this.setBlock(world, i + 8, j + 50, k + 37, Dungeons.amethystStone, 0);
        this.setBlock(world, i + 8, j + 51, k + 20, Dungeons.amethystStone, 0);
        this.setBlock(world, i + 8, j + 51, k + 21, Dungeons.amethystStone, 0);
        this.setBlock(world, i + 8, j + 51, k + 22, Dungeons.amethystStone, 0);
        this.setBlock(world, i + 8, j + 51, k + 23, Dungeons.amethystStone, 0);
        this.setBlock(world, i + 8, j + 51, k + 24, Dungeons.amethystStone, 0);
        this.setBlock(world, i + 8, j + 51, k + 25, Dungeons.amethystStone, 0);
        this.setBlock(world, i + 8, j + 51, k + 26, Dungeons.amethystStone, 0);
        this.setBlock(world, i + 8, j + 51, k + 27, Dungeons.amethystStone, 0);
        this.setBlock(world, i + 8, j + 51, k + 28, Dungeons.amethystStone, 0);
        this.setBlock(world, i + 8, j + 51, k + 29, Dungeons.amethystStone, 0);
        this.setBlock(world, i + 8, j + 51, k + 30, Dungeons.amethystStone, 0);
        this.setBlock(world, i + 8, j + 51, k + 31, Dungeons.amethystStone, 0);
        this.setBlock(world, i + 8, j + 51, k + 32, Dungeons.amethystStone, 0);
        this.setBlock(world, i + 8, j + 51, k + 33, Dungeons.crystalliumDirt, 0);
        this.setBlock(world, i + 8, j + 51, k + 34, Dungeons.crystalliumDirt, 0);
        this.setBlock(world, i + 8, j + 51, k + 35, Dungeons.crystalliumGrass, 0);
        this.setBlock(world, i + 8, j + 51, k + 36, Dungeons.amethystStone, 0);
        this.setBlock(world, i + 8, j + 51, k + 37, Dungeons.amethystStone, 0);
        this.setBlock(world, i + 8, j + 52, k + 21, Dungeons.amethystStone, 0);
        this.setBlock(world, i + 8, j + 52, k + 22, Dungeons.amethystStone, 0);
        this.setBlock(world, i + 8, j + 52, k + 23, Dungeons.amethystStone, 0);
        this.setBlock(world, i + 8, j + 52, k + 24, Dungeons.amethystStone, 0);
        this.setBlock(world, i + 8, j + 52, k + 25, Dungeons.amethystStone, 0);
        this.setBlock(world, i + 8, j + 52, k + 26, Dungeons.amethystStone, 0);
        this.setBlock(world, i + 8, j + 52, k + 27, Dungeons.amethystStone, 0);
        this.setBlock(world, i + 8, j + 52, k + 28, Dungeons.amethystStone, 0);
        this.setBlock(world, i + 8, j + 52, k + 29, Dungeons.amethystStone, 0);
        this.setBlock(world, i + 8, j + 52, k + 30, Dungeons.crystalliumDirt, 0);
        this.setBlock(world, i + 8, j + 52, k + 31, Dungeons.crystalliumDirt, 0);
        this.setBlock(world, i + 8, j + 52, k + 32, Dungeons.crystalliumGrass, 0);
        this.setBlock(world, i + 8, j + 52, k + 33, Dungeons.crystalliumGrass, 0);
        this.setBlock(world, i + 8, j + 52, k + 34, Dungeons.crystalliumGrass, 0);
        this.setBlock(world, i + 8, j + 53, k + 23, Dungeons.amethystStone, 0);
        this.setBlock(world, i + 8, j + 53, k + 24, Dungeons.amethystStone, 0);
        this.setBlock(world, i + 8, j + 53, k + 25, Dungeons.amethystStone, 0);
        this.setBlock(world, i + 8, j + 53, k + 26, Dungeons.amethystStone, 0);
        this.setBlock(world, i + 8, j + 53, k + 27, Dungeons.amethystStone, 0);
        this.setBlock(world, i + 8, j + 53, k + 28, Dungeons.crystalliumDirt, 0);
        this.setBlock(world, i + 8, j + 53, k + 29, Dungeons.crystalliumGrass, 0);
        this.setBlock(world, i + 8, j + 53, k + 30, Dungeons.crystalliumGrass, 0);
        this.setBlock(world, i + 8, j + 53, k + 31, Dungeons.crystalliumGrass, 0);
        this.setBlock(world, i + 8, j + 54, k + 25, Dungeons.crystalliumGrass, 0);
        this.setBlock(world, i + 8, j + 54, k + 26, Dungeons.crystalliumGrass, 0);
        this.setBlock(world, i + 8, j + 54, k + 27, Dungeons.crystalliumGrass, 0);
        this.setBlock(world, i + 8, j + 54, k + 28, Dungeons.crystalliumGrass, 0);
        this.setBlock(world, i + 9, j + 21, k + 28, Dungeons.amethystStone, 0);
        this.setBlock(world, i + 9, j + 21, k + 29, Dungeons.amethystStone, 0);
        this.setBlock(world, i + 9, j + 21, k + 30, Dungeons.amethystStone, 0);
        this.setBlock(world, i + 9, j + 21, k + 31, Dungeons.amethystStone, 0);
        this.setBlock(world, i + 9, j + 22, k + 24, Dungeons.amethystStone, 0);
        this.setBlock(world, i + 9, j + 22, k + 25, Dungeons.amethystStone, 0);
        this.setBlock(world, i + 9, j + 22, k + 26, Dungeons.amethystStone, 0);
        this.setBlock(world, i + 9, j + 22, k + 27, Dungeons.amethystStone, 0);
        this.setBlock(world, i + 9, j + 22, k + 28, Dungeons.amethystStone, 0);
        this.setBlock(world, i + 9, j + 22, k + 29, Dungeons.amethystStone, 0);
        this.setBlock(world, i + 9, j + 22, k + 30, Dungeons.amethystStone, 0);
        this.setBlock(world, i + 9, j + 22, k + 31, Dungeons.amethystStone, 0);
        this.setBlock(world, i + 9, j + 22, k + 32, Dungeons.amethystStone, 0);
        this.setBlock(world, i + 9, j + 22, k + 33, Dungeons.amethystStone, 0);
        this.setBlock(world, i + 9, j + 22, k + 34, Dungeons.amethystStone, 0);
        this.setBlock(world, i + 9, j + 22, k + 35, Dungeons.amethystStone, 0);
        this.setBlock(world, i + 9, j + 22, k + 36, Dungeons.amethystStone, 0);
        this.setBlock(world, i + 9, j + 23, k + 18, Dungeons.amethystStone, 0);
        this.setBlock(world, i + 9, j + 23, k + 19, Dungeons.amethystStone, 0);
        this.setBlock(world, i + 9, j + 23, k + 20, Dungeons.amethystStone, 0);
        this.setBlock(world, i + 9, j + 23, k + 21, Dungeons.amethystStone, 0);
        this.setBlock(world, i + 9, j + 23, k + 22, Dungeons.amethystStone, 0);
        this.setBlock(world, i + 9, j + 23, k + 23, Dungeons.amethystStone, 0);
        this.setBlock(world, i + 9, j + 23, k + 24, Dungeons.amethystStone, 0);
        this.setBlock(world, i + 9, j + 23, k + 25, Dungeons.amethystStone, 0);
        this.setBlock(world, i + 9, j + 23, k + 26, Dungeons.amethystStone, 0);
        this.setBlock(world, i + 9, j + 23, k + 27, Dungeons.amethystStone, 0);
        this.setBlock(world, i + 9, j + 23, k + 28, Dungeons.amethystStone, 0);
        this.setBlock(world, i + 9, j + 23, k + 29, Dungeons.amethystStone, 0);
        this.setBlock(world, i + 9, j + 23, k + 30, Dungeons.amethystStone, 0);
        this.setBlock(world, i + 9, j + 23, k + 31, Dungeons.amethystStone, 0);
        this.setBlock(world, i + 9, j + 23, k + 32, Dungeons.amethystStone, 0);
        this.setBlock(world, i + 9, j + 23, k + 33, Dungeons.amethystStone, 0);
        this.setBlock(world, i + 9, j + 23, k + 34, Dungeons.amethystStone, 0);
        this.setBlock(world, i + 9, j + 23, k + 35, Dungeons.amethystStone, 0);
        this.setBlock(world, i + 9, j + 23, k + 36, Dungeons.amethystStone, 0);
        this.setBlock(world, i + 9, j + 23, k + 37, Dungeons.amethystStone, 0);
        this.setBlock(world, i + 9, j + 23, k + 38, Dungeons.amethystStone, 0);
        this.setBlock(world, i + 9, j + 23, k + 39, Dungeons.amethystStone, 0);
        this.setBlock(world, i + 9, j + 24, k + 18, Dungeons.crystalliumDirt, 0);
        this.setBlock(world, i + 9, j + 24, k + 19, Dungeons.crystalliumDirt, 0);
        this.setBlock(world, i + 9, j + 24, k + 20, Dungeons.crystalliumDirt, 0);
        this.setBlock(world, i + 9, j + 24, k + 21, Dungeons.crystalliumDirt, 0);
        this.setBlock(world, i + 9, j + 24, k + 22, Dungeons.crystalliumDirt, 0);
        this.setBlock(world, i + 9, j + 24, k + 23, Dungeons.crystalliumDirt, 0);
        this.setBlock(world, i + 9, j + 24, k + 24, Dungeons.crystalliumDirt, 0);
        this.setBlock(world, i + 9, j + 24, k + 25, Dungeons.crystalliumDirt, 0);
        this.setBlock(world, i + 9, j + 24, k + 26, Dungeons.crystalliumDirt, 0);
        this.setBlock(world, i + 9, j + 24, k + 27, Dungeons.crystalliumDirt, 0);
        this.setBlock(world, i + 9, j + 24, k + 28, Dungeons.crystalliumDirt, 0);
        this.setBlock(world, i + 9, j + 24, k + 29, Dungeons.crystalliumDirt, 0);
        this.setBlock(world, i + 9, j + 24, k + 30, Dungeons.crystalliumDirt, 0);
        this.setBlock(world, i + 9, j + 24, k + 31, Dungeons.crystalliumDirt, 0);
        this.setBlock(world, i + 9, j + 24, k + 32, Dungeons.crystalliumDirt, 0);
        this.setBlock(world, i + 9, j + 24, k + 33, Dungeons.crystalliumDirt, 0);
        this.setBlock(world, i + 9, j + 24, k + 34, Dungeons.crystalliumDirt, 0);
        this.setBlock(world, i + 9, j + 24, k + 35, Dungeons.crystalliumDirt, 0);
        this.setBlock(world, i + 9, j + 24, k + 36, Dungeons.crystalliumDirt, 0);
        this.setBlock(world, i + 9, j + 24, k + 37, Dungeons.crystalliumDirt, 0);
        this.setBlock(world, i + 9, j + 24, k + 38, Dungeons.crystalliumDirt, 0);
        this.setBlock(world, i + 9, j + 24, k + 39, Dungeons.crystalliumDirt, 0);
        this.setBlock(world, i + 9, j + 25, k + 17, Dungeons.crystalliumDirt, 0);
        this.setBlock(world, i + 9, j + 25, k + 18, Dungeons.crystalliumDirt, 0);
        this.setBlock(world, i + 9, j + 25, k + 19, Dungeons.crystalliumDirt, 0);
        this.setBlock(world, i + 9, j + 25, k + 20, Dungeons.crystalliumDirt, 0);
        this.setBlock(world, i + 9, j + 25, k + 21, Dungeons.crystalliumDirt, 0);
        this.setBlock(world, i + 9, j + 25, k + 22, Dungeons.crystalliumDirt, 0);
        this.setBlock(world, i + 9, j + 25, k + 23, Dungeons.crystalliumDirt, 0);
        this.setBlock(world, i + 9, j + 25, k + 24, Dungeons.crystalliumDirt, 0);
        this.setBlock(world, i + 9, j + 25, k + 25, Dungeons.crystalliumDirt, 0);
        this.setBlock(world, i + 9, j + 25, k + 26, Dungeons.crystalliumDirt, 0);
        this.setBlock(world, i + 9, j + 25, k + 27, Dungeons.crystalliumDirt, 0);
        this.setBlock(world, i + 9, j + 25, k + 28, Dungeons.crystalliumDirt, 0);
        this.setBlock(world, i + 9, j + 25, k + 29, Dungeons.crystalliumDirt, 0);
        this.setBlock(world, i + 9, j + 25, k + 30, Dungeons.crystalliumDirt, 0);
        this.setBlock(world, i + 9, j + 25, k + 31, Dungeons.crystalliumDirt, 0);
        this.setBlock(world, i + 9, j + 25, k + 32, Dungeons.crystalliumDirt, 0);
        this.setBlock(world, i + 9, j + 25, k + 33, Dungeons.crystalliumDirt, 0);
        this.setBlock(world, i + 9, j + 25, k + 34, Dungeons.crystalliumDirt, 0);
        this.setBlock(world, i + 9, j + 25, k + 35, Dungeons.crystalliumDirt, 0);
        this.setBlock(world, i + 9, j + 25, k + 36, Dungeons.crystalliumDirt, 0);
        this.setBlock(world, i + 9, j + 25, k + 37, Dungeons.crystalliumDirt, 0);
        this.setBlock(world, i + 9, j + 25, k + 38, Dungeons.crystalliumDirt, 0);
        this.setBlock(world, i + 9, j + 25, k + 39, Dungeons.crystalliumDirt, 0);
        this.setBlock(world, i + 9, j + 25, k + 40, Dungeons.crystalliumDirt, 0);
        this.setBlock(world, i + 9, j + 25, k + 41, Dungeons.crystalliumDirt, 0);
        this.setBlock(world, i + 9, j + 26, k + 17, Dungeons.crystalliumGrass, 0);
        this.setBlock(world, i + 9, j + 26, k + 18, Dungeons.crystalliumGrass, 0);
        this.setBlock(world, i + 9, j + 26, k + 19, Dungeons.crystalliumGrass, 0);
        this.setBlock(world, i + 9, j + 26, k + 20, Dungeons.crystalliumGrass, 0);
        this.setBlock(world, i + 9, j + 26, k + 21, Dungeons.crystalliumGrass, 0);
        this.setBlock(world, i + 9, j + 26, k + 22, Dungeons.crystalliumGrass, 0);
        this.setBlock(world, i + 9, j + 26, k + 23, Dungeons.crystalliumGrass, 0);
        this.setBlock(world, i + 9, j + 26, k + 24, Dungeons.crystalliumGrass, 0);
        this.setBlock(world, i + 9, j + 26, k + 25, Dungeons.crystalliumGrass, 0);
        this.setBlock(world, i + 9, j + 26, k + 26, Dungeons.crystalliumGrass, 0);
        this.setBlock(world, i + 9, j + 26, k + 27, Dungeons.crystalliumGrass, 0);
        this.setBlock(world, i + 9, j + 26, k + 28, Dungeons.crystalliumGrass, 0);
        this.setBlock(world, i + 9, j + 26, k + 29, Dungeons.crystalliumGrass, 0);
        this.setBlock(world, i + 9, j + 26, k + 30, Dungeons.crystalliumGrass, 0);
        this.setBlock(world, i + 9, j + 26, k + 31, Dungeons.crystalliumGrass, 0);
        this.setBlock(world, i + 9, j + 26, k + 32, Dungeons.crystalliumGrass, 0);
        this.setBlock(world, i + 9, j + 26, k + 33, Dungeons.crystalliumGrass, 0);
        this.setBlock(world, i + 9, j + 26, k + 34, Dungeons.crystalliumGrass, 0);
        this.setBlock(world, i + 9, j + 26, k + 35, Dungeons.crystalliumGrass, 0);
        this.setBlock(world, i + 9, j + 26, k + 36, Dungeons.crystalliumGrass, 0);
        this.setBlock(world, i + 9, j + 26, k + 37, Dungeons.crystalliumGrass, 0);
        this.setBlock(world, i + 9, j + 26, k + 38, Dungeons.crystalliumGrass, 0);
        this.setBlock(world, i + 9, j + 26, k + 39, Dungeons.crystalliumGrass, 0);
        this.setBlock(world, i + 9, j + 26, k + 40, Dungeons.crystalliumGrass, 0);
        this.setBlock(world, i + 9, j + 26, k + 41, Dungeons.crystalliumGrass, 0);
        this.setBlock(world, i + 9, j + 26, k + 42, Dungeons.crystalliumGrass, 0);
        this.setBlock(world, i + 9, j + 44, k + 29, Dungeons.amethystStone, 0);
        this.setBlock(world, i + 9, j + 44, k + 30, Dungeons.amethystStone, 0);
        this.setBlock(world, i + 9, j + 44, k + 31, Dungeons.amethystStone, 0);
        this.setBlock(world, i + 9, j + 44, k + 32, Dungeons.amethystStone, 0);
        this.setBlock(world, i + 9, j + 44, k + 33, Dungeons.amethystStone, 0);
        this.setBlock(world, i + 9, j + 44, k + 34, Dungeons.amethystStone, 0);
        this.setBlock(world, i + 9, j + 45, k + 25, Dungeons.amethystStone, 0);
        this.setBlock(world, i + 9, j + 45, k + 26, Dungeons.amethystStone, 0);
        this.setBlock(world, i + 9, j + 45, k + 27, Dungeons.amethystStone, 0);
        this.setBlock(world, i + 9, j + 45, k + 28, Dungeons.amethystStone, 0);
        this.setBlock(world, i + 9, j + 45, k + 29, Dungeons.amethystStone, 0);
        this.setBlock(world, i + 9, j + 45, k + 30, Dungeons.amethystStone, 0);
        this.setBlock(world, i + 9, j + 45, k + 31, Dungeons.amethystStone, 0);
        this.setBlock(world, i + 9, j + 45, k + 32, Dungeons.amethystStone, 0);
        this.setBlock(world, i + 9, j + 45, k + 33, Dungeons.amethystStone, 0);
        this.setBlock(world, i + 9, j + 45, k + 34, Dungeons.amethystStone, 0);
        this.setBlock(world, i + 9, j + 45, k + 35, Dungeons.amethystStone, 0);
        this.setBlock(world, i + 9, j + 45, k + 36, Dungeons.amethystStone, 0);
        this.setBlock(world, i + 9, j + 46, k + 22, Dungeons.amethystStone, 0);
        this.setBlock(world, i + 9, j + 46, k + 23, Dungeons.amethystStone, 0);
        this.setBlock(world, i + 9, j + 46, k + 24, Dungeons.amethystStone, 0);
        this.setBlock(world, i + 9, j + 46, k + 25, Dungeons.amethystStone, 0);
        this.setBlock(world, i + 9, j + 46, k + 26, Dungeons.amethystStone, 0);
        this.setBlock(world, i + 9, j + 46, k + 27, Dungeons.amethystStone, 0);
        this.setBlock(world, i + 9, j + 46, k + 28, Dungeons.amethystStone, 0);
        this.setBlock(world, i + 9, j + 46, k + 29, Dungeons.amethystStone, 0);
        this.setBlock(world, i + 9, j + 46, k + 30, Dungeons.amethystStone, 0);
        this.setBlock(world, i + 9, j + 46, k + 31, Dungeons.amethystStone, 0);
        this.setBlock(world, i + 9, j + 46, k + 32, Dungeons.amethystStone, 0);
        this.setBlock(world, i + 9, j + 46, k + 33, Dungeons.amethystStone, 0);
        this.setBlock(world, i + 9, j + 46, k + 34, Dungeons.amethystStone, 0);
        this.setBlock(world, i + 9, j + 46, k + 35, Dungeons.amethystStone, 0);
        this.setBlock(world, i + 9, j + 46, k + 36, Dungeons.amethystStone, 0);
        this.setBlock(world, i + 9, j + 46, k + 37, Dungeons.amethystStone, 0);
        this.setBlock(world, i + 9, j + 47, k + 21, Dungeons.amethystStone, 0);
        this.setBlock(world, i + 9, j + 47, k + 22, Dungeons.amethystStone, 0);
        this.setBlock(world, i + 9, j + 47, k + 23, Dungeons.amethystStone, 0);
        this.setBlock(world, i + 9, j + 47, k + 24, Dungeons.amethystStone, 0);
        this.setBlock(world, i + 9, j + 47, k + 25, Dungeons.amethystStone, 0);
        this.setBlock(world, i + 9, j + 47, k + 26, Dungeons.amethystStone, 0);
        this.setBlock(world, i + 9, j + 47, k + 27, Dungeons.amethystStone, 0);
        this.setBlock(world, i + 9, j + 47, k + 28, Dungeons.amethystStone, 0);
        this.setBlock(world, i + 9, j + 47, k + 29, Dungeons.amethystStone, 0);
        this.setBlock(world, i + 9, j + 47, k + 30, Dungeons.amethystStone, 0);
        this.setBlock(world, i + 9, j + 47, k + 31, Dungeons.amethystStone, 0);
        this.setBlock(world, i + 9, j + 47, k + 32, Dungeons.amethystStone, 0);
        this.setBlock(world, i + 9, j + 47, k + 33, Dungeons.amethystStone, 0);
        this.setBlock(world, i + 9, j + 47, k + 34, Dungeons.amethystStone, 0);
        this.setBlock(world, i + 9, j + 47, k + 35, Dungeons.amethystStone, 0);
        this.setBlock(world, i + 9, j + 47, k + 36, Dungeons.amethystStone, 0);
        this.setBlock(world, i + 9, j + 47, k + 37, Dungeons.amethystStone, 0);
        this.setBlock(world, i + 9, j + 48, k + 20, Dungeons.amethystStone, 0);
        this.setBlock(world, i + 9, j + 48, k + 21, Dungeons.amethystStone, 0);
        this.setBlock(world, i + 9, j + 48, k + 22, Dungeons.amethystStone, 0);
        this.setBlock(world, i + 9, j + 48, k + 23, Dungeons.amethystStone, 0);
        this.setBlock(world, i + 9, j + 48, k + 24, Dungeons.amethystStone, 0);
        this.setBlock(world, i + 9, j + 48, k + 25, Dungeons.amethystStone, 0);
        this.setBlock(world, i + 9, j + 48, k + 26, Dungeons.amethystStone, 0);
        this.setBlock(world, i + 9, j + 48, k + 27, Dungeons.amethystStone, 0);
        this.setBlock(world, i + 9, j + 48, k + 28, Dungeons.amethystStone, 0);
        this.setBlock(world, i + 9, j + 48, k + 29, Dungeons.amethystStone, 0);
        this.setBlock(world, i + 9, j + 48, k + 30, Dungeons.amethystStone, 0);
        this.setBlock(world, i + 9, j + 48, k + 31, Dungeons.amethystStone, 0);
        this.setBlock(world, i + 9, j + 48, k + 32, Dungeons.amethystStone, 0);
        this.setBlock(world, i + 9, j + 48, k + 33, Dungeons.amethystStone, 0);
        this.setBlock(world, i + 9, j + 48, k + 34, Dungeons.amethystStone, 0);
        this.setBlock(world, i + 9, j + 48, k + 35, Dungeons.amethystStone, 0);
        this.setBlock(world, i + 9, j + 48, k + 36, Dungeons.amethystStone, 0);
        this.setBlock(world, i + 9, j + 48, k + 37, Dungeons.amethystStone, 0);
        this.setBlock(world, i + 9, j + 49, k + 20, Dungeons.amethystStone, 0);
        this.setBlock(world, i + 9, j + 49, k + 21, Dungeons.amethystStone, 0);
        this.setBlock(world, i + 9, j + 49, k + 22, Dungeons.amethystStone, 0);
        this.setBlock(world, i + 9, j + 49, k + 23, Dungeons.amethystStone, 0);
        this.setBlock(world, i + 9, j + 49, k + 24, Dungeons.amethystStone, 0);
        this.setBlock(world, i + 9, j + 49, k + 25, Dungeons.amethystStone, 0);
        this.setBlock(world, i + 9, j + 49, k + 26, Dungeons.amethystStone, 0);
        this.setBlock(world, i + 9, j + 49, k + 27, Dungeons.amethystStone, 0);
        this.setBlock(world, i + 9, j + 49, k + 28, Dungeons.amethystStone, 0);
        this.setBlock(world, i + 9, j + 49, k + 29, Dungeons.amethystStone, 0);
        this.setBlock(world, i + 9, j + 49, k + 30, Dungeons.amethystStone, 0);
        this.setBlock(world, i + 9, j + 49, k + 31, Dungeons.amethystStone, 0);
        this.setBlock(world, i + 9, j + 49, k + 32, Dungeons.amethystStone, 0);
        this.setBlock(world, i + 9, j + 49, k + 33, Dungeons.amethystStone, 0);
        this.setBlock(world, i + 9, j + 49, k + 34, Dungeons.amethystStone, 0);
        this.setBlock(world, i + 9, j + 49, k + 35, Dungeons.amethystStone, 0);
        this.setBlock(world, i + 9, j + 49, k + 36, Dungeons.amethystStone, 0);
        this.setBlock(world, i + 9, j + 49, k + 37, Dungeons.amethystStone, 0);
        this.setBlock(world, i + 9, j + 50, k + 20, Dungeons.amethystStone, 0);
        this.setBlock(world, i + 9, j + 50, k + 21, Dungeons.amethystStone, 0);
        this.setBlock(world, i + 9, j + 50, k + 22, Dungeons.amethystStone, 0);
        this.setBlock(world, i + 9, j + 50, k + 23, Dungeons.amethystStone, 0);
        this.setBlock(world, i + 9, j + 50, k + 24, Dungeons.amethystStone, 0);
        this.setBlock(world, i + 9, j + 50, k + 25, Dungeons.amethystStone, 0);
        this.setBlock(world, i + 9, j + 50, k + 26, Dungeons.amethystStone, 0);
        this.setBlock(world, i + 9, j + 50, k + 27, Dungeons.amethystStone, 0);
        this.setBlock(world, i + 9, j + 50, k + 28, Dungeons.amethystStone, 0);
        this.setBlock(world, i + 9, j + 50, k + 29, Dungeons.amethystStone, 0);
        this.setBlock(world, i + 9, j + 50, k + 30, Dungeons.amethystStone, 0);
        this.setBlock(world, i + 9, j + 50, k + 31, Dungeons.amethystStone, 0);
        this.setBlock(world, i + 9, j + 50, k + 32, Dungeons.amethystStone, 0);
        this.setBlock(world, i + 9, j + 50, k + 33, Dungeons.amethystStone, 0);
        this.setBlock(world, i + 9, j + 50, k + 34, Dungeons.amethystStone, 0);
        this.setBlock(world, i + 9, j + 50, k + 35, Dungeons.amethystStone, 0);
        this.setBlock(world, i + 9, j + 50, k + 36, Dungeons.amethystStone, 0);
        this.setBlock(world, i + 9, j + 50, k + 37, Dungeons.amethystStone, 0);
        this.setBlock(world, i + 9, j + 51, k + 20, Dungeons.amethystStone, 0);
        this.setBlock(world, i + 9, j + 51, k + 21, Dungeons.amethystStone, 0);
        this.setBlock(world, i + 9, j + 51, k + 22, Dungeons.amethystStone, 0);
        this.setBlock(world, i + 9, j + 51, k + 23, Dungeons.amethystStone, 0);
        this.setBlock(world, i + 9, j + 51, k + 24, Dungeons.amethystStone, 0);
        this.setBlock(world, i + 9, j + 51, k + 25, Dungeons.amethystStone, 0);
        this.setBlock(world, i + 9, j + 51, k + 26, Dungeons.amethystStone, 0);
        this.setBlock(world, i + 9, j + 51, k + 27, Dungeons.amethystStone, 0);
        this.setBlock(world, i + 9, j + 51, k + 28, Dungeons.amethystStone, 0);
        this.setBlock(world, i + 9, j + 51, k + 29, Dungeons.amethystStone, 0);
        this.setBlock(world, i + 9, j + 51, k + 30, Dungeons.amethystStone, 0);
        this.setBlock(world, i + 9, j + 51, k + 31, Dungeons.amethystStone, 0);
        this.setBlock(world, i + 9, j + 51, k + 32, Dungeons.amethystStone, 0);
        this.setBlock(world, i + 9, j + 51, k + 33, Dungeons.crystalliumDirt, 0);
        this.setBlock(world, i + 9, j + 51, k + 34, Dungeons.crystalliumDirt, 0);
        this.setBlock(world, i + 9, j + 51, k + 35, Dungeons.crystalliumDirt, 0);
        this.setBlock(world, i + 9, j + 51, k + 36, Dungeons.amethystStone, 0);
        this.setBlock(world, i + 9, j + 51, k + 37, Dungeons.amethystStone, 0);
        this.setBlock(world, i + 9, j + 52, k + 20, Dungeons.amethystStone, 0);
        this.setBlock(world, i + 9, j + 52, k + 21, Dungeons.amethystStone, 0);
        this.setBlock(world, i + 9, j + 52, k + 22, Dungeons.amethystStone, 0);
        this.setBlock(world, i + 9, j + 52, k + 23, Dungeons.amethystStone, 0);
        this.setBlock(world, i + 9, j + 52, k + 24, Dungeons.amethystStone, 0);
        this.setBlock(world, i + 9, j + 52, k + 25, Dungeons.amethystStone, 0);
        this.setBlock(world, i + 9, j + 52, k + 26, Dungeons.amethystStone, 0);
        this.setBlock(world, i + 9, j + 52, k + 27, Dungeons.amethystStone, 0);
        this.setBlock(world, i + 9, j + 52, k + 28, Dungeons.amethystStone, 0);
        this.setBlock(world, i + 9, j + 52, k + 29, Dungeons.amethystStone, 0);
        this.setBlock(world, i + 9, j + 52, k + 30, Dungeons.crystalliumDirt, 0);
        this.setBlock(world, i + 9, j + 52, k + 31, Dungeons.crystalliumDirt, 0);
        this.setBlock(world, i + 9, j + 52, k + 32, Dungeons.crystalliumGrass, 0);
        this.setBlock(world, i + 9, j + 52, k + 33, Dungeons.crystalliumGrass, 0);
        this.setBlock(world, i + 9, j + 52, k + 34, Dungeons.crystalliumGrass, 0);
        this.setBlock(world, i + 9, j + 52, k + 35, Dungeons.crystalliumGrass, 0);
        this.setBlock(world, i + 9, j + 52, k + 36, Dungeons.amethystStone, 0);
        this.setBlock(world, i + 9, j + 53, k + 22, Dungeons.amethystStone, 0);
        this.setBlock(world, i + 9, j + 53, k + 23, Dungeons.amethystStone, 0);
        this.setBlock(world, i + 9, j + 53, k + 24, Dungeons.amethystStone, 0);
        this.setBlock(world, i + 9, j + 53, k + 25, Dungeons.amethystStone, 0);
        this.setBlock(world, i + 9, j + 53, k + 26, Dungeons.amethystStone, 0);
        this.setBlock(world, i + 9, j + 53, k + 27, Dungeons.amethystStone, 0);
        this.setBlock(world, i + 9, j + 53, k + 28, Dungeons.crystalliumDirt, 0);
        this.setBlock(world, i + 9, j + 53, k + 29, Dungeons.amethystStone, 0);
        this.setBlock(world, i + 9, j + 53, k + 30, Dungeons.crystalliumGrass, 0);
        this.setBlock(world, i + 9, j + 53, k + 31, Dungeons.crystalliumGrass, 0);
        this.setBlock(world, i + 9, j + 54, k + 25, Dungeons.crystalliumGrass, 0);
        this.setBlock(world, i + 9, j + 54, k + 26, Dungeons.crystalliumGrass, 0);
        this.setBlock(world, i + 9, j + 54, k + 27, Dungeons.crystalliumGrass, 0);
        this.setBlock(world, i + 9, j + 54, k + 28, Dungeons.crystalliumGrass, 0);
        this.setBlock(world, i + 9, j + 54, k + 29, Dungeons.crystalliumGrass, 0);
        this.setBlock(world, i + 10, j + 20, k + 28, Dungeons.amethystStone, 0);
        this.setBlock(world, i + 10, j + 20, k + 29, Dungeons.amethystStone, 0);
        this.setBlock(world, i + 10, j + 20, k + 30, Dungeons.amethystStone, 0);
        this.setBlock(world, i + 10, j + 21, k + 26, Dungeons.amethystStone, 0);
        this.setBlock(world, i + 10, j + 21, k + 27, Dungeons.amethystStone, 0);
        this.setBlock(world, i + 10, j + 21, k + 28, Dungeons.amethystStone, 0);
        this.setBlock(world, i + 10, j + 21, k + 29, Dungeons.amethystStone, 0);
        this.setBlock(world, i + 10, j + 21, k + 30, Dungeons.amethystStone, 0);
        this.setBlock(world, i + 10, j + 21, k + 31, Dungeons.amethystStone, 0);
        this.setBlock(world, i + 10, j + 21, k + 32, Dungeons.amethystStone, 0);
        this.setBlock(world, i + 10, j + 21, k + 33, Dungeons.amethystStone, 0);
        this.setBlock(world, i + 10, j + 22, k + 22, Dungeons.amethystStone, 0);
        this.setBlock(world, i + 10, j + 22, k + 23, Dungeons.amethystStone, 0);
        this.setBlock(world, i + 10, j + 22, k + 24, Dungeons.amethystStone, 0);
        this.setBlock(world, i + 10, j + 22, k + 25, Dungeons.amethystStone, 0);
        this.setBlock(world, i + 10, j + 22, k + 26, Dungeons.amethystStone, 0);
        this.setBlock(world, i + 10, j + 22, k + 27, Dungeons.amethystStone, 0);
        this.setBlock(world, i + 10, j + 22, k + 28, Dungeons.amethystStone, 0);
        this.setBlock(world, i + 10, j + 22, k + 29, Dungeons.amethystStone, 0);
        this.setBlock(world, i + 10, j + 22, k + 30, Dungeons.amethystStone, 0);
        this.setBlock(world, i + 10, j + 22, k + 31, Dungeons.amethystStone, 0);
        this.setBlock(world, i + 10, j + 22, k + 32, Dungeons.amethystStone, 0);
        this.setBlock(world, i + 10, j + 22, k + 33, Dungeons.amethystStone, 0);
        this.setBlock(world, i + 10, j + 22, k + 34, Dungeons.amethystStone, 0);
        this.setBlock(world, i + 10, j + 22, k + 35, Dungeons.amethystStone, 0);
        this.setBlock(world, i + 10, j + 22, k + 36, Dungeons.amethystStone, 0);
        this.setBlock(world, i + 10, j + 22, k + 37, Dungeons.amethystStone, 0);
        this.setBlock(world, i + 10, j + 22, k + 38, Dungeons.amethystStone, 0);
        this.setBlock(world, i + 10, j + 23, k + 17, Dungeons.amethystStone, 0);
        this.setBlock(world, i + 10, j + 23, k + 18, Dungeons.amethystStone, 0);
        this.setBlock(world, i + 10, j + 23, k + 19, Dungeons.amethystStone, 0);
        this.setBlock(world, i + 10, j + 23, k + 20, Dungeons.amethystStone, 0);
        this.setBlock(world, i + 10, j + 23, k + 21, Dungeons.amethystStone, 0);
        this.setBlock(world, i + 10, j + 23, k + 22, Dungeons.amethystStone, 0);
        this.setBlock(world, i + 10, j + 23, k + 23, Dungeons.amethystStone, 0);
        this.setBlock(world, i + 10, j + 23, k + 24, Dungeons.amethystStone, 0);
        this.setBlock(world, i + 10, j + 23, k + 25, Dungeons.amethystStone, 0);
        this.setBlock(world, i + 10, j + 23, k + 26, Dungeons.amethystStone, 0);
        this.setBlock(world, i + 10, j + 23, k + 27, Dungeons.amethystStone, 0);
        this.setBlock(world, i + 10, j + 23, k + 28, Dungeons.amethystStone, 0);
        this.setBlock(world, i + 10, j + 23, k + 29, Dungeons.amethystStone, 0);
        this.setBlock(world, i + 10, j + 23, k + 30, Dungeons.amethystStone, 0);
        this.setBlock(world, i + 10, j + 23, k + 31, Dungeons.amethystStone, 0);
        this.setBlock(world, i + 10, j + 23, k + 32, Dungeons.amethystStone, 0);
        this.setBlock(world, i + 10, j + 23, k + 33, Dungeons.amethystStone, 0);
        this.setBlock(world, i + 10, j + 23, k + 34, Dungeons.amethystStone, 0);
        this.setBlock(world, i + 10, j + 23, k + 35, Dungeons.amethystStone, 0);
        this.setBlock(world, i + 10, j + 23, k + 36, Dungeons.amethystStone, 0);
        this.setBlock(world, i + 10, j + 23, k + 37, Dungeons.amethystStone, 0);
        this.setBlock(world, i + 10, j + 23, k + 38, Dungeons.amethystStone, 0);
        this.setBlock(world, i + 10, j + 23, k + 39, Dungeons.amethystStone, 0);
        this.setBlock(world, i + 10, j + 24, k + 17, Dungeons.crystalliumDirt, 0);
        this.setBlock(world, i + 10, j + 24, k + 18, Dungeons.crystalliumDirt, 0);
        this.setBlock(world, i + 10, j + 24, k + 19, Dungeons.crystalliumDirt, 0);
        this.setBlock(world, i + 10, j + 24, k + 20, Dungeons.crystalliumDirt, 0);
        this.setBlock(world, i + 10, j + 24, k + 21, Dungeons.crystalliumDirt, 0);
        this.setBlock(world, i + 10, j + 24, k + 22, Dungeons.crystalliumDirt, 0);
        this.setBlock(world, i + 10, j + 24, k + 23, Dungeons.crystalliumDirt, 0);
        this.setBlock(world, i + 10, j + 24, k + 24, Dungeons.crystalliumDirt, 0);
        this.setBlock(world, i + 10, j + 24, k + 25, Dungeons.crystalliumDirt, 0);
        this.setBlock(world, i + 10, j + 24, k + 26, Dungeons.crystalliumDirt, 0);
        this.setBlock(world, i + 10, j + 24, k + 27, Dungeons.crystalliumDirt, 0);
        this.setBlock(world, i + 10, j + 24, k + 28, Dungeons.crystalliumDirt, 0);
        this.setBlock(world, i + 10, j + 24, k + 29, Dungeons.crystalliumDirt, 0);
        this.setBlock(world, i + 10, j + 24, k + 30, Dungeons.crystalliumDirt, 0);
        this.setBlock(world, i + 10, j + 24, k + 31, Dungeons.crystalliumDirt, 0);
        this.setBlock(world, i + 10, j + 24, k + 32, Dungeons.crystalliumDirt, 0);
        this.setBlock(world, i + 10, j + 24, k + 33, Dungeons.crystalliumDirt, 0);
        this.setBlock(world, i + 10, j + 24, k + 34, Dungeons.crystalliumDirt, 0);
        this.setBlock(world, i + 10, j + 24, k + 35, Dungeons.crystalliumDirt, 0);
        this.setBlock(world, i + 10, j + 24, k + 36, Dungeons.crystalliumDirt, 0);
        this.setBlock(world, i + 10, j + 24, k + 37, Dungeons.crystalliumDirt, 0);
        this.setBlock(world, i + 10, j + 24, k + 38, Dungeons.crystalliumDirt, 0);
        this.setBlock(world, i + 10, j + 24, k + 39, Dungeons.crystalliumDirt, 0);
        this.setBlock(world, i + 10, j + 25, k + 16, Dungeons.crystalliumDirt, 0);
        this.setBlock(world, i + 10, j + 25, k + 17, Dungeons.crystalliumDirt, 0);
        this.setBlock(world, i + 10, j + 25, k + 18, Dungeons.crystalliumDirt, 0);
        this.setBlock(world, i + 10, j + 25, k + 19, Dungeons.crystalliumDirt, 0);
        this.setBlock(world, i + 10, j + 25, k + 20, Dungeons.crystalliumDirt, 0);
        this.setBlock(world, i + 10, j + 25, k + 21, Dungeons.crystalliumDirt, 0);
        this.setBlock(world, i + 10, j + 25, k + 22, Dungeons.crystalliumDirt, 0);
        this.setBlock(world, i + 10, j + 25, k + 23, Dungeons.crystalliumDirt, 0);
        this.setBlock(world, i + 10, j + 25, k + 24, Dungeons.crystalliumDirt, 0);
        this.setBlock(world, i + 10, j + 25, k + 25, Dungeons.crystalliumDirt, 0);
        this.setBlock(world, i + 10, j + 25, k + 26, Dungeons.crystalliumDirt, 0);
        this.setBlock(world, i + 10, j + 25, k + 27, Dungeons.crystalliumDirt, 0);
        this.setBlock(world, i + 10, j + 25, k + 28, Dungeons.crystalliumDirt, 0);
        this.setBlock(world, i + 10, j + 25, k + 29, Dungeons.crystalliumDirt, 0);
        this.setBlock(world, i + 10, j + 25, k + 30, Dungeons.crystalliumDirt, 0);
        this.setBlock(world, i + 10, j + 25, k + 31, Dungeons.crystalliumDirt, 0);
        this.setBlock(world, i + 10, j + 25, k + 32, Dungeons.crystalliumDirt, 0);
        this.setBlock(world, i + 10, j + 25, k + 33, Dungeons.crystalliumDirt, 0);
        this.setBlock(world, i + 10, j + 25, k + 34, Dungeons.crystalliumDirt, 0);
        this.setBlock(world, i + 10, j + 25, k + 35, Dungeons.crystalliumDirt, 0);
        this.setBlock(world, i + 10, j + 25, k + 36, Dungeons.crystalliumDirt, 0);
        this.setBlock(world, i + 10, j + 25, k + 37, Dungeons.crystalliumDirt, 0);
        this.setBlock(world, i + 10, j + 25, k + 38, Dungeons.crystalliumDirt, 0);
        this.setBlock(world, i + 10, j + 25, k + 39, Dungeons.crystalliumDirt, 0);
        this.setBlock(world, i + 10, j + 25, k + 40, Dungeons.crystalliumDirt, 0);
        this.setBlock(world, i + 10, j + 25, k + 41, Dungeons.crystalliumDirt, 0);
        this.setBlock(world, i + 10, j + 25, k + 42, Dungeons.crystalliumDirt, 0);
        this.setBlock(world, i + 10, j + 25, k + 43, Dungeons.crystalliumDirt, 0);
        this.setBlock(world, i + 10, j + 25, k + 44, Dungeons.crystalliumDirt, 0);
        this.setBlock(world, i + 10, j + 26, k + 15, Dungeons.crystalliumGrass, 0);
        this.setBlock(world, i + 10, j + 26, k + 16, Dungeons.crystalliumGrass, 0);
        this.setBlock(world, i + 10, j + 26, k + 17, Dungeons.crystalliumGrass, 0);
        this.setBlock(world, i + 10, j + 26, k + 18, Dungeons.crystalliumGrass, 0);
        this.setBlock(world, i + 10, j + 26, k + 19, Dungeons.crystalliumGrass, 0);
        this.setBlock(world, i + 10, j + 26, k + 20, Dungeons.crystalliumGrass, 0);
        this.setBlock(world, i + 10, j + 26, k + 21, Dungeons.crystalliumGrass, 0);
        this.setBlock(world, i + 10, j + 26, k + 22, Dungeons.crystalliumGrass, 0);
        this.setBlock(world, i + 10, j + 26, k + 23, Dungeons.crystalliumGrass, 0);
        this.setBlock(world, i + 10, j + 26, k + 24, Dungeons.crystalliumGrass, 0);
        this.setBlock(world, i + 10, j + 26, k + 25, Dungeons.crystalliumGrass, 0);
        this.setBlock(world, i + 10, j + 26, k + 26, Dungeons.crystalliumGrass, 0);
        this.setBlock(world, i + 10, j + 26, k + 27, Dungeons.crystalliumGrass, 0);
        this.setBlock(world, i + 10, j + 26, k + 28, Dungeons.crystalliumGrass, 0);
        this.setBlock(world, i + 10, j + 26, k + 29, Dungeons.crystalliumGrass, 0);
        this.setBlock(world, i + 10, j + 26, k + 30, Dungeons.crystalliumGrass, 0);
        this.setBlock(world, i + 10, j + 26, k + 31, Dungeons.crystalliumGrass, 0);
        this.setBlock(world, i + 10, j + 26, k + 32, Dungeons.crystalliumGrass, 0);
        this.setBlock(world, i + 10, j + 26, k + 33, Dungeons.crystalliumGrass, 0);
        this.setBlock(world, i + 10, j + 26, k + 34, Dungeons.crystalliumGrass, 0);
        this.setBlock(world, i + 10, j + 26, k + 35, Dungeons.crystalliumGrass, 0);
        this.setBlock(world, i + 10, j + 26, k + 36, Dungeons.crystalliumGrass, 0);
        this.setBlock(world, i + 10, j + 26, k + 37, Dungeons.crystalliumGrass, 0);
        this.setBlock(world, i + 10, j + 26, k + 38, Dungeons.crystalliumGrass, 0);
        this.setBlock(world, i + 10, j + 26, k + 39, Dungeons.crystalliumGrass, 0);
        this.setBlock(world, i + 10, j + 26, k + 40, Dungeons.crystalliumGrass, 0);
        this.setBlock(world, i + 10, j + 26, k + 41, Dungeons.crystalliumGrass, 0);
        this.setBlock(world, i + 10, j + 26, k + 42, Dungeons.crystalliumGrass, 0);
        this.setBlock(world, i + 10, j + 26, k + 43, Dungeons.crystalliumGrass, 0);
        this.setBlock(world, i + 10, j + 26, k + 44, Dungeons.crystalliumGrass, 0);
        this.setBlock(world, i + 10, j + 26, k + 45, Dungeons.crystalliumGrass, 0);
        this.setBlock(world, i + 10, j + 44, k + 29, Dungeons.amethystStone, 0);
        this.setBlock(world, i + 10, j + 44, k + 30, Dungeons.amethystStone, 0);
        this.setBlock(world, i + 10, j + 44, k + 31, Dungeons.amethystStone, 0);
        this.setBlock(world, i + 10, j + 44, k + 32, Dungeons.amethystStone, 0);
        this.setBlock(world, i + 10, j + 44, k + 33, Dungeons.amethystStone, 0);
        this.setBlock(world, i + 10, j + 44, k + 34, Dungeons.amethystStone, 0);
        this.setBlock(world, i + 10, j + 44, k + 35, Dungeons.amethystStone, 0);
        this.setBlock(world, i + 10, j + 45, k + 24, Dungeons.amethystStone, 0);
        this.setBlock(world, i + 10, j + 45, k + 25, Dungeons.amethystStone, 0);
        this.setBlock(world, i + 10, j + 45, k + 26, Dungeons.amethystStone, 0);
        this.setBlock(world, i + 10, j + 45, k + 27, Dungeons.amethystStone, 0);
        this.setBlock(world, i + 10, j + 45, k + 28, Dungeons.amethystStone, 0);
        this.setBlock(world, i + 10, j + 45, k + 29, Dungeons.amethystStone, 0);
        this.setBlock(world, i + 10, j + 45, k + 30, Dungeons.amethystStone, 0);
        this.setBlock(world, i + 10, j + 45, k + 31, Dungeons.amethystStone, 0);
        this.setBlock(world, i + 10, j + 45, k + 32, Dungeons.amethystStone, 0);
        this.setBlock(world, i + 10, j + 45, k + 33, Dungeons.amethystStone, 0);
        this.setBlock(world, i + 10, j + 45, k + 34, Dungeons.amethystStone, 0);
        this.setBlock(world, i + 10, j + 45, k + 35, Dungeons.amethystStone, 0);
        this.setBlock(world, i + 10, j + 45, k + 36, Dungeons.amethystStone, 0);
        this.setBlock(world, i + 10, j + 46, k + 22, Dungeons.amethystStone, 0);
        this.setBlock(world, i + 10, j + 46, k + 23, Dungeons.amethystStone, 0);
        this.setBlock(world, i + 10, j + 46, k + 24, Dungeons.amethystStone, 0);
        this.setBlock(world, i + 10, j + 46, k + 25, Dungeons.amethystStone, 0);
        this.setBlock(world, i + 10, j + 46, k + 26, Dungeons.amethystStone, 0);
        this.setBlock(world, i + 10, j + 46, k + 27, Dungeons.amethystStone, 0);
        this.setBlock(world, i + 10, j + 46, k + 28, Dungeons.amethystStone, 0);
        this.setBlock(world, i + 10, j + 46, k + 29, Dungeons.amethystStone, 0);
        this.setBlock(world, i + 10, j + 46, k + 30, Dungeons.amethystStone, 0);
        this.setBlock(world, i + 10, j + 46, k + 31, Dungeons.amethystStone, 0);
        this.setBlock(world, i + 10, j + 46, k + 32, Dungeons.amethystStone, 0);
        this.setBlock(world, i + 10, j + 46, k + 33, Dungeons.amethystStone, 0);
        this.setBlock(world, i + 10, j + 46, k + 34, Dungeons.amethystStone, 0);
        this.setBlock(world, i + 10, j + 46, k + 35, Dungeons.amethystStone, 0);
        this.setBlock(world, i + 10, j + 46, k + 36, Dungeons.amethystStone, 0);
        this.setBlock(world, i + 10, j + 46, k + 37, Dungeons.amethystStone, 0);
        this.setBlock(world, i + 10, j + 47, k + 21, Dungeons.amethystStone, 0);
        this.setBlock(world, i + 10, j + 47, k + 22, Dungeons.amethystStone, 0);
        this.setBlock(world, i + 10, j + 47, k + 23, Dungeons.amethystStone, 0);
        this.setBlock(world, i + 10, j + 47, k + 24, Dungeons.amethystStone, 0);
        this.setBlock(world, i + 10, j + 47, k + 25, Dungeons.amethystStone, 0);
        this.setBlock(world, i + 10, j + 47, k + 26, Dungeons.amethystStone, 0);
        this.setBlock(world, i + 10, j + 47, k + 27, Dungeons.amethystStone, 0);
        this.setBlock(world, i + 10, j + 47, k + 28, Dungeons.amethystStone, 0);
        this.setBlock(world, i + 10, j + 47, k + 29, Dungeons.amethystStone, 0);
        this.setBlock(world, i + 10, j + 47, k + 30, Dungeons.amethystStone, 0);
        this.setBlock(world, i + 10, j + 47, k + 31, Dungeons.amethystStone, 0);
        this.setBlock(world, i + 10, j + 47, k + 32, Dungeons.amethystStone, 0);
        this.setBlock(world, i + 10, j + 47, k + 33, Dungeons.amethystStone, 0);
        this.setBlock(world, i + 10, j + 47, k + 34, Dungeons.amethystStone, 0);
        this.setBlock(world, i + 10, j + 47, k + 35, Dungeons.amethystStone, 0);
        this.setBlock(world, i + 10, j + 47, k + 36, Dungeons.amethystStone, 0);
        this.setBlock(world, i + 10, j + 47, k + 37, Dungeons.amethystStone, 0);
        this.setBlock(world, i + 10, j + 47, k + 38, Dungeons.amethystStone, 0);
        this.setBlock(world, i + 10, j + 48, k + 20, Dungeons.amethystStone, 0);
        this.setBlock(world, i + 10, j + 48, k + 21, Dungeons.amethystStone, 0);
        this.setBlock(world, i + 10, j + 48, k + 22, Dungeons.amethystStone, 0);
        this.setBlock(world, i + 10, j + 48, k + 23, Dungeons.amethystStone, 0);
        this.setBlock(world, i + 10, j + 48, k + 24, Dungeons.amethystStone, 0);
        this.setBlock(world, i + 10, j + 48, k + 25, Dungeons.amethystStone, 0);
        this.setBlock(world, i + 10, j + 48, k + 26, Dungeons.amethystStone, 0);
        this.setBlock(world, i + 10, j + 48, k + 27, Dungeons.amethystStone, 0);
        this.setBlock(world, i + 10, j + 48, k + 28, Dungeons.amethystStone, 0);
        this.setBlock(world, i + 10, j + 48, k + 29, Dungeons.amethystStone, 0);
        this.setBlock(world, i + 10, j + 48, k + 30, Dungeons.amethystStone, 0);
        this.setBlock(world, i + 10, j + 48, k + 31, Dungeons.amethystStone, 0);
        this.setBlock(world, i + 10, j + 48, k + 32, Dungeons.amethystStone, 0);
        this.setBlock(world, i + 10, j + 48, k + 33, Dungeons.amethystStone, 0);
        this.setBlock(world, i + 10, j + 48, k + 34, Dungeons.amethystStone, 0);
        this.setBlock(world, i + 10, j + 48, k + 35, Dungeons.amethystStone, 0);
        this.setBlock(world, i + 10, j + 48, k + 36, Dungeons.amethystStone, 0);
        this.setBlock(world, i + 10, j + 48, k + 37, Dungeons.amethystStone, 0);
        this.setBlock(world, i + 10, j + 48, k + 38, Dungeons.amethystStone, 0);
        this.setBlock(world, i + 10, j + 49, k + 19, Dungeons.amethystStone, 0);
        this.setBlock(world, i + 10, j + 49, k + 20, Dungeons.amethystStone, 0);
        this.setBlock(world, i + 10, j + 49, k + 21, Dungeons.amethystStone, 0);
        this.setBlock(world, i + 10, j + 49, k + 22, Dungeons.amethystStone, 0);
        this.setBlock(world, i + 10, j + 49, k + 23, Dungeons.amethystStone, 0);
        this.setBlock(world, i + 10, j + 49, k + 24, Dungeons.amethystStone, 0);
        this.setBlock(world, i + 10, j + 49, k + 25, Dungeons.amethystStone, 0);
        this.setBlock(world, i + 10, j + 49, k + 26, Dungeons.amethystStone, 0);
        this.setBlock(world, i + 10, j + 49, k + 27, Dungeons.amethystStone, 0);
        this.setBlock(world, i + 10, j + 49, k + 28, Dungeons.amethystStone, 0);
        this.setBlock(world, i + 10, j + 49, k + 29, Dungeons.amethystStone, 0);
        this.setBlock(world, i + 10, j + 49, k + 30, Dungeons.amethystStone, 0);
        this.setBlock(world, i + 10, j + 49, k + 31, Dungeons.amethystStone, 0);
        this.setBlock(world, i + 10, j + 49, k + 32, Dungeons.amethystStone, 0);
        this.setBlock(world, i + 10, j + 49, k + 33, Dungeons.amethystStone, 0);
        this.setBlock(world, i + 10, j + 49, k + 34, Dungeons.amethystStone, 0);
        this.setBlock(world, i + 10, j + 49, k + 35, Dungeons.amethystStone, 0);
        this.setBlock(world, i + 10, j + 49, k + 36, Dungeons.amethystStone, 0);
        this.setBlock(world, i + 10, j + 49, k + 37, Dungeons.amethystStone, 0);
        this.setBlock(world, i + 10, j + 49, k + 38, Dungeons.amethystStone, 0);
        this.setBlock(world, i + 10, j + 50, k + 19, Dungeons.amethystStone, 0);
        this.setBlock(world, i + 10, j + 50, k + 20, Dungeons.amethystStone, 0);
        this.setBlock(world, i + 10, j + 50, k + 21, Dungeons.amethystStone, 0);
        this.setBlock(world, i + 10, j + 50, k + 22, Dungeons.amethystStone, 0);
        this.setBlock(world, i + 10, j + 50, k + 23, Dungeons.amethystStone, 0);
        this.setBlock(world, i + 10, j + 50, k + 24, Dungeons.amethystStone, 0);
        this.setBlock(world, i + 10, j + 50, k + 25, Dungeons.amethystStone, 0);
        this.setBlock(world, i + 10, j + 50, k + 26, Dungeons.amethystStone, 0);
        this.setBlock(world, i + 10, j + 50, k + 27, Dungeons.amethystStone, 0);
        this.setBlock(world, i + 10, j + 50, k + 28, Dungeons.amethystStone, 0);
        this.setBlock(world, i + 10, j + 50, k + 29, Dungeons.amethystStone, 0);
        this.setBlock(world, i + 10, j + 50, k + 30, Dungeons.amethystStone, 0);
        this.setBlock(world, i + 10, j + 50, k + 31, Dungeons.amethystStone, 0);
        this.setBlock(world, i + 10, j + 50, k + 32, Dungeons.amethystStone, 0);
        this.setBlock(world, i + 10, j + 50, k + 33, Dungeons.amethystStone, 0);
        this.setBlock(world, i + 10, j + 50, k + 34, Dungeons.amethystStone, 0);
        this.setBlock(world, i + 10, j + 50, k + 35, Dungeons.amethystStone, 0);
        this.setBlock(world, i + 10, j + 50, k + 36, Dungeons.amethystStone, 0);
        this.setBlock(world, i + 10, j + 50, k + 37, Dungeons.amethystStone, 0);
        this.setBlock(world, i + 10, j + 50, k + 38, Dungeons.amethystStone, 0);
        this.setBlock(world, i + 10, j + 51, k + 19, Dungeons.amethystStone, 0);
        this.setBlock(world, i + 10, j + 51, k + 20, Dungeons.amethystStone, 0);
