

package com.gibby.dungeon.gen;

import net.minecraft.world.gen.feature.*;
import net.minecraft.world.*;
import java.util.*;
import net.minecraft.init.*;
import net.minecraft.block.*;

public class WorldGenJungleTemple extends WorldGenerator
{
    public boolean generate(final World world, final Random rand, final int i, final int j, final int k) {
        if (world.getBlock(i, j, k) != Blocks.grass || world.getBlock(i + 24, j, k) != Blocks.grass || world.getBlock(i + 24, j, k + 32) != Blocks.grass || world.getBlock(i, j, k + 32) != Blocks.grass || world.getBlock(i, j + 2, k) != Blocks.air || world.getBlock(i + 24, j + 2, k) != Blocks.air || world.getBlock(i + 24, j + 2, k + 32) != Blocks.air || world.getBlock(i, j + 2, k + 32) != Blocks.air) {
            return false;
        }
        world.setBlock(i + 2, j + 0, k + 2, Blocks.cobblestone);
        world.setBlock(i + 2, j + 0, k + 3, Blocks.cobblestone);
        world.setBlock(i + 2, j + 0, k + 4, Blocks.mossy_cobblestone);
        world.setBlock(i + 2, j + 0, k + 5, Blocks.mossy_cobblestone);
        world.setBlock(i + 2, j + 0, k + 6, Blocks.cobblestone);
        world.setBlock(i + 2, j + 0, k + 7, Blocks.mossy_cobblestone);
        world.setBlock(i + 2, j + 0, k + 8, Blocks.mossy_cobblestone);
        world.setBlock(i + 2, j + 0, k + 9, Blocks.mossy_cobblestone);
        world.setBlock(i + 2, j + 0, k + 10, Blocks.mossy_cobblestone);
        world.setBlock(i + 2, j + 0, k + 11, Blocks.mossy_cobblestone);
        world.setBlock(i + 2, j + 0, k + 12, Blocks.cobblestone);
        world.setBlock(i + 2, j + 0, k + 13, Blocks.mossy_cobblestone);
        world.setBlock(i + 2, j + 0, k + 14, Blocks.cobblestone);
        world.setBlock(i + 2, j + 0, k + 15, Blocks.mossy_cobblestone);
        world.setBlock(i + 2, j + 0, k + 16, Blocks.mossy_cobblestone);
        world.setBlock(i + 2, j + 0, k + 17, Blocks.mossy_cobblestone);
        world.setBlock(i + 2, j + 0, k + 18, Blocks.cobblestone);
        world.setBlock(i + 2, j + 0, k + 19, Blocks.cobblestone);
        world.setBlock(i + 2, j + 0, k + 20, Blocks.cobblestone);
        world.setBlock(i + 2, j + 0, k + 21, Blocks.mossy_cobblestone);
        world.setBlock(i + 2, j + 0, k + 22, Blocks.cobblestone);
        world.setBlock(i + 2, j + 0, k + 23, Blocks.mossy_cobblestone);
        world.setBlock(i + 2, j + 0, k + 24, Blocks.cobblestone);
        world.setBlock(i + 2, j + 0, k + 25, Blocks.cobblestone);
        world.setBlock(i + 2, j + 0, k + 26, Blocks.cobblestone);
        world.setBlock(i + 2, j + 0, k + 27, Blocks.mossy_cobblestone);
        world.setBlock(i + 2, j + 0, k + 28, Blocks.mossy_cobblestone);
        world.setBlock(i + 2, j + 0, k + 29, Blocks.mossy_cobblestone);
        world.setBlock(i + 2, j + 0, k + 30, Blocks.cobblestone);
        world.setBlock(i + 2, j + 1, k + 2, Blocks.cobblestone);
        world.setBlock(i + 2, j + 1, k + 3, Blocks.cobblestone);
        world.setBlock(i + 2, j + 1, k + 4, Blocks.cobblestone);
        world.setBlock(i + 2, j + 1, k + 5, Blocks.mossy_cobblestone);
        world.setBlock(i + 2, j + 1, k + 6, Blocks.cobblestone);
        world.setBlock(i + 2, j + 1, k + 7, Blocks.cobblestone);
        world.setBlock(i + 2, j + 1, k + 8, Blocks.mossy_cobblestone);
        world.setBlock(i + 2, j + 1, k + 9, Blocks.cobblestone);
        world.setBlock(i + 2, j + 1, k + 10, Blocks.cobblestone);
        world.setBlock(i + 2, j + 1, k + 11, Blocks.cobblestone);
        world.setBlock(i + 2, j + 1, k + 12, Blocks.cobblestone);
        world.setBlock(i + 2, j + 1, k + 13, Blocks.mossy_cobblestone);
        world.setBlock(i + 2, j + 1, k + 14, Blocks.mossy_cobblestone);
        world.setBlock(i + 2, j + 1, k + 15, Blocks.cobblestone);
        world.setBlock(i + 2, j + 1, k + 16, Blocks.cobblestone);
        world.setBlock(i + 2, j + 1, k + 17, Blocks.mossy_cobblestone);
        world.setBlock(i + 2, j + 1, k + 18, Blocks.cobblestone);
        world.setBlock(i + 2, j + 1, k + 19, Blocks.cobblestone);
        world.setBlock(i + 2, j + 1, k + 20, Blocks.mossy_cobblestone);
        world.setBlock(i + 2, j + 1, k + 21, Blocks.mossy_cobblestone);
        world.setBlock(i + 2, j + 1, k + 22, Blocks.mossy_cobblestone);
        world.setBlock(i + 2, j + 1, k + 23, Blocks.mossy_cobblestone);
        world.setBlock(i + 2, j + 1, k + 24, Blocks.mossy_cobblestone);
        world.setBlock(i + 2, j + 1, k + 25, Blocks.cobblestone);
        world.setBlock(i + 2, j + 1, k + 26, Blocks.mossy_cobblestone);
        world.setBlock(i + 2, j + 1, k + 27, Blocks.mossy_cobblestone);
        world.setBlock(i + 2, j + 1, k + 28, Blocks.mossy_cobblestone);
        world.setBlock(i + 2, j + 1, k + 29, Blocks.mossy_cobblestone);
        world.setBlock(i + 2, j + 1, k + 30, Blocks.cobblestone);
        world.setBlock(i + 2, j + 2, k + 2, Blocks.cobblestone);
        world.setBlock(i + 2, j + 2, k + 3, Blocks.cobblestone);
        world.setBlock(i + 2, j + 2, k + 4, Blocks.cobblestone);
        world.setBlock(i + 2, j + 2, k + 5, Blocks.cobblestone);
        world.setBlock(i + 2, j + 2, k + 6, Blocks.cobblestone);
        world.setBlock(i + 2, j + 2, k + 7, Blocks.mossy_cobblestone);
        world.setBlock(i + 2, j + 2, k + 8, Blocks.cobblestone);
        world.setBlock(i + 2, j + 2, k + 9, Blocks.cobblestone);
        world.setBlock(i + 2, j + 2, k + 10, Blocks.cobblestone);
        world.setBlock(i + 2, j + 2, k + 11, Blocks.cobblestone);
        world.setBlock(i + 2, j + 2, k + 12, Blocks.cobblestone);
        world.setBlock(i + 2, j + 2, k + 13, Blocks.cobblestone);
        world.setBlock(i + 2, j + 2, k + 14, Blocks.cobblestone);
        world.setBlock(i + 2, j + 2, k + 15, Blocks.mossy_cobblestone);
        world.setBlock(i + 2, j + 2, k + 16, Blocks.cobblestone);
        world.setBlock(i + 2, j + 2, k + 17, Blocks.cobblestone);
        world.setBlock(i + 2, j + 2, k + 18, Blocks.mossy_cobblestone);
        world.setBlock(i + 2, j + 2, k + 19, Blocks.cobblestone);
        world.setBlock(i + 2, j + 2, k + 20, Blocks.mossy_cobblestone);
        world.setBlock(i + 2, j + 2, k + 21, Blocks.cobblestone);
        world.setBlock(i + 2, j + 2, k + 22, Blocks.cobblestone);
        world.setBlock(i + 2, j + 2, k + 23, Blocks.mossy_cobblestone);
        world.setBlock(i + 2, j + 2, k + 24, Blocks.cobblestone);
        world.setBlock(i + 2, j + 2, k + 25, Blocks.mossy_cobblestone);
        world.setBlock(i + 2, j + 2, k + 26, Blocks.cobblestone);
        world.setBlock(i + 2, j + 2, k + 27, Blocks.mossy_cobblestone);
        world.setBlock(i + 2, j + 2, k + 28, Blocks.mossy_cobblestone);
        world.setBlock(i + 2, j + 2, k + 29, Blocks.cobblestone);
        world.setBlock(i + 2, j + 2, k + 30, Blocks.cobblestone);
        world.setBlock(i + 2, j + 3, k + 2, (Block)Blocks.stone_slab, 3, 0);
        world.setBlock(i + 2, j + 3, k + 4, Blocks.mossy_cobblestone);
        world.setBlock(i + 2, j + 3, k + 6, (Block)Blocks.stone_slab, 3, 0);
        world.setBlock(i + 2, j + 3, k + 8, Blocks.mossy_cobblestone);
        world.setBlock(i + 2, j + 3, k + 10, (Block)Blocks.stone_slab, 3, 0);
        world.setBlock(i + 2, j + 3, k + 12, Blocks.mossy_cobblestone);
        world.setBlock(i + 2, j + 3, k + 14, (Block)Blocks.stone_slab, 3, 0);
        world.setBlock(i + 2, j + 3, k + 16, Blocks.mossy_cobblestone);
        world.setBlock(i + 2, j + 3, k + 18, (Block)Blocks.stone_slab, 3, 0);
        world.setBlock(i + 2, j + 3, k + 20, Blocks.mossy_cobblestone);
        world.setBlock(i + 2, j + 3, k + 22, (Block)Blocks.stone_slab, 3, 0);
        world.setBlock(i + 2, j + 3, k + 24, Blocks.mossy_cobblestone);
        world.setBlock(i + 2, j + 3, k + 26, (Block)Blocks.stone_slab, 3, 0);
        world.setBlock(i + 2, j + 3, k + 28, Blocks.mossy_cobblestone);
        world.setBlock(i + 2, j + 3, k + 30, (Block)Blocks.stone_slab, 3, 0);
        world.setBlock(i + 3, j + 0, k + 2, Blocks.cobblestone);
        world.setBlock(i + 3, j + 0, k + 3, Blocks.mossy_cobblestone);
        world.setBlock(i + 3, j + 0, k + 4, Blocks.cobblestone);
        world.setBlock(i + 3, j + 0, k + 5, Blocks.cobblestone);
        world.setBlock(i + 3, j + 0, k + 6, Blocks.mossy_cobblestone);
        world.setBlock(i + 3, j + 0, k + 7, Blocks.cobblestone);
        world.setBlock(i + 3, j + 0, k + 8, Blocks.cobblestone);
        world.setBlock(i + 3, j + 0, k + 9, Blocks.mossy_cobblestone);
        world.setBlock(i + 3, j + 0, k + 10, Blocks.cobblestone);
        world.setBlock(i + 3, j + 0, k + 11, Blocks.mossy_cobblestone);
        world.setBlock(i + 3, j + 0, k + 12, Blocks.cobblestone);
        world.setBlock(i + 3, j + 0, k + 13, Blocks.cobblestone);
        world.setBlock(i + 3, j + 0, k + 14, Blocks.mossy_cobblestone);
        world.setBlock(i + 3, j + 0, k + 15, Blocks.cobblestone);
        world.setBlock(i + 3, j + 0, k + 16, Blocks.mossy_cobblestone);
        world.setBlock(i + 3, j + 0, k + 17, Blocks.mossy_cobblestone);
        world.setBlock(i + 3, j + 0, k + 18, Blocks.cobblestone);
        world.setBlock(i + 3, j + 0, k + 19, Blocks.mossy_cobblestone);
        world.setBlock(i + 3, j + 0, k + 20, Blocks.cobblestone);
        world.setBlock(i + 3, j + 0, k + 21, Blocks.mossy_cobblestone);
        world.setBlock(i + 3, j + 0, k + 22, Blocks.mossy_cobblestone);
        world.setBlock(i + 3, j + 0, k + 23, Blocks.cobblestone);
        world.setBlock(i + 3, j + 0, k + 24, Blocks.mossy_cobblestone);
        world.setBlock(i + 3, j + 0, k + 25, Blocks.cobblestone);
        world.setBlock(i + 3, j + 0, k + 26, Blocks.cobblestone);
        world.setBlock(i + 3, j + 0, k + 27, Blocks.cobblestone);
        world.setBlock(i + 3, j + 0, k + 28, Blocks.mossy_cobblestone);
        world.setBlock(i + 3, j + 0, k + 29, Blocks.mossy_cobblestone);
        world.setBlock(i + 3, j + 0, k + 30, Blocks.cobblestone);
        world.setBlock(i + 3, j + 1, k + 2, Blocks.cobblestone);
        world.setBlock(i + 3, j + 1, k + 30, Blocks.mossy_cobblestone);
        world.setBlock(i + 3, j + 2, k + 2, Blocks.mossy_cobblestone);
        world.setBlock(i + 3, j + 2, k + 30, Blocks.cobblestone);
        world.setBlock(i + 3, j + 6, k + 7, Blocks.cobblestone);
        world.setBlock(i + 3, j + 6, k + 10, Blocks.cobblestone);
        world.setBlock(i + 3, j + 6, k + 13, Blocks.cobblestone);
        world.setBlock(i + 3, j + 6, k + 16, Blocks.mossy_cobblestone);
        world.setBlock(i + 3, j + 6, k + 19, Blocks.cobblestone);
        world.setBlock(i + 3, j + 6, k + 22, Blocks.cobblestone);
        world.setBlock(i + 3, j + 6, k + 25, Blocks.mossy_cobblestone);
        world.setBlock(i + 4, j + 0, k + 2, Blocks.mossy_cobblestone);
        world.setBlock(i + 4, j + 0, k + 3, Blocks.mossy_cobblestone);
        world.setBlock(i + 4, j + 0, k + 4, Blocks.mossy_cobblestone);
        world.setBlock(i + 4, j + 0, k + 5, Blocks.cobblestone);
        world.setBlock(i + 4, j + 0, k + 6, Blocks.cobblestone);
        world.setBlock(i + 4, j + 0, k + 7, Blocks.mossy_cobblestone);
        world.setBlock(i + 4, j + 0, k + 8, Blocks.cobblestone);
        world.setBlock(i + 4, j + 0, k + 9, Blocks.mossy_cobblestone);
        world.setBlock(i + 4, j + 0, k + 10, Blocks.mossy_cobblestone);
        world.setBlock(i + 4, j + 0, k + 11, Blocks.cobblestone);
        world.setBlock(i + 4, j + 0, k + 12, Blocks.mossy_cobblestone);
        world.setBlock(i + 4, j + 0, k + 13, Blocks.mossy_cobblestone);
        world.setBlock(i + 4, j + 0, k + 14, Blocks.cobblestone);
        world.setBlock(i + 4, j + 0, k + 15, Blocks.cobblestone);
        world.setBlock(i + 4, j + 0, k + 16, Blocks.cobblestone);
        world.setBlock(i + 4, j + 0, k + 17, Blocks.cobblestone);
        world.setBlock(i + 4, j + 0, k + 18, Blocks.mossy_cobblestone);
        world.setBlock(i + 4, j + 0, k + 19, Blocks.cobblestone);
        world.setBlock(i + 4, j + 0, k + 20, Blocks.mossy_cobblestone);
        world.setBlock(i + 4, j + 0, k + 21, Blocks.mossy_cobblestone);
        world.setBlock(i + 4, j + 0, k + 22, Blocks.cobblestone);
        world.setBlock(i + 4, j + 0, k + 23, Blocks.cobblestone);
        world.setBlock(i + 4, j + 0, k + 24, Blocks.mossy_cobblestone);
        world.setBlock(i + 4, j + 0, k + 25, Blocks.mossy_cobblestone);
        world.setBlock(i + 4, j + 0, k + 26, Blocks.mossy_cobblestone);
        world.setBlock(i + 4, j + 0, k + 27, Blocks.mossy_cobblestone);
        world.setBlock(i + 4, j + 0, k + 28, Blocks.mossy_cobblestone);
        world.setBlock(i + 4, j + 0, k + 29, Blocks.mossy_cobblestone);
        world.setBlock(i + 4, j + 0, k + 30, Blocks.cobblestone);
        world.setBlock(i + 4, j + 1, k + 2, Blocks.cobblestone);
        world.setBlock(i + 4, j + 1, k + 30, Blocks.cobblestone);
        world.setBlock(i + 4, j + 2, k + 2, Blocks.cobblestone);
        world.setBlock(i + 4, j + 2, k + 30, Blocks.mossy_cobblestone);
        world.setBlock(i + 4, j + 3, k + 2, Blocks.mossy_cobblestone);
        world.setBlock(i + 4, j + 3, k + 30, Blocks.mossy_cobblestone);
        world.setBlock(i + 4, j + 5, k + 7, Blocks.cobblestone);
        world.setBlock(i + 4, j + 5, k + 10, Blocks.mossy_cobblestone);
        world.setBlock(i + 4, j + 5, k + 13, Blocks.cobblestone);
        world.setBlock(i + 4, j + 5, k + 16, Blocks.mossy_cobblestone);
        world.setBlock(i + 4, j + 5, k + 19, Blocks.mossy_cobblestone);
        world.setBlock(i + 4, j + 5, k + 22, Blocks.cobblestone);
        world.setBlock(i + 4, j + 5, k + 25, Blocks.cobblestone);
        world.setBlock(i + 4, j + 6, k + 4, Blocks.mossy_cobblestone);
        world.setBlock(i + 4, j + 6, k + 5, Blocks.mossy_cobblestone);
        world.setBlock(i + 4, j + 6, k + 6, Blocks.mossy_cobblestone);
        world.setBlock(i + 4, j + 6, k + 7, Blocks.cobblestone);
        world.setBlock(i + 4, j + 6, k + 8, Blocks.cobblestone);
        world.setBlock(i + 4, j + 6, k + 9, Blocks.cobblestone);
        world.setBlock(i + 4, j + 6, k + 10, Blocks.cobblestone);
        world.setBlock(i + 4, j + 6, k + 11, Blocks.mossy_cobblestone);
        world.setBlock(i + 4, j + 6, k + 12, Blocks.cobblestone);
        world.setBlock(i + 4, j + 6, k + 13, Blocks.cobblestone);
        world.setBlock(i + 4, j + 6, k + 14, Blocks.mossy_cobblestone);
        world.setBlock(i + 4, j + 6, k + 15, Blocks.mossy_cobblestone);
        world.setBlock(i + 4, j + 6, k + 16, Blocks.cobblestone);
        world.setBlock(i + 4, j + 6, k + 17, Blocks.cobblestone);
        world.setBlock(i + 4, j + 6, k + 18, Blocks.mossy_cobblestone);
        world.setBlock(i + 4, j + 6, k + 19, Blocks.mossy_cobblestone);
        world.setBlock(i + 4, j + 6, k + 20, Blocks.cobblestone);
        world.setBlock(i + 4, j + 6, k + 21, Blocks.mossy_cobblestone);
        world.setBlock(i + 4, j + 6, k + 22, Blocks.cobblestone);
        world.setBlock(i + 4, j + 6, k + 23, Blocks.mossy_cobblestone);
        world.setBlock(i + 4, j + 6, k + 24, Blocks.cobblestone);
        world.setBlock(i + 4, j + 6, k + 25, Blocks.cobblestone);
        world.setBlock(i + 4, j + 6, k + 26, Blocks.mossy_cobblestone);
        world.setBlock(i + 4, j + 6, k + 27, Blocks.mossy_cobblestone);
        world.setBlock(i + 4, j + 6, k + 28, Blocks.cobblestone);
        world.setBlock(i + 5, j + 0, k + 2, Blocks.cobblestone);
        world.setBlock(i + 5, j + 0, k + 3, Blocks.cobblestone);
        world.setBlock(i + 5, j + 0, k + 4, Blocks.cobblestone);
        world.setBlock(i + 5, j + 0, k + 5, Blocks.mossy_cobblestone);
        world.setBlock(i + 5, j + 0, k + 6, Blocks.cobblestone);
        world.setBlock(i + 5, j + 0, k + 7, Blocks.mossy_cobblestone);
        world.setBlock(i + 5, j + 0, k + 8, Blocks.mossy_cobblestone);
        world.setBlock(i + 5, j + 0, k + 9, Blocks.mossy_cobblestone);
        world.setBlock(i + 5, j + 0, k + 10, Blocks.cobblestone);
        world.setBlock(i + 5, j + 0, k + 11, Blocks.cobblestone);
        world.setBlock(i + 5, j + 0, k + 12, Blocks.mossy_cobblestone);
        world.setBlock(i + 5, j + 0, k + 13, Blocks.cobblestone);
        world.setBlock(i + 5, j + 0, k + 14, Blocks.cobblestone);
        world.setBlock(i + 5, j + 0, k + 15, Blocks.mossy_cobblestone);
        world.setBlock(i + 5, j + 0, k + 16, Blocks.cobblestone);
        world.setBlock(i + 5, j + 0, k + 17, Blocks.cobblestone);
        world.setBlock(i + 5, j + 0, k + 18, Blocks.mossy_cobblestone);
        world.setBlock(i + 5, j + 0, k + 19, Blocks.cobblestone);
        world.setBlock(i + 5, j + 0, k + 20, Blocks.mossy_cobblestone);
        world.setBlock(i + 5, j + 0, k + 21, Blocks.cobblestone);
        world.setBlock(i + 5, j + 0, k + 22, Blocks.cobblestone);
        world.setBlock(i + 5, j + 0, k + 23, Blocks.mossy_cobblestone);
        world.setBlock(i + 5, j + 0, k + 24, Blocks.cobblestone);
        world.setBlock(i + 5, j + 0, k + 25, Blocks.cobblestone);
        world.setBlock(i + 5, j + 0, k + 26, Blocks.cobblestone);
        world.setBlock(i + 5, j + 0, k + 27, Blocks.cobblestone);
        world.setBlock(i + 5, j + 0, k + 28, Blocks.mossy_cobblestone);
        world.setBlock(i + 5, j + 0, k + 29, Blocks.mossy_cobblestone);
        world.setBlock(i + 5, j + 0, k + 30, Blocks.mossy_cobblestone);
        world.setBlock(i + 5, j + 1, k + 2, Blocks.cobblestone);
        world.setBlock(i + 5, j + 1, k + 6, (Block)Blocks.double_stone_slab, 3, 0);
        world.setBlock(i + 5, j + 1, k + 7, Blocks.mossy_cobblestone);
        world.setBlock(i + 5, j + 1, k + 10, Blocks.cobblestone);
        world.setBlock(i + 5, j + 1, k + 13, Blocks.mossy_cobblestone);
        world.setBlock(i + 5, j + 1, k + 16, Blocks.mossy_cobblestone);
        world.setBlock(i + 5, j + 1, k + 19, Blocks.cobblestone);
        world.setBlock(i + 5, j + 1, k + 22, Blocks.mossy_cobblestone);
        world.setBlock(i + 5, j + 1, k + 25, Blocks.cobblestone);
        world.setBlock(i + 5, j + 1, k + 26, (Block)Blocks.double_stone_slab, 3, 0);
        world.setBlock(i + 5, j + 1, k + 30, Blocks.cobblestone);
        world.setBlock(i + 5, j + 2, k + 2, Blocks.cobblestone);
        world.setBlock(i + 5, j + 2, k + 7, Blocks.cobblestone);
        world.setBlock(i + 5, j + 2, k + 10, Blocks.mossy_cobblestone);
        world.setBlock(i + 5, j + 2, k + 13, Blocks.cobblestone);
        world.setBlock(i + 5, j + 2, k + 16, Blocks.mossy_cobblestone);
        world.setBlock(i + 5, j + 2, k + 19, Blocks.mossy_cobblestone);
        world.setBlock(i + 5, j + 2, k + 22, Blocks.cobblestone);
        world.setBlock(i + 5, j + 2, k + 25, Blocks.cobblestone);
        world.setBlock(i + 5, j + 2, k + 30, Blocks.mossy_cobblestone);
        world.setBlock(i + 5, j + 3, k + 7, Blocks.cobblestone);
        world.setBlock(i + 5, j + 3, k + 10, Blocks.mossy_cobblestone);
        world.setBlock(i + 5, j + 3, k + 13, Blocks.mossy_cobblestone);
        world.setBlock(i + 5, j + 3, k + 16, Blocks.cobblestone);
        world.setBlock(i + 5, j + 3, k + 19, Blocks.cobblestone);
        world.setBlock(i + 5, j + 3, k + 22, Blocks.cobblestone);
        world.setBlock(i + 5, j + 3, k + 25, Blocks.mossy_cobblestone);
        world.setBlock(i + 5, j + 4, k + 7, Blocks.mossy_cobblestone);
        world.setBlock(i + 5, j + 4, k + 10, Blocks.mossy_cobblestone);
        world.setBlock(i + 5, j + 4, k + 13, Blocks.mossy_cobblestone);
        world.setBlock(i + 5, j + 4, k + 16, Blocks.mossy_cobblestone);
        world.setBlock(i + 5, j + 4, k + 19, Blocks.mossy_cobblestone);
        world.setBlock(i + 5, j + 4, k + 22, Blocks.mossy_cobblestone);
        world.setBlock(i + 5, j + 4, k + 25, Blocks.mossy_cobblestone);
        world.setBlock(i + 5, j + 5, k + 7, Blocks.mossy_cobblestone);
        world.setBlock(i + 5, j + 5, k + 10, Blocks.mossy_cobblestone);
        world.setBlock(i + 5, j + 5, k + 13, Blocks.cobblestone);
        world.setBlock(i + 5, j + 5, k + 16, Blocks.cobblestone);
        world.setBlock(i + 5, j + 5, k + 19, Blocks.cobblestone);
        world.setBlock(i + 5, j + 5, k + 22, Blocks.mossy_cobblestone);
        world.setBlock(i + 5, j + 5, k + 25, Blocks.mossy_cobblestone);
        world.setBlock(i + 5, j + 6, k + 4, Blocks.cobblestone);
        world.setBlock(i + 5, j + 6, k + 7, Blocks.mossy_cobblestone);
        world.setBlock(i + 5, j + 6, k + 10, Blocks.mossy_cobblestone);
        world.setBlock(i + 5, j + 6, k + 13, Blocks.mossy_cobblestone);
        world.setBlock(i + 5, j + 6, k + 16, Blocks.cobblestone);
        world.setBlock(i + 5, j + 6, k + 19, Blocks.mossy_cobblestone);
        world.setBlock(i + 5, j + 6, k + 22, Blocks.cobblestone);
        world.setBlock(i + 5, j + 6, k + 25, Blocks.cobblestone);
        world.setBlock(i + 5, j + 6, k + 28, Blocks.mossy_cobblestone);
        world.setBlock(i + 5, j + 7, k + 7, Blocks.mossy_cobblestone);
        world.setBlock(i + 5, j + 7, k + 10, Blocks.cobblestone);
        world.setBlock(i + 5, j + 7, k + 13, Blocks.mossy_cobblestone);
        world.setBlock(i + 5, j + 7, k + 16, Blocks.cobblestone);
        world.setBlock(i + 5, j + 7, k + 19, Blocks.mossy_cobblestone);
        world.setBlock(i + 5, j + 7, k + 22, Blocks.mossy_cobblestone);
        world.setBlock(i + 5, j + 7, k + 25, Blocks.mossy_cobblestone);
        world.setBlock(i + 6, j + 0, k + 2, Blocks.mossy_cobblestone);
        world.setBlock(i + 6, j + 0, k + 3, Blocks.mossy_cobblestone);
        world.setBlock(i + 6, j + 0, k + 4, Blocks.cobblestone);
        world.setBlock(i + 6, j + 0, k + 5, Blocks.cobblestone);
        world.setBlock(i + 6, j + 0, k + 6, Blocks.mossy_cobblestone);
        world.setBlock(i + 6, j + 0, k + 7, Blocks.cobblestone);
        world.setBlock(i + 6, j + 0, k + 8, Blocks.cobblestone);
        world.setBlock(i + 6, j + 0, k + 9, Blocks.cobblestone);
        world.setBlock(i + 6, j + 0, k + 10, Blocks.mossy_cobblestone);
        world.setBlock(i + 6, j + 0, k + 11, Blocks.cobblestone);
        world.setBlock(i + 6, j + 0, k + 12, Blocks.cobblestone);
        world.setBlock(i + 6, j + 0, k + 13, Blocks.cobblestone);
        world.setBlock(i + 6, j + 0, k + 14, Blocks.mossy_cobblestone);
        world.setBlock(i + 6, j + 0, k + 15, Blocks.cobblestone);
        world.setBlock(i + 6, j + 0, k + 16, Blocks.cobblestone);
        world.setBlock(i + 6, j + 0, k + 17, Blocks.mossy_cobblestone);
        world.setBlock(i + 6, j + 0, k + 18, Blocks.cobblestone);
        world.setBlock(i + 6, j + 0, k + 19, Blocks.mossy_cobblestone);
        world.setBlock(i + 6, j + 0, k + 20, Blocks.mossy_cobblestone);
        world.setBlock(i + 6, j + 0, k + 21, Blocks.mossy_cobblestone);
        world.setBlock(i + 6, j + 0, k + 22, Blocks.cobblestone);
        world.setBlock(i + 6, j + 0, k + 23, Blocks.cobblestone);
        world.setBlock(i + 6, j + 0, k + 24, Blocks.mossy_cobblestone);
        world.setBlock(i + 6, j + 0, k + 25, Blocks.mossy_cobblestone);
        world.setBlock(i + 6, j + 0, k + 26, Blocks.mossy_cobblestone);
        world.setBlock(i + 6, j + 0, k + 27, Blocks.cobblestone);
        world.setBlock(i + 6, j + 0, k + 28, Blocks.cobblestone);
        world.setBlock(i + 6, j + 0, k + 29, Blocks.cobblestone);
        world.setBlock(i + 6, j + 0, k + 30, Blocks.mossy_cobblestone);
        world.setBlock(i + 6, j + 1, k + 2, Blocks.cobblestone);
        world.setBlock(i + 6, j + 1, k + 5, (Block)Blocks.double_stone_slab, 3, 0);
        world.setBlock(i + 6, j + 1, k + 6, Blocks.glowstone);
        world.setBlock(i + 6, j + 1, k + 7, Blocks.mossy_cobblestone);
        world.setBlock(i + 6, j + 1, k + 8, Blocks.cobblestone);
        world.setBlock(i + 6, j + 1, k + 9, Blocks.mossy_cobblestone);
        world.setBlock(i + 6, j + 1, k + 10, Blocks.mossy_cobblestone);
        world.setBlock(i + 6, j + 1, k + 11, Blocks.cobblestone);
        world.setBlock(i + 6, j + 1, k + 12, Blocks.cobblestone);
        world.setBlock(i + 6, j + 1, k + 13, Blocks.mossy_cobblestone);
        world.setBlock(i + 6, j + 1, k + 14, Blocks.cobblestone);
        world.setBlock(i + 6, j + 1, k + 15, Blocks.mossy_cobblestone);
        world.setBlock(i + 6, j + 1, k + 16, Blocks.mossy_cobblestone);
        world.setBlock(i + 6, j + 1, k + 17, Blocks.cobblestone);
        world.setBlock(i + 6, j + 1, k + 18, Blocks.mossy_cobblestone);
        world.setBlock(i + 6, j + 1, k + 19, Blocks.mossy_cobblestone);
        world.setBlock(i + 6, j + 1, k + 20, Blocks.cobblestone);
        world.setBlock(i + 6, j + 1, k + 21, Blocks.mossy_cobblestone);
        world.setBlock(i + 6, j + 1, k + 22, Blocks.cobblestone);
        world.setBlock(i + 6, j + 1, k + 23, Blocks.mossy_cobblestone);
        world.setBlock(i + 6, j + 1, k + 24, Blocks.mossy_cobblestone);
        world.setBlock(i + 6, j + 1, k + 25, Blocks.mossy_cobblestone);
        world.setBlock(i + 6, j + 1, k + 26, Blocks.glowstone);
        world.setBlock(i + 6, j + 1, k + 27, (Block)Blocks.double_stone_slab, 3, 0);
        world.setBlock(i + 6, j + 1, k + 30, Blocks.cobblestone);
        world.setBlock(i + 6, j + 2, k + 2, Blocks.cobblestone);
        world.setBlock(i + 6, j + 2, k + 6, Blocks.mossy_cobblestone);
        world.setBlock(i + 6, j + 2, k + 7, Blocks.cobblestone);
        world.setBlock(i + 6, j + 2, k + 8, (Block)Blocks.stone_slab, 11, 0);
        world.setBlock(i + 6, j + 2, k + 9, (Block)Blocks.stone_slab, 11, 0);
        world.setBlock(i + 6, j + 2, k + 10, Blocks.cobblestone);
        world.setBlock(i + 6, j + 2, k + 11, (Block)Blocks.stone_slab, 11, 0);
        world.setBlock(i + 6, j + 2, k + 12, (Block)Blocks.stone_slab, 11, 0);
        world.setBlock(i + 6, j + 2, k + 13, Blocks.cobblestone);
        world.setBlock(i + 6, j + 2, k + 14, (Block)Blocks.stone_slab, 11, 0);
        world.setBlock(i + 6, j + 2, k + 15, (Block)Blocks.stone_slab, 11, 0);
        world.setBlock(i + 6, j + 2, k + 16, Blocks.cobblestone);
        world.setBlock(i + 6, j + 2, k + 17, (Block)Blocks.stone_slab, 11, 0);
        world.setBlock(i + 6, j + 2, k + 18, (Block)Blocks.stone_slab, 11, 0);
        world.setBlock(i + 6, j + 2, k + 19, Blocks.cobblestone);
        world.setBlock(i + 6, j + 2, k + 20, (Block)Blocks.stone_slab, 11, 0);
        world.setBlock(i + 6, j + 2, k + 21, (Block)Blocks.stone_slab, 11, 0);
        world.setBlock(i + 6, j + 2, k + 22, Blocks.cobblestone);
        world.setBlock(i + 6, j + 2, k + 23, (Block)Blocks.stone_slab, 11, 0);
        world.setBlock(i + 6, j + 2, k + 24, (Block)Blocks.stone_slab, 11, 0);
        world.setBlock(i + 6, j + 2, k + 25, Blocks.cobblestone);
        world.setBlock(i + 6, j + 2, k + 26, Blocks.cobblestone);
        world.setBlock(i + 6, j + 2, k + 30, Blocks.cobblestone);
        world.setBlock(i + 6, j + 3, k + 2, (Block)Blocks.stone_slab, 3, 0);
        world.setBlock(i + 6, j + 3, k + 6, Blocks.cobblestone);
        world.setBlock(i + 6, j + 3, k + 7, Blocks.cobblestone);
        world.setBlock(i + 6, j + 3, k + 8, Blocks.cobblestone);
        world.setBlock(i + 6, j + 3, k + 9, Blocks.mossy_cobblestone);
        world.setBlock(i + 6, j + 3, k + 10, Blocks.cobblestone);
        world.setBlock(i + 6, j + 3, k + 11, Blocks.mossy_cobblestone);
        world.setBlock(i + 6, j + 3, k + 12, Blocks.mossy_cobblestone);
        world.setBlock(i + 6, j + 3, k + 13, Blocks.cobblestone);
        world.setBlock(i + 6, j + 3, k + 14, Blocks.mossy_cobblestone);
        world.setBlock(i + 6, j + 3, k + 15, Blocks.mossy_cobblestone);
        world.setBlock(i + 6, j + 3, k + 16, Blocks.mossy_cobblestone);
        world.setBlock(i + 6, j + 3, k + 17, Blocks.mossy_cobblestone);
        world.setBlock(i + 6, j + 3, k + 18, Blocks.mossy_cobblestone);
        world.setBlock(i + 6, j + 3, k + 19, Blocks.cobblestone);
        world.setBlock(i + 6, j + 3, k + 20, Blocks.cobblestone);
        world.setBlock(i + 6, j + 3, k + 21, Blocks.mossy_cobblestone);
        world.setBlock(i + 6, j + 3, k + 22, Blocks.mossy_cobblestone);
        world.setBlock(i + 6, j + 3, k + 23, Blocks.cobblestone);
        world.setBlock(i + 6, j + 3, k + 24, Blocks.mossy_cobblestone);
        world.setBlock(i + 6, j + 3, k + 25, Blocks.cobblestone);
        world.setBlock(i + 6, j + 3, k + 26, Blocks.mossy_cobblestone);
        world.setBlock(i + 6, j + 3, k + 30, (Block)Blocks.stone_slab, 3, 0);
        world.setBlock(i + 6, j + 4, k + 6, Blocks.mossy_cobblestone);
        world.setBlock(i + 6, j + 4, k + 7, Blocks.cobblestone);
        world.setBlock(i + 6, j + 4, k + 8, Blocks.cobblestone);
        world.setBlock(i + 6, j + 4, k + 9, Blocks.cobblestone);
        world.setBlock(i + 6, j + 4, k + 10, Blocks.cobblestone);
        world.setBlock(i + 6, j + 4, k + 11, Blocks.cobblestone);
        world.setBlock(i + 6, j + 4, k + 12, Blocks.cobblestone);
        world.setBlock(i + 6, j + 4, k + 13, Blocks.mossy_cobblestone);
        world.setBlock(i + 6, j + 4, k + 14, Blocks.mossy_cobblestone);
        world.setBlock(i + 6, j + 4, k + 15, Blocks.cobblestone);
        world.setBlock(i + 6, j + 4, k + 16, Blocks.mossy_cobblestone);
        world.setBlock(i + 6, j + 4, k + 17, Blocks.cobblestone);
        world.setBlock(i + 6, j + 4, k + 18, Blocks.cobblestone);
        world.setBlock(i + 6, j + 4, k + 19, Blocks.mossy_cobblestone);
        world.setBlock(i + 6, j + 4, k + 20, Blocks.mossy_cobblestone);
        world.setBlock(i + 6, j + 4, k + 21, Blocks.cobblestone);
        world.setBlock(i + 6, j + 4, k + 22, Blocks.mossy_cobblestone);
        world.setBlock(i + 6, j + 4, k + 23, Blocks.mossy_cobblestone);
        world.setBlock(i + 6, j + 4, k + 24, Blocks.mossy_cobblestone);
        world.setBlock(i + 6, j + 4, k + 25, Blocks.cobblestone);
        world.setBlock(i + 6, j + 4, k + 26, Blocks.mossy_cobblestone);
        world.setBlock(i + 6, j + 5, k + 6, Blocks.cobblestone);
        world.setBlock(i + 6, j + 5, k + 7, Blocks.mossy_cobblestone);
        world.setBlock(i + 6, j + 5, k + 8, Blocks.cobblestone);
        world.setBlock(i + 6, j + 5, k + 9, Blocks.mossy_cobblestone);
        world.setBlock(i + 6, j + 5, k + 10, Blocks.mossy_cobblestone);
        world.setBlock(i + 6, j + 5, k + 11, Blocks.mossy_cobblestone);
        world.setBlock(i + 6, j + 5, k + 12, Blocks.cobblestone);
        world.setBlock(i + 6, j + 5, k + 13, Blocks.cobblestone);
        world.setBlock(i + 6, j + 5, k + 14, Blocks.mossy_cobblestone);
        world.setBlock(i + 6, j + 5, k + 15, Blocks.mossy_cobblestone);
        world.setBlock(i + 6, j + 5, k + 16, Blocks.mossy_cobblestone);
        world.setBlock(i + 6, j + 5, k + 17, Blocks.cobblestone);
        world.setBlock(i + 6, j + 5, k + 18, Blocks.cobblestone);
        world.setBlock(i + 6, j + 5, k + 19, Blocks.mossy_cobblestone);
        world.setBlock(i + 6, j + 5, k + 20, Blocks.cobblestone);
        world.setBlock(i + 6, j + 5, k + 21, Blocks.cobblestone);
        world.setBlock(i + 6, j + 5, k + 22, Blocks.mossy_cobblestone);
        world.setBlock(i + 6, j + 5, k + 23, Blocks.mossy_cobblestone);
        world.setBlock(i + 6, j + 5, k + 24, Blocks.cobblestone);
        world.setBlock(i + 6, j + 5, k + 25, Blocks.mossy_cobblestone);
        world.setBlock(i + 6, j + 5, k + 26, Blocks.mossy_cobblestone);
        world.setBlock(i + 6, j + 6, k + 4, Blocks.cobblestone);
        world.setBlock(i + 6, j + 6, k + 6, Blocks.cobblestone);
        world.setBlock(i + 6, j + 6, k + 7, Blocks.cobblestone);
        world.setBlock(i + 6, j + 6, k + 8, Blocks.cobblestone);
        world.setBlock(i + 6, j + 6, k + 9, Blocks.cobblestone);
        world.setBlock(i + 6, j + 6, k + 10, Blocks.mossy_cobblestone);
        world.setBlock(i + 6, j + 6, k + 11, Blocks.cobblestone);
        world.setBlock(i + 6, j + 6, k + 12, Blocks.cobblestone);
        world.setBlock(i + 6, j + 6, k + 13, Blocks.cobblestone);
        world.setBlock(i + 6, j + 6, k + 14, Blocks.mossy_cobblestone);
        world.setBlock(i + 6, j + 6, k + 15, Blocks.mossy_cobblestone);
        world.setBlock(i + 6, j + 6, k + 16, Blocks.mossy_cobblestone);
        world.setBlock(i + 6, j + 6, k + 17, Blocks.cobblestone);
        world.setBlock(i + 6, j + 6, k + 18, Blocks.cobblestone);
        world.setBlock(i + 6, j + 6, k + 19, Blocks.cobblestone);
        world.setBlock(i + 6, j + 6, k + 20, Blocks.mossy_cobblestone);
        world.setBlock(i + 6, j + 6, k + 21, Blocks.cobblestone);
        world.setBlock(i + 6, j + 6, k + 22, Blocks.mossy_cobblestone);
        world.setBlock(i + 6, j + 6, k + 23, Blocks.mossy_cobblestone);
        world.setBlock(i + 6, j + 6, k + 24, Blocks.cobblestone);
        world.setBlock(i + 6, j + 6, k + 25, Blocks.cobblestone);
        world.setBlock(i + 6, j + 6, k + 26, Blocks.mossy_cobblestone);
        world.setBlock(i + 6, j + 6, k + 28, Blocks.cobblestone);
        world.setBlock(i + 6, j + 7, k + 6, Blocks.mossy_cobblestone);
        world.setBlock(i + 6, j + 7, k + 7, Blocks.cobblestone);
        world.setBlock(i + 6, j + 7, k + 8, Blocks.cobblestone);
        world.setBlock(i + 6, j + 7, k + 9, Blocks.mossy_cobblestone);
        world.setBlock(i + 6, j + 7, k + 10, Blocks.cobblestone);
        world.setBlock(i + 6, j + 7, k + 11, Blocks.mossy_cobblestone);
        world.setBlock(i + 6, j + 7, k + 12, Blocks.mossy_cobblestone);
        world.setBlock(i + 6, j + 7, k + 13, Blocks.mossy_cobblestone);
        world.setBlock(i + 6, j + 7, k + 14, Blocks.cobblestone);
        world.setBlock(i + 6, j + 7, k + 15, Blocks.cobblestone);
        world.setBlock(i + 6, j + 7, k + 16, Blocks.mossy_cobblestone);
        world.setBlock(i + 6, j + 7, k + 17, Blocks.cobblestone);
        world.setBlock(i + 6, j + 7, k + 18, Blocks.cobblestone);
        world.setBlock(i + 6, j + 7, k + 19, Blocks.cobblestone);
        world.setBlock(i + 6, j + 7, k + 20, Blocks.mossy_cobblestone);
        world.setBlock(i + 6, j + 7, k + 21, Blocks.mossy_cobblestone);
        world.setBlock(i + 6, j + 7, k + 22, Blocks.cobblestone);
        world.setBlock(i + 6, j + 7, k + 23, Blocks.cobblestone);
        world.setBlock(i + 6, j + 7, k + 24, Blocks.cobblestone);
        world.setBlock(i + 6, j + 7, k + 25, Blocks.cobblestone);
        world.setBlock(i + 6, j + 7, k + 26, Blocks.mossy_cobblestone);
        world.setBlock(i + 6, j + 8, k + 6, Blocks.mossy_cobblestone);
        world.setBlock(i + 6, j + 8, k + 7, Blocks.cobblestone);
        world.setBlock(i + 6, j + 8, k + 8, Blocks.cobblestone);
        world.setBlock(i + 6, j + 8, k + 9, Blocks.mossy_cobblestone);
        world.setBlock(i + 6, j + 8, k + 10, Blocks.cobblestone);
        world.setBlock(i + 6, j + 8, k + 11, Blocks.cobblestone);
        world.setBlock(i + 6, j + 8, k + 12, Blocks.mossy_cobblestone);
        world.setBlock(i + 6, j + 8, k + 13, Blocks.mossy_cobblestone);
        world.setBlock(i + 6, j + 8, k + 14, Blocks.mossy_cobblestone);
        world.setBlock(i + 6, j + 8, k + 15, Blocks.cobblestone);
        world.setBlock(i + 6, j + 8, k + 16, Blocks.mossy_cobblestone);
        world.setBlock(i + 6, j + 8, k + 17, Blocks.cobblestone);
        world.setBlock(i + 6, j + 8, k + 18, Blocks.mossy_cobblestone);
        world.setBlock(i + 6, j + 8, k + 19, Blocks.cobblestone);
        world.setBlock(i + 6, j + 8, k + 20, Blocks.cobblestone);
        world.setBlock(i + 6, j + 8, k + 21, Blocks.mossy_cobblestone);
        world.setBlock(i + 6, j + 8, k + 22, Blocks.mossy_cobblestone);
        world.setBlock(i + 6, j + 8, k + 23, Blocks.mossy_cobblestone);
        world.setBlock(i + 6, j + 8, k + 24, Blocks.mossy_cobblestone);
        world.setBlock(i + 6, j + 8, k + 25, Blocks.cobblestone);
        world.setBlock(i + 6, j + 8, k + 26, Blocks.mossy_cobblestone);
        world.setBlock(i + 7, j + 0, k + 2, Blocks.mossy_cobblestone);
        world.setBlock(i + 7, j + 0, k + 3, Blocks.mossy_cobblestone);
        world.setBlock(i + 7, j + 0, k + 4, Blocks.mossy_cobblestone);
        world.setBlock(i + 7, j + 0, k + 5, Blocks.mossy_cobblestone);
        world.setBlock(i + 7, j + 0, k + 6, Blocks.mossy_cobblestone);
        world.setBlock(i + 7, j + 0, k + 7, Blocks.mossy_cobblestone);
        world.setBlock(i + 7, j + 0, k + 8, Blocks.cobblestone);
        world.setBlock(i + 7, j + 0, k + 9, Blocks.mossy_cobblestone);
        world.setBlock(i + 7, j + 0, k + 10, Blocks.mossy_cobblestone);
        world.setBlock(i + 7, j + 0, k + 11, Blocks.mossy_cobblestone);
        world.setBlock(i + 7, j + 0, k + 12, Blocks.cobblestone);
        world.setBlock(i + 7, j + 0, k + 13, Blocks.mossy_cobblestone);
        world.setBlock(i + 7, j + 0, k + 14, Blocks.mossy_cobblestone);
        world.setBlock(i + 7, j + 0, k + 15, Blocks.mossy_cobblestone);
        world.setBlock(i + 7, j + 0, k + 16, Blocks.mossy_cobblestone);
        world.setBlock(i + 7, j + 0, k + 17, Blocks.mossy_cobblestone);
        world.setBlock(i + 7, j + 0, k + 18, Blocks.cobblestone);
        world.setBlock(i + 7, j + 0, k + 19, Blocks.mossy_cobblestone);
        world.setBlock(i + 7, j + 0, k + 20, Blocks.cobblestone);
        world.setBlock(i + 7, j + 0, k + 21, Blocks.cobblestone);
        world.setBlock(i + 7, j + 0, k + 22, Blocks.cobblestone);
        world.setBlock(i + 7, j + 0, k + 23, Blocks.mossy_cobblestone);
        world.setBlock(i + 7, j + 0, k + 24, Blocks.mossy_cobblestone);
        world.setBlock(i + 7, j + 0, k + 25, Blocks.mossy_cobblestone);
        world.setBlock(i + 7, j + 0, k + 26, Blocks.mossy_cobblestone);
        world.setBlock(i + 7, j + 0, k + 27, Blocks.cobblestone);
        world.setBlock(i + 7, j + 0, k + 28, Blocks.mossy_cobblestone);
        world.setBlock(i + 7, j + 0, k + 29, Blocks.cobblestone);
        world.setBlock(i + 7, j + 0, k + 30, Blocks.cobblestone);
        world.setBlock(i + 7, j + 1, k + 2, Blocks.mossy_cobblestone);
        world.setBlock(i + 7, j + 1, k + 5, Blocks.mossy_cobblestone);
        world.setBlock(i + 7, j + 1, k + 6, Blocks.cobblestone);
        world.setBlock(i + 7, j + 1, k + 26, Blocks.mossy_cobblestone);
        world.setBlock(i + 7, j + 1, k + 27, Blocks.cobblestone);
        world.setBlock(i + 7, j + 1, k + 30, Blocks.mossy_cobblestone);
        world.setBlock(i + 7, j + 2, k + 2, Blocks.cobblestone);
        world.setBlock(i + 7, j + 2, k + 5, Blocks.mossy_cobblestone);
        world.setBlock(i + 7, j + 2, k + 6, Blocks.cobblestone);
        world.setBlock(i + 7, j + 2, k + 26, Blocks.cobblestone);
        world.setBlock(i + 7, j + 2, k + 27, Blocks.cobblestone);
        world.setBlock(i + 7, j + 2, k + 30, Blocks.cobblestone);
        world.setBlock(i + 7, j + 3, k + 5, Blocks.cobblestone);
        world.setBlock(i + 7, j + 3, k + 6, Blocks.cobblestone);
        world.setBlock(i + 7, j + 3, k + 26, Blocks.mossy_cobblestone);
        world.setBlock(i + 7, j + 3, k + 27, Blocks.mossy_cobblestone);
        world.setBlock(i + 7, j + 4, k + 5, Blocks.cobblestone);
        world.setBlock(i + 7, j + 4, k + 6, Blocks.cobblestone);
        world.setBlock(i + 7, j + 4, k + 7, Blocks.cobblestone);
        world.setBlock(i + 7, j + 4, k + 10, Blocks.mossy_cobblestone);
        world.setBlock(i + 7, j + 4, k + 13, Blocks.mossy_cobblestone);
        world.setBlock(i + 7, j + 4, k + 16, Blocks.cobblestone);
        world.setBlock(i + 7, j + 4, k + 19, Blocks.mossy_cobblestone);
        world.setBlock(i + 7, j + 4, k + 22, Blocks.cobblestone);
        world.setBlock(i + 7, j + 4, k + 25, Blocks.cobblestone);
        world.setBlock(i + 7, j + 4, k + 26, Blocks.mossy_cobblestone);
        world.setBlock(i + 7, j + 4, k + 27, Blocks.cobblestone);
        world.setBlock(i + 7, j + 5, k + 4, Blocks.cobblestone);
        world.setBlock(i + 7, j + 5, k + 5, Blocks.mossy_cobblestone);
        world.setBlock(i + 7, j + 5, k + 6, Blocks.mossy_cobblestone);
        world.setBlock(i + 7, j + 5, k + 7, Blocks.mossy_cobblestone);
        world.setBlock(i + 7, j + 5, k + 8, Blocks.cobblestone);
        world.setBlock(i + 7, j + 5, k + 10, Blocks.cobblestone);
        world.setBlock(i + 7, j + 5, k + 13, Blocks.mossy_cobblestone);
        world.setBlock(i + 7, j + 5, k + 16, Blocks.mossy_cobblestone);
        world.setBlock(i + 7, j + 5, k + 19, Blocks.cobblestone);
        world.setBlock(i + 7, j + 5, k + 22, Blocks.cobblestone);
        world.setBlock(i + 7, j + 5, k + 24, Blocks.mossy_cobblestone);
        world.setBlock(i + 7, j + 5, k + 25, Blocks.mossy_cobblestone);
        world.setBlock(i + 7, j + 5, k + 26, Blocks.mossy_cobblestone);
        world.setBlock(i + 7, j + 5, k + 27, Blocks.mossy_cobblestone);
        world.setBlock(i + 7, j + 5, k + 28, Blocks.mossy_cobblestone);
        world.setBlock(i + 7, j + 6, k + 3, Blocks.mossy_cobblestone);
        world.setBlock(i + 7, j + 6, k + 4, Blocks.mossy_cobblestone);
        world.setBlock(i + 7, j + 6, k + 5, Blocks.mossy_cobblestone);
        world.setBlock(i + 7, j + 6, k + 6, Blocks.mossy_cobblestone);
        world.setBlock(i + 7, j + 6, k + 7, Blocks.cobblestone);
        world.setBlock(i + 7, j + 6, k + 8, Blocks.mossy_cobblestone);
        world.setBlock(i + 7, j + 6, k + 10, Blocks.mossy_cobblestone);
        world.setBlock(i + 7, j + 6, k + 13, Blocks.mossy_cobblestone);
        world.setBlock(i + 7, j + 6, k + 16, Blocks.cobblestone);
        world.setBlock(i + 7, j + 6, k + 19, Blocks.mossy_cobblestone);
        world.setBlock(i + 7, j + 6, k + 22, Blocks.mossy_cobblestone);
        world.setBlock(i + 7, j + 6, k + 24, Blocks.mossy_cobblestone);
        world.setBlock(i + 7, j + 6, k + 25, Blocks.mossy_cobblestone);
        world.setBlock(i + 7, j + 6, k + 26, Blocks.cobblestone);
        world.setBlock(i + 7, j + 6, k + 27, Blocks.mossy_cobblestone);
        world.setBlock(i + 7, j + 6, k + 28, Blocks.mossy_cobblestone);
        world.setBlock(i + 7, j + 6, k + 29, Blocks.mossy_cobblestone);
        world.setBlock(i + 7, j + 7, k + 5, Blocks.mossy_cobblestone);
        world.setBlock(i + 7, j + 7, k + 6, Blocks.mossy_cobblestone);
        world.setBlock(i + 7, j + 7, k + 7, Blocks.mossy_cobblestone);
        world.setBlock(i + 7, j + 7, k + 8, Blocks.mossy_cobblestone);
        world.setBlock(i + 7, j + 7, k + 10, Blocks.cobblestone);
        world.setBlock(i + 7, j + 7, k + 13, Blocks.mossy_cobblestone);
        world.setBlock(i + 7, j + 7, k + 16, Blocks.cobblestone);
        world.setBlock(i + 7, j + 7, k + 19, Blocks.mossy_cobblestone);
        world.setBlock(i + 7, j + 7, k + 22, Blocks.cobblestone);
        world.setBlock(i + 7, j + 7, k + 24, Blocks.mossy_cobblestone);
        world.setBlock(i + 7, j + 7, k + 25, Blocks.cobblestone);
        world.setBlock(i + 7, j + 7, k + 26, Blocks.cobblestone);
        world.setBlock(i + 7, j + 7, k + 27, Blocks.cobblestone);
        world.setBlock(i + 7, j + 8, k + 6, Blocks.cobblestone);
        world.setBlock(i + 7, j + 8, k + 7, Blocks.cobblestone);
        world.setBlock(i + 7, j + 8, k + 8, Blocks.cobblestone);
        world.setBlock(i + 7, j + 8, k + 10, Blocks.cobblestone);
        world.setBlock(i + 7, j + 8, k + 13, Blocks.cobblestone);
        world.setBlock(i + 7, j + 8, k + 16, Blocks.mossy_cobblestone);
        world.setBlock(i + 7, j + 8, k + 19, Blocks.cobblestone);
        world.setBlock(i + 7, j + 8, k + 22, Blocks.cobblestone);
        world.setBlock(i + 7, j + 8, k + 24, Blocks.cobblestone);
        world.setBlock(i + 7, j + 8, k + 25, Blocks.mossy_cobblestone);
        world.setBlock(i + 7, j + 8, k + 26, Blocks.mossy_cobblestone);
        world.setBlock(i + 8, j + 0, k + 2, Blocks.mossy_cobblestone);
        world.setBlock(i + 8, j + 0, k + 3, Blocks.cobblestone);
        world.setBlock(i + 8, j + 0, k + 4, Blocks.cobblestone);
        world.setBlock(i + 8, j + 0, k + 5, Blocks.cobblestone);
        world.setBlock(i + 8, j + 0, k + 6, Blocks.cobblestone);
        world.setBlock(i + 8, j + 0, k + 7, Blocks.cobblestone);
        world.setBlock(i + 8, j + 0, k + 8, Blocks.cobblestone);
        world.setBlock(i + 8, j + 0, k + 9, Blocks.mossy_cobblestone);
        world.setBlock(i + 8, j + 0, k + 10, Blocks.mossy_cobblestone);
        world.setBlock(i + 8, j + 0, k + 11, Blocks.mossy_cobblestone);
        world.setBlock(i + 8, j + 0, k + 12, Blocks.cobblestone);
        world.setBlock(i + 8, j + 0, k + 13, Blocks.mossy_cobblestone);
        world.setBlock(i + 8, j + 0, k + 14, Blocks.cobblestone);
        world.setBlock(i + 8, j + 0, k + 15, Blocks.mossy_cobblestone);
        world.setBlock(i + 8, j + 0, k + 16, Blocks.mossy_cobblestone);
        world.setBlock(i + 8, j + 0, k + 17, Blocks.mossy_cobblestone);
        world.setBlock(i + 8, j + 0, k + 18, Blocks.mossy_cobblestone);
        world.setBlock(i + 8, j + 0, k + 19, Blocks.cobblestone);
        world.setBlock(i + 8, j + 0, k + 20, Blocks.mossy_cobblestone);
        world.setBlock(i + 8, j + 0, k + 21, Blocks.cobblestone);
        world.setBlock(i + 8, j + 0, k + 22, Blocks.cobblestone);
        world.setBlock(i + 8, j + 0, k + 23, Blocks.cobblestone);
        world.setBlock(i + 8, j + 0, k + 24, Blocks.cobblestone);
        world.setBlock(i + 8, j + 0, k + 25, Blocks.cobblestone);
        world.setBlock(i + 8, j + 0, k + 26, Blocks.mossy_cobblestone);
        world.setBlock(i + 8, j + 0, k + 27, Blocks.mossy_cobblestone);
        world.setBlock(i + 8, j + 0, k + 28, Blocks.mossy_cobblestone);
        world.setBlock(i + 8, j + 0, k + 29, Blocks.cobblestone);
        world.setBlock(i + 8, j + 0, k + 30, Blocks.mossy_cobblestone);
        world.setBlock(i + 8, j + 1, k + 2, Blocks.mossy_cobblestone);
        world.setBlock(i + 8, j + 1, k + 6, Blocks.mossy_cobblestone);
        world.setBlock(i + 8, j + 1, k + 16, (Block)Blocks.stone_slab, 3, 0);
        world.setBlock(i + 8, j + 1, k + 19, Blocks.skull, 1, 0);
        world.setBlock(i + 8, j + 1, k + 26, Blocks.mossy_cobblestone);
        world.setBlock(i + 8, j + 1, k + 30, Blocks.mossy_cobblestone);
        world.setBlock(i + 8, j + 2, k + 2, Blocks.cobblestone);
        world.setBlock(i + 8, j + 2, k + 6, (Block)Blocks.stone_slab, 11, 0);
        world.setBlock(i + 8, j + 2, k + 26, (Block)Blocks.stone_slab, 11, 0);
        world.setBlock(i + 8, j + 2, k + 30, Blocks.cobblestone);
        world.setBlock(i + 8, j + 3, k + 2, Blocks.mossy_cobblestone);
        world.setBlock(i + 8, j + 3, k + 6, Blocks.mossy_cobblestone);
        world.setBlock(i + 8, j + 3, k + 26, Blocks.cobblestone);
        world.setBlock(i + 8, j + 3, k + 30, Blocks.mossy_cobblestone);
        world.setBlock(i + 8, j + 4, k + 6, Blocks.cobblestone);
        world.setBlock(i + 8, j + 4, k + 26, Blocks.mossy_cobblestone);
        world.setBlock(i + 8, j + 5, k + 6, Blocks.mossy_cobblestone);
        world.setBlock(i + 8, j + 5, k + 7, Blocks.cobblestone);
        world.setBlock(i + 8, j + 5, k + 10, Blocks.mossy_cobblestone);
        world.setBlock(i + 8, j + 5, k + 13, Blocks.cobblestone);
        world.setBlock(i + 8, j + 5, k + 16, Blocks.cobblestone);
        world.setBlock(i + 8, j + 5, k + 19, Blocks.mossy_cobblestone);
        world.setBlock(i + 8, j + 5, k + 22, Blocks.cobblestone);
        world.setBlock(i + 8, j + 5, k + 25, Blocks.mossy_cobblestone);
        world.setBlock(i + 8, j + 5, k + 26, Blocks.mossy_cobblestone);
        world.setBlock(i + 8, j + 6, k + 4, Blocks.mossy_cobblestone);
        world.setBlock(i + 8, j + 6, k + 6, Blocks.mossy_cobblestone);
        world.setBlock(i + 8, j + 6, k + 7, Blocks.mossy_cobblestone);
        world.setBlock(i + 8, j + 6, k + 10, Blocks.mossy_cobblestone);
        world.setBlock(i + 8, j + 6, k + 13, Blocks.cobblestone);
        world.setBlock(i + 8, j + 6, k + 16, Blocks.mossy_cobblestone);
        world.setBlock(i + 8, j + 6, k + 19, Blocks.mossy_cobblestone);
        world.setBlock(i + 8, j + 6, k + 22, Blocks.mossy_cobblestone);
        world.setBlock(i + 8, j + 6, k + 25, Blocks.mossy_cobblestone);
        world.setBlock(i + 8, j + 6, k + 26, Blocks.mossy_cobblestone);
        world.setBlock(i + 8, j + 6, k + 28, Blocks.cobblestone);
        world.setBlock(i + 8, j + 7, k + 6, Blocks.cobblestone);
        world.setBlock(i + 8, j + 7, k + 7, Blocks.mossy_cobblestone);
        world.setBlock(i + 8, j + 7, k + 10, Blocks.cobblestone);
        world.setBlock(i + 8, j + 7, k + 13, Blocks.cobblestone);
        world.setBlock(i + 8, j + 7, k + 16, Blocks.mossy_cobblestone);
        world.setBlock(i + 8, j + 7, k + 19, Blocks.mossy_cobblestone);
        world.setBlock(i + 8, j + 7, k + 22, Blocks.cobblestone);
        world.setBlock(i + 8, j + 7, k + 25, Blocks.mossy_cobblestone);
        world.setBlock(i + 8, j + 7, k + 26, Blocks.mossy_cobblestone);
        world.setBlock(i + 8, j + 8, k + 6, Blocks.cobblestone);
        world.setBlock(i + 8, j + 8, k + 7, Blocks.cobblestone);
        world.setBlock(i + 8, j + 8, k + 8, Blocks.cobblestone);
        world.setBlock(i + 8, j + 8, k + 9, Blocks.mossy_cobblestone);
        world.setBlock(i + 8, j + 8, k + 10, Blocks.cobblestone);
        world.setBlock(i + 8, j + 8, k + 11, Blocks.mossy_cobblestone);
        world.setBlock(i + 8, j + 8, k + 12, Blocks.mossy_cobblestone);
        world.setBlock(i + 8, j + 8, k + 13, Blocks.cobblestone);
        world.setBlock(i + 8, j + 8, k + 14, Blocks.cobblestone);
        world.setBlock(i + 8, j + 8, k + 15, Blocks.cobblestone);
        world.setBlock(i + 8, j + 8, k + 16, Blocks.cobblestone);
        world.setBlock(i + 8, j + 8, k + 17, Blocks.cobblestone);
        world.setBlock(i + 8, j + 8, k + 18, Blocks.cobblestone);
        world.setBlock(i + 8, j + 8, k + 19, Blocks.cobblestone);
        world.setBlock(i + 8, j + 8, k + 20, Blocks.cobblestone);
        world.setBlock(i + 8, j + 8, k + 21, Blocks.cobblestone);
        world.setBlock(i + 8, j + 8, k + 22, Blocks.mossy_cobblestone);
        world.setBlock(i + 8, j + 8, k + 23, Blocks.cobblestone);
        world.setBlock(i + 8, j + 8, k + 24, Blocks.cobblestone);
        world.setBlock(i + 8, j + 8, k + 25, Blocks.mossy_cobblestone);
        world.setBlock(i + 8, j + 8, k + 26, Blocks.mossy_cobblestone);
        world.setBlock(i + 8, j + 9, k + 8, Blocks.mossy_cobblestone);
        world.setBlock(i + 8, j + 9, k + 10, Blocks.mossy_cobblestone);
        world.setBlock(i + 8, j + 9, k + 13, Blocks.mossy_cobblestone);
        world.setBlock(i + 8, j + 9, k + 16, Blocks.mossy_cobblestone);
        world.setBlock(i + 8, j + 9, k + 19, Blocks.mossy_cobblestone);
        world.setBlock(i + 8, j + 9, k + 22, Blocks.mossy_cobblestone);
        world.setBlock(i + 8, j + 9, k + 24, Blocks.mossy_cobblestone);
        world.setBlock(i + 9, j + 0, k + 2, Blocks.mossy_cobblestone);
        world.setBlock(i + 9, j + 0, k + 3, Blocks.mossy_cobblestone);
        world.setBlock(i + 9, j + 0, k + 4, Blocks.mossy_cobblestone);
        world.setBlock(i + 9, j + 0, k + 5, Blocks.cobblestone);
        world.setBlock(i + 9, j + 0, k + 6, Blocks.cobblestone);
        world.setBlock(i + 9, j + 0, k + 7, Blocks.mossy_cobblestone);
        world.setBlock(i + 9, j + 0, k + 8, Blocks.cobblestone);
        world.setBlock(i + 9, j + 0, k + 9, Blocks.mossy_cobblestone);
        world.setBlock(i + 9, j + 0, k + 10, Blocks.mossy_cobblestone);
        world.setBlock(i + 9, j + 0, k + 11, Blocks.mossy_cobblestone);
        world.setBlock(i + 9, j + 0, k + 12, Blocks.mossy_cobblestone);
        world.setBlock(i + 9, j + 0, k + 13, Blocks.cobblestone);
        world.setBlock(i + 9, j + 0, k + 14, Blocks.cobblestone);
        world.setBlock(i + 9, j + 0, k + 15, Blocks.cobblestone);
        world.setBlock(i + 9, j + 0, k + 16, Blocks.cobblestone);
        world.setBlock(i + 9, j + 0, k + 17, Blocks.cobblestone);
        world.setBlock(i + 9, j + 0, k + 18, Blocks.cobblestone);
        world.setBlock(i + 9, j + 0, k + 19, Blocks.mossy_cobblestone);
        world.setBlock(i + 9, j + 0, k + 20, Blocks.mossy_cobblestone);
        world.setBlock(i + 9, j + 0, k + 21, Blocks.cobblestone);
        world.setBlock(i + 9, j + 0, k + 22, Blocks.cobblestone);
        world.setBlock(i + 9, j + 0, k + 23, Blocks.cobblestone);
        world.setBlock(i + 9, j + 0, k + 24, Blocks.cobblestone);
        world.setBlock(i + 9, j + 0, k + 25, Blocks.cobblestone);
        world.setBlock(i + 9, j + 0, k + 26, Blocks.mossy_cobblestone);
        world.setBlock(i + 9, j + 0, k + 27, Blocks.mossy_cobblestone);
        world.setBlock(i + 9, j + 0, k + 28, Blocks.mossy_cobblestone);
        world.setBlock(i + 9, j + 0, k + 29, Blocks.cobblestone);
        world.setBlock(i + 9, j + 0, k + 30, Blocks.cobblestone);
        world.setBlock(i + 9, j + 1, k + 2, Blocks.mossy_cobblestone);
        world.setBlock(i + 9, j + 1, k + 6, Blocks.mossy_cobblestone);
        world.setBlock(i + 9, j + 1, k + 15, (Block)Blocks.stone_slab, 3, 0);
        world.setBlock(i + 9, j + 1, k + 16, Blocks.mossy_cobblestone);
        world.setBlock(i + 9, j + 1, k + 17, (Block)Blocks.stone_slab, 3, 0);
        world.setBlock(i + 9, j + 1, k + 26, Blocks.cobblestone);
        world.setBlock(i + 9, j + 1, k + 30, Blocks.cobblestone);
        world.setBlock(i + 9, j + 2, k + 2, Blocks.mossy_cobblestone);
        world.setBlock(i + 9, j + 2, k + 6, (Block)Blocks.stone_slab, 11, 0);
        world.setBlock(i + 9, j + 2, k + 26, (Block)Blocks.stone_slab, 11, 0);
        world.setBlock(i + 9, j + 2, k + 30, Blocks.cobblestone);
        world.setBlock(i + 9, j + 3, k + 6, Blocks.cobblestone);
        world.setBlock(i + 9, j + 3, k + 26, Blocks.mossy_cobblestone);
        world.setBlock(i + 9, j + 4, k + 6, Blocks.mossy_cobblestone);
        world.setBlock(i + 9, j + 4, k + 26, Blocks.mossy_cobblestone);
        world.setBlock(i + 9, j + 5, k + 6, Blocks.mossy_cobblestone);
        world.setBlock(i + 9, j + 5, k + 26, Blocks.cobblestone);
        world.setBlock(i + 9, j + 6, k + 4, Blocks.cobblestone);
        world.setBlock(i + 9, j + 6, k + 6, Blocks.cobblestone);
        world.setBlock(i + 9, j + 6, k + 26, Blocks.cobblestone);
        world.setBlock(i + 9, j + 6, k + 28, Blocks.mossy_cobblestone);
        world.setBlock(i + 9, j + 7, k + 6, Blocks.mossy_cobblestone);
        world.setBlock(i + 9, j + 7, k + 10, Blocks.mossy_cobblestone);
        world.setBlock(i + 9, j + 7, k + 13, Blocks.mossy_cobblestone);
        world.setBlock(i + 9, j + 7, k + 16, Blocks.cobblestone);
        world.setBlock(i + 9, j + 7, k + 19, Blocks.mossy_cobblestone);
        world.setBlock(i + 9, j + 7, k + 22, Blocks.mossy_cobblestone);
        world.setBlock(i + 9, j + 7, k + 26, Blocks.cobblestone);
        world.setBlock(i + 9, j + 8, k + 6, Blocks.cobblestone);
        world.setBlock(i + 9, j + 8, k + 10, Blocks.mossy_cobblestone);
        world.setBlock(i + 9, j + 8, k + 13, Blocks.mossy_cobblestone);
        world.setBlock(i + 9, j + 8, k + 16, Blocks.cobblestone);
        world.setBlock(i + 9, j + 8, k + 19, Blocks.cobblestone);
        world.setBlock(i + 9, j + 8, k + 22, Blocks.cobblestone);
        world.setBlock(i + 9, j + 8, k + 26, Blocks.cobblestone);
        world.setBlock(i + 10, j + 0, k + 2, Blocks.cobblestone);
        world.setBlock(i + 10, j + 0, k + 3, Blocks.cobblestone);
        world.setBlock(i + 10, j + 0, k + 4, Blocks.mossy_cobblestone);
        world.setBlock(i + 10, j + 0, k + 5, Blocks.cobblestone);
        world.setBlock(i + 10, j + 0, k + 6, Blocks.cobblestone);
        world.setBlock(i + 10, j + 0, k + 7, Blocks.mossy_cobblestone);
        world.setBlock(i + 10, j + 0, k + 8, Blocks.cobblestone);
        world.setBlock(i + 10, j + 0, k + 9, Blocks.mossy_cobblestone);
        world.setBlock(i + 10, j + 0, k + 10, Blocks.cobblestone);
        world.setBlock(i + 10, j + 0, k + 11, Blocks.mossy_cobblestone);
        world.setBlock(i + 10, j + 0, k + 12, Blocks.mossy_cobblestone);
        world.setBlock(i + 10, j + 0, k + 13, Blocks.mossy_cobblestone);
        world.setBlock(i + 10, j + 0, k + 14, Blocks.cobblestone);
        world.setBlock(i + 10, j + 0, k + 15, Blocks.mossy_cobblestone);
        world.setBlock(i + 10, j + 0, k + 16, Blocks.cobblestone);
        world.setBlock(i + 10, j + 0, k + 17, Blocks.cobblestone);
        world.setBlock(i + 10, j + 0, k + 18, Blocks.mossy_cobblestone);
        world.setBlock(i + 10, j + 0, k + 19, Blocks.mossy_cobblestone);
        world.setBlock(i + 10, j + 0, k + 20, Blocks.cobblestone);
        world.setBlock(i + 10, j + 0, k + 21, Blocks.mossy_cobblestone);
        world.setBlock(i + 10, j + 0, k + 22, Blocks.mossy_cobblestone);
        world.setBlock(i + 10, j + 0, k + 23, Blocks.cobblestone);
        world.setBlock(i + 10, j + 0, k + 24, Blocks.mossy_cobblestone);
        world.setBlock(i + 10, j + 0, k + 25, Blocks.mossy_cobblestone);
        world.setBlock(i + 10, j + 0, k + 26, Blocks.mossy_cobblestone);
        world.setBlock(i + 10, j + 0, k + 27, Blocks.mossy_cobblestone);
        world.setBlock(i + 10, j + 0, k + 28, Blocks.mossy_cobblestone);
        world.setBlock(i + 10, j + 0, k + 29, Blocks.mossy_cobblestone);
        world.setBlock(i + 10, j + 0, k + 30, Blocks.cobblestone);
        world.setBlock(i + 10, j + 1, k + 2, Blocks.cobblestone);
        world.setBlock(i + 10, j + 1, k + 5, Blocks.cobblestone);
        world.setBlock(i + 10, j + 1, k + 6, Blocks.mossy_cobblestone);
        world.setBlock(i + 10, j + 1, k + 14, (Block)Blocks.stone_slab, 3, 0);
        world.setBlock(i + 10, j + 1, k + 15, Blocks.cobblestone);
        world.setBlock(i + 10, j + 1, k + 17, Blocks.mossy_cobblestone);
        world.setBlock(i + 10, j + 1, k + 18, (Block)Blocks.stone_slab, 3, 0);
        world.setBlock(i + 10, j + 1, k + 23, Blocks.skull, 1, 0);
        world.setBlock(i + 10, j + 1, k + 26, Blocks.mossy_cobblestone);
        world.setBlock(i + 10, j + 1, k + 27, Blocks.cobblestone);
        world.setBlock(i + 10, j + 1, k + 30, Blocks.cobblestone);
        world.setBlock(i + 10, j + 2, k + 2, Blocks.cobblestone);
        world.setBlock(i + 10, j + 2, k + 5, Blocks.mossy_cobblestone);
        world.setBlock(i + 10, j + 2, k + 6, Blocks.cobblestone);
        world.setBlock(i + 10, j + 2, k + 26, Blocks.cobblestone);
        world.setBlock(i + 10, j + 2, k + 27, Blocks.cobblestone);
        world.setBlock(i + 10, j + 2, k + 30, Blocks.cobblestone);
        world.setBlock(i + 10, j + 3, k + 2, (Block)Blocks.stone_slab, 3, 0);
        world.setBlock(i + 10, j + 3, k + 5, Blocks.mossy_cobblestone);
        world.setBlock(i + 10, j + 3, k + 6, Blocks.cobblestone);
        world.setBlock(i + 10, j + 3, k + 26, Blocks.cobblestone);
        world.setBlock(i + 10, j + 3, k + 27, Blocks.mossy_cobblestone);
        world.setBlock(i + 10, j + 3, k + 30, (Block)Blocks.stone_slab, 3, 0);
        world.setBlock(i + 10, j + 4, k + 5, Blocks.cobblestone);
        world.setBlock(i + 10, j + 4, k + 6, Blocks.mossy_cobblestone);
        world.setBlock(i + 10, j + 4, k + 7, Blocks.cobblestone);
        world.setBlock(i + 10, j + 4, k + 25, Blocks.mossy_cobblestone);
        world.setBlock(i + 10, j + 4, k + 26, Blocks.cobblestone);
        world.setBlock(i + 10, j + 4, k + 27, Blocks.mossy_cobblestone);
        world.setBlock(i + 10, j + 5, k + 4, Blocks.cobblestone);
        world.setBlock(i + 10, j + 5, k + 5, Blocks.cobblestone);
        world.setBlock(i + 10, j + 5, k + 6, Blocks.cobblestone);
        world.setBlock(i + 10, j + 5, k + 7, Blocks.mossy_cobblestone);
        world.setBlock(i + 10, j + 5, k + 8, Blocks.mossy_cobblestone);
        world.setBlock(i + 10, j + 5, k + 24, Blocks.mossy_cobblestone);
        world.setBlock(i + 10, j + 5, k + 25, Blocks.mossy_cobblestone);
        world.setBlock(i + 10, j + 5, k + 26, Blocks.cobblestone);
        world.setBlock(i + 10, j + 5, k + 27, Blocks.mossy_cobblestone);
        world.setBlock(i + 10, j + 5, k + 28, Blocks.cobblestone);
        world.setBlock(i + 10, j + 6, k + 3, Blocks.cobblestone);
        world.setBlock(i + 10, j + 6, k + 4, Blocks.mossy_cobblestone);
        world.setBlock(i + 10, j + 6, k + 5, Blocks.cobblestone);
        world.setBlock(i + 10, j + 6, k + 6, Blocks.mossy_cobblestone);
        world.setBlock(i + 10, j + 6, k + 7, Blocks.mossy_cobblestone);
        world.setBlock(i + 10, j + 6, k + 8, Blocks.mossy_cobblestone);
        world.setBlock(i + 10, j + 6, k + 24, Blocks.mossy_cobblestone);
        world.setBlock(i + 10, j + 6, k + 25, Blocks.mossy_cobblestone);
        world.setBlock(i + 10, j + 6, k + 26, Blocks.cobblestone);
        world.setBlock(i + 10, j + 6, k + 27, Blocks.cobblestone);
        world.setBlock(i + 10, j + 6, k + 28, Blocks.cobblestone);
        world.setBlock(i + 10, j + 6, k + 29, Blocks.cobblestone);
        world.setBlock(i + 10, j + 7, k + 5, Blocks.mossy_cobblestone);
        world.setBlock(i + 10, j + 7, k + 6, Blocks.mossy_cobblestone);
        world.setBlock(i + 10, j + 7, k + 7, Blocks.mossy_cobblestone);
        world.setBlock(i + 10, j + 7, k + 8, Blocks.mossy_cobblestone);
        world.setBlock(i + 10, j + 7, k + 9, Blocks.cobblestone);
        world.setBlock(i + 10, j + 7, k + 23, Blocks.cobblestone);
        world.setBlock(i + 10, j + 7, k + 24, Blocks.mossy_cobblestone);
        world.setBlock(i + 10, j + 7, k + 25, Blocks.cobblestone);
        world.setBlock(i + 10, j + 7, k + 26, Blocks.cobblestone);
        world.setBlock(i + 10, j + 7, k + 27, Blocks.cobblestone);
        world.setBlock(i + 10, j + 8, k + 6, Blocks.cobblestone);
        world.setBlock(i + 10, j + 8, k + 7, Blocks.cobblestone);
        world.setBlock(i + 10, j + 8, k + 8, Blocks.mossy_cobblestone);
        world.setBlock(i + 10, j + 8, k + 9, Blocks.mossy_cobblestone);
        world.setBlock(i + 10, j + 8, k + 10, Blocks.mossy_cobblestone);
        world.setBlock(i + 10, j + 8, k + 11, Blocks.mossy_cobblestone);
        world.setBlock(i + 10, j + 8, k + 12, Blocks.cobblestone);
        world.setBlock(i + 10, j + 8, k + 13, Blocks.cobblestone);
        world.setBlock(i + 10, j + 8, k + 14, Blocks.mossy_cobblestone);
        world.setBlock(i + 10, j + 8, k + 15, Blocks.mossy_cobblestone);
        world.setBlock(i + 10, j + 8, k + 16, Blocks.cobblestone);
        world.setBlock(i + 10, j + 8, k + 17, Blocks.mossy_cobblestone);
        world.setBlock(i + 10, j + 8, k + 18, Blocks.mossy_cobblestone);
        world.setBlock(i + 10, j + 8, k + 19, Blocks.cobblestone);
        world.setBlock(i + 10, j + 8, k + 20, Blocks.mossy_cobblestone);
        world.setBlock(i + 10, j + 8, k + 21, Blocks.mossy_cobblestone);
        world.setBlock(i + 10, j + 8, k + 22, Blocks.cobblestone);
        world.setBlock(i + 10, j + 8, k + 23, Blocks.cobblestone);
        world.setBlock(i + 10, j + 8, k + 24, Blocks.cobblestone);
        world.setBlock(i + 10, j + 8, k + 25, Blocks.cobblestone);
        world.setBlock(i + 10, j + 8, k + 26, Blocks.mossy_cobblestone);
        world.setBlock(i + 10, j + 9, k + 10, Blocks.cobblestone);
        world.setBlock(i + 10, j + 9, k + 13, Blocks.cobblestone);
        world.setBlock(i + 10, j + 9, k + 16, Blocks.mossy_cobblestone);
        world.setBlock(i + 10, j + 9, k + 19, Blocks.cobblestone);
        world.setBlock(i + 10, j + 9, k + 22, Blocks.cobblestone);
        world.setBlock(i + 11, j + 0, k + 2, Blocks.mossy_cobblestone);
        world.setBlock(i + 11, j + 0, k + 3, Blocks.mossy_cobblestone);
        world.setBlock(i + 11, j + 0, k + 4, Blocks.cobblestone);
        world.setBlock(i + 11, j + 0, k + 5, Blocks.cobblestone);
        world.setBlock(i + 11, j + 0, k + 6, Blocks.cobblestone);
        world.setBlock(i + 11, j + 0, k + 7, Blocks.cobblestone);
        world.setBlock(i + 11, j + 0, k + 8, Blocks.cobblestone);
        world.setBlock(i + 11, j + 0, k + 9, Blocks.mossy_cobblestone);
        world.setBlock(i + 11, j + 0, k + 10, Blocks.cobblestone);
        world.setBlock(i + 11, j + 0, k + 11, Blocks.cobblestone);
        world.setBlock(i + 11, j + 0, k + 12, Blocks.mossy_cobblestone);
        world.setBlock(i + 11, j + 0, k + 13, Blocks.mossy_cobblestone);
        world.setBlock(i + 11, j + 0, k + 14, Blocks.cobblestone);
        world.setBlock(i + 11, j + 0, k + 15, Blocks.cobblestone);
        world.setBlock(i + 11, j + 0, k + 16, (Block)Blocks.stone_slab, 3, 0);
        world.setBlock(i + 11, j + 0, k + 17, Blocks.cobblestone);
        world.setBlock(i + 11, j + 0, k + 18, Blocks.cobblestone);
        world.setBlock(i + 11, j + 0, k + 19, Blocks.mossy_cobblestone);
        world.setBlock(i + 11, j + 0, k + 20, Blocks.mossy_cobblestone);
        world.setBlock(i + 11, j + 0, k + 21, Blocks.cobblestone);
        world.setBlock(i + 11, j + 0, k + 22, Blocks.cobblestone);
        world.setBlock(i + 11, j + 0, k + 23, Blocks.cobblestone);
        world.setBlock(i + 11, j + 0, k + 24, Blocks.mossy_cobblestone);
        world.setBlock(i + 11, j + 0, k + 25, (Block)Blocks.double_stone_slab, 3, 0);
        world.setBlock(i + 11, j + 0, k + 26, Blocks.cobblestone);
        world.setBlock(i + 11, j + 0, k + 27, Blocks.mossy_cobblestone);
        world.setBlock(i + 11, j + 0, k + 28, Blocks.cobblestone);
        world.setBlock(i + 11, j + 0, k + 29, Blocks.mossy_cobblestone);
        world.setBlock(i + 11, j + 0, k + 30, Blocks.cobblestone);
        world.setBlock(i + 11, j + 1, k + 2, Blocks.mossy_cobblestone);
        world.setBlock(i + 11, j + 1, k + 6, Blocks.cobblestone);
        world.setBlock(i + 11, j + 1, k + 13, (Block)Blocks.stone_slab, 3, 0);
        world.setBlock(i + 11, j + 1, k + 14, Blocks.mossy_cobblestone);
        world.setBlock(i + 11, j + 1, k + 18, Blocks.cobblestone);
        world.setBlock(i + 11, j + 1, k + 19, (Block)Blocks.stone_slab, 3, 0);
        world.setBlock(i + 11, j + 1, k + 26, Blocks.cobblestone);
        world.setBlock(i + 11, j + 1, k + 30, Blocks.mossy_cobblestone);
        world.setBlock(i + 11, j + 2, k + 2, Blocks.cobblestone);
        world.setBlock(i + 11, j + 2, k + 6, (Block)Blocks.stone_slab, 11, 0);
        world.setBlock(i + 11, j + 2, k + 26, (Block)Blocks.stone_slab, 11, 0);
        world.setBlock(i + 11, j + 2, k + 30, Blocks.cobblestone);
        world.setBlock(i + 11, j + 3, k + 6, Blocks.mossy_cobblestone);
        world.setBlock(i + 11, j + 3, k + 26, Blocks.cobblestone);
        world.setBlock(i + 11, j + 4, k + 6, Blocks.mossy_cobblestone);
        world.setBlock(i + 11, j + 4, k + 26, Blocks.cobblestone);
        world.setBlock(i + 11, j + 5, k + 6, Blocks.cobblestone);
        world.setBlock(i + 11, j + 5, k + 26, Blocks.cobblestone);
        world.setBlock(i + 11, j + 6, k + 4, Blocks.cobblestone);
        world.setBlock(i + 11, j + 6, k + 6, Blocks.cobblestone);
        world.setBlock(i + 11, j + 6, k + 26, Blocks.mossy_cobblestone);
        world.setBlock(i + 11, j + 6, k + 28, Blocks.mossy_cobblestone);
        world.setBlock(i + 11, j + 7, k + 6, Blocks.mossy_cobblestone);
        world.setBlock(i + 11, j + 7, k + 26, Blocks.cobblestone);
        world.setBlock(i + 11, j + 8, k + 6, Blocks.mossy_cobblestone);
        world.setBlock(i + 11, j + 8, k + 26, Blocks.cobblestone);
        world.setBlock(i + 11, j + 10, k + 10, Blocks.cobblestone);
        world.setBlock(i + 11, j + 10, k + 13, Blocks.cobblestone);
        world.setBlock(i + 11, j + 10, k + 16, Blocks.cobblestone);
        world.setBlock(i + 11, j + 10, k + 19, Blocks.mossy_cobblestone);
        world.setBlock(i + 11, j + 10, k + 22, Blocks.mossy_cobblestone);
        world.setBlock(i + 12, j + 0, k + 2, Blocks.mossy_cobblestone);
        world.setBlock(i + 12, j + 0, k + 3, Blocks.cobblestone);
        world.setBlock(i + 12, j + 0, k + 4, Blocks.cobblestone);
        world.setBlock(i + 12, j + 0, k + 5, Blocks.mossy_cobblestone);
        world.setBlock(i + 12, j + 0, k + 6, Blocks.mossy_cobblestone);
        world.setBlock(i + 12, j + 0, k + 8, Blocks.cobblestone);
        world.setBlock(i + 12, j + 0, k + 9, Blocks.mossy_cobblestone);
        world.setBlock(i + 12, j + 0, k + 10, Blocks.mossy_cobblestone);
        world.setBlock(i + 12, j + 0, k + 11, Blocks.mossy_cobblestone);
        world.setBlock(i + 12, j + 0, k + 12, Blocks.mossy_cobblestone);
        world.setBlock(i + 12, j + 0, k + 13, Blocks.mossy_cobblestone);
        world.setBlock(i + 12, j + 0, k + 14, Blocks.cobblestone);
        world.setBlock(i + 12, j + 0, k + 15, (Block)Blocks.stone_slab, 3, 0);
        world.setBlock(i + 12, j + 0, k + 17, (Block)Blocks.stone_slab, 3, 0);
        world.setBlock(i + 12, j + 0, k + 18, Blocks.cobblestone);
        world.setBlock(i + 12, j + 0, k + 19, Blocks.cobblestone);
        world.setBlock(i + 12, j + 0, k + 20, Blocks.mossy_cobblestone);
        world.setBlock(i + 12, j + 0, k + 21, Blocks.cobblestone);
        world.setBlock(i + 12, j + 0, k + 22, Blocks.cobblestone);
        world.setBlock(i + 12, j + 0, k + 23, (Block)Blocks.double_stone_slab, 3, 0);
        world.setBlock(i + 12, j + 0, k + 24, Blocks.glowstone);
        WorldGenWarlordDungeon.chest(world, rand, i + 12, j + 0, k + 25, "dungeonChest", 10);
        world.setBlock(i + 12, j + 0, k + 26, Blocks.mossy_cobblestone);
        world.setBlock(i + 12, j + 0, k + 27, Blocks.cobblestone);
        world.setBlock(i + 12, j + 0, k + 28, Blocks.cobblestone);
        world.setBlock(i + 12, j + 0, k + 29, Blocks.cobblestone);
        world.setBlock(i + 12, j + 0, k + 30, Blocks.mossy_cobblestone);
        world.setBlock(i + 12, j + 1, k + 2, Blocks.cobblestone);
        world.setBlock(i + 12, j + 1, k + 6, (Block)Blocks.stone_slab, 11, 0);
        world.setBlock(i + 12, j + 1, k + 7, Blocks.cobblestone);
        world.setBlock(i + 12, j + 1, k + 12, (Block)Blocks.stone_slab, 3, 0);
        world.setBlock(i + 12, j + 1, k + 13, Blocks.mossy_cobblestone);
        world.setBlock(i + 12, j + 1, k + 19, Blocks.mossy_cobblestone);
        world.setBlock(i + 12, j + 1, k + 20, (Block)Blocks.stone_slab, 3, 0);
        world.setBlock(i + 12, j + 1, k + 24, Blocks.cobblestone);
        world.setBlock(i + 12, j + 1, k + 25, Blocks.cobblestone);
        world.setBlock(i + 12, j + 1, k + 26, (Block)Blocks.stone_slab, 11, 0);
        world.setBlock(i + 12, j + 1, k + 30, Blocks.mossy_cobblestone);
        world.setBlock(i + 12, j + 2, k + 2, Blocks.cobblestone);
        world.setBlock(i + 12, j + 2, k + 7, Blocks.skull, 1, 0);
        world.setBlock(i + 12, j + 2, k + 24, Blocks.skull, 1, 0);
        world.setBlock(i + 12, j + 2, k + 30, Blocks.cobblestone);
        world.setBlock(i + 12, j + 3, k + 2, Blocks.mossy_cobblestone);
        world.setBlock(i + 12, j + 3, k + 6, (Block)Blocks.stone_slab, 3, 0);
        world.setBlock(i + 12, j + 3, k + 26, (Block)Blocks.stone_slab, 3, 0);
        world.setBlock(i + 12, j + 3, k + 30, Blocks.mossy_cobblestone);
        world.setBlock(i + 12, j + 4, k + 6, Blocks.mossy_cobblestone);
        world.setBlock(i + 12, j + 4, k + 26, Blocks.cobblestone);
        world.setBlock(i + 12, j + 5, k + 6, Blocks.cobblestone);
        world.setBlock(i + 12, j + 5, k + 26, Blocks.mossy_cobblestone);
        world.setBlock(i + 12, j + 6, k + 4, Blocks.cobblestone);
        world.setBlock(i + 12, j + 6, k + 6, Blocks.mossy_cobblestone);
        world.setBlock(i + 12, j + 6, k + 26, Blocks.mossy_cobblestone);
        world.setBlock(i + 12, j + 6, k + 28, Blocks.cobblestone);
        world.setBlock(i + 12, j + 7, k + 6, Blocks.mossy_cobblestone);
        world.setBlock(i + 12, j + 7, k + 26, Blocks.cobblestone);
        world.setBlock(i + 12, j + 8, k + 6, Blocks.mossy_cobblestone);
        world.setBlock(i + 12, j + 8, k + 26, Blocks.cobblestone);
        world.setBlock(i + 12, j + 10, k + 10, Blocks.cobblestone);
        world.setBlock(i + 12, j + 10, k + 13, Blocks.cobblestone);
        world.setBlock(i + 12, j + 10, k + 16, Blocks.cobblestone);
        world.setBlock(i + 12, j + 10, k + 19, Blocks.mossy_cobblestone);
        world.setBlock(i + 12, j + 10, k + 22, Blocks.cobblestone);
        world.setBlock(i + 13, j + 0, k + 2, Blocks.mossy_cobblestone);
        world.setBlock(i + 13, j + 0, k + 3, Blocks.cobblestone);
        world.setBlock(i + 13, j + 0, k + 4, Blocks.cobblestone);
        world.setBlock(i + 13, j + 0, k + 5, Blocks.cobblestone);
        world.setBlock(i + 13, j + 0, k + 6, Blocks.cobblestone);
        world.setBlock(i + 13, j + 0, k + 7, Blocks.mossy_cobblestone);
        world.setBlock(i + 13, j + 0, k + 8, Blocks.mossy_cobblestone);
        world.setBlock(i + 13, j + 0, k + 9, Blocks.cobblestone);
        world.setBlock(i + 13, j + 0, k + 10, Blocks.mossy_cobblestone);
        world.setBlock(i + 13, j + 0, k + 11, Blocks.mossy_cobblestone);
        world.setBlock(i + 13, j + 0, k + 12, Blocks.mossy_cobblestone);
        world.setBlock(i + 13, j + 0, k + 13, Blocks.cobblestone);
        world.setBlock(i + 13, j + 0, k + 14, Blocks.cobblestone);
        world.setBlock(i + 13, j + 0, k + 15, Blocks.cobblestone);
        world.setBlock(i + 13, j + 0, k + 16, (Block)Blocks.stone_slab, 3, 0);
        world.setBlock(i + 13, j + 0, k + 17, Blocks.cobblestone);
        world.setBlock(i + 13, j + 0, k + 18, Blocks.cobblestone);
        world.setBlock(i + 13, j + 0, k + 19, Blocks.mossy_cobblestone);
        world.setBlock(i + 13, j + 0, k + 20, Blocks.cobblestone);
        world.setBlock(i + 13, j + 0, k + 21, Blocks.mossy_cobblestone);
        world.setBlock(i + 13, j + 0, k + 22, Blocks.mossy_cobblestone);
        world.setBlock(i + 13, j + 0, k + 23, Blocks.mossy_cobblestone);
        world.setBlock(i + 13, j + 0, k + 24, Blocks.mossy_cobblestone);
        world.setBlock(i + 13, j + 0, k + 25, (Block)Blocks.double_stone_slab, 3, 0);
        world.setBlock(i + 13, j + 0, k + 26, Blocks.mossy_cobblestone);
        world.setBlock(i + 13, j + 0, k + 27, Blocks.mossy_cobblestone);
        world.setBlock(i + 13, j + 0, k + 28, Blocks.mossy_cobblestone);
        world.setBlock(i + 13, j + 0, k + 29, Blocks.cobblestone);
        world.setBlock(i + 13, j + 0, k + 30, Blocks.cobblestone);
        world.setBlock(i + 13, j + 1, k + 2, Blocks.mossy_cobblestone);
        world.setBlock(i + 13, j + 1, k + 6, Blocks.cobblestone);
        world.setBlock(i + 13, j + 1, k + 13, (Block)Blocks.stone_slab, 3, 0);
        world.setBlock(i + 13, j + 1, k + 14, Blocks.mossy_cobblestone);
        world.setBlock(i + 13, j + 1, k + 18, Blocks.mossy_cobblestone);
        world.setBlock(i + 13, j + 1, k + 19, (Block)Blocks.stone_slab, 3, 0);
        world.setBlock(i + 13, j + 1, k + 26, Blocks.mossy_cobblestone);
        world.setBlock(i + 13, j + 1, k + 30, Blocks.cobblestone);
        world.setBlock(i + 13, j + 2, k + 2, Blocks.cobblestone);
        world.setBlock(i + 13, j + 2, k + 6, (Block)Blocks.stone_slab, 11, 0);
        world.setBlock(i + 13, j + 2, k + 26, (Block)Blocks.stone_slab, 11, 0);
        world.setBlock(i + 13, j + 2, k + 30, Blocks.cobblestone);
        world.setBlock(i + 13, j + 3, k + 6, Blocks.cobblestone);
        world.setBlock(i + 13, j + 3, k + 26, Blocks.mossy_cobblestone);
        world.setBlock(i + 13, j + 4, k + 6, Blocks.mossy_cobblestone);
        world.setBlock(i + 13, j + 4, k + 26, Blocks.cobblestone);
        world.setBlock(i + 13, j + 5, k + 6, Blocks.mossy_cobblestone);
        world.setBlock(i + 13, j + 5, k + 26, Blocks.mossy_cobblestone);
        world.setBlock(i + 13, j + 6, k + 4, Blocks.cobblestone);
        world.setBlock(i + 13, j + 6, k + 6, Blocks.mossy_cobblestone);
        world.setBlock(i + 13, j + 6, k + 26, Blocks.cobblestone);
        world.setBlock(i + 13, j + 6, k + 28, Blocks.mossy_cobblestone);
        world.setBlock(i + 13, j + 7, k + 6, Blocks.mossy_cobblestone);
        world.setBlock(i + 13, j + 7, k + 26, Blocks.mossy_cobblestone);
        world.setBlock(i + 13, j + 8, k + 6, Blocks.mossy_cobblestone);
        world.setBlock(i + 13, j + 8, k + 26, Blocks.mossy_cobblestone);
        world.setBlock(i + 13, j + 10, k + 10, Blocks.cobblestone);
        world.setBlock(i + 13, j + 10, k + 13, Blocks.mossy_cobblestone);
        world.setBlock(i + 13, j + 10, k + 16, Blocks.mossy_cobblestone);
        world.setBlock(i + 13, j + 10, k + 19, Blocks.cobblestone);
        world.setBlock(i + 13, j + 10, k + 22, Blocks.cobblestone);
        world.setBlock(i + 14, j + 0, k + 2, Blocks.mossy_cobblestone);
        world.setBlock(i + 14, j + 0, k + 3, Blocks.cobblestone);
        world.setBlock(i + 14, j + 0, k + 4, Blocks.mossy_cobblestone);
        world.setBlock(i + 14, j + 0, k + 5, Blocks.mossy_cobblestone);
        world.setBlock(i + 14, j + 0, k + 6, Blocks.mossy_cobblestone);
        world.setBlock(i + 14, j + 0, k + 7, Blocks.mossy_cobblestone);
        world.setBlock(i + 14, j + 0, k + 8, Blocks.mossy_cobblestone);
        world.setBlock(i + 14, j + 0, k + 9, Blocks.cobblestone);
        world.setBlock(i + 14, j + 0, k + 10, Blocks.cobblestone);
        world.setBlock(i + 14, j + 0, k + 11, Blocks.mossy_cobblestone);
        world.setBlock(i + 14, j + 0, k + 12, Blocks.mossy_cobblestone);
        world.setBlock(i + 14, j + 0, k + 13, Blocks.mossy_cobblestone);
        world.setBlock(i + 14, j + 0, k + 14, Blocks.mossy_cobblestone);
        world.setBlock(i + 14, j + 0, k + 15, Blocks.cobblestone);
        world.setBlock(i + 14, j + 0, k + 16, Blocks.cobblestone);
        world.setBlock(i + 14, j + 0, k + 17, Blocks.cobblestone);
        world.setBlock(i + 14, j + 0, k + 18, Blocks.mossy_cobblestone);
        world.setBlock(i + 14, j + 0, k + 19, Blocks.cobblestone);
        world.setBlock(i + 14, j + 0, k + 20, Blocks.mossy_cobblestone);
        world.setBlock(i + 14, j + 0, k + 21, Blocks.mossy_cobblestone);
        world.setBlock(i + 14, j + 0, k + 22, Blocks.mossy_cobblestone);
        world.setBlock(i + 14, j + 0, k + 23, Blocks.mossy_cobblestone);
        world.setBlock(i + 14, j + 0, k + 24, Blocks.cobblestone);
        world.setBlock(i + 14, j + 0, k + 25, Blocks.cobblestone);
        world.setBlock(i + 14, j + 0, k + 26, Blocks.cobblestone);
        world.setBlock(i + 14, j + 0, k + 27, Blocks.cobblestone);
        world.setBlock(i + 14, j + 0, k + 28, Blocks.cobblestone);
        world.setBlock(i + 14, j + 0, k + 29, Blocks.cobblestone);
        world.setBlock(i + 14, j + 0, k + 30, Blocks.mossy_cobblestone);
        world.setBlock(i + 14, j + 1, k + 2, Blocks.mossy_cobblestone);
        world.setBlock(i + 14, j + 1, k + 5, Blocks.mossy_cobblestone);
        world.setBlock(i + 14, j + 1, k + 6, Blocks.mossy_cobblestone);
        world.setBlock(i + 14, j + 1, k + 14, (Block)Blocks.stone_slab, 3, 0);
        world.setBlock(i + 14, j + 1, k + 15, Blocks.mossy_cobblestone);
        world.setBlock(i + 14, j + 1, k + 17, Blocks.cobblestone);
        world.setBlock(i + 14, j + 1, k + 18, (Block)Blocks.stone_slab, 3, 0);
        world.setBlock(i + 14, j + 1, k + 26, Blocks.cobblestone);
        world.setBlock(i + 14, j + 1, k + 27, Blocks.cobblestone);
        world.setBlock(i + 14, j + 1, k + 30, Blocks.cobblestone);
        world.setBlock(i + 14, j + 2, k + 2, Blocks.cobblestone);
        world.setBlock(i + 14, j + 2, k + 5, Blocks.cobblestone);
        world.setBlock(i + 14, j + 2, k + 6, Blocks.cobblestone);
        world.setBlock(i + 14, j + 2, k + 26, Blocks.cobblestone);
        world.setBlock(i + 14, j + 2, k + 27, Blocks.cobblestone);
        world.setBlock(i + 14, j + 2, k + 30, Blocks.cobblestone);
        world.setBlock(i + 14, j + 3, k + 2, (Block)Blocks.stone_slab, 3, 0);
        world.setBlock(i + 14, j + 3, k + 5, Blocks.cobblestone);
        world.setBlock(i + 14, j + 3, k + 6, Blocks.cobblestone);
        world.setBlock(i + 14, j + 3, k + 26, Blocks.cobblestone);
        world.setBlock(i + 14, j + 3, k + 27, Blocks.mossy_cobblestone);
        world.setBlock(i + 14, j + 3, k + 30, (Block)Blocks.stone_slab, 3, 0);
        world.setBlock(i + 14, j + 4, k + 5, Blocks.cobblestone);
        world.setBlock(i + 14, j + 4, k + 6, Blocks.mossy_cobblestone);
        world.setBlock(i + 14, j + 4, k + 7, Blocks.cobblestone);
        world.setBlock(i + 14, j + 4, k + 25, Blocks.cobblestone);
        world.setBlock(i + 14, j + 4, k + 26, Blocks.cobblestone);
        world.setBlock(i + 14, j + 4, k + 27, Blocks.mossy_cobblestone);
        world.setBlock(i + 14, j + 5, k + 4, Blocks.mossy_cobblestone);
        world.setBlock(i + 14, j + 5, k + 5, Blocks.mossy_cobblestone);
        world.setBlock(i + 14, j + 5, k + 6, Blocks.cobblestone);
        world.setBlock(i + 14, j + 5, k + 7, Blocks.cobblestone);
        world.setBlock(i + 14, j + 5, k + 8, Blocks.cobblestone);
        world.setBlock(i + 14, j + 5, k + 24, Blocks.mossy_cobblestone);
        world.setBlock(i + 14, j + 5, k + 25, Blocks.cobblestone);
        world.setBlock(i + 14, j + 5, k + 26, Blocks.mossy_cobblestone);
        world.setBlock(i + 14, j + 5, k + 27, Blocks.cobblestone);
        world.setBlock(i + 14, j + 5, k + 28, Blocks.mossy_cobblestone);
        world.setBlock(i + 14, j + 6, k + 3, Blocks.cobblestone);
        world.setBlock(i + 14, j + 6, k + 4, Blocks.cobblestone);
        world.setBlock(i + 14, j + 6, k + 5, Blocks.mossy_cobblestone);
        world.setBlock(i + 14, j + 6, k + 6, Blocks.cobblestone);
        world.setBlock(i + 14, j + 6, k + 7, Blocks.mossy_cobblestone);
        world.setBlock(i + 14, j + 6, k + 8, Blocks.cobblestone);
        world.setBlock(i + 14, j + 6, k + 24, Blocks.mossy_cobblestone);
        world.setBlock(i + 14, j + 6, k + 25, Blocks.mossy_cobblestone);
        world.setBlock(i + 14, j + 6, k + 26, Blocks.mossy_cobblestone);
        world.setBlock(i + 14, j + 6, k + 27, Blocks.cobblestone);
        world.setBlock(i + 14, j + 6, k + 28, Blocks.mossy_cobblestone);
        world.setBlock(i + 14, j + 6, k + 29, Blocks.cobblestone);
        world.setBlock(i + 14, j + 7, k + 5, Blocks.mossy_cobblestone);
        world.setBlock(i + 14, j + 7, k + 6, Blocks.mossy_cobblestone);
        world.setBlock(i + 14, j + 7, k + 7, Blocks.cobblestone);
        world.setBlock(i + 14, j + 7, k + 8, Blocks.mossy_cobblestone);
        world.setBlock(i + 14, j + 7, k + 9, Blocks.mossy_cobblestone);
        world.setBlock(i + 14, j + 7, k + 23, Blocks.mossy_cobblestone);
        world.setBlock(i + 14, j + 7, k + 24, Blocks.mossy_cobblestone);
        world.setBlock(i + 14, j + 7, k + 25, Blocks.mossy_cobblestone);
        world.setBlock(i + 14, j + 7, k + 26, Blocks.mossy_cobblestone);
        world.setBlock(i + 14, j + 7, k + 27, Blocks.mossy_cobblestone);
        world.setBlock(i + 14, j + 8, k + 6, Blocks.cobblestone);
        world.setBlock(i + 14, j + 8, k + 7, Blocks.mossy_cobblestone);
        world.setBlock(i + 14, j + 8, k + 8, Blocks.mossy_cobblestone);
        world.setBlock(i + 14, j + 8, k + 9, Blocks.cobblestone);
        world.setBlock(i + 14, j + 8, k + 10, Blocks.cobblestone);
        world.setBlock(i + 14, j + 8, k + 11, Blocks.cobblestone);
        world.setBlock(i + 14, j + 8, k + 12, Blocks.cobblestone);
        world.setBlock(i + 14, j + 8, k + 13, Blocks.mossy_cobblestone);
        world.setBlock(i + 14, j + 8, k + 14, Blocks.mossy_cobblestone);
        world.setBlock(i + 14, j + 8, k + 15, Blocks.cobblestone);
        world.setBlock(i + 14, j + 8, k + 16, Blocks.mossy_cobblestone);
        world.setBlock(i + 14, j + 8, k + 17, Blocks.mossy_cobblestone);
        world.setBlock(i + 14, j + 8, k + 18, Blocks.cobblestone);
        world.setBlock(i + 14, j + 8, k + 19, Blocks.cobblestone);
        world.setBlock(i + 14, j + 8, k + 20, Blocks.mossy_cobblestone);
        world.setBlock(i + 14, j + 8, k + 21, Blocks.cobblestone);
        world.setBlock(i + 14, j + 8, k + 22, Blocks.mossy_cobblestone);
        world.setBlock(i + 14, j + 8, k + 23, Blocks.mossy_cobblestone);
        world.setBlock(i + 14, j + 8, k + 24, Blocks.cobblestone);
        world.setBlock(i + 14, j + 8, k + 25, Blocks.mossy_cobblestone);
        world.setBlock(i + 14, j + 8, k + 26, Blocks.mossy_cobblestone);
        world.setBlock(i + 14, j + 9, k + 10, Blocks.cobblestone);
        world.setBlock(i + 14, j + 9, k + 13, Blocks.cobblestone);
        world.setBlock(i + 14, j + 9, k + 16, Blocks.mossy_cobblestone);
        world.setBlock(i + 14, j + 9, k + 19, Blocks.mossy_cobblestone);
        world.setBlock(i + 14, j + 9, k + 22, Blocks.cobblestone);
        world.setBlock(i + 15, j + 0, k + 2, Blocks.mossy_cobblestone);
        world.setBlock(i + 15, j + 0, k + 3, Blocks.mossy_cobblestone);
        world.setBlock(i + 15, j + 0, k + 4, Blocks.mossy_cobblestone);
        world.setBlock(i + 15, j + 0, k + 5, Blocks.mossy_cobblestone);
        world.setBlock(i + 15, j + 0, k + 6, Blocks.mossy_cobblestone);
        world.setBlock(i + 15, j + 0, k + 7, Blocks.cobblestone);
        world.setBlock(i + 15, j + 0, k + 8, Blocks.mossy_cobblestone);
        world.setBlock(i + 15, j + 0, k + 9, Blocks.mossy_cobblestone);
        world.setBlock(i + 15, j + 0, k + 10, Blocks.cobblestone);
        world.setBlock(i + 15, j + 0, k + 11, Blocks.cobblestone);
        world.setBlock(i + 15, j + 0, k + 12, Blocks.mossy_cobblestone);
        world.setBlock(i + 15, j + 0, k + 13, Blocks.mossy_cobblestone);
        world.setBlock(i + 15, j + 0, k + 14, Blocks.mossy_cobblestone);
        world.setBlock(i + 15, j + 0, k + 15, Blocks.mossy_cobblestone);
        world.setBlock(i + 15, j + 0, k + 16, Blocks.mossy_cobblestone);
        world.setBlock(i + 15, j + 0, k + 17, Blocks.mossy_cobblestone);
        world.setBlock(i + 15, j + 0, k + 18, Blocks.mossy_cobblestone);
        world.setBlock(i + 15, j + 0, k + 19, Blocks.mossy_cobblestone);
        world.setBlock(i + 15, j + 0, k + 20, Blocks.cobblestone);
        world.setBlock(i + 15, j + 0, k + 21, Blocks.mossy_cobblestone);
        world.setBlock(i + 15, j + 0, k + 22, Blocks.cobblestone);
        world.setBlock(i + 15, j + 0, k + 23, Blocks.mossy_cobblestone);
        world.setBlock(i + 15, j + 0, k + 24, Blocks.mossy_cobblestone);
        world.setBlock(i + 15, j + 0, k + 25, Blocks.cobblestone);
        world.setBlock(i + 15, j + 0, k + 26, Blocks.cobblestone);
        world.setBlock(i + 15, j + 0, k + 27, Blocks.cobblestone);
        world.setBlock(i + 15, j + 0, k + 28, Blocks.cobblestone);
        world.setBlock(i + 15, j + 0, k + 29, Blocks.cobblestone);
        world.setBlock(i + 15, j + 0, k + 30, Blocks.cobblestone);
        world.setBlock(i + 15, j + 1, k + 2, Blocks.mossy_cobblestone);
        world.setBlock(i + 15, j + 1, k + 6, Blocks.cobblestone);
        world.setBlock(i + 15, j + 1, k + 15, (Block)Blocks.stone_slab, 3, 0);
        world.setBlock(i + 15, j + 1, k + 16, Blocks.cobblestone);
        world.setBlock(i + 15, j + 1, k + 17, (Block)Blocks.stone_slab, 3, 0);
        world.setBlock(i + 15, j + 1, k + 26, Blocks.cobblestone);
        world.setBlock(i + 15, j + 1, k + 30, Blocks.cobblestone);
        world.setBlock(i + 15, j + 2, k + 2, Blocks.cobblestone);
        world.setBlock(i + 15, j + 2, k + 6, (Block)Blocks.stone_slab, 11, 0);
        world.setBlock(i + 15, j + 2, k + 26, (Block)Blocks.stone_slab, 11, 0);
        world.setBlock(i + 15, j + 2, k + 30, Blocks.cobblestone);
        world.setBlock(i + 15, j + 3, k + 6, Blocks.cobblestone);
        world.setBlock(i + 15, j + 3, k + 26, Blocks.cobblestone);
        world.setBlock(i + 15, j + 4, k + 6, Blocks.mossy_cobblestone);
        world.setBlock(i + 15, j + 4, k + 26, Blocks.mossy_cobblestone);
        world.setBlock(i + 15, j + 5, k + 6, Blocks.cobblestone);
        world.setBlock(i + 15, j + 5, k + 26, Blocks.mossy_cobblestone);
        world.setBlock(i + 15, j + 6, k + 4, Blocks.cobblestone);
        world.setBlock(i + 15, j + 6, k + 6, Blocks.mossy_cobblestone);
        world.setBlock(i + 15, j + 6, k + 26, Blocks.cobblestone);
        world.setBlock(i + 15, j + 6, k + 28, Blocks.mossy_cobblestone);
        world.setBlock(i + 15, j + 7, k + 6, Blocks.mossy_cobblestone);
        world.setBlock(i + 15, j + 7, k + 10, Blocks.mossy_cobblestone);
        world.setBlock(i + 15, j + 7, k + 19, Blocks.mossy_cobblestone);
        world.setBlock(i + 15, j + 7, k + 22, Blocks.cobblestone);
        world.setBlock(i + 15, j + 7, k + 26, Blocks.cobblestone);
        world.setBlock(i + 15, j + 8, k + 6, Blocks.mossy_cobblestone);
        world.setBlock(i + 15, j + 8, k + 10, Blocks.mossy_cobblestone);
        world.setBlock(i + 15, j + 8, k + 19, Blocks.mossy_cobblestone);
        world.setBlock(i + 15, j + 8, k + 22, Blocks.mossy_cobblestone);
        world.setBlock(i + 15, j + 8, k + 26, Blocks.mossy_cobblestone);
        world.setBlock(i + 16, j + 0, k + 2, Blocks.mossy_cobblestone);
        world.setBlock(i + 16, j + 0, k + 3, Blocks.mossy_cobblestone);
        world.setBlock(i + 16, j + 0, k + 4, Blocks.mossy_cobblestone);
        world.setBlock(i + 16, j + 0, k + 5, Blocks.mossy_cobblestone);
        world.setBlock(i + 16, j + 0, k + 6, Blocks.cobblestone);
        world.setBlock(i + 16, j + 0, k + 7, Blocks.mossy_cobblestone);
        world.setBlock(i + 16, j + 0, k + 8, Blocks.mossy_cobblestone);
        world.setBlock(i + 16, j + 0, k + 9, Blocks.cobblestone);
        world.setBlock(i + 16, j + 0, k + 10, Blocks.cobblestone);
        world.setBlock(i + 16, j + 0, k + 11, Blocks.mossy_cobblestone);
        world.setBlock(i + 16, j + 0, k + 12, Blocks.cobblestone);
        world.setBlock(i + 16, j + 0, k + 13, Blocks.cobblestone);
        world.setBlock(i + 16, j + 0, k + 14, Blocks.mossy_cobblestone);
        world.setBlock(i + 16, j + 0, k + 15, Blocks.mossy_cobblestone);
        world.setBlock(i + 16, j + 0, k + 16, Blocks.mossy_cobblestone);
        world.setBlock(i + 16, j + 0, k + 17, Blocks.cobblestone);
        world.setBlock(i + 16, j + 0, k + 18, Blocks.cobblestone);
        world.setBlock(i + 16, j + 0, k + 19, Blocks.mossy_cobblestone);
        world.setBlock(i + 16, j + 0, k + 20, Blocks.mossy_cobblestone);
        world.setBlock(i + 16, j + 0, k + 21, Blocks.mossy_cobblestone);
        world.setBlock(i + 16, j + 0, k + 22, Blocks.cobblestone);
        world.setBlock(i + 16, j + 0, k + 23, Blocks.mossy_cobblestone);
        world.setBlock(i + 16, j + 0, k + 24, Blocks.cobblestone);
        world.setBlock(i + 16, j + 0, k + 25, Blocks.cobblestone);
        world.setBlock(i + 16, j + 0, k + 26, Blocks.cobblestone);
        world.setBlock(i + 16, j + 0, k + 27, Blocks.cobblestone);
        world.setBlock(i + 16, j + 0, k + 28, Blocks.cobblestone);
        world.setBlock(i + 16, j + 0, k + 29, Blocks.mossy_cobblestone);
        world.setBlock(i + 16, j + 0, k + 30, Blocks.cobblestone);
        world.setBlock(i + 16, j + 1, k + 2, Blocks.mossy_cobblestone);
        world.setBlock(i + 16, j + 1, k + 6, Blocks.cobblestone);
        world.setBlock(i + 16, j + 1, k + 16, (Block)Blocks.stone_slab, 3, 0);
        world.setBlock(i + 16, j + 1, k + 26, Blocks.cobblestone);
        world.setBlock(i + 16, j + 1, k + 30, Blocks.cobblestone);
        world.setBlock(i + 16, j + 2, k + 2, Blocks.cobblestone);
        world.setBlock(i + 16, j + 2, k + 6, (Block)Blocks.stone_slab, 11, 0);
        world.setBlock(i + 16, j + 2, k + 26, (Block)Blocks.stone_slab, 11, 0);
        world.setBlock(i + 16, j + 2, k + 30, Blocks.cobblestone);
        world.setBlock(i + 16, j + 3, k + 2, Blocks.mossy_cobblestone);
        world.setBlock(i + 16, j + 3, k + 6, Blocks.mossy_cobblestone);
        world.setBlock(i + 16, j + 3, k + 26, Blocks.cobblestone);
        world.setBlock(i + 16, j + 3, k + 30, Blocks.mossy_cobblestone);
        world.setBlock(i + 16, j + 4, k + 6, Blocks.cobblestone);
        world.setBlock(i + 16, j + 4, k + 26, Blocks.mossy_cobblestone);
        world.setBlock(i + 16, j + 5, k + 6, Blocks.mossy_cobblestone);
        world.setBlock(i + 16, j + 5, k + 7, Blocks.mossy_cobblestone);
        world.setBlock(i + 16, j + 5, k + 10, Blocks.cobblestone);
        world.setBlock(i + 16, j + 5, k + 19, Blocks.mossy_cobblestone);
        world.setBlock(i + 16, j + 5, k + 22, Blocks.mossy_cobblestone);
        world.setBlock(i + 16, j + 5, k + 25, Blocks.mossy_cobblestone);
        world.setBlock(i + 16, j + 5, k + 26, Blocks.mossy_cobblestone);
        world.setBlock(i + 16, j + 6, k + 4, Blocks.mossy_cobblestone);
        world.setBlock(i + 16, j + 6, k + 6, Blocks.mossy_cobblestone);
        world.setBlock(i + 16, j + 6, k + 7, Blocks.cobblestone);
        world.setBlock(i + 16, j + 6, k + 10, Blocks.cobblestone);
        world.setBlock(i + 16, j + 6, k + 19, Blocks.cobblestone);
        world.setBlock(i + 16, j + 6, k + 22, Blocks.cobblestone);
        world.setBlock(i + 16, j + 6, k + 25, Blocks.mossy_cobblestone);
        world.setBlock(i + 16, j + 6, k + 26, Blocks.mossy_cobblestone);
        world.setBlock(i + 16, j + 6, k + 28, Blocks.mossy_cobblestone);
        world.setBlock(i + 16, j + 7, k + 6, Blocks.mossy_cobblestone);
        world.setBlock(i + 16, j + 7, k + 7, Blocks.cobblestone);
        world.setBlock(i + 16, j + 7, k + 10, Blocks.mossy_cobblestone);
        world.setBlock(i + 16, j + 7, k + 19, Blocks.cobblestone);
        world.setBlock(i + 16, j + 7, k + 22, Blocks.mossy_cobblestone);
        world.setBlock(i + 16, j + 7, k + 25, Blocks.mossy_cobblestone);
        world.setBlock(i + 16, j + 7, k + 26, Blocks.cobblestone);
        world.setBlock(i + 16, j + 8, k + 6, Blocks.cobblestone);
        world.setBlock(i + 16, j + 8, k + 7, Blocks.cobblestone);
        world.setBlock(i + 16, j + 8, k + 8, Blocks.cobblestone);
        world.setBlock(i + 16, j + 8, k + 9, Blocks.mossy_cobblestone);
        world.setBlock(i + 16, j + 8, k + 10, Blocks.cobblestone);
        world.setBlock(i + 16, j + 8, k + 11, Blocks.mossy_cobblestone);
        world.setBlock(i + 16, j + 8, k + 12, Blocks.cobblestone);
        world.setBlock(i + 16, j + 8, k + 13, Blocks.mossy_cobblestone);
        world.setBlock(i + 16, j + 8, k + 14, Blocks.mossy_cobblestone);
        world.setBlock(i + 16, j + 8, k + 15, Blocks.cobblestone);
        world.setBlock(i + 16, j + 8, k + 16, Blocks.mossy_cobblestone);
        world.setBlock(i + 16, j + 8, k + 17, Blocks.cobblestone);
        world.setBlock(i + 16, j + 8, k + 18, Blocks.cobblestone);
        world.setBlock(i + 16, j + 8, k + 19, Blocks.mossy_cobblestone);
        world.setBlock(i + 16, j + 8, k + 20, Blocks.cobblestone);
        world.setBlock(i + 16, j + 8, k + 21, Blocks.cobblestone);
        world.setBlock(i + 16, j + 8, k + 22, Blocks.cobblestone);
        world.setBlock(i + 16, j + 8, k + 23, Blocks.cobblestone);
        world.setBlock(i + 16, j + 8, k + 24, Blocks.mossy_cobblestone);
        world.setBlock(i + 16, j + 8, k + 25, Blocks.cobblestone);
        world.setBlock(i + 16, j + 8, k + 26, Blocks.mossy_cobblestone);
        world.setBlock(i + 16, j + 9, k + 8, Blocks.mossy_cobblestone);
        world.setBlock(i + 16, j + 9, k + 10, Blocks.mossy_cobblestone);
        world.setBlock(i + 16, j + 9, k + 19, Blocks.mossy_cobblestone);
        world.setBlock(i + 16, j + 9, k + 22, Blocks.mossy_cobblestone);
        world.setBlock(i + 16, j + 9, k + 24, Blocks.mossy_cobblestone);
        world.setBlock(i + 17, j + 0, k + 2, Blocks.cobblestone);
        world.setBlock(i + 17, j + 0, k + 3, Blocks.mossy_cobblestone);
        world.setBlock(i + 17, j + 0, k + 4, Blocks.mossy_cobblestone);
        world.setBlock(i + 17, j + 0, k + 5, Blocks.cobblestone);
        world.setBlock(i + 17, j + 0, k + 6, Blocks.mossy_cobblestone);
        world.setBlock(i + 17, j + 0, k + 7, Blocks.cobblestone);
        world.setBlock(i + 17, j + 0, k + 8, Blocks.cobblestone);
        world.setBlock(i + 17, j + 0, k + 9, Blocks.cobblestone);
        world.setBlock(i + 17, j + 0, k + 10, Blocks.cobblestone);
        world.setBlock(i + 17, j + 0, k + 11, Blocks.cobblestone);
        world.setBlock(i + 17, j + 0, k + 12, Blocks.mossy_cobblestone);
        world.setBlock(i + 17, j + 0, k + 13, Blocks.mossy_cobblestone);
        world.setBlock(i + 17, j + 0, k + 14, Blocks.mossy_cobblestone);
        world.setBlock(i + 17, j + 0, k + 15, Blocks.mossy_cobblestone);
        world.setBlock(i + 17, j + 0, k + 16, Blocks.cobblestone);
        world.setBlock(i + 17, j + 0, k + 17, Blocks.cobblestone);
        world.setBlock(i + 17, j + 0, k + 18, Blocks.cobblestone);
        world.setBlock(i + 17, j + 0, k + 19, Blocks.mossy_cobblestone);
        world.setBlock(i + 17, j + 0, k + 20, Blocks.cobblestone);
        world.setBlock(i + 17, j + 0, k + 21, Blocks.cobblestone);
        world.setBlock(i + 17, j + 0, k + 22, Blocks.mossy_cobblestone);
        world.setBlock(i + 17, j + 0, k + 23, Blocks.mossy_cobblestone);
        world.setBlock(i + 17, j + 0, k + 24, Blocks.cobblestone);
        world.setBlock(i + 17, j + 0, k + 25, Blocks.mossy_cobblestone);
        world.setBlock(i + 17, j + 0, k + 26, Blocks.cobblestone);
        world.setBlock(i + 17, j + 0, k + 27, Blocks.mossy_cobblestone);
        world.setBlock(i + 17, j + 0, k + 28, Blocks.mossy_cobblestone);
        world.setBlock(i + 17, j + 0, k + 29, Blocks.cobblestone);
        world.setBlock(i + 17, j + 0, k + 30, Blocks.mossy_cobblestone);
        world.setBlock(i + 17, j + 1, k + 2, Blocks.mossy_cobblestone);
        world.setBlock(i + 17, j + 1, k + 5, Blocks.cobblestone);
        world.setBlock(i + 17, j + 1, k + 6, Blocks.cobblestone);
        world.setBlock(i + 17, j + 1, k + 25, Blocks.skull, 1, 0);
        world.setBlock(i + 17, j + 1, k + 26, Blocks.cobblestone);
        world.setBlock(i + 17, j + 1, k + 27, Blocks.mossy_cobblestone);
        world.setBlock(i + 17, j + 1, k + 30, Blocks.cobblestone);
        world.setBlock(i + 17, j + 2, k + 2, Blocks.cobblestone);
        world.setBlock(i + 17, j + 2, k + 5, Blocks.cobblestone);
        world.setBlock(i + 17, j + 2, k + 6, Blocks.cobblestone);
        world.setBlock(i + 17, j + 2, k + 26, Blocks.cobblestone);
        world.setBlock(i + 17, j + 2, k + 27, Blocks.cobblestone);
        world.setBlock(i + 17, j + 2, k + 30, Blocks.mossy_cobblestone);
        world.setBlock(i + 17, j + 3, k + 5, Blocks.cobblestone);
        world.setBlock(i + 17, j + 3, k + 6, Blocks.mossy_cobblestone);
        world.setBlock(i + 17, j + 3, k + 26, Blocks.cobblestone);
        world.setBlock(i + 17, j + 3, k + 27, Blocks.mossy_cobblestone);
        world.setBlock(i + 17, j + 4, k + 5, Blocks.mossy_cobblestone);
        world.setBlock(i + 17, j + 4, k + 6, Blocks.mossy_cobblestone);
        world.setBlock(i + 17, j + 4, k + 7, Blocks.cobblestone);
        world.setBlock(i + 17, j + 4, k + 10, Blocks.cobblestone);
        world.setBlock(i + 17, j + 4, k + 19, Blocks.mossy_cobblestone);
        world.setBlock(i + 17, j + 4, k + 22, Blocks.cobblestone);
        world.setBlock(i + 17, j + 4, k + 25, Blocks.mossy_cobblestone);
        world.setBlock(i + 17, j + 4, k + 26, Blocks.cobblestone);
        world.setBlock(i + 17, j + 4, k + 27, Blocks.cobblestone);
        world.setBlock(i + 17, j + 5, k + 4, Blocks.mossy_cobblestone);
        world.setBlock(i + 17, j + 5, k + 5, Blocks.cobblestone);
        world.setBlock(i + 17, j + 5, k + 6, Blocks.cobblestone);
        world.setBlock(i + 17, j + 5, k + 7, Blocks.mossy_cobblestone);
        world.setBlock(i + 17, j + 5, k + 8, Blocks.mossy_cobblestone);
        world.setBlock(i + 17, j + 5, k + 10, Blocks.cobblestone);
        world.setBlock(i + 17, j + 5, k + 19, Blocks.cobblestone);
        world.setBlock(i + 17, j + 5, k + 22, Blocks.cobblestone);
        world.setBlock(i + 17, j + 5, k + 24, Blocks.mossy_cobblestone);
        world.setBlock(i + 17, j + 5, k + 25, Blocks.mossy_cobblestone);
        world.setBlock(i + 17, j + 5, k + 26, Blocks.mossy_cobblestone);
        world.setBlock(i + 17, j + 5, k + 27, Blocks.mossy_cobblestone);
        world.setBlock(i + 17, j + 5, k + 28, Blocks.mossy_cobblestone);
        world.setBlock(i + 17, j + 6, k + 3, Blocks.cobblestone);
        world.setBlock(i + 17, j + 6, k + 4, Blocks.mossy_cobblestone);
        world.setBlock(i + 17, j + 6, k + 5, Blocks.mossy_cobblestone);
        world.setBlock(i + 17, j + 6, k + 6, Blocks.cobblestone);
        world.setBlock(i + 17, j + 6, k + 7, Blocks.cobblestone);
        world.setBlock(i + 17, j + 6, k + 8, Blocks.mossy_cobblestone);
        world.setBlock(i + 17, j + 6, k + 10, Blocks.mossy_cobblestone);
        world.setBlock(i + 17, j + 6, k + 19, Blocks.cobblestone);
