

package com.gibby.dungeon.gen;

import net.minecraft.world.gen.feature.*;
import net.minecraft.world.*;
import java.util.*;
import net.minecraft.init.*;
import com.gibby.dungeon.*;

public class WorldGenTallNetherRuins extends WorldGenerator
{
    public boolean generate(final World world, final Random rand, final int i, final int j, final int k) {
        if (world.getBlock(i, j, k) != Blocks.netherrack || world.getBlock(i + 27, j, k + 18) != Blocks.netherrack || world.getBlock(i, j + 1, k) != Blocks.air || world.getBlock(i + 27, j + 1, k + 18) != Blocks.air || world.getBlock(i, j + 30, k) != Blocks.air || world.getBlock(i + 27, j + 30, k + 18) != Blocks.air) {
            return false;
        }
        world.setBlock(i + 0, j + 0, k + 0, Blocks.netherrack);
        world.setBlock(i + 0, j + 0, k + 1, Blocks.netherrack);
        world.setBlock(i + 0, j + 0, k + 2, Blocks.netherrack);
        world.setBlock(i + 0, j + 0, k + 3, Blocks.netherrack);
        world.setBlock(i + 0, j + 0, k + 4, Blocks.netherrack);
        world.setBlock(i + 0, j + 0, k + 5, Blocks.netherrack);
        world.setBlock(i + 0, j + 0, k + 6, Blocks.netherrack);
        world.setBlock(i + 0, j + 0, k + 7, Blocks.netherrack);
        world.setBlock(i + 0, j + 0, k + 8, Blocks.netherrack);
        world.setBlock(i + 0, j + 0, k + 9, Blocks.netherrack);
        world.setBlock(i + 0, j + 0, k + 10, Blocks.netherrack);
        world.setBlock(i + 0, j + 0, k + 11, Blocks.netherrack);
        world.setBlock(i + 0, j + 0, k + 12, Blocks.netherrack);
        world.setBlock(i + 0, j + 0, k + 13, Blocks.netherrack);
        world.setBlock(i + 0, j + 0, k + 14, Blocks.netherrack);
        world.setBlock(i + 0, j + 0, k + 15, Blocks.netherrack);
        world.setBlock(i + 0, j + 0, k + 16, Blocks.netherrack);
        world.setBlock(i + 0, j + 0, k + 17, Blocks.netherrack);
        world.setBlock(i + 0, j + 0, k + 18, Blocks.netherrack);
        world.setBlock(i + 0, j + 0, k + 19, Blocks.netherrack);
        world.setBlock(i + 0, j + 0, k + 20, Blocks.netherrack);
        world.setBlock(i + 0, j + 0, k + 21, Blocks.netherrack);
        world.setBlock(i + 0, j + 0, k + 22, Blocks.netherrack);
        world.setBlock(i + 0, j + 0, k + 23, Blocks.netherrack);
        world.setBlock(i + 0, j + 0, k + 24, Blocks.netherrack);
        world.setBlock(i + 0, j + 0, k + 25, Blocks.netherrack);
        world.setBlock(i + 1, j + 0, k + 0, Blocks.netherrack);
        world.setBlock(i + 1, j + 0, k + 1, Blocks.netherrack);
        world.setBlock(i + 1, j + 0, k + 2, Blocks.netherrack);
        world.setBlock(i + 1, j + 0, k + 3, Blocks.netherrack);
        world.setBlock(i + 1, j + 0, k + 4, Blocks.netherrack);
        world.setBlock(i + 1, j + 0, k + 5, Blocks.netherrack);
        world.setBlock(i + 1, j + 0, k + 6, Blocks.netherrack);
        world.setBlock(i + 1, j + 0, k + 7, Blocks.netherrack);
        world.setBlock(i + 1, j + 0, k + 8, Blocks.netherrack);
        world.setBlock(i + 1, j + 0, k + 9, Blocks.netherrack);
        world.setBlock(i + 1, j + 0, k + 10, Blocks.netherrack);
        world.setBlock(i + 1, j + 0, k + 11, Blocks.netherrack);
        world.setBlock(i + 1, j + 0, k + 12, Blocks.netherrack);
        world.setBlock(i + 1, j + 0, k + 13, Blocks.netherrack);
        world.setBlock(i + 1, j + 0, k + 14, Blocks.netherrack);
        world.setBlock(i + 1, j + 0, k + 15, Blocks.netherrack);
        world.setBlock(i + 1, j + 0, k + 16, Blocks.netherrack);
        world.setBlock(i + 1, j + 0, k + 17, Blocks.netherrack);
        world.setBlock(i + 1, j + 0, k + 18, Blocks.netherrack);
        world.setBlock(i + 1, j + 0, k + 19, Blocks.netherrack);
        world.setBlock(i + 1, j + 0, k + 20, Blocks.netherrack);
        world.setBlock(i + 1, j + 0, k + 21, Blocks.netherrack);
        world.setBlock(i + 1, j + 0, k + 22, Blocks.netherrack);
        world.setBlock(i + 1, j + 0, k + 23, Blocks.netherrack);
        world.setBlock(i + 1, j + 0, k + 24, Blocks.netherrack);
        world.setBlock(i + 1, j + 0, k + 25, Blocks.netherrack);
        world.setBlock(i + 2, j + 0, k + 0, Blocks.netherrack);
        world.setBlock(i + 2, j + 0, k + 1, Blocks.netherrack);
        world.setBlock(i + 2, j + 0, k + 2, Blocks.netherrack);
        world.setBlock(i + 2, j + 0, k + 3, Blocks.netherrack);
        world.setBlock(i + 2, j + 0, k + 4, Blocks.netherrack);
        world.setBlock(i + 2, j + 0, k + 5, Blocks.netherrack);
        world.setBlock(i + 2, j + 0, k + 6, Blocks.netherrack);
        world.setBlock(i + 2, j + 0, k + 7, Blocks.netherrack);
        world.setBlock(i + 2, j + 0, k + 8, Blocks.netherrack);
        world.setBlock(i + 2, j + 0, k + 9, Blocks.netherrack);
        world.setBlock(i + 2, j + 0, k + 10, Blocks.netherrack);
        world.setBlock(i + 2, j + 0, k + 11, Blocks.netherrack);
        world.setBlock(i + 2, j + 0, k + 12, Blocks.netherrack);
        world.setBlock(i + 2, j + 0, k + 13, Blocks.netherrack);
        world.setBlock(i + 2, j + 0, k + 14, Blocks.netherrack);
        world.setBlock(i + 2, j + 0, k + 15, Blocks.netherrack);
        world.setBlock(i + 2, j + 0, k + 16, Blocks.netherrack);
        world.setBlock(i + 2, j + 0, k + 17, Blocks.netherrack);
        world.setBlock(i + 2, j + 0, k + 18, Blocks.netherrack);
        world.setBlock(i + 2, j + 0, k + 19, Blocks.netherrack);
        world.setBlock(i + 2, j + 0, k + 20, Blocks.netherrack);
        world.setBlock(i + 2, j + 0, k + 21, Blocks.netherrack);
        world.setBlock(i + 2, j + 0, k + 22, Blocks.netherrack);
        world.setBlock(i + 2, j + 0, k + 23, Blocks.netherrack);
        world.setBlock(i + 2, j + 0, k + 24, Blocks.netherrack);
        world.setBlock(i + 2, j + 0, k + 25, Blocks.netherrack);
        world.setBlock(i + 2, j + 1, k + 12, Blocks.nether_brick, 2, 0);
        world.setBlock(i + 3, j + 0, k + 0, Blocks.netherrack);
        world.setBlock(i + 3, j + 0, k + 1, Blocks.netherrack);
        world.setBlock(i + 3, j + 0, k + 2, Blocks.netherrack);
        world.setBlock(i + 3, j + 0, k + 3, Blocks.netherrack);
        world.setBlock(i + 3, j + 0, k + 4, Blocks.nether_brick, 2, 0);
        world.setBlock(i + 3, j + 0, k + 5, Blocks.netherrack);
        world.setBlock(i + 3, j + 0, k + 6, Blocks.nether_brick, 2, 0);
        world.setBlock(i + 3, j + 0, k + 7, Blocks.netherrack);
        world.setBlock(i + 3, j + 0, k + 8, Blocks.nether_brick_fence, 3, 0);
        world.setBlock(i + 3, j + 0, k + 9, Blocks.netherrack);
        world.setBlock(i + 3, j + 0, k + 10, Blocks.nether_brick);
        world.setBlock(i + 3, j + 0, k + 11, Blocks.netherrack);
        world.setBlock(i + 3, j + 0, k + 12, Blocks.nether_brick);
        world.setBlock(i + 3, j + 0, k + 13, Blocks.nether_brick);
        world.setBlock(i + 3, j + 0, k + 14, Blocks.netherrack);
        world.setBlock(i + 3, j + 0, k + 15, Blocks.nether_brick);
        world.setBlock(i + 3, j + 0, k + 16, Blocks.netherrack);
        world.setBlock(i + 3, j + 0, k + 17, Blocks.netherrack);
        world.setBlock(i + 3, j + 0, k + 18, Blocks.netherrack);
        world.setBlock(i + 3, j + 0, k + 19, Blocks.netherrack);
        world.setBlock(i + 3, j + 0, k + 20, Blocks.netherrack);
        world.setBlock(i + 3, j + 0, k + 21, Blocks.netherrack);
        world.setBlock(i + 3, j + 0, k + 22, Blocks.netherrack);
        world.setBlock(i + 3, j + 0, k + 23, Blocks.nether_brick, 2, 0);
        world.setBlock(i + 3, j + 0, k + 24, Blocks.netherrack);
        world.setBlock(i + 3, j + 0, k + 25, Blocks.netherrack);
        world.setBlock(i + 3, j + 1, k + 5, Blocks.nether_brick, 2, 0);
        world.setBlock(i + 3, j + 1, k + 7, Blocks.nether_brick, 2, 0);
        world.setBlock(i + 3, j + 1, k + 10, Blocks.nether_brick_fence, 3, 0);
        world.setBlock(i + 3, j + 1, k + 17, Blocks.nether_brick, 2, 0);
        world.setBlock(i + 3, j + 1, k + 19, Blocks.nether_brick, 2, 0);
        world.setBlock(i + 3, j + 1, k + 22, Blocks.nether_brick, 2, 0);
        world.setBlock(i + 4, j + 0, k + 0, Blocks.netherrack);
        world.setBlock(i + 4, j + 0, k + 1, Blocks.netherrack);
        world.setBlock(i + 4, j + 0, k + 2, Blocks.netherrack);
        world.setBlock(i + 4, j + 0, k + 3, Blocks.netherrack);
        world.setBlock(i + 4, j + 0, k + 4, Blocks.netherrack);
        world.setBlock(i + 4, j + 0, k + 5, Blocks.netherrack);
        world.setBlock(i + 4, j + 0, k + 6, Blocks.nether_brick);
        world.setBlock(i + 4, j + 0, k + 7, Blocks.netherrack);
        world.setBlock(i + 4, j + 0, k + 8, Blocks.netherrack);
        world.setBlock(i + 4, j + 0, k + 9, Blocks.netherrack);
        world.setBlock(i + 4, j + 0, k + 10, Blocks.nether_brick);
        world.setBlock(i + 4, j + 0, k + 11, Blocks.netherrack);
        world.setBlock(i + 4, j + 0, k + 12, Blocks.nether_brick);
        world.setBlock(i + 4, j + 0, k + 13, Blocks.netherrack);
        world.setBlock(i + 4, j + 0, k + 14, Blocks.netherrack);
        world.setBlock(i + 4, j + 0, k + 15, Blocks.netherrack);
        world.setBlock(i + 4, j + 0, k + 16, Blocks.nether_brick);
        world.setBlock(i + 4, j + 0, k + 17, Blocks.netherrack);
        world.setBlock(i + 4, j + 0, k + 18, Blocks.nether_brick_fence, 3, 0);
        world.setBlock(i + 4, j + 0, k + 19, Blocks.netherrack);
        world.setBlock(i + 4, j + 0, k + 20, Blocks.nether_brick, 2, 0);
        world.setBlock(i + 4, j + 0, k + 21, Blocks.netherrack);
        world.setBlock(i + 4, j + 0, k + 22, Blocks.netherrack);
        world.setBlock(i + 4, j + 0, k + 23, Blocks.netherrack);
        world.setBlock(i + 4, j + 0, k + 24, Blocks.netherrack);
        world.setBlock(i + 4, j + 0, k + 25, Blocks.netherrack);
        world.setBlock(i + 4, j + 1, k + 3, Blocks.nether_brick, 2, 0);
        world.setBlock(i + 4, j + 1, k + 9, Blocks.nether_brick, 2, 0);
        world.setBlock(i + 4, j + 1, k + 14, Blocks.nether_brick, 2, 0);
        world.setBlock(i + 4, j + 1, k + 15, Blocks.nether_brick, 2, 0);
        world.setBlock(i + 4, j + 1, k + 21, Blocks.nether_brick_fence, 3, 0);
        world.setBlock(i + 4, j + 1, k + 24, Blocks.nether_brick, 2, 0);
        world.setBlock(i + 5, j + 0, k + 0, Blocks.netherrack);
        world.setBlock(i + 5, j + 0, k + 1, Blocks.netherrack);
        world.setBlock(i + 5, j + 0, k + 2, Blocks.netherrack);
        world.setBlock(i + 5, j + 0, k + 3, Blocks.netherrack);
        world.setBlock(i + 5, j + 0, k + 4, Blocks.nether_brick);
        world.setBlock(i + 5, j + 0, k + 5, Blocks.netherrack);
        world.setBlock(i + 5, j + 0, k + 6, Blocks.netherrack);
        world.setBlock(i + 5, j + 0, k + 7, Blocks.netherrack);
        world.setBlock(i + 5, j + 0, k + 8, Blocks.netherrack);
        world.setBlock(i + 5, j + 0, k + 9, Blocks.nether_brick);
        world.setBlock(i + 5, j + 0, k + 10, Blocks.nether_brick);
        world.setBlock(i + 5, j + 0, k + 11, Blocks.netherrack);
        world.setBlock(i + 5, j + 0, k + 12, Blocks.nether_brick);
        world.setBlock(i + 5, j + 0, k + 13, Blocks.nether_brick);
        world.setBlock(i + 5, j + 0, k + 14, Blocks.nether_brick);
        world.setBlock(i + 5, j + 0, k + 15, Blocks.netherrack);
        world.setBlock(i + 5, j + 0, k + 16, Blocks.netherrack);
        world.setBlock(i + 5, j + 0, k + 17, Blocks.netherrack);
        world.setBlock(i + 5, j + 0, k + 18, Blocks.netherrack);
        world.setBlock(i + 5, j + 0, k + 19, Blocks.netherrack);
        world.setBlock(i + 5, j + 0, k + 20, Blocks.netherrack);
        world.setBlock(i + 5, j + 0, k + 21, Blocks.netherrack);
        world.setBlock(i + 5, j + 0, k + 22, Blocks.netherrack);
        world.setBlock(i + 5, j + 0, k + 23, Blocks.netherrack);
        world.setBlock(i + 5, j + 0, k + 24, Blocks.nether_brick);
        world.setBlock(i + 5, j + 0, k + 25, Blocks.netherrack);
        world.setBlock(i + 5, j + 1, k + 4, Blocks.nether_brick, 2, 0);
        world.setBlock(i + 5, j + 1, k + 5, Blocks.nether_brick, 2, 0);
        world.setBlock(i + 5, j + 1, k + 6, Blocks.nether_brick, 2, 0);
        world.setBlock(i + 5, j + 1, k + 7, Blocks.nether_brick, 2, 0);
        world.setBlock(i + 5, j + 1, k + 8, Blocks.nether_brick, 2, 0);
        world.setBlock(i + 5, j + 1, k + 11, Blocks.nether_brick, 2, 0);
        world.setBlock(i + 5, j + 1, k + 13, Blocks.nether_brick, 1, 0);
        world.setBlock(i + 5, j + 1, k + 14, Blocks.nether_brick_fence, 3, 0);
        world.setBlock(i + 5, j + 1, k + 15, Blocks.nether_brick, 2, 0);
        world.setBlock(i + 5, j + 1, k + 16, Blocks.nether_brick, 2, 0);
        world.setBlock(i + 5, j + 1, k + 17, Blocks.nether_brick, 2, 0);
        world.setBlock(i + 5, j + 1, k + 19, Blocks.nether_brick, 2, 0);
        world.setBlock(i + 5, j + 1, k + 20, Blocks.nether_brick, 2, 0);
        world.setBlock(i + 5, j + 1, k + 21, Blocks.nether_brick, 2, 0);
        world.setBlock(i + 5, j + 1, k + 22, Blocks.nether_brick, 2, 0);
        world.setBlock(i + 5, j + 1, k + 23, Blocks.nether_brick, 2, 0);
        world.setBlock(i + 5, j + 2, k + 4, Blocks.nether_brick, 2, 0);
        world.setBlock(i + 5, j + 2, k + 5, Blocks.nether_brick, 2, 0);
        world.setBlock(i + 5, j + 2, k + 21, Blocks.nether_brick, 2, 0);
        world.setBlock(i + 5, j + 2, k + 22, Blocks.nether_brick, 2, 0);
        world.setBlock(i + 5, j + 3, k + 4, Blocks.nether_brick, 1, 0);
        world.setBlock(i + 5, j + 3, k + 5, Blocks.nether_brick, 2, 0);
        world.setBlock(i + 5, j + 3, k + 21, Blocks.nether_brick, 1, 0);
        world.setBlock(i + 5, j + 3, k + 22, Blocks.nether_brick, 2, 0);
        world.setBlock(i + 5, j + 4, k + 4, Blocks.nether_brick, 1, 0);
        world.setBlock(i + 5, j + 4, k + 5, Blocks.nether_brick, 1, 0);
        world.setBlock(i + 5, j + 4, k + 21, Blocks.nether_brick, 1, 0);
        world.setBlock(i + 5, j + 4, k + 22, Blocks.nether_brick, 1, 0);
        world.setBlock(i + 5, j + 5, k + 4, Blocks.nether_brick, 2, 0);
        world.setBlock(i + 5, j + 5, k + 5, Blocks.nether_brick, 2, 0);
        world.setBlock(i + 5, j + 5, k + 21, Blocks.nether_brick, 1, 0);
        world.setBlock(i + 5, j + 5, k + 22, Blocks.nether_brick, 1, 0);
        world.setBlock(i + 5, j + 6, k + 4, Blocks.nether_brick, 2, 0);
        world.setBlock(i + 5, j + 6, k + 5, Blocks.nether_brick, 1, 0);
        world.setBlock(i + 5, j + 6, k + 21, Blocks.nether_brick, 2, 0);
        world.setBlock(i + 5, j + 6, k + 22, Blocks.nether_brick, 2, 0);
        world.setBlock(i + 5, j + 7, k + 4, Blocks.nether_brick, 2, 0);
        world.setBlock(i + 5, j + 7, k + 21, Blocks.nether_brick, 2, 0);
        world.setBlock(i + 5, j + 7, k + 22, Blocks.nether_brick, 1, 0);
        world.setBlock(i + 5, j + 8, k + 4, Blocks.nether_brick, 2, 0);
        world.setBlock(i + 5, j + 8, k + 20, Blocks.nether_brick, 2, 0);
        world.setBlock(i + 5, j + 8, k + 21, Blocks.nether_brick, 1, 0);
        world.setBlock(i + 5, j + 8, k + 22, Blocks.nether_brick, 2, 0);
        world.setBlock(i + 5, j + 9, k + 4, Blocks.nether_brick, 2, 0);
        world.setBlock(i + 5, j + 9, k + 19, Blocks.nether_brick, 2, 0);
        world.setBlock(i + 5, j + 9, k + 20, Blocks.nether_brick, 2, 0);
        world.setBlock(i + 5, j + 9, k + 21, Blocks.nether_brick, 1, 0);
        world.setBlock(i + 5, j + 9, k + 22, Blocks.nether_brick, 1, 0);
        world.setBlock(i + 5, j + 10, k + 4, Blocks.nether_brick, 2, 0);
        world.setBlock(i + 5, j + 10, k + 18, Blocks.nether_brick, 2, 0);
        world.setBlock(i + 5, j + 10, k + 19, Blocks.nether_brick, 2, 0);
        world.setBlock(i + 5, j + 10, k + 20, Blocks.nether_brick, 2, 0);
        world.setBlock(i + 5, j + 10, k + 22, Blocks.nether_brick, 2, 0);
        world.setBlock(i + 5, j + 11, k + 21, Blocks.nether_brick, 2, 0);
        world.setBlock(i + 5, j + 11, k + 22, Blocks.nether_brick, 2, 0);
        world.setBlock(i + 5, j + 12, k + 22, Blocks.nether_brick, 2, 0);
        world.setBlock(i + 5, j + 13, k + 22, Blocks.nether_brick, 2, 0);
        world.setBlock(i + 6, j + 0, k + 0, Blocks.netherrack);
        world.setBlock(i + 6, j + 0, k + 1, Blocks.netherrack);
        world.setBlock(i + 6, j + 0, k + 2, Blocks.netherrack);
        world.setBlock(i + 6, j + 0, k + 3, Blocks.netherrack);
        world.setBlock(i + 6, j + 0, k + 4, Blocks.netherrack);
        world.setBlock(i + 6, j + 0, k + 5, Blocks.nether_brick);
        world.setBlock(i + 6, j + 0, k + 6, Blocks.nether_brick, 2, 0);
        world.setBlock(i + 6, j + 0, k + 7, Blocks.netherrack);
        world.setBlock(i + 6, j + 0, k + 8, Blocks.nether_brick);
        world.setBlock(i + 6, j + 0, k + 9, Blocks.netherrack);
        world.setBlock(i + 6, j + 0, k + 10, Blocks.nether_brick);
        world.setBlock(i + 6, j + 0, k + 11, Blocks.netherrack);
        world.setBlock(i + 6, j + 0, k + 12, Blocks.nether_brick);
        world.setBlock(i + 6, j + 0, k + 13, Blocks.netherrack);
        world.setBlock(i + 6, j + 0, k + 14, Blocks.netherrack);
        world.setBlock(i + 6, j + 0, k + 15, Blocks.nether_brick);
        world.setBlock(i + 6, j + 0, k + 16, Blocks.netherrack);
        world.setBlock(i + 6, j + 0, k + 17, Blocks.nether_brick);
        world.setBlock(i + 6, j + 0, k + 18, Blocks.nether_brick);
        world.setBlock(i + 6, j + 0, k + 19, Blocks.netherrack);
        world.setBlock(i + 6, j + 0, k + 20, Blocks.nether_brick);
        world.setBlock(i + 6, j + 0, k + 21, Blocks.netherrack);
        world.setBlock(i + 6, j + 0, k + 22, Blocks.netherrack);
        world.setBlock(i + 6, j + 0, k + 23, Blocks.netherrack);
        world.setBlock(i + 6, j + 0, k + 24, Blocks.netherrack);
        world.setBlock(i + 6, j + 0, k + 25, Blocks.netherrack);
        world.setBlock(i + 6, j + 1, k + 3, Blocks.nether_brick, 2, 0);
        world.setBlock(i + 6, j + 1, k + 4, Blocks.nether_brick, 2, 0);
        world.setBlock(i + 6, j + 1, k + 5, Blocks.nether_brick, 2, 0);
        world.setBlock(i + 6, j + 1, k + 6, Blocks.nether_brick_fence, 3, 0);
        world.setBlock(i + 6, j + 1, k + 7, Blocks.nether_brick, 2, 0);
        world.setBlock(i + 6, j + 1, k + 9, Blocks.nether_brick, 2, 0);
        world.setBlock(i + 6, j + 1, k + 10, Blocks.nether_brick_fence, 3, 0);
        world.setBlock(i + 6, j + 1, k + 11, Blocks.nether_brick, 2, 0);
        world.setBlock(i + 6, j + 1, k + 12, Blocks.nether_brick_fence, 3, 0);
        world.setBlock(i + 6, j + 1, k + 16, Blocks.nether_brick, 2, 0);
        world.setBlock(i + 6, j + 1, k + 19, Blocks.nether_brick, 2, 0);
        world.setBlock(i + 6, j + 1, k + 21, Blocks.nether_brick, 2, 0);
        world.setBlock(i + 6, j + 1, k + 22, Blocks.nether_brick, 2, 0);
        world.setBlock(i + 6, j + 1, k + 24, Blocks.nether_brick, 2, 0);
        world.setBlock(i + 6, j + 2, k + 4, Blocks.nether_brick, 2, 0);
        world.setBlock(i + 6, j + 2, k + 5, Blocks.nether_brick, 1, 0);
        world.setBlock(i + 6, j + 2, k + 21, Blocks.nether_brick, 1, 0);
        world.setBlock(i + 6, j + 2, k + 22, Blocks.nether_brick, 2, 0);
        world.setBlock(i + 6, j + 3, k + 4, Blocks.nether_brick, 2, 0);
        world.setBlock(i + 6, j + 3, k + 5, Blocks.nether_brick, 1, 0);
        world.setBlock(i + 6, j + 3, k + 21, Blocks.nether_brick, 1, 0);
        world.setBlock(i + 6, j + 3, k + 22, Blocks.nether_brick, 1, 0);
        world.setBlock(i + 6, j + 4, k + 4, Blocks.nether_brick, 1, 0);
        world.setBlock(i + 6, j + 4, k + 21, Blocks.nether_brick, 2, 0);
        world.setBlock(i + 6, j + 4, k + 22, Blocks.nether_brick, 1, 0);
        world.setBlock(i + 6, j + 5, k + 4, Blocks.nether_brick, 1, 0);
        world.setBlock(i + 6, j + 5, k + 21, Blocks.nether_brick, 2, 0);
        world.setBlock(i + 6, j + 5, k + 22, Blocks.nether_brick, 1, 0);
        world.setBlock(i + 6, j + 6, k + 4, Blocks.nether_brick, 2, 0);
        world.setBlock(i + 6, j + 6, k + 21, Blocks.nether_brick, 2, 0);
        world.setBlock(i + 6, j + 6, k + 22, Blocks.nether_brick, 1, 0);
        world.setBlock(i + 6, j + 7, k + 4, Blocks.nether_brick, 2, 0);
        world.setBlock(i + 6, j + 7, k + 21, Blocks.nether_brick, 2, 0);
        world.setBlock(i + 6, j + 7, k + 22, Blocks.nether_brick, 2, 0);
        world.setBlock(i + 6, j + 8, k + 4, Blocks.nether_brick, 2, 0);
        world.setBlock(i + 6, j + 8, k + 20, Blocks.nether_brick, 2, 0);
        world.setBlock(i + 6, j + 8, k + 21, Blocks.nether_brick, 2, 0);
        world.setBlock(i + 6, j + 8, k + 22, Blocks.nether_brick, 2, 0);
        world.setBlock(i + 6, j + 9, k + 19, Blocks.nether_brick, 2, 0);
        world.setBlock(i + 6, j + 9, k + 20, Blocks.nether_brick, 1, 0);
        world.setBlock(i + 6, j + 9, k + 21, Blocks.nether_brick, 2, 0);
        world.setBlock(i + 6, j + 9, k + 22, Blocks.nether_brick, 2, 0);
        world.setBlock(i + 6, j + 10, k + 20, Blocks.nether_brick, 2, 0);
        world.setBlock(i + 6, j + 10, k + 21, Blocks.nether_brick, 2, 0);
        world.setBlock(i + 6, j + 10, k + 22, Blocks.nether_brick, 1, 0);
        world.setBlock(i + 6, j + 11, k + 21, Blocks.nether_brick_fence, 3, 0);
        world.setBlock(i + 6, j + 11, k + 22, Blocks.nether_brick, 2, 0);
        world.setBlock(i + 6, j + 12, k + 22, Blocks.nether_brick, 2, 0);
        world.setBlock(i + 7, j + 0, k + 0, Blocks.netherrack);
        world.setBlock(i + 7, j + 0, k + 1, Blocks.netherrack);
        world.setBlock(i + 7, j + 0, k + 2, Blocks.nether_brick, 2, 0);
        world.setBlock(i + 7, j + 0, k + 3, Blocks.nether_brick, 2, 0);
        world.setBlock(i + 7, j + 0, k + 4, Blocks.netherrack);
        world.setBlock(i + 7, j + 0, k + 5, Blocks.netherrack);
        world.setBlock(i + 7, j + 0, k + 6, Blocks.nether_brick);
        world.setBlock(i + 7, j + 0, k + 7, Blocks.netherrack);
        world.setBlock(i + 7, j + 0, k + 8, Blocks.nether_brick, 2, 0);
        world.setBlock(i + 7, j + 0, k + 9, Blocks.netherrack);
        world.setBlock(i + 7, j + 0, k + 10, Blocks.nether_brick);
        world.setBlock(i + 7, j + 0, k + 11, Blocks.netherrack);
        world.setBlock(i + 7, j + 0, k + 12, Blocks.nether_brick, 2, 0);
        world.setBlock(i + 7, j + 0, k + 13, Blocks.nether_brick);
        world.setBlock(i + 7, j + 0, k + 14, Blocks.netherrack);
        world.setBlock(i + 7, j + 0, k + 15, Blocks.nether_brick);
        world.setBlock(i + 7, j + 0, k + 16, Blocks.nether_brick);
        world.setBlock(i + 7, j + 0, k + 17, Blocks.netherrack);
        world.setBlock(i + 7, j + 0, k + 18, Blocks.nether_brick, 2, 0);
        world.setBlock(i + 7, j + 0, k + 19, Blocks.netherrack);
        world.setBlock(i + 7, j + 0, k + 20, Blocks.nether_brick, 2, 0);
        world.setBlock(i + 7, j + 0, k + 21, Blocks.nether_brick);
        world.setBlock(i + 7, j + 0, k + 22, Blocks.nether_brick);
        world.setBlock(i + 7, j + 0, k + 23, Blocks.netherrack);
        world.setBlock(i + 7, j + 0, k + 24, Blocks.netherrack);
        world.setBlock(i + 7, j + 0, k + 25, Blocks.nether_brick);
        world.setBlock(i + 7, j + 1, k + 4, Blocks.nether_brick, 2, 0);
        world.setBlock(i + 7, j + 1, k + 7, Blocks.nether_brick, 2, 0);
        world.setBlock(i + 7, j + 1, k + 11, Blocks.nether_brick, 2, 0);
        world.setBlock(i + 7, j + 1, k + 13, Blocks.nether_brick, 2, 0);
        world.setBlock(i + 7, j + 1, k + 14, Blocks.nether_brick, 1, 0);
        world.setBlock(i + 7, j + 1, k + 15, Blocks.nether_brick, 2, 0);
        world.setBlock(i + 7, j + 1, k + 16, Blocks.nether_brick, 2, 0);
        world.setBlock(i + 7, j + 1, k + 19, Blocks.nether_brick, 2, 0);
        world.setBlock(i + 7, j + 1, k + 24, Blocks.nether_brick, 2, 0);
        world.setBlock(i + 7, j + 2, k + 4, Blocks.nether_brick, 2, 0);
        world.setBlock(i + 7, j + 8, k + 21, Blocks.nether_brick, 2, 0);
        world.setBlock(i + 7, j + 8, k + 22, Blocks.nether_brick, 2, 0);
        world.setBlock(i + 7, j + 9, k + 21, Blocks.nether_brick, 2, 0);
        world.setBlock(i + 7, j + 9, k + 22, Blocks.nether_brick, 1, 0);
        world.setBlock(i + 7, j + 10, k + 21, Blocks.nether_brick_fence, 3, 0);
        world.setBlock(i + 7, j + 10, k + 22, Blocks.nether_brick, 2, 0);
        world.setBlock(i + 7, j + 11, k + 22, Blocks.nether_brick, 2, 0);
        world.setBlock(i + 8, j + 0, k + 0, Blocks.netherrack);
        world.setBlock(i + 8, j + 0, k + 1, Blocks.netherrack);
        world.setBlock(i + 8, j + 0, k + 2, Blocks.netherrack);
        world.setBlock(i + 8, j + 0, k + 3, Blocks.netherrack);
        world.setBlock(i + 8, j + 0, k + 4, Blocks.netherrack);
        world.setBlock(i + 8, j + 0, k + 5, Blocks.netherrack);
        world.setBlock(i + 8, j + 0, k + 6, Blocks.nether_brick, 2, 0);
        world.setBlock(i + 8, j + 0, k + 7, Blocks.netherrack);
        world.setBlock(i + 8, j + 0, k + 8, Blocks.nether_brick);
        world.setBlock(i + 8, j + 0, k + 9, Blocks.netherrack);
        world.setBlock(i + 8, j + 0, k + 10, Blocks.netherrack);
        world.setBlock(i + 8, j + 0, k + 11, Blocks.nether_brick);
        world.setBlock(i + 8, j + 0, k + 12, Blocks.netherrack);
        world.setBlock(i + 8, j + 0, k + 13, Blocks.nether_brick);
        world.setBlock(i + 8, j + 0, k + 14, Blocks.netherrack);
        world.setBlock(i + 8, j + 0, k + 15, Blocks.nether_brick);
        world.setBlock(i + 8, j + 0, k + 16, Blocks.nether_brick);
        world.setBlock(i + 8, j + 0, k + 17, Blocks.netherrack);
        world.setBlock(i + 8, j + 0, k + 18, Blocks.netherrack);
        world.setBlock(i + 8, j + 0, k + 19, Blocks.netherrack);
        world.setBlock(i + 8, j + 0, k + 20, Blocks.nether_brick);
        world.setBlock(i + 8, j + 0, k + 21, Blocks.nether_brick);
        world.setBlock(i + 8, j + 0, k + 22, Blocks.netherrack);
        world.setBlock(i + 8, j + 0, k + 23, Blocks.netherrack);
        world.setBlock(i + 8, j + 0, k + 24, Blocks.netherrack);
        world.setBlock(i + 8, j + 0, k + 25, Blocks.netherrack);
        world.setBlock(i + 8, j + 1, k + 2, Blocks.nether_brick, 2, 0);
        world.setBlock(i + 8, j + 1, k + 4, Blocks.nether_brick, 2, 0);
        world.setBlock(i + 8, j + 1, k + 5, Blocks.nether_brick, 2, 0);
        world.setBlock(i + 8, j + 1, k + 7, Blocks.nether_brick, 1, 0);
        world.setBlock(i + 8, j + 1, k + 9, Blocks.nether_brick, 1, 0);
        world.setBlock(i + 8, j + 1, k + 13, Blocks.nether_brick, 2, 0);
        world.setBlock(i + 8, j + 1, k + 17, Blocks.nether_brick, 2, 0);
        world.setBlock(i + 8, j + 1, k + 19, Blocks.nether_brick, 2, 0);
        world.setBlock(i + 8, j + 1, k + 22, Blocks.nether_brick, 2, 0);
        world.setBlock(i + 8, j + 1, k + 24, Blocks.nether_brick, 2, 0);
        world.setBlock(i + 8, j + 2, k + 5, Blocks.nether_brick, 2, 0);
        world.setBlock(i + 8, j + 2, k + 19, Blocks.nether_brick, 1, 0);
        world.setBlock(i + 8, j + 9, k + 21, Blocks.nether_brick, 1, 0);
        world.setBlock(i + 8, j + 9, k + 22, Blocks.nether_brick, 2, 0);
        world.setBlock(i + 8, j + 10, k + 21, Blocks.nether_brick, 2, 0);
        world.setBlock(i + 8, j + 10, k + 22, Blocks.nether_brick, 2, 0);
        world.setBlock(i + 9, j + 0, k + 0, Blocks.netherrack);
        world.setBlock(i + 9, j + 0, k + 1, Blocks.netherrack);
        world.setBlock(i + 9, j + 0, k + 2, Blocks.netherrack);
        world.setBlock(i + 9, j + 0, k + 3, Blocks.netherrack);
        world.setBlock(i + 9, j + 0, k + 4, Blocks.netherrack);
        world.setBlock(i + 9, j + 0, k + 5, Blocks.nether_brick);
        world.setBlock(i + 9, j + 0, k + 6, Blocks.nether_brick);
        world.setBlock(i + 9, j + 0, k + 7, Blocks.netherrack);
        world.setBlock(i + 9, j + 0, k + 8, Blocks.netherrack);
        world.setBlock(i + 9, j + 0, k + 9, Blocks.netherrack);
        world.setBlock(i + 9, j + 0, k + 10, Blocks.nether_brick);
        world.setBlock(i + 9, j + 0, k + 11, Blocks.nether_brick, 2, 0);
        world.setBlock(i + 9, j + 0, k + 12, Blocks.netherrack);
        world.setBlock(i + 9, j + 0, k + 13, Blocks.netherrack);
        world.setBlock(i + 9, j + 0, k + 14, Blocks.nether_brick);
        world.setBlock(i + 9, j + 0, k + 15, Blocks.netherrack);
        world.setBlock(i + 9, j + 0, k + 16, Blocks.netherrack);
        world.setBlock(i + 9, j + 0, k + 17, Blocks.nether_brick);
        world.setBlock(i + 9, j + 0, k + 18, Blocks.nether_brick);
        world.setBlock(i + 9, j + 0, k + 19, Blocks.nether_brick);
        world.setBlock(i + 9, j + 0, k + 20, Blocks.netherrack);
        world.setBlock(i + 9, j + 0, k + 21, Blocks.nether_brick);
        world.setBlock(i + 9, j + 0, k + 22, Blocks.netherrack);
        world.setBlock(i + 9, j + 0, k + 23, Blocks.nether_brick);
        world.setBlock(i + 9, j + 0, k + 24, Blocks.netherrack);
        world.setBlock(i + 9, j + 0, k + 25, Blocks.nether_brick);
        world.setBlock(i + 9, j + 1, k + 2, Blocks.nether_brick_fence, 3, 0);
        world.setBlock(i + 9, j + 1, k + 4, Blocks.nether_brick, 2, 0);
        world.setBlock(i + 9, j + 1, k + 5, Blocks.nether_brick, 1, 0);
        world.setBlock(i + 9, j + 1, k + 8, Blocks.nether_brick, 2, 0);
        world.setBlock(i + 9, j + 1, k + 9, Blocks.nether_brick_fence, 3, 0);
        world.setBlock(i + 9, j + 1, k + 11, Blocks.nether_brick, 2, 0);
        world.setBlock(i + 9, j + 1, k + 13, Blocks.nether_brick, 2, 0);
        world.setBlock(i + 9, j + 1, k + 14, Blocks.nether_brick, 2, 0);
        WorldGenWarlordDungeon.chest(world, rand, i + 9, j + 1, k + 17, "NetherStructure", rand.nextInt(5) + 1);
        world.setBlock(i + 9, j + 1, k + 18, Blocks.nether_brick, 2, 0);
        world.setBlock(i + 9, j + 1, k + 20, Blocks.nether_brick, 2, 0);
        world.setBlock(i + 9, j + 2, k + 4, Blocks.nether_brick, 2, 0);
        world.setBlock(i + 9, j + 2, k + 11, Blocks.nether_brick, 2, 0);
        world.setBlock(i + 9, j + 2, k + 14, Blocks.nether_brick, 1, 0);
        world.setBlock(i + 9, j + 10, k + 21, Blocks.nether_brick, 2, 0);
        world.setBlock(i + 9, j + 10, k + 22, Blocks.nether_brick, 2, 0);
        world.setBlock(i + 9, j + 11, k + 21, Blocks.nether_brick, 2, 0);
        world.setBlock(i + 9, j + 11, k + 22, Blocks.nether_brick_fence, 3, 0);
        world.setBlock(i + 10, j + 0, k + 0, Blocks.netherrack);
        world.setBlock(i + 10, j + 0, k + 1, Blocks.netherrack);
        world.setBlock(i + 10, j + 0, k + 2, Blocks.netherrack);
        world.setBlock(i + 10, j + 0, k + 3, Blocks.netherrack);
        world.setBlock(i + 10, j + 0, k + 4, Blocks.nether_brick);
        world.setBlock(i + 10, j + 0, k + 5, Blocks.nether_brick);
        world.setBlock(i + 10, j + 0, k + 6, Blocks.netherrack);
        world.setBlock(i + 10, j + 0, k + 7, Blocks.netherrack);
        world.setBlock(i + 10, j + 0, k + 8, Blocks.netherrack);
        world.setBlock(i + 10, j + 0, k + 9, Blocks.nether_brick);
        world.setBlock(i + 10, j + 0, k + 10, Blocks.netherrack);
        world.setBlock(i + 10, j + 0, k + 11, Blocks.nether_brick);
        world.setBlock(i + 10, j + 0, k + 12, Blocks.nether_brick, 2, 0);
        world.setBlock(i + 10, j + 0, k + 13, Blocks.netherrack);
        world.setBlock(i + 10, j + 0, k + 14, Blocks.nether_brick);
        world.setBlock(i + 10, j + 0, k + 15, Blocks.nether_brick);
        world.setBlock(i + 10, j + 0, k + 16, Blocks.nether_brick, 2, 0);
        world.setBlock(i + 10, j + 0, k + 17, Blocks.nether_brick);
        world.setBlock(i + 10, j + 0, k + 18, Blocks.nether_brick);
        world.setBlock(i + 10, j + 0, k + 19, Blocks.nether_brick);
        world.setBlock(i + 10, j + 0, k + 20, Blocks.netherrack);
        world.setBlock(i + 10, j + 0, k + 21, Blocks.nether_brick, 2, 0);
        world.setBlock(i + 10, j + 0, k + 22, Blocks.netherrack);
        world.setBlock(i + 10, j + 0, k + 23, Blocks.nether_brick, 2, 0);
        world.setBlock(i + 10, j + 0, k + 24, Blocks.netherrack);
        world.setBlock(i + 10, j + 0, k + 25, Blocks.netherrack);
        world.setBlock(i + 10, j + 1, k + 2, Blocks.nether_brick, 2, 0);
        world.setBlock(i + 10, j + 1, k + 4, Blocks.nether_brick_fence, 3, 0);
        world.setBlock(i + 10, j + 1, k + 6, Blocks.nether_brick, 1, 0);
        world.setBlock(i + 10, j + 1, k + 8, Blocks.nether_brick, 1, 0);
        world.setBlock(i + 10, j + 1, k + 9, Blocks.nether_brick, 2, 0);
        world.setBlock(i + 10, j + 1, k + 12, Blocks.nether_brick, 2, 0);
        world.setBlock(i + 10, j + 1, k + 13, Blocks.nether_brick, 2, 0);
        world.setBlock(i + 10, j + 1, k + 16, Blocks.nether_brick, 2, 0);
        world.setBlock(i + 10, j + 1, k + 20, Blocks.nether_brick, 2, 0);
        world.setBlock(i + 10, j + 1, k + 22, Blocks.nether_brick, 2, 0);
        world.setBlock(i + 10, j + 1, k + 24, Blocks.nether_brick, 2, 0);
        world.setBlock(i + 10, j + 1, k + 25, Blocks.nether_brick, 2, 0);
        world.setBlock(i + 10, j + 10, k + 21, Blocks.nether_brick, 2, 0);
        world.setBlock(i + 10, j + 10, k + 22, Blocks.nether_brick, 2, 0);
        world.setBlock(i + 11, j + 0, k + 0, Blocks.netherrack);
        world.setBlock(i + 11, j + 0, k + 1, Blocks.netherrack);
        world.setBlock(i + 11, j + 0, k + 2, Blocks.netherrack);
        world.setBlock(i + 11, j + 0, k + 3, Blocks.netherrack);
        world.setBlock(i + 11, j + 0, k + 4, Blocks.netherrack);
        world.setBlock(i + 11, j + 0, k + 5, Blocks.nether_brick, 2, 0);
        world.setBlock(i + 11, j + 0, k + 6, Blocks.nether_brick, 2, 0);
        world.setBlock(i + 11, j + 0, k + 7, Blocks.netherrack);
        world.setBlock(i + 11, j + 0, k + 8, Blocks.nether_brick);
        world.setBlock(i + 11, j + 0, k + 9, Blocks.netherrack);
        world.setBlock(i + 11, j + 0, k + 10, Blocks.nether_brick);
        world.setBlock(i + 11, j + 0, k + 11, Blocks.netherrack);
        world.setBlock(i + 11, j + 0, k + 12, Blocks.nether_brick);
        world.setBlock(i + 11, j + 0, k + 13, Blocks.netherrack);
        world.setBlock(i + 11, j + 0, k + 14, Blocks.netherrack);
        world.setBlock(i + 11, j + 0, k + 15, Blocks.nether_brick);
        world.setBlock(i + 11, j + 0, k + 16, Blocks.nether_brick);
        world.setBlock(i + 11, j + 0, k + 17, Blocks.netherrack);
        world.setBlock(i + 11, j + 0, k + 18, Blocks.nether_brick);
        world.setBlock(i + 11, j + 0, k + 19, Blocks.nether_brick);
        world.setBlock(i + 11, j + 0, k + 20, Blocks.netherrack);
        world.setBlock(i + 11, j + 0, k + 21, Blocks.netherrack);
        world.setBlock(i + 11, j + 0, k + 22, Blocks.netherrack);
        world.setBlock(i + 11, j + 0, k + 23, Blocks.netherrack);
        world.setBlock(i + 11, j + 0, k + 24, Blocks.netherrack);
        world.setBlock(i + 11, j + 0, k + 25, Blocks.nether_brick, 2, 0);
        world.setBlock(i + 11, j + 1, k + 4, Blocks.nether_brick, 2, 0);
        world.setBlock(i + 11, j + 1, k + 8, Blocks.nether_brick_fence, 3, 0);
        Dungeons.spawner(world, i + 11, j + 1, k + 9, 16, 3);
        world.setBlock(i + 11, j + 1, k + 10, Blocks.nether_brick, 2, 0);
        world.setBlock(i + 11, j + 1, k + 13, Blocks.nether_brick, 2, 0);
        world.setBlock(i + 11, j + 1, k + 15, Blocks.nether_brick, 2, 0);
        world.setBlock(i + 11, j + 1, k + 17, Blocks.nether_brick, 2, 0);
        world.setBlock(i + 11, j + 1, k + 21, Blocks.nether_brick, 2, 0);
        world.setBlock(i + 11, j + 1, k + 22, Blocks.nether_brick, 2, 0);
        world.setBlock(i + 11, j + 2, k + 4, Blocks.nether_brick, 2, 0);
        world.setBlock(i + 11, j + 2, k + 17, Blocks.nether_brick, 1, 0);
        world.setBlock(i + 11, j + 10, k + 21, Blocks.nether_brick, 2, 0);
        world.setBlock(i + 12, j + 0, k + 0, Blocks.netherrack);
        world.setBlock(i + 12, j + 0, k + 1, Blocks.netherrack);
        world.setBlock(i + 12, j + 0, k + 2, Blocks.nether_brick);
        world.setBlock(i + 12, j + 0, k + 3, Blocks.netherrack);
        world.setBlock(i + 12, j + 0, k + 4, Blocks.netherrack);
        world.setBlock(i + 12, j + 0, k + 5, Blocks.nether_brick);
        world.setBlock(i + 12, j + 0, k + 6, Blocks.netherrack);
        world.setBlock(i + 12, j + 0, k + 7, Blocks.netherrack);
        world.setBlock(i + 12, j + 0, k + 8, Blocks.nether_brick);
        world.setBlock(i + 12, j + 0, k + 9, Blocks.nether_brick);
        world.setBlock(i + 12, j + 0, k + 10, Blocks.netherrack);
        world.setBlock(i + 12, j + 0, k + 11, Blocks.netherrack);
        world.setBlock(i + 12, j + 0, k + 12, Blocks.netherrack);
        world.setBlock(i + 12, j + 0, k + 13, Blocks.nether_brick);
        world.setBlock(i + 12, j + 0, k + 14, Blocks.netherrack);
        world.setBlock(i + 12, j + 0, k + 15, Blocks.nether_brick);
        world.setBlock(i + 12, j + 0, k + 16, Blocks.nether_brick);
        world.setBlock(i + 12, j + 0, k + 17, Blocks.nether_brick);
        world.setBlock(i + 12, j + 0, k + 18, Blocks.netherrack);
        world.setBlock(i + 12, j + 0, k + 19, Blocks.nether_brick, 2, 0);
        world.setBlock(i + 12, j + 0, k + 20, Blocks.nether_brick);
        world.setBlock(i + 12, j + 0, k + 21, Blocks.netherrack);
        world.setBlock(i + 12, j + 0, k + 22, Blocks.netherrack);
        world.setBlock(i + 12, j + 0, k + 23, Blocks.netherrack);
        world.setBlock(i + 12, j + 0, k + 24, Blocks.netherrack);
        world.setBlock(i + 12, j + 0, k + 25, Blocks.netherrack);
        world.setBlock(i + 12, j + 1, k + 0, Blocks.nether_brick, 2, 0);
        world.setBlock(i + 12, j + 1, k + 1, Blocks.nether_brick, 2, 0);
        world.setBlock(i + 12, j + 1, k + 5, Blocks.nether_brick_fence, 3, 0);
        world.setBlock(i + 12, j + 1, k + 7, Blocks.nether_brick, 2, 0);
        world.setBlock(i + 12, j + 1, k + 8, Blocks.nether_brick_fence, 3, 0);
        world.setBlock(i + 12, j + 1, k + 11, Blocks.nether_brick, 2, 0);
        world.setBlock(i + 12, j + 1, k + 14, Blocks.nether_brick, 2, 0);
        world.setBlock(i + 12, j + 1, k + 20, Blocks.nether_brick, 1, 0);
        world.setBlock(i + 12, j + 1, k + 21, Blocks.nether_brick, 2, 0);
        world.setBlock(i + 12, j + 1, k + 22, Blocks.nether_brick, 2, 0);
        world.setBlock(i + 12, j + 1, k + 23, Blocks.nether_brick, 2, 0);
        world.setBlock(i + 12, j + 2, k + 11, Blocks.nether_brick, 2, 0);
        world.setBlock(i + 12, j + 2, k + 14, Blocks.nether_brick, 1, 0);
        world.setBlock(i + 12, j + 2, k + 21, Blocks.nether_brick, 2, 0);
        world.setBlock(i + 12, j + 3, k + 21, Blocks.nether_brick, 2, 0);
        world.setBlock(i + 13, j + 0, k + 0, Blocks.netherrack);
        world.setBlock(i + 13, j + 0, k + 1, Blocks.netherrack);
        world.setBlock(i + 13, j + 0, k + 2, Blocks.nether_brick);
        world.setBlock(i + 13, j + 0, k + 3, Blocks.netherrack);
        world.setBlock(i + 13, j + 0, k + 4, Blocks.nether_brick);
        world.setBlock(i + 13, j + 0, k + 5, Blocks.netherrack);
        world.setBlock(i + 13, j + 0, k + 6, Blocks.nether_brick, 2, 0);
        world.setBlock(i + 13, j + 0, k + 7, Blocks.nether_brick);
        world.setBlock(i + 13, j + 0, k + 8, Blocks.nether_brick);
        world.setBlock(i + 13, j + 0, k + 9, Blocks.netherrack);
        world.setBlock(i + 13, j + 0, k + 10, Blocks.nether_brick);
        world.setBlock(i + 13, j + 0, k + 11, Blocks.netherrack);
        world.setBlock(i + 13, j + 0, k + 12, Blocks.nether_brick);
        world.setBlock(i + 13, j + 0, k + 13, Blocks.nether_brick);
        world.setBlock(i + 13, j + 0, k + 14, Blocks.netherrack);
        world.setBlock(i + 13, j + 0, k + 15, Blocks.nether_brick, 2, 0);
        world.setBlock(i + 13, j + 0, k + 16, Blocks.nether_brick, 2, 0);
        world.setBlock(i + 13, j + 0, k + 17, Blocks.nether_brick, 2, 0);
        world.setBlock(i + 13, j + 0, k + 18, Blocks.netherrack);
        world.setBlock(i + 13, j + 0, k + 19, Blocks.netherrack);
        world.setBlock(i + 13, j + 0, k + 20, Blocks.netherrack);
        world.setBlock(i + 13, j + 0, k + 21, Blocks.nether_brick);
        world.setBlock(i + 13, j + 0, k + 22, Blocks.netherrack);
        world.setBlock(i + 13, j + 0, k + 23, Blocks.netherrack);
        world.setBlock(i + 13, j + 0, k + 24, Blocks.netherrack);
        world.setBlock(i + 13, j + 0, k + 25, Blocks.netherrack);
        world.setBlock(i + 13, j + 1, k + 5, Blocks.nether_brick, 2, 0);
        world.setBlock(i + 13, j + 1, k + 6, Blocks.nether_brick, 2, 0);
        world.setBlock(i + 13, j + 1, k + 8, Blocks.nether_brick_fence, 3, 0);
        world.setBlock(i + 13, j + 1, k + 10, Blocks.nether_brick_fence, 3, 0);
        world.setBlock(i + 13, j + 1, k + 11, Blocks.nether_brick, 2, 0);
        world.setBlock(i + 13, j + 1, k + 13, Blocks.nether_brick, 2, 0);
        world.setBlock(i + 13, j + 1, k + 22, Blocks.nether_brick, 2, 0);
        world.setBlock(i + 13, j + 1, k + 24, Blocks.nether_brick, 2, 0);
        world.setBlock(i + 13, j + 2, k + 5, Blocks.nether_brick, 2, 0);
        world.setBlock(i + 13, j + 2, k + 6, Blocks.nether_brick, 1, 0);
        world.setBlock(i + 13, j + 2, k + 22, Blocks.nether_brick, 2, 0);
        world.setBlock(i + 14, j + 0, k + 0, Blocks.netherrack);
        world.setBlock(i + 14, j + 0, k + 1, Blocks.netherrack);
        world.setBlock(i + 14, j + 0, k + 2, Blocks.netherrack);
        world.setBlock(i + 14, j + 0, k + 3, Blocks.netherrack);
        world.setBlock(i + 14, j + 0, k + 4, Blocks.netherrack);
        world.setBlock(i + 14, j + 0, k + 5, Blocks.netherrack);
        world.setBlock(i + 14, j + 0, k + 6, Blocks.nether_brick);
        world.setBlock(i + 14, j + 0, k + 7, Blocks.nether_brick);
        world.setBlock(i + 14, j + 0, k + 8, Blocks.nether_brick);
        world.setBlock(i + 14, j + 0, k + 9, Blocks.nether_brick);
        world.setBlock(i + 14, j + 0, k + 10, Blocks.netherrack);
        world.setBlock(i + 14, j + 0, k + 11, Blocks.nether_brick);
        world.setBlock(i + 14, j + 0, k + 12, Blocks.nether_brick);
        world.setBlock(i + 14, j + 0, k + 13, Blocks.nether_brick, 2, 0);
        world.setBlock(i + 14, j + 0, k + 14, Blocks.netherrack);
        world.setBlock(i + 14, j + 0, k + 15, Blocks.nether_brick);
        world.setBlock(i + 14, j + 0, k + 16, Blocks.nether_brick);
        world.setBlock(i + 14, j + 0, k + 17, Blocks.netherrack);
        world.setBlock(i + 14, j + 0, k + 18, Blocks.nether_brick);
        world.setBlock(i + 14, j + 0, k + 19, Blocks.nether_brick);
        world.setBlock(i + 14, j + 0, k + 20, Blocks.netherrack);
        world.setBlock(i + 14, j + 0, k + 21, Blocks.netherrack);
        world.setBlock(i + 14, j + 0, k + 22, Blocks.netherrack);
        world.setBlock(i + 14, j + 0, k + 23, Blocks.netherrack);
        world.setBlock(i + 14, j + 0, k + 24, Blocks.nether_brick, 2, 0);
        world.setBlock(i + 14, j + 0, k + 25, Blocks.netherrack);
        world.setBlock(i + 14, j + 1, k + 3, Blocks.nether_brick, 2, 0);
        world.setBlock(i + 14, j + 1, k + 4, Blocks.nether_brick, 2, 0);
        world.setBlock(i + 14, j + 1, k + 5, Blocks.nether_brick, 2, 0);
        world.setBlock(i + 14, j + 1, k + 6, Blocks.nether_brick, 2, 0);
        world.setBlock(i + 14, j + 1, k + 8, Blocks.nether_brick, 2, 0);
        world.setBlock(i + 14, j + 1, k + 14, Blocks.nether_brick, 2, 0);
        world.setBlock(i + 14, j + 1, k + 17, Blocks.nether_brick, 2, 0);
        world.setBlock(i + 14, j + 1, k + 21, Blocks.nether_brick, 2, 0);
        world.setBlock(i + 14, j + 1, k + 22, Blocks.nether_brick, 2, 0);
        world.setBlock(i + 14, j + 2, k + 4, Blocks.nether_brick, 2, 0);
        world.setBlock(i + 14, j + 12, k + 22, Blocks.nether_brick, 2, 0);
        world.setBlock(i + 15, j + 0, k + 0, Blocks.netherrack);
        world.setBlock(i + 15, j + 0, k + 1, Blocks.netherrack);
        world.setBlock(i + 15, j + 0, k + 2, Blocks.netherrack);
        world.setBlock(i + 15, j + 0, k + 3, Blocks.netherrack);
        world.setBlock(i + 15, j + 0, k + 4, Blocks.netherrack);
        world.setBlock(i + 15, j + 0, k + 5, Blocks.nether_brick);
        world.setBlock(i + 15, j + 0, k + 6, Blocks.netherrack);
        world.setBlock(i + 15, j + 0, k + 7, Blocks.netherrack);
        world.setBlock(i + 15, j + 0, k + 8, Blocks.nether_brick, 2, 0);
        world.setBlock(i + 15, j + 0, k + 9, Blocks.netherrack);
        world.setBlock(i + 15, j + 0, k + 10, Blocks.nether_brick);
        world.setBlock(i + 15, j + 0, k + 11, Blocks.netherrack);
        world.setBlock(i + 15, j + 0, k + 12, Blocks.nether_brick);
        world.setBlock(i + 15, j + 0, k + 13, Blocks.nether_brick, 2, 0);
        world.setBlock(i + 15, j + 0, k + 14, Blocks.netherrack);
        world.setBlock(i + 15, j + 0, k + 15, Blocks.nether_brick);
        world.setBlock(i + 15, j + 0, k + 16, Blocks.netherrack);
        world.setBlock(i + 15, j + 0, k + 17, Blocks.nether_brick);
        world.setBlock(i + 15, j + 0, k + 18, Blocks.nether_brick);
        world.setBlock(i + 15, j + 0, k + 19, Blocks.nether_brick, 2, 0);
        world.setBlock(i + 15, j + 0, k + 20, Blocks.netherrack);
        world.setBlock(i + 15, j + 0, k + 21, Blocks.netherrack);
        world.setBlock(i + 15, j + 0, k + 22, Blocks.nether_brick, 2, 0);
        world.setBlock(i + 15, j + 0, k + 23, Blocks.netherrack);
        world.setBlock(i + 15, j + 0, k + 24, Blocks.nether_brick);
        world.setBlock(i + 15, j + 0, k + 25, Blocks.nether_brick, 2, 0);
        world.setBlock(i + 15, j + 1, k + 2, Blocks.nether_brick, 2, 0);
        world.setBlock(i + 15, j + 1, k + 4, Blocks.nether_brick, 2, 0);
        world.setBlock(i + 15, j + 1, k + 5, Blocks.nether_brick_fence, 3, 0);
        world.setBlock(i + 15, j + 1, k + 7, Blocks.nether_brick, 2, 0);
        world.setBlock(i + 15, j + 1, k + 8, Blocks.nether_brick, 1, 0);
        world.setBlock(i + 15, j + 1, k + 9, Blocks.nether_brick, 2, 0);
        world.setBlock(i + 15, j + 1, k + 11, Blocks.nether_brick, 2, 0);
        world.setBlock(i + 15, j + 1, k + 12, Blocks.nether_brick_fence, 3, 0);
        world.setBlock(i + 15, j + 1, k + 13, Blocks.nether_brick, 2, 0);
        world.setBlock(i + 15, j + 1, k + 17, Blocks.nether_brick, 2, 0);
        world.setBlock(i + 15, j + 1, k + 18, Blocks.nether_brick, 2, 0);
        world.setBlock(i + 15, j + 1, k + 20, Blocks.nether_brick, 2, 0);
        world.setBlock(i + 15, j + 2, k + 4, Blocks.nether_brick, 2, 0);
        world.setBlock(i + 15, j + 2, k + 13, Blocks.nether_brick, 2, 0);
        world.setBlock(i + 15, j + 12, k + 21, Blocks.nether_brick, 2, 0);
        world.setBlock(i + 15, j + 12, k + 22, Blocks.nether_brick, 2, 0);
        world.setBlock(i + 16, j + 0, k + 0, Blocks.netherrack);
        world.setBlock(i + 16, j + 0, k + 1, Blocks.nether_brick);
        world.setBlock(i + 16, j + 0, k + 2, Blocks.nether_brick);
        world.setBlock(i + 16, j + 0, k + 3, Blocks.netherrack);
        world.setBlock(i + 16, j + 0, k + 4, Blocks.netherrack);
        world.setBlock(i + 16, j + 0, k + 5, Blocks.nether_brick);
        world.setBlock(i + 16, j + 0, k + 6, Blocks.nether_brick);
        world.setBlock(i + 16, j + 0, k + 7, Blocks.netherrack);
        world.setBlock(i + 16, j + 0, k + 8, Blocks.nether_brick, 2, 0);
        world.setBlock(i + 16, j + 0, k + 9, Blocks.netherrack);
        world.setBlock(i + 16, j + 0, k + 10, Blocks.nether_brick, 2, 0);
        world.setBlock(i + 16, j + 0, k + 11, Blocks.nether_brick);
        world.setBlock(i + 16, j + 0, k + 12, Blocks.nether_brick);
        world.setBlock(i + 16, j + 0, k + 13, Blocks.nether_brick, 2, 0);
        world.setBlock(i + 16, j + 0, k + 14, Blocks.nether_brick);
        world.setBlock(i + 16, j + 0, k + 15, Blocks.netherrack);
        world.setBlock(i + 16, j + 0, k + 16, Blocks.netherrack);
        world.setBlock(i + 16, j + 0, k + 17, Blocks.nether_brick);
        world.setBlock(i + 16, j + 0, k + 18, Blocks.netherrack);
        world.setBlock(i + 16, j + 0, k + 19, Blocks.nether_brick);
        world.setBlock(i + 16, j + 0, k + 20, Blocks.nether_brick);
        world.setBlock(i + 16, j + 0, k + 21, Blocks.netherrack);
        world.setBlock(i + 16, j + 0, k + 22, Blocks.nether_brick);
        world.setBlock(i + 16, j + 0, k + 23, Blocks.netherrack);
        world.setBlock(i + 16, j + 0, k + 24, Blocks.netherrack);
        world.setBlock(i + 16, j + 0, k + 25, Blocks.netherrack);
        world.setBlock(i + 16, j + 1, k + 4, Blocks.nether_brick, 2, 0);
        world.setBlock(i + 16, j + 1, k + 5, Blocks.nether_brick, 1, 0);
        world.setBlock(i + 16, j + 1, k + 6, Blocks.nether_brick, 1, 0);
        world.setBlock(i + 16, j + 1, k + 7, Blocks.nether_brick, 2, 0);
        WorldGenWarlordDungeon.chest(world, rand, i + 16, j + 1, k + 8, "NetherStructure", rand.nextInt(5) + 1);
        world.setBlock(i + 16, j + 1, k + 9, Blocks.nether_brick, 2, 0);
        world.setBlock(i + 16, j + 1, k + 10, Blocks.nether_brick, 2, 0);
        world.setBlock(i + 16, j + 1, k + 12, Blocks.nether_brick, 2, 0);
        world.setBlock(i + 16, j + 1, k + 14, Blocks.nether_brick, 2, 0);
        world.setBlock(i + 16, j + 1, k + 15, Blocks.nether_brick, 2, 0);
        world.setBlock(i + 16, j + 1, k + 17, Blocks.nether_brick, 2, 0);
        world.setBlock(i + 16, j + 1, k + 20, Blocks.nether_brick, 2, 0);
        world.setBlock(i + 16, j + 2, k + 4, Blocks.nether_brick, 2, 0);
        world.setBlock(i + 16, j + 2, k + 7, Blocks.nether_brick, 2, 0);
        world.setBlock(i + 16, j + 2, k + 14, Blocks.nether_brick, 2, 0);
        world.setBlock(i + 16, j + 2, k + 15, Blocks.nether_brick, 2, 0);
        world.setBlock(i + 16, j + 12, k + 21, Blocks.nether_brick, 2, 0);
        world.setBlock(i + 16, j + 12, k + 22, Blocks.nether_brick, 2, 0);
        world.setBlock(i + 16, j + 13, k + 21, Blocks.nether_brick_fence, 3, 0);
        world.setBlock(i + 17, j + 0, k + 0, Blocks.netherrack);
        world.setBlock(i + 17, j + 0, k + 1, Blocks.netherrack);
        world.setBlock(i + 17, j + 0, k + 2, Blocks.netherrack);
        world.setBlock(i + 17, j + 0, k + 3, Blocks.netherrack);
        world.setBlock(i + 17, j + 0, k + 4, Blocks.nether_brick);
        world.setBlock(i + 17, j + 0, k + 5, Blocks.netherrack);
        world.setBlock(i + 17, j + 0, k + 6, Blocks.netherrack);
        world.setBlock(i + 17, j + 0, k + 7, Blocks.nether_brick);
        world.setBlock(i + 17, j + 0, k + 8, Blocks.netherrack);
        world.setBlock(i + 17, j + 0, k + 9, Blocks.nether_brick);
        world.setBlock(i + 17, j + 0, k + 10, Blocks.netherrack);
        world.setBlock(i + 17, j + 0, k + 11, Blocks.nether_brick);
        world.setBlock(i + 17, j + 0, k + 12, Blocks.netherrack);
        world.setBlock(i + 17, j + 0, k + 13, Blocks.nether_brick);
        world.setBlock(i + 17, j + 0, k + 14, Blocks.netherrack);
        world.setBlock(i + 17, j + 0, k + 15, Blocks.nether_brick);
        world.setBlock(i + 17, j + 0, k + 16, Blocks.netherrack);
        world.setBlock(i + 17, j + 0, k + 17, Blocks.netherrack);
        world.setBlock(i + 17, j + 0, k + 18, Blocks.nether_brick);
        world.setBlock(i + 17, j + 0, k + 19, Blocks.netherrack);
        world.setBlock(i + 17, j + 0, k + 20, Blocks.netherrack);
        world.setBlock(i + 17, j + 0, k + 21, Blocks.nether_brick);
        world.setBlock(i + 17, j + 0, k + 22, Blocks.netherrack);
        world.setBlock(i + 17, j + 0, k + 23, Blocks.netherrack);
        world.setBlock(i + 17, j + 0, k + 24, Blocks.nether_brick);
        world.setBlock(i + 17, j + 0, k + 25, Blocks.netherrack);
        world.setBlock(i + 17, j + 1, k + 2, Blocks.nether_brick, 2, 0);
        world.setBlock(i + 17, j + 1, k + 4, Blocks.nether_brick, 1, 0);
        world.setBlock(i + 17, j + 1, k + 5, Blocks.nether_brick, 2, 0);
        world.setBlock(i + 17, j + 1, k + 11, Blocks.nether_brick, 1, 0);
        world.setBlock(i + 17, j + 1, k + 14, Blocks.nether_brick, 2, 0);
        world.setBlock(i + 17, j + 1, k + 15, Blocks.nether_brick, 2, 0);
        world.setBlock(i + 17, j + 1, k + 19, Blocks.nether_brick, 2, 0);
        world.setBlock(i + 17, j + 1, k + 22, Blocks.nether_brick, 1, 0);
        world.setBlock(i + 17, j + 1, k + 24, Blocks.nether_brick_fence, 3, 0);
        world.setBlock(i + 17, j + 11, k + 21, Blocks.nether_brick, 2, 0);
        world.setBlock(i + 17, j + 11, k + 22, Blocks.nether_brick, 2, 0);
        world.setBlock(i + 17, j + 12, k + 21, Blocks.nether_brick, 1, 0);
        world.setBlock(i + 17, j + 12, k + 22, Blocks.nether_brick, 1, 0);
        world.setBlock(i + 18, j + 0, k + 0, Blocks.netherrack);
        world.setBlock(i + 18, j + 0, k + 1, Blocks.nether_brick);
        world.setBlock(i + 18, j + 0, k + 2, Blocks.netherrack);
        world.setBlock(i + 18, j + 0, k + 3, Blocks.netherrack);
        world.setBlock(i + 18, j + 0, k + 4, Blocks.nether_brick);
        world.setBlock(i + 18, j + 0, k + 5, Blocks.nether_brick);
        world.setBlock(i + 18, j + 0, k + 6, Blocks.netherrack);
        world.setBlock(i + 18, j + 0, k + 7, Blocks.netherrack);
        world.setBlock(i + 18, j + 0, k + 8, Blocks.netherrack);
        world.setBlock(i + 18, j + 0, k + 9, Blocks.nether_brick);
        world.setBlock(i + 18, j + 0, k + 10, Blocks.netherrack);
        world.setBlock(i + 18, j + 0, k + 11, Blocks.nether_brick);
        world.setBlock(i + 18, j + 0, k + 12, Blocks.netherrack);
        world.setBlock(i + 18, j + 0, k + 13, Blocks.nether_brick);
        world.setBlock(i + 18, j + 0, k + 14, Blocks.netherrack);
        world.setBlock(i + 18, j + 0, k + 15, Blocks.netherrack);
        world.setBlock(i + 18, j + 0, k + 16, Blocks.netherrack);
        world.setBlock(i + 18, j + 0, k + 17, Blocks.nether_brick);
        world.setBlock(i + 18, j + 0, k + 18, Blocks.nether_brick);
        world.setBlock(i + 18, j + 0, k + 19, Blocks.nether_brick);
        world.setBlock(i + 18, j + 0, k + 20, Blocks.netherrack);
        world.setBlock(i + 18, j + 0, k + 21, Blocks.nether_brick);
        world.setBlock(i + 18, j + 0, k + 22, Blocks.nether_brick);
        world.setBlock(i + 18, j + 0, k + 23, Blocks.netherrack);
        world.setBlock(i + 18, j + 0, k + 24, Blocks.nether_brick, 2, 0);
        world.setBlock(i + 18, j + 0, k + 25, Blocks.netherrack);
        world.setBlock(i + 18, j + 1, k + 4, Blocks.nether_brick, 2, 0);
        world.setBlock(i + 18, j + 1, k + 6, Blocks.nether_brick_fence, 3, 0);
        world.setBlock(i + 18, j + 1, k + 8, Blocks.nether_brick, 2, 0);
        world.setBlock(i + 18, j + 1, k + 10, Blocks.nether_brick_fence, 3, 0);
        world.setBlock(i + 18, j + 1, k + 11, Blocks.nether_brick_fence, 3, 0);
        world.setBlock(i + 18, j + 1, k + 13, Blocks.nether_brick_fence, 3, 0);
        Dungeons.spawner(world, i + 18, j + 1, k + 16, 16, 2);
        world.setBlock(i + 18, j + 1, k + 17, Blocks.nether_brick, 2, 0);
        world.setBlock(i + 18, j + 1, k + 18, Blocks.nether_brick_fence, 3, 0);
        world.setBlock(i + 18, j + 1, k + 20, Blocks.nether_brick, 2, 0);
        world.setBlock(i + 18, j + 2, k + 4, Blocks.nether_brick, 1, 0);
        world.setBlock(i + 18, j + 11, k + 21, Blocks.nether_brick, 2, 0);
        world.setBlock(i + 18, j + 11, k + 22, Blocks.nether_brick, 1, 0);
        world.setBlock(i + 18, j + 12, k + 21, Blocks.nether_brick, 2, 0);
        world.setBlock(i + 18, j + 12, k + 22, Blocks.nether_brick, 2, 0);
        world.setBlock(i + 18, j + 13, k + 22, Blocks.nether_brick, 2, 0);
        world.setBlock(i + 19, j + 0, k + 0, Blocks.netherrack);
        world.setBlock(i + 19, j + 0, k + 1, Blocks.nether_brick, 2, 0);
        world.setBlock(i + 19, j + 0, k + 2, Blocks.netherrack);
        world.setBlock(i + 19, j + 0, k + 3, Blocks.netherrack);
        world.setBlock(i + 19, j + 0, k + 4, Blocks.netherrack);
        world.setBlock(i + 19, j + 0, k + 5, Blocks.netherrack);
        world.setBlock(i + 19, j + 0, k + 6, Blocks.netherrack);
        world.setBlock(i + 19, j + 0, k + 7, Blocks.nether_brick);
        world.setBlock(i + 19, j + 0, k + 8, Blocks.netherrack);
        world.setBlock(i + 19, j + 0, k + 9, Blocks.nether_brick);
        world.setBlock(i + 19, j + 0, k + 10, Blocks.netherrack);
        world.setBlock(i + 19, j + 0, k + 11, Blocks.netherrack);
        world.setBlock(i + 19, j + 0, k + 12, Blocks.nether_brick, 2, 0);
        world.setBlock(i + 19, j + 0, k + 13, Blocks.netherrack);
        world.setBlock(i + 19, j + 0, k + 14, Blocks.netherrack);
        world.setBlock(i + 19, j + 0, k + 15, Blocks.nether_brick);
        world.setBlock(i + 19, j + 0, k + 16, Blocks.nether_brick);
        world.setBlock(i + 19, j + 0, k + 17, Blocks.nether_brick);
        world.setBlock(i + 19, j + 0, k + 18, Blocks.nether_brick);
        world.setBlock(i + 19, j + 0, k + 19, Blocks.netherrack);
        world.setBlock(i + 19, j + 0, k + 20, Blocks.nether_brick, 2, 0);
        world.setBlock(i + 19, j + 0, k + 21, Blocks.nether_brick);
        world.setBlock(i + 19, j + 0, k + 22, Blocks.nether_brick);
        world.setBlock(i + 19, j + 0, k + 23, Blocks.netherrack);
        world.setBlock(i + 19, j + 0, k + 24, Blocks.netherrack);
        world.setBlock(i + 19, j + 0, k + 25, Blocks.netherrack);
        world.setBlock(i + 19, j + 1, k + 2, Blocks.nether_brick, 2, 0);
        world.setBlock(i + 19, j + 1, k + 4, Blocks.nether_brick, 2, 0);
        world.setBlock(i + 19, j + 1, k + 5, Blocks.nether_brick, 2, 0);
        world.setBlock(i + 19, j + 1, k + 7, Blocks.nether_brick, 2, 0);
        world.setBlock(i + 19, j + 1, k + 8, Blocks.nether_brick, 2, 0);
        world.setBlock(i + 19, j + 1, k + 11, Blocks.nether_brick, 2, 0);
        world.setBlock(i + 19, j + 1, k + 15, Blocks.nether_brick_fence, 3, 0);
        world.setBlock(i + 19, j + 1, k + 16, Blocks.nether_brick_fence, 3, 0);
        world.setBlock(i + 19, j + 1, k + 18, Blocks.nether_brick, 2, 0);
        world.setBlock(i + 19, j + 1, k + 22, Blocks.nether_brick_fence, 3, 0);
        world.setBlock(i + 19, j + 2, k + 4, Blocks.nether_brick, 2, 0);
        world.setBlock(i + 19, j + 2, k + 5, Blocks.nether_brick, 2, 0);
        world.setBlock(i + 19, j + 2, k + 7, Blocks.nether_brick, 2, 0);
        world.setBlock(i + 19, j + 2, k + 11, Blocks.nether_brick, 1, 0);
        world.setBlock(i + 19, j + 10, k + 21, Blocks.nether_brick, 2, 0);
        world.setBlock(i + 19, j + 10, k + 22, Blocks.nether_brick, 2, 0);
        world.setBlock(i + 19, j + 11, k + 22, Blocks.nether_brick, 2, 0);
        world.setBlock(i + 19, j + 12, k + 21, Blocks.nether_brick, 2, 0);
        world.setBlock(i + 19, j + 12, k + 22, Blocks.nether_brick, 1, 0);
        world.setBlock(i + 20, j + 0, k + 0, Blocks.netherrack);
        world.setBlock(i + 20, j + 0, k + 1, Blocks.netherrack);
        world.setBlock(i + 20, j + 0, k + 2, Blocks.nether_brick, 2, 0);
        world.setBlock(i + 20, j + 0, k + 3, Blocks.netherrack);
        world.setBlock(i + 20, j + 0, k + 4, Blocks.nether_brick, 2, 0);
        world.setBlock(i + 20, j + 0, k + 5, Blocks.netherrack);
        world.setBlock(i + 20, j + 0, k + 6, Blocks.nether_brick);
        world.setBlock(i + 20, j + 0, k + 7, Blocks.nether_brick);
        world.setBlock(i + 20, j + 0, k + 8, Blocks.netherrack);
        world.setBlock(i + 20, j + 0, k + 9, Blocks.netherrack);
        world.setBlock(i + 20, j + 0, k + 10, Blocks.nether_brick);
        world.setBlock(i + 20, j + 0, k + 11, Blocks.netherrack);
        world.setBlock(i + 20, j + 0, k + 12, Blocks.nether_brick);
        world.setBlock(i + 20, j + 0, k + 13, Blocks.netherrack);
        world.setBlock(i + 20, j + 0, k + 14, Blocks.netherrack);
        world.setBlock(i + 20, j + 0, k + 15, Blocks.nether_brick);
        world.setBlock(i + 20, j + 0, k + 16, Blocks.nether_brick);
        world.setBlock(i + 20, j + 0, k + 17, Blocks.nether_brick);
        world.setBlock(i + 20, j + 0, k + 18, Blocks.netherrack);
        world.setBlock(i + 20, j + 0, k + 19, Blocks.nether_brick, 2, 0);
        world.setBlock(i + 20, j + 0, k + 20, Blocks.netherrack);
        world.setBlock(i + 20, j + 0, k + 21, Blocks.nether_brick, 2, 0);
        world.setBlock(i + 20, j + 0, k + 22, Blocks.nether_brick);
        world.setBlock(i + 20, j + 0, k + 23, Blocks.nether_brick, 2, 0);
        world.setBlock(i + 20, j + 0, k + 24, Blocks.nether_brick);
        world.setBlock(i + 20, j + 0, k + 25, Blocks.nether_brick);
        world.setBlock(i + 20, j + 1, k + 5, Blocks.nether_brick, 1, 0);
        world.setBlock(i + 20, j + 1, k + 8, Blocks.nether_brick_fence, 3, 0);
        world.setBlock(i + 20, j + 1, k + 11, Blocks.nether_brick, 2, 0);
        world.setBlock(i + 20, j + 1, k + 13, Blocks.nether_brick, 2, 0);
        world.setBlock(i + 20, j + 10, k + 21, Blocks.nether_brick, 2, 0);
        world.setBlock(i + 20, j + 10, k + 22, Blocks.nether_brick, 2, 0);
        world.setBlock(i + 20, j + 11, k + 21, Blocks.nether_brick, 2, 0);
        world.setBlock(i + 20, j + 11, k + 22, Blocks.nether_brick, 1, 0);
        world.setBlock(i + 20, j + 12, k + 21, Blocks.nether_brick, 1, 0);
        world.setBlock(i + 20, j + 12, k + 22, Blocks.nether_brick, 2, 0);
        world.setBlock(i + 20, j + 13, k + 21, Blocks.nether_brick_fence, 3, 0);
        world.setBlock(i + 21, j + 0, k + 0, Blocks.netherrack);
        world.setBlock(i + 21, j + 0, k + 1, Blocks.netherrack);
        world.setBlock(i + 21, j + 0, k + 2, Blocks.netherrack);
        world.setBlock(i + 21, j + 0, k + 3, Blocks.netherrack);
        world.setBlock(i + 21, j + 0, k + 4, Blocks.netherrack);
        world.setBlock(i + 21, j + 0, k + 5, Blocks.nether_brick);
        world.setBlock(i + 21, j + 0, k + 6, Blocks.nether_brick, 2, 0);
        world.setBlock(i + 21, j + 0, k + 7, Blocks.netherrack);
        world.setBlock(i + 21, j + 0, k + 8, Blocks.nether_brick);
        world.setBlock(i + 21, j + 0, k + 9, Blocks.netherrack);
        world.setBlock(i + 21, j + 0, k + 10, Blocks.netherrack);
        world.setBlock(i + 21, j + 0, k + 11, Blocks.nether_brick);
        world.setBlock(i + 21, j + 0, k + 12, Blocks.nether_brick);
        world.setBlock(i + 21, j + 0, k + 13, Blocks.nether_brick);
        world.setBlock(i + 21, j + 0, k + 14, Blocks.nether_brick);
        world.setBlock(i + 21, j + 0, k + 15, Blocks.netherrack);
        world.setBlock(i + 21, j + 0, k + 16, Blocks.nether_brick);
        world.setBlock(i + 21, j + 0, k + 17, Blocks.netherrack);
        world.setBlock(i + 21, j + 0, k + 18, Blocks.netherrack);
        world.setBlock(i + 21, j + 0, k + 19, Blocks.nether_brick);
        world.setBlock(i + 21, j + 0, k + 20, Blocks.netherrack);
        world.setBlock(i + 21, j + 0, k + 21, Blocks.nether_brick);
        world.setBlock(i + 21, j + 0, k + 22, Blocks.nether_brick);
        world.setBlock(i + 21, j + 0, k + 23, Blocks.nether_brick);
        world.setBlock(i + 21, j + 0, k + 24, Blocks.netherrack);
        world.setBlock(i + 21, j + 0, k + 25, Blocks.netherrack);
        world.setBlock(i + 21, j + 1, k + 1, Blocks.nether_brick, 2, 0);
        world.setBlock(i + 21, j + 1, k + 4, Blocks.nether_brick, 2, 0);
        world.setBlock(i + 21, j + 1, k + 6, Blocks.nether_brick, 2, 0);
        world.setBlock(i + 21, j + 1, k + 7, Blocks.nether_brick, 2, 0);
        world.setBlock(i + 21, j + 1, k + 9, Blocks.nether_brick, 1, 0);
        world.setBlock(i + 21, j + 1, k + 10, Blocks.nether_brick, 2, 0);
        world.setBlock(i + 21, j + 1, k + 11, Blocks.nether_brick, 1, 0);
        world.setBlock(i + 21, j + 1, k + 13, Blocks.nether_brick, 2, 0);
        world.setBlock(i + 21, j + 1, k + 15, Blocks.nether_brick, 2, 0);
        world.setBlock(i + 21, j + 1, k + 17, Blocks.nether_brick_fence, 3, 0);
        world.setBlock(i + 21, j + 1, k + 19, Blocks.nether_brick, 2, 0);
        world.setBlock(i + 21, j + 1, k + 21, Blocks.nether_brick_fence, 3, 0);
        world.setBlock(i + 21, j + 1, k + 25, Blocks.nether_brick_fence, 3, 0);
        world.setBlock(i + 21, j + 9, k + 21, Blocks.nether_brick, 2, 0);
        world.setBlock(i + 21, j + 9, k + 22, Blocks.nether_brick, 2, 0);
        world.setBlock(i + 21, j + 10, k + 21, Blocks.nether_brick, 2, 0);
        world.setBlock(i + 21, j + 10, k + 22, Blocks.nether_brick, 2, 0);
        world.setBlock(i + 21, j + 11, k + 21, Blocks.nether_brick, 1, 0);
        world.setBlock(i + 21, j + 11, k + 22, Blocks.nether_brick, 1, 0);
        world.setBlock(i + 21, j + 12, k + 21, Blocks.nether_brick, 1, 0);
        world.setBlock(i + 21, j + 12, k + 22, Blocks.nether_brick, 2, 0);
        world.setBlock(i + 22, j + 0, k + 0, Blocks.netherrack);
        world.setBlock(i + 22, j + 0, k + 1, Blocks.netherrack);
        world.setBlock(i + 22, j + 0, k + 2, Blocks.nether_brick, 2, 0);
        world.setBlock(i + 22, j + 0, k + 3, Blocks.netherrack);
        world.setBlock(i + 22, j + 0, k + 4, Blocks.nether_brick);
        world.setBlock(i + 22, j + 0, k + 5, Blocks.netherrack);
        world.setBlock(i + 22, j + 0, k + 6, Blocks.nether_brick);
        world.setBlock(i + 22, j + 0, k + 7, Blocks.nether_brick);
        world.setBlock(i + 22, j + 0, k + 8, Blocks.netherrack);
        world.setBlock(i + 22, j + 0, k + 9, Blocks.nether_brick);
        world.setBlock(i + 22, j + 0, k + 10, Blocks.nether_brick);
        world.setBlock(i + 22, j + 0, k + 11, Blocks.netherrack);
        world.setBlock(i + 22, j + 0, k + 12, Blocks.nether_brick, 2, 0);
        world.setBlock(i + 22, j + 0, k + 13, Blocks.netherrack);
        world.setBlock(i + 22, j + 0, k + 14, Blocks.nether_brick);
        world.setBlock(i + 22, j + 0, k + 15, Blocks.netherrack);
        world.setBlock(i + 22, j + 0, k + 16, Blocks.nether_brick);
        world.setBlock(i + 22, j + 0, k + 17, Blocks.nether_brick);
        world.setBlock(i + 22, j + 0, k + 18, Blocks.netherrack);
        world.setBlock(i + 22, j + 0, k + 19, Blocks.netherrack);
        world.setBlock(i + 22, j + 0, k + 20, Blocks.nether_brick);
        world.setBlock(i + 22, j + 0, k + 21, Blocks.nether_brick);
        world.setBlock(i + 22, j + 0, k + 22, Blocks.nether_brick);
        world.setBlock(i + 22, j + 0, k + 23, Blocks.netherrack);
        world.setBlock(i + 22, j + 0, k + 24, Blocks.nether_brick, 2, 0);
        world.setBlock(i + 22, j + 0, k + 25, Blocks.nether_brick);
        world.setBlock(i + 22, j + 1, k + 5, Blocks.nether_brick_fence, 3, 0);
        world.setBlock(i + 22, j + 1, k + 8, Blocks.nether_brick, 2, 0);
        world.setBlock(i + 22, j + 1, k + 11, Blocks.nether_brick, 2, 0);
        world.setBlock(i + 22, j + 1, k + 13, Blocks.nether_brick, 2, 0);
        world.setBlock(i + 22, j + 1, k + 15, Blocks.nether_brick, 2, 0);
        world.setBlock(i + 22, j + 1, k + 16, Blocks.nether_brick, 2, 0);
        world.setBlock(i + 22, j + 1, k + 18, Blocks.nether_brick, 2, 0);
        world.setBlock(i + 22, j + 1, k + 19, Blocks.nether_brick, 2, 0);
        world.setBlock(i + 22, j + 2, k + 8, Blocks.nether_brick, 1, 0);
        world.setBlock(i + 22, j + 2, k + 16, Blocks.nether_brick, 2, 0);
        world.setBlock(i + 22, j + 8, k + 21, Blocks.nether_brick, 2, 0);
        world.setBlock(i + 22, j + 8, k + 22, Blocks.nether_brick, 1, 0);
        world.setBlock(i + 22, j + 9, k + 21, Blocks.nether_brick, 2, 0);
        world.setBlock(i + 22, j + 9, k + 22, Blocks.nether_brick, 2, 0);
        world.setBlock(i + 22, j + 10, k + 21, Blocks.nether_brick, 2, 0);
        world.setBlock(i + 22, j + 10, k + 22, Blocks.nether_brick, 1, 0);
        world.setBlock(i + 22, j + 11, k + 21, Blocks.nether_brick, 2, 0);
        world.setBlock(i + 22, j + 11, k + 22, Blocks.nether_brick, 2, 0);
        world.setBlock(i + 22, j + 12, k + 21, Blocks.nether_brick, 2, 0);
        world.setBlock(i + 22, j + 12, k + 22, Blocks.nether_brick, 2, 0);
        world.setBlock(i + 22, j + 14, k + 22, Blocks.nether_brick, 2, 0);
        world.setBlock(i + 23, j + 0, k + 0, Blocks.netherrack);
        world.setBlock(i + 23, j + 0, k + 1, Blocks.nether_brick);
        world.setBlock(i + 23, j + 0, k + 2, Blocks.netherrack);
        world.setBlock(i + 23, j + 0, k + 3, Blocks.netherrack);
        world.setBlock(i + 23, j + 0, k + 4, Blocks.nether_brick, 2, 0);
        world.setBlock(i + 23, j + 0, k + 5, Blocks.netherrack);
        world.setBlock(i + 23, j + 0, k + 6, Blocks.nether_brick);
        world.setBlock(i + 23, j + 0, k + 7, Blocks.netherrack);
        world.setBlock(i + 23, j + 0, k + 8, Blocks.netherrack);
        world.setBlock(i + 23, j + 0, k + 9, Blocks.nether_brick, 2, 0);
        world.setBlock(i + 23, j + 0, k + 10, Blocks.netherrack);
        world.setBlock(i + 23, j + 0, k + 11, Blocks.netherrack);
        world.setBlock(i + 23, j + 0, k + 12, Blocks.netherrack);
        world.setBlock(i + 23, j + 0, k + 13, Blocks.nether_brick, 2, 0);
        world.setBlock(i + 23, j + 0, k + 14, Blocks.netherrack);
        world.setBlock(i + 23, j + 0, k + 15, Blocks.nether_brick);
        world.setBlock(i + 23, j + 0, k + 16, Blocks.netherrack);
        world.setBlock(i + 23, j + 0, k + 17, Blocks.nether_brick);
        world.setBlock(i + 23, j + 0, k + 18, Blocks.netherrack);
        world.setBlock(i + 23, j + 0, k + 19, Blocks.nether_brick);
        world.setBlock(i + 23, j + 0, k + 20, Blocks.netherrack);
        world.setBlock(i + 23, j + 0, k + 21, Blocks.nether_brick);
        world.setBlock(i + 23, j + 0, k + 22, Blocks.nether_brick);
        world.setBlock(i + 23, j + 0, k + 23, Blocks.netherrack);
        world.setBlock(i + 23, j + 0, k + 24, Blocks.netherrack);
        world.setBlock(i + 23, j + 0, k + 25, Blocks.netherrack);
        world.setBlock(i + 23, j + 1, k + 3, Blocks.nether_brick, 2, 0);
        world.setBlock(i + 23, j + 1, k + 4, Blocks.nether_brick, 2, 0);
        world.setBlock(i + 23, j + 1, k + 5, Blocks.nether_brick, 2, 0);
        world.setBlock(i + 23, j + 1, k + 8, Blocks.nether_brick, 2, 0);
        world.setBlock(i + 23, j + 1, k + 10, Blocks.nether_brick, 2, 0);
        world.setBlock(i + 23, j + 1, k + 11, Blocks.nether_brick, 2, 0);
        world.setBlock(i + 23, j + 1, k + 12, Blocks.nether_brick, 2, 0);
        world.setBlock(i + 23, j + 1, k + 13, Blocks.nether_brick, 1, 0);
        world.setBlock(i + 23, j + 1, k + 14, Blocks.nether_brick, 2, 0);
        world.setBlock(i + 23, j + 1, k + 15, Blocks.nether_brick, 2, 0);
        world.setBlock(i + 23, j + 1, k + 16, Blocks.nether_brick, 1, 0);
        world.setBlock(i + 23, j + 1, k + 19, Blocks.nether_brick, 2, 0);
        world.setBlock(i + 23, j + 1, k + 20, Blocks.nether_brick, 2, 0);
        world.setBlock(i + 23, j + 1, k + 21, Blocks.nether_brick, 2, 0);
        world.setBlock(i + 23, j + 1, k + 22, Blocks.nether_brick, 1, 0);
        world.setBlock(i + 23, j + 1, k + 23, Blocks.nether_brick, 2, 0);
        world.setBlock(i + 23, j + 1, k + 24, Blocks.nether_brick, 2, 0);
        world.setBlock(i + 23, j + 2, k + 4, Blocks.nether_brick, 2, 0);
        world.setBlock(i + 23, j + 2, k + 5, Blocks.nether_brick, 2, 0);
        world.setBlock(i + 23, j + 2, k + 8, Blocks.nether_brick, 2, 0);
        world.setBlock(i + 23, j + 2, k + 9, Blocks.nether_brick, 1, 0);
        world.setBlock(i + 23, j + 2, k + 12, Blocks.nether_brick, 2, 0);
        world.setBlock(i + 23, j + 2, k + 14, Blocks.nether_brick, 1, 0);
        world.setBlock(i + 23, j + 2, k + 21, Blocks.nether_brick, 2, 0);
        world.setBlock(i + 23, j + 2, k + 22, Blocks.nether_brick, 1, 0);
        world.setBlock(i + 23, j + 3, k + 4, Blocks.nether_brick, 2, 0);
        world.setBlock(i + 23, j + 3, k + 5, Blocks.nether_brick, 2, 0);
        world.setBlock(i + 23, j + 3, k + 21, Blocks.nether_brick, 1, 0);
        world.setBlock(i + 23, j + 3, k + 22, Blocks.nether_brick, 1, 0);
        world.setBlock(i + 23, j + 4, k + 4, Blocks.nether_brick, 1, 0);
        world.setBlock(i + 23, j + 4, k + 5, Blocks.nether_brick, 2, 0);
        world.setBlock(i + 23, j + 4, k + 21, Blocks.nether_brick, 1, 0);
        world.setBlock(i + 23, j + 4, k + 22, Blocks.nether_brick, 1, 0);
        world.setBlock(i + 23, j + 5, k + 4, Blocks.nether_brick, 1, 0);
        world.setBlock(i + 23, j + 5, k + 21, Blocks.nether_brick, 2, 0);
        world.setBlock(i + 23, j + 5, k + 22, Blocks.nether_brick, 2, 0);
        world.setBlock(i + 23, j + 6, k + 4, Blocks.nether_brick, 2, 0);
        world.setBlock(i + 23, j + 6, k + 21, Blocks.nether_brick, 2, 0);
        world.setBlock(i + 23, j + 6, k + 22, Blocks.nether_brick, 2, 0);
        world.setBlock(i + 23, j + 7, k + 21, Blocks.nether_brick, 2, 0);
        world.setBlock(i + 23, j + 7, k + 22, Blocks.nether_brick, 2, 0);
        world.setBlock(i + 23, j + 8, k + 20, Blocks.nether_brick, 1, 0);
        world.setBlock(i + 23, j + 8, k + 21, Blocks.nether_brick, 2, 0);
        world.setBlock(i + 23, j + 8, k + 22, Blocks.nether_brick, 2, 0);
        world.setBlock(i + 23, j + 9, k + 19, Blocks.nether_brick, 2, 0);
        world.setBlock(i + 23, j + 9, k + 20, Blocks.nether_brick, 2, 0);
        world.setBlock(i + 23, j + 9, k + 21, Blocks.nether_brick, 2, 0);
        world.setBlock(i + 23, j + 9, k + 22, Blocks.nether_brick, 1, 0);
        world.setBlock(i + 23, j + 10, k + 16, Blocks.nether_brick, 2, 0);
        world.setBlock(i + 23, j + 10, k + 17, Blocks.nether_brick, 2, 0);
        world.setBlock(i + 23, j + 10, k + 18, Blocks.nether_brick, 2, 0);
        world.setBlock(i + 23, j + 10, k + 19, Blocks.nether_brick, 2, 0);
        world.setBlock(i + 23, j + 10, k + 20, Blocks.nether_brick, 1, 0);
        world.setBlock(i + 23, j + 10, k + 21, Blocks.nether_brick, 2, 0);
        world.setBlock(i + 23, j + 10, k + 22, Blocks.nether_brick, 2, 0);
        world.setBlock(i + 23, j + 11, k + 18, Blocks.nether_brick, 2, 0);
        world.setBlock(i + 23, j + 11, k + 19, Blocks.nether_brick_fence, 3, 0);
        world.setBlock(i + 23, j + 11, k + 20, Blocks.nether_brick, 2, 0);
        world.setBlock(i + 23, j + 11, k + 21, Blocks.nether_brick, 2, 0);
        world.setBlock(i + 23, j + 11, k + 22, Blocks.nether_brick, 2, 0);
        world.setBlock(i + 23, j + 12, k + 21, Blocks.nether_brick, 2, 0);
        world.setBlock(i + 23, j + 12, k + 22, Blocks.nether_brick, 1, 0);
        world.setBlock(i + 23, j + 13, k + 21, Blocks.nether_brick_fence, 3, 0);
        world.setBlock(i + 23, j + 13, k + 22, Blocks.nether_brick, 2, 0);
        world.setBlock(i + 23, j + 14, k + 22, Blocks.nether_brick, 2, 0);
        world.setBlock(i + 23, j + 15, k + 22, Blocks.nether_brick, 2, 0);
        world.setBlock(i + 24, j + 0, k + 0, Blocks.netherrack);
        world.setBlock(i + 24, j + 0, k + 1, Blocks.netherrack);
        world.setBlock(i + 24, j + 0, k + 2, Blocks.netherrack);
        world.setBlock(i + 24, j + 0, k + 3, Blocks.nether_brick);
        world.setBlock(i + 24, j + 0, k + 4, Blocks.netherrack);
        world.setBlock(i + 24, j + 0, k + 5, Blocks.nether_brick);
        world.setBlock(i + 24, j + 0, k + 6, Blocks.netherrack);
        world.setBlock(i + 24, j + 0, k + 7, Blocks.nether_brick);
        world.setBlock(i + 24, j + 0, k + 8, Blocks.nether_brick);
        world.setBlock(i + 24, j + 0, k + 9, Blocks.netherrack);
        world.setBlock(i + 24, j + 0, k + 10, Blocks.netherrack);
        world.setBlock(i + 24, j + 0, k + 11, Blocks.nether_brick);
        world.setBlock(i + 24, j + 0, k + 12, Blocks.nether_brick);
        world.setBlock(i + 24, j + 0, k + 13, Blocks.nether_brick);
        world.setBlock(i + 24, j + 0, k + 14, Blocks.netherrack);
        world.setBlock(i + 24, j + 0, k + 15, Blocks.nether_brick);
        world.setBlock(i + 24, j + 0, k + 16, Blocks.netherrack);
        world.setBlock(i + 24, j + 0, k + 17, Blocks.nether_brick);
        world.setBlock(i + 24, j + 0, k + 18, Blocks.nether_brick);
        world.setBlock(i + 24, j + 0, k + 19, Blocks.nether_brick);
        world.setBlock(i + 24, j + 0, k + 20, Blocks.netherrack);
        world.setBlock(i + 24, j + 0, k + 21, Blocks.netherrack);
        world.setBlock(i + 24, j + 0, k + 22, Blocks.netherrack);
        world.setBlock(i + 24, j + 0, k + 23, Blocks.netherrack);
        world.setBlock(i + 24, j + 0, k + 24, Blocks.netherrack);
        world.setBlock(i + 24, j + 0, k + 25, Blocks.netherrack);
        world.setBlock(i + 24, j + 1, k + 1, Blocks.nether_brick, 2, 0);
        world.setBlock(i + 24, j + 1, k + 4, Blocks.nether_brick, 2, 0);
        world.setBlock(i + 24, j + 1, k + 5, Blocks.nether_brick, 1, 0);
        world.setBlock(i + 24, j + 1, k + 6, Blocks.nether_brick, 2, 0);
        world.setBlock(i + 24, j + 1, k + 7, Blocks.nether_brick, 2, 0);
        world.setBlock(i + 24, j + 1, k + 9, Blocks.nether_brick, 2, 0);
        world.setBlock(i + 24, j + 1, k + 14, Blocks.nether_brick, 2, 0);
        world.setBlock(i + 24, j + 1, k + 16, Blocks.nether_brick, 2, 0);
        world.setBlock(i + 24, j + 1, k + 20, Blocks.nether_brick, 2, 0);
        world.setBlock(i + 24, j + 1, k + 21, Blocks.nether_brick, 2, 0);
        world.setBlock(i + 24, j + 1, k + 22, Blocks.nether_brick, 2, 0);
        world.setBlock(i + 24, j + 1, k + 23, Blocks.nether_brick_fence, 3, 0);
        world.setBlock(i + 24, j + 2, k + 4, Blocks.nether_brick, 2, 0);
        world.setBlock(i + 24, j + 2, k + 5, Blocks.nether_brick, 1, 0);
        world.setBlock(i + 24, j + 2, k + 6, Blocks.nether_brick, 2, 0);
        world.setBlock(i + 24, j + 2, k + 9, Blocks.nether_brick, 2, 0);
        world.setBlock(i + 24, j + 2, k + 21, Blocks.nether_brick, 1, 0);
        world.setBlock(i + 24, j + 2, k + 22, Blocks.nether_brick, 1, 0);
        world.setBlock(i + 24, j + 3, k + 4, Blocks.nether_brick, 1, 0);
        world.setBlock(i + 24, j + 3, k + 5, Blocks.nether_brick, 1, 0);
        world.setBlock(i + 24, j + 3, k + 21, Blocks.nether_brick, 1, 0);
        world.setBlock(i + 24, j + 3, k + 22, Blocks.nether_brick, 2, 0);
        world.setBlock(i + 24, j + 4, k + 4, Blocks.nether_brick, 2, 0);
        world.setBlock(i + 24, j + 4, k + 5, Blocks.nether_brick, 2, 0);
        world.setBlock(i + 24, j + 4, k + 21, Blocks.nether_brick, 1, 0);
        world.setBlock(i + 24, j + 4, k + 22, Blocks.nether_brick, 1, 0);
        world.setBlock(i + 24, j + 5, k + 4, Blocks.nether_brick, 1, 0);
        world.setBlock(i + 24, j + 5, k + 5, Blocks.nether_brick, 2, 0);
        world.setBlock(i + 24, j + 5, k + 21, Blocks.nether_brick, 2, 0);
        world.setBlock(i + 24, j + 5, k + 22, Blocks.nether_brick, 2, 0);
        world.setBlock(i + 24, j + 6, k + 4, Blocks.nether_brick, 2, 0);
        world.setBlock(i + 24, j + 6, k + 5, Blocks.nether_brick, 2, 0);
        world.setBlock(i + 24, j + 6, k + 21, Blocks.nether_brick, 1, 0);
        world.setBlock(i + 24, j + 6, k + 22, Blocks.nether_brick, 2, 0);
        world.setBlock(i + 24, j + 7, k + 4, Blocks.nether_brick, 2, 0);
        world.setBlock(i + 24, j + 7, k + 21, Blocks.nether_brick, 2, 0);
        world.setBlock(i + 24, j + 7, k + 22, Blocks.nether_brick, 2, 0);
        world.setBlock(i + 24, j + 8, k + 4, Blocks.nether_brick, 2, 0);
        world.setBlock(i + 24, j + 8, k + 5, Blocks.nether_brick, 2, 0);
        world.setBlock(i + 24, j + 8, k + 20, Blocks.nether_brick, 2, 0);
        world.setBlock(i + 24, j + 8, k + 21, Blocks.nether_brick, 2, 0);
        world.setBlock(i + 24, j + 8, k + 22, Blocks.nether_brick, 2, 0);
        world.setBlock(i + 24, j + 9, k + 4, Blocks.nether_brick, 2, 0);
        world.setBlock(i + 24, j + 9, k + 19, Blocks.nether_brick, 2, 0);
        world.setBlock(i + 24, j + 9, k + 20, Blocks.nether_brick, 2, 0);
        world.setBlock(i + 24, j + 9, k + 21, Blocks.nether_brick, 1, 0);
        world.setBlock(i + 24, j + 9, k + 22, Blocks.nether_brick, 2, 0);
        world.setBlock(i + 24, j + 10, k + 18, Blocks.nether_brick, 2, 0);
        world.setBlock(i + 24, j + 10, k + 19, Blocks.nether_brick, 2, 0);
        world.setBlock(i + 24, j + 10, k + 20, Blocks.nether_brick, 2, 0);
        world.setBlock(i + 24, j + 10, k + 21, Blocks.nether_brick, 2, 0);
        world.setBlock(i + 24, j + 10, k + 22, Blocks.nether_brick, 1, 0);
        world.setBlock(i + 24, j + 11, k + 20, Blocks.nether_brick_fence, 3, 0);
        world.setBlock(i + 24, j + 11, k + 21, Blocks.nether_brick, 2, 0);
        world.setBlock(i + 24, j + 11, k + 22, Blocks.nether_brick, 2, 0);
        world.setBlock(i + 24, j + 12, k + 21, Blocks.nether_brick, 2, 0);
        world.setBlock(i + 24, j + 12, k + 22, Blocks.nether_brick, 2, 0);
        world.setBlock(i + 24, j + 13, k + 21, Blocks.nether_brick, 2, 0);
        world.setBlock(i + 24, j + 13, k + 22, Blocks.nether_brick, 1, 0);
        world.setBlock(i + 24, j + 14, k + 21, Blocks.nether_brick, 2, 0);
        world.setBlock(i + 24, j + 14, k + 22, Blocks.nether_brick, 2, 0);
        world.setBlock(i + 24, j + 15, k + 22, Blocks.nether_brick, 1, 0);
        world.setBlock(i + 24, j + 16, k + 22, Blocks.nether_brick, 2, 0);
        world.setBlock(i + 25, j + 0, k + 0, Blocks.netherrack);
        world.setBlock(i + 25, j + 0, k + 1, Blocks.netherrack);
        world.setBlock(i + 25, j + 0, k + 2, Blocks.netherrack);
        world.setBlock(i + 25, j + 0, k + 3, Blocks.netherrack);
        world.setBlock(i + 25, j + 0, k + 4, Blocks.netherrack);
        world.setBlock(i + 25, j + 0, k + 5, Blocks.netherrack);
        world.setBlock(i + 25, j + 0, k + 6, Blocks.nether_brick, 2, 0);
        world.setBlock(i + 25, j + 0, k + 7, Blocks.netherrack);
        world.setBlock(i + 25, j + 0, k + 8, Blocks.nether_brick, 2, 0);
        world.setBlock(i + 25, j + 0, k + 9, Blocks.netherrack);
        world.setBlock(i + 25, j + 0, k + 10, Blocks.netherrack);
        world.setBlock(i + 25, j + 0, k + 11, Blocks.nether_brick, 2, 0);
        world.setBlock(i + 25, j + 0, k + 12, Blocks.netherrack);
        world.setBlock(i + 25, j + 0, k + 13, Blocks.netherrack);
        world.setBlock(i + 25, j + 0, k + 14, Blocks.netherrack);
        world.setBlock(i + 25, j + 0, k + 15, Blocks.netherrack);
        world.setBlock(i + 25, j + 0, k + 16, Blocks.netherrack);
        world.setBlock(i + 25, j + 0, k + 17, Blocks.netherrack);
        world.setBlock(i + 25, j + 0, k + 18, Blocks.netherrack);
        world.setBlock(i + 25, j + 0, k + 19, Blocks.netherrack);
        world.setBlock(i + 25, j + 0, k + 20, Blocks.netherrack);
        world.setBlock(i + 25, j + 0, k + 21, Blocks.netherrack);
        world.setBlock(i + 25, j + 0, k + 22, Blocks.netherrack);
        world.setBlock(i + 25, j + 0, k + 23, Blocks.netherrack);
        world.setBlock(i + 25, j + 0, k + 24, Blocks.netherrack);
        world.setBlock(i + 25, j + 0, k + 25, Blocks.netherrack);
        world.setBlock(i + 25, j + 1, k + 2, Blocks.nether_brick, 2, 0);
        world.setBlock(i + 25, j + 1, k + 15, Blocks.nether_brick, 2, 0);
        world.setBlock(i + 25, j + 1, k + 21, Blocks.nether_brick_fence, 3, 0);
        world.setBlock(i + 26, j + 0, k + 0, Blocks.netherrack);
        world.setBlock(i + 26, j + 0, k + 1, Blocks.netherrack);
        world.setBlock(i + 26, j + 0, k + 2, Blocks.netherrack);
        world.setBlock(i + 26, j + 0, k + 3, Blocks.netherrack);
        world.setBlock(i + 26, j + 0, k + 4, Blocks.netherrack);
        world.setBlock(i + 26, j + 0, k + 5, Blocks.netherrack);
        world.setBlock(i + 26, j + 0, k + 6, Blocks.nether_brick, 2, 0);
        world.setBlock(i + 26, j + 0, k + 7, Blocks.netherrack);
        world.setBlock(i + 26, j + 0, k + 8, Blocks.netherrack);
        world.setBlock(i + 26, j + 0, k + 9, Blocks.netherrack);
        world.setBlock(i + 26, j + 0, k + 10, Blocks.netherrack);
        world.setBlock(i + 26, j + 0, k + 11, Blocks.netherrack);
        world.setBlock(i + 26, j + 0, k + 12, Blocks.netherrack);
        world.setBlock(i + 26, j + 0, k + 13, Blocks.nether_brick);
        world.setBlock(i + 26, j + 0, k + 14, Blocks.netherrack);
        world.setBlock(i + 26, j + 0, k + 15, Blocks.netherrack);
        world.setBlock(i + 26, j + 0, k + 16, Blocks.netherrack);
        world.setBlock(i + 26, j + 0, k + 17, Blocks.netherrack);
        world.setBlock(i + 26, j + 0, k + 18, Blocks.netherrack);
        world.setBlock(i + 26, j + 0, k + 19, Blocks.netherrack);
        world.setBlock(i + 26, j + 0, k + 20, Blocks.netherrack);
        world.setBlock(i + 26, j + 0, k + 21, Blocks.netherrack);
        world.setBlock(i + 26, j + 0, k + 22, Blocks.netherrack);
        world.setBlock(i + 26, j + 0, k + 23, Blocks.netherrack);
        world.setBlock(i + 26, j + 0, k + 24, Blocks.netherrack);
        world.setBlock(i + 26, j + 0, k + 25, Blocks.netherrack);
        world.setBlock(i + 26, j + 1, k + 2, Blocks.nether_brick_fence, 3, 0);
        world.setBlock(i + 26, j + 1, k + 4, Blocks.nether_brick_fence, 3, 0);
        world.setBlock(i + 26, j + 1, k + 5, Blocks.nether_brick, 2, 0);
        world.setBlock(i + 26, j + 1, k + 7, Blocks.nether_brick, 2, 0);
        world.setBlock(i + 26, j + 1, k + 8, Blocks.nether_brick, 2, 0);
        world.setBlock(i + 26, j + 1, k + 10, Blocks.nether_brick, 2, 0);
        world.setBlock(i + 26, j + 1, k + 12, Blocks.nether_brick, 2, 0);
        world.setBlock(i + 26, j + 1, k + 14, Blocks.nether_brick, 2, 0);
        world.setBlock(i + 26, j + 1, k + 16, Blocks.nether_brick, 2, 0);
        world.setBlock(i + 26, j + 1, k + 17, Blocks.nether_brick, 2, 0);
        world.setBlock(i + 26, j + 1, k + 18, Blocks.nether_brick_fence, 3, 0);
        world.setBlock(i + 26, j + 1, k + 19, Blocks.nether_brick, 2, 0);
        world.setBlock(i + 26, j + 1, k + 20, Blocks.nether_brick_fence, 3, 0);
        world.setBlock(i + 26, j + 1, k + 21, Blocks.nether_brick, 2, 0);
        world.setBlock(i + 26, j + 2, k + 8, Blocks.nether_brick, 2, 0);
        world.setBlock(i + 26, j + 2, k + 16, Blocks.nether_brick, 2, 0);
        world.setBlock(i + 27, j + 0, k + 0, Blocks.netherrack);
        world.setBlock(i + 27, j + 0, k + 1, Blocks.netherrack);
        world.setBlock(i + 27, j + 0, k + 2, Blocks.netherrack);
        world.setBlock(i + 27, j + 0, k + 3, Blocks.netherrack);
        world.setBlock(i + 27, j + 0, k + 4, Blocks.netherrack);
        world.setBlock(i + 27, j + 0, k + 5, Blocks.netherrack);
        world.setBlock(i + 27, j + 0, k + 6, Blocks.netherrack);
        world.setBlock(i + 27, j + 0, k + 7, Blocks.netherrack);
        world.setBlock(i + 27, j + 0, k + 8, Blocks.netherrack);
        world.setBlock(i + 27, j + 0, k + 9, Blocks.netherrack);
        world.setBlock(i + 27, j + 0, k + 10, Blocks.nether_brick, 2, 0);
        world.setBlock(i + 27, j + 0, k + 11, Blocks.netherrack);
        world.setBlock(i + 27, j + 0, k + 12, Blocks.netherrack);
        world.setBlock(i + 27, j + 0, k + 13, Blocks.netherrack);
        world.setBlock(i + 27, j + 0, k + 14, Blocks.netherrack);
        world.setBlock(i + 27, j + 0, k + 15, Blocks.netherrack);
        world.setBlock(i + 27, j + 0, k + 16, Blocks.netherrack);
        world.setBlock(i + 27, j + 0, k + 17, Blocks.netherrack);
        world.setBlock(i + 27, j + 0, k + 18, Blocks.netherrack);
        world.setBlock(i + 27, j + 0, k + 19, Blocks.netherrack);
        world.setBlock(i + 27, j + 0, k + 20, Blocks.netherrack);
        world.setBlock(i + 27, j + 0, k + 21, Blocks.netherrack);
        world.setBlock(i + 27, j + 0, k + 22, Blocks.netherrack);
        world.setBlock(i + 27, j + 0, k + 23, Blocks.netherrack);
        world.setBlock(i + 27, j + 0, k + 24, Blocks.netherrack);
        world.setBlock(i + 27, j + 0, k + 25, Blocks.netherrack);
        world.setBlock(i + 27, j + 1, k + 6, Blocks.nether_brick, 2, 0);
        return true;
    }
}
