

package com.gibby.dungeon.gen;

import net.minecraft.world.gen.feature.*;
import cpw.mods.fml.common.*;
import java.util.*;
import net.minecraft.world.chunk.*;
import net.minecraft.block.*;
import net.minecraft.world.*;
import com.gibby.dungeon.*;
import net.minecraft.init.*;

public class WorldGenCrystalliumCoocoon extends WorldGenerator implements IWorldGenerator
{
    public void generate(final Random random, final int chunkX, final int chunkZ, final World world, final IChunkProvider chunkGenerator, final IChunkProvider chunkProvider) {
    }
    
    public void setBlock(final World world, final int x, final int y, final int z, final Block block, final int metadata) {
        final Block b1 = world.getBlock(x, y, z);
        if (b1.isAir((IBlockAccess)world, x, y, z) || b1.isLeaves((IBlockAccess)world, x, y, z)) {
            world.setBlock(x, y, z, block, metadata, 2);
        }
    }
    
    public boolean generate(final World world, final Random rand, final int i, final int j, final int k) {
        if (world.getBlock(i, j, k) != Dungeons.crystalliumDirt || world.getBlock(i + 21, j, k + 21) != Dungeons.crystalliumDirt || world.getBlock(i, j + 1, k) != Dungeons.crystalliumGrass || world.getBlock(i + 21, j + 1, k + 1) != Dungeons.crystalliumGrass || world.getBlock(i, j + 21, k) != Blocks.air || world.getBlock(i + 21, j + 21, k + 21) != Blocks.air) {
            return false;
        }
        this.setBlock(world, i + 2, j + 9, k + 16, Dungeons.amethystStone, 0);
        this.setBlock(world, i + 2, j + 10, k + 12, Dungeons.amethystStone, 0);
        this.setBlock(world, i + 2, j + 10, k + 13, Dungeons.amethystStone, 0);
        this.setBlock(world, i + 2, j + 10, k + 14, Dungeons.amethystStone, 0);
        this.setBlock(world, i + 2, j + 10, k + 15, Dungeons.amethystStone, 0);
        this.setBlock(world, i + 2, j + 10, k + 16, Dungeons.amethystStone, 0);
        this.setBlock(world, i + 2, j + 11, k + 12, Dungeons.amethystStone, 0);
        this.setBlock(world, i + 2, j + 11, k + 13, Dungeons.amethystStone, 0);
        this.setBlock(world, i + 2, j + 11, k + 14, Dungeons.amethystStone, 0);
        this.setBlock(world, i + 2, j + 11, k + 15, Dungeons.amethystStone, 0);
        this.setBlock(world, i + 2, j + 11, k + 16, Dungeons.amethystStone, 0);
        this.setBlock(world, i + 2, j + 12, k + 13, Dungeons.amethystStone, 0);
        this.setBlock(world, i + 2, j + 12, k + 14, Dungeons.amethystStone, 0);
        this.setBlock(world, i + 2, j + 12, k + 15, Dungeons.amethystStone, 0);
        this.setBlock(world, i + 2, j + 13, k + 13, Dungeons.amethystStone, 0);
        this.setBlock(world, i + 2, j + 13, k + 14, Dungeons.amethystStone, 0);
        this.setBlock(world, i + 2, j + 13, k + 15, Dungeons.amethystStone, 0);
        this.setBlock(world, i + 3, j + 8, k + 16, Dungeons.amethystStone, 0);
        this.setBlock(world, i + 3, j + 9, k + 12, Dungeons.amethystStone, 0);
        this.setBlock(world, i + 3, j + 9, k + 13, Dungeons.amethystStone, 0);
        this.setBlock(world, i + 3, j + 9, k + 14, Dungeons.amethystStone, 0);
        this.setBlock(world, i + 3, j + 9, k + 15, Dungeons.amethystStone, 0);
        this.setBlock(world, i + 3, j + 9, k + 16, Dungeons.amethystStone, 0);
        this.setBlock(world, i + 3, j + 9, k + 17, Dungeons.amethystStone, 0);
        this.setBlock(world, i + 3, j + 9, k + 18, Dungeons.amethystStone, 0);
        this.setBlock(world, i + 3, j + 10, k + 10, Dungeons.amethystStone, 0);
        this.setBlock(world, i + 3, j + 10, k + 11, Dungeons.amethystStone, 0);
        this.setBlock(world, i + 3, j + 10, k + 12, Dungeons.amethystStone, 0);
        this.setBlock(world, i + 3, j + 10, k + 13, Dungeons.amethystStone, 0);
        this.setBlock(world, i + 3, j + 10, k + 14, Dungeons.amethystStone, 0);
        this.setBlock(world, i + 3, j + 10, k + 15, Dungeons.amethystStone, 0);
        this.setBlock(world, i + 3, j + 10, k + 16, Dungeons.amethystStone, 0);
        this.setBlock(world, i + 3, j + 10, k + 17, Dungeons.amethystStone, 0);
        this.setBlock(world, i + 3, j + 10, k + 18, Dungeons.amethystStone, 0);
        this.setBlock(world, i + 3, j + 11, k + 10, Dungeons.amethystStone, 0);
        this.setBlock(world, i + 3, j + 11, k + 11, Dungeons.amethystStone, 0);
        this.setBlock(world, i + 3, j + 11, k + 12, Dungeons.amethystStone, 0);
        this.setBlock(world, i + 3, j + 11, k + 13, Dungeons.amethystStone, 0);
        this.setBlock(world, i + 3, j + 11, k + 14, Dungeons.amethystStone, 0);
        this.setBlock(world, i + 3, j + 11, k + 15, Dungeons.amethystStone, 0);
        this.setBlock(world, i + 3, j + 11, k + 16, Dungeons.amethystStone, 0);
        this.setBlock(world, i + 3, j + 11, k + 17, Dungeons.amethystStone, 0);
        this.setBlock(world, i + 3, j + 11, k + 18, Dungeons.amethystStone, 0);
        this.setBlock(world, i + 3, j + 12, k + 11, Dungeons.amethystStone, 0);
        this.setBlock(world, i + 3, j + 12, k + 12, Dungeons.amethystStone, 0);
        this.setBlock(world, i + 3, j + 12, k + 13, Dungeons.amethystStone, 0);
        this.setBlock(world, i + 3, j + 12, k + 14, Dungeons.amethystStone, 0);
        this.setBlock(world, i + 3, j + 12, k + 15, Dungeons.amethystStone, 0);
        this.setBlock(world, i + 3, j + 12, k + 16, Dungeons.amethystStone, 0);
        this.setBlock(world, i + 3, j + 12, k + 17, Dungeons.amethystStone, 0);
        this.setBlock(world, i + 3, j + 13, k + 12, Dungeons.amethystStone, 0);
        this.setBlock(world, i + 3, j + 13, k + 13, Dungeons.amethystStone, 0);
        this.setBlock(world, i + 3, j + 13, k + 14, Dungeons.amethystStone, 0);
        this.setBlock(world, i + 3, j + 13, k + 15, Dungeons.amethystStone, 0);
        this.setBlock(world, i + 3, j + 13, k + 16, Dungeons.amethystStone, 0);
        this.setBlock(world, i + 3, j + 14, k + 13, Dungeons.amethystStone, 0);
        this.setBlock(world, i + 3, j + 14, k + 14, Dungeons.amethystStone, 0);
        this.setBlock(world, i + 3, j + 14, k + 15, Dungeons.amethystStone, 0);
        this.setBlock(world, i + 3, j + 14, k + 16, Dungeons.amethystStone, 0);
        this.setBlock(world, i + 3, j + 14, k + 17, Dungeons.amethystStone, 0);
        this.setBlock(world, i + 3, j + 15, k + 15, Dungeons.amethystStone, 0);
        this.setBlock(world, i + 3, j + 15, k + 16, Dungeons.amethystStone, 0);
        this.setBlock(world, i + 3, j + 15, k + 17, Dungeons.amethystStone, 0);
        this.setBlock(world, i + 3, j + 15, k + 18, Dungeons.amethystStone, 0);
        this.setBlock(world, i + 3, j + 15, k + 19, Dungeons.amethystStone, 0);
        this.setBlock(world, i + 3, j + 15, k + 20, Dungeons.amethystStone, 0);
        this.setBlock(world, i + 4, j + 5, k + 16, Dungeons.amethystStone, 0);
        this.setBlock(world, i + 4, j + 6, k + 16, Dungeons.amethystStone, 0);
        this.setBlock(world, i + 4, j + 7, k + 13, Dungeons.amethystStone, 0);
        this.setBlock(world, i + 4, j + 7, k + 14, Dungeons.amethystStone, 0);
        this.setBlock(world, i + 4, j + 7, k + 15, Dungeons.amethystStone, 0);
        this.setBlock(world, i + 4, j + 7, k + 16, Dungeons.amethystStone, 0);
        this.setBlock(world, i + 4, j + 8, k + 13, Dungeons.amethystStone, 0);
        this.setBlock(world, i + 4, j + 8, k + 14, Dungeons.amethystStone, 0);
        this.setBlock(world, i + 4, j + 8, k + 15, Dungeons.amethystStone, 0);
        this.setBlock(world, i + 4, j + 8, k + 16, Dungeons.amethystStone, 0);
        this.setBlock(world, i + 4, j + 8, k + 17, Dungeons.amethystStone, 0);
        this.setBlock(world, i + 4, j + 8, k + 18, Dungeons.amethystStone, 0);
        this.setBlock(world, i + 4, j + 8, k + 19, Dungeons.amethystStone, 0);
        this.setBlock(world, i + 4, j + 9, k + 11, Dungeons.amethystStone, 0);
        this.setBlock(world, i + 4, j + 9, k + 12, Dungeons.amethystStone, 0);
        this.setBlock(world, i + 4, j + 9, k + 13, Dungeons.amethystStone, 0);
        this.setBlock(world, i + 4, j + 9, k + 14, Dungeons.amethystStone, 0);
        this.setBlock(world, i + 4, j + 9, k + 15, Dungeons.amethystStone, 0);
        this.setBlock(world, i + 4, j + 9, k + 16, Dungeons.amethystStone, 0);
        this.setBlock(world, i + 4, j + 9, k + 17, Dungeons.amethystStone, 0);
        this.setBlock(world, i + 4, j + 9, k + 18, Dungeons.amethystStone, 0);
        this.setBlock(world, i + 4, j + 9, k + 19, Dungeons.amethystStone, 0);
        this.setBlock(world, i + 4, j + 10, k + 9, Dungeons.amethystStone, 0);
        this.setBlock(world, i + 4, j + 10, k + 10, Dungeons.amethystStone, 0);
        this.setBlock(world, i + 4, j + 10, k + 11, Dungeons.amethystStone, 0);
        this.setBlock(world, i + 4, j + 10, k + 12, Dungeons.amethystStone, 0);
        this.setBlock(world, i + 4, j + 10, k + 13, Dungeons.amethystStone, 0);
        this.setBlock(world, i + 4, j + 10, k + 14, Dungeons.amethystStone, 0);
        this.setBlock(world, i + 4, j + 10, k + 15, Dungeons.amethystStone, 0);
        this.setBlock(world, i + 4, j + 10, k + 16, Dungeons.amethystStone, 0);
        this.setBlock(world, i + 4, j + 10, k + 17, Dungeons.amethystStone, 0);
        this.setBlock(world, i + 4, j + 10, k + 18, Dungeons.amethystStone, 0);
        this.setBlock(world, i + 4, j + 10, k + 19, Dungeons.amethystStone, 0);
        this.setBlock(world, i + 4, j + 11, k + 9, Dungeons.amethystStone, 0);
        this.setBlock(world, i + 4, j + 11, k + 10, Dungeons.amethystStone, 0);
        this.setBlock(world, i + 4, j + 11, k + 11, Dungeons.amethystStone, 0);
        this.setBlock(world, i + 4, j + 11, k + 12, Dungeons.amethystStone, 0);
        this.setBlock(world, i + 4, j + 11, k + 13, Dungeons.amethystStone, 0);
        this.setBlock(world, i + 4, j + 11, k + 14, Dungeons.amethystStone, 0);
        this.setBlock(world, i + 4, j + 11, k + 15, Dungeons.amethystStone, 0);
        this.setBlock(world, i + 4, j + 11, k + 16, Dungeons.amethystStone, 0);
        this.setBlock(world, i + 4, j + 11, k + 17, Dungeons.amethystStone, 0);
        this.setBlock(world, i + 4, j + 11, k + 18, Dungeons.amethystStone, 0);
        this.setBlock(world, i + 4, j + 11, k + 19, Dungeons.amethystStone, 0);
        this.setBlock(world, i + 4, j + 12, k + 10, Dungeons.amethystStone, 0);
        this.setBlock(world, i + 4, j + 12, k + 11, Dungeons.amethystStone, 0);
        this.setBlock(world, i + 4, j + 12, k + 12, Dungeons.amethystStone, 0);
        this.setBlock(world, i + 4, j + 12, k + 18, Dungeons.amethystStone, 0);
        this.setBlock(world, i + 4, j + 13, k + 10, Dungeons.amethystStone, 0);
        this.setBlock(world, i + 4, j + 13, k + 11, Dungeons.amethystStone, 0);
        this.setBlock(world, i + 4, j + 13, k + 17, Dungeons.amethystStone, 0);
        this.setBlock(world, i + 4, j + 13, k + 18, Dungeons.amethystStone, 0);
        this.setBlock(world, i + 4, j + 13, k + 19, Dungeons.amethystStone, 0);
        this.setBlock(world, i + 4, j + 14, k + 11, Dungeons.amethystStone, 0);
        this.setBlock(world, i + 4, j + 14, k + 12, Dungeons.amethystStone, 0);
        this.setBlock(world, i + 4, j + 14, k + 17, Dungeons.amethystStone, 0);
        this.setBlock(world, i + 4, j + 14, k + 18, Dungeons.amethystStone, 0);
        this.setBlock(world, i + 4, j + 14, k + 19, Dungeons.amethystStone, 0);
        this.setBlock(world, i + 4, j + 14, k + 20, Dungeons.amethystStone, 0);
        this.setBlock(world, i + 4, j + 15, k + 11, Dungeons.amethystStone, 0);
        this.setBlock(world, i + 4, j + 15, k + 12, Dungeons.amethystStone, 0);
        this.setBlock(world, i + 4, j + 15, k + 13, Dungeons.amethystStone, 0);
        this.setBlock(world, i + 4, j + 15, k + 14, Dungeons.amethystStone, 0);
        this.setBlock(world, i + 4, j + 15, k + 16, Dungeons.amethystStone, 0);
        this.setBlock(world, i + 4, j + 15, k + 17, Dungeons.amethystStone, 0);
        this.setBlock(world, i + 4, j + 15, k + 18, Dungeons.amethystStone, 0);
        this.setBlock(world, i + 4, j + 15, k + 19, Dungeons.amethystStone, 0);
        this.setBlock(world, i + 4, j + 15, k + 20, Dungeons.amethystStone, 0);
        this.setBlock(world, i + 4, j + 15, k + 21, Dungeons.amethystStone, 0);
        this.setBlock(world, i + 4, j + 16, k + 11, Dungeons.amethystStone, 0);
        this.setBlock(world, i + 4, j + 16, k + 12, Dungeons.amethystStone, 0);
        this.setBlock(world, i + 4, j + 16, k + 13, Dungeons.amethystStone, 0);
        this.setBlock(world, i + 4, j + 16, k + 14, Dungeons.amethystStone, 0);
        this.setBlock(world, i + 4, j + 16, k + 15, Dungeons.amethystStone, 0);
        this.setBlock(world, i + 4, j + 16, k + 16, Dungeons.amethystStone, 0);
        this.setBlock(world, i + 4, j + 16, k + 17, Dungeons.amethystStone, 0);
        this.setBlock(world, i + 4, j + 16, k + 18, Dungeons.amethystStone, 0);
        this.setBlock(world, i + 4, j + 16, k + 19, Dungeons.amethystStone, 0);
        this.setBlock(world, i + 4, j + 16, k + 20, Dungeons.amethystStone, 0);
        this.setBlock(world, i + 4, j + 16, k + 21, Dungeons.amethystStone, 0);
        this.setBlock(world, i + 4, j + 16, k + 22, Dungeons.amethystStone, 0);
        this.setBlock(world, i + 4, j + 17, k + 15, Dungeons.amethystStone, 0);
        this.setBlock(world, i + 4, j + 18, k + 15, Dungeons.amethystStone, 0);
        this.setBlock(world, i + 4, j + 19, k + 15, Dungeons.amethystStone, 0);
        this.setBlock(world, i + 5, j + 7, k + 12, Dungeons.amethystStone, 0);
        this.setBlock(world, i + 5, j + 7, k + 13, Dungeons.amethystStone, 0);
        this.setBlock(world, i + 5, j + 7, k + 14, Dungeons.amethystStone, 0);
        this.setBlock(world, i + 5, j + 7, k + 15, Dungeons.amethystStone, 0);
        this.setBlock(world, i + 5, j + 7, k + 16, Dungeons.amethystStone, 0);
        this.setBlock(world, i + 5, j + 7, k + 17, Dungeons.amethystStone, 0);
        this.setBlock(world, i + 5, j + 8, k + 10, Dungeons.amethystStone, 0);
        this.setBlock(world, i + 5, j + 8, k + 11, Dungeons.amethystStone, 0);
        this.setBlock(world, i + 5, j + 8, k + 12, Dungeons.amethystStone, 0);
        this.setBlock(world, i + 5, j + 8, k + 13, Dungeons.amethystStone, 0);
        this.setBlock(world, i + 5, j + 8, k + 14, Dungeons.amethystStone, 0);
        this.setBlock(world, i + 5, j + 8, k + 15, Dungeons.amethystStone, 0);
        this.setBlock(world, i + 5, j + 8, k + 16, Dungeons.amethystStone, 0);
        this.setBlock(world, i + 5, j + 8, k + 17, Dungeons.amethystStone, 0);
        this.setBlock(world, i + 5, j + 8, k + 18, Dungeons.amethystStone, 0);
        this.setBlock(world, i + 5, j + 8, k + 19, Dungeons.amethystStone, 0);
        this.setBlock(world, i + 5, j + 8, k + 20, Dungeons.amethystStone, 0);
        this.setBlock(world, i + 5, j + 9, k + 10, Dungeons.amethystStone, 0);
        this.setBlock(world, i + 5, j + 9, k + 11, Dungeons.amethystStone, 0);
        this.setBlock(world, i + 5, j + 9, k + 12, Dungeons.amethystStone, 0);
        this.setBlock(world, i + 5, j + 9, k + 13, Dungeons.amethystStone, 0);
        this.setBlock(world, i + 5, j + 9, k + 14, Dungeons.amethystStone, 0);
        this.setBlock(world, i + 5, j + 9, k + 15, Dungeons.amethystStone, 0);
        this.setBlock(world, i + 5, j + 9, k + 16, Dungeons.amethystStone, 0);
        this.setBlock(world, i + 5, j + 9, k + 17, Dungeons.amethystStone, 0);
        this.setBlock(world, i + 5, j + 9, k + 18, Dungeons.amethystStone, 0);
        this.setBlock(world, i + 5, j + 9, k + 19, Dungeons.amethystStone, 0);
        this.setBlock(world, i + 5, j + 9, k + 20, Dungeons.amethystStone, 0);
        this.setBlock(world, i + 5, j + 10, k + 9, Dungeons.amethystStone, 0);
        this.setBlock(world, i + 5, j + 10, k + 10, Dungeons.amethystStone, 0);
        this.setBlock(world, i + 5, j + 10, k + 11, Dungeons.amethystStone, 0);
        this.setBlock(world, i + 5, j + 10, k + 14, Dungeons.amethystStone, 0);
        this.setBlock(world, i + 5, j + 10, k + 15, Dungeons.amethystStone, 0);
        this.setBlock(world, i + 5, j + 10, k + 16, Dungeons.amethystStone, 0);
        this.setBlock(world, i + 5, j + 10, k + 18, Dungeons.amethystStone, 0);
        this.setBlock(world, i + 5, j + 10, k + 19, Dungeons.amethystStone, 0);
        this.setBlock(world, i + 5, j + 10, k + 20, Dungeons.amethystStone, 0);
        this.setBlock(world, i + 5, j + 10, k + 21, Dungeons.amethystStone, 0);
        this.setBlock(world, i + 5, j + 10, k + 22, Dungeons.amethystStone, 0);
        this.setBlock(world, i + 5, j + 10, k + 23, Dungeons.amethystStone, 0);
        this.setBlock(world, i + 5, j + 11, k + 9, Dungeons.amethystStone, 0);
        this.setBlock(world, i + 5, j + 11, k + 10, Dungeons.amethystStone, 0);
        this.setBlock(world, i + 5, j + 11, k + 11, Dungeons.amethystStone, 0);
        this.setBlock(world, i + 5, j + 11, k + 19, Dungeons.amethystStone, 0);
        this.setBlock(world, i + 5, j + 11, k + 20, Dungeons.amethystStone, 0);
        this.setBlock(world, i + 5, j + 11, k + 21, Dungeons.amethystStone, 0);
        this.setBlock(world, i + 5, j + 11, k + 22, Dungeons.amethystStone, 0);
        this.setBlock(world, i + 5, j + 11, k + 23, Dungeons.amethystStone, 0);
        this.setBlock(world, i + 5, j + 12, k + 9, Dungeons.amethystStone, 0);
        this.setBlock(world, i + 5, j + 12, k + 10, Dungeons.amethystStone, 0);
        this.setBlock(world, i + 5, j + 12, k + 11, Dungeons.amethystStone, 0);
        this.setBlock(world, i + 5, j + 12, k + 19, Dungeons.amethystStone, 0);
        this.setBlock(world, i + 5, j + 12, k + 20, Dungeons.amethystStone, 0);
        this.setBlock(world, i + 5, j + 12, k + 21, Dungeons.amethystStone, 0);
        this.setBlock(world, i + 5, j + 12, k + 22, Dungeons.amethystStone, 0);
        this.setBlock(world, i + 5, j + 13, k + 10, Dungeons.amethystStone, 0);
        this.setBlock(world, i + 5, j + 13, k + 11, Dungeons.amethystStone, 0);
        this.setBlock(world, i + 5, j + 13, k + 19, Dungeons.amethystStone, 0);
        this.setBlock(world, i + 5, j + 13, k + 20, Dungeons.amethystStone, 0);
        this.setBlock(world, i + 5, j + 13, k + 21, Dungeons.amethystStone, 0);
        this.setBlock(world, i + 5, j + 14, k + 10, Dungeons.amethystStone, 0);
        this.setBlock(world, i + 5, j + 14, k + 11, Dungeons.amethystStone, 0);
        this.setBlock(world, i + 5, j + 14, k + 18, Dungeons.amethystStone, 0);
        this.setBlock(world, i + 5, j + 14, k + 19, Dungeons.amethystStone, 0);
        this.setBlock(world, i + 5, j + 14, k + 20, Dungeons.amethystStone, 0);
        this.setBlock(world, i + 5, j + 14, k + 21, Dungeons.amethystStone, 0);
        this.setBlock(world, i + 5, j + 14, k + 22, Dungeons.amethystStone, 0);
        this.setBlock(world, i + 5, j + 15, k + 10, Dungeons.amethystStone, 0);
        this.setBlock(world, i + 5, j + 15, k + 11, Dungeons.amethystStone, 0);
        this.setBlock(world, i + 5, j + 15, k + 17, Dungeons.amethystStone, 0);
        this.setBlock(world, i + 5, j + 15, k + 18, Dungeons.amethystStone, 0);
        this.setBlock(world, i + 5, j + 15, k + 19, Dungeons.amethystStone, 0);
        this.setBlock(world, i + 5, j + 15, k + 20, Dungeons.amethystStone, 0);
        this.setBlock(world, i + 5, j + 15, k + 21, Dungeons.amethystStone, 0);
        this.setBlock(world, i + 5, j + 15, k + 22, Dungeons.amethystStone, 0);
        this.setBlock(world, i + 5, j + 16, k + 11, Dungeons.amethystStone, 0);
        this.setBlock(world, i + 5, j + 16, k + 12, Dungeons.amethystStone, 0);
        this.setBlock(world, i + 5, j + 16, k + 13, Dungeons.amethystStone, 0);
        this.setBlock(world, i + 5, j + 16, k + 16, Dungeons.amethystStone, 0);
        this.setBlock(world, i + 5, j + 16, k + 17, Dungeons.amethystStone, 0);
        this.setBlock(world, i + 5, j + 16, k + 18, Dungeons.amethystStone, 0);
        this.setBlock(world, i + 5, j + 16, k + 19, Dungeons.amethystStone, 0);
        this.setBlock(world, i + 5, j + 16, k + 20, Dungeons.amethystStone, 0);
        this.setBlock(world, i + 5, j + 16, k + 21, Dungeons.amethystStone, 0);
        this.setBlock(world, i + 5, j + 16, k + 22, Dungeons.amethystStone, 0);
        this.setBlock(world, i + 5, j + 16, k + 23, Dungeons.amethystStone, 0);
        this.setBlock(world, i + 5, j + 17, k + 11, Dungeons.amethystStone, 0);
        this.setBlock(world, i + 5, j + 17, k + 12, Dungeons.amethystStone, 0);
        this.setBlock(world, i + 5, j + 17, k + 13, Dungeons.amethystStone, 0);
        this.setBlock(world, i + 5, j + 17, k + 14, Dungeons.amethystStone, 0);
        this.setBlock(world, i + 5, j + 17, k + 15, Dungeons.amethystStone, 0);
        this.setBlock(world, i + 5, j + 17, k + 16, Dungeons.amethystStone, 0);
        this.setBlock(world, i + 5, j + 17, k + 17, Dungeons.amethystStone, 0);
        this.setBlock(world, i + 5, j + 17, k + 18, Dungeons.amethystStone, 0);
        this.setBlock(world, i + 5, j + 17, k + 19, Dungeons.amethystStone, 0);
        this.setBlock(world, i + 5, j + 17, k + 20, Dungeons.amethystStone, 0);
        this.setBlock(world, i + 5, j + 17, k + 21, Dungeons.amethystStone, 0);
        this.setBlock(world, i + 5, j + 17, k + 22, Dungeons.amethystStone, 0);
        this.setBlock(world, i + 6, j + 4, k + 14, Dungeons.amethystStone, 0);
        this.setBlock(world, i + 6, j + 5, k + 14, Dungeons.amethystStone, 0);
        this.setBlock(world, i + 6, j + 6, k + 9, Dungeons.amethystStone, 0);
        this.setBlock(world, i + 6, j + 6, k + 13, Dungeons.amethystStone, 0);
        this.setBlock(world, i + 6, j + 6, k + 14, Dungeons.amethystStone, 0);
        this.setBlock(world, i + 6, j + 6, k + 15, Dungeons.amethystStone, 0);
        this.setBlock(world, i + 6, j + 6, k + 16, Dungeons.amethystStone, 0);
        this.setBlock(world, i + 6, j + 7, k + 9, Dungeons.amethystStone, 0);
        this.setBlock(world, i + 6, j + 7, k + 10, Dungeons.amethystStone, 0);
        this.setBlock(world, i + 6, j + 7, k + 11, Dungeons.amethystStone, 0);
        this.setBlock(world, i + 6, j + 7, k + 12, Dungeons.amethystStone, 0);
        this.setBlock(world, i + 6, j + 7, k + 13, Dungeons.amethystStone, 0);
        this.setBlock(world, i + 6, j + 7, k + 14, Dungeons.amethystStone, 0);
        this.setBlock(world, i + 6, j + 7, k + 15, Dungeons.amethystStone, 0);
        this.setBlock(world, i + 6, j + 7, k + 16, Dungeons.amethystStone, 0);
        this.setBlock(world, i + 6, j + 7, k + 17, Dungeons.amethystStone, 0);
        this.setBlock(world, i + 6, j + 7, k + 18, Dungeons.amethystStone, 0);
        this.setBlock(world, i + 6, j + 7, k + 19, Dungeons.amethystStone, 0);
        this.setBlock(world, i + 6, j + 8, k + 9, Dungeons.amethystStone, 0);
        this.setBlock(world, i + 6, j + 8, k + 10, Dungeons.amethystStone, 0);
        this.setBlock(world, i + 6, j + 8, k + 11, Dungeons.amethystStone, 0);
        this.setBlock(world, i + 6, j + 8, k + 12, Dungeons.amethystStone, 0);
        this.setBlock(world, i + 6, j + 8, k + 13, Dungeons.amethystStone, 0);
        this.setBlock(world, i + 6, j + 8, k + 14, Dungeons.amethystStone, 0);
        this.setBlock(world, i + 6, j + 8, k + 16, Dungeons.amethystStone, 0);
        this.setBlock(world, i + 6, j + 8, k + 18, Dungeons.amethystStone, 0);
        this.setBlock(world, i + 6, j + 8, k + 19, Dungeons.amethystStone, 0);
        this.setBlock(world, i + 6, j + 8, k + 20, Dungeons.amethystStone, 0);
        this.setBlock(world, i + 6, j + 8, k + 21, Dungeons.amethystStone, 0);
        this.setBlock(world, i + 6, j + 8, k + 22, Dungeons.amethystStone, 0);
        this.setBlock(world, i + 6, j + 9, k + 9, Dungeons.amethystStone, 0);
        this.setBlock(world, i + 6, j + 9, k + 10, Dungeons.amethystStone, 0);
        this.setBlock(world, i + 6, j + 9, k + 14, Dungeons.amethystStone, 0);
        this.setBlock(world, i + 6, j + 9, k + 15, Dungeons.amethystStone, 0);
        this.setBlock(world, i + 6, j + 9, k + 20, Dungeons.amethystStone, 0);
        this.setBlock(world, i + 6, j + 9, k + 21, Dungeons.amethystStone, 0);
        this.setBlock(world, i + 6, j + 9, k + 22, Dungeons.amethystStone, 0);
        this.setBlock(world, i + 6, j + 9, k + 23, Dungeons.amethystStone, 0);
        this.setBlock(world, i + 6, j + 10, k + 8, Dungeons.amethystStone, 0);
        this.setBlock(world, i + 6, j + 10, k + 9, Dungeons.amethystStone, 0);
        this.setBlock(world, i + 6, j + 10, k + 10, Dungeons.amethystStone, 0);
        this.setBlock(world, i + 6, j + 10, k + 22, Dungeons.amethystStone, 0);
        this.setBlock(world, i + 6, j + 10, k + 23, Dungeons.amethystStone, 0);
        this.setBlock(world, i + 6, j + 10, k + 24, Dungeons.amethystStone, 0);
        this.setBlock(world, i + 6, j + 10, k + 25, Dungeons.amethystStone, 0);
        this.setBlock(world, i + 6, j + 11, k + 8, Dungeons.amethystStone, 0);
        this.setBlock(world, i + 6, j + 11, k + 9, Dungeons.amethystStone, 0);
        this.setBlock(world, i + 6, j + 11, k + 10, Dungeons.amethystStone, 0);
        this.setBlock(world, i + 6, j + 11, k + 22, Dungeons.amethystStone, 0);
        this.setBlock(world, i + 6, j + 11, k + 23, Dungeons.amethystStone, 0);
        this.setBlock(world, i + 6, j + 11, k + 24, Dungeons.amethystStone, 0);
        this.setBlock(world, i + 6, j + 11, k + 25, Dungeons.amethystStone, 0);
        this.setBlock(world, i + 6, j + 12, k + 9, Dungeons.amethystStone, 0);
        this.setBlock(world, i + 6, j + 12, k + 10, Dungeons.amethystStone, 0);
        this.setBlock(world, i + 6, j + 12, k + 22, Dungeons.amethystStone, 0);
        this.setBlock(world, i + 6, j + 12, k + 23, Dungeons.amethystStone, 0);
        this.setBlock(world, i + 6, j + 12, k + 24, Dungeons.amethystStone, 0);
        this.setBlock(world, i + 6, j + 13, k + 9, Dungeons.amethystStone, 0);
        this.setBlock(world, i + 6, j + 13, k + 10, Dungeons.amethystStone, 0);
        this.setBlock(world, i + 6, j + 13, k + 22, Dungeons.amethystStone, 0);
        this.setBlock(world, i + 6, j + 13, k + 23, Dungeons.amethystStone, 0);
        this.setBlock(world, i + 6, j + 14, k + 10, Dungeons.amethystStone, 0);
        this.setBlock(world, i + 6, j + 14, k + 11, Dungeons.amethystStone, 0);
        this.setBlock(world, i + 6, j + 14, k + 21, Dungeons.amethystStone, 0);
        this.setBlock(world, i + 6, j + 14, k + 22, Dungeons.amethystStone, 0);
        this.setBlock(world, i + 6, j + 15, k + 10, Dungeons.amethystStone, 0);
        this.setBlock(world, i + 6, j + 15, k + 11, Dungeons.amethystStone, 0);
        this.setBlock(world, i + 6, j + 15, k + 20, Dungeons.amethystStone, 0);
        this.setBlock(world, i + 6, j + 15, k + 21, Dungeons.amethystStone, 0);
        this.setBlock(world, i + 6, j + 15, k + 22, Dungeons.amethystStone, 0);
        this.setBlock(world, i + 6, j + 15, k + 23, Dungeons.amethystStone, 0);
        this.setBlock(world, i + 6, j + 16, k + 10, Dungeons.amethystStone, 0);
        this.setBlock(world, i + 6, j + 16, k + 11, Dungeons.amethystStone, 0);
        this.setBlock(world, i + 6, j + 16, k + 12, Dungeons.amethystStone, 0);
        this.setBlock(world, i + 6, j + 16, k + 19, Dungeons.amethystStone, 0);
        this.setBlock(world, i + 6, j + 16, k + 20, Dungeons.amethystStone, 0);
        this.setBlock(world, i + 6, j + 16, k + 21, Dungeons.amethystStone, 0);
        this.setBlock(world, i + 6, j + 16, k + 22, Dungeons.amethystStone, 0);
        this.setBlock(world, i + 6, j + 16, k + 23, Dungeons.amethystStone, 0);
        this.setBlock(world, i + 6, j + 17, k + 10, Dungeons.amethystStone, 0);
        this.setBlock(world, i + 6, j + 17, k + 11, Dungeons.amethystStone, 0);
        this.setBlock(world, i + 6, j + 17, k + 12, Dungeons.amethystStone, 0);
        this.setBlock(world, i + 6, j + 17, k + 13, Dungeons.amethystStone, 0);
        this.setBlock(world, i + 6, j + 17, k + 16, Dungeons.amethystStone, 0);
        this.setBlock(world, i + 6, j + 17, k + 17, Dungeons.amethystStone, 0);
        this.setBlock(world, i + 6, j + 17, k + 18, Dungeons.amethystStone, 0);
        this.setBlock(world, i + 6, j + 17, k + 19, Dungeons.amethystStone, 0);
        this.setBlock(world, i + 6, j + 17, k + 20, Dungeons.amethystStone, 0);
        this.setBlock(world, i + 6, j + 17, k + 21, Dungeons.amethystStone, 0);
        this.setBlock(world, i + 6, j + 17, k + 22, Dungeons.amethystStone, 0);
        this.setBlock(world, i + 6, j + 18, k + 12, Dungeons.amethystStone, 0);
        this.setBlock(world, i + 6, j + 18, k + 13, Dungeons.amethystStone, 0);
        this.setBlock(world, i + 6, j + 18, k + 14, Dungeons.amethystStone, 0);
        this.setBlock(world, i + 6, j + 18, k + 15, Dungeons.amethystStone, 0);
        this.setBlock(world, i + 6, j + 18, k + 16, Dungeons.amethystStone, 0);
        this.setBlock(world, i + 6, j + 18, k + 17, Dungeons.amethystStone, 0);
        this.setBlock(world, i + 6, j + 18, k + 18, Dungeons.amethystStone, 0);
        this.setBlock(world, i + 6, j + 18, k + 19, Dungeons.amethystStone, 0);
        this.setBlock(world, i + 6, j + 18, k + 20, Dungeons.amethystStone, 0);
        this.setBlock(world, i + 6, j + 19, k + 18, Dungeons.amethystStone, 0);
        this.setBlock(world, i + 6, j + 19, k + 19, Dungeons.amethystStone, 0);
        this.setBlock(world, i + 6, j + 19, k + 20, Dungeons.amethystStone, 0);
        this.setBlock(world, i + 7, j + 6, k + 12, Dungeons.amethystStone, 0);
        this.setBlock(world, i + 7, j + 6, k + 13, Dungeons.amethystStone, 0);
        this.setBlock(world, i + 7, j + 6, k + 14, Dungeons.amethystStone, 0);
        this.setBlock(world, i + 7, j + 6, k + 15, Dungeons.amethystStone, 0);
        this.setBlock(world, i + 7, j + 6, k + 16, Dungeons.amethystStone, 0);
        this.setBlock(world, i + 7, j + 6, k + 17, Dungeons.amethystStone, 0);
        this.setBlock(world, i + 7, j + 6, k + 18, Dungeons.amethystStone, 0);
        this.setBlock(world, i + 7, j + 6, k + 19, Dungeons.amethystStone, 0);
        this.setBlock(world, i + 7, j + 6, k + 20, Dungeons.amethystStone, 0);
        this.setBlock(world, i + 7, j + 7, k + 10, Dungeons.amethystStone, 0);
        this.setBlock(world, i + 7, j + 7, k + 11, Dungeons.amethystStone, 0);
        this.setBlock(world, i + 7, j + 7, k + 12, Dungeons.amethystStone, 0);
        this.setBlock(world, i + 7, j + 7, k + 13, Dungeons.amethystStone, 0);
        this.setBlock(world, i + 7, j + 7, k + 14, Dungeons.amethystStone, 0);
        this.setBlock(world, i + 7, j + 7, k + 15, Dungeons.amethystStone, 0);
        this.setBlock(world, i + 7, j + 7, k + 17, Dungeons.amethystStone, 0);
        this.setBlock(world, i + 7, j + 7, k + 18, Dungeons.amethystStone, 0);
        this.setBlock(world, i + 7, j + 7, k + 20, Dungeons.amethystStone, 0);
        this.setBlock(world, i + 7, j + 7, k + 21, Dungeons.amethystStone, 0);
        this.setBlock(world, i + 7, j + 7, k + 22, Dungeons.amethystStone, 0);
        this.setBlock(world, i + 7, j + 8, k + 8, Dungeons.amethystStone, 0);
        this.setBlock(world, i + 7, j + 8, k + 9, Dungeons.amethystStone, 0);
        this.setBlock(world, i + 7, j + 8, k + 10, Dungeons.amethystStone, 0);
        this.setBlock(world, i + 7, j + 8, k + 21, Dungeons.amethystStone, 0);
        this.setBlock(world, i + 7, j + 8, k + 22, Dungeons.amethystStone, 0);
        this.setBlock(world, i + 7, j + 8, k + 23, Dungeons.amethystStone, 0);
        this.setBlock(world, i + 7, j + 8, k + 24, Dungeons.amethystStone, 0);
        this.setBlock(world, i + 7, j + 9, k + 8, Dungeons.amethystStone, 0);
        this.setBlock(world, i + 7, j + 9, k + 9, Dungeons.amethystStone, 0);
        this.setBlock(world, i + 7, j + 9, k + 22, Dungeons.amethystStone, 0);
        this.setBlock(world, i + 7, j + 9, k + 23, Dungeons.amethystStone, 0);
        this.setBlock(world, i + 7, j + 9, k + 24, Dungeons.amethystStone, 0);
        this.setBlock(world, i + 7, j + 10, k + 8, Dungeons.amethystStone, 0);
        this.setBlock(world, i + 7, j + 10, k + 9, Dungeons.amethystStone, 0);
        this.setBlock(world, i + 7, j + 10, k + 22, Dungeons.amethystStone, 0);
        this.setBlock(world, i + 7, j + 10, k + 23, Dungeons.amethystStone, 0);
        this.setBlock(world, i + 7, j + 10, k + 24, Dungeons.amethystStone, 0);
        this.setBlock(world, i + 7, j + 10, k + 25, Dungeons.amethystStone, 0);
        this.setBlock(world, i + 7, j + 10, k + 26, Dungeons.amethystStone, 0);
        this.setBlock(world, i + 7, j + 11, k + 8, Dungeons.amethystStone, 0);
        this.setBlock(world, i + 7, j + 11, k + 9, Dungeons.amethystStone, 0);
        this.setBlock(world, i + 7, j + 11, k + 23, Dungeons.amethystStone, 0);
        this.setBlock(world, i + 7, j + 11, k + 24, Dungeons.amethystStone, 0);
        this.setBlock(world, i + 7, j + 11, k + 25, Dungeons.amethystStone, 0);
        this.setBlock(world, i + 7, j + 11, k + 26, Dungeons.amethystStone, 0);
        this.setBlock(world, i + 7, j + 12, k + 8, Dungeons.amethystStone, 0);
        this.setBlock(world, i + 7, j + 12, k + 9, Dungeons.amethystStone, 0);
        this.setBlock(world, i + 7, j + 12, k + 23, Dungeons.amethystStone, 0);
        this.setBlock(world, i + 7, j + 12, k + 24, Dungeons.amethystStone, 0);
        this.setBlock(world, i + 7, j + 12, k + 25, Dungeons.amethystStone, 0);
        this.setBlock(world, i + 7, j + 13, k + 8, Dungeons.amethystStone, 0);
        this.setBlock(world, i + 7, j + 13, k + 9, Dungeons.amethystStone, 0);
        this.setBlock(world, i + 7, j + 13, k + 10, Dungeons.amethystStone, 0);
        this.setBlock(world, i + 7, j + 13, k + 23, Dungeons.amethystStone, 0);
        this.setBlock(world, i + 7, j + 13, k + 24, Dungeons.amethystStone, 0);
        this.setBlock(world, i + 7, j + 13, k + 25, Dungeons.amethystStone, 0);
        this.setBlock(world, i + 7, j + 14, k + 9, Dungeons.amethystStone, 0);
        this.setBlock(world, i + 7, j + 14, k + 10, Dungeons.amethystStone, 0);
        this.setBlock(world, i + 7, j + 14, k + 23, Dungeons.amethystStone, 0);
        this.setBlock(world, i + 7, j + 14, k + 24, Dungeons.amethystStone, 0);
        this.setBlock(world, i + 7, j + 15, k + 9, Dungeons.amethystStone, 0);
        this.setBlock(world, i + 7, j + 15, k + 10, Dungeons.amethystStone, 0);
        this.setBlock(world, i + 7, j + 15, k + 11, Dungeons.amethystStone, 0);
        this.setBlock(world, i + 7, j + 15, k + 23, Dungeons.amethystStone, 0);
        this.setBlock(world, i + 7, j + 16, k + 9, Dungeons.amethystStone, 0);
        this.setBlock(world, i + 7, j + 16, k + 10, Dungeons.amethystStone, 0);
        this.setBlock(world, i + 7, j + 16, k + 11, Dungeons.amethystStone, 0);
        this.setBlock(world, i + 7, j + 16, k + 20, Dungeons.amethystStone, 0);
        this.setBlock(world, i + 7, j + 16, k + 21, Dungeons.amethystStone, 0);
        this.setBlock(world, i + 7, j + 16, k + 22, Dungeons.amethystStone, 0);
        this.setBlock(world, i + 7, j + 16, k + 23, Dungeons.amethystStone, 0);
        this.setBlock(world, i + 7, j + 16, k + 24, Dungeons.amethystStone, 0);
        this.setBlock(world, i + 7, j + 17, k + 9, Dungeons.amethystStone, 0);
        this.setBlock(world, i + 7, j + 17, k + 10, Dungeons.amethystStone, 0);
        this.setBlock(world, i + 7, j + 17, k + 11, Dungeons.amethystStone, 0);
        this.setBlock(world, i + 7, j + 17, k + 12, Dungeons.amethystStone, 0);
        this.setBlock(world, i + 7, j + 17, k + 19, Dungeons.amethystStone, 0);
        this.setBlock(world, i + 7, j + 17, k + 20, Dungeons.amethystStone, 0);
        this.setBlock(world, i + 7, j + 17, k + 21, Dungeons.amethystStone, 0);
        this.setBlock(world, i + 7, j + 17, k + 22, Dungeons.amethystStone, 0);
        this.setBlock(world, i + 7, j + 17, k + 23, Dungeons.amethystStone, 0);
        this.setBlock(world, i + 7, j + 18, k + 10, Dungeons.amethystStone, 0);
        this.setBlock(world, i + 7, j + 18, k + 11, Dungeons.amethystStone, 0);
        this.setBlock(world, i + 7, j + 18, k + 12, Dungeons.amethystStone, 0);
        this.setBlock(world, i + 7, j + 18, k + 13, Dungeons.amethystStone, 0);
        this.setBlock(world, i + 7, j + 18, k + 14, Dungeons.amethystStone, 0);
        this.setBlock(world, i + 7, j + 18, k + 16, Dungeons.amethystStone, 0);
        this.setBlock(world, i + 7, j + 18, k + 17, Dungeons.amethystStone, 0);
        this.setBlock(world, i + 7, j + 18, k + 18, Dungeons.amethystStone, 0);
        this.setBlock(world, i + 7, j + 18, k + 19, Dungeons.amethystStone, 0);
        this.setBlock(world, i + 7, j + 18, k + 20, Dungeons.amethystStone, 0);
        this.setBlock(world, i + 7, j + 18, k + 21, Dungeons.amethystStone, 0);
        this.setBlock(world, i + 7, j + 19, k + 12, Dungeons.amethystStone, 0);
        this.setBlock(world, i + 7, j + 19, k + 13, Dungeons.amethystStone, 0);
        this.setBlock(world, i + 7, j + 19, k + 14, Dungeons.amethystStone, 0);
        this.setBlock(world, i + 7, j + 19, k + 15, Dungeons.amethystStone, 0);
        this.setBlock(world, i + 7, j + 19, k + 16, Dungeons.amethystStone, 0);
        this.setBlock(world, i + 7, j + 19, k + 18, Dungeons.amethystStone, 0);
        this.setBlock(world, i + 7, j + 19, k + 19, Dungeons.amethystStone, 0);
        this.setBlock(world, i + 7, j + 19, k + 20, Dungeons.amethystStone, 0);
        this.setBlock(world, i + 7, j + 19, k + 21, Dungeons.amethystStone, 0);
        this.setBlock(world, i + 7, j + 20, k + 12, Dungeons.amethystStone, 0);
        this.setBlock(world, i + 7, j + 20, k + 16, Dungeons.amethystStone, 0);
        this.setBlock(world, i + 7, j + 20, k + 18, Dungeons.amethystStone, 0);
        this.setBlock(world, i + 7, j + 20, k + 19, Dungeons.amethystStone, 0);
        this.setBlock(world, i + 7, j + 20, k + 20, Dungeons.amethystStone, 0);
        this.setBlock(world, i + 7, j + 20, k + 21, Dungeons.amethystStone, 0);
        this.setBlock(world, i + 7, j + 21, k + 12, Dungeons.amethystStone, 0);
        this.setBlock(world, i + 7, j + 21, k + 18, Dungeons.amethystStone, 0);
        this.setBlock(world, i + 7, j + 21, k + 19, Dungeons.amethystStone, 0);
        this.setBlock(world, i + 7, j + 22, k + 12, Dungeons.amethystStone, 0);
        this.setBlock(world, i + 8, j + 2, k + 15, Dungeons.amethystStone, 0);
        this.setBlock(world, i + 8, j + 3, k + 15, Dungeons.amethystStone, 0);
        this.setBlock(world, i + 8, j + 4, k + 15, Dungeons.amethystStone, 0);
        this.setBlock(world, i + 8, j + 5, k + 13, Dungeons.amethystStone, 0);
        this.setBlock(world, i + 8, j + 5, k + 14, Dungeons.amethystStone, 0);
        this.setBlock(world, i + 8, j + 5, k + 15, Dungeons.amethystStone, 0);
        this.setBlock(world, i + 8, j + 5, k + 16, Dungeons.amethystStone, 0);
        this.setBlock(world, i + 8, j + 5, k + 17, Dungeons.amethystStone, 0);
        this.setBlock(world, i + 8, j + 5, k + 18, Dungeons.amethystStone, 0);
        this.setBlock(world, i + 8, j + 5, k + 19, Dungeons.amethystStone, 0);
        this.setBlock(world, i + 8, j + 5, k + 20, Dungeons.amethystStone, 0);
        this.setBlock(world, i + 8, j + 6, k + 11, Dungeons.amethystStone, 0);
        this.setBlock(world, i + 8, j + 6, k + 12, Dungeons.amethystStone, 0);
        this.setBlock(world, i + 8, j + 6, k + 13, Dungeons.amethystStone, 0);
        this.setBlock(world, i + 8, j + 6, k + 14, Dungeons.amethystStone, 0);
        this.setBlock(world, i + 8, j + 6, k + 15, Dungeons.amethystStone, 0);
        this.setBlock(world, i + 8, j + 6, k + 16, Dungeons.amethystStone, 0);
        this.setBlock(world, i + 8, j + 6, k + 17, Dungeons.amethystStone, 0);
        this.setBlock(world, i + 8, j + 6, k + 18, Dungeons.amethystStone, 0);
        this.setBlock(world, i + 8, j + 6, k + 19, Dungeons.amethystStone, 0);
        this.setBlock(world, i + 8, j + 6, k + 20, Dungeons.amethystStone, 0);
        this.setBlock(world, i + 8, j + 7, k + 9, Dungeons.amethystStone, 0);
        this.setBlock(world, i + 8, j + 7, k + 10, Dungeons.amethystStone, 0);
        this.setBlock(world, i + 8, j + 7, k + 11, Dungeons.amethystStone, 0);
        this.setBlock(world, i + 8, j + 7, k + 21, Dungeons.amethystStone, 0);
        this.setBlock(world, i + 8, j + 7, k + 22, Dungeons.amethystStone, 0);
        this.setBlock(world, i + 8, j + 7, k + 23, Dungeons.amethystStone, 0);
        this.setBlock(world, i + 8, j + 8, k + 7, Dungeons.amethystStone, 0);
        this.setBlock(world, i + 8, j + 8, k + 8, Dungeons.amethystStone, 0);
        this.setBlock(world, i + 8, j + 8, k + 9, Dungeons.amethystStone, 0);
        this.setBlock(world, i + 8, j + 8, k + 10, Dungeons.amethystStone, 0);
        this.setBlock(world, i + 8, j + 8, k + 22, Dungeons.amethystStone, 0);
        this.setBlock(world, i + 8, j + 8, k + 23, Dungeons.amethystStone, 0);
        this.setBlock(world, i + 8, j + 8, k + 24, Dungeons.amethystStone, 0);
        this.setBlock(world, i + 8, j + 9, k + 7, Dungeons.amethystStone, 0);
        this.setBlock(world, i + 8, j + 9, k + 8, Dungeons.amethystStone, 0);
        this.setBlock(world, i + 8, j + 9, k + 9, Dungeons.amethystStone, 0);
        this.setBlock(world, i + 8, j + 9, k + 24, Dungeons.amethystStone, 0);
        this.setBlock(world, i + 8, j + 9, k + 25, Dungeons.amethystStone, 0);
        this.setBlock(world, i + 8, j + 10, k + 7, Dungeons.amethystStone, 0);
        this.setBlock(world, i + 8, j + 10, k + 8, Dungeons.amethystStone, 0);
        this.setBlock(world, i + 8, j + 10, k + 23, Dungeons.amethystStone, 0);
        this.setBlock(world, i + 8, j + 10, k + 24, Dungeons.amethystStone, 0);
        this.setBlock(world, i + 8, j + 10, k + 25, Dungeons.amethystStone, 0);
        this.setBlock(world, i + 8, j + 10, k + 26, Dungeons.amethystStone, 0);
        this.setBlock(world, i + 8, j + 11, k + 6, Dungeons.amethystStone, 0);
        this.setBlock(world, i + 8, j + 11, k + 7, Dungeons.amethystStone, 0);
        this.setBlock(world, i + 8, j + 11, k + 8, Dungeons.amethystStone, 0);
        this.setBlock(world, i + 8, j + 11, k + 23, Dungeons.amethystStone, 0);
        this.setBlock(world, i + 8, j + 11, k + 24, Dungeons.amethystStone, 0);
        this.setBlock(world, i + 8, j + 11, k + 25, Dungeons.amethystStone, 0);
        this.setBlock(world, i + 8, j + 11, k + 26, Dungeons.amethystStone, 0);
        this.setBlock(world, i + 8, j + 12, k + 6, Dungeons.amethystStone, 0);
        this.setBlock(world, i + 8, j + 12, k + 7, Dungeons.amethystStone, 0);
        this.setBlock(world, i + 8, j + 12, k + 8, Dungeons.amethystStone, 0);
        this.setBlock(world, i + 8, j + 12, k + 9, Dungeons.amethystStone, 0);
        this.setBlock(world, i + 8, j + 12, k + 24, Dungeons.amethystStone, 0);
        this.setBlock(world, i + 8, j + 12, k + 25, Dungeons.amethystStone, 0);
        this.setBlock(world, i + 8, j + 12, k + 26, Dungeons.amethystStone, 0);
        this.setBlock(world, i + 8, j + 13, k + 6, Dungeons.amethystStone, 0);
        this.setBlock(world, i + 8, j + 13, k + 7, Dungeons.amethystStone, 0);
        this.setBlock(world, i + 8, j + 13, k + 8, Dungeons.amethystStone, 0);
        this.setBlock(world, i + 8, j + 13, k + 9, Dungeons.amethystStone, 0);
        this.setBlock(world, i + 8, j + 13, k + 24, Dungeons.amethystStone, 0);
        this.setBlock(world, i + 8, j + 13, k + 25, Dungeons.amethystStone, 0);
        this.setBlock(world, i + 8, j + 14, k + 7, Dungeons.amethystStone, 0);
        this.setBlock(world, i + 8, j + 14, k + 8, Dungeons.amethystStone, 0);
        this.setBlock(world, i + 8, j + 14, k + 9, Dungeons.amethystStone, 0);
        this.setBlock(world, i + 8, j + 14, k + 10, Dungeons.amethystStone, 0);
        this.setBlock(world, i + 8, j + 14, k + 15, Dungeons.carvedCrystalliumBrick, 0);
        this.setBlock(world, i + 8, j + 14, k + 23, Dungeons.amethystStone, 0);
        this.setBlock(world, i + 8, j + 14, k + 24, Dungeons.amethystStone, 0);
        this.setBlock(world, i + 8, j + 14, k + 25, Dungeons.amethystStone, 0);
        this.setBlock(world, i + 8, j + 15, k + 8, Dungeons.amethystStone, 0);
        this.setBlock(world, i + 8, j + 15, k + 9, Dungeons.amethystStone, 0);
        this.setBlock(world, i + 8, j + 15, k + 10, Dungeons.amethystStone, 0);
        this.setBlock(world, i + 8, j + 15, k + 11, Dungeons.amethystStone, 0);
        this.setBlock(world, i + 8, j + 15, k + 15, Dungeons.carvedCrystalliumBrick, 0);
        this.setBlock(world, i + 8, j + 15, k + 23, Dungeons.amethystStone, 0);
        this.setBlock(world, i + 8, j + 15, k + 24, Dungeons.amethystStone, 0);
        this.setBlock(world, i + 8, j + 15, k + 25, Dungeons.amethystStone, 0);
        this.setBlock(world, i + 8, j + 16, k + 8, Dungeons.amethystStone, 0);
        this.setBlock(world, i + 8, j + 16, k + 9, Dungeons.amethystStone, 0);
        this.setBlock(world, i + 8, j + 16, k + 10, Dungeons.amethystStone, 0);
        this.setBlock(world, i + 8, j + 16, k + 11, Dungeons.amethystStone, 0);
        this.setBlock(world, i + 8, j + 16, k + 15, Dungeons.carvedCrystalliumBrick, 0);
        this.setBlock(world, i + 8, j + 16, k + 22, Dungeons.amethystStone, 0);
        this.setBlock(world, i + 8, j + 16, k + 23, Dungeons.amethystStone, 0);
        this.setBlock(world, i + 8, j + 16, k + 24, Dungeons.amethystStone, 0);
        this.setBlock(world, i + 8, j + 16, k + 25, Dungeons.amethystStone, 0);
        this.setBlock(world, i + 8, j + 17, k + 8, Dungeons.amethystStone, 0);
        this.setBlock(world, i + 8, j + 17, k + 9, Dungeons.amethystStone, 0);
        this.setBlock(world, i + 8, j + 17, k + 10, Dungeons.amethystStone, 0);
        this.setBlock(world, i + 8, j + 17, k + 11, Dungeons.amethystStone, 0);
        this.setBlock(world, i + 8, j + 17, k + 15, Dungeons.carvedCrystalliumBrick, 0);
        this.setBlock(world, i + 8, j + 17, k + 16, Dungeons.carvedCrystalliumBrick, 0);
        this.setBlock(world, i + 8, j + 17, k + 22, Dungeons.amethystStone, 0);
        this.setBlock(world, i + 8, j + 17, k + 23, Dungeons.amethystStone, 0);
        this.setBlock(world, i + 8, j + 17, k + 24, Dungeons.amethystStone, 0);
        this.setBlock(world, i + 8, j + 17, k + 25, Dungeons.amethystStone, 0);
        this.setBlock(world, i + 8, j + 18, k + 10, Dungeons.amethystStone, 0);
        this.setBlock(world, i + 8, j + 18, k + 11, Dungeons.amethystStone, 0);
        this.setBlock(world, i + 8, j + 18, k + 12, Dungeons.amethystStone, 0);
        this.setBlock(world, i + 8, j + 18, k + 13, Dungeons.amethystStone, 0);
        this.setBlock(world, i + 8, j + 18, k + 15, Dungeons.carvedCrystalliumBrick, 0);
        this.setBlock(world, i + 8, j + 18, k + 16, Dungeons.carvedCrystalliumBrick, 0);
        this.setBlock(world, i + 8, j + 18, k + 20, Dungeons.amethystStone, 0);
        this.setBlock(world, i + 8, j + 18, k + 21, Dungeons.amethystStone, 0);
        this.setBlock(world, i + 8, j + 18, k + 22, Dungeons.amethystStone, 0);
        this.setBlock(world, i + 8, j + 18, k + 23, Dungeons.amethystStone, 0);
        this.setBlock(world, i + 8, j + 19, k + 12, Dungeons.amethystStone, 0);
        this.setBlock(world, i + 8, j + 19, k + 13, Dungeons.amethystStone, 0);
        this.setBlock(world, i + 8, j + 19, k + 14, Dungeons.amethystStone, 0);
        this.setBlock(world, i + 8, j + 19, k + 15, Dungeons.amethystStone, 0);
        this.setBlock(world, i + 8, j + 19, k + 16, Dungeons.amethystStone, 0);
        this.setBlock(world, i + 8, j + 19, k + 17, Dungeons.amethystStone, 0);
        this.setBlock(world, i + 8, j + 19, k + 18, Dungeons.amethystStone, 0);
        this.setBlock(world, i + 8, j + 19, k + 19, Dungeons.amethystStone, 0);
        this.setBlock(world, i + 8, j + 19, k + 20, Dungeons.amethystStone, 0);
        this.setBlock(world, i + 8, j + 19, k + 21, Dungeons.amethystStone, 0);
        this.setBlock(world, i + 8, j + 19, k + 22, Dungeons.amethystStone, 0);
        this.setBlock(world, i + 8, j + 19, k + 23, Dungeons.amethystStone, 0);
        this.setBlock(world, i + 8, j + 20, k + 13, Dungeons.amethystStone, 0);
        this.setBlock(world, i + 8, j + 20, k + 14, Dungeons.amethystStone, 0);
        this.setBlock(world, i + 8, j + 20, k + 15, Dungeons.amethystStone, 0);
        this.setBlock(world, i + 8, j + 20, k + 16, Dungeons.amethystStone, 0);
        this.setBlock(world, i + 8, j + 20, k + 17, Dungeons.amethystStone, 0);
        this.setBlock(world, i + 8, j + 20, k + 18, Dungeons.amethystStone, 0);
        this.setBlock(world, i + 8, j + 20, k + 19, Dungeons.amethystStone, 0);
        this.setBlock(world, i + 8, j + 20, k + 20, Dungeons.amethystStone, 0);
        this.setBlock(world, i + 8, j + 20, k + 21, Dungeons.amethystStone, 0);
        this.setBlock(world, i + 8, j + 20, k + 22, Dungeons.amethystStone, 0);
        this.setBlock(world, i + 8, j + 20, k + 23, Dungeons.amethystStone, 0);
        this.setBlock(world, i + 8, j + 21, k + 17, Dungeons.amethystStone, 0);
        this.setBlock(world, i + 8, j + 21, k + 18, Dungeons.amethystStone, 0);
        this.setBlock(world, i + 8, j + 21, k + 19, Dungeons.amethystStone, 0);
        this.setBlock(world, i + 8, j + 21, k + 20, Dungeons.amethystStone, 0);
        this.setBlock(world, i + 8, j + 22, k + 18, Dungeons.amethystStone, 0);
        this.setBlock(world, i + 9, j + 3, k + 12, Dungeons.amethystStone, 0);
        this.setBlock(world, i + 9, j + 4, k + 12, Dungeons.amethystStone, 0);
        this.setBlock(world, i + 9, j + 4, k + 13, Dungeons.amethystStone, 0);
        this.setBlock(world, i + 9, j + 4, k + 14, Dungeons.amethystStone, 0);
        this.setBlock(world, i + 9, j + 4, k + 15, Dungeons.amethystStone, 0);
        this.setBlock(world, i + 9, j + 4, k + 16, Dungeons.amethystStone, 0);
        this.setBlock(world, i + 9, j + 4, k + 17, Dungeons.amethystStone, 0);
        this.setBlock(world, i + 9, j + 4, k + 18, Dungeons.amethystStone, 0);
        this.setBlock(world, i + 9, j + 5, k + 12, Dungeons.amethystStone, 0);
        this.setBlock(world, i + 9, j + 5, k + 13, Dungeons.amethystStone, 0);
        this.setBlock(world, i + 9, j + 5, k + 14, Dungeons.amethystStone, 0);
        this.setBlock(world, i + 9, j + 5, k + 15, Dungeons.amethystStone, 0);
        this.setBlock(world, i + 9, j + 5, k + 16, Dungeons.amethystStone, 0);
        this.setBlock(world, i + 9, j + 5, k + 17, Dungeons.amethystStone, 0);
        this.setBlock(world, i + 9, j + 5, k + 18, Dungeons.amethystStone, 0);
        this.setBlock(world, i + 9, j + 5, k + 19, Dungeons.amethystStone, 0);
        this.setBlock(world, i + 9, j + 5, k + 20, Dungeons.amethystStone, 0);
        this.setBlock(world, i + 9, j + 6, k + 11, Dungeons.amethystStone, 0);
        this.setBlock(world, i + 9, j + 6, k + 12, Dungeons.amethystStone, 0);
        this.setBlock(world, i + 9, j + 6, k + 13, Dungeons.amethystStone, 0);
        this.setBlock(world, i + 9, j + 6, k + 21, Dungeons.amethystStone, 0);
        this.setBlock(world, i + 9, j + 6, k + 22, Dungeons.amethystStone, 0);
        this.setBlock(world, i + 9, j + 7, k + 9, Dungeons.amethystStone, 0);
        this.setBlock(world, i + 9, j + 7, k + 10, Dungeons.amethystStone, 0);
        this.setBlock(world, i + 9, j + 7, k + 22, Dungeons.amethystStone, 0);
        this.setBlock(world, i + 9, j + 7, k + 23, Dungeons.amethystStone, 0);
        this.setBlock(world, i + 9, j + 7, k + 24, Dungeons.amethystStone, 0);
        this.setBlock(world, i + 9, j + 7, k + 25, Dungeons.amethystStone, 0);
        this.setBlock(world, i + 9, j + 8, k + 7, Dungeons.amethystStone, 0);
        this.setBlock(world, i + 9, j + 8, k + 8, Dungeons.amethystStone, 0);
        this.setBlock(world, i + 9, j + 8, k + 9, Dungeons.amethystStone, 0);
        this.setBlock(world, i + 9, j + 8, k + 10, Dungeons.amethystStone, 0);
        this.setBlock(world, i + 9, j + 8, k + 23, Dungeons.amethystStone, 0);
        this.setBlock(world, i + 9, j + 8, k + 24, Dungeons.amethystStone, 0);
        this.setBlock(world, i + 9, j + 8, k + 25, Dungeons.amethystStone, 0);
        this.setBlock(world, i + 9, j + 9, k + 7, Dungeons.amethystStone, 0);
        this.setBlock(world, i + 9, j + 9, k + 8, Dungeons.amethystStone, 0);
        this.setBlock(world, i + 9, j + 9, k + 9, Dungeons.amethystStone, 0);
        this.setBlock(world, i + 9, j + 9, k + 24, Dungeons.amethystStone, 0);
        this.setBlock(world, i + 9, j + 9, k + 25, Dungeons.amethystStone, 0);
        this.setBlock(world, i + 9, j + 9, k + 26, Dungeons.amethystStone, 0);
        this.setBlock(world, i + 9, j + 10, k + 6, Dungeons.amethystStone, 0);
        this.setBlock(world, i + 9, j + 10, k + 7, Dungeons.amethystStone, 0);
        this.setBlock(world, i + 9, j + 10, k + 8, Dungeons.amethystStone, 0);
        this.setBlock(world, i + 9, j + 10, k + 24, Dungeons.amethystStone, 0);
        this.setBlock(world, i + 9, j + 10, k + 25, Dungeons.amethystStone, 0);
        this.setBlock(world, i + 9, j + 10, k + 26, Dungeons.amethystStone, 0);
        this.setBlock(world, i + 9, j + 10, k + 27, Dungeons.amethystStone, 0);
        this.setBlock(world, i + 9, j + 11, k + 5, Dungeons.amethystStone, 0);
        this.setBlock(world, i + 9, j + 11, k + 6, Dungeons.amethystStone, 0);
        this.setBlock(world, i + 9, j + 11, k + 7, Dungeons.amethystStone, 0);
        this.setBlock(world, i + 9, j + 11, k + 8, Dungeons.amethystStone, 0);
        this.setBlock(world, i + 9, j + 11, k + 24, Dungeons.amethystStone, 0);
        this.setBlock(world, i + 9, j + 11, k + 25, Dungeons.amethystStone, 0);
        this.setBlock(world, i + 9, j + 11, k + 26, Dungeons.amethystStone, 0);
        this.setBlock(world, i + 9, j + 11, k + 27, Dungeons.amethystStone, 0);
        this.setBlock(world, i + 9, j + 12, k + 5, Dungeons.amethystStone, 0);
        this.setBlock(world, i + 9, j + 12, k + 6, Dungeons.amethystStone, 0);
        this.setBlock(world, i + 9, j + 12, k + 7, Dungeons.amethystStone, 0);
        this.setBlock(world, i + 9, j + 12, k + 8, Dungeons.amethystStone, 0);
        this.setBlock(world, i + 9, j + 12, k + 25, Dungeons.amethystStone, 0);
        this.setBlock(world, i + 9, j + 12, k + 26, Dungeons.amethystStone, 0);
        this.setBlock(world, i + 9, j + 13, k + 5, Dungeons.amethystStone, 0);
        this.setBlock(world, i + 9, j + 13, k + 6, Dungeons.amethystStone, 0);
        this.setBlock(world, i + 9, j + 13, k + 7, Dungeons.amethystStone, 0);
        this.setBlock(world, i + 9, j + 13, k + 8, Dungeons.amethystStone, 0);
        this.setBlock(world, i + 9, j + 13, k + 9, Dungeons.amethystStone, 0);
        this.setBlock(world, i + 9, j + 13, k + 24, Dungeons.amethystStone, 0);
        this.setBlock(world, i + 9, j + 13, k + 25, Dungeons.amethystStone, 0);
        this.setBlock(world, i + 9, j + 13, k + 26, Dungeons.amethystStone, 0);
        this.setBlock(world, i + 9, j + 14, k + 6, Dungeons.amethystStone, 0);
        this.setBlock(world, i + 9, j + 14, k + 7, Dungeons.amethystStone, 0);
        this.setBlock(world, i + 9, j + 14, k + 8, Dungeons.amethystStone, 0);
        this.setBlock(world, i + 9, j + 14, k + 9, Dungeons.amethystStone, 0);
        this.setBlock(world, i + 9, j + 14, k + 24, Dungeons.amethystStone, 0);
        this.setBlock(world, i + 9, j + 14, k + 25, Dungeons.amethystStone, 0);
        this.setBlock(world, i + 9, j + 15, k + 6, Dungeons.amethystStone, 0);
        this.setBlock(world, i + 9, j + 15, k + 7, Dungeons.amethystStone, 0);
        this.setBlock(world, i + 9, j + 15, k + 8, Dungeons.amethystStone, 0);
        this.setBlock(world, i + 9, j + 15, k + 9, Dungeons.amethystStone, 0);
        this.setBlock(world, i + 9, j + 15, k + 10, Dungeons.amethystStone, 0);
        this.setBlock(world, i + 9, j + 15, k + 23, Dungeons.amethystStone, 0);
        this.setBlock(world, i + 9, j + 15, k + 24, Dungeons.amethystStone, 0);
        this.setBlock(world, i + 9, j + 15, k + 25, Dungeons.amethystStone, 0);
        this.setBlock(world, i + 9, j + 16, k + 6, Dungeons.amethystStone, 0);
        this.setBlock(world, i + 9, j + 16, k + 7, Dungeons.amethystStone, 0);
        this.setBlock(world, i + 9, j + 16, k + 8, Dungeons.amethystStone, 0);
        this.setBlock(world, i + 9, j + 16, k + 9, Dungeons.amethystStone, 0);
        this.setBlock(world, i + 9, j + 16, k + 10, Dungeons.amethystStone, 0);
        this.setBlock(world, i + 9, j + 16, k + 23, Dungeons.amethystStone, 0);
        this.setBlock(world, i + 9, j + 16, k + 24, Dungeons.amethystStone, 0);
        this.setBlock(world, i + 9, j + 16, k + 25, Dungeons.amethystStone, 0);
        this.setBlock(world, i + 9, j + 17, k + 7, Dungeons.amethystStone, 0);
        this.setBlock(world, i + 9, j + 17, k + 8, Dungeons.amethystStone, 0);
        this.setBlock(world, i + 9, j + 17, k + 9, Dungeons.amethystStone, 0);
        this.setBlock(world, i + 9, j + 17, k + 10, Dungeons.amethystStone, 0);
        this.setBlock(world, i + 9, j + 17, k + 11, Dungeons.amethystStone, 0);
        this.setBlock(world, i + 9, j + 17, k + 23, Dungeons.amethystStone, 0);
        this.setBlock(world, i + 9, j + 17, k + 24, Dungeons.amethystStone, 0);
        this.setBlock(world, i + 9, j + 17, k + 25, Dungeons.amethystStone, 0);
        this.setBlock(world, i + 9, j + 18, k + 7, Dungeons.amethystStone, 0);
        this.setBlock(world, i + 9, j + 18, k + 10, Dungeons.amethystStone, 0);
        this.setBlock(world, i + 9, j + 18, k + 11, Dungeons.amethystStone, 0);
        this.setBlock(world, i + 9, j + 18, k + 12, Dungeons.amethystStone, 0);
        this.setBlock(world, i + 9, j + 18, k + 15, Dungeons.carvedCrystalliumBrick, 0);
        this.setBlock(world, i + 9, j + 18, k + 23, Dungeons.amethystStone, 0);
        this.setBlock(world, i + 9, j + 18, k + 24, Dungeons.amethystStone, 0);
        this.setBlock(world, i + 9, j + 19, k + 7, Dungeons.amethystStone, 0);
        this.setBlock(world, i + 9, j + 19, k + 11, Dungeons.amethystStone, 0);
        this.setBlock(world, i + 9, j + 19, k + 12, Dungeons.amethystStone, 0);
        this.setBlock(world, i + 9, j + 19, k + 13, Dungeons.amethystStone, 0);
        this.setBlock(world, i + 9, j + 19, k + 14, Dungeons.amethystStone, 0);
        this.setBlock(world, i + 9, j + 19, k + 15, Dungeons.carvedCrystalliumBrick, 0);
        this.setBlock(world, i + 9, j + 19, k + 20, Dungeons.amethystStone, 0);
        this.setBlock(world, i + 9, j + 19, k + 21, Dungeons.amethystStone, 0);
        this.setBlock(world, i + 9, j + 19, k + 22, Dungeons.amethystStone, 0);
        this.setBlock(world, i + 9, j + 19, k + 23, Dungeons.amethystStone, 0);
        this.setBlock(world, i + 9, j + 19, k + 24, Dungeons.amethystStone, 0);
        this.setBlock(world, i + 9, j + 20, k + 12, Dungeons.amethystStone, 0);
        this.setBlock(world, i + 9, j + 20, k + 13, Dungeons.amethystStone, 0);
        this.setBlock(world, i + 9, j + 20, k + 14, Dungeons.amethystStone, 0);
        this.setBlock(world, i + 9, j + 20, k + 15, Dungeons.amethystStone, 0);
        this.setBlock(world, i + 9, j + 20, k + 16, Dungeons.amethystStone, 0);
        this.setBlock(world, i + 9, j + 20, k + 17, Dungeons.amethystStone, 0);
        this.setBlock(world, i + 9, j + 20, k + 18, Dungeons.amethystStone, 0);
        this.setBlock(world, i + 9, j + 20, k + 19, Dungeons.amethystStone, 0);
        this.setBlock(world, i + 9, j + 20, k + 20, Dungeons.amethystStone, 0);
        this.setBlock(world, i + 9, j + 20, k + 21, Dungeons.amethystStone, 0);
        this.setBlock(world, i + 9, j + 20, k + 22, Dungeons.amethystStone, 0);
        this.setBlock(world, i + 9, j + 20, k + 23, Dungeons.amethystStone, 0);
        this.setBlock(world, i + 9, j + 20, k + 24, Dungeons.amethystStone, 0);
        this.setBlock(world, i + 9, j + 21, k + 12, Dungeons.amethystStone, 0);
        this.setBlock(world, i + 9, j + 21, k + 13, Dungeons.amethystStone, 0);
        this.setBlock(world, i + 9, j + 21, k + 14, Dungeons.amethystStone, 0);
        this.setBlock(world, i + 9, j + 21, k + 15, Dungeons.amethystStone, 0);
        this.setBlock(world, i + 9, j + 21, k + 16, Dungeons.amethystStone, 0);
        this.setBlock(world, i + 9, j + 21, k + 17, Dungeons.amethystStone, 0);
        this.setBlock(world, i + 9, j + 21, k + 18, Dungeons.amethystStone, 0);
        this.setBlock(world, i + 9, j + 21, k + 19, Dungeons.amethystStone, 0);
        this.setBlock(world, i + 9, j + 21, k + 20, Dungeons.amethystStone, 0);
        this.setBlock(world, i + 9, j + 21, k + 21, Dungeons.amethystStone, 0);
        this.setBlock(world, i + 9, j + 21, k + 22, Dungeons.amethystStone, 0);
        this.setBlock(world, i + 9, j + 22, k + 12, Dungeons.amethystStone, 0);
        this.setBlock(world, i + 9, j + 22, k + 15, Dungeons.amethystStone, 0);
        this.setBlock(world, i + 9, j + 22, k + 16, Dungeons.amethystStone, 0);
        this.setBlock(world, i + 9, j + 22, k + 17, Dungeons.amethystStone, 0);
        this.setBlock(world, i + 9, j + 22, k + 18, Dungeons.amethystStone, 0);
        this.setBlock(world, i + 9, j + 22, k + 19, Dungeons.amethystStone, 0);
        this.setBlock(world, i + 9, j + 22, k + 22, Dungeons.amethystStone, 0);
        this.setBlock(world, i + 9, j + 23, k + 12, Dungeons.amethystStone, 0);
        this.setBlock(world, i + 9, j + 23, k + 18, Dungeons.amethystStone, 0);
        this.setBlock(world, i + 9, j + 24, k + 18, Dungeons.amethystStone, 0);
        this.setBlock(world, i + 10, j + 2, k + 20, Dungeons.amethystStone, 0);
        this.setBlock(world, i + 10, j + 3, k + 20, Dungeons.amethystStone, 0);
        this.setBlock(world, i + 10, j + 3, k + 24, Dungeons.amethystStone, 0);
        this.setBlock(world, i + 10, j + 4, k + 13, Dungeons.amethystStone, 0);
        this.setBlock(world, i + 10, j + 4, k + 14, Dungeons.amethystStone, 0);
        this.setBlock(world, i + 10, j + 4, k + 15, Dungeons.amethystStone, 0);
        this.setBlock(world, i + 10, j + 4, k + 16, Dungeons.amethystStone, 0);
        this.setBlock(world, i + 10, j + 4, k + 17, Dungeons.amethystStone, 0);
        this.setBlock(world, i + 10, j + 4, k + 18, Dungeons.amethystStone, 0);
        this.setBlock(world, i + 10, j + 4, k + 19, Dungeons.amethystStone, 0);
        this.setBlock(world, i + 10, j + 4, k + 20, Dungeons.amethystStone, 0);
        this.setBlock(world, i + 10, j + 4, k + 24, Dungeons.amethystStone, 0);
        this.setBlock(world, i + 10, j + 5, k + 10, Dungeons.amethystStone, 0);
        this.setBlock(world, i + 10, j + 5, k + 11, Dungeons.amethystStone, 0);
        this.setBlock(world, i + 10, j + 5, k + 12, Dungeons.amethystStone, 0);
        this.setBlock(world, i + 10, j + 5, k + 13, Dungeons.amethystStone, 0);
        this.setBlock(world, i + 10, j + 5, k + 14, Dungeons.amethystStone, 0);
        this.setBlock(world, i + 10, j + 5, k + 15, Dungeons.amethystStone, 0);
        this.setBlock(world, i + 10, j + 5, k + 16, Dungeons.amethystStone, 0);
        this.setBlock(world, i + 10, j + 5, k + 20, Dungeons.amethystStone, 0);
        this.setBlock(world, i + 10, j + 5, k + 21, Dungeons.amethystStone, 0);
        this.setBlock(world, i + 10, j + 5, k + 22, Dungeons.amethystStone, 0);
        this.setBlock(world, i + 10, j + 5, k + 23, Dungeons.amethystStone, 0);
        this.setBlock(world, i + 10, j + 5, k + 24, Dungeons.amethystStone, 0);
        this.setBlock(world, i + 10, j + 6, k + 7, Dungeons.amethystStone, 0);
        this.setBlock(world, i + 10, j + 6, k + 10, Dungeons.amethystStone, 0);
        this.setBlock(world, i + 10, j + 6, k + 11, Dungeons.amethystStone, 0);
        this.setBlock(world, i + 10, j + 6, k + 12, Dungeons.amethystStone, 0);
        this.setBlock(world, i + 10, j + 6, k + 22, Dungeons.amethystStone, 0);
        this.setBlock(world, i + 10, j + 6, k + 23, Dungeons.amethystStone, 0);
        this.setBlock(world, i + 10, j + 6, k + 24, Dungeons.amethystStone, 0);
        this.setBlock(world, i + 10, j + 7, k + 7, Dungeons.amethystStone, 0);
        this.setBlock(world, i + 10, j + 7, k + 9, Dungeons.amethystStone, 0);
        this.setBlock(world, i + 10, j + 7, k + 10, Dungeons.amethystStone, 0);
        this.setBlock(world, i + 10, j + 7, k + 11, Dungeons.amethystStone, 0);
        this.setBlock(world, i + 10, j + 7, k + 23, Dungeons.amethystStone, 0);
        this.setBlock(world, i + 10, j + 7, k + 24, Dungeons.amethystStone, 0);
        this.setBlock(world, i + 10, j + 7, k + 25, Dungeons.amethystStone, 0);
        this.setBlock(world, i + 10, j + 8, k + 7, Dungeons.amethystStone, 0);
        this.setBlock(world, i + 10, j + 8, k + 8, Dungeons.amethystStone, 0);
        this.setBlock(world, i + 10, j + 8, k + 9, Dungeons.amethystStone, 0);
        this.setBlock(world, i + 10, j + 8, k + 10, Dungeons.amethystStone, 0);
        this.setBlock(world, i + 10, j + 8, k + 24, Dungeons.amethystStone, 0);
        this.setBlock(world, i + 10, j + 8, k + 25, Dungeons.amethystStone, 0);
        this.setBlock(world, i + 10, j + 9, k + 7, Dungeons.amethystStone, 0);
        this.setBlock(world, i + 10, j + 9, k + 8, Dungeons.amethystStone, 0);
        this.setBlock(world, i + 10, j + 9, k + 9, Dungeons.amethystStone, 0);
        this.setBlock(world, i + 10, j + 9, k + 24, Dungeons.amethystStone, 0);
        this.setBlock(world, i + 10, j + 9, k + 25, Dungeons.amethystStone, 0);
        this.setBlock(world, i + 10, j + 9, k + 26, Dungeons.amethystStone, 0);
        this.setBlock(world, i + 10, j + 10, k + 6, Dungeons.amethystStone, 0);
        this.setBlock(world, i + 10, j + 10, k + 7, Dungeons.amethystStone, 0);
        this.setBlock(world, i + 10, j + 10, k + 8, Dungeons.amethystStone, 0);
        this.setBlock(world, i + 10, j + 10, k + 25, Dungeons.amethystStone, 0);
        this.setBlock(world, i + 10, j + 10, k + 26, Dungeons.amethystStone, 0);
        this.setBlock(world, i + 10, j + 10, k + 27, Dungeons.amethystStone, 0);
        this.setBlock(world, i + 10, j + 11, k + 5, Dungeons.amethystStone, 0);
        this.setBlock(world, i + 10, j + 11, k + 6, Dungeons.amethystStone, 0);
        this.setBlock(world, i + 10, j + 11, k + 7, Dungeons.amethystStone, 0);
        this.setBlock(world, i + 10, j + 11, k + 8, Dungeons.amethystStone, 0);
        this.setBlock(world, i + 10, j + 11, k + 26, Dungeons.amethystStone, 0);
        this.setBlock(world, i + 10, j + 11, k + 27, Dungeons.amethystStone, 0);
        this.setBlock(world, i + 10, j + 12, k + 5, Dungeons.amethystStone, 0);
        this.setBlock(world, i + 10, j + 12, k + 6, Dungeons.amethystStone, 0);
        this.setBlock(world, i + 10, j + 12, k + 7, Dungeons.amethystStone, 0);
        this.setBlock(world, i + 10, j + 12, k + 8, Dungeons.amethystStone, 0);
        this.setBlock(world, i + 10, j + 12, k + 25, Dungeons.amethystStone, 0);
        this.setBlock(world, i + 10, j + 12, k + 26, Dungeons.amethystStone, 0);
        this.setBlock(world, i + 10, j + 12, k + 27, Dungeons.amethystStone, 0);
        this.setBlock(world, i + 10, j + 13, k + 5, Dungeons.amethystStone, 0);
        this.setBlock(world, i + 10, j + 13, k + 6, Dungeons.amethystStone, 0);
        this.setBlock(world, i + 10, j + 13, k + 7, Dungeons.amethystStone, 0);
        this.setBlock(world, i + 10, j + 13, k + 8, Dungeons.amethystStone, 0);
        this.setBlock(world, i + 10, j + 13, k + 25, Dungeons.amethystStone, 0);
        this.setBlock(world, i + 10, j + 13, k + 26, Dungeons.amethystStone, 0);
        this.setBlock(world, i + 10, j + 14, k + 5, Dungeons.amethystStone, 0);
        this.setBlock(world, i + 10, j + 14, k + 6, Dungeons.amethystStone, 0);
        this.setBlock(world, i + 10, j + 14, k + 7, Dungeons.amethystStone, 0);
        this.setBlock(world, i + 10, j + 14, k + 8, Dungeons.amethystStone, 0);
        this.setBlock(world, i + 10, j + 14, k + 24, Dungeons.amethystStone, 0);
        this.setBlock(world, i + 10, j + 14, k + 25, Dungeons.amethystStone, 0);
        this.setBlock(world, i + 10, j + 14, k + 26, Dungeons.amethystStone, 0);
        this.setBlock(world, i + 10, j + 15, k + 5, Dungeons.amethystStone, 0);
        this.setBlock(world, i + 10, j + 15, k + 6, Dungeons.amethystStone, 0);
        this.setBlock(world, i + 10, j + 15, k + 7, Dungeons.amethystStone, 0);
        this.setBlock(world, i + 10, j + 15, k + 8, Dungeons.amethystStone, 0);
        this.setBlock(world, i + 10, j + 15, k + 24, Dungeons.amethystStone, 0);
        this.setBlock(world, i + 10, j + 15, k + 25, Dungeons.amethystStone, 0);
        this.setBlock(world, i + 10, j + 15, k + 26, Dungeons.amethystStone, 0);
        this.setBlock(world, i + 10, j + 16, k + 6, Dungeons.amethystStone, 0);
        this.setBlock(world, i + 10, j + 16, k + 7, Dungeons.amethystStone, 0);
        this.setBlock(world, i + 10, j + 16, k + 8, Dungeons.amethystStone, 0);
        this.setBlock(world, i + 10, j + 16, k + 9, Dungeons.amethystStone, 0);
        this.setBlock(world, i + 10, j + 16, k + 10, Dungeons.amethystStone, 0);
        this.setBlock(world, i + 10, j + 16, k + 24, Dungeons.amethystStone, 0);
        this.setBlock(world, i + 10, j + 16, k + 26, Dungeons.amethystStone, 0);
        this.setBlock(world, i + 10, j + 17, k + 7, Dungeons.amethystStone, 0);
        this.setBlock(world, i + 10, j + 17, k + 8, Dungeons.amethystStone, 0);
        this.setBlock(world, i + 10, j + 17, k + 9, Dungeons.amethystStone, 0);
        this.setBlock(world, i + 10, j + 17, k + 10, Dungeons.amethystStone, 0);
        this.setBlock(world, i + 10, j + 17, k + 11, Dungeons.amethystStone, 0);
        this.setBlock(world, i + 10, j + 17, k + 24, Dungeons.amethystStone, 0);
        this.setBlock(world, i + 10, j + 17, k + 25, Dungeons.amethystStone, 0);
        this.setBlock(world, i + 10, j + 17, k + 26, Dungeons.amethystStone, 0);
        this.setBlock(world, i + 10, j + 18, k + 9, Dungeons.amethystStone, 0);
        this.setBlock(world, i + 10, j + 18, k + 10, Dungeons.amethystStone, 0);
        this.setBlock(world, i + 10, j + 18, k + 11, Dungeons.amethystStone, 0);
        this.setBlock(world, i + 10, j + 18, k + 12, Dungeons.amethystStone, 0);
        this.setBlock(world, i + 10, j + 18, k + 24, Dungeons.amethystStone, 0);
        this.setBlock(world, i + 10, j + 18, k + 25, Dungeons.amethystStone, 0);
        this.setBlock(world, i + 10, j + 19, k + 10, Dungeons.amethystStone, 0);
        this.setBlock(world, i + 10, j + 19, k + 11, Dungeons.amethystStone, 0);
        this.setBlock(world, i + 10, j + 19, k + 12, Dungeons.amethystStone, 0);
        this.setBlock(world, i + 10, j + 19, k + 23, Dungeons.amethystStone, 0);
        this.setBlock(world, i + 10, j + 19, k + 24, Dungeons.amethystStone, 0);
        this.setBlock(world, i + 10, j + 20, k + 11, Dungeons.amethystStone, 0);
        this.setBlock(world, i + 10, j + 20, k + 12, Dungeons.amethystStone, 0);
        this.setBlock(world, i + 10, j + 20, k + 13, Dungeons.amethystStone, 0);
        this.setBlock(world, i + 10, j + 20, k + 19, Dungeons.amethystStone, 0);
        this.setBlock(world, i + 10, j + 20, k + 20, Dungeons.amethystStone, 0);
        this.setBlock(world, i + 10, j + 20, k + 21, Dungeons.amethystStone, 0);
        this.setBlock(world, i + 10, j + 20, k + 22, Dungeons.amethystStone, 0);
        this.setBlock(world, i + 10, j + 20, k + 23, Dungeons.amethystStone, 0);
        this.setBlock(world, i + 10, j + 20, k + 24, Dungeons.amethystStone, 0);
        this.setBlock(world, i + 10, j + 21, k + 11, Dungeons.amethystStone, 0);
        this.setBlock(world, i + 10, j + 21, k + 12, Dungeons.amethystStone, 0);
        this.setBlock(world, i + 10, j + 21, k + 13, Dungeons.amethystStone, 0);
        this.setBlock(world, i + 10, j + 21, k + 14, Dungeons.amethystStone, 0);
        this.setBlock(world, i + 10, j + 21, k + 15, Dungeons.amethystStone, 0);
        this.setBlock(world, i + 10, j + 21, k + 16, Dungeons.amethystStone, 0);
        this.setBlock(world, i + 10, j + 21, k + 17, Dungeons.amethystStone, 0);
        this.setBlock(world, i + 10, j + 21, k + 18, Dungeons.amethystStone, 0);
        this.setBlock(world, i + 10, j + 21, k + 19, Dungeons.amethystStone, 0);
        this.setBlock(world, i + 10, j + 21, k + 20, Dungeons.amethystStone, 0);
        this.setBlock(world, i + 10, j + 21, k + 21, Dungeons.amethystStone, 0);
        this.setBlock(world, i + 10, j + 21, k + 22, Dungeons.amethystStone, 0);
        this.setBlock(world, i + 10, j + 21, k + 23, Dungeons.amethystStone, 0);
        this.setBlock(world, i + 10, j + 22, k + 15, Dungeons.amethystStone, 0);
        this.setBlock(world, i + 10, j + 22, k + 16, Dungeons.amethystStone, 0);
        this.setBlock(world, i + 10, j + 22, k + 17, Dungeons.amethystStone, 0);
        this.setBlock(world, i + 10, j + 22, k + 18, Dungeons.amethystStone, 0);
        this.setBlock(world, i + 10, j + 22, k + 19, Dungeons.amethystStone, 0);
        this.setBlock(world, i + 11, j + 2, k + 13, Dungeons.amethystStone, 0);
        this.setBlock(world, i + 11, j + 3, k + 13, Dungeons.amethystStone, 0);
        this.setBlock(world, i + 11, j + 3, k + 14, Dungeons.amethystStone, 0);
        this.setBlock(world, i + 11, j + 3, k + 15, Dungeons.amethystStone, 0);
        this.setBlock(world, i + 11, j + 3, k + 16, Dungeons.amethystStone, 0);
        this.setBlock(world, i + 11, j + 3, k + 17, Dungeons.amethystStone, 0);
        this.setBlock(world, i + 11, j + 3, k + 18, Dungeons.amethystStone, 0);
        this.setBlock(world, i + 11, j + 4, k + 12, Dungeons.amethystStone, 0);
        this.setBlock(world, i + 11, j + 4, k + 13, Dungeons.amethystStone, 0);
        this.setBlock(world, i + 11, j + 4, k + 14, Dungeons.amethystStone, 0);
        this.setBlock(world, i + 11, j + 4, k + 15, Dungeons.amethystStone, 0);
        this.setBlock(world, i + 11, j + 4, k + 16, Dungeons.amethystStone, 0);
        this.setBlock(world, i + 11, j + 4, k + 17, Dungeons.amethystStone, 0);
        this.setBlock(world, i + 11, j + 4, k + 18, Dungeons.amethystStone, 0);
        this.setBlock(world, i + 11, j + 4, k + 19, Dungeons.amethystStone, 0);
        this.setBlock(world, i + 11, j + 4, k + 20, Dungeons.amethystStone, 0);
        this.setBlock(world, i + 11, j + 4, k + 21, Dungeons.amethystStone, 0);
        this.setBlock(world, i + 11, j + 5, k + 9, Dungeons.amethystStone, 0);
        this.setBlock(world, i + 11, j + 5, k + 10, Dungeons.amethystStone, 0);
        this.setBlock(world, i + 11, j + 5, k + 11, Dungeons.amethystStone, 0);
        this.setBlock(world, i + 11, j + 5, k + 12, Dungeons.amethystStone, 0);
        this.setBlock(world, i + 11, j + 5, k + 13, Dungeons.amethystStone, 0);
        this.setBlock(world, i + 11, j + 5, k + 21, Dungeons.amethystStone, 0);
        this.setBlock(world, i + 11, j + 5, k + 22, Dungeons.amethystStone, 0);
        this.setBlock(world, i + 11, j + 5, k + 23, Dungeons.amethystStone, 0);
        this.setBlock(world, i + 11, j + 5, k + 24, Dungeons.amethystStone, 0);
        this.setBlock(world, i + 11, j + 6, k + 9, Dungeons.amethystStone, 0);
        this.setBlock(world, i + 11, j + 6, k + 10, Dungeons.amethystStone, 0);
        this.setBlock(world, i + 11, j + 6, k + 11, Dungeons.amethystStone, 0);
        this.setBlock(world, i + 11, j + 6, k + 22, Dungeons.amethystStone, 0);
        this.setBlock(world, i + 11, j + 6, k + 23, Dungeons.amethystStone, 0);
        this.setBlock(world, i + 11, j + 6, k + 24, Dungeons.amethystStone, 0);
        this.setBlock(world, i + 11, j + 6, k + 25, Dungeons.amethystStone, 0);
        this.setBlock(world, i + 11, j + 7, k + 8, Dungeons.amethystStone, 0);
        this.setBlock(world, i + 11, j + 7, k + 9, Dungeons.amethystStone, 0);
        this.setBlock(world, i + 11, j + 7, k + 10, Dungeons.amethystStone, 0);
        this.setBlock(world, i + 11, j + 7, k + 24, Dungeons.amethystStone, 0);
        this.setBlock(world, i + 11, j + 7, k + 25, Dungeons.amethystStone, 0);
        this.setBlock(world, i + 11, j + 7, k + 26, Dungeons.amethystStone, 0);
        this.setBlock(world, i + 11, j + 8, k + 7, Dungeons.amethystStone, 0);
        this.setBlock(world, i + 11, j + 8, k + 8, Dungeons.amethystStone, 0);
        this.setBlock(world, i + 11, j + 8, k + 9, Dungeons.amethystStone, 0);
        this.setBlock(world, i + 11, j + 8, k + 25, Dungeons.amethystStone, 0);
        this.setBlock(world, i + 11, j + 8, k + 26, Dungeons.amethystStone, 0);
        this.setBlock(world, i + 11, j + 8, k + 27, Dungeons.amethystStone, 0);
        this.setBlock(world, i + 11, j + 9, k + 7, Dungeons.amethystStone, 0);
        this.setBlock(world, i + 11, j + 9, k + 8, Dungeons.amethystStone, 0);
        this.setBlock(world, i + 11, j + 9, k + 9, Dungeons.amethystStone, 0);
        this.setBlock(world, i + 11, j + 9, k + 26, Dungeons.amethystStone, 0);
        this.setBlock(world, i + 11, j + 9, k + 27, Dungeons.amethystStone, 0);
        this.setBlock(world, i + 11, j + 10, k + 6, Dungeons.amethystStone, 0);
        this.setBlock(world, i + 11, j + 10, k + 7, Dungeons.amethystStone, 0);
        this.setBlock(world, i + 11, j + 10, k + 8, Dungeons.amethystStone, 0);
        this.setBlock(world, i + 11, j + 10, k + 26, Dungeons.amethystStone, 0);
        this.setBlock(world, i + 11, j + 10, k + 27, Dungeons.amethystStone, 0);
        this.setBlock(world, i + 11, j + 11, k + 5, Dungeons.amethystStone, 0);
        this.setBlock(world, i + 11, j + 11, k + 6, Dungeons.amethystStone, 0);
        this.setBlock(world, i + 11, j + 11, k + 7, Dungeons.amethystStone, 0);
        this.setBlock(world, i + 11, j + 11, k + 8, Dungeons.amethystStone, 0);
        this.setBlock(world, i + 11, j + 11, k + 26, Dungeons.amethystStone, 0);
        this.setBlock(world, i + 11, j + 11, k + 27, Dungeons.amethystStone, 0);
        this.setBlock(world, i + 11, j + 12, k + 4, Dungeons.amethystStone, 0);
        this.setBlock(world, i + 11, j + 12, k + 5, Dungeons.amethystStone, 0);
        this.setBlock(world, i + 11, j + 12, k + 6, Dungeons.amethystStone, 0);
        this.setBlock(world, i + 11, j + 12, k + 7, Dungeons.amethystStone, 0);
        this.setBlock(world, i + 11, j + 12, k + 26, Dungeons.amethystStone, 0);
        this.setBlock(world, i + 11, j + 12, k + 27, Dungeons.amethystStone, 0);
        this.setBlock(world, i + 11, j + 13, k + 4, Dungeons.amethystStone, 0);
        this.setBlock(world, i + 11, j + 13, k + 5, Dungeons.amethystStone, 0);
        this.setBlock(world, i + 11, j + 13, k + 6, Dungeons.amethystStone, 0);
        this.setBlock(world, i + 11, j + 13, k + 7, Dungeons.amethystStone, 0);
        this.setBlock(world, i + 11, j + 13, k + 26, Dungeons.amethystStone, 0);
        this.setBlock(world, i + 11, j + 14, k + 5, Dungeons.amethystStone, 0);
        this.setBlock(world, i + 11, j + 14, k + 6, Dungeons.amethystStone, 0);
        this.setBlock(world, i + 11, j + 14, k + 7, Dungeons.amethystStone, 0);
        this.setBlock(world, i + 11, j + 14, k + 25, Dungeons.amethystStone, 0);
        this.setBlock(world, i + 11, j + 14, k + 26, Dungeons.amethystStone, 0);
        this.setBlock(world, i + 11, j + 15, k + 5, Dungeons.amethystStone, 0);
        this.setBlock(world, i + 11, j + 15, k + 6, Dungeons.amethystStone, 0);
        this.setBlock(world, i + 11, j + 15, k + 7, Dungeons.amethystStone, 0);
        this.setBlock(world, i + 11, j + 15, k + 8, Dungeons.amethystStone, 0);
        this.setBlock(world, i + 11, j + 15, k + 25, Dungeons.amethystStone, 0);
        this.setBlock(world, i + 11, j + 15, k + 26, Dungeons.amethystStone, 0);
        this.setBlock(world, i + 11, j + 16, k + 6, Dungeons.amethystStone, 0);
        this.setBlock(world, i + 11, j + 16, k + 7, Dungeons.amethystStone, 0);
        this.setBlock(world, i + 11, j + 16, k + 8, Dungeons.amethystStone, 0);
        this.setBlock(world, i + 11, j + 16, k + 9, Dungeons.amethystStone, 0);
        this.setBlock(world, i + 11, j + 16, k + 24, Dungeons.amethystStone, 0);
        this.setBlock(world, i + 11, j + 16, k + 25, Dungeons.amethystStone, 0);
        this.setBlock(world, i + 11, j + 16, k + 26, Dungeons.amethystStone, 0);
        this.setBlock(world, i + 11, j + 17, k + 7, Dungeons.amethystStone, 0);
        this.setBlock(world, i + 11, j + 17, k + 8, Dungeons.amethystStone, 0);
        this.setBlock(world, i + 11, j + 17, k + 9, Dungeons.amethystStone, 0);
        this.setBlock(world, i + 11, j + 17, k + 10, Dungeons.amethystStone, 0);
        this.setBlock(world, i + 11, j + 17, k + 11, Dungeons.amethystStone, 0);
        this.setBlock(world, i + 11, j + 17, k + 24, Dungeons.amethystStone, 0);
        this.setBlock(world, i + 11, j + 17, k + 25, Dungeons.amethystStone, 0);
        this.setBlock(world, i + 11, j + 17, k + 26, Dungeons.amethystStone, 0);
        this.setBlock(world, i + 11, j + 17, k + 27, Dungeons.amethystStone, 0);
        this.setBlock(world, i + 11, j + 18, k + 9, Dungeons.amethystStone, 0);
        this.setBlock(world, i + 11, j + 18, k + 10, Dungeons.amethystStone, 0);
        this.setBlock(world, i + 11, j + 18, k + 11, Dungeons.amethystStone, 0);
        this.setBlock(world, i + 11, j + 18, k + 12, Dungeons.amethystStone, 0);
        this.setBlock(world, i + 11, j + 18, k + 24, Dungeons.amethystStone, 0);
        this.setBlock(world, i + 11, j + 18, k + 25, Dungeons.amethystStone, 0);
        this.setBlock(world, i + 11, j + 18, k + 26, Dungeons.amethystStone, 0);
        this.setBlock(world, i + 11, j + 19, k + 9, Dungeons.amethystStone, 0);
        this.setBlock(world, i + 11, j + 19, k + 10, Dungeons.amethystStone, 0);
        this.setBlock(world, i + 11, j + 19, k + 11, Dungeons.amethystStone, 0);
        this.setBlock(world, i + 11, j + 19, k + 12, Dungeons.amethystStone, 0);
        this.setBlock(world, i + 11, j + 19, k + 23, Dungeons.amethystStone, 0);
        this.setBlock(world, i + 11, j + 19, k + 24, Dungeons.amethystStone, 0);
        this.setBlock(world, i + 11, j + 19, k + 25, Dungeons.amethystStone, 0);
        this.setBlock(world, i + 11, j + 20, k + 10, Dungeons.amethystStone, 0);
        this.setBlock(world, i + 11, j + 20, k + 11, Dungeons.amethystStone, 0);
        this.setBlock(world, i + 11, j + 20, k + 12, Dungeons.amethystStone, 0);
        this.setBlock(world, i + 11, j + 20, k + 21, Dungeons.amethystStone, 0);
        this.setBlock(world, i + 11, j + 20, k + 22, Dungeons.amethystStone, 0);
        this.setBlock(world, i + 11, j + 20, k + 23, Dungeons.amethystStone, 0);
        this.setBlock(world, i + 11, j + 20, k + 24, Dungeons.amethystStone, 0);
        this.setBlock(world, i + 11, j + 20, k + 25, Dungeons.amethystStone, 0);
        this.setBlock(world, i + 11, j + 21, k + 11, Dungeons.amethystStone, 0);
        this.setBlock(world, i + 11, j + 21, k + 12, Dungeons.amethystStone, 0);
        this.setBlock(world, i + 11, j + 21, k + 13, Dungeons.amethystStone, 0);
        this.setBlock(world, i + 11, j + 21, k + 14, Dungeons.amethystStone, 0);
        this.setBlock(world, i + 11, j + 21, k + 15, Dungeons.amethystStone, 0);
        this.setBlock(world, i + 11, j + 21, k + 18, Dungeons.amethystStone, 0);
        this.setBlock(world, i + 11, j + 21, k + 19, Dungeons.amethystStone, 0);
        this.setBlock(world, i + 11, j + 21, k + 20, Dungeons.amethystStone, 0);
        this.setBlock(world, i + 11, j + 21, k + 21, Dungeons.amethystStone, 0);
        this.setBlock(world, i + 11, j + 21, k + 22, Dungeons.amethystStone, 0);
        this.setBlock(world, i + 11, j + 21, k + 23, Dungeons.amethystStone, 0);
        this.setBlock(world, i + 11, j + 21, k + 24, Dungeons.amethystStone, 0);
        this.setBlock(world, i + 11, j + 22, k + 12, Dungeons.amethystStone, 0);
        this.setBlock(world, i + 11, j + 22, k + 13, Dungeons.amethystStone, 0);
        this.setBlock(world, i + 11, j + 22, k + 14, Dungeons.amethystStone, 0);
        this.setBlock(world, i + 11, j + 22, k + 15, Dungeons.amethystStone, 0);
        this.setBlock(world, i + 11, j + 22, k + 16, Dungeons.amethystStone, 0);
        this.setBlock(world, i + 11, j + 22, k + 17, Dungeons.amethystStone, 0);
        this.setBlock(world, i + 11, j + 22, k + 18, Dungeons.amethystStone, 0);
        this.setBlock(world, i + 11, j + 22, k + 19, Dungeons.amethystStone, 0);
        this.setBlock(world, i + 11, j + 22, k + 20, Dungeons.amethystStone, 0);
        this.setBlock(world, i + 11, j + 22, k + 21, Dungeons.amethystStone, 0);
        this.setBlock(world, i + 11, j + 23, k + 12, Dungeons.amethystStone, 0);
        this.setBlock(world, i + 11, j + 23, k + 13, Dungeons.amethystStone, 0);
        this.setBlock(world, i + 11, j + 23, k + 14, Dungeons.amethystStone, 0);
        this.setBlock(world, i + 11, j + 23, k + 15, Dungeons.amethystStone, 0);
        this.setBlock(world, i + 11, j + 23, k + 16, Dungeons.amethystStone, 0);
        this.setBlock(world, i + 11, j + 23, k + 17, Dungeons.amethystStone, 0);
        this.setBlock(world, i + 12, j + 3, k + 9, Dungeons.amethystStone, 0);
        this.setBlock(world, i + 12, j + 3, k + 13, Dungeons.amethystStone, 0);
        this.setBlock(world, i + 12, j + 3, k + 14, Dungeons.amethystStone, 0);
        this.setBlock(world, i + 12, j + 3, k + 15, Dungeons.amethystStone, 0);
        this.setBlock(world, i + 12, j + 3, k + 16, Dungeons.amethystStone, 0);
        this.setBlock(world, i + 12, j + 3, k + 17, Dungeons.amethystStone, 0);
        this.setBlock(world, i + 12, j + 3, k + 18, Dungeons.amethystStone, 0);
        this.setBlock(world, i + 12, j + 4, k + 9, Dungeons.amethystStone, 0);
        this.setBlock(world, i + 12, j + 4, k + 11, Dungeons.amethystStone, 0);
        this.setBlock(world, i + 12, j + 4, k + 12, Dungeons.amethystStone, 0);
        this.setBlock(world, i + 12, j + 4, k + 13, Dungeons.amethystStone, 0);
        this.setBlock(world, i + 12, j + 4, k + 14, Dungeons.amethystStone, 0);
        this.setBlock(world, i + 12, j + 4, k + 15, Dungeons.amethystStone, 0);
        this.setBlock(world, i + 12, j + 4, k + 16, Dungeons.amethystStone, 0);
        this.setBlock(world, i + 12, j + 4, k + 17, Dungeons.amethystStone, 0);
        this.setBlock(world, i + 12, j + 4, k + 18, Dungeons.amethystStone, 0);
        this.setBlock(world, i + 12, j + 4, k + 19, Dungeons.amethystStone, 0);
        this.setBlock(world, i + 12, j + 4, k + 20, Dungeons.amethystStone, 0);
        this.setBlock(world, i + 12, j + 4, k + 21, Dungeons.amethystStone, 0);
        this.setBlock(world, i + 12, j + 4, k + 22, Dungeons.amethystStone, 0);
        this.setBlock(world, i + 12, j + 4, k + 23, Dungeons.amethystStone, 0);
        this.setBlock(world, i + 12, j + 5, k + 9, Dungeons.amethystStone, 0);
        this.setBlock(world, i + 12, j + 5, k + 10, Dungeons.amethystStone, 0);
        this.setBlock(world, i + 12, j + 5, k + 11, Dungeons.amethystStone, 0);
        this.setBlock(world, i + 12, j + 5, k + 12, Dungeons.amethystStone, 0);
        this.setBlock(world, i + 12, j + 5, k + 15, Dungeons.purpleBrick, 0);
        this.setBlock(world, i + 12, j + 5, k + 18, Dungeons.purpleBrick, 0);
        this.setBlock(world, i + 12, j + 5, k + 21, Dungeons.amethystStone, 0);
        this.setBlock(world, i + 12, j + 5, k + 22, Dungeons.amethystStone, 0);
        this.setBlock(world, i + 12, j + 5, k + 23, Dungeons.amethystStone, 0);
        this.setBlock(world, i + 12, j + 5, k + 24, Dungeons.amethystStone, 0);
        this.setBlock(world, i + 12, j + 5, k + 25, Dungeons.amethystStone, 0);
        this.setBlock(world, i + 12, j + 6, k + 9, Dungeons.amethystStone, 0);
        this.setBlock(world, i + 12, j + 6, k + 10, Dungeons.amethystStone, 0);
        this.setBlock(world, i + 12, j + 6, k + 11, Dungeons.amethystStone, 0);
        this.setBlock(world, i + 12, j + 6, k + 23, Dungeons.amethystStone, 0);
        this.setBlock(world, i + 12, j + 6, k + 24, Dungeons.amethystStone, 0);
        this.setBlock(world, i + 12, j + 6, k + 25, Dungeons.amethystStone, 0);
        this.setBlock(world, i + 12, j + 7, k + 8, Dungeons.amethystStone, 0);
        this.setBlock(world, i + 12, j + 7, k + 9, Dungeons.amethystStone, 0);
        this.setBlock(world, i + 12, j + 7, k + 10, Dungeons.amethystStone, 0);
        this.setBlock(world, i + 12, j + 7, k + 25, Dungeons.amethystStone, 0);
        this.setBlock(world, i + 12, j + 7, k + 26, Dungeons.amethystStone, 0);
        this.setBlock(world, i + 12, j + 8, k + 7, Dungeons.amethystStone, 0);
        this.setBlock(world, i + 12, j + 8, k + 8, Dungeons.amethystStone, 0);
        this.setBlock(world, i + 12, j + 8, k + 9, Dungeons.amethystStone, 0);
        this.setBlock(world, i + 12, j + 8, k + 26, Dungeons.amethystStone, 0);
        this.setBlock(world, i + 12, j + 8, k + 27, Dungeons.amethystStone, 0);
        this.setBlock(world, i + 12, j + 9, k + 7, Dungeons.amethystStone, 0);
        this.setBlock(world, i + 12, j + 9, k + 8, Dungeons.amethystStone, 0);
        this.setBlock(world, i + 12, j + 9, k + 9, Dungeons.amethystStone, 0);
        this.setBlock(world, i + 12, j + 9, k + 26, Dungeons.amethystStone, 0);
        this.setBlock(world, i + 12, j + 9, k + 27, Dungeons.amethystStone, 0);
        this.setBlock(world, i + 12, j + 10, k + 6, Dungeons.amethystStone, 0);
        this.setBlock(world, i + 12, j + 10, k + 7, Dungeons.amethystStone, 0);
        this.setBlock(world, i + 12, j + 10, k + 26, Dungeons.amethystStone, 0);
        this.setBlock(world, i + 12, j + 10, k + 27, Dungeons.amethystStone, 0);
        this.setBlock(world, i + 12, j + 11, k + 5, Dungeons.amethystStone, 0);
        this.setBlock(world, i + 12, j + 11, k + 6, Dungeons.amethystStone, 0);
        this.setBlock(world, i + 12, j + 11, k + 7, Dungeons.amethystStone, 0);
        this.setBlock(world, i + 12, j + 11, k + 26, Dungeons.amethystStone, 0);
        this.setBlock(world, i + 12, j + 11, k + 27, Dungeons.amethystStone, 0);
        this.setBlock(world, i + 12, j + 12, k + 4, Dungeons.amethystStone, 0);
        this.setBlock(world, i + 12, j + 12, k + 5, Dungeons.amethystStone, 0);
        this.setBlock(world, i + 12, j + 12, k + 6, Dungeons.amethystStone, 0);
        this.setBlock(world, i + 12, j + 12, k + 7, Dungeons.amethystStone, 0);
        this.setBlock(world, i + 12, j + 12, k + 26, Dungeons.amethystStone, 0);
        this.setBlock(world, i + 12, j + 13, k + 4, Dungeons.amethystStone, 0);
        this.setBlock(world, i + 12, j + 13, k + 5, Dungeons.amethystStone, 0);
        this.setBlock(world, i + 12, j + 13, k + 6, Dungeons.amethystStone, 0);
        this.setBlock(world, i + 12, j + 13, k + 7, Dungeons.amethystStone, 0);
        this.setBlock(world, i + 12, j + 13, k + 26, Dungeons.amethystStone, 0);
        this.setBlock(world, i + 12, j + 14, k + 4, Dungeons.amethystStone, 0);
        this.setBlock(world, i + 12, j + 14, k + 5, Dungeons.amethystStone, 0);
        this.setBlock(world, i + 12, j + 14, k + 6, Dungeons.amethystStone, 0);
        this.setBlock(world, i + 12, j + 14, k + 7, Dungeons.amethystStone, 0);
        this.setBlock(world, i + 12, j + 14, k + 26, Dungeons.amethystStone, 0);
        this.setBlock(world, i + 12, j + 15, k + 4, Dungeons.amethystStone, 0);
        this.setBlock(world, i + 12, j + 15, k + 5, Dungeons.amethystStone, 0);
        this.setBlock(world, i + 12, j + 15, k + 6, Dungeons.amethystStone, 0);
        this.setBlock(world, i + 12, j + 15, k + 7, Dungeons.amethystStone, 0);
        this.setBlock(world, i + 12, j + 15, k + 8, Dungeons.amethystStone, 0);
        this.setBlock(world, i + 12, j + 15, k + 25, Dungeons.amethystStone, 0);
        this.setBlock(world, i + 12, j + 15, k + 26, Dungeons.amethystStone, 0);
        this.setBlock(world, i + 12, j + 16, k + 5, Dungeons.amethystStone, 0);
        this.setBlock(world, i + 12, j + 16, k + 6, Dungeons.amethystStone, 0);
        this.setBlock(world, i + 12, j + 16, k + 7, Dungeons.amethystStone, 0);
        this.setBlock(world, i + 12, j + 16, k + 8, Dungeons.amethystStone, 0);
        this.setBlock(world, i + 12, j + 16, k + 9, Dungeons.amethystStone, 0);
        this.setBlock(world, i + 12, j + 16, k + 24, Dungeons.amethystStone, 0);
        this.setBlock(world, i + 12, j + 16, k + 25, Dungeons.amethystStone, 0);
        this.setBlock(world, i + 12, j + 16, k + 26, Dungeons.amethystStone, 0);
        this.setBlock(world, i + 12, j + 17, k + 7, Dungeons.amethystStone, 0);
        this.setBlock(world, i + 12, j + 17, k + 8, Dungeons.amethystStone, 0);
        this.setBlock(world, i + 12, j + 17, k + 9, Dungeons.amethystStone, 0);
        this.setBlock(world, i + 12, j + 17, k + 10, Dungeons.amethystStone, 0);
        this.setBlock(world, i + 12, j + 17, k + 11, Dungeons.amethystStone, 0);
        this.setBlock(world, i + 12, j + 17, k + 24, Dungeons.amethystStone, 0);
        this.setBlock(world, i + 12, j + 17, k + 25, Dungeons.amethystStone, 0);
        this.setBlock(world, i + 12, j + 17, k + 26, Dungeons.amethystStone, 0);
        this.setBlock(world, i + 12, j + 17, k + 27, Dungeons.amethystStone, 0);
        this.setBlock(world, i + 12, j + 18, k + 9, Dungeons.amethystStone, 0);
        this.setBlock(world, i + 12, j + 18, k + 10, Dungeons.amethystStone, 0);
        this.setBlock(world, i + 12, j + 18, k + 11, Dungeons.amethystStone, 0);
        this.setBlock(world, i + 12, j + 18, k + 24, Dungeons.amethystStone, 0);
        this.setBlock(world, i + 12, j + 18, k + 25, Dungeons.amethystStone, 0);
        this.setBlock(world, i + 12, j + 18, k + 26, Dungeons.amethystStone, 0);
        this.setBlock(world, i + 12, j + 18, k + 27, Dungeons.amethystStone, 0);
        this.setBlock(world, i + 12, j + 19, k + 9, Dungeons.amethystStone, 0);
        this.setBlock(world, i + 12, j + 19, k + 10, Dungeons.amethystStone, 0);
        this.setBlock(world, i + 12, j + 19, k + 11, Dungeons.amethystStone, 0);
        this.setBlock(world, i + 12, j + 19, k + 12, Dungeons.amethystStone, 0);
        this.setBlock(world, i + 12, j + 19, k + 24, Dungeons.amethystStone, 0);
        this.setBlock(world, i + 12, j + 19, k + 25, Dungeons.amethystStone, 0);
        this.setBlock(world, i + 12, j + 19, k + 26, Dungeons.amethystStone, 0);
        this.setBlock(world, i + 12, j + 20, k + 9, Dungeons.amethystStone, 0);
        this.setBlock(world, i + 12, j + 20, k + 10, Dungeons.amethystStone, 0);
        this.setBlock(world, i + 12, j + 20, k + 11, Dungeons.amethystStone, 0);
        this.setBlock(world, i + 12, j + 20, k + 12, Dungeons.amethystStone, 0);
        this.setBlock(world, i + 12, j + 20, k + 13, Dungeons.amethystStone, 0);
        this.setBlock(world, i + 12, j + 20, k + 23, Dungeons.amethystStone, 0);
        this.setBlock(world, i + 12, j + 20, k + 24, Dungeons.amethystStone, 0);
        this.setBlock(world, i + 12, j + 20, k + 25, Dungeons.amethystStone, 0);
        this.setBlock(world, i + 12, j + 20, k + 26, Dungeons.amethystStone, 0);
        this.setBlock(world, i + 12, j + 21, k + 11, Dungeons.amethystStone, 0);
        this.setBlock(world, i + 12, j + 21, k + 12, Dungeons.amethystStone, 0);
        this.setBlock(world, i + 12, j + 21, k + 13, Dungeons.amethystStone, 0);
        this.setBlock(world, i + 12, j + 21, k + 14, Dungeons.amethystStone, 0);
        this.setBlock(world, i + 12, j + 21, k + 19, Dungeons.amethystStone, 0);
        this.setBlock(world, i + 12, j + 21, k + 20, Dungeons.amethystStone, 0);
        this.setBlock(world, i + 12, j + 21, k + 21, Dungeons.amethystStone, 0);
        this.setBlock(world, i + 12, j + 21, k + 22, Dungeons.amethystStone, 0);
        this.setBlock(world, i + 12, j + 21, k + 23, Dungeons.amethystStone, 0);
        this.setBlock(world, i + 12, j + 21, k + 24, Dungeons.amethystStone, 0);
        this.setBlock(world, i + 12, j + 21, k + 25, Dungeons.amethystStone, 0);
        this.setBlock(world, i + 12, j + 22, k + 12, Dungeons.amethystStone, 0);
        this.setBlock(world, i + 12, j + 22, k + 13, Dungeons.amethystStone, 0);
        this.setBlock(world, i + 12, j + 22, k + 14, Dungeons.amethystStone, 0);
        this.setBlock(world, i + 12, j + 22, k + 15, Dungeons.amethystStone, 0);
        this.setBlock(world, i + 12, j + 22, k + 16, Dungeons.amethystStone, 0);
        this.setBlock(world, i + 12, j + 22, k + 17, Dungeons.amethystStone, 0);
        this.setBlock(world, i + 12, j + 22, k + 18, Dungeons.amethystStone, 0);
        this.setBlock(world, i + 12, j + 22, k + 19, Dungeons.amethystStone, 0);
        this.setBlock(world, i + 12, j + 22, k + 20, Dungeons.amethystStone, 0);
        this.setBlock(world, i + 12, j + 22, k + 21, Dungeons.amethystStone, 0);
        this.setBlock(world, i + 12, j + 22, k + 22, Dungeons.amethystStone, 0);
        this.setBlock(world, i + 12, j + 22, k + 23, Dungeons.amethystStone, 0);
        this.setBlock(world, i + 12, j + 23, k + 12, Dungeons.amethystStone, 0);
        this.setBlock(world, i + 12, j + 23, k + 13, Dungeons.amethystStone, 0);
        this.setBlock(world, i + 12, j + 23, k + 14, Dungeons.amethystStone, 0);
        this.setBlock(world, i + 12, j + 23, k + 15, Dungeons.amethystStone, 0);
        this.setBlock(world, i + 12, j + 23, k + 16, Dungeons.amethystStone, 0);
        this.setBlock(world, i + 12, j + 23, k + 17, Dungeons.amethystStone, 0);
        this.setBlock(world, i + 12, j + 23, k + 18, Dungeons.amethystStone, 0);
        this.setBlock(world, i + 12, j + 23, k + 19, Dungeons.amethystStone, 0);
        this.setBlock(world, i + 12, j + 23, k + 20, Dungeons.amethystStone, 0);
        this.setBlock(world, i + 12, j + 23, k + 21, Dungeons.amethystStone, 0);
        this.setBlock(world, i + 12, j + 24, k + 16, Dungeons.amethystStone, 0);
        this.setBlock(world, i + 12, j + 25, k + 16, Dungeons.amethystStone, 0);
        this.setBlock(world, i + 13, j + 2, k + 23, Dungeons.amethystStone, 0);
        this.setBlock(world, i + 13, j + 3, k + 13, Dungeons.amethystStone, 0);
        this.setBlock(world, i + 13, j + 3, k + 14, Dungeons.amethystStone, 0);
        this.setBlock(world, i + 13, j + 3, k + 15, Dungeons.amethystStone, 0);
        this.setBlock(world, i + 13, j + 3, k + 16, Dungeons.amethystStone, 0);
        this.setBlock(world, i + 13, j + 3, k + 17, Dungeons.amethystStone, 0);
        this.setBlock(world, i + 13, j + 3, k + 18, Dungeons.amethystStone, 0);
        this.setBlock(world, i + 13, j + 3, k + 19, Dungeons.amethystStone, 0);
        this.setBlock(world, i + 13, j + 3, k + 23, Dungeons.amethystStone, 0);
        this.setBlock(world, i + 13, j + 4, k + 11, Dungeons.amethystStone, 0);
        this.setBlock(world, i + 13, j + 4, k + 12, Dungeons.amethystStone, 0);
        this.setBlock(world, i + 13, j + 4, k + 13, Dungeons.amethystStone, 0);
        this.setBlock(world, i + 13, j + 4, k + 14, Dungeons.amethystStone, 0);
        this.setBlock(world, i + 13, j + 4, k + 15, Dungeons.amethystStone, 0);
        this.setBlock(world, i + 13, j + 4, k + 16, Dungeons.amethystStone, 0);
        this.setBlock(world, i + 13, j + 4, k + 17, Dungeons.amethystStone, 0);
        this.setBlock(world, i + 13, j + 4, k + 18, Dungeons.amethystStone, 0);
        this.setBlock(world, i + 13, j + 4, k + 19, Dungeons.amethystStone, 0);
        this.setBlock(world, i + 13, j + 4, k + 20, Dungeons.amethystStone, 0);
        this.setBlock(world, i + 13, j + 4, k + 21, Dungeons.amethystStone, 0);
        this.setBlock(world, i + 13, j + 4, k + 22, Dungeons.amethystStone, 0);
        this.setBlock(world, i + 13, j + 4, k + 23, Dungeons.amethystStone, 0);
        this.setBlock(world, i + 13, j + 5, k + 10, Dungeons.amethystStone, 0);
        this.setBlock(world, i + 13, j + 5, k + 11, Dungeons.amethystStone, 0);
        this.setBlock(world, i + 13, j + 5, k + 12, Dungeons.amethystStone, 0);
        this.setBlock(world, i + 13, j + 5, k + 14, Dungeons.purpleBrick, 0);
        this.setBlock(world, i + 13, j + 5, k + 15, Dungeons.purpleBrick, 0);
        this.setBlock(world, i + 13, j + 5, k + 16, Dungeons.purpleBrick, 0);
        this.setBlock(world, i + 13, j + 5, k + 17, Dungeons.purpleBrick, 0);
        this.setBlock(world, i + 13, j + 5, k + 18, Dungeons.purpleBrick, 0);
        this.setBlock(world, i + 13, j + 5, k + 19, Dungeons.purpleBrick, 0);
        this.setBlock(world, i + 13, j + 5, k + 21, Dungeons.amethystStone, 0);
