package com.gibby.dungeon.gen;

import com.gibby.dungeon.Dungeons;
import cpw.mods.fml.common.IWorldGenerator;
import net.minecraft.block.Block;
import net.minecraft.init.Blocks;
import net.minecraft.world.IBlockAccess;
import net.minecraft.world.World;
import net.minecraft.world.chunk.IChunkProvider;
import net.minecraft.world.gen.feature.WorldGenerator;

import java.util.Random;

public class WorldGenMidnightVillage extends WorldGenerator implements IWorldGenerator
{
    public void generate(final Random random, final int chunkX, final int chunkZ, final World world, final IChunkProvider chunkGenerator, final IChunkProvider chunkProvider) {
    }

    public void setBlock(final World world, final int x, final int y, final int z, final Block block, final int metadata) {
        final Block b1 = world.getBlock(x, y, z);
        if (b1.isAir(world, x, y, z) || b1.isLeaves(world, x, y, z)) {
            world.setBlock(x, y, z, block, metadata, 2);
        }
    }

    public boolean generate(final World world, final Random rand, final int i, final int j, final int k) {
        if (world.getBlock(i, j - 1, k) != Dungeons.midnightGrass || world.getBlock(i + 20, j - 1, k + 20) != Dungeons.midnightGrass || world.getBlock(i + 40, j - 1, k + 40) != Dungeons.midnightGrass || world.getBlock(i + 0, j - 1, k + 20) != Dungeons.midnightGrass || world.getBlock(i + 20, j - 1, k + 0) != Dungeons.midnightGrass) {
            return false;
        }
        this.setBlock(world, i + 1, j + 34, k + 14, Dungeons.midnightFence, 0);
        this.setBlock(world, i + 1, j + 34, k + 16, Dungeons.midnightFence, 0);
        this.setBlock(world, i + 1, j + 34, k + 18, Dungeons.midnightFence, 0);
        this.setBlock(world, i + 1, j + 34, k + 20, Dungeons.midnightFence, 0);
        this.setBlock(world, i + 1, j + 34, k + 23, Dungeons.midnightFence, 0);
        this.setBlock(world, i + 1, j + 34, k + 25, Dungeons.midnightFence, 0);
        this.setBlock(world, i + 1, j + 34, k + 27, Dungeons.midnightFence, 0);
        this.setBlock(world, i + 1, j + 34, k + 29, Dungeons.midnightFence, 0);
        this.setBlock(world, i + 1, j + 34, k + 32, Dungeons.midnightFence, 0);
        this.setBlock(world, i + 1, j + 34, k + 34, Dungeons.midnightFence, 0);
        this.setBlock(world, i + 1, j + 34, k + 36, Dungeons.midnightFence, 0);
        this.setBlock(world, i + 1, j + 34, k + 38, Dungeons.midnightFence, 0);
        this.setBlock(world, i + 1, j + 35, k + 3, Dungeons.midnightFence, 0);
        this.setBlock(world, i + 1, j + 35, k + 5, Dungeons.midnightFence, 0);
        this.setBlock(world, i + 1, j + 35, k + 7, Dungeons.midnightFence, 0);
        this.setBlock(world, i + 1, j + 35, k + 9, Dungeons.midnightFence, 0);
        this.setBlock(world, i + 1, j + 35, k + 11, Dungeons.midnightFence, 0);
        this.setBlock(world, i + 1, j + 35, k + 14, Dungeons.blueGlow, 0);
        this.setBlock(world, i + 1, j + 35, k + 16, Dungeons.blueGlow, 0);
        this.setBlock(world, i + 1, j + 35, k + 18, Dungeons.blueGlow, 0);
        this.setBlock(world, i + 1, j + 35, k + 20, Dungeons.blueGlow, 0);
        this.setBlock(world, i + 1, j + 35, k + 23, Dungeons.blueGlow, 0);
        this.setBlock(world, i + 1, j + 35, k + 25, Dungeons.blueGlow, 0);
        this.setBlock(world, i + 1, j + 35, k + 27, Dungeons.blueGlow, 0);
        this.setBlock(world, i + 1, j + 35, k + 29, Dungeons.blueGlow, 0);
        this.setBlock(world, i + 1, j + 35, k + 32, Dungeons.blueGlow, 0);
        this.setBlock(world, i + 1, j + 35, k + 34, Dungeons.blueGlow, 0);
        this.setBlock(world, i + 1, j + 35, k + 36, Dungeons.blueGlow, 0);
        this.setBlock(world, i + 1, j + 35, k + 38, Dungeons.blueGlow, 0);
        this.setBlock(world, i + 1, j + 35, k + 41, Dungeons.midnightFence, 0);
        this.setBlock(world, i + 1, j + 35, k + 43, Dungeons.midnightFence, 0);
        this.setBlock(world, i + 1, j + 35, k + 45, Dungeons.midnightFence, 0);
        this.setBlock(world, i + 1, j + 35, k + 47, Dungeons.midnightFence, 0);
        this.setBlock(world, i + 1, j + 35, k + 49, Dungeons.midnightFence, 0);
        this.setBlock(world, i + 1, j + 36, k + 3, Dungeons.blueGlow, 0);
        this.setBlock(world, i + 1, j + 36, k + 5, Dungeons.blueGlow, 0);
        this.setBlock(world, i + 1, j + 36, k + 7, Dungeons.blueGlow, 0);
        this.setBlock(world, i + 1, j + 36, k + 9, Dungeons.blueGlow, 0);
        this.setBlock(world, i + 1, j + 36, k + 11, Dungeons.blueGlow, 0);
        this.setBlock(world, i + 1, j + 36, k + 14, Dungeons.lightBlueGlow, 0);
        this.setBlock(world, i + 1, j + 36, k + 16, Dungeons.lightBlueGlow, 0);
        this.setBlock(world, i + 1, j + 36, k + 18, Dungeons.lightBlueGlow, 0);
        this.setBlock(world, i + 1, j + 36, k + 20, Dungeons.lightBlueGlow, 0);
        this.setBlock(world, i + 1, j + 36, k + 23, Dungeons.lightBlueGlow, 0);
        this.setBlock(world, i + 1, j + 36, k + 25, Dungeons.lightBlueGlow, 0);
        this.setBlock(world, i + 1, j + 36, k + 27, Dungeons.lightBlueGlow, 0);
        this.setBlock(world, i + 1, j + 36, k + 29, Dungeons.lightBlueGlow, 0);
        this.setBlock(world, i + 1, j + 36, k + 32, Dungeons.lightBlueGlow, 0);
        this.setBlock(world, i + 1, j + 36, k + 34, Dungeons.lightBlueGlow, 0);
        this.setBlock(world, i + 1, j + 36, k + 36, Dungeons.lightBlueGlow, 0);
        this.setBlock(world, i + 1, j + 36, k + 38, Dungeons.lightBlueGlow, 0);
        this.setBlock(world, i + 1, j + 36, k + 41, Dungeons.blueGlow, 0);
        this.setBlock(world, i + 1, j + 36, k + 43, Dungeons.blueGlow, 0);
        this.setBlock(world, i + 1, j + 36, k + 45, Dungeons.blueGlow, 0);
        this.setBlock(world, i + 1, j + 36, k + 47, Dungeons.blueGlow, 0);
        this.setBlock(world, i + 1, j + 36, k + 49, Dungeons.blueGlow, 0);
        this.setBlock(world, i + 1, j + 37, k + 3, Dungeons.lightBlueGlow, 0);
        this.setBlock(world, i + 1, j + 37, k + 5, Dungeons.lightBlueGlow, 0);
        this.setBlock(world, i + 1, j + 37, k + 7, Dungeons.lightBlueGlow, 0);
        this.setBlock(world, i + 1, j + 37, k + 9, Dungeons.lightBlueGlow, 0);
        this.setBlock(world, i + 1, j + 37, k + 11, Dungeons.lightBlueGlow, 0);
        this.setBlock(world, i + 1, j + 37, k + 41, Dungeons.lightBlueGlow, 0);
        this.setBlock(world, i + 1, j + 37, k + 43, Dungeons.lightBlueGlow, 0);
        this.setBlock(world, i + 1, j + 37, k + 45, Dungeons.lightBlueGlow, 0);
        this.setBlock(world, i + 1, j + 37, k + 47, Dungeons.lightBlueGlow, 0);
        this.setBlock(world, i + 1, j + 37, k + 49, Dungeons.lightBlueGlow, 0);
        this.setBlock(world, i + 2, j + 28, k + 3, Dungeons.blueBrick, 0);
        this.setBlock(world, i + 2, j + 28, k + 4, Dungeons.blueBrick, 0);
        this.setBlock(world, i + 2, j + 28, k + 5, Dungeons.blueBrick, 0);
        this.setBlock(world, i + 2, j + 28, k + 6, Dungeons.blueBrick, 0);
        this.setBlock(world, i + 2, j + 28, k + 7, Dungeons.blueBrick, 0);
        this.setBlock(world, i + 2, j + 28, k + 8, Dungeons.blueBrick, 0);
        this.setBlock(world, i + 2, j + 28, k + 9, Dungeons.blueBrick, 0);
        this.setBlock(world, i + 2, j + 28, k + 10, Dungeons.blueBrick, 0);
        this.setBlock(world, i + 2, j + 28, k + 11, Dungeons.blueBrick, 0);
        this.setBlock(world, i + 2, j + 28, k + 14, Dungeons.blueGlow, 0);
        this.setBlock(world, i + 2, j + 28, k + 15, Dungeons.blueGlow, 0);
        this.setBlock(world, i + 2, j + 28, k + 16, Dungeons.blueGlow, 0);
        this.setBlock(world, i + 2, j + 28, k + 17, Dungeons.blueGlow, 0);
        this.setBlock(world, i + 2, j + 28, k + 18, Dungeons.blueGlow, 0);
        this.setBlock(world, i + 2, j + 28, k + 19, Dungeons.blueGlow, 0);
        this.setBlock(world, i + 2, j + 28, k + 20, Dungeons.blueGlow, 0);
        this.setBlock(world, i + 2, j + 28, k + 23, Dungeons.blueGlow, 0);
        this.setBlock(world, i + 2, j + 28, k + 24, Dungeons.blueGlow, 0);
        this.setBlock(world, i + 2, j + 28, k + 25, Dungeons.blueGlow, 0);
        this.setBlock(world, i + 2, j + 28, k + 26, Dungeons.blueGlow, 0);
        this.setBlock(world, i + 2, j + 28, k + 27, Dungeons.blueGlow, 0);
        this.setBlock(world, i + 2, j + 28, k + 28, Dungeons.blueGlow, 0);
        this.setBlock(world, i + 2, j + 28, k + 29, Dungeons.blueGlow, 0);
        this.setBlock(world, i + 2, j + 28, k + 32, Dungeons.blueGlow, 0);
        this.setBlock(world, i + 2, j + 28, k + 33, Dungeons.blueGlow, 0);
        this.setBlock(world, i + 2, j + 28, k + 34, Dungeons.blueGlow, 0);
        this.setBlock(world, i + 2, j + 28, k + 35, Dungeons.blueGlow, 0);
        this.setBlock(world, i + 2, j + 28, k + 36, Dungeons.blueGlow, 0);
        this.setBlock(world, i + 2, j + 28, k + 37, Dungeons.blueGlow, 0);
        this.setBlock(world, i + 2, j + 28, k + 38, Dungeons.blueGlow, 0);
        this.setBlock(world, i + 2, j + 28, k + 41, Dungeons.blueBrick, 0);
        this.setBlock(world, i + 2, j + 28, k + 42, Dungeons.blueBrick, 0);
        this.setBlock(world, i + 2, j + 28, k + 43, Dungeons.blueBrick, 0);
        this.setBlock(world, i + 2, j + 28, k + 44, Dungeons.blueBrick, 0);
        this.setBlock(world, i + 2, j + 28, k + 45, Dungeons.blueBrick, 0);
        this.setBlock(world, i + 2, j + 28, k + 46, Dungeons.blueBrick, 0);
        this.setBlock(world, i + 2, j + 28, k + 47, Dungeons.blueBrick, 0);
        this.setBlock(world, i + 2, j + 28, k + 48, Dungeons.blueBrick, 0);
        this.setBlock(world, i + 2, j + 28, k + 49, Dungeons.blueBrick, 0);
        this.setBlock(world, i + 2, j + 29, k + 3, Dungeons.blueBrick, 0);
        this.setBlock(world, i + 2, j + 29, k + 4, Dungeons.blueBrick, 0);
        this.setBlock(world, i + 2, j + 29, k + 5, Dungeons.blueBrick, 0);
        this.setBlock(world, i + 2, j + 29, k + 6, Dungeons.blueBrick, 0);
        this.setBlock(world, i + 2, j + 29, k + 7, Dungeons.blueBrick, 0);
        this.setBlock(world, i + 2, j + 29, k + 8, Dungeons.blueBrick, 0);
        this.setBlock(world, i + 2, j + 29, k + 9, Dungeons.blueBrick, 0);
        this.setBlock(world, i + 2, j + 29, k + 10, Dungeons.blueBrick, 0);
        this.setBlock(world, i + 2, j + 29, k + 11, Dungeons.blueBrick, 0);
        this.setBlock(world, i + 2, j + 29, k + 14, Dungeons.blueBrick, 0);
        this.setBlock(world, i + 2, j + 29, k + 15, Dungeons.blueBrick, 0);
        this.setBlock(world, i + 2, j + 29, k + 16, Dungeons.blueBrick, 0);
        this.setBlock(world, i + 2, j + 29, k + 17, Dungeons.blueBrick, 0);
        this.setBlock(world, i + 2, j + 29, k + 18, Dungeons.blueBrick, 0);
        this.setBlock(world, i + 2, j + 29, k + 19, Dungeons.blueBrick, 0);
        this.setBlock(world, i + 2, j + 29, k + 20, Dungeons.blueBrick, 0);
        this.setBlock(world, i + 2, j + 29, k + 23, Dungeons.blueBrick, 0);
        this.setBlock(world, i + 2, j + 29, k + 24, Dungeons.blueBrick, 0);
        this.setBlock(world, i + 2, j + 29, k + 25, Dungeons.blueBrick, 0);
        this.setBlock(world, i + 2, j + 29, k + 26, Dungeons.blueBrick, 0);
        this.setBlock(world, i + 2, j + 29, k + 27, Dungeons.blueBrick, 0);
        this.setBlock(world, i + 2, j + 29, k + 28, Dungeons.blueBrick, 0);
        this.setBlock(world, i + 2, j + 29, k + 29, Dungeons.blueBrick, 0);
        this.setBlock(world, i + 2, j + 29, k + 32, Dungeons.blueBrick, 0);
        this.setBlock(world, i + 2, j + 29, k + 33, Dungeons.blueBrick, 0);
        this.setBlock(world, i + 2, j + 29, k + 34, Dungeons.blueBrick, 0);
        this.setBlock(world, i + 2, j + 29, k + 35, Dungeons.blueBrick, 0);
        this.setBlock(world, i + 2, j + 29, k + 36, Dungeons.blueBrick, 0);
        this.setBlock(world, i + 2, j + 29, k + 37, Dungeons.blueBrick, 0);
        this.setBlock(world, i + 2, j + 29, k + 38, Dungeons.blueBrick, 0);
        this.setBlock(world, i + 2, j + 29, k + 41, Dungeons.blueBrick, 0);
        this.setBlock(world, i + 2, j + 29, k + 42, Dungeons.blueBrick, 0);
        this.setBlock(world, i + 2, j + 29, k + 43, Dungeons.blueBrick, 0);
        this.setBlock(world, i + 2, j + 29, k + 44, Dungeons.blueBrick, 0);
        this.setBlock(world, i + 2, j + 29, k + 45, Dungeons.blueBrick, 0);
        this.setBlock(world, i + 2, j + 29, k + 46, Dungeons.blueBrick, 0);
        this.setBlock(world, i + 2, j + 29, k + 47, Dungeons.blueBrick, 0);
        this.setBlock(world, i + 2, j + 29, k + 48, Dungeons.blueBrick, 0);
        this.setBlock(world, i + 2, j + 29, k + 49, Dungeons.blueBrick, 0);
        this.setBlock(world, i + 2, j + 30, k + 3, Dungeons.blueBrick, 0);
        this.setBlock(world, i + 2, j + 30, k + 4, Dungeons.blueBrick, 0);
        this.setBlock(world, i + 2, j + 30, k + 5, Dungeons.blueBrick, 0);
        this.setBlock(world, i + 2, j + 30, k + 6, Dungeons.blueBrick, 0);
        this.setBlock(world, i + 2, j + 30, k + 7, Dungeons.blueBrick, 0);
        this.setBlock(world, i + 2, j + 30, k + 8, Dungeons.blueBrick, 0);
        this.setBlock(world, i + 2, j + 30, k + 9, Dungeons.blueBrick, 0);
        this.setBlock(world, i + 2, j + 30, k + 10, Dungeons.blueBrick, 0);
        this.setBlock(world, i + 2, j + 30, k + 11, Dungeons.blueBrick, 0);
        this.setBlock(world, i + 2, j + 30, k + 14, Dungeons.blueBrick, 0);
        this.setBlock(world, i + 2, j + 30, k + 15, Dungeons.blueBrick, 0);
        this.setBlock(world, i + 2, j + 30, k + 16, Dungeons.blueBrick, 0);
        this.setBlock(world, i + 2, j + 30, k + 17, Dungeons.blueBrick, 0);
        this.setBlock(world, i + 2, j + 30, k + 18, Dungeons.blueBrick, 0);
        this.setBlock(world, i + 2, j + 30, k + 19, Dungeons.blueBrick, 0);
        this.setBlock(world, i + 2, j + 30, k + 20, Dungeons.blueBrick, 0);
        this.setBlock(world, i + 2, j + 30, k + 23, Dungeons.blueBrick, 0);
        this.setBlock(world, i + 2, j + 30, k + 24, Dungeons.blueBrick, 0);
        this.setBlock(world, i + 2, j + 30, k + 25, Dungeons.blueBrick, 0);
        this.setBlock(world, i + 2, j + 30, k + 26, Dungeons.blueBrick, 0);
        this.setBlock(world, i + 2, j + 30, k + 27, Dungeons.blueBrick, 0);
        this.setBlock(world, i + 2, j + 30, k + 28, Dungeons.blueBrick, 0);
        this.setBlock(world, i + 2, j + 30, k + 29, Dungeons.blueBrick, 0);
        this.setBlock(world, i + 2, j + 30, k + 32, Dungeons.blueBrick, 0);
        this.setBlock(world, i + 2, j + 30, k + 33, Dungeons.blueBrick, 0);
        this.setBlock(world, i + 2, j + 30, k + 34, Dungeons.blueBrick, 0);
        this.setBlock(world, i + 2, j + 30, k + 35, Dungeons.blueBrick, 0);
        this.setBlock(world, i + 2, j + 30, k + 36, Dungeons.blueBrick, 0);
        this.setBlock(world, i + 2, j + 30, k + 37, Dungeons.blueBrick, 0);
        this.setBlock(world, i + 2, j + 30, k + 38, Dungeons.blueBrick, 0);
        this.setBlock(world, i + 2, j + 30, k + 41, Dungeons.blueBrick, 0);
        this.setBlock(world, i + 2, j + 30, k + 42, Dungeons.blueBrick, 0);
        this.setBlock(world, i + 2, j + 30, k + 43, Dungeons.blueBrick, 0);
        this.setBlock(world, i + 2, j + 30, k + 44, Dungeons.blueBrick, 0);
        this.setBlock(world, i + 2, j + 30, k + 45, Dungeons.blueBrick, 0);
        this.setBlock(world, i + 2, j + 30, k + 46, Dungeons.blueBrick, 0);
        this.setBlock(world, i + 2, j + 30, k + 47, Dungeons.blueBrick, 0);
        this.setBlock(world, i + 2, j + 30, k + 48, Dungeons.blueBrick, 0);
        this.setBlock(world, i + 2, j + 30, k + 49, Dungeons.blueBrick, 0);
        this.setBlock(world, i + 2, j + 31, k + 3, Dungeons.blueBrick, 0);
        this.setBlock(world, i + 2, j + 31, k + 4, Dungeons.blueBrick, 0);
        this.setBlock(world, i + 2, j + 31, k + 5, Dungeons.blueBrick, 0);
        this.setBlock(world, i + 2, j + 31, k + 6, Dungeons.blueBrick, 0);
        this.setBlock(world, i + 2, j + 31, k + 7, Dungeons.blueBrick, 0);
        this.setBlock(world, i + 2, j + 31, k + 8, Dungeons.blueBrick, 0);
        this.setBlock(world, i + 2, j + 31, k + 9, Dungeons.blueBrick, 0);
        this.setBlock(world, i + 2, j + 31, k + 10, Dungeons.blueBrick, 0);
        this.setBlock(world, i + 2, j + 31, k + 11, Dungeons.blueBrick, 0);
        this.setBlock(world, i + 2, j + 31, k + 14, Dungeons.blueBrick, 0);
        this.setBlock(world, i + 2, j + 31, k + 15, Dungeons.blueBrick, 0);
        this.setBlock(world, i + 2, j + 31, k + 16, Dungeons.blueBrick, 0);
        this.setBlock(world, i + 2, j + 31, k + 17, Dungeons.blueBrick, 0);
        this.setBlock(world, i + 2, j + 31, k + 18, Dungeons.blueBrick, 0);
        this.setBlock(world, i + 2, j + 31, k + 19, Dungeons.blueBrick, 0);
        this.setBlock(world, i + 2, j + 31, k + 20, Dungeons.blueBrick, 0);
        this.setBlock(world, i + 2, j + 31, k + 23, Dungeons.blueBrick, 0);
        this.setBlock(world, i + 2, j + 31, k + 24, Dungeons.blueBrick, 0);
        this.setBlock(world, i + 2, j + 31, k + 25, Dungeons.blueBrick, 0);
        this.setBlock(world, i + 2, j + 31, k + 26, Dungeons.blueBrick, 0);
        this.setBlock(world, i + 2, j + 31, k + 27, Dungeons.blueBrick, 0);
        this.setBlock(world, i + 2, j + 31, k + 28, Dungeons.blueBrick, 0);
        this.setBlock(world, i + 2, j + 31, k + 29, Dungeons.blueBrick, 0);
        this.setBlock(world, i + 2, j + 31, k + 32, Dungeons.blueBrick, 0);
        this.setBlock(world, i + 2, j + 31, k + 33, Dungeons.blueBrick, 0);
        this.setBlock(world, i + 2, j + 31, k + 34, Dungeons.blueBrick, 0);
        this.setBlock(world, i + 2, j + 31, k + 35, Dungeons.blueBrick, 0);
        this.setBlock(world, i + 2, j + 31, k + 36, Dungeons.blueBrick, 0);
        this.setBlock(world, i + 2, j + 31, k + 37, Dungeons.blueBrick, 0);
        this.setBlock(world, i + 2, j + 31, k + 38, Dungeons.blueBrick, 0);
        this.setBlock(world, i + 2, j + 31, k + 41, Dungeons.blueBrick, 0);
        this.setBlock(world, i + 2, j + 31, k + 42, Dungeons.blueBrick, 0);
        this.setBlock(world, i + 2, j + 31, k + 43, Dungeons.blueBrick, 0);
        this.setBlock(world, i + 2, j + 31, k + 44, Dungeons.blueBrick, 0);
        this.setBlock(world, i + 2, j + 31, k + 45, Dungeons.blueBrick, 0);
        this.setBlock(world, i + 2, j + 31, k + 46, Dungeons.blueBrick, 0);
        this.setBlock(world, i + 2, j + 31, k + 47, Dungeons.blueBrick, 0);
        this.setBlock(world, i + 2, j + 31, k + 48, Dungeons.blueBrick, 0);
        this.setBlock(world, i + 2, j + 31, k + 49, Dungeons.blueBrick, 0);
        this.setBlock(world, i + 2, j + 32, k + 3, Dungeons.blueBrick, 0);
        this.setBlock(world, i + 2, j + 32, k + 4, Dungeons.blueBrick, 0);
        this.setBlock(world, i + 2, j + 32, k + 5, Dungeons.blueBrick, 0);
        this.setBlock(world, i + 2, j + 32, k + 6, Dungeons.blueBrick, 0);
        this.setBlock(world, i + 2, j + 32, k + 7, Dungeons.blueBrick, 0);
        this.setBlock(world, i + 2, j + 32, k + 8, Dungeons.blueBrick, 0);
        this.setBlock(world, i + 2, j + 32, k + 9, Dungeons.blueBrick, 0);
        this.setBlock(world, i + 2, j + 32, k + 10, Dungeons.blueBrick, 0);
        this.setBlock(world, i + 2, j + 32, k + 11, Dungeons.blueBrick, 0);
        this.setBlock(world, i + 2, j + 32, k + 14, Dungeons.blueBrick, 0);
        this.setBlock(world, i + 2, j + 32, k + 15, Dungeons.blueBrick, 0);
        this.setBlock(world, i + 2, j + 32, k + 16, Dungeons.blueBrick, 0);
        this.setBlock(world, i + 2, j + 32, k + 17, Dungeons.blueBrick, 0);
        this.setBlock(world, i + 2, j + 32, k + 18, Dungeons.blueBrick, 0);
        this.setBlock(world, i + 2, j + 32, k + 19, Dungeons.blueBrick, 0);
        this.setBlock(world, i + 2, j + 32, k + 20, Dungeons.blueBrick, 0);
        this.setBlock(world, i + 2, j + 32, k + 23, Dungeons.blueBrick, 0);
        this.setBlock(world, i + 2, j + 32, k + 24, Dungeons.blueBrick, 0);
        this.setBlock(world, i + 2, j + 32, k + 25, Dungeons.blueBrick, 0);
        this.setBlock(world, i + 2, j + 32, k + 26, Dungeons.blueBrick, 0);
        this.setBlock(world, i + 2, j + 32, k + 27, Dungeons.blueBrick, 0);
        this.setBlock(world, i + 2, j + 32, k + 28, Dungeons.blueBrick, 0);
        this.setBlock(world, i + 2, j + 32, k + 29, Dungeons.blueBrick, 0);
        this.setBlock(world, i + 2, j + 32, k + 32, Dungeons.blueBrick, 0);
        this.setBlock(world, i + 2, j + 32, k + 33, Dungeons.blueBrick, 0);
        this.setBlock(world, i + 2, j + 32, k + 34, Dungeons.blueBrick, 0);
        this.setBlock(world, i + 2, j + 32, k + 35, Dungeons.blueBrick, 0);
        this.setBlock(world, i + 2, j + 32, k + 36, Dungeons.blueBrick, 0);
        this.setBlock(world, i + 2, j + 32, k + 37, Dungeons.blueBrick, 0);
        this.setBlock(world, i + 2, j + 32, k + 38, Dungeons.blueBrick, 0);
        this.setBlock(world, i + 2, j + 32, k + 41, Dungeons.blueBrick, 0);
        this.setBlock(world, i + 2, j + 32, k + 42, Dungeons.blueBrick, 0);
        this.setBlock(world, i + 2, j + 32, k + 43, Dungeons.blueBrick, 0);
        this.setBlock(world, i + 2, j + 32, k + 44, Dungeons.blueBrick, 0);
        this.setBlock(world, i + 2, j + 32, k + 45, Dungeons.blueBrick, 0);
        this.setBlock(world, i + 2, j + 32, k + 46, Dungeons.blueBrick, 0);
        this.setBlock(world, i + 2, j + 32, k + 47, Dungeons.blueBrick, 0);
        this.setBlock(world, i + 2, j + 32, k + 48, Dungeons.blueBrick, 0);
        this.setBlock(world, i + 2, j + 32, k + 49, Dungeons.blueBrick, 0);
        this.setBlock(world, i + 2, j + 33, k + 3, Dungeons.blueBrick, 0);
        this.setBlock(world, i + 2, j + 33, k + 4, Dungeons.blueBrick, 0);
        this.setBlock(world, i + 2, j + 33, k + 5, Dungeons.blueBrick, 0);
        this.setBlock(world, i + 2, j + 33, k + 6, Dungeons.blueBrick, 0);
        this.setBlock(world, i + 2, j + 33, k + 7, Dungeons.blueBrick, 0);
        this.setBlock(world, i + 2, j + 33, k + 8, Dungeons.blueBrick, 0);
        this.setBlock(world, i + 2, j + 33, k + 9, Dungeons.blueBrick, 0);
        this.setBlock(world, i + 2, j + 33, k + 10, Dungeons.blueBrick, 0);
        this.setBlock(world, i + 2, j + 33, k + 11, Dungeons.blueBrick, 0);
        this.setBlock(world, i + 2, j + 33, k + 14, Dungeons.blueBrick, 0);
        this.setBlock(world, i + 2, j + 33, k + 15, Dungeons.blueBrick, 0);
        this.setBlock(world, i + 2, j + 33, k + 16, Dungeons.blueBrick, 0);
        this.setBlock(world, i + 2, j + 33, k + 17, Dungeons.blueBrick, 0);
        this.setBlock(world, i + 2, j + 33, k + 18, Dungeons.blueBrick, 0);
        this.setBlock(world, i + 2, j + 33, k + 19, Dungeons.blueBrick, 0);
        this.setBlock(world, i + 2, j + 33, k + 20, Dungeons.blueBrick, 0);
        this.setBlock(world, i + 2, j + 33, k + 23, Dungeons.blueBrick, 0);
        this.setBlock(world, i + 2, j + 33, k + 24, Dungeons.blueBrick, 0);
        this.setBlock(world, i + 2, j + 33, k + 25, Dungeons.blueBrick, 0);
        this.setBlock(world, i + 2, j + 33, k + 26, Dungeons.blueBrick, 0);
        this.setBlock(world, i + 2, j + 33, k + 27, Dungeons.blueBrick, 0);
        this.setBlock(world, i + 2, j + 33, k + 28, Dungeons.blueBrick, 0);
        this.setBlock(world, i + 2, j + 33, k + 29, Dungeons.blueBrick, 0);
        this.setBlock(world, i + 2, j + 33, k + 32, Dungeons.blueBrick, 0);
        this.setBlock(world, i + 2, j + 33, k + 33, Dungeons.blueBrick, 0);
        this.setBlock(world, i + 2, j + 33, k + 34, Dungeons.blueBrick, 0);
        this.setBlock(world, i + 2, j + 33, k + 35, Dungeons.blueBrick, 0);
        this.setBlock(world, i + 2, j + 33, k + 36, Dungeons.blueBrick, 0);
        this.setBlock(world, i + 2, j + 33, k + 37, Dungeons.blueBrick, 0);
        this.setBlock(world, i + 2, j + 33, k + 38, Dungeons.blueBrick, 0);
        this.setBlock(world, i + 2, j + 33, k + 41, Dungeons.blueBrick, 0);
        this.setBlock(world, i + 2, j + 33, k + 42, Dungeons.blueBrick, 0);
        this.setBlock(world, i + 2, j + 33, k + 43, Dungeons.blueBrick, 0);
        this.setBlock(world, i + 2, j + 33, k + 44, Dungeons.blueBrick, 0);
        this.setBlock(world, i + 2, j + 33, k + 45, Dungeons.blueBrick, 0);
        this.setBlock(world, i + 2, j + 33, k + 46, Dungeons.blueBrick, 0);
        this.setBlock(world, i + 2, j + 33, k + 47, Dungeons.blueBrick, 0);
        this.setBlock(world, i + 2, j + 33, k + 48, Dungeons.blueBrick, 0);
        this.setBlock(world, i + 2, j + 33, k + 49, Dungeons.blueBrick, 0);
        this.setBlock(world, i + 2, j + 34, k + 3, Dungeons.blueBrick, 0);
        this.setBlock(world, i + 2, j + 34, k + 4, Dungeons.blueBrick, 0);
        this.setBlock(world, i + 2, j + 34, k + 5, Dungeons.blueBrick, 0);
        this.setBlock(world, i + 2, j + 34, k + 6, Dungeons.blueBrick, 0);
        this.setBlock(world, i + 2, j + 34, k + 7, Dungeons.blueBrick, 0);
        this.setBlock(world, i + 2, j + 34, k + 8, Dungeons.blueBrick, 0);
        this.setBlock(world, i + 2, j + 34, k + 9, Dungeons.blueBrick, 0);
        this.setBlock(world, i + 2, j + 34, k + 10, Dungeons.blueBrick, 0);
        this.setBlock(world, i + 2, j + 34, k + 11, Dungeons.blueBrick, 0);
        this.setBlock(world, i + 2, j + 34, k + 14, Dungeons.blueBrick, 0);
        this.setBlock(world, i + 2, j + 34, k + 15, Dungeons.blueBrick, 0);
        this.setBlock(world, i + 2, j + 34, k + 16, Dungeons.blueBrick, 0);
        this.setBlock(world, i + 2, j + 34, k + 17, Dungeons.blueBrick, 0);
        this.setBlock(world, i + 2, j + 34, k + 18, Dungeons.blueBrick, 0);
        this.setBlock(world, i + 2, j + 34, k + 19, Dungeons.blueBrick, 0);
        this.setBlock(world, i + 2, j + 34, k + 20, Dungeons.blueBrick, 0);
        this.setBlock(world, i + 2, j + 34, k + 23, Dungeons.blueBrick, 0);
        this.setBlock(world, i + 2, j + 34, k + 24, Dungeons.blueBrick, 0);
        this.setBlock(world, i + 2, j + 34, k + 25, Dungeons.blueBrick, 0);
        this.setBlock(world, i + 2, j + 34, k + 26, Dungeons.blueBrick, 0);
        this.setBlock(world, i + 2, j + 34, k + 27, Dungeons.blueBrick, 0);
        this.setBlock(world, i + 2, j + 34, k + 28, Dungeons.blueBrick, 0);
        this.setBlock(world, i + 2, j + 34, k + 29, Dungeons.blueBrick, 0);
        this.setBlock(world, i + 2, j + 34, k + 32, Dungeons.blueBrick, 0);
        this.setBlock(world, i + 2, j + 34, k + 33, Dungeons.blueBrick, 0);
        this.setBlock(world, i + 2, j + 34, k + 34, Dungeons.blueBrick, 0);
        this.setBlock(world, i + 2, j + 34, k + 35, Dungeons.blueBrick, 0);
        this.setBlock(world, i + 2, j + 34, k + 36, Dungeons.blueBrick, 0);
        this.setBlock(world, i + 2, j + 34, k + 37, Dungeons.blueBrick, 0);
        this.setBlock(world, i + 2, j + 34, k + 38, Dungeons.blueBrick, 0);
        this.setBlock(world, i + 2, j + 34, k + 41, Dungeons.blueBrick, 0);
        this.setBlock(world, i + 2, j + 34, k + 42, Dungeons.blueBrick, 0);
        this.setBlock(world, i + 2, j + 34, k + 43, Dungeons.blueBrick, 0);
        this.setBlock(world, i + 2, j + 34, k + 44, Dungeons.blueBrick, 0);
        this.setBlock(world, i + 2, j + 34, k + 45, Dungeons.blueBrick, 0);
        this.setBlock(world, i + 2, j + 34, k + 46, Dungeons.blueBrick, 0);
        this.setBlock(world, i + 2, j + 34, k + 47, Dungeons.blueBrick, 0);
        this.setBlock(world, i + 2, j + 34, k + 48, Dungeons.blueBrick, 0);
        this.setBlock(world, i + 2, j + 34, k + 49, Dungeons.blueBrick, 0);
        this.setBlock(world, i + 2, j + 35, k + 2, Dungeons.midnightFence, 0);
        this.setBlock(world, i + 2, j + 35, k + 3, Dungeons.blueBrick, 0);
        this.setBlock(world, i + 2, j + 35, k + 4, Dungeons.blueBrick, 0);
        this.setBlock(world, i + 2, j + 35, k + 5, Dungeons.blueBrick, 0);
        this.setBlock(world, i + 2, j + 35, k + 6, Dungeons.blueBrick, 0);
        this.setBlock(world, i + 2, j + 35, k + 7, Dungeons.blueBrick, 0);
        this.setBlock(world, i + 2, j + 35, k + 8, Dungeons.blueBrick, 0);
        this.setBlock(world, i + 2, j + 35, k + 9, Dungeons.blueBrick, 0);
        this.setBlock(world, i + 2, j + 35, k + 10, Dungeons.blueBrick, 0);
        this.setBlock(world, i + 2, j + 35, k + 11, Dungeons.blueBrick, 0);
        this.setBlock(world, i + 2, j + 35, k + 14, Dungeons.blueGlow, 0);
        this.setBlock(world, i + 2, j + 35, k + 15, Dungeons.blueGlow, 0);
        this.setBlock(world, i + 2, j + 35, k + 16, Dungeons.blueGlow, 0);
        this.setBlock(world, i + 2, j + 35, k + 17, Dungeons.blueGlow, 0);
        this.setBlock(world, i + 2, j + 35, k + 18, Dungeons.blueGlow, 0);
        this.setBlock(world, i + 2, j + 35, k + 19, Dungeons.blueGlow, 0);
        this.setBlock(world, i + 2, j + 35, k + 20, Dungeons.blueGlow, 0);
        this.setBlock(world, i + 2, j + 35, k + 23, Dungeons.blueGlow, 0);
        this.setBlock(world, i + 2, j + 35, k + 24, Dungeons.blueGlow, 0);
        this.setBlock(world, i + 2, j + 35, k + 25, Dungeons.blueGlow, 0);
        this.setBlock(world, i + 2, j + 35, k + 26, Dungeons.blueGlow, 0);
        this.setBlock(world, i + 2, j + 35, k + 27, Dungeons.blueGlow, 0);
        this.setBlock(world, i + 2, j + 35, k + 28, Dungeons.blueGlow, 0);
        this.setBlock(world, i + 2, j + 35, k + 29, Dungeons.blueGlow, 0);
        this.setBlock(world, i + 2, j + 35, k + 32, Dungeons.blueGlow, 0);
        this.setBlock(world, i + 2, j + 35, k + 33, Dungeons.blueGlow, 0);
        this.setBlock(world, i + 2, j + 35, k + 34, Dungeons.blueGlow, 0);
        this.setBlock(world, i + 2, j + 35, k + 35, Dungeons.blueGlow, 0);
        this.setBlock(world, i + 2, j + 35, k + 36, Dungeons.blueGlow, 0);
        this.setBlock(world, i + 2, j + 35, k + 37, Dungeons.blueGlow, 0);
        this.setBlock(world, i + 2, j + 35, k + 38, Dungeons.blueGlow, 0);
        this.setBlock(world, i + 2, j + 35, k + 41, Dungeons.blueBrick, 0);
        this.setBlock(world, i + 2, j + 35, k + 42, Dungeons.blueBrick, 0);
        this.setBlock(world, i + 2, j + 35, k + 43, Dungeons.blueBrick, 0);
        this.setBlock(world, i + 2, j + 35, k + 44, Dungeons.blueBrick, 0);
        this.setBlock(world, i + 2, j + 35, k + 45, Dungeons.blueBrick, 0);
        this.setBlock(world, i + 2, j + 35, k + 46, Dungeons.blueBrick, 0);
        this.setBlock(world, i + 2, j + 35, k + 47, Dungeons.blueBrick, 0);
        this.setBlock(world, i + 2, j + 35, k + 48, Dungeons.blueBrick, 0);
        this.setBlock(world, i + 2, j + 35, k + 49, Dungeons.blueBrick, 0);
        this.setBlock(world, i + 2, j + 35, k + 50, Dungeons.midnightFence, 0);
        this.setBlock(world, i + 2, j + 36, k + 2, Dungeons.blueGlow, 0);
        this.setBlock(world, i + 2, j + 36, k + 3, Dungeons.blueGlow, 0);
        this.setBlock(world, i + 2, j + 36, k + 4, Dungeons.blueGlow, 0);
        this.setBlock(world, i + 2, j + 36, k + 5, Dungeons.blueGlow, 0);
        this.setBlock(world, i + 2, j + 36, k + 6, Dungeons.blueGlow, 0);
        this.setBlock(world, i + 2, j + 36, k + 7, Dungeons.blueGlow, 0);
        this.setBlock(world, i + 2, j + 36, k + 8, Dungeons.blueGlow, 0);
        this.setBlock(world, i + 2, j + 36, k + 9, Dungeons.blueGlow, 0);
        this.setBlock(world, i + 2, j + 36, k + 10, Dungeons.blueGlow, 0);
        this.setBlock(world, i + 2, j + 36, k + 11, Dungeons.blueGlow, 0);
        this.setBlock(world, i + 2, j + 36, k + 41, Dungeons.blueGlow, 0);
        this.setBlock(world, i + 2, j + 36, k + 42, Dungeons.blueGlow, 0);
        this.setBlock(world, i + 2, j + 36, k + 43, Dungeons.blueGlow, 0);
        this.setBlock(world, i + 2, j + 36, k + 44, Dungeons.blueGlow, 0);
        this.setBlock(world, i + 2, j + 36, k + 45, Dungeons.blueGlow, 0);
        this.setBlock(world, i + 2, j + 36, k + 46, Dungeons.blueGlow, 0);
        this.setBlock(world, i + 2, j + 36, k + 47, Dungeons.blueGlow, 0);
        this.setBlock(world, i + 2, j + 36, k + 48, Dungeons.blueGlow, 0);
        this.setBlock(world, i + 2, j + 36, k + 49, Dungeons.blueGlow, 0);
        this.setBlock(world, i + 2, j + 36, k + 50, Dungeons.blueGlow, 0);
        this.setBlock(world, i + 2, j + 37, k + 2, Dungeons.lightBlueGlow, 0);
        this.setBlock(world, i + 2, j + 37, k + 50, Dungeons.lightBlueGlow, 0);
        this.setBlock(world, i + 3, j + 28, k + 3, Dungeons.blueBrick, 0);
        this.setBlock(world, i + 3, j + 28, k + 4, Dungeons.blueBrick, 0);
        this.setBlock(world, i + 3, j + 28, k + 5, Dungeons.blueBrick, 0);
        this.setBlock(world, i + 3, j + 28, k + 6, Dungeons.blueBrick, 0);
        this.setBlock(world, i + 3, j + 28, k + 7, Dungeons.blueBrick, 0);
        this.setBlock(world, i + 3, j + 28, k + 8, Dungeons.blueBrick, 0);
        this.setBlock(world, i + 3, j + 28, k + 9, Dungeons.blueBrick, 0);
        this.setBlock(world, i + 3, j + 28, k + 10, Dungeons.blueBrick, 0);
        this.setBlock(world, i + 3, j + 28, k + 11, Dungeons.blueBrick, 0);
        this.setBlock(world, i + 3, j + 28, k + 14, Dungeons.blueGlow, 0);
        this.setBlock(world, i + 3, j + 28, k + 15, Dungeons.blueGlow, 0);
        this.setBlock(world, i + 3, j + 28, k + 16, Dungeons.blueGlow, 0);
        this.setBlock(world, i + 3, j + 28, k + 17, Dungeons.blueGlow, 0);
        this.setBlock(world, i + 3, j + 28, k + 18, Dungeons.blueGlow, 0);
        this.setBlock(world, i + 3, j + 28, k + 19, Dungeons.blueGlow, 0);
        this.setBlock(world, i + 3, j + 28, k + 20, Dungeons.blueGlow, 0);
        this.setBlock(world, i + 3, j + 28, k + 23, Dungeons.blueGlow, 0);
        this.setBlock(world, i + 3, j + 28, k + 24, Dungeons.blueGlow, 0);
        this.setBlock(world, i + 3, j + 28, k + 25, Dungeons.blueGlow, 0);
        this.setBlock(world, i + 3, j + 28, k + 26, Dungeons.blueGlow, 0);
        this.setBlock(world, i + 3, j + 28, k + 27, Dungeons.blueGlow, 0);
        this.setBlock(world, i + 3, j + 28, k + 28, Dungeons.blueGlow, 0);
        this.setBlock(world, i + 3, j + 28, k + 29, Dungeons.blueGlow, 0);
        this.setBlock(world, i + 3, j + 28, k + 32, Dungeons.blueGlow, 0);
        this.setBlock(world, i + 3, j + 28, k + 33, Dungeons.blueGlow, 0);
        this.setBlock(world, i + 3, j + 28, k + 34, Dungeons.blueGlow, 0);
        this.setBlock(world, i + 3, j + 28, k + 35, Dungeons.blueGlow, 0);
        this.setBlock(world, i + 3, j + 28, k + 36, Dungeons.blueGlow, 0);
        this.setBlock(world, i + 3, j + 28, k + 37, Dungeons.blueGlow, 0);
        this.setBlock(world, i + 3, j + 28, k + 38, Dungeons.blueGlow, 0);
        this.setBlock(world, i + 3, j + 28, k + 41, Dungeons.blueBrick, 0);
        this.setBlock(world, i + 3, j + 28, k + 42, Dungeons.blueBrick, 0);
        this.setBlock(world, i + 3, j + 28, k + 43, Dungeons.blueBrick, 0);
        this.setBlock(world, i + 3, j + 28, k + 44, Dungeons.blueBrick, 0);
        this.setBlock(world, i + 3, j + 28, k + 45, Dungeons.blueBrick, 0);
        this.setBlock(world, i + 3, j + 28, k + 46, Dungeons.blueBrick, 0);
        this.setBlock(world, i + 3, j + 28, k + 47, Dungeons.blueBrick, 0);
        this.setBlock(world, i + 3, j + 28, k + 48, Dungeons.blueBrick, 0);
        this.setBlock(world, i + 3, j + 28, k + 49, Dungeons.blueBrick, 0);
        this.setBlock(world, i + 3, j + 29, k + 3, Dungeons.blueBrick, 0);
        this.setBlock(world, i + 3, j + 29, k + 11, Dungeons.blueBrick, 0);
        this.setBlock(world, i + 3, j + 29, k + 14, Dungeons.blueBrick, 0);
        this.setBlock(world, i + 3, j + 29, k + 15, Dungeons.nightCounter, 0);
        this.setBlock(world, i + 3, j + 29, k + 17, Dungeons.midnightFence, 0);
        this.setBlock(world, i + 3, j + 29, k + 20, Dungeons.blueBrick, 0);
        this.setBlock(world, i + 3, j + 29, k + 23, Dungeons.blueBrick, 0);
        this.setBlock(world, i + 3, j + 29, k + 24, Dungeons.nightCounter, 0);
        this.setBlock(world, i + 3, j + 29, k + 26, Dungeons.midnightFence, 0);
        this.setBlock(world, i + 3, j + 29, k + 29, Dungeons.blueBrick, 0);
        this.setBlock(world, i + 3, j + 29, k + 32, Dungeons.blueBrick, 0);
        this.setBlock(world, i + 3, j + 29, k + 33, Dungeons.nightCounter, 0);
        this.setBlock(world, i + 3, j + 29, k + 35, Dungeons.midnightFence, 0);
        this.setBlock(world, i + 3, j + 29, k + 38, Dungeons.blueBrick, 0);
        this.setBlock(world, i + 3, j + 29, k + 41, Dungeons.blueBrick, 0);
        this.setBlock(world, i + 3, j + 29, k + 49, Dungeons.blueBrick, 0);
        this.setBlock(world, i + 3, j + 30, k + 3, Dungeons.blueBrick, 0);
        this.setBlock(world, i + 3, j + 30, k + 11, Dungeons.blueBrick, 0);
        this.setBlock(world, i + 3, j + 30, k + 14, Dungeons.blueBrick, 0);
        this.setBlock(world, i + 3, j + 30, k + 17, Dungeons.midnightFence, 0);
        this.setBlock(world, i + 3, j + 30, k + 20, Dungeons.blueBrick, 0);
        this.setBlock(world, i + 3, j + 30, k + 23, Dungeons.blueBrick, 0);
        this.setBlock(world, i + 3, j + 30, k + 26, Dungeons.midnightFence, 0);
        this.setBlock(world, i + 3, j + 30, k + 29, Dungeons.blueBrick, 0);
        this.setBlock(world, i + 3, j + 30, k + 32, Dungeons.blueBrick, 0);
        this.setBlock(world, i + 3, j + 30, k + 35, Dungeons.midnightFence, 0);
        this.setBlock(world, i + 3, j + 30, k + 38, Dungeons.blueBrick, 0);
        this.setBlock(world, i + 3, j + 30, k + 41, Dungeons.blueBrick, 0);
        this.setBlock(world, i + 3, j + 30, k + 49, Dungeons.blueBrick, 0);
        this.setBlock(world, i + 3, j + 31, k + 3, Dungeons.blueBrick, 0);
        this.setBlock(world, i + 3, j + 31, k + 11, Dungeons.blueBrick, 0);
        this.setBlock(world, i + 3, j + 31, k + 14, Dungeons.blueBrick, 0);
        this.setBlock(world, i + 3, j + 31, k + 17, Dungeons.nightLight, 0);
        this.setBlock(world, i + 3, j + 31, k + 20, Dungeons.blueBrick, 0);
        this.setBlock(world, i + 3, j + 31, k + 23, Dungeons.blueBrick, 0);
        this.setBlock(world, i + 3, j + 31, k + 26, Dungeons.nightLight, 0);
        this.setBlock(world, i + 3, j + 31, k + 29, Dungeons.blueBrick, 0);
        this.setBlock(world, i + 3, j + 31, k + 32, Dungeons.blueBrick, 0);
        this.setBlock(world, i + 3, j + 31, k + 35, Dungeons.nightLight, 0);
        this.setBlock(world, i + 3, j + 31, k + 38, Dungeons.blueBrick, 0);
        this.setBlock(world, i + 3, j + 31, k + 41, Dungeons.blueBrick, 0);
        this.setBlock(world, i + 3, j + 31, k + 49, Dungeons.blueBrick, 0);
        this.setBlock(world, i + 3, j + 32, k + 3, Dungeons.blueBrick, 0);
        this.setBlock(world, i + 3, j + 32, k + 11, Dungeons.blueBrick, 0);
        this.setBlock(world, i + 3, j + 32, k + 14, Dungeons.blueBrick, 0);
        this.setBlock(world, i + 3, j + 32, k + 20, Dungeons.blueBrick, 0);
        this.setBlock(world, i + 3, j + 32, k + 23, Dungeons.blueBrick, 0);
        this.setBlock(world, i + 3, j + 32, k + 29, Dungeons.blueBrick, 0);
        this.setBlock(world, i + 3, j + 32, k + 32, Dungeons.blueBrick, 0);
        this.setBlock(world, i + 3, j + 32, k + 38, Dungeons.blueBrick, 0);
        this.setBlock(world, i + 3, j + 32, k + 41, Dungeons.blueBrick, 0);
        this.setBlock(world, i + 3, j + 32, k + 49, Dungeons.blueBrick, 0);
        this.setBlock(world, i + 3, j + 33, k + 3, Dungeons.blueBrick, 0);
        this.setBlock(world, i + 3, j + 33, k + 11, Dungeons.blueBrick, 0);
        this.setBlock(world, i + 3, j + 33, k + 14, Dungeons.blueBrick, 0);
        this.setBlock(world, i + 3, j + 33, k + 20, Dungeons.blueBrick, 0);
        this.setBlock(world, i + 3, j + 33, k + 23, Dungeons.blueBrick, 0);
        this.setBlock(world, i + 3, j + 33, k + 29, Dungeons.blueBrick, 0);
        this.setBlock(world, i + 3, j + 33, k + 32, Dungeons.blueBrick, 0);
        this.setBlock(world, i + 3, j + 33, k + 38, Dungeons.blueBrick, 0);
        this.setBlock(world, i + 3, j + 33, k + 41, Dungeons.blueBrick, 0);
        this.setBlock(world, i + 3, j + 33, k + 49, Dungeons.blueBrick, 0);
        this.setBlock(world, i + 3, j + 34, k + 3, Dungeons.blueBrick, 0);
        this.setBlock(world, i + 3, j + 34, k + 11, Dungeons.blueBrick, 0);
        this.setBlock(world, i + 3, j + 34, k + 14, Dungeons.blueBrick, 0);
        this.setBlock(world, i + 3, j + 34, k + 20, Dungeons.blueBrick, 0);
        this.setBlock(world, i + 3, j + 34, k + 23, Dungeons.blueBrick, 0);
        this.setBlock(world, i + 3, j + 34, k + 29, Dungeons.blueBrick, 0);
        this.setBlock(world, i + 3, j + 34, k + 32, Dungeons.blueBrick, 0);
        this.setBlock(world, i + 3, j + 34, k + 38, Dungeons.blueBrick, 0);
        this.setBlock(world, i + 3, j + 34, k + 41, Dungeons.blueBrick, 0);
        this.setBlock(world, i + 3, j + 34, k + 49, Dungeons.blueBrick, 0);
        this.setBlock(world, i + 3, j + 35, k + 3, Dungeons.blueBrick, 0);
        this.setBlock(world, i + 3, j + 35, k + 11, Dungeons.blueBrick, 0);
        this.setBlock(world, i + 3, j + 35, k + 14, Dungeons.blueGlow, 0);
        this.setBlock(world, i + 3, j + 35, k + 15, Dungeons.blueGlow, 0);
        this.setBlock(world, i + 3, j + 35, k + 16, Dungeons.blueGlow, 0);
        this.setBlock(world, i + 3, j + 35, k + 17, Dungeons.blueGlow, 0);
        this.setBlock(world, i + 3, j + 35, k + 18, Dungeons.blueGlow, 0);
        this.setBlock(world, i + 3, j + 35, k + 19, Dungeons.blueGlow, 0);
        this.setBlock(world, i + 3, j + 35, k + 20, Dungeons.blueGlow, 0);
        this.setBlock(world, i + 3, j + 35, k + 23, Dungeons.blueGlow, 0);
        this.setBlock(world, i + 3, j + 35, k + 24, Dungeons.blueGlow, 0);
        this.setBlock(world, i + 3, j + 35, k + 25, Dungeons.blueGlow, 0);
        this.setBlock(world, i + 3, j + 35, k + 26, Dungeons.blueGlow, 0);
        this.setBlock(world, i + 3, j + 35, k + 27, Dungeons.blueGlow, 0);
        this.setBlock(world, i + 3, j + 35, k + 28, Dungeons.blueGlow, 0);
        this.setBlock(world, i + 3, j + 35, k + 29, Dungeons.blueGlow, 0);
        this.setBlock(world, i + 3, j + 35, k + 32, Dungeons.blueGlow, 0);
        this.setBlock(world, i + 3, j + 35, k + 33, Dungeons.blueGlow, 0);
        this.setBlock(world, i + 3, j + 35, k + 34, Dungeons.blueGlow, 0);
        this.setBlock(world, i + 3, j + 35, k + 35, Dungeons.blueGlow, 0);
        this.setBlock(world, i + 3, j + 35, k + 36, Dungeons.blueGlow, 0);
        this.setBlock(world, i + 3, j + 35, k + 37, Dungeons.blueGlow, 0);
        this.setBlock(world, i + 3, j + 35, k + 38, Dungeons.blueGlow, 0);
        this.setBlock(world, i + 3, j + 35, k + 41, Dungeons.blueBrick, 0);
        this.setBlock(world, i + 3, j + 35, k + 49, Dungeons.blueBrick, 0);
        this.setBlock(world, i + 3, j + 36, k + 3, Dungeons.blueGlow, 0);
        this.setBlock(world, i + 3, j + 36, k + 4, Dungeons.blueGlow, 0);
        this.setBlock(world, i + 3, j + 36, k + 5, Dungeons.blueGlow, 0);
        this.setBlock(world, i + 3, j + 36, k + 6, Dungeons.blueGlow, 0);
        this.setBlock(world, i + 3, j + 36, k + 7, Dungeons.blueGlow, 0);
        this.setBlock(world, i + 3, j + 36, k + 8, Dungeons.blueGlow, 0);
        this.setBlock(world, i + 3, j + 36, k + 9, Dungeons.blueGlow, 0);
        this.setBlock(world, i + 3, j + 36, k + 10, Dungeons.blueGlow, 0);
        this.setBlock(world, i + 3, j + 36, k + 11, Dungeons.blueGlow, 0);
        this.setBlock(world, i + 3, j + 36, k + 41, Dungeons.blueGlow, 0);
        this.setBlock(world, i + 3, j + 36, k + 42, Dungeons.blueGlow, 0);
        this.setBlock(world, i + 3, j + 36, k + 43, Dungeons.blueGlow, 0);
        this.setBlock(world, i + 3, j + 36, k + 44, Dungeons.blueGlow, 0);
        this.setBlock(world, i + 3, j + 36, k + 45, Dungeons.blueGlow, 0);
        this.setBlock(world, i + 3, j + 36, k + 46, Dungeons.blueGlow, 0);
        this.setBlock(world, i + 3, j + 36, k + 47, Dungeons.blueGlow, 0);
        this.setBlock(world, i + 3, j + 36, k + 48, Dungeons.blueGlow, 0);
        this.setBlock(world, i + 3, j + 36, k + 49, Dungeons.blueGlow, 0);
        this.setBlock(world, i + 4, j + 28, k + 3, Dungeons.blueBrick, 0);
        this.setBlock(world, i + 4, j + 28, k + 4, Dungeons.blueBrick, 0);
        this.setBlock(world, i + 4, j + 28, k + 5, Dungeons.blueBrick, 0);
        this.setBlock(world, i + 4, j + 28, k + 6, Dungeons.blueBrick, 0);
        this.setBlock(world, i + 4, j + 28, k + 7, Dungeons.blueBrick, 0);
        this.setBlock(world, i + 4, j + 28, k + 8, Dungeons.blueBrick, 0);
        this.setBlock(world, i + 4, j + 28, k + 9, Dungeons.blueBrick, 0);
        this.setBlock(world, i + 4, j + 28, k + 10, Dungeons.blueBrick, 0);
        this.setBlock(world, i + 4, j + 28, k + 11, Dungeons.blueBrick, 0);
        this.setBlock(world, i + 4, j + 28, k + 14, Dungeons.blueGlow, 0);
        this.setBlock(world, i + 4, j + 28, k + 15, Dungeons.blueGlow, 0);
        this.setBlock(world, i + 4, j + 28, k + 16, Dungeons.blueGlow, 0);
        this.setBlock(world, i + 4, j + 28, k + 17, Dungeons.blueGlow, 0);
        this.setBlock(world, i + 4, j + 28, k + 18, Dungeons.blueGlow, 0);
        this.setBlock(world, i + 4, j + 28, k + 19, Dungeons.blueGlow, 0);
        this.setBlock(world, i + 4, j + 28, k + 20, Dungeons.blueGlow, 0);
        this.setBlock(world, i + 4, j + 28, k + 23, Dungeons.blueGlow, 0);
        this.setBlock(world, i + 4, j + 28, k + 24, Dungeons.blueGlow, 0);
        this.setBlock(world, i + 4, j + 28, k + 25, Dungeons.blueGlow, 0);
        this.setBlock(world, i + 4, j + 28, k + 26, Dungeons.blueGlow, 0);
        this.setBlock(world, i + 4, j + 28, k + 27, Dungeons.blueGlow, 0);
        this.setBlock(world, i + 4, j + 28, k + 28, Dungeons.blueGlow, 0);
        this.setBlock(world, i + 4, j + 28, k + 29, Dungeons.blueGlow, 0);
        this.setBlock(world, i + 4, j + 28, k + 32, Dungeons.blueGlow, 0);
        this.setBlock(world, i + 4, j + 28, k + 33, Dungeons.blueGlow, 0);
        this.setBlock(world, i + 4, j + 28, k + 34, Dungeons.blueGlow, 0);
        this.setBlock(world, i + 4, j + 28, k + 35, Dungeons.blueGlow, 0);
        this.setBlock(world, i + 4, j + 28, k + 36, Dungeons.blueGlow, 0);
        this.setBlock(world, i + 4, j + 28, k + 37, Dungeons.blueGlow, 0);
        this.setBlock(world, i + 4, j + 28, k + 38, Dungeons.blueGlow, 0);
        this.setBlock(world, i + 4, j + 28, k + 41, Dungeons.blueBrick, 0);
        this.setBlock(world, i + 4, j + 28, k + 42, Dungeons.blueBrick, 0);
        this.setBlock(world, i + 4, j + 28, k + 43, Dungeons.blueBrick, 0);
        this.setBlock(world, i + 4, j + 28, k + 44, Dungeons.blueBrick, 0);
        this.setBlock(world, i + 4, j + 28, k + 45, Dungeons.blueBrick, 0);
        this.setBlock(world, i + 4, j + 28, k + 46, Dungeons.blueBrick, 0);
        this.setBlock(world, i + 4, j + 28, k + 47, Dungeons.blueBrick, 0);
        this.setBlock(world, i + 4, j + 28, k + 48, Dungeons.blueBrick, 0);
        this.setBlock(world, i + 4, j + 28, k + 49, Dungeons.blueBrick, 0);
        this.setBlock(world, i + 4, j + 29, k + 3, Dungeons.blueBrick, 0);
        this.setBlock(world, i + 4, j + 29, k + 11, Dungeons.blueBrick, 0);
        this.setBlock(world, i + 4, j + 29, k + 14, Dungeons.blueBrick, 0);
        this.setBlock(world, i + 4, j + 29, k + 15, Dungeons.nightCounter, 0);
        this.setBlock(world, i + 4, j + 29, k + 20, Dungeons.blueBrick, 0);
        this.setBlock(world, i + 4, j + 29, k + 23, Dungeons.blueBrick, 0);
        this.setBlock(world, i + 4, j + 29, k + 24, Dungeons.nightCounter, 0);
        this.setBlock(world, i + 4, j + 29, k + 29, Dungeons.blueBrick, 0);
        this.setBlock(world, i + 4, j + 29, k + 32, Dungeons.blueBrick, 0);
        this.setBlock(world, i + 4, j + 29, k + 33, Dungeons.nightCounter, 0);
        this.setBlock(world, i + 4, j + 29, k + 36, Blocks.enchanting_table, 0);
        this.setBlock(world, i + 4, j + 29, k + 38, Dungeons.blueBrick, 0);
        this.setBlock(world, i + 4, j + 29, k + 41, Dungeons.blueBrick, 0);
        this.setBlock(world, i + 4, j + 29, k + 49, Dungeons.blueBrick, 0);
        this.setBlock(world, i + 4, j + 30, k + 3, Dungeons.blueBrick, 0);
        this.setBlock(world, i + 4, j + 30, k + 11, Dungeons.blueBrick, 0);
        this.setBlock(world, i + 4, j + 30, k + 14, Dungeons.blueBrick, 0);
        this.setBlock(world, i + 4, j + 30, k + 20, Dungeons.blueBrick, 0);
        this.setBlock(world, i + 4, j + 30, k + 23, Dungeons.blueBrick, 0);
        this.setBlock(world, i + 4, j + 30, k + 29, Dungeons.blueBrick, 0);
        this.setBlock(world, i + 4, j + 30, k + 32, Dungeons.blueBrick, 0);
        this.setBlock(world, i + 4, j + 30, k + 38, Dungeons.blueBrick, 0);
        this.setBlock(world, i + 4, j + 30, k + 41, Dungeons.blueBrick, 0);
        this.setBlock(world, i + 4, j + 30, k + 49, Dungeons.blueBrick, 0);
        this.setBlock(world, i + 4, j + 31, k + 3, Dungeons.blueBrick, 0);
        this.setBlock(world, i + 4, j + 31, k + 11, Dungeons.blueBrick, 0);
        this.setBlock(world, i + 4, j + 31, k + 14, Dungeons.blueBrick, 0);
        this.setBlock(world, i + 4, j + 31, k + 20, Dungeons.blueBrick, 0);
        this.setBlock(world, i + 4, j + 31, k + 23, Dungeons.blueBrick, 0);
        this.setBlock(world, i + 4, j + 31, k + 29, Dungeons.blueBrick, 0);
        this.setBlock(world, i + 4, j + 31, k + 32, Dungeons.blueBrick, 0);
        this.setBlock(world, i + 4, j + 31, k + 38, Dungeons.blueBrick, 0);
        this.setBlock(world, i + 4, j + 31, k + 41, Dungeons.blueBrick, 0);
        this.setBlock(world, i + 4, j + 31, k + 49, Dungeons.blueBrick, 0);
        this.setBlock(world, i + 4, j + 32, k + 3, Dungeons.blueBrick, 0);
        this.setBlock(world, i + 4, j + 32, k + 11, Dungeons.blueBrick, 0);
        this.setBlock(world, i + 4, j + 32, k + 14, Dungeons.blueBrick, 0);
        this.setBlock(world, i + 4, j + 32, k + 20, Dungeons.blueBrick, 0);
        this.setBlock(world, i + 4, j + 32, k + 23, Dungeons.blueBrick, 0);
        this.setBlock(world, i + 4, j + 32, k + 29, Dungeons.blueBrick, 0);
        this.setBlock(world, i + 4, j + 32, k + 32, Dungeons.blueBrick, 0);
        this.setBlock(world, i + 4, j + 32, k + 38, Dungeons.blueBrick, 0);
        this.setBlock(world, i + 4, j + 32, k + 41, Dungeons.blueBrick, 0);
        this.setBlock(world, i + 4, j + 32, k + 49, Dungeons.blueBrick, 0);
        this.setBlock(world, i + 4, j + 33, k + 3, Dungeons.blueBrick, 0);
        this.setBlock(world, i + 4, j + 33, k + 11, Dungeons.blueBrick, 0);
        this.setBlock(world, i + 4, j + 33, k + 14, Dungeons.blueBrick, 0);
        this.setBlock(world, i + 4, j + 33, k + 20, Dungeons.blueBrick, 0);
        this.setBlock(world, i + 4, j + 33, k + 23, Dungeons.blueBrick, 0);
        this.setBlock(world, i + 4, j + 33, k + 29, Dungeons.blueBrick, 0);
        this.setBlock(world, i + 4, j + 33, k + 32, Dungeons.blueBrick, 0);
        this.setBlock(world, i + 4, j + 33, k + 38, Dungeons.blueBrick, 0);
        this.setBlock(world, i + 4, j + 33, k + 41, Dungeons.blueBrick, 0);
        this.setBlock(world, i + 4, j + 33, k + 49, Dungeons.blueBrick, 0);
        this.setBlock(world, i + 4, j + 34, k + 3, Dungeons.blueBrick, 0);
        this.setBlock(world, i + 4, j + 34, k + 11, Dungeons.blueBrick, 0);
        this.setBlock(world, i + 4, j + 34, k + 14, Dungeons.blueBrick, 0);
        this.setBlock(world, i + 4, j + 34, k + 20, Dungeons.blueBrick, 0);
        this.setBlock(world, i + 4, j + 34, k + 23, Dungeons.blueBrick, 0);
        this.setBlock(world, i + 4, j + 34, k + 29, Dungeons.blueBrick, 0);
        this.setBlock(world, i + 4, j + 34, k + 32, Dungeons.blueBrick, 0);
        this.setBlock(world, i + 4, j + 34, k + 38, Dungeons.blueBrick, 0);
        this.setBlock(world, i + 4, j + 34, k + 41, Dungeons.blueBrick, 0);
        this.setBlock(world, i + 4, j + 34, k + 49, Dungeons.blueBrick, 0);
        this.setBlock(world, i + 4, j + 35, k + 2, Dungeons.midnightFence, 0);
        this.setBlock(world, i + 4, j + 35, k + 3, Dungeons.blueBrick, 0);
        this.setBlock(world, i + 4, j + 35, k + 11, Dungeons.blueBrick, 0);
        this.setBlock(world, i + 4, j + 35, k + 14, Dungeons.blueGlow, 0);
        this.setBlock(world, i + 4, j + 35, k + 15, Dungeons.blueGlow, 0);
        this.setBlock(world, i + 4, j + 35, k + 16, Dungeons.blueGlow, 0);
        this.setBlock(world, i + 4, j + 35, k + 17, Dungeons.blueGlow, 0);
        this.setBlock(world, i + 4, j + 35, k + 18, Dungeons.blueGlow, 0);
        this.setBlock(world, i + 4, j + 35, k + 19, Dungeons.blueGlow, 0);
        this.setBlock(world, i + 4, j + 35, k + 20, Dungeons.blueGlow, 0);
        this.setBlock(world, i + 4, j + 35, k + 23, Dungeons.blueGlow, 0);
        this.setBlock(world, i + 4, j + 35, k + 24, Dungeons.blueGlow, 0);
        this.setBlock(world, i + 4, j + 35, k + 25, Dungeons.blueGlow, 0);
        this.setBlock(world, i + 4, j + 35, k + 26, Dungeons.blueGlow, 0);
        this.setBlock(world, i + 4, j + 35, k + 27, Dungeons.blueGlow, 0);
        this.setBlock(world, i + 4, j + 35, k + 28, Dungeons.blueGlow, 0);
        this.setBlock(world, i + 4, j + 35, k + 29, Dungeons.blueGlow, 0);
        this.setBlock(world, i + 4, j + 35, k + 32, Dungeons.blueGlow, 0);
        this.setBlock(world, i + 4, j + 35, k + 33, Dungeons.blueGlow, 0);
        this.setBlock(world, i + 4, j + 35, k + 34, Dungeons.blueGlow, 0);
        this.setBlock(world, i + 4, j + 35, k + 35, Dungeons.blueGlow, 0);
        this.setBlock(world, i + 4, j + 35, k + 36, Dungeons.blueGlow, 0);
        this.setBlock(world, i + 4, j + 35, k + 37, Dungeons.blueGlow, 0);
        this.setBlock(world, i + 4, j + 35, k + 38, Dungeons.blueGlow, 0);
        this.setBlock(world, i + 4, j + 35, k + 41, Dungeons.blueBrick, 0);
        this.setBlock(world, i + 4, j + 35, k + 49, Dungeons.blueBrick, 0);
        this.setBlock(world, i + 4, j + 35, k + 50, Dungeons.midnightFence, 0);
        this.setBlock(world, i + 4, j + 36, k + 2, Dungeons.blueGlow, 0);
        this.setBlock(world, i + 4, j + 36, k + 3, Dungeons.blueGlow, 0);
        this.setBlock(world, i + 4, j + 36, k + 4, Dungeons.blueGlow, 0);
        this.setBlock(world, i + 4, j + 36, k + 5, Dungeons.blueGlow, 0);
        this.setBlock(world, i + 4, j + 36, k + 6, Dungeons.blueGlow, 0);
        this.setBlock(world, i + 4, j + 36, k + 7, Dungeons.blueGlow, 0);
        this.setBlock(world, i + 4, j + 36, k + 8, Dungeons.blueGlow, 0);
        this.setBlock(world, i + 4, j + 36, k + 9, Dungeons.blueGlow, 0);
        this.setBlock(world, i + 4, j + 36, k + 10, Dungeons.blueGlow, 0);
        this.setBlock(world, i + 4, j + 36, k + 11, Dungeons.blueGlow, 0);
        this.setBlock(world, i + 4, j + 36, k + 17, Dungeons.greenGlow, 0);
        this.setBlock(world, i + 4, j + 36, k + 26, Dungeons.greenGlow, 0);
        this.setBlock(world, i + 4, j + 36, k + 35, Dungeons.greenGlow, 0);
        this.setBlock(world, i + 4, j + 36, k + 41, Dungeons.blueGlow, 0);
        this.setBlock(world, i + 4, j + 36, k + 42, Dungeons.blueGlow, 0);
        this.setBlock(world, i + 4, j + 36, k + 43, Dungeons.blueGlow, 0);
        this.setBlock(world, i + 4, j + 36, k + 44, Dungeons.blueGlow, 0);
        this.setBlock(world, i + 4, j + 36, k + 45, Dungeons.blueGlow, 0);
        this.setBlock(world, i + 4, j + 36, k + 46, Dungeons.blueGlow, 0);
        this.setBlock(world, i + 4, j + 36, k + 47, Dungeons.blueGlow, 0);
        this.setBlock(world, i + 4, j + 36, k + 48, Dungeons.blueGlow, 0);
        this.setBlock(world, i + 4, j + 36, k + 49, Dungeons.blueGlow, 0);
        this.setBlock(world, i + 4, j + 36, k + 50, Dungeons.blueGlow, 0);
        this.setBlock(world, i + 4, j + 37, k + 2, Dungeons.lightBlueGlow, 0);
        this.setBlock(world, i + 4, j + 37, k + 7, Dungeons.greenGlow, 0);
        this.setBlock(world, i + 4, j + 37, k + 35, Dungeons.greenGlow, 0);
        this.setBlock(world, i + 4, j + 37, k + 45, Dungeons.greenGlow, 0);
        this.setBlock(world, i + 4, j + 37, k + 50, Dungeons.lightBlueGlow, 0);
        this.setBlock(world, i + 4, j + 38, k + 7, Dungeons.greenGlow, 0);
        this.setBlock(world, i + 4, j + 38, k + 45, Dungeons.greenGlow, 0);
        this.setBlock(world, i + 5, j + 28, k + 3, Dungeons.blueBrick, 0);
        this.setBlock(world, i + 5, j + 28, k + 4, Dungeons.blueBrick, 0);
        this.setBlock(world, i + 5, j + 28, k + 5, Dungeons.blueBrick, 0);
        this.setBlock(world, i + 5, j + 28, k + 6, Dungeons.blueBrick, 0);
        this.setBlock(world, i + 5, j + 28, k + 7, Dungeons.blueBrick, 0);
        this.setBlock(world, i + 5, j + 28, k + 8, Dungeons.blueBrick, 0);
        this.setBlock(world, i + 5, j + 28, k + 9, Dungeons.blueBrick, 0);
        this.setBlock(world, i + 5, j + 28, k + 10, Dungeons.blueBrick, 0);
        this.setBlock(world, i + 5, j + 28, k + 11, Dungeons.blueBrick, 0);
        this.setBlock(world, i + 5, j + 28, k + 14, Dungeons.blueGlow, 0);
        this.setBlock(world, i + 5, j + 28, k + 15, Dungeons.blueGlow, 0);
        this.setBlock(world, i + 5, j + 28, k + 16, Dungeons.blueGlow, 0);
        this.setBlock(world, i + 5, j + 28, k + 17, Dungeons.blueGlow, 0);
        this.setBlock(world, i + 5, j + 28, k + 18, Dungeons.blueGlow, 0);
        this.setBlock(world, i + 5, j + 28, k + 19, Dungeons.blueGlow, 0);
        this.setBlock(world, i + 5, j + 28, k + 20, Dungeons.blueGlow, 0);
        this.setBlock(world, i + 5, j + 28, k + 23, Dungeons.blueGlow, 0);
        this.setBlock(world, i + 5, j + 28, k + 24, Dungeons.blueGlow, 0);
        this.setBlock(world, i + 5, j + 28, k + 25, Dungeons.blueGlow, 0);
        this.setBlock(world, i + 5, j + 28, k + 26, Dungeons.blueGlow, 0);
        this.setBlock(world, i + 5, j + 28, k + 27, Dungeons.blueGlow, 0);
        this.setBlock(world, i + 5, j + 28, k + 28, Dungeons.blueGlow, 0);
        this.setBlock(world, i + 5, j + 28, k + 29, Dungeons.blueGlow, 0);
        this.setBlock(world, i + 5, j + 28, k + 32, Dungeons.blueGlow, 0);
        this.setBlock(world, i + 5, j + 28, k + 33, Dungeons.blueGlow, 0);
        this.setBlock(world, i + 5, j + 28, k + 34, Dungeons.blueGlow, 0);
        this.setBlock(world, i + 5, j + 28, k + 35, Dungeons.blueGlow, 0);
        this.setBlock(world, i + 5, j + 28, k + 36, Dungeons.blueGlow, 0);
        this.setBlock(world, i + 5, j + 28, k + 37, Dungeons.blueGlow, 0);
        this.setBlock(world, i + 5, j + 28, k + 38, Dungeons.blueGlow, 0);
        this.setBlock(world, i + 5, j + 28, k + 41, Dungeons.blueBrick, 0);
        this.setBlock(world, i + 5, j + 28, k + 42, Dungeons.blueBrick, 0);
        this.setBlock(world, i + 5, j + 28, k + 43, Dungeons.blueBrick, 0);
        this.setBlock(world, i + 5, j + 28, k + 44, Dungeons.blueBrick, 0);
        this.setBlock(world, i + 5, j + 28, k + 45, Dungeons.blueBrick, 0);
        this.setBlock(world, i + 5, j + 28, k + 46, Dungeons.blueBrick, 0);
        this.setBlock(world, i + 5, j + 28, k + 47, Dungeons.blueBrick, 0);
        this.setBlock(world, i + 5, j + 28, k + 48, Dungeons.blueBrick, 0);
        this.setBlock(world, i + 5, j + 28, k + 49, Dungeons.blueBrick, 0);
        this.setBlock(world, i + 5, j + 29, k + 3, Dungeons.blueBrick, 0);
        this.setBlock(world, i + 5, j + 29, k + 11, Dungeons.blueBrick, 0);
        this.setBlock(world, i + 5, j + 29, k + 14, Dungeons.blueBrick, 0);
        this.setBlock(world, i + 5, j + 29, k + 15, Dungeons.nightCounter, 0);
        Dungeons.spawner(world, i + 5, j + 29, k + 17, 50, 1);
        this.setBlock(world, i + 5, j + 29, k + 20, Dungeons.blueBrick, 0);
        this.setBlock(world, i + 5, j + 29, k + 23, Dungeons.blueBrick, 0);
        this.setBlock(world, i + 5, j + 29, k + 24, Dungeons.nightCounter, 0);
        Dungeons.spawner(world, i + 5, j + 29, k + 26, 50, 1);
        this.setBlock(world, i + 5, j + 29, k + 29, Dungeons.blueBrick, 0);
        this.setBlock(world, i + 5, j + 29, k + 32, Dungeons.blueBrick, 0);
        this.setBlock(world, i + 5, j + 29, k + 33, Dungeons.nightCounter, 0);
        this.setBlock(world, i + 5, j + 29, k + 38, Dungeons.blueBrick, 0);
        this.setBlock(world, i + 5, j + 29, k + 41, Dungeons.blueBrick, 0);
        this.setBlock(world, i + 5, j + 29, k + 49, Dungeons.blueBrick, 0);
        this.setBlock(world, i + 5, j + 30, k + 3, Dungeons.blueBrick, 0);
        this.setBlock(world, i + 5, j + 30, k + 11, Dungeons.blueBrick, 0);
        this.setBlock(world, i + 5, j + 30, k + 14, Dungeons.blueBrick, 0);
        this.setBlock(world, i + 5, j + 30, k + 20, Dungeons.blueBrick, 0);
        this.setBlock(world, i + 5, j + 30, k + 23, Dungeons.blueBrick, 0);
        this.setBlock(world, i + 5, j + 30, k + 29, Dungeons.blueBrick, 0);
        this.setBlock(world, i + 5, j + 30, k + 32, Dungeons.blueBrick, 0);
        this.setBlock(world, i + 5, j + 30, k + 38, Dungeons.blueBrick, 0);
        this.setBlock(world, i + 5, j + 30, k + 41, Dungeons.blueBrick, 0);
        this.setBlock(world, i + 5, j + 30, k + 49, Dungeons.blueBrick, 0);
        this.setBlock(world, i + 5, j + 31, k + 3, Dungeons.blueBrick, 0);
        this.setBlock(world, i + 5, j + 31, k + 11, Dungeons.blueBrick, 0);
        this.setBlock(world, i + 5, j + 31, k + 14, Dungeons.blueBrick, 0);
        this.setBlock(world, i + 5, j + 31, k + 20, Dungeons.blueBrick, 0);
        this.setBlock(world, i + 5, j + 31, k + 23, Dungeons.blueBrick, 0);
        this.setBlock(world, i + 5, j + 31, k + 29, Dungeons.blueBrick, 0);
        this.setBlock(world, i + 5, j + 31, k + 32, Dungeons.blueBrick, 0);
        this.setBlock(world, i + 5, j + 31, k + 38, Dungeons.blueBrick, 0);
        this.setBlock(world, i + 5, j + 31, k + 41, Dungeons.blueBrick, 0);
        this.setBlock(world, i + 5, j + 31, k + 49, Dungeons.blueBrick, 0);
        this.setBlock(world, i + 5, j + 32, k + 3, Dungeons.blueBrick, 0);
        this.setBlock(world, i + 5, j + 32, k + 11, Dungeons.blueBrick, 0);
        this.setBlock(world, i + 5, j + 32, k + 14, Dungeons.blueBrick, 0);
        this.setBlock(world, i + 5, j + 32, k + 20, Dungeons.blueBrick, 0);
        this.setBlock(world, i + 5, j + 32, k + 23, Dungeons.blueBrick, 0);
        this.setBlock(world, i + 5, j + 32, k + 29, Dungeons.blueBrick, 0);
        this.setBlock(world, i + 5, j + 32, k + 32, Dungeons.blueBrick, 0);
        this.setBlock(world, i + 5, j + 32, k + 38, Dungeons.blueBrick, 0);
        this.setBlock(world, i + 5, j + 32, k + 41, Dungeons.blueBrick, 0);
        this.setBlock(world, i + 5, j + 32, k + 49, Dungeons.blueBrick, 0);
        this.setBlock(world, i + 5, j + 33, k + 3, Dungeons.blueBrick, 0);
        this.setBlock(world, i + 5, j + 33, k + 11, Dungeons.blueBrick, 0);
        this.setBlock(world, i + 5, j + 33, k + 14, Dungeons.blueBrick, 0);
        this.setBlock(world, i + 5, j + 33, k + 20, Dungeons.blueBrick, 0);
        this.setBlock(world, i + 5, j + 33, k + 23, Dungeons.blueBrick, 0);
        this.setBlock(world, i + 5, j + 33, k + 29, Dungeons.blueBrick, 0);
        this.setBlock(world, i + 5, j + 33, k + 32, Dungeons.blueBrick, 0);
        this.setBlock(world, i + 5, j + 33, k + 38, Dungeons.blueBrick, 0);
        this.setBlock(world, i + 5, j + 33, k + 41, Dungeons.blueBrick, 0);
        this.setBlock(world, i + 5, j + 33, k + 49, Dungeons.blueBrick, 0);
        this.setBlock(world, i + 5, j + 34, k + 3, Dungeons.blueBrick, 0);
        this.setBlock(world, i + 5, j + 34, k + 11, Dungeons.blueBrick, 0);
        this.setBlock(world, i + 5, j + 34, k + 14, Dungeons.blueBrick, 0);
        this.setBlock(world, i + 5, j + 34, k + 20, Dungeons.blueBrick, 0);
        this.setBlock(world, i + 5, j + 34, k + 23, Dungeons.blueBrick, 0);
        this.setBlock(world, i + 5, j + 34, k + 29, Dungeons.blueBrick, 0);
        this.setBlock(world, i + 5, j + 34, k + 32, Dungeons.blueBrick, 0);
        this.setBlock(world, i + 5, j + 34, k + 38, Dungeons.blueBrick, 0);
        this.setBlock(world, i + 5, j + 34, k + 41, Dungeons.blueBrick, 0);
        this.setBlock(world, i + 5, j + 34, k + 49, Dungeons.blueBrick, 0);
        this.setBlock(world, i + 5, j + 35, k + 3, Dungeons.blueBrick, 0);
        this.setBlock(world, i + 5, j + 35, k + 11, Dungeons.blueBrick, 0);
        this.setBlock(world, i + 5, j + 35, k + 14, Dungeons.blueGlow, 0);
        this.setBlock(world, i + 5, j + 35, k + 15, Dungeons.blueGlow, 0);
        this.setBlock(world, i + 5, j + 35, k + 16, Dungeons.blueGlow, 0);
        this.setBlock(world, i + 5, j + 35, k + 17, Dungeons.blueGlow, 0);
        this.setBlock(world, i + 5, j + 35, k + 18, Dungeons.blueGlow, 0);
        this.setBlock(world, i + 5, j + 35, k + 19, Dungeons.blueGlow, 0);
        this.setBlock(world, i + 5, j + 35, k + 20, Dungeons.blueGlow, 0);
        this.setBlock(world, i + 5, j + 35, k + 23, Dungeons.blueGlow, 0);
        this.setBlock(world, i + 5, j + 35, k + 24, Dungeons.blueGlow, 0);
        this.setBlock(world, i + 5, j + 35, k + 25, Dungeons.blueGlow, 0);
        this.setBlock(world, i + 5, j + 35, k + 26, Dungeons.blueGlow, 0);
        this.setBlock(world, i + 5, j + 35, k + 27, Dungeons.blueGlow, 0);
        this.setBlock(world, i + 5, j + 35, k + 28, Dungeons.blueGlow, 0);
        this.setBlock(world, i + 5, j + 35, k + 29, Dungeons.blueGlow, 0);
        this.setBlock(world, i + 5, j + 35, k + 32, Dungeons.blueGlow, 0);
        this.setBlock(world, i + 5, j + 35, k + 33, Dungeons.blueGlow, 0);
        this.setBlock(world, i + 5, j + 35, k + 34, Dungeons.blueGlow, 0);
        this.setBlock(world, i + 5, j + 35, k + 35, Dungeons.blueGlow, 0);
        this.setBlock(world, i + 5, j + 35, k + 36, Dungeons.blueGlow, 0);
        this.setBlock(world, i + 5, j + 35, k + 37, Dungeons.blueGlow, 0);
        this.setBlock(world, i + 5, j + 35, k + 38, Dungeons.blueGlow, 0);
        this.setBlock(world, i + 5, j + 35, k + 41, Dungeons.blueBrick, 0);
        this.setBlock(world, i + 5, j + 35, k + 49, Dungeons.blueBrick, 0);
        this.setBlock(world, i + 5, j + 36, k + 3, Dungeons.blueGlow, 0);
        this.setBlock(world, i + 5, j + 36, k + 4, Dungeons.blueGlow, 0);
        this.setBlock(world, i + 5, j + 36, k + 5, Dungeons.blueGlow, 0);
        this.setBlock(world, i + 5, j + 36, k + 6, Dungeons.blueGlow, 0);
        this.setBlock(world, i + 5, j + 36, k + 7, Dungeons.blueGlow, 0);
        this.setBlock(world, i + 5, j + 36, k + 8, Dungeons.blueGlow, 0);
        this.setBlock(world, i + 5, j + 36, k + 9, Dungeons.blueGlow, 0);
        this.setBlock(world, i + 5, j + 36, k + 10, Dungeons.blueGlow, 0);
        this.setBlock(world, i + 5, j + 36, k + 11, Dungeons.blueGlow, 0);
        this.setBlock(world, i + 5, j + 36, k + 16, Dungeons.greenGlow, 0);
        this.setBlock(world, i + 5, j + 36, k + 17, Dungeons.greenGlow, 0);
        this.setBlock(world, i + 5, j + 36, k + 18, Dungeons.greenGlow, 0);
        this.setBlock(world, i + 5, j + 36, k + 25, Dungeons.greenGlow, 0);
        this.setBlock(world, i + 5, j + 36, k + 26, Dungeons.greenGlow, 0);
        this.setBlock(world, i + 5, j + 36, k + 27, Dungeons.greenGlow, 0);
        this.setBlock(world, i + 5, j + 36, k + 34, Dungeons.greenGlow, 0);
        this.setBlock(world, i + 5, j + 36, k + 35, Dungeons.greenGlow, 0);
        this.setBlock(world, i + 5, j + 36, k + 36, Dungeons.greenGlow, 0);
        this.setBlock(world, i + 5, j + 36, k + 41, Dungeons.blueGlow, 0);
        this.setBlock(world, i + 5, j + 36, k + 42, Dungeons.blueGlow, 0);
        this.setBlock(world, i + 5, j + 36, k + 43, Dungeons.blueGlow, 0);
        this.setBlock(world, i + 5, j + 36, k + 44, Dungeons.blueGlow, 0);
        this.setBlock(world, i + 5, j + 36, k + 45, Dungeons.blueGlow, 0);
        this.setBlock(world, i + 5, j + 36, k + 46, Dungeons.blueGlow, 0);
        this.setBlock(world, i + 5, j + 36, k + 47, Dungeons.blueGlow, 0);
        this.setBlock(world, i + 5, j + 36, k + 48, Dungeons.blueGlow, 0);
        this.setBlock(world, i + 5, j + 36, k + 49, Dungeons.blueGlow, 0);
        this.setBlock(world, i + 5, j + 37, k + 6, Dungeons.greenGlow, 0);
        this.setBlock(world, i + 5, j + 37, k + 7, Dungeons.greenGlow, 0);
        this.setBlock(world, i + 5, j + 37, k + 8, Dungeons.greenGlow, 0);
        this.setBlock(world, i + 5, j + 37, k + 16, Dungeons.greenGlow, 0);
        this.setBlock(world, i + 5, j + 37, k + 17, Dungeons.greenGlow, 0);
        this.setBlock(world, i + 5, j + 37, k + 18, Dungeons.greenGlow, 0);
        this.setBlock(world, i + 5, j + 37, k + 25, Dungeons.greenGlow, 0);
        this.setBlock(world, i + 5, j + 37, k + 26, Dungeons.greenGlow, 0);
        this.setBlock(world, i + 5, j + 37, k + 27, Dungeons.greenGlow, 0);
        this.setBlock(world, i + 5, j + 37, k + 34, Dungeons.greenGlow, 0);
        this.setBlock(world, i + 5, j + 37, k + 35, Dungeons.greenGlow, 0);
        this.setBlock(world, i + 5, j + 37, k + 36, Dungeons.greenGlow, 0);
        this.setBlock(world, i + 5, j + 37, k + 44, Dungeons.greenGlow, 0);
        this.setBlock(world, i + 5, j + 37, k + 45, Dungeons.greenGlow, 0);
        this.setBlock(world, i + 5, j + 37, k + 46, Dungeons.greenGlow, 0);
        this.setBlock(world, i + 5, j + 38, k + 6, Dungeons.greenGlow, 0);
        this.setBlock(world, i + 5, j + 38, k + 7, Dungeons.greenGlow, 0);
        this.setBlock(world, i + 5, j + 38, k + 8, Dungeons.greenGlow, 0);
        this.setBlock(world, i + 5, j + 38, k + 16, Dungeons.greenGlow, 0);
        this.setBlock(world, i + 5, j + 38, k + 17, Dungeons.greenGlow, 0);
        this.setBlock(world, i + 5, j + 38, k + 18, Dungeons.greenGlow, 0);
        this.setBlock(world, i + 5, j + 38, k + 25, Dungeons.greenGlow, 0);
        this.setBlock(world, i + 5, j + 38, k + 26, Dungeons.greenGlow, 0);
        this.setBlock(world, i + 5, j + 38, k + 27, Dungeons.greenGlow, 0);
        this.setBlock(world, i + 5, j + 38, k + 34, Dungeons.greenGlow, 0);
        this.setBlock(world, i + 5, j + 38, k + 35, Dungeons.greenGlow, 0);
        this.setBlock(world, i + 5, j + 38, k + 36, Dungeons.greenGlow, 0);
        this.setBlock(world, i + 5, j + 38, k + 44, Dungeons.greenGlow, 0);
        this.setBlock(world, i + 5, j + 38, k + 45, Dungeons.greenGlow, 0);
        this.setBlock(world, i + 5, j + 38, k + 46, Dungeons.greenGlow, 0);
        this.setBlock(world, i + 5, j + 39, k + 6, Dungeons.greenGlow, 0);
        this.setBlock(world, i + 5, j + 39, k + 7, Dungeons.greenGlow, 0);
        this.setBlock(world, i + 5, j + 39, k + 8, Dungeons.greenGlow, 0);
        this.setBlock(world, i + 5, j + 39, k + 17, Dungeons.greenGlow, 0);
        this.setBlock(world, i + 5, j + 39, k + 26, Dungeons.greenGlow, 0);
        this.setBlock(world, i + 5, j + 39, k + 35, Dungeons.greenGlow, 0);
        this.setBlock(world, i + 5, j + 39, k + 44, Dungeons.greenGlow, 0);
        this.setBlock(world, i + 5, j + 39, k + 45, Dungeons.greenGlow, 0);
        this.setBlock(world, i + 5, j + 39, k + 46, Dungeons.greenGlow, 0);
        this.setBlock(world, i + 5, j + 40, k + 7, Dungeons.greenGlow, 0);
        this.setBlock(world, i + 5, j + 40, k + 17, Dungeons.greenGlow, 0);
        this.setBlock(world, i + 5, j + 40, k + 26, Dungeons.greenGlow, 0);
        this.setBlock(world, i + 5, j + 40, k + 35, Dungeons.greenGlow, 0);
        this.setBlock(world, i + 5, j + 40, k + 45, Dungeons.greenGlow, 0);
        this.setBlock(world, i + 5, j + 41, k + 7, Dungeons.greenGlow, 0);
        this.setBlock(world, i + 5, j + 41, k + 45, Dungeons.greenGlow, 0);
        this.setBlock(world, i + 6, j + 28, k + 3, Dungeons.blueBrick, 0);
        this.setBlock(world, i + 6, j + 28, k + 4, Dungeons.blueBrick, 0);
        this.setBlock(world, i + 6, j + 28, k + 5, Dungeons.blueBrick, 0);
        this.setBlock(world, i + 6, j + 28, k + 6, Dungeons.blueBrick, 0);
        this.setBlock(world, i + 6, j + 28, k + 7, Dungeons.blueBrick, 0);
        this.setBlock(world, i + 6, j + 28, k + 8, Dungeons.blueBrick, 0);
        this.setBlock(world, i + 6, j + 28, k + 9, Dungeons.blueBrick, 0);
        this.setBlock(world, i + 6, j + 28, k + 10, Dungeons.blueBrick, 0);
        this.setBlock(world, i + 6, j + 28, k + 11, Dungeons.blueBrick, 0);
        this.setBlock(world, i + 6, j + 28, k + 14, Dungeons.blueGlow, 0);
        this.setBlock(world, i + 6, j + 28, k + 15, Dungeons.blueGlow, 0);
        this.setBlock(world, i + 6, j + 28, k + 16, Dungeons.blueGlow, 0);
        this.setBlock(world, i + 6, j + 28, k + 17, Dungeons.blueGlow, 0);
        this.setBlock(world, i + 6, j + 28, k + 18, Dungeons.blueGlow, 0);
        this.setBlock(world, i + 6, j + 28, k + 19, Dungeons.blueGlow, 0);
        this.setBlock(world, i + 6, j + 28, k + 20, Dungeons.blueGlow, 0);
        this.setBlock(world, i + 6, j + 28, k + 23, Dungeons.blueGlow, 0);
        this.setBlock(world, i + 6, j + 28, k + 24, Dungeons.blueGlow, 0);
        this.setBlock(world, i + 6, j + 28, k + 25, Dungeons.blueGlow, 0);
        this.setBlock(world, i + 6, j + 28, k + 26, Dungeons.blueGlow, 0);
        this.setBlock(world, i + 6, j + 28, k + 27, Dungeons.blueGlow, 0);
        this.setBlock(world, i + 6, j + 28, k + 28, Dungeons.blueGlow, 0);
        this.setBlock(world, i + 6, j + 28, k + 29, Dungeons.blueGlow, 0);
        this.setBlock(world, i + 6, j + 28, k + 32, Dungeons.blueGlow, 0);
        this.setBlock(world, i + 6, j + 28, k + 33, Dungeons.blueGlow, 0);
        this.setBlock(world, i + 6, j + 28, k + 34, Dungeons.blueGlow, 0);
        this.setBlock(world, i + 6, j + 28, k + 35, Dungeons.blueGlow, 0);
        this.setBlock(world, i + 6, j + 28, k + 36, Dungeons.blueGlow, 0);
        this.setBlock(world, i + 6, j + 28, k + 37, Dungeons.blueGlow, 0);
        this.setBlock(world, i + 6, j + 28, k + 38, Dungeons.blueGlow, 0);
        this.setBlock(world, i + 6, j + 28, k + 41, Dungeons.blueBrick, 0);
        this.setBlock(world, i + 6, j + 28, k + 42, Dungeons.blueBrick, 0);
        this.setBlock(world, i + 6, j + 28, k + 43, Dungeons.blueBrick, 0);
        this.setBlock(world, i + 6, j + 28, k + 44, Dungeons.blueBrick, 0);
        this.setBlock(world, i + 6, j + 28, k + 45, Dungeons.blueBrick, 0);
        this.setBlock(world, i + 6, j + 28, k + 46, Dungeons.blueBrick, 0);
        this.setBlock(world, i + 6, j + 28, k + 47, Dungeons.blueBrick, 0);
        this.setBlock(world, i + 6, j + 28, k + 48, Dungeons.blueBrick, 0);
        this.setBlock(world, i + 6, j + 28, k + 49, Dungeons.blueBrick, 0);
        this.setBlock(world, i + 6, j + 29, k + 3, Dungeons.blueBrick, 0);
        this.setBlock(world, i + 6, j + 29, k + 11, Dungeons.blueBrick, 0);
        this.setBlock(world, i + 6, j + 29, k + 14, Dungeons.blueBrick, 0);
        this.setBlock(world, i + 6, j + 29, k + 15, Dungeons.nightCounter, 0);
        this.setBlock(world, i + 6, j + 29, k + 20, Dungeons.blueBrick, 0);
        this.setBlock(world, i + 6, j + 29, k + 23, Dungeons.blueBrick, 0);
        this.setBlock(world, i + 6, j + 29, k + 24, Dungeons.nightCounter, 0);
        this.setBlock(world, i + 6, j + 29, k + 29, Dungeons.blueBrick, 0);
        this.setBlock(world, i + 6, j + 29, k + 32, Dungeons.blueBrick, 0);
        this.setBlock(world, i + 6, j + 29, k + 33, Dungeons.nightCounter, 0);
        this.setBlock(world, i + 6, j + 29, k + 38, Dungeons.blueBrick, 0);
        this.setBlock(world, i + 6, j + 29, k + 41, Dungeons.blueBrick, 0);
        this.setBlock(world, i + 6, j + 29, k + 49, Dungeons.blueBrick, 0);
        this.setBlock(world, i + 6, j + 30, k + 3, Dungeons.blueBrick, 0);
        this.setBlock(world, i + 6, j + 30, k + 11, Dungeons.blueBrick, 0);
        this.setBlock(world, i + 6, j + 30, k + 14, Dungeons.blueBrick, 0);
        this.setBlock(world, i + 6, j + 30, k + 20, Dungeons.blueBrick, 0);
        this.setBlock(world, i + 6, j + 30, k + 23, Dungeons.blueBrick, 0);
        this.setBlock(world, i + 6, j + 30, k + 29, Dungeons.blueBrick, 0);
        this.setBlock(world, i + 6, j + 30, k + 32, Dungeons.blueBrick, 0);
        this.setBlock(world, i + 6, j + 30, k + 38, Dungeons.blueBrick, 0);
        this.setBlock(world, i + 6, j + 30, k + 41, Dungeons.blueBrick, 0);
        this.setBlock(world, i + 6, j + 30, k + 49, Dungeons.blueBrick, 0);
        this.setBlock(world, i + 6, j + 31, k + 3, Dungeons.blueBrick, 0);
        this.setBlock(world, i + 6, j + 31, k + 11, Dungeons.blueBrick, 0);
        this.setBlock(world, i + 6, j + 31, k + 14, Dungeons.blueBrick, 0);
        this.setBlock(world, i + 6, j + 31, k + 20, Dungeons.blueBrick, 0);
        this.setBlock(world, i + 6, j + 31, k + 23, Dungeons.blueBrick, 0);
        this.setBlock(world, i + 6, j + 31, k + 29, Dungeons.blueBrick, 0);
        this.setBlock(world, i + 6, j + 31, k + 32, Dungeons.blueBrick, 0);
        this.setBlock(world, i + 6, j + 31, k + 38, Dungeons.blueBrick, 0);
        this.setBlock(world, i + 6, j + 31, k + 41, Dungeons.blueBrick, 0);
        this.setBlock(world, i + 6, j + 31, k + 49, Dungeons.blueBrick, 0);
        this.setBlock(world, i + 6, j + 32, k + 3, Dungeons.blueBrick, 0);
        this.setBlock(world, i + 6, j + 32, k + 11, Dungeons.blueBrick, 0);
        this.setBlock(world, i + 6, j + 32, k + 14, Dungeons.blueBrick, 0);
        this.setBlock(world, i + 6, j + 32, k + 20, Dungeons.blueBrick, 0);
        this.setBlock(world, i + 6, j + 32, k + 23, Dungeons.blueBrick, 0);
        this.setBlock(world, i + 6, j + 32, k + 29, Dungeons.blueBrick, 0);
        this.setBlock(world, i + 6, j + 32, k + 32, Dungeons.blueBrick, 0);
        this.setBlock(world, i + 6, j + 32, k + 38, Dungeons.blueBrick, 0);
        this.setBlock(world, i + 6, j + 32, k + 41, Dungeons.blueBrick, 0);
        this.setBlock(world, i + 6, j + 32, k + 49, Dungeons.blueBrick, 0);
        this.setBlock(world, i + 6, j + 33, k + 3, Dungeons.blueBrick, 0);
        this.setBlock(world, i + 6, j + 33, k + 11, Dungeons.blueBrick, 0);
        this.setBlock(world, i + 6, j + 33, k + 14, Dungeons.blueBrick, 0);
        this.setBlock(world, i + 6, j + 33, k + 20, Dungeons.blueBrick, 0);
        this.setBlock(world, i + 6, j + 33, k + 23, Dungeons.blueBrick, 0);
        this.setBlock(world, i + 6, j + 33, k + 29, Dungeons.blueBrick, 0);
        this.setBlock(world, i + 6, j + 33, k + 32, Dungeons.blueBrick, 0);
        this.setBlock(world, i + 6, j + 33, k + 38, Dungeons.blueBrick, 0);
        this.setBlock(world, i + 6, j + 33, k + 41, Dungeons.blueBrick, 0);
        this.setBlock(world, i + 6, j + 33, k + 49, Dungeons.blueBrick, 0);
        this.setBlock(world, i + 6, j + 34, k + 3, Dungeons.blueBrick, 0);
        this.setBlock(world, i + 6, j + 34, k + 11, Dungeons.blueBrick, 0);
        this.setBlock(world, i + 6, j + 34, k + 14, Dungeons.blueBrick, 0);
        this.setBlock(world, i + 6, j + 34, k + 20, Dungeons.blueBrick, 0);
        this.setBlock(world, i + 6, j + 34, k + 23, Dungeons.blueBrick, 0);
        this.setBlock(world, i + 6, j + 34, k + 29, Dungeons.blueBrick, 0);
        this.setBlock(world, i + 6, j + 34, k + 32, Dungeons.blueBrick, 0);
        this.setBlock(world, i + 6, j + 34, k + 38, Dungeons.blueBrick, 0);
        this.setBlock(world, i + 6, j + 34, k + 41, Dungeons.blueBrick, 0);
        this.setBlock(world, i + 6, j + 34, k + 49, Dungeons.blueBrick, 0);
        this.setBlock(world, i + 6, j + 35, k + 2, Dungeons.midnightFence, 0);
        this.setBlock(world, i + 6, j + 35, k + 3, Dungeons.blueBrick, 0);
        this.setBlock(world, i + 6, j + 35, k + 11, Dungeons.blueBrick, 0);
        this.setBlock(world, i + 6, j + 35, k + 14, Dungeons.blueGlow, 0);
        this.setBlock(world, i + 6, j + 35, k + 15, Dungeons.blueGlow, 0);
        this.setBlock(world, i + 6, j + 35, k + 16, Dungeons.blueGlow, 0);
        this.setBlock(world, i + 6, j + 35, k + 17, Dungeons.blueGlow, 0);
        this.setBlock(world, i + 6, j + 35, k + 18, Dungeons.blueGlow, 0);
        this.setBlock(world, i + 6, j + 35, k + 19, Dungeons.blueGlow, 0);
        this.setBlock(world, i + 6, j + 35, k + 20, Dungeons.blueGlow, 0);
        this.setBlock(world, i + 6, j + 35, k + 23, Dungeons.blueGlow, 0);
        this.setBlock(world, i + 6, j + 35, k + 24, Dungeons.blueGlow, 0);
        this.setBlock(world, i + 6, j + 35, k + 25, Dungeons.blueGlow, 0);
        this.setBlock(world, i + 6, j + 35, k + 26, Dungeons.blueGlow, 0);
        this.setBlock(world, i + 6, j + 35, k + 27, Dungeons.blueGlow, 0);
        this.setBlock(world, i + 6, j + 35, k + 28, Dungeons.blueGlow, 0);
        this.setBlock(world, i + 6, j + 35, k + 29, Dungeons.blueGlow, 0);
        this.setBlock(world, i + 6, j + 35, k + 32, Dungeons.blueGlow, 0);
        this.setBlock(world, i + 6, j + 35, k + 33, Dungeons.blueGlow, 0);
        this.setBlock(world, i + 6, j + 35, k + 34, Dungeons.blueGlow, 0);
        this.setBlock(world, i + 6, j + 35, k + 35, Dungeons.blueGlow, 0);
        this.setBlock(world, i + 6, j + 35, k + 36, Dungeons.blueGlow, 0);
        this.setBlock(world, i + 6, j + 35, k + 37, Dungeons.blueGlow, 0);
        this.setBlock(world, i + 6, j + 35, k + 38, Dungeons.blueGlow, 0);
        this.setBlock(world, i + 6, j + 35, k + 41, Dungeons.blueBrick, 0);
        this.setBlock(world, i + 6, j + 35, k + 49, Dungeons.blueBrick, 0);
        this.setBlock(world, i + 6, j + 35, k + 50, Dungeons.midnightFence, 0);
        this.setBlock(world, i + 6, j + 36, k + 2, Dungeons.blueGlow, 0);
        this.setBlock(world, i + 6, j + 36, k + 3, Dungeons.blueGlow, 0);
        this.setBlock(world, i + 6, j + 36, k + 4, Dungeons.blueGlow, 0);
        this.setBlock(world, i + 6, j + 36, k + 5, Dungeons.blueGlow, 0);
        this.setBlock(world, i + 6, j + 36, k + 6, Dungeons.blueGlow, 0);
        this.setBlock(world, i + 6, j + 36, k + 7, Dungeons.blueGlow, 0);
        this.setBlock(world, i + 6, j + 36, k + 8, Dungeons.blueGlow, 0);
        this.setBlock(world, i + 6, j + 36, k + 9, Dungeons.blueGlow, 0);
        this.setBlock(world, i + 6, j + 36, k + 10, Dungeons.blueGlow, 0);
        this.setBlock(world, i + 6, j + 36, k + 11, Dungeons.blueGlow, 0);
        this.setBlock(world, i + 6, j + 36, k + 15, Dungeons.greenGlow, 0);
        this.setBlock(world, i + 6, j + 36, k + 16, Dungeons.greenGlow, 0);
        this.setBlock(world, i + 6, j + 36, k + 17, Dungeons.greenGlow, 0);
        this.setBlock(world, i + 6, j + 36, k + 18, Dungeons.greenGlow, 0);
        this.setBlock(world, i + 6, j + 36, k + 19, Dungeons.greenGlow, 0);
        this.setBlock(world, i + 6, j + 36, k + 24, Dungeons.greenGlow, 0);
        this.setBlock(world, i + 6, j + 36, k + 25, Dungeons.greenGlow, 0);
        this.setBlock(world, i + 6, j + 36, k + 26, Dungeons.greenGlow, 0);
        this.setBlock(world, i + 6, j + 36, k + 27, Dungeons.greenGlow, 0);
        this.setBlock(world, i + 6, j + 36, k + 28, Dungeons.greenGlow, 0);
        this.setBlock(world, i + 6, j + 36, k + 33, Dungeons.greenGlow, 0);
        this.setBlock(world, i + 6, j + 36, k + 34, Dungeons.greenGlow, 0);
        this.setBlock(world, i + 6, j + 36, k + 35, Dungeons.greenGlow, 0);
        this.setBlock(world, i + 6, j + 36, k + 36, Dungeons.greenGlow, 0);
        this.setBlock(world, i + 6, j + 36, k + 37, Dungeons.greenGlow, 0);
        this.setBlock(world, i + 6, j + 36, k + 41, Dungeons.blueGlow, 0);
        this.setBlock(world, i + 6, j + 36, k + 42, Dungeons.blueGlow, 0);
        this.setBlock(world, i + 6, j + 36, k + 43, Dungeons.blueGlow, 0);
        this.setBlock(world, i + 6, j + 36, k + 44, Dungeons.blueGlow, 0);
        this.setBlock(world, i + 6, j + 36, k + 45, Dungeons.blueGlow, 0);
        this.setBlock(world, i + 6, j + 36, k + 46, Dungeons.blueGlow, 0);
        this.setBlock(world, i + 6, j + 36, k + 47, Dungeons.blueGlow, 0);
        this.setBlock(world, i + 6, j + 36, k + 48, Dungeons.blueGlow, 0);
        this.setBlock(world, i + 6, j + 36, k + 49, Dungeons.blueGlow, 0);
        this.setBlock(world, i + 6, j + 36, k + 50, Dungeons.blueGlow, 0);
        this.setBlock(world, i + 6, j + 37, k + 2, Dungeons.lightBlueGlow, 0);
        this.setBlock(world, i + 6, j + 37, k + 5, Dungeons.greenGlow, 0);
        this.setBlock(world, i + 6, j + 37, k + 6, Dungeons.greenGlow, 0);
        this.setBlock(world, i + 6, j + 37, k + 7, Dungeons.greenGlow, 0);
        this.setBlock(world, i + 6, j + 37, k + 8, Dungeons.greenGlow, 0);
        this.setBlock(world, i + 6, j + 37, k + 9, Dungeons.greenGlow, 0);
        this.setBlock(world, i + 6, j + 37, k + 10, Dungeons.greenGlow, 0);
        this.setBlock(world, i + 6, j + 37, k + 11, Dungeons.greenGlow, 0);
        this.setBlock(world, i + 6, j + 37, k + 12, Dungeons.greenGlow, 0);
        this.setBlock(world, i + 6, j + 37, k + 13, Dungeons.greenGlow, 0);
        this.setBlock(world, i + 6, j + 37, k + 14, Dungeons.greenGlow, 0);
        this.setBlock(world, i + 6, j + 37, k + 15, Dungeons.greenGlow, 0);
        this.setBlock(world, i + 6, j + 37, k + 16, Dungeons.greenGlow, 0);
        this.setBlock(world, i + 6, j + 37, k + 17, Dungeons.greenGlow, 0);
        this.setBlock(world, i + 6, j + 37, k + 18, Dungeons.greenGlow, 0);
        this.setBlock(world, i + 6, j + 37, k + 19, Dungeons.greenGlow, 0);
        this.setBlock(world, i + 6, j + 37, k + 20, Dungeons.greenGlow, 0);
        this.setBlock(world, i + 6, j + 37, k + 21, Dungeons.greenGlow, 0);
        this.setBlock(world, i + 6, j + 37, k + 22, Dungeons.greenGlow, 0);
        this.setBlock(world, i + 6, j + 37, k + 23, Dungeons.greenGlow, 0);
        this.setBlock(world, i + 6, j + 37, k + 24, Dungeons.greenGlow, 0);
        this.setBlock(world, i + 6, j + 37, k + 25, Dungeons.greenGlow, 0);
        this.setBlock(world, i + 6, j + 37, k + 26, Dungeons.greenGlow, 0);
        this.setBlock(world, i + 6, j + 37, k + 27, Dungeons.greenGlow, 0);
        this.setBlock(world, i + 6, j + 37, k + 28, Dungeons.greenGlow, 0);
        this.setBlock(world, i + 6, j + 37, k + 29, Dungeons.greenGlow, 0);
        this.setBlock(world, i + 6, j + 37, k + 30, Dungeons.greenGlow, 0);
        this.setBlock(world, i + 6, j + 37, k + 31, Dungeons.greenGlow, 0);
        this.setBlock(world, i + 6, j + 37, k + 32, Dungeons.greenGlow, 0);
        this.setBlock(world, i + 6, j + 37, k + 33, Dungeons.greenGlow, 0);
        this.setBlock(world, i + 6, j + 37, k + 34, Dungeons.greenGlow, 0);
        this.setBlock(world, i + 6, j + 37, k + 35, Dungeons.greenGlow, 0);
        this.setBlock(world, i + 6, j + 37, k + 36, Dungeons.greenGlow, 0);
        this.setBlock(world, i + 6, j + 37, k + 37, Dungeons.greenGlow, 0);
        this.setBlock(world, i + 6, j + 37, k + 38, Dungeons.greenGlow, 0);
        this.setBlock(world, i + 6, j + 37, k + 39, Dungeons.greenGlow, 0);
        this.setBlock(world, i + 6, j + 37, k + 40, Dungeons.greenGlow, 0);
        this.setBlock(world, i + 6, j + 37, k + 41, Dungeons.greenGlow, 0);
        this.setBlock(world, i + 6, j + 37, k + 42, Dungeons.greenGlow, 0);
        this.setBlock(world, i + 6, j + 37, k + 43, Dungeons.greenGlow, 0);
        this.setBlock(world, i + 6, j + 37, k + 44, Dungeons.greenGlow, 0);
        this.setBlock(world, i + 6, j + 37, k + 45, Dungeons.greenGlow, 0);
        this.setBlock(world, i + 6, j + 37, k + 46, Dungeons.greenGlow, 0);
        this.setBlock(world, i + 6, j + 37, k + 47, Dungeons.greenGlow, 0);
        this.setBlock(world, i + 6, j + 37, k + 50, Dungeons.lightBlueGlow, 0);
        this.setBlock(world, i + 6, j + 38, k + 6, Dungeons.greenGlow, 0);
        this.setBlock(world, i + 6, j + 38, k + 7, Dungeons.greenGlow, 0);
        this.setBlock(world, i + 6, j + 38, k + 8, Dungeons.greenGlow, 0);
        this.setBlock(world, i + 6, j + 38, k + 9, Dungeons.greenGlow, 0);
        this.setBlock(world, i + 6, j + 38, k + 16, Dungeons.greenGlow, 0);
        this.setBlock(world, i + 6, j + 38, k + 17, Dungeons.greenGlow, 0);
        this.setBlock(world, i + 6, j + 38, k + 18, Dungeons.greenGlow, 0);
        this.setBlock(world, i + 6, j + 38, k + 25, Dungeons.greenGlow, 0);
        this.setBlock(world, i + 6, j + 38, k + 26, Dungeons.greenGlow, 0);
        this.setBlock(world, i + 6, j + 38, k + 27, Dungeons.greenGlow, 0);
        this.setBlock(world, i + 6, j + 38, k + 34, Dungeons.greenGlow, 0);
        this.setBlock(world, i + 6, j + 38, k + 35, Dungeons.greenGlow, 0);
        this.setBlock(world, i + 6, j + 38, k + 36, Dungeons.greenGlow, 0);
        this.setBlock(world, i + 6, j + 38, k + 43, Dungeons.greenGlow, 0);
        this.setBlock(world, i + 6, j + 38, k + 44, Dungeons.greenGlow, 0);
        this.setBlock(world, i + 6, j + 38, k + 45, Dungeons.greenGlow, 0);
        this.setBlock(world, i + 6, j + 38, k + 46, Dungeons.greenGlow, 0);
        this.setBlock(world, i + 6, j + 38, k + 47, Dungeons.greenGlow, 0);
        this.setBlock(world, i + 6, j + 39, k + 6, Dungeons.greenGlow, 0);
        this.setBlock(world, i + 6, j + 39, k + 7, Dungeons.greenGlow, 0);
        this.setBlock(world, i + 6, j + 39, k + 8, Dungeons.greenGlow, 0);
        this.setBlock(world, i + 6, j + 39, k + 16, Dungeons.greenGlow, 0);
        this.setBlock(world, i + 6, j + 39, k + 17, Dungeons.greenGlow, 0);
        this.setBlock(world, i + 6, j + 39, k + 18, Dungeons.greenGlow, 0);
        this.setBlock(world, i + 6, j + 39, k + 25, Dungeons.greenGlow, 0);
        this.setBlock(world, i + 6, j + 39, k + 26, Dungeons.greenGlow, 0);
        this.setBlock(world, i + 6, j + 39, k + 27, Dungeons.greenGlow, 0);
        this.setBlock(world, i + 6, j + 39, k + 34, Dungeons.greenGlow, 0);
        this.setBlock(world, i + 6, j + 39, k + 35, Dungeons.greenGlow, 0);
        this.setBlock(world, i + 6, j + 39, k + 36, Dungeons.greenGlow, 0);
        this.setBlock(world, i + 6, j + 39, k + 44, Dungeons.greenGlow, 0);
        this.setBlock(world, i + 6, j + 39, k + 45, Dungeons.greenGlow, 0);
        this.setBlock(world, i + 6, j + 39, k + 46, Dungeons.greenGlow, 0);
        this.setBlock(world, i + 6, j + 40, k + 6, Dungeons.greenGlow, 0);
        this.setBlock(world, i + 6, j + 40, k + 7, Dungeons.greenGlow, 0);
        this.setBlock(world, i + 6, j + 40, k + 8, Dungeons.greenGlow, 0);
        this.setBlock(world, i + 6, j + 40, k + 16, Dungeons.greenGlow, 0);
        this.setBlock(world, i + 6, j + 40, k + 17, Dungeons.greenGlow, 0);
        this.setBlock(world, i + 6, j + 40, k + 18, Dungeons.greenGlow, 0);
        this.setBlock(world, i + 6, j + 40, k + 25, Dungeons.greenGlow, 0);
        this.setBlock(world, i + 6, j + 40, k + 26, Dungeons.greenGlow, 0);
        this.setBlock(world, i + 6, j + 40, k + 27, Dungeons.greenGlow, 0);
        this.setBlock(world, i + 6, j + 40, k + 34, Dungeons.greenGlow, 0);
        this.setBlock(world, i + 6, j + 40, k + 35, Dungeons.greenGlow, 0);
        this.setBlock(world, i + 6, j + 40, k + 36, Dungeons.greenGlow, 0);
        this.setBlock(world, i + 6, j + 40, k + 44, Dungeons.greenGlow, 0);
        this.setBlock(world, i + 6, j + 40, k + 45, Dungeons.greenGlow, 0);
        this.setBlock(world, i + 6, j + 40, k + 46, Dungeons.greenGlow, 0);
        this.setBlock(world, i + 6, j + 41, k + 6, Dungeons.greenGlow, 0);
        this.setBlock(world, i + 6, j + 41, k + 7, Dungeons.greenGlow, 0);
        this.setBlock(world, i + 6, j + 41, k + 8, Dungeons.greenGlow, 0);
        this.setBlock(world, i + 6, j + 41, k + 17, Dungeons.greenGlow, 0);
        this.setBlock(world, i + 6, j + 41, k + 26, Dungeons.greenGlow, 0);
        this.setBlock(world, i + 6, j + 41, k + 35, Dungeons.greenGlow, 0);
        this.setBlock(world, i + 6, j + 41, k + 44, Dungeons.greenGlow, 0);
        this.setBlock(world, i + 6, j + 41, k + 45, Dungeons.greenGlow, 0);
        this.setBlock(world, i + 6, j + 41, k + 46, Dungeons.greenGlow, 0);
        this.setBlock(world, i + 6, j + 42, k + 7, Dungeons.greenGlow, 0);
        this.setBlock(world, i + 6, j + 42, k + 17, Dungeons.greenGlow, 0);
        this.setBlock(world, i + 6, j + 42, k + 26, Dungeons.greenGlow, 0);
        this.setBlock(world, i + 6, j + 42, k + 35, Dungeons.greenGlow, 0);
        this.setBlock(world, i + 6, j + 42, k + 45, Dungeons.greenGlow, 0);
        this.setBlock(world, i + 6, j + 43, k + 7, Dungeons.greenGlow, 0);
        this.setBlock(world, i + 6, j + 43, k + 17, Dungeons.greenGlow, 0);
        this.setBlock(world, i + 6, j + 43, k + 26, Dungeons.greenGlow, 0);
        this.setBlock(world, i + 6, j + 43, k + 35, Dungeons.greenGlow, 0);
        this.setBlock(world, i + 6, j + 43, k + 45, Dungeons.greenGlow, 0);
        this.setBlock(world, i + 6, j + 44, k + 7, Dungeons.greenGlow, 0);
        this.setBlock(world, i + 6, j + 44, k + 17, Dungeons.greenGlow, 0);
        this.setBlock(world, i + 6, j + 44, k + 26, Dungeons.greenGlow, 0);
        this.setBlock(world, i + 6, j + 44, k + 35, Dungeons.greenGlow, 0);
        this.setBlock(world, i + 6, j + 44, k + 45, Dungeons.greenGlow, 0);
        this.setBlock(world, i + 6, j + 45, k + 7, Dungeons.greenGlow, 0);
        this.setBlock(world, i + 6, j + 45, k + 45, Dungeons.greenGlow, 0);
        this.setBlock(world, i + 7, j + 28, k + 3, Dungeons.blueBrick, 0);
        this.setBlock(world, i + 7, j + 28, k + 4, Dungeons.blueBrick, 0);
        this.setBlock(world, i + 7, j + 28, k + 5, Dungeons.blueBrick, 0);
        this.setBlock(world, i + 7, j + 28, k + 6, Dungeons.blueBrick, 0);
        this.setBlock(world, i + 7, j + 28, k + 7, Dungeons.blueBrick, 0);
        this.setBlock(world, i + 7, j + 28, k + 8, Dungeons.blueBrick, 0);
        this.setBlock(world, i + 7, j + 28, k + 9, Dungeons.blueBrick, 0);
        this.setBlock(world, i + 7, j + 28, k + 10, Dungeons.blueBrick, 0);
        this.setBlock(world, i + 7, j + 28, k + 11, Dungeons.blueBrick, 0);
        this.setBlock(world, i + 7, j + 28, k + 14, Dungeons.blueGlow, 0);
        this.setBlock(world, i + 7, j + 28, k + 15, Dungeons.blueGlow, 0);
        this.setBlock(world, i + 7, j + 28, k + 16, Dungeons.blueGlow, 0);
        this.setBlock(world, i + 7, j + 28, k + 17, Dungeons.blueGlow, 0);
        this.setBlock(world, i + 7, j + 28, k + 18, Dungeons.blueGlow, 0);
        this.setBlock(world, i + 7, j + 28, k + 19, Dungeons.blueGlow, 0);
        this.setBlock(world, i + 7, j + 28, k + 20, Dungeons.blueGlow, 0);
        this.setBlock(world, i + 7, j + 28, k + 23, Dungeons.blueGlow, 0);
        this.setBlock(world, i + 7, j + 28, k + 24, Dungeons.blueGlow, 0);
        this.setBlock(world, i + 7, j + 28, k + 25, Dungeons.blueGlow, 0);
        this.setBlock(world, i + 7, j + 28, k + 26, Dungeons.blueGlow, 0);
        this.setBlock(world, i + 7, j + 28, k + 27, Dungeons.blueGlow, 0);
        this.setBlock(world, i + 7, j + 28, k + 28, Dungeons.blueGlow, 0);
        this.setBlock(world, i + 7, j + 28, k + 29, Dungeons.blueGlow, 0);
        this.setBlock(world, i + 7, j + 28, k + 32, Dungeons.blueGlow, 0);
        this.setBlock(world, i + 7, j + 28, k + 33, Dungeons.blueGlow, 0);
        this.setBlock(world, i + 7, j + 28, k + 34, Dungeons.blueGlow, 0);
        this.setBlock(world, i + 7, j + 28, k + 35, Dungeons.blueGlow, 0);
        this.setBlock(world, i + 7, j + 28, k + 36, Dungeons.blueGlow, 0);
        this.setBlock(world, i + 7, j + 28, k + 37, Dungeons.blueGlow, 0);
        this.setBlock(world, i + 7, j + 28, k + 38, Dungeons.blueGlow, 0);
        this.setBlock(world, i + 7, j + 28, k + 41, Dungeons.blueBrick, 0);
        this.setBlock(world, i + 7, j + 28, k + 42, Dungeons.blueBrick, 0);
        this.setBlock(world, i + 7, j + 28, k + 43, Dungeons.blueBrick, 0);
        this.setBlock(world, i + 7, j + 28, k + 44, Dungeons.blueBrick, 0);
        this.setBlock(world, i + 7, j + 28, k + 45, Dungeons.blueBrick, 0);
        this.setBlock(world, i + 7, j + 28, k + 46, Dungeons.blueBrick, 0);
        this.setBlock(world, i + 7, j + 28, k + 47, Dungeons.blueBrick, 0);
        this.setBlock(world, i + 7, j + 28, k + 48, Dungeons.blueBrick, 0);
        this.setBlock(world, i + 7, j + 28, k + 49, Dungeons.blueBrick, 0);
        this.setBlock(world, i + 7, j + 29, k + 3, Dungeons.blueBrick, 0);
        this.setBlock(world, i + 7, j + 29, k + 11, Dungeons.blueBrick, 0);
        this.setBlock(world, i + 7, j + 29, k + 14, Dungeons.blueBrick, 0);
        this.setBlock(world, i + 7, j + 29, k + 15, Dungeons.nightCounter, 0);
        this.setBlock(world, i + 7, j + 29, k + 19, Blocks.furnace, 2);
        this.setBlock(world, i + 7, j + 29, k + 20, Dungeons.blueBrick, 0);
        this.setBlock(world, i + 7, j + 29, k + 23, Dungeons.blueBrick, 0);
        this.setBlock(world, i + 7, j + 29, k + 24, Dungeons.nightCounter, 0);
        this.setBlock(world, i + 7, j + 29, k + 28, Blocks.furnace, 2);
        this.setBlock(world, i + 7, j + 29, k + 29, Dungeons.blueBrick, 0);
        this.setBlock(world, i + 7, j + 29, k + 32, Dungeons.blueBrick, 0);
        this.setBlock(world, i + 7, j + 29, k + 33, Dungeons.nightCounter, 0);
        Dungeons.spawner(world, i + 7, j + 29, k + 36, 50, 1);
        this.setBlock(world, i + 7, j + 29, k + 38, Dungeons.blueBrick, 0);
        this.setBlock(world, i + 7, j + 29, k + 41, Dungeons.blueBrick, 0);
        this.setBlock(world, i + 7, j + 29, k + 49, Dungeons.blueBrick, 0);
        this.setBlock(world, i + 7, j + 30, k + 3, Dungeons.blueBrick, 0);
        this.setBlock(world, i + 7, j + 30, k + 11, Dungeons.blueBrick, 0);
        this.setBlock(world, i + 7, j + 30, k + 14, Dungeons.blueBrick, 0);
        this.setBlock(world, i + 7, j + 30, k + 20, Dungeons.blueBrick, 0);
        this.setBlock(world, i + 7, j + 30, k + 23, Dungeons.blueBrick, 0);
        this.setBlock(world, i + 7, j + 30, k + 29, Dungeons.blueBrick, 0);
        this.setBlock(world, i + 7, j + 30, k + 32, Dungeons.blueBrick, 0);
        this.setBlock(world, i + 7, j + 30, k + 38, Dungeons.blueBrick, 0);
        this.setBlock(world, i + 7, j + 30, k + 41, Dungeons.blueBrick, 0);
        this.setBlock(world, i + 7, j + 30, k + 49, Dungeons.blueBrick, 0);
        this.setBlock(world, i + 7, j + 31, k + 3, Dungeons.blueBrick, 0);
        this.setBlock(world, i + 7, j + 31, k + 11, Dungeons.blueBrick, 0);
        this.setBlock(world, i + 7, j + 31, k + 14, Dungeons.blueBrick, 0);
        this.setBlock(world, i + 7, j + 31, k + 20, Dungeons.blueBrick, 0);
        this.setBlock(world, i + 7, j + 31, k + 23, Dungeons.blueBrick, 0);
        this.setBlock(world, i + 7, j + 31, k + 29, Dungeons.blueBrick, 0);
        this.setBlock(world, i + 7, j + 31, k + 32, Dungeons.blueBrick, 0);
        this.setBlock(world, i + 7, j + 31, k + 38, Dungeons.blueBrick, 0);
        this.setBlock(world, i + 7, j + 31, k + 41, Dungeons.blueBrick, 0);
        this.setBlock(world, i + 7, j + 31, k + 49, Dungeons.blueBrick, 0);
        this.setBlock(world, i + 7, j + 32, k + 3, Dungeons.blueBrick, 0);
        this.setBlock(world, i + 7, j + 32, k + 11, Dungeons.blueBrick, 0);
        this.setBlock(world, i + 7, j + 32, k + 14, Dungeons.blueBrick, 0);
        this.setBlock(world, i + 7, j + 32, k + 20, Dungeons.blueBrick, 0);
        this.setBlock(world, i + 7, j + 32, k + 23, Dungeons.blueBrick, 0);
        this.setBlock(world, i + 7, j + 32, k + 29, Dungeons.blueBrick, 0);
        this.setBlock(world, i + 7, j + 32, k + 32, Dungeons.blueBrick, 0);
        this.setBlock(world, i + 7, j + 32, k + 38, Dungeons.blueBrick, 0);
        this.setBlock(world, i + 7, j + 32, k + 41, Dungeons.blueBrick, 0);
        this.setBlock(world, i + 7, j + 32, k + 49, Dungeons.blueBrick, 0);
        this.setBlock(world, i + 7, j + 33, k + 3, Dungeons.blueBrick, 0);
        this.setBlock(world, i + 7, j + 33, k + 11, Dungeons.blueBrick, 0);
        this.setBlock(world, i + 7, j + 33, k + 14, Dungeons.blueBrick, 0);
        this.setBlock(world, i + 7, j + 33, k + 20, Dungeons.blueBrick, 0);
        this.setBlock(world, i + 7, j + 33, k + 23, Dungeons.blueBrick, 0);
        this.setBlock(world, i + 7, j + 33, k + 29, Dungeons.blueBrick, 0);
        this.setBlock(world, i + 7, j + 33, k + 32, Dungeons.blueBrick, 0);
        this.setBlock(world, i + 7, j + 33, k + 38, Dungeons.blueBrick, 0);
        this.setBlock(world, i + 7, j + 33, k + 41, Dungeons.blueBrick, 0);
        this.setBlock(world, i + 7, j + 33, k + 49, Dungeons.blueBrick, 0);
        this.setBlock(world, i + 7, j + 34, k + 3, Dungeons.blueBrick, 0);
        this.setBlock(world, i + 7, j + 34, k + 11, Dungeons.blueBrick, 0);
        this.setBlock(world, i + 7, j + 34, k + 14, Dungeons.blueBrick, 0);
        this.setBlock(world, i + 7, j + 34, k + 20, Dungeons.blueBrick, 0);
