

package com.gibby.dungeon.gen;

import net.minecraft.world.gen.feature.*;
import cpw.mods.fml.common.*;
import java.util.*;
import net.minecraft.world.chunk.*;
import net.minecraft.block.*;
import net.minecraft.world.*;
import net.minecraft.init.*;
import com.gibby.dungeon.*;

public class WorldGenDesertTemple2 extends WorldGenerator implements IWorldGenerator
{
    public void generate(final Random random, final int chunkX, final int chunkZ, final World world, final IChunkProvider chunkGenerator, final IChunkProvider chunkProvider) {
    }

    public void setBlock(final World world, final int x, final int y, final int z, final Block block, final int metadata) {
        final Block b1 = world.getBlock(x, y, z);
        if (b1.isAir((IBlockAccess)world, x, y, z) || b1.isLeaves((IBlockAccess)world, x, y, z)) {
            world.setBlock(x, y, z, block, metadata, 2);
        }
    }

    public boolean generate(final World world, final Random rand, final int i, final int j, final int k) {
        if (world.getBlock(i, j, k) != Blocks.sand || world.getBlock(i + 30, j, k + 30) != Blocks.sand || world.getBlock(i, j + 1, k) != Blocks.air || world.getBlock(i + 30, j + 1, k + 30) != Blocks.air) {
            return false;
        }
        this.setBlock(world, i, j, k, Blocks.sandstone, 0);
        this.setBlock(world, i, j, k + 1, Blocks.sandstone, 0);
        this.setBlock(world, i, j, k + 2, Blocks.sandstone, 0);
        this.setBlock(world, i, j, k + 3, Blocks.sandstone, 0);
        this.setBlock(world, i, j, k + 4, Blocks.sandstone, 0);
        this.setBlock(world, i, j, k + 5, Blocks.sandstone, 0);
        this.setBlock(world, i, j, k + 6, Blocks.sandstone, 0);
        this.setBlock(world, i, j, k + 7, Blocks.sandstone, 0);
        this.setBlock(world, i, j, k + 8, Blocks.sandstone, 0);
        this.setBlock(world, i, j, k + 9, Blocks.sandstone, 0);
        this.setBlock(world, i, j, k + 10, Blocks.sandstone, 0);
        this.setBlock(world, i, j, k + 11, Blocks.sandstone, 0);
        this.setBlock(world, i, j, k + 12, Blocks.sandstone, 0);
        this.setBlock(world, i, j, k + 13, Blocks.sandstone, 0);
        this.setBlock(world, i, j, k + 14, Blocks.sandstone, 0);
        this.setBlock(world, i, j, k + 15, Blocks.sandstone, 0);
        this.setBlock(world, i, j, k + 16, Blocks.sandstone, 0);
        this.setBlock(world, i, j, k + 17, Blocks.sandstone, 0);
        this.setBlock(world, i, j, k + 18, Blocks.sandstone, 0);
        this.setBlock(world, i, j, k + 19, Blocks.sandstone, 0);
        this.setBlock(world, i, j, k + 20, Blocks.sandstone, 0);
        this.setBlock(world, i, j, k + 21, Blocks.sandstone, 0);
        this.setBlock(world, i, j, k + 22, Blocks.sandstone, 0);
        this.setBlock(world, i, j, k + 23, Blocks.sandstone, 0);
        this.setBlock(world, i, j, k + 24, Blocks.sandstone, 0);
        this.setBlock(world, i, j, k + 25, Blocks.sandstone, 0);
        this.setBlock(world, i, j, k + 26, Blocks.sandstone, 0);
        this.setBlock(world, i, j, k + 27, Blocks.sandstone, 0);
        this.setBlock(world, i, j, k + 28, Blocks.sandstone, 0);
        this.setBlock(world, i, j, k + 29, Blocks.sandstone, 0);
        this.setBlock(world, i, j, k + 30, Blocks.sandstone, 0);
        this.setBlock(world, i, j, k + 31, Blocks.sandstone, 0);
        this.setBlock(world, i + 1, j, k, Blocks.sandstone, 0);
        this.setBlock(world, i + 1, j, k + 1, Blocks.sandstone, 0);
        this.setBlock(world, i + 1, j, k + 2, Blocks.sandstone, 0);
        this.setBlock(world, i + 1, j, k + 3, Blocks.sandstone, 0);
        this.setBlock(world, i + 1, j, k + 4, Blocks.sandstone, 0);
        this.setBlock(world, i + 1, j, k + 5, Blocks.sandstone, 0);
        this.setBlock(world, i + 1, j, k + 6, Blocks.sandstone, 0);
        this.setBlock(world, i + 1, j, k + 7, Blocks.sandstone, 0);
        this.setBlock(world, i + 1, j, k + 8, Blocks.sandstone, 0);
        this.setBlock(world, i + 1, j, k + 9, Blocks.sandstone, 0);
        this.setBlock(world, i + 1, j, k + 10, Blocks.sandstone, 0);
        this.setBlock(world, i + 1, j, k + 11, Blocks.sandstone, 0);
        this.setBlock(world, i + 1, j, k + 12, Blocks.sandstone, 0);
        this.setBlock(world, i + 1, j, k + 13, Blocks.sandstone, 0);
        this.setBlock(world, i + 1, j, k + 14, Blocks.sandstone, 0);
        this.setBlock(world, i + 1, j, k + 15, Blocks.sandstone, 0);
        this.setBlock(world, i + 1, j, k + 16, Blocks.sandstone, 0);
        this.setBlock(world, i + 1, j, k + 17, Blocks.sandstone, 0);
        this.setBlock(world, i + 1, j, k + 18, Blocks.sandstone, 0);
        this.setBlock(world, i + 1, j, k + 19, Blocks.sandstone, 0);
        this.setBlock(world, i + 1, j, k + 20, Blocks.sandstone, 0);
        this.setBlock(world, i + 1, j, k + 21, Blocks.sandstone, 0);
        this.setBlock(world, i + 1, j, k + 22, Blocks.sandstone, 0);
        this.setBlock(world, i + 1, j, k + 23, Blocks.sandstone, 0);
        this.setBlock(world, i + 1, j, k + 24, Blocks.sandstone, 0);
        this.setBlock(world, i + 1, j, k + 25, Blocks.sandstone, 0);
        this.setBlock(world, i + 1, j, k + 26, Blocks.sandstone, 0);
        this.setBlock(world, i + 1, j, k + 27, Blocks.sandstone, 0);
        this.setBlock(world, i + 1, j, k + 28, Blocks.sandstone, 0);
        this.setBlock(world, i + 1, j, k + 29, Blocks.sandstone, 0);
        this.setBlock(world, i + 1, j, k + 30, Blocks.sandstone, 0);
        this.setBlock(world, i + 1, j, k + 31, Blocks.sandstone, 0);
        this.setBlock(world, i + 2, j, k, Blocks.sandstone, 0);
        this.setBlock(world, i + 2, j, k + 1, Blocks.sandstone, 0);
        this.setBlock(world, i + 2, j, k + 2, Blocks.sandstone, 0);
        this.setBlock(world, i + 2, j, k + 3, Blocks.sandstone, 0);
        this.setBlock(world, i + 2, j, k + 4, Blocks.sandstone, 0);
        this.setBlock(world, i + 2, j, k + 5, Blocks.sandstone, 0);
        this.setBlock(world, i + 2, j, k + 6, Blocks.sandstone, 0);
        this.setBlock(world, i + 2, j, k + 7, Blocks.sandstone, 0);
        this.setBlock(world, i + 2, j, k + 8, Blocks.sandstone, 0);
        this.setBlock(world, i + 2, j, k + 9, Blocks.sandstone, 0);
        this.setBlock(world, i + 2, j, k + 10, Blocks.sandstone, 0);
        this.setBlock(world, i + 2, j, k + 11, Blocks.sandstone, 0);
        this.setBlock(world, i + 2, j, k + 12, Blocks.sandstone, 0);
        this.setBlock(world, i + 2, j, k + 13, Blocks.sandstone, 0);
        this.setBlock(world, i + 2, j, k + 14, Blocks.sandstone, 0);
        this.setBlock(world, i + 2, j, k + 15, Blocks.dirt, 0);
        this.setBlock(world, i + 2, j, k + 16, Blocks.sandstone, 0);
        this.setBlock(world, i + 2, j, k + 17, Blocks.sandstone, 0);
        this.setBlock(world, i + 2, j, k + 18, Blocks.sandstone, 0);
        this.setBlock(world, i + 2, j, k + 19, Blocks.sandstone, 0);
        this.setBlock(world, i + 2, j, k + 20, Blocks.sandstone, 0);
        this.setBlock(world, i + 2, j, k + 21, Blocks.sandstone, 0);
        this.setBlock(world, i + 2, j, k + 22, Blocks.sandstone, 0);
        this.setBlock(world, i + 2, j, k + 23, Blocks.sandstone, 0);
        this.setBlock(world, i + 2, j, k + 24, Blocks.sandstone, 0);
        this.setBlock(world, i + 2, j, k + 25, Blocks.sandstone, 0);
        this.setBlock(world, i + 2, j, k + 26, Blocks.sandstone, 0);
        this.setBlock(world, i + 2, j, k + 27, Blocks.sandstone, 0);
        this.setBlock(world, i + 2, j, k + 28, Blocks.sandstone, 0);
        this.setBlock(world, i + 2, j, k + 29, Blocks.sandstone, 0);
        this.setBlock(world, i + 2, j, k + 30, Blocks.sandstone, 0);
        this.setBlock(world, i + 2, j, k + 31, Blocks.sandstone, 0);
        this.setBlock(world, i + 2, j + 1, k + 15, Blocks.wool, 4);
        this.setBlock(world, i + 2, j + 3, k + 13, Blocks.wool, 4);
        this.setBlock(world, i + 2, j + 3, k + 17, Blocks.wool, 4);
        this.setBlock(world, i + 2, j + 5, k + 15, Blocks.wool, 4);
        this.setBlock(world, i + 3, j, k, Blocks.sandstone, 0);
        this.setBlock(world, i + 3, j, k + 1, Blocks.sandstone, 0);
        this.setBlock(world, i + 3, j, k + 2, Blocks.sandstone, 0);
        this.setBlock(world, i + 3, j, k + 3, Blocks.sandstone, 0);
        this.setBlock(world, i + 3, j, k + 4, Blocks.sandstone, 0);
        this.setBlock(world, i + 3, j, k + 5, Blocks.sandstone, 0);
        this.setBlock(world, i + 3, j, k + 6, Blocks.sandstone, 0);
        this.setBlock(world, i + 3, j, k + 7, Blocks.sandstone, 0);
        this.setBlock(world, i + 3, j, k + 8, Blocks.sandstone, 0);
        this.setBlock(world, i + 3, j, k + 9, Blocks.sandstone, 0);
        this.setBlock(world, i + 3, j, k + 10, Blocks.sandstone, 0);
        this.setBlock(world, i + 3, j, k + 11, Blocks.sandstone, 0);
        this.setBlock(world, i + 3, j, k + 12, Blocks.sandstone, 0);
        this.setBlock(world, i + 3, j, k + 13, Blocks.sandstone, 0);
        this.setBlock(world, i + 3, j, k + 14, Blocks.sandstone, 0);
        this.setBlock(world, i + 3, j, k + 15, Blocks.sandstone, 0);
        this.setBlock(world, i + 3, j, k + 16, Blocks.sandstone, 0);
        this.setBlock(world, i + 3, j, k + 17, Blocks.sandstone, 0);
        this.setBlock(world, i + 3, j, k + 18, Blocks.sandstone, 0);
        this.setBlock(world, i + 3, j, k + 19, Blocks.sandstone, 0);
        this.setBlock(world, i + 3, j, k + 20, Blocks.sandstone, 0);
        this.setBlock(world, i + 3, j, k + 21, Blocks.sandstone, 0);
        this.setBlock(world, i + 3, j, k + 22, Blocks.sandstone, 0);
        this.setBlock(world, i + 3, j, k + 23, Blocks.sandstone, 0);
        this.setBlock(world, i + 3, j, k + 24, Blocks.sandstone, 0);
        this.setBlock(world, i + 3, j, k + 25, Blocks.sandstone, 0);
        this.setBlock(world, i + 3, j, k + 26, Blocks.sandstone, 0);
        this.setBlock(world, i + 3, j, k + 27, Blocks.sandstone, 0);
        this.setBlock(world, i + 3, j, k + 28, Blocks.sandstone, 0);
        this.setBlock(world, i + 3, j, k + 29, Blocks.sandstone, 0);
        this.setBlock(world, i + 3, j, k + 30, Blocks.sandstone, 0);
        this.setBlock(world, i + 3, j, k + 31, Blocks.sandstone, 0);
        this.setBlock(world, i + 3, j + 1, k + 3, Blocks.sandstone, 0);
        this.setBlock(world, i + 3, j + 1, k + 4, Blocks.sandstone, 0);
        this.setBlock(world, i + 3, j + 1, k + 5, Blocks.sandstone, 0);
        this.setBlock(world, i + 3, j + 1, k + 6, Blocks.sandstone, 0);
        this.setBlock(world, i + 3, j + 1, k + 7, Blocks.sandstone, 0);
        this.setBlock(world, i + 3, j + 1, k + 8, Blocks.sandstone, 0);
        this.setBlock(world, i + 3, j + 1, k + 9, Blocks.sandstone, 0);
        this.setBlock(world, i + 3, j + 1, k + 10, Blocks.sandstone, 0);
        this.setBlock(world, i + 3, j + 1, k + 11, Blocks.sandstone, 0);
        this.setBlock(world, i + 3, j + 1, k + 12, Blocks.sandstone, 0);
        this.setBlock(world, i + 3, j + 1, k + 13, Blocks.sandstone, 0);
        this.setBlock(world, i + 3, j + 1, k + 14, Blocks.sandstone, 0);
        this.setBlock(world, i + 3, j + 1, k + 15, Blocks.sandstone, 0);
        this.setBlock(world, i + 3, j + 1, k + 16, Blocks.sandstone, 0);
        this.setBlock(world, i + 3, j + 1, k + 17, Blocks.sandstone, 0);
        this.setBlock(world, i + 3, j + 1, k + 18, Blocks.sandstone, 0);
        this.setBlock(world, i + 3, j + 1, k + 19, Blocks.sandstone, 0);
        this.setBlock(world, i + 3, j + 1, k + 20, Blocks.sandstone, 0);
        this.setBlock(world, i + 3, j + 1, k + 21, Blocks.sandstone, 0);
        this.setBlock(world, i + 3, j + 1, k + 22, Blocks.sandstone, 0);
        this.setBlock(world, i + 3, j + 1, k + 23, Blocks.sandstone, 0);
        this.setBlock(world, i + 3, j + 1, k + 24, Blocks.sandstone, 0);
        this.setBlock(world, i + 3, j + 1, k + 25, Blocks.sandstone, 0);
        this.setBlock(world, i + 3, j + 1, k + 26, Blocks.sandstone, 0);
        this.setBlock(world, i + 3, j + 1, k + 27, Blocks.sandstone, 0);
        this.setBlock(world, i + 3, j + 2, k + 3, Blocks.sandstone, 0);
        this.setBlock(world, i + 3, j + 2, k + 4, Blocks.sandstone, 0);
        this.setBlock(world, i + 3, j + 2, k + 5, Blocks.sandstone, 0);
        this.setBlock(world, i + 3, j + 2, k + 6, Blocks.sandstone, 0);
        this.setBlock(world, i + 3, j + 2, k + 7, Blocks.sandstone, 0);
        this.setBlock(world, i + 3, j + 2, k + 8, Blocks.sandstone, 0);
        this.setBlock(world, i + 3, j + 2, k + 9, Blocks.sandstone, 0);
        this.setBlock(world, i + 3, j + 2, k + 10, Blocks.sandstone, 0);
        this.setBlock(world, i + 3, j + 2, k + 11, Blocks.sandstone, 0);
        this.setBlock(world, i + 3, j + 2, k + 12, Blocks.sandstone, 0);
        this.setBlock(world, i + 3, j + 2, k + 13, Blocks.sandstone, 0);
        this.setBlock(world, i + 3, j + 2, k + 14, Blocks.wool, 4);
        this.setBlock(world, i + 3, j + 2, k + 16, Blocks.wool, 4);
        this.setBlock(world, i + 3, j + 2, k + 17, Blocks.sandstone, 0);
        this.setBlock(world, i + 3, j + 2, k + 18, Blocks.sandstone, 0);
        this.setBlock(world, i + 3, j + 2, k + 19, Blocks.sandstone, 0);
        this.setBlock(world, i + 3, j + 2, k + 20, Blocks.sandstone, 0);
        this.setBlock(world, i + 3, j + 2, k + 21, Blocks.sandstone, 0);
        this.setBlock(world, i + 3, j + 2, k + 22, Blocks.sandstone, 0);
        this.setBlock(world, i + 3, j + 2, k + 23, Blocks.sandstone, 0);
        this.setBlock(world, i + 3, j + 2, k + 24, Blocks.sandstone, 0);
        this.setBlock(world, i + 3, j + 2, k + 25, Blocks.sandstone, 0);
        this.setBlock(world, i + 3, j + 2, k + 26, Blocks.sandstone, 0);
        this.setBlock(world, i + 3, j + 2, k + 27, Blocks.sandstone, 0);
        this.setBlock(world, i + 3, j + 3, k + 3, Blocks.stone_slab, 1);
        this.setBlock(world, i + 3, j + 3, k + 4, Blocks.stone_slab, 1);
        this.setBlock(world, i + 3, j + 3, k + 5, Blocks.stone_slab, 1);
        this.setBlock(world, i + 3, j + 3, k + 6, Blocks.stone_slab, 1);
        this.setBlock(world, i + 3, j + 3, k + 7, Blocks.sandstone, 0);
        this.setBlock(world, i + 3, j + 3, k + 8, Blocks.sandstone, 0);
        this.setBlock(world, i + 3, j + 3, k + 9, Blocks.sandstone, 0);
        this.setBlock(world, i + 3, j + 3, k + 10, Blocks.sandstone, 0);
        this.setBlock(world, i + 3, j + 3, k + 11, Blocks.sandstone, 0);
        this.setBlock(world, i + 3, j + 3, k + 12, Blocks.sandstone, 0);
        this.setBlock(world, i + 3, j + 3, k + 13, Blocks.sandstone, 0);
        this.setBlock(world, i + 3, j + 3, k + 17, Blocks.sandstone, 0);
        this.setBlock(world, i + 3, j + 3, k + 18, Blocks.sandstone, 0);
        this.setBlock(world, i + 3, j + 3, k + 19, Blocks.sandstone, 0);
        this.setBlock(world, i + 3, j + 3, k + 20, Blocks.sandstone, 0);
        this.setBlock(world, i + 3, j + 3, k + 21, Blocks.sandstone, 0);
        this.setBlock(world, i + 3, j + 3, k + 22, Blocks.sandstone, 0);
        this.setBlock(world, i + 3, j + 3, k + 23, Blocks.sandstone, 0);
        this.setBlock(world, i + 3, j + 3, k + 24, Blocks.stone_slab, 1);
        this.setBlock(world, i + 3, j + 3, k + 25, Blocks.stone_slab, 1);
        this.setBlock(world, i + 3, j + 3, k + 26, Blocks.stone_slab, 1);
        this.setBlock(world, i + 3, j + 3, k + 27, Blocks.stone_slab, 1);
        this.setBlock(world, i + 3, j + 4, k + 9, Blocks.sandstone, 0);
        this.setBlock(world, i + 3, j + 4, k + 10, Blocks.sandstone, 0);
        this.setBlock(world, i + 3, j + 4, k + 11, Blocks.sandstone, 0);
        this.setBlock(world, i + 3, j + 4, k + 12, Blocks.sandstone, 0);
        this.setBlock(world, i + 3, j + 4, k + 13, Blocks.sandstone, 0);
        this.setBlock(world, i + 3, j + 4, k + 14, Blocks.wool, 4);
        this.setBlock(world, i + 3, j + 4, k + 16, Blocks.wool, 4);
        this.setBlock(world, i + 3, j + 4, k + 17, Blocks.sandstone, 0);
        this.setBlock(world, i + 3, j + 4, k + 18, Blocks.sandstone, 0);
        this.setBlock(world, i + 3, j + 4, k + 19, Blocks.sandstone, 0);
        this.setBlock(world, i + 3, j + 4, k + 20, Blocks.sandstone, 0);
        this.setBlock(world, i + 3, j + 4, k + 21, Blocks.sandstone, 0);
        this.setBlock(world, i + 3, j + 5, k + 14, Blocks.sandstone, 0);
        this.setBlock(world, i + 3, j + 5, k + 15, Blocks.sandstone, 0);
        this.setBlock(world, i + 3, j + 5, k + 16, Blocks.sandstone, 0);
        this.setBlock(world, i + 4, j, k, Blocks.sandstone, 0);
        this.setBlock(world, i + 4, j, k + 1, Blocks.sandstone, 0);
        this.setBlock(world, i + 4, j, k + 2, Blocks.sandstone, 0);
        this.setBlock(world, i + 4, j, k + 3, Blocks.sandstone, 0);
        this.setBlock(world, i + 4, j, k + 4, Blocks.sandstone, 0);
        this.setBlock(world, i + 4, j, k + 5, Blocks.wool, 4);
        this.setBlock(world, i + 4, j, k + 6, Blocks.sandstone, 0);
        this.setBlock(world, i + 4, j, k + 7, Blocks.wool, 4);
        this.setBlock(world, i + 4, j, k + 8, Blocks.wool, 4);
        this.setBlock(world, i + 4, j, k + 9, Blocks.wool, 4);
        this.setBlock(world, i + 4, j, k + 10, Blocks.wool, 4);
        this.setBlock(world, i + 4, j, k + 11, Blocks.wool, 4);
        this.setBlock(world, i + 4, j, k + 12, Blocks.wool, 4);
        this.setBlock(world, i + 4, j, k + 13, Blocks.wool, 4);
        this.setBlock(world, i + 4, j, k + 14, Blocks.wool, 4);
        this.setBlock(world, i + 4, j, k + 15, Blocks.wool, 4);
        this.setBlock(world, i + 4, j, k + 16, Blocks.wool, 4);
        this.setBlock(world, i + 4, j, k + 17, Blocks.wool, 4);
        this.setBlock(world, i + 4, j, k + 18, Blocks.wool, 4);
        this.setBlock(world, i + 4, j, k + 19, Blocks.wool, 4);
        this.setBlock(world, i + 4, j, k + 20, Blocks.wool, 4);
        this.setBlock(world, i + 4, j, k + 21, Blocks.wool, 4);
        this.setBlock(world, i + 4, j, k + 22, Blocks.wool, 4);
        this.setBlock(world, i + 4, j, k + 23, Blocks.wool, 4);
        this.setBlock(world, i + 4, j, k + 24, Blocks.sandstone, 0);
        this.setBlock(world, i + 4, j, k + 25, Blocks.wool, 4);
        this.setBlock(world, i + 4, j, k + 26, Blocks.sandstone, 0);
        this.setBlock(world, i + 4, j, k + 27, Blocks.sandstone, 0);
        this.setBlock(world, i + 4, j, k + 28, Blocks.sandstone, 0);
        this.setBlock(world, i + 4, j, k + 29, Blocks.sandstone, 0);
        this.setBlock(world, i + 4, j, k + 30, Blocks.sandstone, 0);
        this.setBlock(world, i + 4, j, k + 31, Blocks.sandstone, 0);
        this.setBlock(world, i + 4, j + 1, k + 3, Blocks.sandstone, 0);
        this.setBlock(world, i + 4, j + 1, k + 4, Blocks.wool, 4);
        this.setBlock(world, i + 4, j + 1, k + 26, Blocks.wool, 4);
        this.setBlock(world, i + 4, j + 1, k + 27, Blocks.sandstone, 0);
        this.setBlock(world, i + 4, j + 2, k + 3, Blocks.sandstone, 0);
        this.setBlock(world, i + 4, j + 2, k + 4, Blocks.wool, 4);
        this.setBlock(world, i + 4, j + 2, k + 26, Blocks.wool, 4);
        this.setBlock(world, i + 4, j + 2, k + 27, Blocks.sandstone, 0);
        this.setBlock(world, i + 4, j + 3, k + 3, Blocks.stone_slab, 1);
        this.setBlock(world, i + 4, j + 3, k + 4, Blocks.sandstone, 0);
        this.setBlock(world, i + 4, j + 3, k + 5, Blocks.sandstone, 0);
        this.setBlock(world, i + 4, j + 3, k + 6, Blocks.sandstone, 0);
        this.setBlock(world, i + 4, j + 3, k + 7, Blocks.sandstone, 0);
        this.setBlock(world, i + 4, j + 3, k + 8, Blocks.sandstone, 0);
        this.setBlock(world, i + 4, j + 3, k + 22, Blocks.sandstone, 0);
        this.setBlock(world, i + 4, j + 3, k + 23, Blocks.sandstone, 0);
        this.setBlock(world, i + 4, j + 3, k + 24, Blocks.sandstone, 0);
        this.setBlock(world, i + 4, j + 3, k + 25, Blocks.sandstone, 0);
        this.setBlock(world, i + 4, j + 3, k + 26, Blocks.sandstone, 0);
        this.setBlock(world, i + 4, j + 3, k + 27, Blocks.stone_slab, 1);
        this.setBlock(world, i + 4, j + 4, k + 5, Blocks.sandstone, 0);
        this.setBlock(world, i + 4, j + 4, k + 6, Blocks.sandstone, 0);
        this.setBlock(world, i + 4, j + 4, k + 7, Blocks.sandstone, 0);
        this.setBlock(world, i + 4, j + 4, k + 8, Blocks.sandstone, 0);
        this.setBlock(world, i + 4, j + 4, k + 22, Blocks.sandstone, 0);
        this.setBlock(world, i + 4, j + 4, k + 23, Blocks.sandstone, 0);
        this.setBlock(world, i + 4, j + 4, k + 24, Blocks.sandstone, 0);
        this.setBlock(world, i + 4, j + 4, k + 25, Blocks.sandstone, 0);
        this.setBlock(world, i + 4, j + 4, k + 26, Blocks.stone_slab, 1);
        this.setBlock(world, i + 4, j + 5, k + 8, Blocks.sandstone, 0);
        this.setBlock(world, i + 4, j + 5, k + 9, Blocks.sandstone, 0);
        this.setBlock(world, i + 4, j + 5, k + 10, Blocks.sandstone, 0);
        this.setBlock(world, i + 4, j + 5, k + 11, Blocks.sandstone, 0);
        this.setBlock(world, i + 4, j + 5, k + 12, Blocks.sandstone, 0);
        this.setBlock(world, i + 4, j + 5, k + 13, Blocks.sandstone, 0);
        this.setBlock(world, i + 4, j + 5, k + 17, Blocks.sandstone, 0);
        this.setBlock(world, i + 4, j + 5, k + 18, Blocks.sandstone, 0);
        this.setBlock(world, i + 4, j + 5, k + 19, Blocks.sandstone, 0);
        this.setBlock(world, i + 4, j + 5, k + 20, Blocks.sandstone, 0);
        this.setBlock(world, i + 4, j + 5, k + 21, Blocks.sandstone, 0);
        this.setBlock(world, i + 4, j + 5, k + 22, Blocks.sandstone, 0);
        this.setBlock(world, i + 4, j + 6, k + 13, Blocks.sandstone, 0);
        this.setBlock(world, i + 4, j + 6, k + 14, Blocks.sandstone, 0);
        this.setBlock(world, i + 4, j + 6, k + 15, Blocks.sandstone, 0);
        this.setBlock(world, i + 4, j + 6, k + 16, Blocks.sandstone, 0);
        this.setBlock(world, i + 4, j + 6, k + 17, Blocks.sandstone, 0);
        this.setBlock(world, i + 5, j, k, Blocks.sandstone, 0);
        this.setBlock(world, i + 5, j, k + 1, Blocks.sandstone, 0);
        this.setBlock(world, i + 5, j, k + 2, Blocks.sandstone, 0);
        this.setBlock(world, i + 5, j, k + 3, Blocks.sandstone, 0);
        this.setBlock(world, i + 5, j, k + 4, Blocks.wool, 4);
        this.setBlock(world, i + 5, j, k + 5, Blocks.sandstone, 0);
        this.setBlock(world, i + 5, j, k + 6, Blocks.wool, 4);
        this.setBlock(world, i + 5, j, k + 7, Blocks.sandstone, 0);
        this.setBlock(world, i + 5, j, k + 8, Blocks.sandstone, 0);
        this.setBlock(world, i + 5, j, k + 9, Blocks.sandstone, 0);
        this.setBlock(world, i + 5, j, k + 10, Blocks.sandstone, 0);
        this.setBlock(world, i + 5, j, k + 11, Blocks.sandstone, 0);
        this.setBlock(world, i + 5, j, k + 12, Blocks.sandstone, 0);
        this.setBlock(world, i + 5, j, k + 13, Blocks.sandstone, 0);
        this.setBlock(world, i + 5, j, k + 14, Blocks.wool, 4);
        this.setBlock(world, i + 5, j, k + 15, Blocks.sandstone, 0);
        this.setBlock(world, i + 5, j, k + 16, Blocks.wool, 4);
        this.setBlock(world, i + 5, j, k + 17, Blocks.sandstone, 0);
        this.setBlock(world, i + 5, j, k + 18, Blocks.sandstone, 0);
        this.setBlock(world, i + 5, j, k + 19, Blocks.sandstone, 0);
        this.setBlock(world, i + 5, j, k + 20, Blocks.sandstone, 0);
        this.setBlock(world, i + 5, j, k + 21, Blocks.sandstone, 0);
        this.setBlock(world, i + 5, j, k + 22, Blocks.sandstone, 0);
        this.setBlock(world, i + 5, j, k + 23, Blocks.sandstone, 0);
        this.setBlock(world, i + 5, j, k + 24, Blocks.wool, 4);
        this.setBlock(world, i + 5, j, k + 25, Blocks.sandstone, 0);
        this.setBlock(world, i + 5, j, k + 26, Blocks.wool, 4);
        this.setBlock(world, i + 5, j, k + 27, Blocks.sandstone, 0);
        this.setBlock(world, i + 5, j, k + 28, Blocks.sandstone, 0);
        this.setBlock(world, i + 5, j, k + 29, Blocks.sandstone, 0);
        this.setBlock(world, i + 5, j, k + 30, Blocks.sandstone, 0);
        this.setBlock(world, i + 5, j, k + 31, Blocks.sandstone, 0);
        this.setBlock(world, i + 5, j + 1, k + 3, Blocks.sandstone, 0);
        this.setBlock(world, i + 5, j + 1, k + 27, Blocks.sandstone, 0);
        this.setBlock(world, i + 5, j + 2, k + 3, Blocks.sandstone, 0);
        this.setBlock(world, i + 5, j + 2, k + 27, Blocks.sandstone, 0);
        this.setBlock(world, i + 5, j + 3, k + 3, Blocks.stone_slab, 1);
        this.setBlock(world, i + 5, j + 3, k + 4, Blocks.sandstone, 0);
        this.setBlock(world, i + 5, j + 3, k + 26, Blocks.sandstone, 0);
        this.setBlock(world, i + 5, j + 3, k + 27, Blocks.stone_slab, 1);
        this.setBlock(world, i + 5, j + 4, k + 4, Blocks.sandstone, 0);
        this.setBlock(world, i + 5, j + 4, k + 26, Blocks.sandstone, 0);
        this.setBlock(world, i + 5, j + 5, k + 5, Blocks.sandstone, 0);
        this.setBlock(world, i + 5, j + 5, k + 6, Blocks.sandstone, 0);
        this.setBlock(world, i + 5, j + 5, k + 7, Blocks.sandstone, 0);
        this.setBlock(world, i + 5, j + 5, k + 23, Blocks.sandstone, 0);
        this.setBlock(world, i + 5, j + 5, k + 24, Blocks.sandstone, 0);
        this.setBlock(world, i + 5, j + 5, k + 25, Blocks.sandstone, 0);
        this.setBlock(world, i + 5, j + 6, k + 8, Blocks.sandstone, 0);
        this.setBlock(world, i + 5, j + 6, k + 9, Blocks.sandstone, 0);
        this.setBlock(world, i + 5, j + 6, k + 10, Blocks.sandstone, 0);
        this.setBlock(world, i + 5, j + 6, k + 11, Blocks.sandstone, 0);
        this.setBlock(world, i + 5, j + 6, k + 12, Blocks.sandstone, 0);
        this.setBlock(world, i + 5, j + 6, k + 18, Blocks.sandstone, 0);
        this.setBlock(world, i + 5, j + 6, k + 19, Blocks.sandstone, 0);
        this.setBlock(world, i + 5, j + 6, k + 20, Blocks.sandstone, 0);
        this.setBlock(world, i + 5, j + 6, k + 21, Blocks.sandstone, 0);
        this.setBlock(world, i + 5, j + 6, k + 22, Blocks.sandstone, 0);
        this.setBlock(world, i + 5, j + 7, k + 11, Blocks.sandstone, 0);
        this.setBlock(world, i + 5, j + 7, k + 12, Blocks.sandstone, 0);
        this.setBlock(world, i + 5, j + 7, k + 13, Blocks.sandstone, 0);
        this.setBlock(world, i + 5, j + 7, k + 14, Blocks.sandstone, 0);
        this.setBlock(world, i + 5, j + 7, k + 15, Blocks.sandstone, 0);
        this.setBlock(world, i + 5, j + 7, k + 16, Blocks.sandstone, 0);
        this.setBlock(world, i + 5, j + 7, k + 17, Blocks.sandstone, 0);
        this.setBlock(world, i + 5, j + 7, k + 18, Blocks.sandstone, 0);
        this.setBlock(world, i + 5, j + 7, k + 19, Blocks.sandstone, 0);
        this.setBlock(world, i + 6, j, k, Blocks.sandstone, 0);
        this.setBlock(world, i + 6, j, k + 1, Blocks.sandstone, 0);
        this.setBlock(world, i + 6, j, k + 2, Blocks.sandstone, 0);
        this.setBlock(world, i + 6, j, k + 3, Blocks.sandstone, 0);
        this.setBlock(world, i + 6, j, k + 4, Blocks.sandstone, 0);
        this.setBlock(world, i + 6, j, k + 5, Blocks.wool, 4);
        this.setBlock(world, i + 6, j, k + 6, Blocks.sandstone, 0);
        this.setBlock(world, i + 6, j, k + 7, Blocks.wool, 4);
        this.setBlock(world, i + 6, j, k + 8, Blocks.sandstone, 0);
        this.setBlock(world, i + 6, j, k + 9, Blocks.sandstone, 0);
        this.setBlock(world, i + 6, j, k + 10, Blocks.sandstone, 0);
        this.setBlock(world, i + 6, j, k + 11, Blocks.sandstone, 0);
        this.setBlock(world, i + 6, j, k + 12, Blocks.sandstone, 0);
        this.setBlock(world, i + 6, j, k + 13, Blocks.sandstone, 0);
        this.setBlock(world, i + 6, j, k + 14, Blocks.wool, 4);
        this.setBlock(world, i + 6, j, k + 15, Blocks.sandstone, 0);
        this.setBlock(world, i + 6, j, k + 16, Blocks.wool, 4);
        this.setBlock(world, i + 6, j, k + 17, Blocks.sandstone, 0);
        this.setBlock(world, i + 6, j, k + 18, Blocks.sandstone, 0);
        this.setBlock(world, i + 6, j, k + 19, Blocks.sandstone, 0);
        this.setBlock(world, i + 6, j, k + 20, Blocks.sandstone, 0);
        this.setBlock(world, i + 6, j, k + 21, Blocks.sandstone, 0);
        this.setBlock(world, i + 6, j, k + 22, Blocks.sandstone, 0);
        this.setBlock(world, i + 6, j, k + 23, Blocks.wool, 4);
        this.setBlock(world, i + 6, j, k + 24, Blocks.sandstone, 0);
        this.setBlock(world, i + 6, j, k + 25, Blocks.wool, 4);
        this.setBlock(world, i + 6, j, k + 26, Blocks.sandstone, 0);
        this.setBlock(world, i + 6, j, k + 27, Blocks.sandstone, 0);
        this.setBlock(world, i + 6, j, k + 28, Blocks.sandstone, 0);
        this.setBlock(world, i + 6, j, k + 29, Blocks.sandstone, 0);
        this.setBlock(world, i + 6, j, k + 30, Blocks.sandstone, 0);
        this.setBlock(world, i + 6, j, k + 31, Blocks.sandstone, 0);
        this.setBlock(world, i + 6, j + 1, k + 3, Blocks.sandstone, 0);
        this.setBlock(world, i + 6, j + 1, k + 27, Blocks.sandstone, 0);
        this.setBlock(world, i + 6, j + 2, k + 3, Blocks.sandstone, 0);
        this.setBlock(world, i + 6, j + 2, k + 27, Blocks.sandstone, 0);
        this.setBlock(world, i + 6, j + 3, k + 3, Blocks.stone_slab, 1);
        this.setBlock(world, i + 6, j + 3, k + 4, Blocks.sandstone, 0);
        this.setBlock(world, i + 6, j + 3, k + 26, Blocks.sandstone, 0);
        this.setBlock(world, i + 6, j + 3, k + 27, Blocks.stone_slab, 1);
        this.setBlock(world, i + 6, j + 4, k + 4, Blocks.sandstone, 0);
        this.setBlock(world, i + 6, j + 4, k + 26, Blocks.sandstone, 0);
        this.setBlock(world, i + 6, j + 5, k + 5, Blocks.sandstone, 0);
        this.setBlock(world, i + 6, j + 5, k + 6, Blocks.sandstone, 0);
        this.setBlock(world, i + 6, j + 5, k + 24, Blocks.sandstone, 0);
        this.setBlock(world, i + 6, j + 5, k + 25, Blocks.sandstone, 0);
        this.setBlock(world, i + 6, j + 6, k + 6, Blocks.sandstone, 0);
        this.setBlock(world, i + 6, j + 6, k + 7, Blocks.sandstone, 0);
        this.setBlock(world, i + 6, j + 6, k + 23, Blocks.sandstone, 0);
        this.setBlock(world, i + 6, j + 6, k + 24, Blocks.sandstone, 0);
        this.setBlock(world, i + 6, j + 7, k + 8, Blocks.sandstone, 0);
        this.setBlock(world, i + 6, j + 7, k + 9, Blocks.sandstone, 0);
        this.setBlock(world, i + 6, j + 7, k + 10, Blocks.sandstone, 0);
        this.setBlock(world, i + 6, j + 7, k + 20, Blocks.sandstone, 0);
        this.setBlock(world, i + 6, j + 7, k + 21, Blocks.sandstone, 0);
        this.setBlock(world, i + 6, j + 7, k + 22, Blocks.sandstone, 0);
        this.setBlock(world, i + 6, j + 8, k + 11, Blocks.sandstone, 0);
        this.setBlock(world, i + 6, j + 8, k + 12, Blocks.sandstone, 0);
        this.setBlock(world, i + 6, j + 8, k + 13, Blocks.sandstone, 0);
        this.setBlock(world, i + 6, j + 8, k + 14, Blocks.sandstone, 0);
        this.setBlock(world, i + 6, j + 8, k + 15, Blocks.sandstone, 0);
        this.setBlock(world, i + 6, j + 8, k + 16, Blocks.sandstone, 0);
        this.setBlock(world, i + 6, j + 8, k + 17, Blocks.sandstone, 0);
        this.setBlock(world, i + 6, j + 8, k + 18, Blocks.sandstone, 0);
        this.setBlock(world, i + 6, j + 8, k + 19, Blocks.sandstone, 0);
        this.setBlock(world, i + 7, j, k, Blocks.sandstone, 0);
        this.setBlock(world, i + 7, j, k + 1, Blocks.sandstone, 0);
        this.setBlock(world, i + 7, j, k + 2, Blocks.sandstone, 0);
        this.setBlock(world, i + 7, j, k + 3, Blocks.sandstone, 0);
        this.setBlock(world, i + 7, j, k + 4, Blocks.wool, 4);
        this.setBlock(world, i + 7, j, k + 5, Blocks.sandstone, 0);
        this.setBlock(world, i + 7, j, k + 6, Blocks.wool, 4);
        this.setBlock(world, i + 7, j, k + 7, Blocks.sandstone, 0);
        this.setBlock(world, i + 7, j, k + 8, Blocks.wool, 4);
        this.setBlock(world, i + 7, j, k + 9, Blocks.sandstone, 0);
        this.setBlock(world, i + 7, j, k + 10, Blocks.sandstone, 0);
        this.setBlock(world, i + 7, j, k + 11, Blocks.sandstone, 0);
        this.setBlock(world, i + 7, j, k + 12, Blocks.sandstone, 0);
        this.setBlock(world, i + 7, j, k + 13, Blocks.sandstone, 0);
        this.setBlock(world, i + 7, j, k + 14, Blocks.wool, 4);
        this.setBlock(world, i + 7, j, k + 15, Blocks.sandstone, 0);
        this.setBlock(world, i + 7, j, k + 16, Blocks.wool, 4);
        this.setBlock(world, i + 7, j, k + 17, Blocks.sandstone, 0);
        this.setBlock(world, i + 7, j, k + 18, Blocks.sandstone, 0);
        this.setBlock(world, i + 7, j, k + 19, Blocks.sandstone, 0);
        this.setBlock(world, i + 7, j, k + 20, Blocks.sandstone, 0);
        this.setBlock(world, i + 7, j, k + 21, Blocks.sandstone, 0);
        this.setBlock(world, i + 7, j, k + 22, Blocks.wool, 4);
        this.setBlock(world, i + 7, j, k + 23, Blocks.sandstone, 0);
        this.setBlock(world, i + 7, j, k + 24, Blocks.wool, 4);
        this.setBlock(world, i + 7, j, k + 25, Blocks.sandstone, 0);
        this.setBlock(world, i + 7, j, k + 26, Blocks.wool, 4);
        this.setBlock(world, i + 7, j, k + 27, Blocks.sandstone, 0);
        this.setBlock(world, i + 7, j, k + 28, Blocks.sandstone, 0);
        this.setBlock(world, i + 7, j, k + 29, Blocks.sandstone, 0);
        this.setBlock(world, i + 7, j, k + 30, Blocks.sandstone, 0);
        this.setBlock(world, i + 7, j, k + 31, Blocks.sandstone, 0);
        this.setBlock(world, i + 7, j + 1, k + 3, Blocks.sandstone, 0);
        this.setBlock(world, i + 7, j + 1, k + 10, Blocks.air, 1);
        this.setBlock(world, i + 7, j + 1, k + 27, Blocks.sandstone, 0);
        this.setBlock(world, i + 7, j + 2, k + 3, Blocks.sandstone, 0);
        this.setBlock(world, i + 7, j + 2, k + 27, Blocks.sandstone, 0);
        this.setBlock(world, i + 7, j + 3, k + 3, Blocks.sandstone, 0);
        this.setBlock(world, i + 7, j + 3, k + 4, Blocks.sandstone, 0);
        this.setBlock(world, i + 7, j + 3, k + 26, Blocks.sandstone, 0);
        this.setBlock(world, i + 7, j + 3, k + 27, Blocks.sandstone, 0);
        this.setBlock(world, i + 7, j + 4, k + 4, Blocks.sandstone, 0);
        this.setBlock(world, i + 7, j + 4, k + 26, Blocks.sandstone, 0);
        this.setBlock(world, i + 7, j + 5, k + 5, Blocks.sandstone, 0);
        this.setBlock(world, i + 7, j + 5, k + 25, Blocks.sandstone, 0);
        this.setBlock(world, i + 7, j + 6, k + 6, Blocks.sandstone, 0);
        this.setBlock(world, i + 7, j + 6, k + 24, Blocks.sandstone, 0);
        this.setBlock(world, i + 7, j + 7, k + 7, Blocks.sandstone, 0);
        this.setBlock(world, i + 7, j + 7, k + 23, Blocks.sandstone, 0);
        this.setBlock(world, i + 7, j + 8, k + 8, Blocks.sandstone, 0);
        this.setBlock(world, i + 7, j + 8, k + 9, Blocks.sandstone, 0);
        this.setBlock(world, i + 7, j + 8, k + 10, Blocks.sandstone, 0);
        this.setBlock(world, i + 7, j + 8, k + 11, Blocks.sandstone, 0);
        this.setBlock(world, i + 7, j + 8, k + 19, Blocks.sandstone, 0);
        this.setBlock(world, i + 7, j + 8, k + 20, Blocks.sandstone, 0);
        this.setBlock(world, i + 7, j + 8, k + 21, Blocks.sandstone, 0);
        this.setBlock(world, i + 7, j + 8, k + 22, Blocks.sandstone, 0);
        this.setBlock(world, i + 7, j + 9, k + 12, Blocks.sandstone, 0);
        this.setBlock(world, i + 7, j + 9, k + 13, Blocks.sandstone, 0);
        this.setBlock(world, i + 7, j + 9, k + 14, Blocks.sandstone, 0);
        this.setBlock(world, i + 7, j + 9, k + 15, Blocks.sandstone, 0);
        this.setBlock(world, i + 7, j + 9, k + 16, Blocks.sandstone, 0);
        this.setBlock(world, i + 7, j + 9, k + 17, Blocks.sandstone, 0);
        this.setBlock(world, i + 7, j + 9, k + 18, Blocks.sandstone, 0);
        this.setBlock(world, i + 8, j, k, Blocks.sandstone, 0);
        this.setBlock(world, i + 8, j, k + 1, Blocks.sandstone, 0);
        this.setBlock(world, i + 8, j, k + 2, Blocks.sandstone, 0);
        this.setBlock(world, i + 8, j, k + 3, Blocks.sandstone, 0);
        this.setBlock(world, i + 8, j, k + 4, Blocks.wool, 4);
        this.setBlock(world, i + 8, j, k + 5, Blocks.sandstone, 0);
        this.setBlock(world, i + 8, j, k + 6, Blocks.sandstone, 0);
        this.setBlock(world, i + 8, j, k + 7, Blocks.wool, 4);
        this.setBlock(world, i + 8, j, k + 8, Blocks.sandstone, 0);
        this.setBlock(world, i + 8, j, k + 9, Blocks.wool, 4);
        this.setBlock(world, i + 8, j, k + 10, Blocks.sandstone, 0);
        this.setBlock(world, i + 8, j, k + 11, Blocks.sandstone, 0);
        this.setBlock(world, i + 8, j, k + 12, Blocks.sandstone, 0);
        this.setBlock(world, i + 8, j, k + 13, Blocks.sandstone, 0);
        this.setBlock(world, i + 8, j, k + 14, Blocks.wool, 4);
        this.setBlock(world, i + 8, j, k + 15, Blocks.sandstone, 0);
        this.setBlock(world, i + 8, j, k + 16, Blocks.wool, 4);
        this.setBlock(world, i + 8, j, k + 17, Blocks.sandstone, 0);
        this.setBlock(world, i + 8, j, k + 18, Blocks.sandstone, 0);
        this.setBlock(world, i + 8, j, k + 19, Blocks.sandstone, 0);
        this.setBlock(world, i + 8, j, k + 20, Blocks.sandstone, 0);
        this.setBlock(world, i + 8, j, k + 21, Blocks.wool, 4);
        this.setBlock(world, i + 8, j, k + 22, Blocks.sandstone, 0);
        this.setBlock(world, i + 8, j, k + 23, Blocks.wool, 4);
        this.setBlock(world, i + 8, j, k + 24, Blocks.sandstone, 0);
        this.setBlock(world, i + 8, j, k + 25, Blocks.sandstone, 0);
        this.setBlock(world, i + 8, j, k + 26, Blocks.wool, 4);
        this.setBlock(world, i + 8, j, k + 27, Blocks.sandstone, 0);
        this.setBlock(world, i + 8, j, k + 28, Blocks.sandstone, 0);
        this.setBlock(world, i + 8, j, k + 29, Blocks.sandstone, 0);
        this.setBlock(world, i + 8, j, k + 30, Blocks.sandstone, 0);
        this.setBlock(world, i + 8, j, k + 31, Blocks.sandstone, 0);
        this.setBlock(world, i + 8, j + 1, k + 3, Blocks.sandstone, 0);
        this.setBlock(world, i + 8, j + 1, k + 17, Blocks.air, 1);
        this.setBlock(world, i + 8, j + 1, k + 27, Blocks.sandstone, 0);
        this.setBlock(world, i + 8, j + 2, k + 3, Blocks.sandstone, 0);
        this.setBlock(world, i + 8, j + 2, k + 27, Blocks.sandstone, 0);
        this.setBlock(world, i + 8, j + 3, k + 3, Blocks.sandstone, 0);
        this.setBlock(world, i + 8, j + 3, k + 4, Blocks.sandstone, 0);
        this.setBlock(world, i + 8, j + 3, k + 26, Blocks.sandstone, 0);
        this.setBlock(world, i + 8, j + 3, k + 27, Blocks.sandstone, 0);
        this.setBlock(world, i + 8, j + 4, k + 4, Blocks.sandstone, 0);
        this.setBlock(world, i + 8, j + 4, k + 26, Blocks.sandstone, 0);
        this.setBlock(world, i + 8, j + 5, k + 4, Blocks.sandstone, 0);
        this.setBlock(world, i + 8, j + 5, k + 26, Blocks.sandstone, 0);
        this.setBlock(world, i + 8, j + 6, k + 5, Blocks.sandstone, 0);
        this.setBlock(world, i + 8, j + 6, k + 25, Blocks.sandstone, 0);
        this.setBlock(world, i + 8, j + 7, k + 6, Blocks.sandstone, 0);
        this.setBlock(world, i + 8, j + 7, k + 24, Blocks.sandstone, 0);
        this.setBlock(world, i + 8, j + 8, k + 7, Blocks.sandstone, 0);
        this.setBlock(world, i + 8, j + 8, k + 8, Blocks.sandstone, 0);
        this.setBlock(world, i + 8, j + 8, k + 22, Blocks.sandstone, 0);
        this.setBlock(world, i + 8, j + 8, k + 23, Blocks.sandstone, 0);
        this.setBlock(world, i + 8, j + 9, k + 9, Blocks.sandstone, 0);
        this.setBlock(world, i + 8, j + 9, k + 10, Blocks.sandstone, 0);
        this.setBlock(world, i + 8, j + 9, k + 11, Blocks.sandstone, 0);
        this.setBlock(world, i + 8, j + 9, k + 12, Blocks.sandstone, 0);
        this.setBlock(world, i + 8, j + 9, k + 18, Blocks.sandstone, 0);
        this.setBlock(world, i + 8, j + 9, k + 19, Blocks.sandstone, 0);
        this.setBlock(world, i + 8, j + 9, k + 20, Blocks.sandstone, 0);
        this.setBlock(world, i + 8, j + 9, k + 21, Blocks.sandstone, 0);
        this.setBlock(world, i + 8, j + 10, k + 13, Blocks.sandstone, 0);
        this.setBlock(world, i + 8, j + 10, k + 14, Blocks.sandstone, 0);
        this.setBlock(world, i + 8, j + 10, k + 15, Blocks.sandstone, 0);
        this.setBlock(world, i + 8, j + 10, k + 16, Blocks.sandstone, 0);
        this.setBlock(world, i + 8, j + 10, k + 17, Blocks.sandstone, 0);
        this.setBlock(world, i + 8, j + 11, k + 14, Blocks.sandstone, 0);
        this.setBlock(world, i + 8, j + 11, k + 15, Blocks.sandstone, 0);
        this.setBlock(world, i + 8, j + 11, k + 16, Blocks.sandstone, 0);
        this.setBlock(world, i + 9, j, k, Blocks.sandstone, 0);
        this.setBlock(world, i + 9, j, k + 1, Blocks.sandstone, 0);
        this.setBlock(world, i + 9, j, k + 2, Blocks.sandstone, 0);
        this.setBlock(world, i + 9, j, k + 3, Blocks.sandstone, 0);
        this.setBlock(world, i + 9, j, k + 4, Blocks.wool, 4);
        this.setBlock(world, i + 9, j, k + 5, Blocks.sandstone, 0);
        this.setBlock(world, i + 9, j, k + 6, Blocks.sandstone, 0);
        this.setBlock(world, i + 9, j, k + 7, Blocks.sandstone, 0);
        this.setBlock(world, i + 9, j, k + 8, Blocks.wool, 4);
        this.setBlock(world, i + 9, j, k + 9, Blocks.sandstone, 0);
        this.setBlock(world, i + 9, j, k + 10, Blocks.wool, 4);
        this.setBlock(world, i + 9, j, k + 11, Blocks.sandstone, 0);
        this.setBlock(world, i + 9, j, k + 12, Blocks.sandstone, 0);
        this.setBlock(world, i + 9, j, k + 13, Blocks.sandstone, 0);
        this.setBlock(world, i + 9, j, k + 14, Blocks.wool, 4);
        this.setBlock(world, i + 9, j, k + 15, Blocks.sandstone, 0);
        this.setBlock(world, i + 9, j, k + 16, Blocks.wool, 4);
        this.setBlock(world, i + 9, j, k + 17, Blocks.sandstone, 0);
        this.setBlock(world, i + 9, j, k + 18, Blocks.sandstone, 0);
        this.setBlock(world, i + 9, j, k + 19, Blocks.sandstone, 0);
        this.setBlock(world, i + 9, j, k + 20, Blocks.wool, 4);
        this.setBlock(world, i + 9, j, k + 21, Blocks.sandstone, 0);
        this.setBlock(world, i + 9, j, k + 22, Blocks.wool, 4);
        this.setBlock(world, i + 9, j, k + 23, Blocks.sandstone, 0);
        this.setBlock(world, i + 9, j, k + 24, Blocks.sandstone, 0);
        this.setBlock(world, i + 9, j, k + 25, Blocks.sandstone, 0);
        this.setBlock(world, i + 9, j, k + 26, Blocks.wool, 4);
        this.setBlock(world, i + 9, j, k + 27, Blocks.sandstone, 0);
        this.setBlock(world, i + 9, j, k + 28, Blocks.sandstone, 0);
        this.setBlock(world, i + 9, j, k + 29, Blocks.sandstone, 0);
        this.setBlock(world, i + 9, j, k + 30, Blocks.sandstone, 0);
        this.setBlock(world, i + 9, j, k + 31, Blocks.sandstone, 0);
        this.setBlock(world, i + 9, j + 1, k + 3, Blocks.sandstone, 0);
        this.setBlock(world, i + 9, j + 1, k + 27, Blocks.sandstone, 0);
        this.setBlock(world, i + 9, j + 2, k + 3, Blocks.sandstone, 0);
        this.setBlock(world, i + 9, j + 2, k + 27, Blocks.sandstone, 0);
        this.setBlock(world, i + 9, j + 3, k + 3, Blocks.sandstone, 0);
        this.setBlock(world, i + 9, j + 3, k + 27, Blocks.sandstone, 0);
        this.setBlock(world, i + 9, j + 4, k + 3, Blocks.sandstone, 0);
        this.setBlock(world, i + 9, j + 4, k + 27, Blocks.sandstone, 0);
        this.setBlock(world, i + 9, j + 5, k + 4, Blocks.sandstone, 0);
        this.setBlock(world, i + 9, j + 5, k + 26, Blocks.sandstone, 0);
        this.setBlock(world, i + 9, j + 6, k + 5, Blocks.sandstone, 0);
        this.setBlock(world, i + 9, j + 6, k + 25, Blocks.sandstone, 0);
        this.setBlock(world, i + 9, j + 7, k + 6, Blocks.sandstone, 0);
        this.setBlock(world, i + 9, j + 7, k + 24, Blocks.sandstone, 0);
        this.setBlock(world, i + 9, j + 8, k + 7, Blocks.sandstone, 0);
        this.setBlock(world, i + 9, j + 8, k + 23, Blocks.sandstone, 0);
        this.setBlock(world, i + 9, j + 9, k + 8, Blocks.sandstone, 0);
        this.setBlock(world, i + 9, j + 9, k + 21, Blocks.sandstone, 0);
        this.setBlock(world, i + 9, j + 9, k + 22, Blocks.sandstone, 0);
        this.setBlock(world, i + 9, j + 10, k + 9, Blocks.sandstone, 0);
        this.setBlock(world, i + 9, j + 10, k + 10, Blocks.sandstone, 0);
        this.setBlock(world, i + 9, j + 10, k + 11, Blocks.sandstone, 0);
        this.setBlock(world, i + 9, j + 10, k + 12, Blocks.sandstone, 0);
        this.setBlock(world, i + 9, j + 10, k + 13, Blocks.sandstone, 0);
        this.setBlock(world, i + 9, j + 10, k + 17, Blocks.sandstone, 0);
        this.setBlock(world, i + 9, j + 10, k + 18, Blocks.sandstone, 0);
        this.setBlock(world, i + 9, j + 10, k + 19, Blocks.sandstone, 0);
        this.setBlock(world, i + 9, j + 10, k + 20, Blocks.sandstone, 0);
        this.setBlock(world, i + 9, j + 10, k + 21, Blocks.sandstone, 0);
        this.setBlock(world, i + 9, j + 11, k + 10, Blocks.sandstone, 0);
        this.setBlock(world, i + 9, j + 11, k + 11, Blocks.sandstone, 0);
        this.setBlock(world, i + 9, j + 11, k + 12, Blocks.sandstone, 0);
        this.setBlock(world, i + 9, j + 11, k + 13, Blocks.sandstone, 0);
        this.setBlock(world, i + 9, j + 11, k + 17, Blocks.sandstone, 0);
        this.setBlock(world, i + 9, j + 11, k + 18, Blocks.sandstone, 0);
        this.setBlock(world, i + 9, j + 11, k + 19, Blocks.sandstone, 0);
        this.setBlock(world, i + 9, j + 11, k + 20, Blocks.sandstone, 0);
        this.setBlock(world, i + 9, j + 12, k + 14, Blocks.sandstone, 0);
        this.setBlock(world, i + 9, j + 12, k + 15, Blocks.sandstone, 0);
        this.setBlock(world, i + 9, j + 12, k + 16, Blocks.sandstone, 0);
        this.setBlock(world, i + 9, j + 13, k + 15, Blocks.sandstone, 0);
        this.setBlock(world, i + 10, j, k, Blocks.sandstone, 0);
        this.setBlock(world, i + 10, j, k + 1, Blocks.sandstone, 0);
        this.setBlock(world, i + 10, j, k + 2, Blocks.sandstone, 0);
        this.setBlock(world, i + 10, j, k + 3, Blocks.sandstone, 0);
        this.setBlock(world, i + 10, j, k + 4, Blocks.wool, 4);
        this.setBlock(world, i + 10, j, k + 5, Blocks.sandstone, 0);
        this.setBlock(world, i + 10, j, k + 6, Blocks.sandstone, 0);
        this.setBlock(world, i + 10, j, k + 7, Blocks.sandstone, 0);
        this.setBlock(world, i + 10, j, k + 8, Blocks.sandstone, 0);
        this.setBlock(world, i + 10, j, k + 9, Blocks.wool, 4);
        this.setBlock(world, i + 10, j, k + 10, Blocks.sandstone, 0);
        this.setBlock(world, i + 10, j, k + 11, Blocks.wool, 4);
        this.setBlock(world, i + 10, j, k + 12, Blocks.sandstone, 0);
        this.setBlock(world, i + 10, j, k + 13, Blocks.sandstone, 0);
        this.setBlock(world, i + 10, j, k + 14, Blocks.wool, 4);
        this.setBlock(world, i + 10, j, k + 15, Blocks.sandstone, 0);
        this.setBlock(world, i + 10, j, k + 16, Blocks.wool, 4);
        this.setBlock(world, i + 10, j, k + 17, Blocks.sandstone, 0);
        this.setBlock(world, i + 10, j, k + 18, Blocks.sandstone, 0);
        this.setBlock(world, i + 10, j, k + 19, Blocks.wool, 4);
        this.setBlock(world, i + 10, j, k + 20, Blocks.sandstone, 0);
        this.setBlock(world, i + 10, j, k + 21, Blocks.wool, 4);
        this.setBlock(world, i + 10, j, k + 22, Blocks.sandstone, 0);
        this.setBlock(world, i + 10, j, k + 23, Blocks.sandstone, 0);
        this.setBlock(world, i + 10, j, k + 24, Blocks.sandstone, 0);
        this.setBlock(world, i + 10, j, k + 25, Blocks.sandstone, 0);
        this.setBlock(world, i + 10, j, k + 26, Blocks.wool, 4);
        this.setBlock(world, i + 10, j, k + 27, Blocks.sandstone, 0);
        this.setBlock(world, i + 10, j, k + 28, Blocks.sandstone, 0);
        this.setBlock(world, i + 10, j, k + 29, Blocks.sandstone, 0);
        this.setBlock(world, i + 10, j, k + 30, Blocks.sandstone, 0);
        this.setBlock(world, i + 10, j, k + 31, Blocks.sandstone, 0);
        this.setBlock(world, i + 10, j + 1, k + 3, Blocks.sandstone, 0);
        this.setBlock(world, i + 10, j + 1, k + 27, Blocks.sandstone, 0);
        this.setBlock(world, i + 10, j + 2, k + 3, Blocks.sandstone, 0);
        this.setBlock(world, i + 10, j + 2, k + 27, Blocks.sandstone, 0);
        this.setBlock(world, i + 10, j + 3, k + 3, Blocks.sandstone, 0);
        this.setBlock(world, i + 10, j + 3, k + 27, Blocks.sandstone, 0);
        this.setBlock(world, i + 10, j + 4, k + 3, Blocks.sandstone, 0);
        this.setBlock(world, i + 10, j + 4, k + 27, Blocks.sandstone, 0);
        this.setBlock(world, i + 10, j + 5, k + 4, Blocks.sandstone, 0);
        this.setBlock(world, i + 10, j + 5, k + 26, Blocks.sandstone, 0);
        this.setBlock(world, i + 10, j + 6, k + 5, Blocks.sandstone, 0);
        this.setBlock(world, i + 10, j + 6, k + 25, Blocks.sandstone, 0);
        this.setBlock(world, i + 10, j + 7, k + 6, Blocks.sandstone, 0);
        this.setBlock(world, i + 10, j + 7, k + 24, Blocks.sandstone, 0);
        this.setBlock(world, i + 10, j + 8, k + 7, Blocks.sandstone, 0);
        this.setBlock(world, i + 10, j + 8, k + 23, Blocks.sandstone, 0);
        this.setBlock(world, i + 10, j + 9, k + 8, Blocks.sandstone, 0);
        this.setBlock(world, i + 10, j + 9, k + 22, Blocks.sandstone, 0);
        this.setBlock(world, i + 10, j + 10, k + 9, Blocks.sandstone, 0);
        this.setBlock(world, i + 10, j + 10, k + 21, Blocks.sandstone, 0);
        this.setBlock(world, i + 10, j + 11, k + 9, Blocks.sandstone, 0);
        this.setBlock(world, i + 10, j + 11, k + 21, Blocks.sandstone, 0);
        this.setBlock(world, i + 10, j + 12, k + 10, Blocks.sandstone, 0);
        this.setBlock(world, i + 10, j + 12, k + 11, Blocks.sandstone, 0);
        this.setBlock(world, i + 10, j + 12, k + 12, Blocks.sandstone, 0);
        this.setBlock(world, i + 10, j + 12, k + 13, Blocks.sandstone, 0);
        this.setBlock(world, i + 10, j + 12, k + 14, Blocks.sandstone, 0);
        this.setBlock(world, i + 10, j + 12, k + 16, Blocks.sandstone, 0);
        this.setBlock(world, i + 10, j + 12, k + 17, Blocks.sandstone, 0);
        this.setBlock(world, i + 10, j + 12, k + 18, Blocks.sandstone, 0);
        this.setBlock(world, i + 10, j + 12, k + 19, Blocks.sandstone, 0);
        this.setBlock(world, i + 10, j + 12, k + 20, Blocks.sandstone, 0);
        this.setBlock(world, i + 10, j + 13, k + 11, Blocks.sandstone, 0);
        this.setBlock(world, i + 10, j + 13, k + 12, Blocks.sandstone, 0);
        this.setBlock(world, i + 10, j + 13, k + 13, Blocks.sandstone, 0);
        this.setBlock(world, i + 10, j + 13, k + 14, Blocks.sandstone, 0);
        this.setBlock(world, i + 10, j + 13, k + 16, Blocks.sandstone, 0);
        this.setBlock(world, i + 10, j + 13, k + 17, Blocks.sandstone, 0);
        this.setBlock(world, i + 10, j + 13, k + 18, Blocks.sandstone, 0);
        this.setBlock(world, i + 10, j + 13, k + 19, Blocks.sandstone, 0);
        this.setBlock(world, i + 10, j + 14, k + 15, Blocks.sandstone, 0);
        this.setBlock(world, i + 11, j, k, Blocks.sandstone, 0);
        this.setBlock(world, i + 11, j, k + 1, Blocks.sandstone, 0);
        this.setBlock(world, i + 11, j, k + 2, Blocks.sandstone, 0);
        this.setBlock(world, i + 11, j, k + 3, Blocks.sandstone, 0);
        this.setBlock(world, i + 11, j, k + 4, Blocks.wool, 4);
        this.setBlock(world, i + 11, j, k + 5, Blocks.sandstone, 0);
        this.setBlock(world, i + 11, j, k + 6, Blocks.sandstone, 0);
        this.setBlock(world, i + 11, j, k + 7, Blocks.sandstone, 0);
        this.setBlock(world, i + 11, j, k + 8, Blocks.sandstone, 0);
        this.setBlock(world, i + 11, j, k + 9, Blocks.sandstone, 0);
        this.setBlock(world, i + 11, j, k + 10, Blocks.wool, 4);
        this.setBlock(world, i + 11, j, k + 11, Blocks.sandstone, 0);
        this.setBlock(world, i + 11, j, k + 12, Blocks.wool, 4);
        this.setBlock(world, i + 11, j, k + 13, Blocks.sandstone, 0);
        this.setBlock(world, i + 11, j, k + 14, Blocks.wool, 4);
        this.setBlock(world, i + 11, j, k + 15, Blocks.sandstone, 0);
        this.setBlock(world, i + 11, j, k + 16, Blocks.wool, 4);
        this.setBlock(world, i + 11, j, k + 17, Blocks.sandstone, 0);
        this.setBlock(world, i + 11, j, k + 18, Blocks.wool, 4);
        this.setBlock(world, i + 11, j, k + 19, Blocks.sandstone, 0);
        this.setBlock(world, i + 11, j, k + 20, Blocks.wool, 4);
        this.setBlock(world, i + 11, j, k + 21, Blocks.sandstone, 0);
        this.setBlock(world, i + 11, j, k + 22, Blocks.sandstone, 0);
        this.setBlock(world, i + 11, j, k + 23, Blocks.sandstone, 0);
        this.setBlock(world, i + 11, j, k + 24, Blocks.sandstone, 0);
        this.setBlock(world, i + 11, j, k + 25, Blocks.sandstone, 0);
        this.setBlock(world, i + 11, j, k + 26, Blocks.wool, 4);
        this.setBlock(world, i + 11, j, k + 27, Blocks.sandstone, 0);
        this.setBlock(world, i + 11, j, k + 28, Blocks.sandstone, 0);
        this.setBlock(world, i + 11, j, k + 29, Blocks.sandstone, 0);
        this.setBlock(world, i + 11, j, k + 30, Blocks.sandstone, 0);
        this.setBlock(world, i + 11, j, k + 31, Blocks.sandstone, 0);
        this.setBlock(world, i + 11, j + 1, k + 3, Blocks.sandstone, 0);
        this.setBlock(world, i + 11, j + 1, k + 6, Blocks.air, 1);
        this.setBlock(world, i + 11, j + 1, k + 25, Blocks.air, 1);
        this.setBlock(world, i + 11, j + 1, k + 27, Blocks.sandstone, 0);
        this.setBlock(world, i + 11, j + 2, k + 3, Blocks.sandstone, 0);
        this.setBlock(world, i + 11, j + 2, k + 27, Blocks.sandstone, 0);
        this.setBlock(world, i + 11, j + 3, k + 3, Blocks.sandstone, 0);
        this.setBlock(world, i + 11, j + 3, k + 27, Blocks.sandstone, 0);
        this.setBlock(world, i + 11, j + 4, k + 3, Blocks.sandstone, 0);
        this.setBlock(world, i + 11, j + 4, k + 27, Blocks.sandstone, 0);
        this.setBlock(world, i + 11, j + 5, k + 4, Blocks.sandstone, 0);
        this.setBlock(world, i + 11, j + 5, k + 26, Blocks.sandstone, 0);
        this.setBlock(world, i + 11, j + 6, k + 5, Blocks.sandstone, 0);
        this.setBlock(world, i + 11, j + 6, k + 25, Blocks.sandstone, 0);
        this.setBlock(world, i + 11, j + 7, k + 5, Blocks.sandstone, 0);
        this.setBlock(world, i + 11, j + 7, k + 25, Blocks.sandstone, 0);
        this.setBlock(world, i + 11, j + 8, k + 6, Blocks.sandstone, 0);
        this.setBlock(world, i + 11, j + 8, k + 7, Blocks.sandstone, 0);
        this.setBlock(world, i + 11, j + 8, k + 23, Blocks.sandstone, 0);
        this.setBlock(world, i + 11, j + 8, k + 24, Blocks.sandstone, 0);
        this.setBlock(world, i + 11, j + 9, k + 8, Blocks.sandstone, 0);
        this.setBlock(world, i + 11, j + 9, k + 22, Blocks.sandstone, 0);
        this.setBlock(world, i + 11, j + 10, k + 9, Blocks.sandstone, 0);
        this.setBlock(world, i + 11, j + 10, k + 21, Blocks.sandstone, 0);
        this.setBlock(world, i + 11, j + 11, k + 9, Blocks.sandstone, 0);
        this.setBlock(world, i + 11, j + 11, k + 21, Blocks.sandstone, 0);
        this.setBlock(world, i + 11, j + 12, k + 10, Blocks.sandstone, 0);
        this.setBlock(world, i + 11, j + 12, k + 20, Blocks.sandstone, 0);
        this.setBlock(world, i + 11, j + 13, k + 10, Blocks.sandstone, 0);
        this.setBlock(world, i + 11, j + 13, k + 20, Blocks.sandstone, 0);
        this.setBlock(world, i + 11, j + 14, k + 11, Blocks.sandstone, 0);
        this.setBlock(world, i + 11, j + 14, k + 12, Blocks.sandstone, 0);
        this.setBlock(world, i + 11, j + 14, k + 13, Blocks.sandstone, 0);
        this.setBlock(world, i + 11, j + 14, k + 14, Blocks.sandstone, 0);
        this.setBlock(world, i + 11, j + 14, k + 15, Blocks.sandstone, 0);
        this.setBlock(world, i + 11, j + 14, k + 16, Blocks.sandstone, 0);
        this.setBlock(world, i + 11, j + 14, k + 17, Blocks.sandstone, 0);
        this.setBlock(world, i + 11, j + 14, k + 18, Blocks.sandstone, 0);
        this.setBlock(world, i + 11, j + 14, k + 19, Blocks.sandstone, 0);
        this.setBlock(world, i + 11, j + 15, k + 15, Blocks.sandstone, 0);
        this.setBlock(world, i + 12, j, k, Blocks.sandstone, 0);
        this.setBlock(world, i + 12, j, k + 1, Blocks.sandstone, 0);
        this.setBlock(world, i + 12, j, k + 2, Blocks.sandstone, 0);
        this.setBlock(world, i + 12, j, k + 3, Blocks.sandstone, 0);
        this.setBlock(world, i + 12, j, k + 4, Blocks.wool, 4);
        this.setBlock(world, i + 12, j, k + 5, Blocks.sandstone, 0);
        this.setBlock(world, i + 12, j, k + 6, Blocks.sandstone, 0);
        this.setBlock(world, i + 12, j, k + 7, Blocks.sandstone, 0);
        this.setBlock(world, i + 12, j, k + 8, Blocks.sandstone, 0);
        this.setBlock(world, i + 12, j, k + 9, Blocks.sandstone, 0);
        this.setBlock(world, i + 12, j, k + 10, Blocks.sandstone, 0);
        this.setBlock(world, i + 12, j, k + 11, Blocks.wool, 4);
        this.setBlock(world, i + 12, j, k + 12, Blocks.sandstone, 0);
        this.setBlock(world, i + 12, j, k + 13, Blocks.wool, 4);
        this.setBlock(world, i + 12, j, k + 14, Blocks.sandstone, 0);
        this.setBlock(world, i + 12, j, k + 15, Blocks.wool, 4);
        this.setBlock(world, i + 12, j, k + 16, Blocks.sandstone, 0);
        this.setBlock(world, i + 12, j, k + 17, Blocks.wool, 4);
        this.setBlock(world, i + 12, j, k + 18, Blocks.sandstone, 0);
        this.setBlock(world, i + 12, j, k + 19, Blocks.wool, 4);
        this.setBlock(world, i + 12, j, k + 20, Blocks.sandstone, 0);
        this.setBlock(world, i + 12, j, k + 21, Blocks.sandstone, 0);
        this.setBlock(world, i + 12, j, k + 22, Blocks.sandstone, 0);
        this.setBlock(world, i + 12, j, k + 23, Blocks.sandstone, 0);
        this.setBlock(world, i + 12, j, k + 24, Blocks.sandstone, 0);
        this.setBlock(world, i + 12, j, k + 25, Blocks.sandstone, 0);
        this.setBlock(world, i + 12, j, k + 26, Blocks.wool, 4);
        this.setBlock(world, i + 12, j, k + 27, Blocks.sandstone, 0);
        this.setBlock(world, i + 12, j, k + 28, Blocks.sandstone, 0);
        this.setBlock(world, i + 12, j, k + 29, Blocks.sandstone, 0);
        this.setBlock(world, i + 12, j, k + 30, Blocks.sandstone, 0);
        this.setBlock(world, i + 12, j, k + 31, Blocks.sandstone, 0);
        this.setBlock(world, i + 12, j + 1, k + 3, Blocks.sandstone, 0);
        this.setBlock(world, i + 12, j + 1, k + 12, Blocks.wool, 4);
        this.setBlock(world, i + 12, j + 1, k + 13, Blocks.wool, 4);
        this.setBlock(world, i + 12, j + 1, k + 14, Blocks.wool, 4);
        this.setBlock(world, i + 12, j + 1, k + 15, Blocks.wool, 4);
        this.setBlock(world, i + 12, j + 1, k + 16, Blocks.wool, 4);
        this.setBlock(world, i + 12, j + 1, k + 17, Blocks.wool, 4);
        this.setBlock(world, i + 12, j + 1, k + 18, Blocks.wool, 4);
        this.setBlock(world, i + 12, j + 1, k + 27, Blocks.sandstone, 0);
        this.setBlock(world, i + 12, j + 2, k + 3, Blocks.sandstone, 0);
        this.setBlock(world, i + 12, j + 2, k + 27, Blocks.sandstone, 0);
        this.setBlock(world, i + 12, j + 3, k + 3, Blocks.sandstone, 0);
        this.setBlock(world, i + 12, j + 3, k + 27, Blocks.sandstone, 0);
        this.setBlock(world, i + 12, j + 4, k + 3, Blocks.sandstone, 0);
        this.setBlock(world, i + 12, j + 4, k + 27, Blocks.sandstone, 0);
        this.setBlock(world, i + 12, j + 5, k + 4, Blocks.sandstone, 0);
        this.setBlock(world, i + 12, j + 5, k + 26, Blocks.sandstone, 0);
        this.setBlock(world, i + 12, j + 6, k + 5, Blocks.sandstone, 0);
        this.setBlock(world, i + 12, j + 6, k + 25, Blocks.sandstone, 0);
        this.setBlock(world, i + 12, j + 7, k + 5, Blocks.sandstone, 0);
        this.setBlock(world, i + 12, j + 7, k + 25, Blocks.sandstone, 0);
        this.setBlock(world, i + 12, j + 8, k + 6, Blocks.sandstone, 0);
        this.setBlock(world, i + 12, j + 8, k + 24, Blocks.sandstone, 0);
        this.setBlock(world, i + 12, j + 9, k + 7, Blocks.sandstone, 0);
        this.setBlock(world, i + 12, j + 9, k + 8, Blocks.sandstone, 0);
        this.setBlock(world, i + 12, j + 9, k + 22, Blocks.sandstone, 0);
        this.setBlock(world, i + 12, j + 9, k + 23, Blocks.sandstone, 0);
        this.setBlock(world, i + 12, j + 10, k + 9, Blocks.sandstone, 0);
        this.setBlock(world, i + 12, j + 10, k + 21, Blocks.sandstone, 0);
        this.setBlock(world, i + 12, j + 11, k + 9, Blocks.sandstone, 0);
        this.setBlock(world, i + 12, j + 11, k + 21, Blocks.sandstone, 0);
        this.setBlock(world, i + 12, j + 12, k + 10, Blocks.sandstone, 0);
        this.setBlock(world, i + 12, j + 12, k + 20, Blocks.sandstone, 0);
        this.setBlock(world, i + 12, j + 13, k + 10, Blocks.sandstone, 0);
        this.setBlock(world, i + 12, j + 13, k + 20, Blocks.sandstone, 0);
        this.setBlock(world, i + 12, j + 14, k + 11, Blocks.sandstone, 0);
        this.setBlock(world, i + 12, j + 14, k + 19, Blocks.sandstone, 0);
        this.setBlock(world, i + 12, j + 15, k + 12, Blocks.sandstone, 0);
        this.setBlock(world, i + 12, j + 15, k + 13, Blocks.sandstone, 0);
        this.setBlock(world, i + 12, j + 15, k + 14, Blocks.sandstone, 0);
        this.setBlock(world, i + 12, j + 15, k + 16, Blocks.sandstone, 0);
        this.setBlock(world, i + 12, j + 15, k + 17, Blocks.sandstone, 0);
        this.setBlock(world, i + 12, j + 15, k + 18, Blocks.sandstone, 0);
        this.setBlock(world, i + 12, j + 16, k + 14, Blocks.sandstone, 0);
        this.setBlock(world, i + 12, j + 16, k + 15, Blocks.sandstone, 0);
        this.setBlock(world, i + 12, j + 16, k + 16, Blocks.sandstone, 0);
        this.setBlock(world, i + 12, j + 17, k + 14, Blocks.sandstone, 0);
        this.setBlock(world, i + 12, j + 17, k + 16, Blocks.sandstone, 0);
        this.setBlock(world, i + 13, j, k, Blocks.sandstone, 0);
        this.setBlock(world, i + 13, j, k + 1, Blocks.sandstone, 0);
        this.setBlock(world, i + 13, j, k + 2, Blocks.sandstone, 0);
        this.setBlock(world, i + 13, j, k + 3, Blocks.sandstone, 0);
        this.setBlock(world, i + 13, j, k + 4, Blocks.wool, 4);
        this.setBlock(world, i + 13, j, k + 5, Blocks.sandstone, 0);
        this.setBlock(world, i + 13, j, k + 6, Blocks.sandstone, 0);
        this.setBlock(world, i + 13, j, k + 7, Blocks.sandstone, 0);
        this.setBlock(world, i + 13, j, k + 8, Blocks.sandstone, 0);
        this.setBlock(world, i + 13, j, k + 9, Blocks.sandstone, 0);
        this.setBlock(world, i + 13, j, k + 10, Blocks.sandstone, 0);
        this.setBlock(world, i + 13, j, k + 11, Blocks.sandstone, 0);
        this.setBlock(world, i + 13, j, k + 12, Blocks.wool, 4);
        this.setBlock(world, i + 13, j, k + 14, Blocks.sandstone, 0);
        this.setBlock(world, i + 13, j, k + 15, Blocks.sandstone, 0);
        this.setBlock(world, i + 13, j, k + 16, Blocks.sandstone, 0);
        this.setBlock(world, i + 13, j, k + 18, Blocks.wool, 4);
        this.setBlock(world, i + 13, j, k + 19, Blocks.sandstone, 0);
        this.setBlock(world, i + 13, j, k + 20, Blocks.sandstone, 0);
        this.setBlock(world, i + 13, j, k + 21, Blocks.sandstone, 0);
        this.setBlock(world, i + 13, j, k + 22, Blocks.sandstone, 0);
        this.setBlock(world, i + 13, j, k + 23, Blocks.sandstone, 0);
        this.setBlock(world, i + 13, j, k + 24, Blocks.sandstone, 0);
        this.setBlock(world, i + 13, j, k + 25, Blocks.sandstone, 0);
        this.setBlock(world, i + 13, j, k + 26, Blocks.wool, 4);
        this.setBlock(world, i + 13, j, k + 27, Blocks.sandstone, 0);
        this.setBlock(world, i + 13, j, k + 28, Blocks.sandstone, 0);
        this.setBlock(world, i + 13, j, k + 29, Blocks.sandstone, 0);
        this.setBlock(world, i + 13, j, k + 30, Blocks.sandstone, 0);
        this.setBlock(world, i + 13, j, k + 31, Blocks.sandstone, 0);
        this.setBlock(world, i + 13, j + 1, k + 3, Blocks.sandstone, 0);
        this.setBlock(world, i + 13, j + 1, k + 12, Blocks.wool, 4);
        this.setBlock(world, i + 13, j + 1, k + 13, Blocks.sandstone, 0);
        this.setBlock(world, i + 13, j + 1, k + 14, Blocks.sandstone, 0);
        this.setBlock(world, i + 13, j + 1, k + 15, Blocks.sandstone, 0);
        this.setBlock(world, i + 13, j + 1, k + 16, Blocks.sandstone, 0);
        this.setBlock(world, i + 13, j + 1, k + 17, Blocks.sandstone, 0);
        this.setBlock(world, i + 13, j + 1, k + 18, Blocks.wool, 4);
        this.setBlock(world, i + 13, j + 1, k + 27, Blocks.sandstone, 0);
        this.setBlock(world, i + 13, j + 2, k + 3, Blocks.sandstone, 0);
        this.setBlock(world, i + 13, j + 2, k + 13, Blocks.wool, 14);
        this.setBlock(world, i + 13, j + 2, k + 14, Blocks.wool, 14);
        this.setBlock(world, i + 13, j + 2, k + 15, Blocks.wool, 14);
        this.setBlock(world, i + 13, j + 2, k + 16, Blocks.wool, 14);
        this.setBlock(world, i + 13, j + 2, k + 17, Blocks.wool, 14);
        this.setBlock(world, i + 13, j + 2, k + 27, Blocks.sandstone, 0);
        this.setBlock(world, i + 13, j + 3, k + 2, Blocks.wool, 4);
        this.setBlock(world, i + 13, j + 3, k + 3, Blocks.sandstone, 0);
        this.setBlock(world, i + 13, j + 3, k + 27, Blocks.sandstone, 0);
        this.setBlock(world, i + 13, j + 3, k + 28, Blocks.wool, 4);
        this.setBlock(world, i + 13, j + 4, k + 3, Blocks.sandstone, 0);
        this.setBlock(world, i + 13, j + 4, k + 27, Blocks.sandstone, 0);
        this.setBlock(world, i + 13, j + 5, k + 4, Blocks.sandstone, 0);
        this.setBlock(world, i + 13, j + 5, k + 26, Blocks.sandstone, 0);
        this.setBlock(world, i + 13, j + 6, k + 4, Blocks.sandstone, 0);
        this.setBlock(world, i + 13, j + 6, k + 26, Blocks.sandstone, 0);
        this.setBlock(world, i + 13, j + 7, k + 5, Blocks.sandstone, 0);
        this.setBlock(world, i + 13, j + 7, k + 25, Blocks.sandstone, 0);
        this.setBlock(world, i + 13, j + 8, k + 6, Blocks.sandstone, 0);
        this.setBlock(world, i + 13, j + 8, k + 24, Blocks.sandstone, 0);
        this.setBlock(world, i + 13, j + 9, k + 7, Blocks.sandstone, 0);
        this.setBlock(world, i + 13, j + 9, k + 23, Blocks.sandstone, 0);
        this.setBlock(world, i + 13, j + 10, k + 8, Blocks.sandstone, 0);
        this.setBlock(world, i + 13, j + 10, k + 9, Blocks.sandstone, 0);
        this.setBlock(world, i + 13, j + 10, k + 21, Blocks.sandstone, 0);
        this.setBlock(world, i + 13, j + 10, k + 22, Blocks.sandstone, 0);
        this.setBlock(world, i + 13, j + 11, k + 9, Blocks.sandstone, 0);
        this.setBlock(world, i + 13, j + 11, k + 21, Blocks.sandstone, 0);
        this.setBlock(world, i + 13, j + 12, k + 10, Blocks.sandstone, 0);
        this.setBlock(world, i + 13, j + 12, k + 20, Blocks.sandstone, 0);
        this.setBlock(world, i + 13, j + 13, k + 10, Blocks.sandstone, 0);
        this.setBlock(world, i + 13, j + 13, k + 20, Blocks.sandstone, 0);
        this.setBlock(world, i + 13, j + 14, k + 11, Blocks.sandstone, 0);
        this.setBlock(world, i + 13, j + 14, k + 19, Blocks.sandstone, 0);
        this.setBlock(world, i + 13, j + 15, k + 12, Blocks.sandstone, 0);
        this.setBlock(world, i + 13, j + 15, k + 13, Blocks.sandstone, 0);
        this.setBlock(world, i + 13, j + 15, k + 17, Blocks.sandstone, 0);
        this.setBlock(world, i + 13, j + 15, k + 18, Blocks.sandstone, 0);
        this.setBlock(world, i + 13, j + 16, k + 13, Blocks.sandstone, 0);
        this.setBlock(world, i + 13, j + 16, k + 17, Blocks.sandstone, 0);
        this.setBlock(world, i + 13, j + 17, k + 13, Blocks.sandstone, 0);
        this.setBlock(world, i + 13, j + 17, k + 14, Blocks.sandstone, 0);
        this.setBlock(world, i + 13, j + 17, k + 16, Blocks.sandstone, 0);
        this.setBlock(world, i + 13, j + 17, k + 17, Blocks.sandstone, 0);
        this.setBlock(world, i + 13, j + 18, k + 13, Blocks.sandstone, 0);
        this.setBlock(world, i + 13, j + 18, k + 17, Blocks.sandstone, 0);
        this.setBlock(world, i + 14, j, k, Blocks.sandstone, 0);
        this.setBlock(world, i + 14, j, k + 1, Blocks.sandstone, 0);
        this.setBlock(world, i + 14, j, k + 2, Blocks.sandstone, 0);
        this.setBlock(world, i + 14, j, k + 3, Blocks.sandstone, 0);
        this.setBlock(world, i + 14, j, k + 4, Blocks.wool, 4);
        this.setBlock(world, i + 14, j, k + 5, Blocks.wool, 4);
        this.setBlock(world, i + 14, j, k + 6, Blocks.wool, 4);
        this.setBlock(world, i + 14, j, k + 7, Blocks.wool, 4);
        this.setBlock(world, i + 14, j, k + 8, Blocks.wool, 4);
        this.setBlock(world, i + 14, j, k + 9, Blocks.wool, 4);
        this.setBlock(world, i + 14, j, k + 10, Blocks.wool, 4);
        this.setBlock(world, i + 14, j, k + 11, Blocks.wool, 4);
        this.setBlock(world, i + 14, j, k + 12, Blocks.sandstone, 0);
        this.setBlock(world, i + 14, j, k + 13, Blocks.sandstone, 0);
        this.setBlock(world, i + 14, j, k + 14, Blocks.sandstone, 0);
        this.setBlock(world, i + 14, j, k + 15, Blocks.sandstone, 0);
        this.setBlock(world, i + 14, j, k + 16, Blocks.sandstone, 0);
        this.setBlock(world, i + 14, j, k + 17, Blocks.sandstone, 0);
        this.setBlock(world, i + 14, j, k + 18, Blocks.sandstone, 0);
        this.setBlock(world, i + 14, j, k + 19, Blocks.wool, 4);
        this.setBlock(world, i + 14, j, k + 20, Blocks.wool, 4);
        this.setBlock(world, i + 14, j, k + 21, Blocks.wool, 4);
        this.setBlock(world, i + 14, j, k + 22, Blocks.wool, 4);
        this.setBlock(world, i + 14, j, k + 23, Blocks.wool, 4);
        this.setBlock(world, i + 14, j, k + 24, Blocks.wool, 4);
        this.setBlock(world, i + 14, j, k + 25, Blocks.wool, 4);
        this.setBlock(world, i + 14, j, k + 26, Blocks.wool, 4);
        this.setBlock(world, i + 14, j, k + 27, Blocks.sandstone, 0);
        this.setBlock(world, i + 14, j, k + 28, Blocks.sandstone, 0);
        this.setBlock(world, i + 14, j, k + 29, Blocks.sandstone, 0);
        this.setBlock(world, i + 14, j, k + 30, Blocks.sandstone, 0);
        this.setBlock(world, i + 14, j, k + 31, Blocks.sandstone, 0);
        this.setBlock(world, i + 14, j + 1, k + 3, Blocks.sandstone, 0);
        this.setBlock(world, i + 14, j + 1, k + 12, Blocks.wool, 4);
        this.setBlock(world, i + 14, j + 1, k + 13, Blocks.sandstone, 0);
        this.setBlock(world, i + 14, j + 1, k + 14, Blocks.sandstone, 0);
        this.setBlock(world, i + 14, j + 1, k + 15, Blocks.sandstone, 0);
        this.setBlock(world, i + 14, j + 1, k + 16, Blocks.sandstone, 0);
        this.setBlock(world, i + 14, j + 1, k + 17, Blocks.sandstone, 0);
        this.setBlock(world, i + 14, j + 1, k + 18, Blocks.wool, 4);
        this.setBlock(world, i + 14, j + 1, k + 27, Blocks.sandstone, 0);
        this.setBlock(world, i + 14, j + 2, k + 3, Blocks.wool, 4);
        this.setBlock(world, i + 14, j + 2, k + 13, Blocks.wool, 14);
        this.setBlock(world, i + 14, j + 2, k + 14, Blocks.sandstone, 0);
        this.setBlock(world, i + 14, j + 2, k + 15, Blocks.sandstone, 0);
        this.setBlock(world, i + 14, j + 2, k + 16, Blocks.sandstone, 0);
        this.setBlock(world, i + 14, j + 2, k + 17, Blocks.wool, 14);
        this.setBlock(world, i + 14, j + 2, k + 27, Blocks.wool, 4);
        this.setBlock(world, i + 14, j + 3, k + 14, Blocks.wool, 14);
        this.setBlock(world, i + 14, j + 3, k + 15, Blocks.wool, 14);
        this.setBlock(world, i + 14, j + 3, k + 16, Blocks.wool, 14);
        this.setBlock(world, i + 14, j + 4, k + 3, Blocks.wool, 4);
        this.setBlock(world, i + 14, j + 4, k + 27, Blocks.wool, 4);
        this.setBlock(world, i + 14, j + 5, k + 3, Blocks.sandstone, 0);
        this.setBlock(world, i + 14, j + 5, k + 27, Blocks.sandstone, 0);
        this.setBlock(world, i + 14, j + 6, k + 4, Blocks.sandstone, 0);
        this.setBlock(world, i + 14, j + 6, k + 26, Blocks.sandstone, 0);
        this.setBlock(world, i + 14, j + 7, k + 5, Blocks.sandstone, 0);
        this.setBlock(world, i + 14, j + 7, k + 25, Blocks.sandstone, 0);
        this.setBlock(world, i + 14, j + 8, k + 6, Blocks.sandstone, 0);
        this.setBlock(world, i + 14, j + 8, k + 24, Blocks.sandstone, 0);
        this.setBlock(world, i + 14, j + 9, k + 7, Blocks.sandstone, 0);
        this.setBlock(world, i + 14, j + 9, k + 23, Blocks.sandstone, 0);
        this.setBlock(world, i + 14, j + 10, k + 8, Blocks.sandstone, 0);
        this.setBlock(world, i + 14, j + 10, k + 22, Blocks.sandstone, 0);
        this.setBlock(world, i + 14, j + 11, k + 8, Blocks.sandstone, 0);
        this.setBlock(world, i + 14, j + 11, k + 22, Blocks.sandstone, 0);
        this.setBlock(world, i + 14, j + 12, k + 9, Blocks.sandstone, 0);
        this.setBlock(world, i + 14, j + 12, k + 10, Blocks.sandstone, 0);
        this.setBlock(world, i + 14, j + 12, k + 20, Blocks.sandstone, 0);
        this.setBlock(world, i + 14, j + 12, k + 21, Blocks.sandstone, 0);
        this.setBlock(world, i + 14, j + 13, k + 10, Blocks.sandstone, 0);
        this.setBlock(world, i + 14, j + 13, k + 20, Blocks.sandstone, 0);
        this.setBlock(world, i + 14, j + 14, k + 11, Blocks.sandstone, 0);
        this.setBlock(world, i + 14, j + 14, k + 19, Blocks.sandstone, 0);
        this.setBlock(world, i + 14, j + 15, k + 12, Blocks.sandstone, 0);
        this.setBlock(world, i + 14, j + 15, k + 18, Blocks.sandstone, 0);
        this.setBlock(world, i + 14, j + 16, k + 12, Blocks.sandstone, 0);
        this.setBlock(world, i + 14, j + 16, k + 18, Blocks.sandstone, 0);
        this.setBlock(world, i + 14, j + 17, k + 12, Blocks.sandstone, 0);
        this.setBlock(world, i + 14, j + 17, k + 13, Blocks.sandstone, 0);
        this.setBlock(world, i + 14, j + 17, k + 17, Blocks.sandstone, 0);
        this.setBlock(world, i + 14, j + 17, k + 18, Blocks.sandstone, 0);
        this.setBlock(world, i + 15, j, k, Blocks.sandstone, 0);
        this.setBlock(world, i + 15, j, k + 1, Blocks.sandstone, 0);
        this.setBlock(world, i + 15, j, k + 2, Blocks.dirt, 0);
        this.setBlock(world, i + 15, j, k + 3, Blocks.sandstone, 0);
        this.setBlock(world, i + 15, j, k + 4, Blocks.wool, 4);
        this.setBlock(world, i + 15, j, k + 5, Blocks.sandstone, 0);
        this.setBlock(world, i + 15, j, k + 6, Blocks.sandstone, 0);
        this.setBlock(world, i + 15, j, k + 7, Blocks.sandstone, 0);
        this.setBlock(world, i + 15, j, k + 8, Blocks.sandstone, 0);
        this.setBlock(world, i + 15, j, k + 9, Blocks.sandstone, 0);
        this.setBlock(world, i + 15, j, k + 10, Blocks.sandstone, 0);
        this.setBlock(world, i + 15, j, k + 11, Blocks.sandstone, 0);
        this.setBlock(world, i + 15, j, k + 12, Blocks.wool, 4);
        this.setBlock(world, i + 15, j, k + 13, Blocks.sandstone, 0);
        this.setBlock(world, i + 15, j, k + 14, Blocks.sandstone, 0);
        this.setBlock(world, i + 15, j, k + 15, Blocks.sandstone, 0);
        this.setBlock(world, i + 15, j, k + 16, Blocks.sandstone, 0);
        this.setBlock(world, i + 15, j, k + 17, Blocks.sandstone, 0);
        this.setBlock(world, i + 15, j, k + 18, Blocks.wool, 4);
        this.setBlock(world, i + 15, j, k + 19, Blocks.sandstone, 0);
        this.setBlock(world, i + 15, j, k + 20, Blocks.sandstone, 0);
        this.setBlock(world, i + 15, j, k + 21, Blocks.sandstone, 0);
        this.setBlock(world, i + 15, j, k + 22, Blocks.sandstone, 0);
        this.setBlock(world, i + 15, j, k + 23, Blocks.sandstone, 0);
        this.setBlock(world, i + 15, j, k + 24, Blocks.sandstone, 0);
        this.setBlock(world, i + 15, j, k + 25, Blocks.sandstone, 0);
        this.setBlock(world, i + 15, j, k + 26, Blocks.sandstone, 0);
        this.setBlock(world, i + 15, j, k + 27, Blocks.sandstone, 0);
        this.setBlock(world, i + 15, j, k + 28, Blocks.dirt, 0);
        this.setBlock(world, i + 15, j, k + 29, Blocks.sandstone, 0);
        this.setBlock(world, i + 15, j, k + 30, Blocks.sandstone, 0);
        this.setBlock(world, i + 15, j, k + 31, Blocks.sandstone, 0);
        this.setBlock(world, i + 15, j + 1, k + 2, Blocks.wool, 4);
        this.setBlock(world, i + 15, j + 1, k + 3, Blocks.sandstone, 0);
        this.setBlock(world, i + 15, j + 1, k + 12, Blocks.wool, 4);
        this.setBlock(world, i + 15, j + 1, k + 13, Blocks.sandstone, 0);
        this.setBlock(world, i + 15, j + 1, k + 14, Blocks.sandstone, 0);
        this.setBlock(world, i + 15, j + 1, k + 15, Blocks.sandstone, 0);
        this.setBlock(world, i + 15, j + 1, k + 16, Blocks.sandstone, 0);
        this.setBlock(world, i + 15, j + 1, k + 17, Blocks.sandstone, 0);
        this.setBlock(world, i + 15, j + 1, k + 18, Blocks.wool, 4);
        this.setBlock(world, i + 15, j + 1, k + 27, Blocks.sandstone, 0);
        this.setBlock(world, i + 15, j + 1, k + 28, Blocks.wool, 4);
        this.setBlock(world, i + 15, j + 2, k + 13, Blocks.wool, 14);
        this.setBlock(world, i + 15, j + 2, k + 14, Blocks.sandstone, 0);
        this.setBlock(world, i + 15, j + 2, k + 15, Blocks.sandstone, 0);
        this.setBlock(world, i + 15, j + 2, k + 16, Blocks.sandstone, 0);
        this.setBlock(world, i + 15, j + 2, k + 17, Blocks.wool, 14);
        this.setBlock(world, i + 15, j + 3, k + 14, Blocks.wool, 14);
        Dungeons.spawner(world, i + 15, j + 4, k + 15, 24, 3);
        this.setBlock(world, i + 15, j + 3, k + 16, Blocks.wool, 14);
        WorldGenWarlordDungeon.chest(world, rand, i + 15, j + 3, k + 15, "dungeonChest", 10);
        this.setBlock(world, i + 15, j + 5, k + 2, Blocks.wool, 4);
        this.setBlock(world, i + 15, j + 5, k + 3, Blocks.sandstone, 0);
        this.setBlock(world, i + 15, j + 5, k + 27, Blocks.sandstone, 0);
        this.setBlock(world, i + 15, j + 5, k + 28, Blocks.wool, 4);
        this.setBlock(world, i + 15, j + 6, k + 4, Blocks.sandstone, 0);
        this.setBlock(world, i + 15, j + 6, k + 26, Blocks.sandstone, 0);
        this.setBlock(world, i + 15, j + 7, k + 5, Blocks.sandstone, 0);
        this.setBlock(world, i + 15, j + 7, k + 25, Blocks.sandstone, 0);
        this.setBlock(world, i + 15, j + 8, k + 6, Blocks.sandstone, 0);
        this.setBlock(world, i + 15, j + 8, k + 24, Blocks.sandstone, 0);
        this.setBlock(world, i + 15, j + 9, k + 7, Blocks.sandstone, 0);
        this.setBlock(world, i + 15, j + 9, k + 23, Blocks.sandstone, 0);
        this.setBlock(world, i + 15, j + 10, k + 8, Blocks.sandstone, 0);
        this.setBlock(world, i + 15, j + 10, k + 22, Blocks.sandstone, 0);
        this.setBlock(world, i + 15, j + 11, k + 8, Blocks.sandstone, 0);
        this.setBlock(world, i + 15, j + 11, k + 22, Blocks.sandstone, 0);
        this.setBlock(world, i + 15, j + 12, k + 9, Blocks.sandstone, 0);
        this.setBlock(world, i + 15, j + 12, k + 21, Blocks.sandstone, 0);
        this.setBlock(world, i + 15, j + 13, k + 9, Blocks.sandstone, 0);
        this.setBlock(world, i + 15, j + 13, k + 21, Blocks.sandstone, 0);
        this.setBlock(world, i + 15, j + 14, k + 10, Blocks.sandstone, 0);
        this.setBlock(world, i + 15, j + 14, k + 11, Blocks.sandstone, 0);
        this.setBlock(world, i + 15, j + 14, k + 19, Blocks.sandstone, 0);
        this.setBlock(world, i + 15, j + 14, k + 20, Blocks.sandstone, 0);
        this.setBlock(world, i + 15, j + 15, k + 11, Blocks.sandstone, 0);
        this.setBlock(world, i + 15, j + 15, k + 19, Blocks.sandstone, 0);
        this.setBlock(world, i + 15, j + 16, k + 12, Blocks.sandstone, 0);
        this.setBlock(world, i + 15, j + 16, k + 18, Blocks.sandstone, 0);
        this.setBlock(world, i + 16, j, k, Blocks.sandstone, 0);
        this.setBlock(world, i + 16, j, k + 1, Blocks.sandstone, 0);
        this.setBlock(world, i + 16, j, k + 2, Blocks.sandstone, 0);
        this.setBlock(world, i + 16, j, k + 3, Blocks.sandstone, 0);
        this.setBlock(world, i + 16, j, k + 4, Blocks.wool, 4);
        this.setBlock(world, i + 16, j, k + 5, Blocks.wool, 4);
        this.setBlock(world, i + 16, j, k + 6, Blocks.wool, 4);
        this.setBlock(world, i + 16, j, k + 7, Blocks.wool, 4);
        this.setBlock(world, i + 16, j, k + 8, Blocks.wool, 4);
        this.setBlock(world, i + 16, j, k + 9, Blocks.wool, 4);
        this.setBlock(world, i + 16, j, k + 10, Blocks.wool, 4);
        this.setBlock(world, i + 16, j, k + 11, Blocks.wool, 4);
        this.setBlock(world, i + 16, j, k + 12, Blocks.sandstone, 0);
        this.setBlock(world, i + 16, j, k + 13, Blocks.sandstone, 0);
        this.setBlock(world, i + 16, j, k + 14, Blocks.sandstone, 0);
        this.setBlock(world, i + 16, j, k + 15, Blocks.sandstone, 0);
        this.setBlock(world, i + 16, j, k + 16, Blocks.sandstone, 0);
        this.setBlock(world, i + 16, j, k + 17, Blocks.sandstone, 0);
        this.setBlock(world, i + 16, j, k + 18, Blocks.sandstone, 0);
        this.setBlock(world, i + 16, j, k + 19, Blocks.wool, 4);
        this.setBlock(world, i + 16, j, k + 20, Blocks.wool, 4);
        this.setBlock(world, i + 16, j, k + 21, Blocks.wool, 4);
        this.setBlock(world, i + 16, j, k + 22, Blocks.wool, 4);
        this.setBlock(world, i + 16, j, k + 23, Blocks.wool, 4);
        this.setBlock(world, i + 16, j, k + 24, Blocks.wool, 4);
        this.setBlock(world, i + 16, j, k + 25, Blocks.wool, 4);
        this.setBlock(world, i + 16, j, k + 26, Blocks.wool, 4);
        this.setBlock(world, i + 16, j, k + 27, Blocks.sandstone, 0);
        this.setBlock(world, i + 16, j, k + 28, Blocks.sandstone, 0);
        this.setBlock(world, i + 16, j, k + 29, Blocks.sandstone, 0);
        this.setBlock(world, i + 16, j, k + 30, Blocks.sandstone, 0);
        this.setBlock(world, i + 16, j, k + 31, Blocks.sandstone, 0);
        this.setBlock(world, i + 16, j + 1, k + 3, Blocks.sandstone, 0);
        this.setBlock(world, i + 16, j + 1, k + 12, Blocks.wool, 4);
        this.setBlock(world, i + 16, j + 1, k + 13, Blocks.sandstone, 0);
        this.setBlock(world, i + 16, j + 1, k + 14, Blocks.sandstone, 0);
        this.setBlock(world, i + 16, j + 1, k + 15, Blocks.sandstone, 0);
        this.setBlock(world, i + 16, j + 1, k + 16, Blocks.sandstone, 0);
        this.setBlock(world, i + 16, j + 1, k + 17, Blocks.sandstone, 0);
        this.setBlock(world, i + 16, j + 1, k + 18, Blocks.wool, 4);
        this.setBlock(world, i + 16, j + 1, k + 27, Blocks.sandstone, 0);
        this.setBlock(world, i + 16, j + 2, k + 3, Blocks.wool, 4);
        this.setBlock(world, i + 16, j + 2, k + 13, Blocks.wool, 14);
        this.setBlock(world, i + 16, j + 2, k + 14, Blocks.sandstone, 0);
        this.setBlock(world, i + 16, j + 2, k + 15, Blocks.sandstone, 0);
        this.setBlock(world, i + 16, j + 2, k + 16, Blocks.sandstone, 0);
        this.setBlock(world, i + 16, j + 2, k + 17, Blocks.wool, 14);
        this.setBlock(world, i + 16, j + 2, k + 27, Blocks.wool, 4);
        this.setBlock(world, i + 16, j + 3, k + 14, Blocks.wool, 14);
        this.setBlock(world, i + 16, j + 3, k + 15, Blocks.wool, 14);
        this.setBlock(world, i + 16, j + 3, k + 16, Blocks.wool, 14);
        this.setBlock(world, i + 16, j + 4, k + 3, Blocks.wool, 4);
        this.setBlock(world, i + 16, j + 4, k + 27, Blocks.wool, 4);
        this.setBlock(world, i + 16, j + 5, k + 3, Blocks.sandstone, 0);
        this.setBlock(world, i + 16, j + 5, k + 27, Blocks.sandstone, 0);
        this.setBlock(world, i + 16, j + 6, k + 4, Blocks.sandstone, 0);
        this.setBlock(world, i + 16, j + 6, k + 26, Blocks.sandstone, 0);
        this.setBlock(world, i + 16, j + 7, k + 5, Blocks.sandstone, 0);
        this.setBlock(world, i + 16, j + 7, k + 25, Blocks.sandstone, 0);
        this.setBlock(world, i + 16, j + 8, k + 6, Blocks.sandstone, 0);
        this.setBlock(world, i + 16, j + 8, k + 24, Blocks.sandstone, 0);
        this.setBlock(world, i + 16, j + 9, k + 7, Blocks.sandstone, 0);
        this.setBlock(world, i + 16, j + 9, k + 23, Blocks.sandstone, 0);
        this.setBlock(world, i + 16, j + 10, k + 8, Blocks.sandstone, 0);
        this.setBlock(world, i + 16, j + 10, k + 22, Blocks.sandstone, 0);
        this.setBlock(world, i + 16, j + 11, k + 8, Blocks.sandstone, 0);
        this.setBlock(world, i + 16, j + 11, k + 22, Blocks.sandstone, 0);
        this.setBlock(world, i + 16, j + 12, k + 9, Blocks.sandstone, 0);
        this.setBlock(world, i + 16, j + 12, k + 10, Blocks.sandstone, 0);
        this.setBlock(world, i + 16, j + 12, k + 20, Blocks.sandstone, 0);
        this.setBlock(world, i + 16, j + 12, k + 21, Blocks.sandstone, 0);
        this.setBlock(world, i + 16, j + 13, k + 10, Blocks.sandstone, 0);
        this.setBlock(world, i + 16, j + 13, k + 20, Blocks.sandstone, 0);
        this.setBlock(world, i + 16, j + 14, k + 11, Blocks.sandstone, 0);
        this.setBlock(world, i + 16, j + 14, k + 19, Blocks.sandstone, 0);
        this.setBlock(world, i + 16, j + 15, k + 12, Blocks.sandstone, 0);
        this.setBlock(world, i + 16, j + 15, k + 18, Blocks.sandstone, 0);
        this.setBlock(world, i + 16, j + 16, k + 12, Blocks.sandstone, 0);
        this.setBlock(world, i + 16, j + 16, k + 18, Blocks.sandstone, 0);
        this.setBlock(world, i + 16, j + 17, k + 12, Blocks.sandstone, 0);
        this.setBlock(world, i + 16, j + 17, k + 13, Blocks.sandstone, 0);
        this.setBlock(world, i + 16, j + 17, k + 17, Blocks.sandstone, 0);
        this.setBlock(world, i + 16, j + 17, k + 18, Blocks.sandstone, 0);
        this.setBlock(world, i + 17, j, k, Blocks.sandstone, 0);
        this.setBlock(world, i + 17, j, k + 1, Blocks.sandstone, 0);
        this.setBlock(world, i + 17, j, k + 2, Blocks.sandstone, 0);
        this.setBlock(world, i + 17, j, k + 3, Blocks.sandstone, 0);
        this.setBlock(world, i + 17, j, k + 4, Blocks.wool, 4);
        this.setBlock(world, i + 17, j, k + 5, Blocks.sandstone, 0);
        this.setBlock(world, i + 17, j, k + 6, Blocks.sandstone, 0);
        this.setBlock(world, i + 17, j, k + 7, Blocks.sandstone, 0);
        this.setBlock(world, i + 17, j, k + 8, Blocks.sandstone, 0);
        this.setBlock(world, i + 17, j, k + 9, Blocks.sandstone, 0);
        this.setBlock(world, i + 17, j, k + 10, Blocks.sandstone, 0);
        this.setBlock(world, i + 17, j, k + 11, Blocks.sandstone, 0);
        this.setBlock(world, i + 17, j, k + 12, Blocks.wool, 4);
        this.setBlock(world, i + 17, j, k + 14, Blocks.sandstone, 0);
        this.setBlock(world, i + 17, j, k + 15, Blocks.sandstone, 0);
        this.setBlock(world, i + 17, j, k + 16, Blocks.sandstone, 0);
        this.setBlock(world, i + 17, j, k + 18, Blocks.wool, 4);
        this.setBlock(world, i + 17, j, k + 19, Blocks.sandstone, 0);
        this.setBlock(world, i + 17, j, k + 20, Blocks.sandstone, 0);
        this.setBlock(world, i + 17, j, k + 21, Blocks.sandstone, 0);
        this.setBlock(world, i + 17, j, k + 22, Blocks.sandstone, 0);
        this.setBlock(world, i + 17, j, k + 23, Blocks.sandstone, 0);
        this.setBlock(world, i + 17, j, k + 24, Blocks.sandstone, 0);
        this.setBlock(world, i + 17, j, k + 25, Blocks.sandstone, 0);
        this.setBlock(world, i + 17, j, k + 26, Blocks.wool, 4);
        this.setBlock(world, i + 17, j, k + 27, Blocks.sandstone, 0);
        this.setBlock(world, i + 17, j, k + 28, Blocks.sandstone, 0);
        this.setBlock(world, i + 17, j, k + 29, Blocks.sandstone, 0);
        this.setBlock(world, i + 17, j, k + 30, Blocks.sandstone, 0);
        this.setBlock(world, i + 17, j, k + 31, Blocks.sandstone, 0);
        this.setBlock(world, i + 17, j + 1, k + 3, Blocks.sandstone, 0);
        this.setBlock(world, i + 17, j + 1, k + 8, Blocks.air, 1);
        this.setBlock(world, i + 17, j + 1, k + 12, Blocks.wool, 4);
        this.setBlock(world, i + 17, j + 1, k + 13, Blocks.sandstone, 0);
        this.setBlock(world, i + 17, j + 1, k + 14, Blocks.sandstone, 0);
        this.setBlock(world, i + 17, j + 1, k + 15, Blocks.sandstone, 0);
        this.setBlock(world, i + 17, j + 1, k + 16, Blocks.sandstone, 0);
        this.setBlock(world, i + 17, j + 1, k + 17, Blocks.sandstone, 0);
        this.setBlock(world, i + 17, j + 1, k + 18, Blocks.wool, 4);
        this.setBlock(world, i + 17, j + 1, k + 27, Blocks.sandstone, 0);
        this.setBlock(world, i + 17, j + 2, k + 3, Blocks.sandstone, 0);
        this.setBlock(world, i + 17, j + 2, k + 13, Blocks.wool, 14);
        this.setBlock(world, i + 17, j + 2, k + 14, Blocks.wool, 14);
        this.setBlock(world, i + 17, j + 2, k + 15, Blocks.wool, 14);
        this.setBlock(world, i + 17, j + 2, k + 16, Blocks.wool, 14);
        this.setBlock(world, i + 17, j + 2, k + 17, Blocks.wool, 14);
        this.setBlock(world, i + 17, j + 2, k + 27, Blocks.sandstone, 0);
        this.setBlock(world, i + 17, j + 3, k + 2, Blocks.wool, 4);
        this.setBlock(world, i + 17, j + 3, k + 3, Blocks.sandstone, 0);
        this.setBlock(world, i + 17, j + 3, k + 27, Blocks.sandstone, 0);
        this.setBlock(world, i + 17, j + 3, k + 28, Blocks.wool, 4);
        this.setBlock(world, i + 17, j + 4, k + 3, Blocks.sandstone, 0);
        this.setBlock(world, i + 17, j + 4, k + 27, Blocks.sandstone, 0);
        this.setBlock(world, i + 17, j + 5, k + 4, Blocks.sandstone, 0);
        this.setBlock(world, i + 17, j + 5, k + 26, Blocks.sandstone, 0);
        this.setBlock(world, i + 17, j + 6, k + 4, Blocks.sandstone, 0);
        this.setBlock(world, i + 17, j + 6, k + 26, Blocks.sandstone, 0);
        this.setBlock(world, i + 17, j + 7, k + 5, Blocks.sandstone, 0);
        this.setBlock(world, i + 17, j + 7, k + 25, Blocks.sandstone, 0);
        this.setBlock(world, i + 17, j + 8, k + 6, Blocks.sandstone, 0);
        this.setBlock(world, i + 17, j + 8, k + 24, Blocks.sandstone, 0);
        this.setBlock(world, i + 17, j + 9, k + 7, Blocks.sandstone, 0);
        this.setBlock(world, i + 17, j + 9, k + 23, Blocks.sandstone, 0);
        this.setBlock(world, i + 17, j + 10, k + 8, Blocks.sandstone, 0);
        this.setBlock(world, i + 17, j + 10, k + 9, Blocks.sandstone, 0);
        this.setBlock(world, i + 17, j + 10, k + 21, Blocks.sandstone, 0);
        this.setBlock(world, i + 17, j + 10, k + 22, Blocks.sandstone, 0);
        this.setBlock(world, i + 17, j + 11, k + 9, Blocks.sandstone, 0);
        this.setBlock(world, i + 17, j + 11, k + 21, Blocks.sandstone, 0);
        this.setBlock(world, i + 17, j + 12, k + 10, Blocks.sandstone, 0);
        this.setBlock(world, i + 17, j + 12, k + 20, Blocks.sandstone, 0);
        this.setBlock(world, i + 17, j + 13, k + 10, Blocks.sandstone, 0);
        this.setBlock(world, i + 17, j + 13, k + 20, Blocks.sandstone, 0);
        this.setBlock(world, i + 17, j + 14, k + 11, Blocks.sandstone, 0);
        this.setBlock(world, i + 17, j + 14, k + 19, Blocks.sandstone, 0);
        this.setBlock(world, i + 17, j + 15, k + 12, Blocks.sandstone, 0);
        this.setBlock(world, i + 17, j + 15, k + 13, Blocks.sandstone, 0);
        this.setBlock(world, i + 17, j + 15, k + 17, Blocks.sandstone, 0);
        this.setBlock(world, i + 17, j + 15, k + 18, Blocks.sandstone, 0);
        this.setBlock(world, i + 17, j + 16, k + 13, Blocks.sandstone, 0);
        this.setBlock(world, i + 17, j + 16, k + 17, Blocks.sandstone, 0);
        this.setBlock(world, i + 17, j + 17, k + 13, Blocks.sandstone, 0);
        this.setBlock(world, i + 17, j + 17, k + 14, Blocks.sandstone, 0);
        this.setBlock(world, i + 17, j + 17, k + 16, Blocks.sandstone, 0);
        this.setBlock(world, i + 17, j + 17, k + 17, Blocks.sandstone, 0);
        this.setBlock(world, i + 17, j + 18, k + 13, Blocks.sandstone, 0);
        this.setBlock(world, i + 17, j + 18, k + 17, Blocks.sandstone, 0);
        this.setBlock(world, i + 18, j, k, Blocks.sandstone, 0);
        this.setBlock(world, i + 18, j, k + 1, Blocks.sandstone, 0);
        this.setBlock(world, i + 18, j, k + 2, Blocks.sandstone, 0);
        this.setBlock(world, i + 18, j, k + 3, Blocks.sandstone, 0);
        this.setBlock(world, i + 18, j, k + 4, Blocks.wool, 4);
        this.setBlock(world, i + 18, j, k + 5, Blocks.sandstone, 0);
        this.setBlock(world, i + 18, j, k + 6, Blocks.sandstone, 0);
        this.setBlock(world, i + 18, j, k + 7, Blocks.sandstone, 0);
        this.setBlock(world, i + 18, j, k + 8, Blocks.sandstone, 0);
        this.setBlock(world, i + 18, j, k + 9, Blocks.sandstone, 0);
        this.setBlock(world, i + 18, j, k + 10, Blocks.sandstone, 0);
        this.setBlock(world, i + 18, j, k + 11, Blocks.wool, 4);
        this.setBlock(world, i + 18, j, k + 12, Blocks.sandstone, 0);
        this.setBlock(world, i + 18, j, k + 13, Blocks.wool, 4);
        this.setBlock(world, i + 18, j, k + 14, Blocks.sandstone, 0);
        this.setBlock(world, i + 18, j, k + 15, Blocks.wool, 4);
        this.setBlock(world, i + 18, j, k + 16, Blocks.sandstone, 0);
        this.setBlock(world, i + 18, j, k + 17, Blocks.wool, 4);
        this.setBlock(world, i + 18, j, k + 18, Blocks.sandstone, 0);
        this.setBlock(world, i + 18, j, k + 19, Blocks.wool, 4);
        this.setBlock(world, i + 18, j, k + 20, Blocks.sandstone, 0);
        this.setBlock(world, i + 18, j, k + 21, Blocks.sandstone, 0);
        this.setBlock(world, i + 18, j, k + 22, Blocks.sandstone, 0);
        this.setBlock(world, i + 18, j, k + 23, Blocks.sandstone, 0);
        this.setBlock(world, i + 18, j, k + 24, Blocks.sandstone, 0);
        this.setBlock(world, i + 18, j, k + 25, Blocks.sandstone, 0);
        this.setBlock(world, i + 18, j, k + 26, Blocks.wool, 4);
        this.setBlock(world, i + 18, j, k + 27, Blocks.sandstone, 0);
        this.setBlock(world, i + 18, j, k + 28, Blocks.sandstone, 0);
        this.setBlock(world, i + 18, j, k + 29, Blocks.sandstone, 0);
        this.setBlock(world, i + 18, j, k + 30, Blocks.sandstone, 0);
        this.setBlock(world, i + 18, j, k + 31, Blocks.sandstone, 0);
        this.setBlock(world, i + 18, j + 1, k + 3, Blocks.sandstone, 0);
        this.setBlock(world, i + 18, j + 1, k + 12, Blocks.wool, 4);
        this.setBlock(world, i + 18, j + 1, k + 13, Blocks.wool, 4);
        this.setBlock(world, i + 18, j + 1, k + 14, Blocks.wool, 4);
        this.setBlock(world, i + 18, j + 1, k + 15, Blocks.wool, 4);
        this.setBlock(world, i + 18, j + 1, k + 16, Blocks.wool, 4);
        this.setBlock(world, i + 18, j + 1, k + 17, Blocks.wool, 4);
        this.setBlock(world, i + 18, j + 1, k + 18, Blocks.wool, 4);
        this.setBlock(world, i + 18, j + 1, k + 27, Blocks.sandstone, 0);
        this.setBlock(world, i + 18, j + 2, k + 3, Blocks.sandstone, 0);
        this.setBlock(world, i + 18, j + 2, k + 27, Blocks.sandstone, 0);
        this.setBlock(world, i + 18, j + 3, k + 3, Blocks.sandstone, 0);
        this.setBlock(world, i + 18, j + 3, k + 27, Blocks.sandstone, 0);
        this.setBlock(world, i + 18, j + 4, k + 3, Blocks.sandstone, 0);
        this.setBlock(world, i + 18, j + 4, k + 27, Blocks.sandstone, 0);
        this.setBlock(world, i + 18, j + 5, k + 4, Blocks.sandstone, 0);
        this.setBlock(world, i + 18, j + 5, k + 26, Blocks.sandstone, 0);
        this.setBlock(world, i + 18, j + 6, k + 5, Blocks.sandstone, 0);
        this.setBlock(world, i + 18, j + 6, k + 25, Blocks.sandstone, 0);
        this.setBlock(world, i + 18, j + 7, k + 5, Blocks.sandstone, 0);
        this.setBlock(world, i + 18, j + 7, k + 25, Blocks.sandstone, 0);
        this.setBlock(world, i + 18, j + 8, k + 6, Blocks.sandstone, 0);
        this.setBlock(world, i + 18, j + 8, k + 24, Blocks.sandstone, 0);
        this.setBlock(world, i + 18, j + 9, k + 7, Blocks.sandstone, 0);
        this.setBlock(world, i + 18, j + 9, k + 8, Blocks.sandstone, 0);
        this.setBlock(world, i + 18, j + 9, k + 22, Blocks.sandstone, 0);
        this.setBlock(world, i + 18, j + 9, k + 23, Blocks.sandstone, 0);
        this.setBlock(world, i + 18, j + 10, k + 9, Blocks.sandstone, 0);
        this.setBlock(world, i + 18, j + 10, k + 21, Blocks.sandstone, 0);
        this.setBlock(world, i + 18, j + 11, k + 9, Blocks.sandstone, 0);
        this.setBlock(world, i + 18, j + 11, k + 21, Blocks.sandstone, 0);
        this.setBlock(world, i + 18, j + 12, k + 10, Blocks.sandstone, 0);
        this.setBlock(world, i + 18, j + 12, k + 20, Blocks.sandstone, 0);
        this.setBlock(world, i + 18, j + 13, k + 10, Blocks.sandstone, 0);
        this.setBlock(world, i + 18, j + 13, k + 20, Blocks.sandstone, 0);
        this.setBlock(world, i + 18, j + 14, k + 11, Blocks.sandstone, 0);
        this.setBlock(world, i + 18, j + 14, k + 19, Blocks.sandstone, 0);
        this.setBlock(world, i + 18, j + 15, k + 12, Blocks.sandstone, 0);
        this.setBlock(world, i + 18, j + 15, k + 13, Blocks.sandstone, 0);
        this.setBlock(world, i + 18, j + 15, k + 14, Blocks.sandstone, 0);
        this.setBlock(world, i + 18, j + 15, k + 16, Blocks.sandstone, 0);
        this.setBlock(world, i + 18, j + 15, k + 17, Blocks.sandstone, 0);
        this.setBlock(world, i + 18, j + 15, k + 18, Blocks.sandstone, 0);
        this.setBlock(world, i + 18, j + 16, k + 14, Blocks.sandstone, 0);
        this.setBlock(world, i + 18, j + 16, k + 15, Blocks.sandstone, 0);
        this.setBlock(world, i + 18, j + 16, k + 16, Blocks.sandstone, 0);
        this.setBlock(world, i + 18, j + 17, k + 14, Blocks.sandstone, 0);
        this.setBlock(world, i + 18, j + 17, k + 16, Blocks.sandstone, 0);
        this.setBlock(world, i + 19, j, k, Blocks.sandstone, 0);
        this.setBlock(world, i + 19, j, k + 1, Blocks.sandstone, 0);
        this.setBlock(world, i + 19, j, k + 2, Blocks.sandstone, 0);
        this.setBlock(world, i + 19, j, k + 3, Blocks.sandstone, 0);
        this.setBlock(world, i + 19, j, k + 4, Blocks.wool, 4);
        this.setBlock(world, i + 19, j, k + 5, Blocks.sandstone, 0);
        this.setBlock(world, i + 19, j, k + 6, Blocks.sandstone, 0);
        this.setBlock(world, i + 19, j, k + 7, Blocks.sandstone, 0);
        this.setBlock(world, i + 19, j, k + 8, Blocks.sandstone, 0);
        this.setBlock(world, i + 19, j, k + 9, Blocks.sandstone, 0);
        this.setBlock(world, i + 19, j, k + 10, Blocks.wool, 4);
        this.setBlock(world, i + 19, j, k + 11, Blocks.sandstone, 0);
        this.setBlock(world, i + 19, j, k + 12, Blocks.wool, 4);
        this.setBlock(world, i + 19, j, k + 13, Blocks.sandstone, 0);
        this.setBlock(world, i + 19, j, k + 14, Blocks.wool, 4);
        this.setBlock(world, i + 19, j, k + 15, Blocks.sandstone, 0);
        this.setBlock(world, i + 19, j, k + 16, Blocks.wool, 4);
        this.setBlock(world, i + 19, j, k + 17, Blocks.sandstone, 0);
        this.setBlock(world, i + 19, j, k + 18, Blocks.wool, 4);
        this.setBlock(world, i + 19, j, k + 19, Blocks.sandstone, 0);
        this.setBlock(world, i + 19, j, k + 20, Blocks.wool, 4);
        this.setBlock(world, i + 19, j, k + 21, Blocks.sandstone, 0);
        this.setBlock(world, i + 19, j, k + 22, Blocks.sandstone, 0);
        this.setBlock(world, i + 19, j, k + 23, Blocks.sandstone, 0);
        this.setBlock(world, i + 19, j, k + 24, Blocks.sandstone, 0);
        this.setBlock(world, i + 19, j, k + 25, Blocks.sandstone, 0);
        this.setBlock(world, i + 19, j, k + 26, Blocks.wool, 4);
        this.setBlock(world, i + 19, j, k + 27, Blocks.sandstone, 0);
        this.setBlock(world, i + 19, j, k + 28, Blocks.sandstone, 0);
        this.setBlock(world, i + 19, j, k + 29, Blocks.sandstone, 0);
        this.setBlock(world, i + 19, j, k + 30, Blocks.sandstone, 0);
        this.setBlock(world, i + 19, j, k + 31, Blocks.sandstone, 0);
        this.setBlock(world, i + 19, j + 1, k + 3, Blocks.sandstone, 0);
        this.setBlock(world, i + 19, j + 1, k + 23, Blocks.air, 1);
        this.setBlock(world, i + 19, j + 1, k + 27, Blocks.sandstone, 0);
        this.setBlock(world, i + 19, j + 2, k + 3, Blocks.sandstone, 0);
        this.setBlock(world, i + 19, j + 2, k + 27, Blocks.sandstone, 0);
        this.setBlock(world, i + 19, j + 3, k + 3, Blocks.sandstone, 0);
        this.setBlock(world, i + 19, j + 3, k + 27, Blocks.sandstone, 0);
