

package com.gibby.dungeon.gen;

import com.gibby.dungeon.Dungeons;
import cpw.mods.fml.common.IWorldGenerator;
import net.minecraft.block.Block;
import net.minecraft.init.Blocks;
import net.minecraft.world.IBlockAccess;
import net.minecraft.world.World;
import net.minecraft.world.chunk.IChunkProvider;
import net.minecraft.world.gen.feature.WorldGenerator;

import java.util.Random;

public class WorldGenMontaneDungeon_2 extends WorldGenerator implements IWorldGenerator
{
    public void generate(final Random random, final int chunkX, final int chunkZ, final World world, final IChunkProvider chunkGenerator, final IChunkProvider chunkProvider) {
    }

    public void setBlock(final World world, final int x, final int y, final int z, final Block block, final int metadata) {
        final Block b1 = world.getBlock(x, y, z);
        if (b1.isAir((IBlockAccess)world, x, y, z) || b1.isLeaves((IBlockAccess)world, x, y, z)) {
            world.setBlock(x, y, z, block, metadata, 2);
        }
    }

    public boolean generate(final World world, final Random rand, final int i, final int j, final int k) {
        this.setBlock(world, i, j + 35, k + 31, Blocks.stonebrick, 0);
        this.setBlock(world, i, j + 35, k + 32, Blocks.wooden_slab, 8);
        this.setBlock(world, i, j + 35, k + 36, Blocks.wooden_slab, 8);
        this.setBlock(world, i, j + 35, k + 37, Blocks.stonebrick, 0);
        this.setBlock(world, i, j + 36, k + 31, Blocks.stonebrick, 0);
        this.setBlock(world, i, j + 36, k + 32, Blocks.stonebrick, 0);
        this.setBlock(world, i, j + 36, k + 33, Blocks.stonebrick, 0);
        this.setBlock(world, i, j + 36, k + 34, Blocks.stonebrick, 0);
        this.setBlock(world, i, j + 36, k + 35, Blocks.stonebrick, 0);
        this.setBlock(world, i, j + 36, k + 36, Blocks.stonebrick, 0);
        this.setBlock(world, i, j + 36, k + 37, Blocks.stonebrick, 0);
        this.setBlock(world, i, j + 37, k + 31, Blocks.stonebrick, 0);
        this.setBlock(world, i, j + 37, k + 37, Blocks.stonebrick, 0);
        this.setBlock(world, i, j + 71, k + 75, Blocks.air, 15);
        this.setBlock(world, i + 1, j + 35, k + 32, Blocks.wooden_slab, 8);
        this.setBlock(world, i + 1, j + 35, k + 36, Blocks.wooden_slab, 8);
        this.setBlock(world, i + 1, j + 36, k + 32, Blocks.stonebrick, 0);
        this.setBlock(world, i + 1, j + 36, k + 33, Blocks.stonebrick, 0);
        this.setBlock(world, i + 1, j + 36, k + 34, Blocks.stonebrick, 0);
        this.setBlock(world, i + 1, j + 36, k + 35, Blocks.stonebrick, 0);
        this.setBlock(world, i + 1, j + 36, k + 36, Blocks.stonebrick, 0);
        this.setBlock(world, i + 2, j + 35, k + 32, Blocks.wooden_slab, 8);
        this.setBlock(world, i + 2, j + 35, k + 36, Blocks.wooden_slab, 8);
        this.setBlock(world, i + 2, j + 36, k + 32, Blocks.stonebrick, 0);
        this.setBlock(world, i + 2, j + 36, k + 33, Blocks.stonebrick, 0);
        this.setBlock(world, i + 2, j + 36, k + 34, Blocks.stonebrick, 0);
        this.setBlock(world, i + 2, j + 36, k + 35, Blocks.stonebrick, 0);
        this.setBlock(world, i + 2, j + 36, k + 36, Blocks.stonebrick, 0);
        this.setBlock(world, i + 3, j + 35, k + 31, Blocks.stonebrick, 0);
        this.setBlock(world, i + 3, j + 35, k + 32, Blocks.wooden_slab, 8);
        this.setBlock(world, i + 3, j + 35, k + 36, Blocks.wooden_slab, 8);
        this.setBlock(world, i + 3, j + 35, k + 37, Blocks.stonebrick, 0);
        this.setBlock(world, i + 3, j + 36, k + 31, Blocks.stonebrick, 0);
        this.setBlock(world, i + 3, j + 36, k + 32, Blocks.stonebrick, 0);
        this.setBlock(world, i + 3, j + 36, k + 33, Blocks.stonebrick, 0);
        this.setBlock(world, i + 3, j + 36, k + 34, Blocks.stonebrick, 0);
        this.setBlock(world, i + 3, j + 36, k + 35, Blocks.stonebrick, 0);
        this.setBlock(world, i + 3, j + 36, k + 36, Blocks.stonebrick, 0);
        this.setBlock(world, i + 3, j + 36, k + 37, Blocks.stonebrick, 0);
        this.setBlock(world, i + 3, j + 37, k + 31, Blocks.stonebrick, 0);
        this.setBlock(world, i + 3, j + 37, k + 37, Blocks.stonebrick, 0);
        this.setBlock(world, i + 4, j + 35, k + 32, Blocks.planks, 0);
        this.setBlock(world, i + 4, j + 35, k + 36, Blocks.planks, 0);
        this.setBlock(world, i + 4, j + 36, k + 32, Blocks.stonebrick, 0);
        this.setBlock(world, i + 4, j + 36, k + 33, Blocks.stonebrick, 0);
        this.setBlock(world, i + 4, j + 36, k + 34, Blocks.stonebrick, 0);
        this.setBlock(world, i + 4, j + 36, k + 35, Blocks.stonebrick, 0);
        this.setBlock(world, i + 4, j + 36, k + 36, Blocks.stonebrick, 0);
        this.setBlock(world, i + 5, j + 35, k + 32, Blocks.planks, 0);
        this.setBlock(world, i + 5, j + 35, k + 36, Blocks.planks, 0);
        this.setBlock(world, i + 5, j + 36, k + 32, Blocks.stonebrick, 0);
        this.setBlock(world, i + 5, j + 36, k + 33, Blocks.stonebrick, 0);
        this.setBlock(world, i + 5, j + 36, k + 34, Blocks.stonebrick, 0);
        this.setBlock(world, i + 5, j + 36, k + 35, Blocks.stonebrick, 0);
        this.setBlock(world, i + 5, j + 36, k + 36, Blocks.stonebrick, 0);
        this.setBlock(world, i + 6, j + 35, k + 31, Blocks.stonebrick, 0);
        this.setBlock(world, i + 6, j + 35, k + 32, Blocks.planks, 0);
        this.setBlock(world, i + 6, j + 35, k + 36, Blocks.planks, 0);
        this.setBlock(world, i + 6, j + 35, k + 37, Blocks.stonebrick, 0);
        this.setBlock(world, i + 6, j + 36, k + 31, Blocks.stonebrick, 0);
        this.setBlock(world, i + 6, j + 36, k + 32, Blocks.stonebrick, 0);
        this.setBlock(world, i + 6, j + 36, k + 33, Blocks.stonebrick, 0);
        this.setBlock(world, i + 6, j + 36, k + 34, Blocks.stonebrick, 0);
        this.setBlock(world, i + 6, j + 36, k + 35, Blocks.stonebrick, 0);
        this.setBlock(world, i + 6, j + 36, k + 36, Blocks.stonebrick, 0);
        this.setBlock(world, i + 6, j + 36, k + 37, Blocks.stonebrick, 0);
        this.setBlock(world, i + 6, j + 37, k + 31, Blocks.stonebrick, 0);
        this.setBlock(world, i + 6, j + 37, k + 37, Blocks.stonebrick, 0);
        this.setBlock(world, i + 7, j + 28, k + 43, Blocks.stone, 0);
        this.setBlock(world, i + 7, j + 28, k + 44, Blocks.stone, 0);
        this.setBlock(world, i + 7, j + 28, k + 45, Blocks.stone, 0);
        this.setBlock(world, i + 7, j + 28, k + 46, Blocks.stone, 0);
        this.setBlock(world, i + 7, j + 28, k + 47, Blocks.stone, 0);
        this.setBlock(world, i + 7, j + 28, k + 48, Blocks.stone, 0);
        this.setBlock(world, i + 7, j + 28, k + 49, Blocks.stone, 0);
        this.setBlock(world, i + 7, j + 28, k + 50, Blocks.stone, 0);
        this.setBlock(world, i + 7, j + 29, k + 44, Blocks.stone, 0);
        this.setBlock(world, i + 7, j + 29, k + 45, Blocks.stone, 0);
        this.setBlock(world, i + 7, j + 34, k + 32, Blocks.planks, 0);
        this.setBlock(world, i + 7, j + 34, k + 36, Blocks.planks, 0);
        this.setBlock(world, i + 7, j + 35, k + 32, Blocks.planks, 0);
        this.setBlock(world, i + 7, j + 35, k + 36, Blocks.planks, 0);
        this.setBlock(world, i + 7, j + 36, k + 32, Blocks.stonebrick, 0);
        this.setBlock(world, i + 7, j + 36, k + 33, Blocks.stonebrick, 0);
        this.setBlock(world, i + 7, j + 36, k + 34, Blocks.stonebrick, 0);
        this.setBlock(world, i + 7, j + 36, k + 35, Blocks.stonebrick, 0);
        this.setBlock(world, i + 7, j + 36, k + 36, Blocks.stonebrick, 0);
        Dungeons.spawner(world, i + 7, j + 37, k + 34, 28, 2);
        this.setBlock(world, i + 8, j + 26, k + 44, Blocks.bedrock, 0);
        this.setBlock(world, i + 8, j + 27, k + 43, Blocks.bedrock, 0);
        this.setBlock(world, i + 8, j + 27, k + 44, Blocks.bedrock, 0);
        this.setBlock(world, i + 8, j + 27, k + 45, Blocks.stone, 0);
        this.setBlock(world, i + 8, j + 27, k + 46, Blocks.stone, 0);
        this.setBlock(world, i + 8, j + 27, k + 47, Blocks.stone, 0);
        this.setBlock(world, i + 8, j + 27, k + 48, Blocks.stone, 0);
        this.setBlock(world, i + 8, j + 27, k + 49, Blocks.stone, 0);
        this.setBlock(world, i + 8, j + 28, k + 42, Blocks.stone, 0);
        this.setBlock(world, i + 8, j + 28, k + 43, Blocks.stone, 0);
        this.setBlock(world, i + 8, j + 28, k + 44, Blocks.stone, 0);
        this.setBlock(world, i + 8, j + 28, k + 45, Blocks.stone, 0);
        this.setBlock(world, i + 8, j + 28, k + 46, Blocks.stone, 0);
        this.setBlock(world, i + 8, j + 28, k + 47, Blocks.stone, 0);
        this.setBlock(world, i + 8, j + 28, k + 48, Blocks.stone, 0);
        this.setBlock(world, i + 8, j + 28, k + 49, Blocks.stone, 0);
        this.setBlock(world, i + 8, j + 28, k + 50, Blocks.stone, 0);
        this.setBlock(world, i + 8, j + 28, k + 51, Blocks.cobblestone, 0);
        this.setBlock(world, i + 8, j + 28, k + 52, Blocks.cobblestone, 0);
        this.setBlock(world, i + 8, j + 29, k + 43, Blocks.stone, 0);
        this.setBlock(world, i + 8, j + 29, k + 44, Blocks.stone, 0);
        this.setBlock(world, i + 8, j + 29, k + 45, Blocks.stone, 0);
        this.setBlock(world, i + 8, j + 29, k + 46, Blocks.stone, 0);
        this.setBlock(world, i + 8, j + 29, k + 47, Blocks.stone, 0);
        this.setBlock(world, i + 8, j + 29, k + 48, Blocks.stone, 0);
        this.setBlock(world, i + 8, j + 30, k + 43, Blocks.stone, 0);
        this.setBlock(world, i + 8, j + 30, k + 44, Blocks.bedrock, 0);
        this.setBlock(world, i + 8, j + 34, k + 32, Blocks.planks, 0);
        this.setBlock(world, i + 8, j + 34, k + 36, Blocks.planks, 0);
        this.setBlock(world, i + 8, j + 36, k + 32, Blocks.stonebrick, 0);
        this.setBlock(world, i + 8, j + 36, k + 33, Blocks.stonebrick, 0);
        this.setBlock(world, i + 8, j + 36, k + 34, Blocks.stonebrick, 0);
        this.setBlock(world, i + 8, j + 36, k + 35, Blocks.stonebrick, 0);
        this.setBlock(world, i + 8, j + 36, k + 36, Blocks.stonebrick, 0);
        this.setBlock(world, i + 9, j + 25, k + 43, Blocks.stone, 0);
        this.setBlock(world, i + 9, j + 25, k + 44, Blocks.stone, 0);
        this.setBlock(world, i + 9, j + 25, k + 45, Blocks.stone, 0);
        this.setBlock(world, i + 9, j + 26, k + 42, Blocks.stone, 0);
        this.setBlock(world, i + 9, j + 26, k + 43, Blocks.stone, 0);
        this.setBlock(world, i + 9, j + 26, k + 44, Blocks.stone, 0);
        this.setBlock(world, i + 9, j + 26, k + 45, Blocks.stone, 0);
        this.setBlock(world, i + 9, j + 26, k + 46, Blocks.stone, 0);
        this.setBlock(world, i + 9, j + 26, k + 47, Blocks.stone, 0);
        this.setBlock(world, i + 9, j + 26, k + 48, Blocks.stone, 0);
        this.setBlock(world, i + 9, j + 26, k + 49, Blocks.cobblestone, 0);
        this.setBlock(world, i + 9, j + 27, k + 41, Blocks.stone, 0);
        this.setBlock(world, i + 9, j + 27, k + 42, Blocks.stone, 0);
        this.setBlock(world, i + 9, j + 27, k + 43, Blocks.stone, 0);
        this.setBlock(world, i + 9, j + 27, k + 44, Blocks.stone, 0);
        this.setBlock(world, i + 9, j + 27, k + 45, Blocks.stone, 0);
        this.setBlock(world, i + 9, j + 27, k + 46, Blocks.stone, 0);
        this.setBlock(world, i + 9, j + 27, k + 47, Blocks.stone, 0);
        this.setBlock(world, i + 9, j + 27, k + 48, Blocks.stone, 0);
        this.setBlock(world, i + 9, j + 27, k + 49, Blocks.stone, 0);
        this.setBlock(world, i + 9, j + 27, k + 50, Blocks.stone, 0);
        this.setBlock(world, i + 9, j + 27, k + 51, Blocks.cobblestone, 0);
        this.setBlock(world, i + 9, j + 28, k + 41, Blocks.stone, 0);
        this.setBlock(world, i + 9, j + 28, k + 42, Blocks.stone, 0);
        this.setBlock(world, i + 9, j + 28, k + 43, Blocks.cobblestone, 0);
        this.setBlock(world, i + 9, j + 28, k + 44, Blocks.stone, 0);
        this.setBlock(world, i + 9, j + 28, k + 45, Blocks.stone, 0);
        this.setBlock(world, i + 9, j + 28, k + 46, Blocks.stone, 0);
        this.setBlock(world, i + 9, j + 28, k + 47, Blocks.stone, 0);
        this.setBlock(world, i + 9, j + 28, k + 48, Blocks.stone, 0);
        this.setBlock(world, i + 9, j + 28, k + 49, Blocks.stone, 0);
        this.setBlock(world, i + 9, j + 28, k + 50, Blocks.stone, 0);
        this.setBlock(world, i + 9, j + 28, k + 51, Blocks.stone, 0);
        this.setBlock(world, i + 9, j + 28, k + 52, Blocks.stone, 0);
        this.setBlock(world, i + 9, j + 28, k + 53, Blocks.stone, 0);
        this.setBlock(world, i + 9, j + 29, k + 41, Blocks.stone, 0);
        this.setBlock(world, i + 9, j + 29, k + 42, Blocks.stone, 0);
        this.setBlock(world, i + 9, j + 29, k + 43, Blocks.stone, 0);
        this.setBlock(world, i + 9, j + 29, k + 44, Blocks.stone, 0);
        this.setBlock(world, i + 9, j + 29, k + 45, Blocks.stone, 0);
        this.setBlock(world, i + 9, j + 29, k + 46, Blocks.stone, 0);
        this.setBlock(world, i + 9, j + 29, k + 47, Blocks.cobblestone, 0);
        this.setBlock(world, i + 9, j + 29, k + 48, Blocks.stone, 0);
        this.setBlock(world, i + 9, j + 29, k + 49, Blocks.stone, 0);
        this.setBlock(world, i + 9, j + 29, k + 50, Blocks.stone, 0);
        this.setBlock(world, i + 9, j + 30, k + 41, Blocks.stone, 0);
        this.setBlock(world, i + 9, j + 30, k + 42, Blocks.cobblestone, 0);
        this.setBlock(world, i + 9, j + 30, k + 43, Blocks.stone, 0);
        this.setBlock(world, i + 9, j + 30, k + 44, Blocks.stone, 0);
        this.setBlock(world, i + 9, j + 30, k + 45, Blocks.bedrock, 0);
        this.setBlock(world, i + 9, j + 30, k + 46, Blocks.cobblestone, 0);
        this.setBlock(world, i + 9, j + 33, k + 32, Blocks.planks, 0);
        this.setBlock(world, i + 9, j + 33, k + 36, Blocks.planks, 0);
        this.setBlock(world, i + 9, j + 34, k + 32, Blocks.planks, 0);
        this.setBlock(world, i + 9, j + 34, k + 36, Blocks.planks, 0);
        this.setBlock(world, i + 9, j + 35, k + 31, Blocks.stonebrick, 0);
        this.setBlock(world, i + 9, j + 35, k + 37, Blocks.stonebrick, 0);
        this.setBlock(world, i + 9, j + 36, k + 31, Blocks.stonebrick, 0);
        this.setBlock(world, i + 9, j + 36, k + 32, Blocks.stonebrick, 0);
        this.setBlock(world, i + 9, j + 36, k + 33, Blocks.stonebrick, 0);
        this.setBlock(world, i + 9, j + 36, k + 34, Blocks.stonebrick, 0);
        this.setBlock(world, i + 9, j + 36, k + 35, Blocks.stonebrick, 0);
        this.setBlock(world, i + 9, j + 36, k + 36, Blocks.stonebrick, 0);
        this.setBlock(world, i + 9, j + 36, k + 37, Blocks.stonebrick, 0);
        this.setBlock(world, i + 9, j + 37, k + 31, Blocks.stonebrick, 0);
        this.setBlock(world, i + 9, j + 37, k + 37, Blocks.stonebrick, 0);
        this.setBlock(world, i + 10, j + 24, k + 44, Blocks.cobblestone, 0);
        this.setBlock(world, i + 10, j + 25, k + 42, Blocks.stone, 0);
        this.setBlock(world, i + 10, j + 25, k + 43, Blocks.stone, 0);
        this.setBlock(world, i + 10, j + 25, k + 44, Blocks.bedrock, 0);
        this.setBlock(world, i + 10, j + 25, k + 45, Blocks.stone, 0);
        this.setBlock(world, i + 10, j + 25, k + 46, Blocks.stone, 0);
        this.setBlock(world, i + 10, j + 25, k + 47, Blocks.stone, 0);
        this.setBlock(world, i + 10, j + 25, k + 48, Blocks.stone, 0);
        this.setBlock(world, i + 10, j + 26, k + 41, Blocks.stone, 0);
        this.setBlock(world, i + 10, j + 26, k + 42, Blocks.stone, 0);
        this.setBlock(world, i + 10, j + 26, k + 43, Blocks.stone, 0);
        this.setBlock(world, i + 10, j + 26, k + 44, Blocks.stone, 0);
        this.setBlock(world, i + 10, j + 26, k + 45, Blocks.cobblestone, 0);
        this.setBlock(world, i + 10, j + 26, k + 46, Blocks.bedrock, 0);
        this.setBlock(world, i + 10, j + 26, k + 47, Blocks.stone, 0);
        this.setBlock(world, i + 10, j + 26, k + 48, Blocks.cobblestone, 0);
        this.setBlock(world, i + 10, j + 26, k + 49, Blocks.stone, 0);
        this.setBlock(world, i + 10, j + 26, k + 50, Blocks.stone, 0);
        this.setBlock(world, i + 10, j + 27, k + 39, Blocks.stone, 0);
        this.setBlock(world, i + 10, j + 27, k + 41, Blocks.stone, 0);
        this.setBlock(world, i + 10, j + 27, k + 42, Blocks.stone, 0);
        this.setBlock(world, i + 10, j + 27, k + 43, Blocks.stone, 0);
        this.setBlock(world, i + 10, j + 27, k + 44, Blocks.stone, 0);
        this.setBlock(world, i + 10, j + 27, k + 45, Blocks.bedrock, 0);
        this.setBlock(world, i + 10, j + 27, k + 46, Blocks.bedrock, 0);
        this.setBlock(world, i + 10, j + 27, k + 47, Blocks.stone, 0);
        this.setBlock(world, i + 10, j + 27, k + 48, Blocks.stone, 0);
        this.setBlock(world, i + 10, j + 27, k + 49, Blocks.stone, 0);
        this.setBlock(world, i + 10, j + 27, k + 50, Blocks.stone, 0);
        this.setBlock(world, i + 10, j + 27, k + 51, Blocks.bedrock, 0);
        this.setBlock(world, i + 10, j + 27, k + 52, Blocks.stone, 0);
        this.setBlock(world, i + 10, j + 28, k + 40, Blocks.bedrock, 0);
        this.setBlock(world, i + 10, j + 28, k + 41, Blocks.stone, 0);
        this.setBlock(world, i + 10, j + 28, k + 42, Blocks.cobblestone, 0);
        this.setBlock(world, i + 10, j + 28, k + 43, Blocks.stone, 0);
        this.setBlock(world, i + 10, j + 28, k + 44, Blocks.stone, 0);
        this.setBlock(world, i + 10, j + 28, k + 45, Blocks.stone, 0);
        this.setBlock(world, i + 10, j + 28, k + 46, Blocks.cobblestone, 0);
        this.setBlock(world, i + 10, j + 28, k + 47, Blocks.stone, 0);
        this.setBlock(world, i + 10, j + 28, k + 48, Blocks.stone, 0);
        this.setBlock(world, i + 10, j + 28, k + 49, Blocks.bedrock, 0);
        this.setBlock(world, i + 10, j + 28, k + 50, Blocks.stone, 0);
        this.setBlock(world, i + 10, j + 28, k + 51, Blocks.stone, 0);
        this.setBlock(world, i + 10, j + 28, k + 52, Blocks.stone, 0);
        this.setBlock(world, i + 10, j + 28, k + 53, Blocks.bedrock, 0);
        this.setBlock(world, i + 10, j + 28, k + 54, Blocks.cobblestone, 0);
        this.setBlock(world, i + 10, j + 29, k + 41, Blocks.stone, 0);
        this.setBlock(world, i + 10, j + 29, k + 42, Blocks.cobblestone, 0);
        this.setBlock(world, i + 10, j + 29, k + 43, Blocks.stone, 0);
        this.setBlock(world, i + 10, j + 29, k + 44, Blocks.bedrock, 0);
        this.setBlock(world, i + 10, j + 29, k + 45, Blocks.bedrock, 0);
        this.setBlock(world, i + 10, j + 29, k + 46, Blocks.stone, 0);
        this.setBlock(world, i + 10, j + 29, k + 47, Blocks.cobblestone, 0);
        this.setBlock(world, i + 10, j + 29, k + 48, Blocks.bedrock, 0);
        this.setBlock(world, i + 10, j + 29, k + 49, Blocks.stone, 0);
        this.setBlock(world, i + 10, j + 29, k + 50, Blocks.stone, 0);
        this.setBlock(world, i + 10, j + 29, k + 51, Blocks.bedrock, 0);
        this.setBlock(world, i + 10, j + 29, k + 52, Blocks.stone, 0);
        this.setBlock(world, i + 10, j + 30, k + 41, Blocks.stone, 0);
        this.setBlock(world, i + 10, j + 30, k + 42, Blocks.cobblestone, 0);
        this.setBlock(world, i + 10, j + 30, k + 43, Blocks.stone, 0);
        this.setBlock(world, i + 10, j + 30, k + 44, Blocks.stone, 0);
        this.setBlock(world, i + 10, j + 30, k + 45, Blocks.stone, 0);
        this.setBlock(world, i + 10, j + 30, k + 46, Blocks.stone, 0);
        this.setBlock(world, i + 10, j + 30, k + 47, Blocks.cobblestone, 0);
        this.setBlock(world, i + 10, j + 30, k + 48, Blocks.bedrock, 0);
        this.setBlock(world, i + 10, j + 31, k + 42, Blocks.stone, 0);
        this.setBlock(world, i + 10, j + 31, k + 43, Blocks.bedrock, 0);
        this.setBlock(world, i + 10, j + 31, k + 44, Blocks.cobblestone, 0);
        this.setBlock(world, i + 10, j + 31, k + 45, Blocks.stone, 0);
        this.setBlock(world, i + 10, j + 32, k + 32, Blocks.planks, 0);
        this.setBlock(world, i + 10, j + 32, k + 36, Blocks.planks, 0);
        this.setBlock(world, i + 10, j + 33, k + 32, Blocks.planks, 0);
        this.setBlock(world, i + 10, j + 33, k + 36, Blocks.planks, 0);
        this.setBlock(world, i + 10, j + 36, k + 32, Blocks.stonebrick, 0);
        this.setBlock(world, i + 10, j + 36, k + 33, Blocks.stonebrick, 0);
        this.setBlock(world, i + 10, j + 36, k + 34, Blocks.stonebrick, 0);
        this.setBlock(world, i + 10, j + 36, k + 35, Blocks.stonebrick, 0);
        this.setBlock(world, i + 10, j + 36, k + 36, Blocks.stonebrick, 0);
        this.setBlock(world, i + 11, j + 24, k + 43, Blocks.cobblestone, 0);
        this.setBlock(world, i + 11, j + 24, k + 44, Blocks.bedrock, 0);
        this.setBlock(world, i + 11, j + 24, k + 45, Blocks.bedrock, 0);
        this.setBlock(world, i + 11, j + 25, k + 41, Blocks.cobblestone, 0);
        this.setBlock(world, i + 11, j + 25, k + 42, Blocks.bedrock, 0);
        this.setBlock(world, i + 11, j + 25, k + 43, Blocks.cobblestone, 0);
        this.setBlock(world, i + 11, j + 25, k + 44, Blocks.bedrock, 0);
        this.setBlock(world, i + 11, j + 25, k + 45, Blocks.stone, 0);
        this.setBlock(world, i + 11, j + 25, k + 46, Blocks.stone, 0);
        this.setBlock(world, i + 11, j + 25, k + 47, Blocks.stone, 0);
        this.setBlock(world, i + 11, j + 25, k + 48, Blocks.stone, 0);
        this.setBlock(world, i + 11, j + 25, k + 49, Blocks.stone, 0);
        this.setBlock(world, i + 11, j + 25, k + 50, Blocks.stone, 0);
        this.setBlock(world, i + 11, j + 26, k + 41, Blocks.stone, 0);
        this.setBlock(world, i + 11, j + 26, k + 42, Blocks.cobblestone, 0);
        this.setBlock(world, i + 11, j + 26, k + 43, Blocks.stone, 0);
        this.setBlock(world, i + 11, j + 26, k + 44, Blocks.stone, 0);
        this.setBlock(world, i + 11, j + 26, k + 45, Blocks.stone, 0);
        this.setBlock(world, i + 11, j + 26, k + 46, Blocks.cobblestone, 0);
        this.setBlock(world, i + 11, j + 26, k + 47, Blocks.stone, 0);
        this.setBlock(world, i + 11, j + 26, k + 48, Blocks.stone, 0);
        this.setBlock(world, i + 11, j + 26, k + 49, Blocks.stone, 0);
        this.setBlock(world, i + 11, j + 26, k + 50, Blocks.stone, 0);
        this.setBlock(world, i + 11, j + 26, k + 51, Blocks.cobblestone, 0);
        this.setBlock(world, i + 11, j + 27, k + 40, Blocks.stone, 0);
        this.setBlock(world, i + 11, j + 27, k + 41, Blocks.stone, 0);
        this.setBlock(world, i + 11, j + 27, k + 42, Blocks.bedrock, 0);
        this.setBlock(world, i + 11, j + 27, k + 43, Blocks.cobblestone, 0);
        this.setBlock(world, i + 11, j + 27, k + 44, Blocks.stone, 0);
        this.setBlock(world, i + 11, j + 27, k + 45, Blocks.stone, 0);
        this.setBlock(world, i + 11, j + 27, k + 46, Blocks.stone, 0);
        this.setBlock(world, i + 11, j + 27, k + 47, Blocks.stone, 0);
        this.setBlock(world, i + 11, j + 27, k + 48, Blocks.bedrock, 0);
        this.setBlock(world, i + 11, j + 27, k + 49, Blocks.stone, 0);
        this.setBlock(world, i + 11, j + 27, k + 50, Blocks.stone, 0);
        this.setBlock(world, i + 11, j + 27, k + 51, Blocks.stone, 0);
        this.setBlock(world, i + 11, j + 27, k + 52, Blocks.bedrock, 0);
        this.setBlock(world, i + 11, j + 27, k + 53, Blocks.stone, 0);
        this.setBlock(world, i + 11, j + 28, k + 33, Blocks.stone, 0);
        this.setBlock(world, i + 11, j + 28, k + 34, Blocks.stone, 0);
        this.setBlock(world, i + 11, j + 28, k + 35, Blocks.cobblestone, 0);
        this.setBlock(world, i + 11, j + 28, k + 36, Blocks.stone, 0);
        this.setBlock(world, i + 11, j + 28, k + 37, Blocks.stone, 0);
        this.setBlock(world, i + 11, j + 28, k + 38, Blocks.bedrock, 0);
        this.setBlock(world, i + 11, j + 28, k + 39, Blocks.stone, 0);
        this.setBlock(world, i + 11, j + 28, k + 40, Blocks.stone, 0);
        this.setBlock(world, i + 11, j + 28, k + 41, Blocks.stone, 0);
        this.setBlock(world, i + 11, j + 28, k + 42, Blocks.stone, 0);
        this.setBlock(world, i + 11, j + 28, k + 43, Blocks.cobblestone, 0);
        this.setBlock(world, i + 11, j + 28, k + 44, Blocks.stone, 0);
        this.setBlock(world, i + 11, j + 28, k + 45, Blocks.stone, 0);
        this.setBlock(world, i + 11, j + 28, k + 46, Blocks.stone, 0);
        this.setBlock(world, i + 11, j + 28, k + 47, Blocks.stone, 0);
        this.setBlock(world, i + 11, j + 28, k + 48, Blocks.bedrock, 0);
        this.setBlock(world, i + 11, j + 28, k + 49, Blocks.stone, 0);
        this.setBlock(world, i + 11, j + 28, k + 50, Blocks.stone, 0);
        this.setBlock(world, i + 11, j + 28, k + 51, Blocks.stone, 0);
        this.setBlock(world, i + 11, j + 28, k + 52, Blocks.stone, 0);
        this.setBlock(world, i + 11, j + 28, k + 53, Blocks.stone, 0);
        this.setBlock(world, i + 11, j + 28, k + 54, Blocks.cobblestone, 0);
        this.setBlock(world, i + 11, j + 28, k + 55, Blocks.stone, 0);
        this.setBlock(world, i + 11, j + 28, k + 56, Blocks.bedrock, 0);
        this.setBlock(world, i + 11, j + 28, k + 57, Blocks.stone, 0);
        this.setBlock(world, i + 11, j + 29, k + 40, Blocks.stone, 0);
        this.setBlock(world, i + 11, j + 29, k + 41, Blocks.stone, 0);
        this.setBlock(world, i + 11, j + 29, k + 42, Blocks.stone, 0);
        this.setBlock(world, i + 11, j + 29, k + 43, Blocks.stone, 0);
        this.setBlock(world, i + 11, j + 29, k + 44, Blocks.stone, 0);
        this.setBlock(world, i + 11, j + 29, k + 45, Blocks.cobblestone, 0);
        this.setBlock(world, i + 11, j + 29, k + 46, Blocks.cobblestone, 0);
        this.setBlock(world, i + 11, j + 29, k + 47, Blocks.stone, 0);
        this.setBlock(world, i + 11, j + 29, k + 48, Blocks.stone, 0);
        this.setBlock(world, i + 11, j + 29, k + 49, Blocks.stone, 0);
        this.setBlock(world, i + 11, j + 29, k + 50, Blocks.cobblestone, 0);
        this.setBlock(world, i + 11, j + 29, k + 51, Blocks.stone, 0);
        this.setBlock(world, i + 11, j + 29, k + 52, Blocks.stone, 0);
        this.setBlock(world, i + 11, j + 29, k + 53, Blocks.stone, 0);
        this.setBlock(world, i + 11, j + 29, k + 54, Blocks.bedrock, 0);
        this.setBlock(world, i + 11, j + 30, k + 32, Blocks.planks, 0);
        this.setBlock(world, i + 11, j + 30, k + 36, Blocks.planks, 0);
        this.setBlock(world, i + 11, j + 30, k + 40, Blocks.stone, 0);
        this.setBlock(world, i + 11, j + 30, k + 41, Blocks.stone, 0);
        this.setBlock(world, i + 11, j + 30, k + 42, Blocks.stone, 0);
        this.setBlock(world, i + 11, j + 30, k + 43, Blocks.stone, 0);
        this.setBlock(world, i + 11, j + 30, k + 44, Blocks.cobblestone, 0);
        this.setBlock(world, i + 11, j + 30, k + 45, Blocks.stone, 0);
        this.setBlock(world, i + 11, j + 30, k + 46, Blocks.stone, 0);
        this.setBlock(world, i + 11, j + 30, k + 47, Blocks.stone, 0);
        this.setBlock(world, i + 11, j + 30, k + 48, Blocks.bedrock, 0);
        this.setBlock(world, i + 11, j + 30, k + 49, Blocks.stone, 0);
        this.setBlock(world, i + 11, j + 30, k + 50, Blocks.stone, 0);
        this.setBlock(world, i + 11, j + 30, k + 51, Blocks.cobblestone, 0);
        this.setBlock(world, i + 11, j + 30, k + 52, Blocks.stone, 0);
        this.setBlock(world, i + 11, j + 31, k + 32, Blocks.planks, 0);
        this.setBlock(world, i + 11, j + 31, k + 36, Blocks.planks, 0);
        this.setBlock(world, i + 11, j + 31, k + 42, Blocks.stone, 0);
        this.setBlock(world, i + 11, j + 31, k + 43, Blocks.stone, 0);
        this.setBlock(world, i + 11, j + 31, k + 44, Blocks.bedrock, 0);
        this.setBlock(world, i + 11, j + 31, k + 45, Blocks.bedrock, 0);
        this.setBlock(world, i + 11, j + 31, k + 46, Blocks.bedrock, 0);
        this.setBlock(world, i + 11, j + 31, k + 47, Blocks.stone, 0);
        this.setBlock(world, i + 11, j + 31, k + 48, Blocks.stone, 0);
        this.setBlock(world, i + 11, j + 32, k + 32, Blocks.planks, 0);
        this.setBlock(world, i + 11, j + 32, k + 36, Blocks.planks, 0);
        this.setBlock(world, i + 11, j + 36, k + 32, Blocks.stonebrick, 0);
        this.setBlock(world, i + 11, j + 36, k + 33, Blocks.stonebrick, 0);
        this.setBlock(world, i + 11, j + 36, k + 34, Blocks.stonebrick, 0);
        this.setBlock(world, i + 11, j + 36, k + 35, Blocks.stonebrick, 0);
        this.setBlock(world, i + 11, j + 36, k + 36, Blocks.stonebrick, 0);
        this.setBlock(world, i + 12, j + 24, k + 42, Blocks.stone, 0);
        this.setBlock(world, i + 12, j + 24, k + 43, Blocks.stone, 0);
        this.setBlock(world, i + 12, j + 24, k + 44, Blocks.stone, 0);
        this.setBlock(world, i + 12, j + 24, k + 45, Blocks.cobblestone, 0);
        this.setBlock(world, i + 12, j + 24, k + 46, Blocks.stone, 0);
        this.setBlock(world, i + 12, j + 24, k + 47, Blocks.stone, 0);
        this.setBlock(world, i + 12, j + 24, k + 48, Blocks.stone, 0);
        this.setBlock(world, i + 12, j + 24, k + 49, Blocks.cobblestone, 0);
        this.setBlock(world, i + 12, j + 25, k + 41, Blocks.stone, 0);
        this.setBlock(world, i + 12, j + 25, k + 42, Blocks.cobblestone, 0);
        this.setBlock(world, i + 12, j + 25, k + 43, Blocks.stone, 0);
        this.setBlock(world, i + 12, j + 25, k + 44, Blocks.stone, 0);
        this.setBlock(world, i + 12, j + 25, k + 45, Blocks.cobblestone, 0);
        this.setBlock(world, i + 12, j + 25, k + 46, Blocks.stone, 0);
        this.setBlock(world, i + 12, j + 25, k + 47, Blocks.bedrock, 0);
        this.setBlock(world, i + 12, j + 25, k + 48, Blocks.cobblestone, 0);
        this.setBlock(world, i + 12, j + 25, k + 49, Blocks.stone, 0);
        this.setBlock(world, i + 12, j + 25, k + 50, Blocks.stone, 0);
        this.setBlock(world, i + 12, j + 25, k + 51, Blocks.stone, 0);
        this.setBlock(world, i + 12, j + 26, k + 39, Blocks.bedrock, 0);
        this.setBlock(world, i + 12, j + 26, k + 40, Blocks.stone, 0);
        this.setBlock(world, i + 12, j + 26, k + 41, Blocks.stone, 0);
        this.setBlock(world, i + 12, j + 26, k + 42, Blocks.stone, 0);
        this.setBlock(world, i + 12, j + 26, k + 43, Blocks.stone, 0);
        this.setBlock(world, i + 12, j + 26, k + 44, Blocks.stone, 0);
        this.setBlock(world, i + 12, j + 26, k + 45, Blocks.stone, 0);
        this.setBlock(world, i + 12, j + 26, k + 46, Blocks.stone, 0);
        this.setBlock(world, i + 12, j + 26, k + 47, Blocks.stone, 0);
        this.setBlock(world, i + 12, j + 26, k + 48, Blocks.stone, 0);
        this.setBlock(world, i + 12, j + 26, k + 49, Blocks.bedrock, 0);
        this.setBlock(world, i + 12, j + 26, k + 50, Blocks.stone, 0);
        this.setBlock(world, i + 12, j + 26, k + 51, Blocks.stone, 0);
        this.setBlock(world, i + 12, j + 26, k + 52, Blocks.stone, 0);
        this.setBlock(world, i + 12, j + 26, k + 53, Blocks.cobblestone, 0);
        this.setBlock(world, i + 12, j + 27, k + 34, Blocks.stone, 0);
        this.setBlock(world, i + 12, j + 27, k + 35, Blocks.stone, 0);
        this.setBlock(world, i + 12, j + 27, k + 36, Blocks.stone, 0);
        this.setBlock(world, i + 12, j + 27, k + 37, Blocks.stone, 0);
        this.setBlock(world, i + 12, j + 27, k + 38, Blocks.bedrock, 0);
        this.setBlock(world, i + 12, j + 27, k + 39, Blocks.cobblestone, 0);
        this.setBlock(world, i + 12, j + 27, k + 40, Blocks.stone, 0);
        this.setBlock(world, i + 12, j + 27, k + 41, Blocks.bedrock, 0);
        this.setBlock(world, i + 12, j + 27, k + 42, Blocks.bedrock, 0);
        this.setBlock(world, i + 12, j + 27, k + 43, Blocks.bedrock, 0);
        this.setBlock(world, i + 12, j + 27, k + 44, Blocks.stone, 0);
        this.setBlock(world, i + 12, j + 27, k + 45, Blocks.stone, 0);
        this.setBlock(world, i + 12, j + 27, k + 46, Blocks.stone, 0);
        this.setBlock(world, i + 12, j + 27, k + 47, Blocks.cobblestone, 0);
        this.setBlock(world, i + 12, j + 27, k + 48, Blocks.stone, 0);
        this.setBlock(world, i + 12, j + 27, k + 49, Blocks.stone, 0);
        this.setBlock(world, i + 12, j + 27, k + 50, Blocks.stone, 0);
        this.setBlock(world, i + 12, j + 27, k + 51, Blocks.stone, 0);
        this.setBlock(world, i + 12, j + 27, k + 52, Blocks.stone, 0);
        this.setBlock(world, i + 12, j + 27, k + 53, Blocks.stone, 0);
        this.setBlock(world, i + 12, j + 27, k + 54, Blocks.stone, 0);
        this.setBlock(world, i + 12, j + 27, k + 55, Blocks.bedrock, 0);
        this.setBlock(world, i + 12, j + 27, k + 56, Blocks.cobblestone, 0);
        this.setBlock(world, i + 12, j + 28, k + 32, Blocks.planks, 0);
        this.setBlock(world, i + 12, j + 28, k + 33, Blocks.stone, 0);
        this.setBlock(world, i + 12, j + 28, k + 34, Blocks.stone, 0);
        this.setBlock(world, i + 12, j + 28, k + 35, Blocks.stone, 0);
        this.setBlock(world, i + 12, j + 28, k + 36, Blocks.stone, 0);
        this.setBlock(world, i + 12, j + 28, k + 37, Blocks.bedrock, 0);
        this.setBlock(world, i + 12, j + 28, k + 38, Blocks.stone, 0);
        this.setBlock(world, i + 12, j + 28, k + 39, Blocks.cobblestone, 0);
        this.setBlock(world, i + 12, j + 28, k + 40, Blocks.stone, 0);
        this.setBlock(world, i + 12, j + 28, k + 41, Blocks.stone, 0);
        this.setBlock(world, i + 12, j + 28, k + 42, Blocks.bedrock, 0);
        this.setBlock(world, i + 12, j + 28, k + 43, Blocks.stone, 0);
        this.setBlock(world, i + 12, j + 28, k + 44, Blocks.stone, 0);
        this.setBlock(world, i + 12, j + 28, k + 45, Blocks.stone, 0);
        this.setBlock(world, i + 12, j + 28, k + 46, Blocks.bedrock, 0);
        this.setBlock(world, i + 12, j + 28, k + 47, Blocks.stone, 0);
        this.setBlock(world, i + 12, j + 28, k + 48, Blocks.bedrock, 0);
        this.setBlock(world, i + 12, j + 28, k + 49, Blocks.stone, 0);
        this.setBlock(world, i + 12, j + 28, k + 50, Blocks.stone, 0);
        this.setBlock(world, i + 12, j + 28, k + 51, Blocks.stone, 0);
        this.setBlock(world, i + 12, j + 28, k + 52, Blocks.cobblestone, 0);
        this.setBlock(world, i + 12, j + 28, k + 53, Blocks.stone, 0);
        this.setBlock(world, i + 12, j + 28, k + 54, Blocks.stone, 0);
        this.setBlock(world, i + 12, j + 28, k + 55, Blocks.stone, 0);
        this.setBlock(world, i + 12, j + 28, k + 56, Blocks.stone, 0);
        this.setBlock(world, i + 12, j + 28, k + 57, Blocks.stone, 0);
        this.setBlock(world, i + 12, j + 28, k + 58, Blocks.stone, 0);
        this.setBlock(world, i + 12, j + 28, k + 59, Blocks.stone, 0);
        this.setBlock(world, i + 12, j + 29, k + 32, Blocks.planks, 0);
        this.setBlock(world, i + 12, j + 29, k + 36, Blocks.planks, 0);
        this.setBlock(world, i + 12, j + 29, k + 37, Blocks.bedrock, 0);
        this.setBlock(world, i + 12, j + 29, k + 38, Blocks.stone, 0);
        this.setBlock(world, i + 12, j + 29, k + 39, Blocks.stone, 0);
        this.setBlock(world, i + 12, j + 29, k + 40, Blocks.stone, 0);
        this.setBlock(world, i + 12, j + 29, k + 41, Blocks.stone, 0);
        this.setBlock(world, i + 12, j + 29, k + 42, Blocks.stone, 0);
        this.setBlock(world, i + 12, j + 29, k + 43, Blocks.stone, 0);
        this.setBlock(world, i + 12, j + 29, k + 44, Blocks.stone, 0);
        this.setBlock(world, i + 12, j + 29, k + 45, Blocks.stone, 0);
        this.setBlock(world, i + 12, j + 29, k + 46, Blocks.stone, 0);
        this.setBlock(world, i + 12, j + 29, k + 47, Blocks.stone, 0);
        this.setBlock(world, i + 12, j + 29, k + 48, Blocks.bedrock, 0);
        this.setBlock(world, i + 12, j + 29, k + 49, Blocks.stone, 0);
        this.setBlock(world, i + 12, j + 29, k + 50, Blocks.stone, 0);
        this.setBlock(world, i + 12, j + 29, k + 51, Blocks.stone, 0);
        this.setBlock(world, i + 12, j + 29, k + 52, Blocks.stone, 0);
        this.setBlock(world, i + 12, j + 29, k + 53, Blocks.stone, 0);
        this.setBlock(world, i + 12, j + 29, k + 54, Blocks.stone, 0);
        this.setBlock(world, i + 12, j + 29, k + 55, Blocks.stone, 0);
        this.setBlock(world, i + 12, j + 30, k + 32, Blocks.planks, 0);
        this.setBlock(world, i + 12, j + 30, k + 36, Blocks.planks, 0);
        this.setBlock(world, i + 12, j + 30, k + 40, Blocks.stone, 0);
        this.setBlock(world, i + 12, j + 30, k + 41, Blocks.stone, 0);
        this.setBlock(world, i + 12, j + 30, k + 42, Blocks.stone, 0);
        this.setBlock(world, i + 12, j + 30, k + 43, Blocks.stone, 0);
        this.setBlock(world, i + 12, j + 30, k + 44, Blocks.stone, 0);
        this.setBlock(world, i + 12, j + 30, k + 45, Blocks.bedrock, 0);
        this.setBlock(world, i + 12, j + 30, k + 46, Blocks.stone, 0);
        this.setBlock(world, i + 12, j + 30, k + 47, Blocks.cobblestone, 0);
        this.setBlock(world, i + 12, j + 30, k + 48, Blocks.stone, 0);
        this.setBlock(world, i + 12, j + 30, k + 49, Blocks.stone, 0);
        this.setBlock(world, i + 12, j + 30, k + 50, Blocks.cobblestone, 0);
        this.setBlock(world, i + 12, j + 30, k + 51, Blocks.stone, 0);
        this.setBlock(world, i + 12, j + 30, k + 52, Blocks.stone, 0);
        this.setBlock(world, i + 12, j + 30, k + 53, Blocks.stone, 0);
        this.setBlock(world, i + 12, j + 30, k + 54, Blocks.stone, 0);
        this.setBlock(world, i + 12, j + 30, k + 55, Blocks.stone, 0);
        this.setBlock(world, i + 12, j + 31, k + 41, Blocks.stone, 0);
        this.setBlock(world, i + 12, j + 31, k + 42, Blocks.stone, 0);
        this.setBlock(world, i + 12, j + 31, k + 43, Blocks.stone, 0);
        this.setBlock(world, i + 12, j + 31, k + 44, Blocks.stone, 0);
        this.setBlock(world, i + 12, j + 31, k + 45, Blocks.stone, 0);
        this.setBlock(world, i + 12, j + 31, k + 46, Blocks.stone, 0);
        this.setBlock(world, i + 12, j + 31, k + 47, Blocks.stone, 0);
        this.setBlock(world, i + 12, j + 31, k + 48, Blocks.cobblestone, 0);
        this.setBlock(world, i + 12, j + 31, k + 49, Blocks.cobblestone, 0);
        this.setBlock(world, i + 12, j + 31, k + 50, Blocks.stone, 0);
        this.setBlock(world, i + 12, j + 32, k + 43, Blocks.cobblestone, 0);
        this.setBlock(world, i + 12, j + 32, k + 44, Blocks.bedrock, 0);
        this.setBlock(world, i + 12, j + 32, k + 45, Blocks.stone, 0);
        this.setBlock(world, i + 12, j + 32, k + 46, Blocks.stone, 0);
        this.setBlock(world, i + 12, j + 32, k + 47, Blocks.stone, 0);
        this.setBlock(world, i + 12, j + 32, k + 48, Blocks.stone, 0);
        this.setBlock(world, i + 12, j + 32, k + 49, Blocks.stone, 0);
        this.setBlock(world, i + 12, j + 32, k + 50, Blocks.stone, 0);
        this.setBlock(world, i + 12, j + 33, k + 44, Blocks.mycelium, 0);
        this.setBlock(world, i + 12, j + 33, k + 45, Blocks.mycelium, 0);
        this.setBlock(world, i + 12, j + 33, k + 46, Blocks.mycelium, 0);
        this.setBlock(world, i + 12, j + 33, k + 47, Blocks.mycelium, 0);
        this.setBlock(world, i + 12, j + 33, k + 48, Blocks.mycelium, 0);
        this.setBlock(world, i + 12, j + 35, k + 31, Blocks.stonebrick, 0);
        this.setBlock(world, i + 12, j + 35, k + 37, Blocks.stonebrick, 0);
        this.setBlock(world, i + 12, j + 36, k + 31, Blocks.stonebrick, 0);
        this.setBlock(world, i + 12, j + 36, k + 32, Blocks.stonebrick, 0);
        this.setBlock(world, i + 12, j + 36, k + 33, Blocks.stonebrick, 0);
        this.setBlock(world, i + 12, j + 36, k + 34, Blocks.stonebrick, 0);
        this.setBlock(world, i + 12, j + 36, k + 35, Blocks.stonebrick, 0);
        this.setBlock(world, i + 12, j + 36, k + 36, Blocks.stonebrick, 0);
        this.setBlock(world, i + 12, j + 36, k + 37, Blocks.stonebrick, 0);
        this.setBlock(world, i + 12, j + 37, k + 31, Blocks.stonebrick, 0);
        this.setBlock(world, i + 12, j + 37, k + 37, Blocks.stonebrick, 0);
        this.setBlock(world, i + 12, j + 40, k + 32, Blocks.cobblestone_wall, 0);
        this.setBlock(world, i + 12, j + 40, k + 33, Blocks.cobblestone_wall, 0);
        this.setBlock(world, i + 12, j + 40, k + 34, Blocks.cobblestone_wall, 0);
        this.setBlock(world, i + 12, j + 40, k + 35, Blocks.cobblestone_wall, 0);
        this.setBlock(world, i + 12, j + 40, k + 36, Blocks.cobblestone_wall, 0);
        this.setBlock(world, i + 12, j + 41, k + 32, Blocks.stained_hardened_clay, 9);
        this.setBlock(world, i + 12, j + 41, k + 33, Blocks.stained_hardened_clay, 9);
        this.setBlock(world, i + 12, j + 41, k + 34, Blocks.stained_hardened_clay, 9);
        this.setBlock(world, i + 12, j + 41, k + 35, Blocks.stained_hardened_clay, 9);
        this.setBlock(world, i + 12, j + 41, k + 36, Blocks.stained_hardened_clay, 9);
        this.setBlock(world, i + 12, j + 45, k + 32, Blocks.cobblestone_wall, 0);
        this.setBlock(world, i + 12, j + 45, k + 33, Blocks.cobblestone_wall, 0);
        this.setBlock(world, i + 12, j + 45, k + 34, Blocks.cobblestone_wall, 0);
        this.setBlock(world, i + 12, j + 45, k + 35, Blocks.cobblestone_wall, 0);
        this.setBlock(world, i + 12, j + 45, k + 36, Blocks.cobblestone_wall, 0);
        this.setBlock(world, i + 12, j + 46, k + 32, Blocks.stained_hardened_clay, 9);
        this.setBlock(world, i + 12, j + 46, k + 33, Blocks.stained_hardened_clay, 9);
        this.setBlock(world, i + 12, j + 46, k + 34, Blocks.stained_hardened_clay, 9);
        this.setBlock(world, i + 12, j + 46, k + 35, Blocks.stained_hardened_clay, 9);
        this.setBlock(world, i + 12, j + 46, k + 36, Blocks.stained_hardened_clay, 9);
        this.setBlock(world, i + 12, j + 50, k + 32, Blocks.cobblestone_wall, 0);
        this.setBlock(world, i + 12, j + 50, k + 33, Blocks.cobblestone_wall, 0);
        this.setBlock(world, i + 12, j + 50, k + 34, Blocks.cobblestone_wall, 0);
        this.setBlock(world, i + 12, j + 50, k + 35, Blocks.cobblestone_wall, 0);
        this.setBlock(world, i + 12, j + 50, k + 36, Blocks.cobblestone_wall, 0);
        this.setBlock(world, i + 12, j + 51, k + 32, Blocks.stained_hardened_clay, 9);
        this.setBlock(world, i + 12, j + 51, k + 33, Blocks.stained_hardened_clay, 9);
        this.setBlock(world, i + 12, j + 51, k + 34, Blocks.stained_hardened_clay, 9);
        this.setBlock(world, i + 12, j + 51, k + 35, Blocks.stained_hardened_clay, 9);
        this.setBlock(world, i + 12, j + 51, k + 36, Blocks.stained_hardened_clay, 9);
        this.setBlock(world, i + 13, j + 24, k + 43, Blocks.stone, 0);
        this.setBlock(world, i + 13, j + 24, k + 44, Blocks.stone, 0);
        this.setBlock(world, i + 13, j + 24, k + 45, Blocks.bedrock, 0);
        this.setBlock(world, i + 13, j + 24, k + 46, Blocks.stone, 0);
        this.setBlock(world, i + 13, j + 24, k + 47, Blocks.stone, 0);
        this.setBlock(world, i + 13, j + 24, k + 48, Blocks.stone, 0);
        this.setBlock(world, i + 13, j + 24, k + 49, Blocks.stone, 0);
        this.setBlock(world, i + 13, j + 24, k + 50, Blocks.stone, 0);
        this.setBlock(world, i + 13, j + 25, k + 38, Blocks.stone, 0);
        this.setBlock(world, i + 13, j + 25, k + 39, Blocks.bedrock, 0);
        this.setBlock(world, i + 13, j + 25, k + 40, Blocks.stone, 0);
        this.setBlock(world, i + 13, j + 25, k + 41, Blocks.stone, 0);
        this.setBlock(world, i + 13, j + 25, k + 42, Blocks.stone, 0);
        this.setBlock(world, i + 13, j + 25, k + 43, Blocks.stone, 0);
        this.setBlock(world, i + 13, j + 25, k + 44, Blocks.cobblestone, 0);
        this.setBlock(world, i + 13, j + 25, k + 45, Blocks.stone, 0);
        this.setBlock(world, i + 13, j + 25, k + 46, Blocks.stone, 0);
        this.setBlock(world, i + 13, j + 25, k + 47, Blocks.cobblestone, 0);
        this.setBlock(world, i + 13, j + 25, k + 48, Blocks.stone, 0);
        this.setBlock(world, i + 13, j + 25, k + 49, Blocks.stone, 0);
        this.setBlock(world, i + 13, j + 25, k + 50, Blocks.bedrock, 0);
        this.setBlock(world, i + 13, j + 25, k + 51, Blocks.stone, 0);
        this.setBlock(world, i + 13, j + 25, k + 52, Blocks.cobblestone, 0);
        this.setBlock(world, i + 13, j + 25, k + 53, Blocks.stone, 0);
        this.setBlock(world, i + 13, j + 26, k + 35, Blocks.stone, 0);
        this.setBlock(world, i + 13, j + 26, k + 36, Blocks.bedrock, 0);
        this.setBlock(world, i + 13, j + 26, k + 37, Blocks.cobblestone, 0);
        this.setBlock(world, i + 13, j + 26, k + 38, Blocks.cobblestone, 0);
        this.setBlock(world, i + 13, j + 26, k + 39, Blocks.cobblestone, 0);
        this.setBlock(world, i + 13, j + 26, k + 40, Blocks.stone, 0);
        this.setBlock(world, i + 13, j + 26, k + 41, Blocks.stone, 0);
        this.setBlock(world, i + 13, j + 26, k + 42, Blocks.cobblestone, 0);
        this.setBlock(world, i + 13, j + 26, k + 43, Blocks.stone, 0);
        this.setBlock(world, i + 13, j + 26, k + 44, Blocks.stone, 0);
        this.setBlock(world, i + 13, j + 26, k + 45, Blocks.cobblestone, 0);
        this.setBlock(world, i + 13, j + 26, k + 46, Blocks.bedrock, 0);
        this.setBlock(world, i + 13, j + 26, k + 47, Blocks.stone, 0);
        this.setBlock(world, i + 13, j + 26, k + 48, Blocks.stone, 0);
        this.setBlock(world, i + 13, j + 26, k + 49, Blocks.stone, 0);
        this.setBlock(world, i + 13, j + 26, k + 50, Blocks.stone, 0);
        this.setBlock(world, i + 13, j + 26, k + 51, Blocks.stone, 0);
        this.setBlock(world, i + 13, j + 26, k + 52, Blocks.stone, 0);
        this.setBlock(world, i + 13, j + 26, k + 53, Blocks.cobblestone, 0);
        this.setBlock(world, i + 13, j + 26, k + 54, Blocks.stone, 0);
        this.setBlock(world, i + 13, j + 26, k + 55, Blocks.stone, 0);
        this.setBlock(world, i + 13, j + 26, k + 56, Blocks.stone, 0);
        this.setBlock(world, i + 13, j + 26, k + 57, Blocks.stone, 0);
        this.setBlock(world, i + 13, j + 26, k + 58, Blocks.stone, 0);
        this.setBlock(world, i + 13, j + 27, k + 32, Blocks.planks, 0);
        this.setBlock(world, i + 13, j + 27, k + 33, Blocks.stone, 0);
        this.setBlock(world, i + 13, j + 27, k + 34, Blocks.bedrock, 0);
        this.setBlock(world, i + 13, j + 27, k + 35, Blocks.cobblestone, 0);
        this.setBlock(world, i + 13, j + 27, k + 36, Blocks.stone, 0);
        this.setBlock(world, i + 13, j + 27, k + 37, Blocks.stone, 0);
        this.setBlock(world, i + 13, j + 27, k + 38, Blocks.stone, 0);
        this.setBlock(world, i + 13, j + 27, k + 39, Blocks.stone, 0);
        this.setBlock(world, i + 13, j + 27, k + 40, Blocks.stone, 0);
        this.setBlock(world, i + 13, j + 27, k + 41, Blocks.stone, 0);
        this.setBlock(world, i + 13, j + 27, k + 42, Blocks.stone, 0);
        this.setBlock(world, i + 13, j + 27, k + 43, Blocks.stone, 0);
        this.setBlock(world, i + 13, j + 27, k + 44, Blocks.stone, 0);
        this.setBlock(world, i + 13, j + 27, k + 45, Blocks.stone, 0);
        this.setBlock(world, i + 13, j + 27, k + 46, Blocks.bedrock, 0);
        this.setBlock(world, i + 13, j + 27, k + 47, Blocks.stone, 0);
        this.setBlock(world, i + 13, j + 27, k + 48, Blocks.bedrock, 0);
        this.setBlock(world, i + 13, j + 27, k + 49, Blocks.stone, 0);
        this.setBlock(world, i + 13, j + 27, k + 50, Blocks.stone, 0);
        this.setBlock(world, i + 13, j + 27, k + 51, Blocks.bedrock, 0);
        this.setBlock(world, i + 13, j + 27, k + 52, Blocks.stone, 0);
        this.setBlock(world, i + 13, j + 27, k + 53, Blocks.stone, 0);
        this.setBlock(world, i + 13, j + 27, k + 54, Blocks.stone, 0);
        this.setBlock(world, i + 13, j + 27, k + 55, Blocks.bedrock, 0);
        this.setBlock(world, i + 13, j + 27, k + 56, Blocks.stone, 0);
        this.setBlock(world, i + 13, j + 27, k + 57, Blocks.cobblestone, 0);
        this.setBlock(world, i + 13, j + 27, k + 58, Blocks.stone, 0);
        this.setBlock(world, i + 13, j + 27, k + 59, Blocks.stone, 0);
        this.setBlock(world, i + 13, j + 28, k + 32, Blocks.planks, 0);
        this.setBlock(world, i + 13, j + 28, k + 33, Blocks.stone, 0);
        this.setBlock(world, i + 13, j + 28, k + 34, Blocks.stone, 0);
        this.setBlock(world, i + 13, j + 28, k + 35, Blocks.cobblestone, 0);
        this.setBlock(world, i + 13, j + 28, k + 36, Blocks.cobblestone, 0);
        this.setBlock(world, i + 13, j + 28, k + 37, Blocks.stone, 0);
        this.setBlock(world, i + 13, j + 28, k + 38, Blocks.stone, 0);
        this.setBlock(world, i + 13, j + 28, k + 39, Blocks.cobblestone, 0);
        this.setBlock(world, i + 13, j + 28, k + 40, Blocks.cobblestone, 0);
        this.setBlock(world, i + 13, j + 28, k + 41, Blocks.stone, 0);
        this.setBlock(world, i + 13, j + 28, k + 42, Blocks.bedrock, 0);
        this.setBlock(world, i + 13, j + 28, k + 43, Blocks.cobblestone, 0);
        this.setBlock(world, i + 13, j + 28, k + 44, Blocks.stone, 0);
        this.setBlock(world, i + 13, j + 28, k + 45, Blocks.cobblestone, 0);
        this.setBlock(world, i + 13, j + 28, k + 46, Blocks.bedrock, 0);
        this.setBlock(world, i + 13, j + 28, k + 47, Blocks.stone, 0);
        this.setBlock(world, i + 13, j + 28, k + 48, Blocks.stone, 0);
        this.setBlock(world, i + 13, j + 28, k + 49, Blocks.stone, 0);
        this.setBlock(world, i + 13, j + 28, k + 50, Blocks.stone, 0);
        this.setBlock(world, i + 13, j + 28, k + 51, Blocks.stone, 0);
        this.setBlock(world, i + 13, j + 28, k + 52, Blocks.stone, 0);
        this.setBlock(world, i + 13, j + 28, k + 53, Blocks.cobblestone, 0);
        this.setBlock(world, i + 13, j + 28, k + 54, Blocks.stone, 0);
        this.setBlock(world, i + 13, j + 28, k + 55, Blocks.stone, 0);
        this.setBlock(world, i + 13, j + 28, k + 56, Blocks.stone, 0);
        this.setBlock(world, i + 13, j + 28, k + 57, Blocks.stone, 0);
        this.setBlock(world, i + 13, j + 28, k + 58, Blocks.stone, 0);
        this.setBlock(world, i + 13, j + 28, k + 59, Blocks.bedrock, 0);
        this.setBlock(world, i + 13, j + 28, k + 60, Blocks.stone, 0);
        this.setBlock(world, i + 13, j + 28, k + 61, Blocks.stone, 0);
        this.setBlock(world, i + 13, j + 28, k + 62, Blocks.stone, 0);
        this.setBlock(world, i + 13, j + 28, k + 63, Blocks.stone, 0);
        this.setBlock(world, i + 13, j + 28, k + 64, Blocks.stone, 0);
        this.setBlock(world, i + 13, j + 29, k + 32, Blocks.stone, 0);
        this.setBlock(world, i + 13, j + 29, k + 33, Blocks.stone, 0);
        this.setBlock(world, i + 13, j + 29, k + 34, Blocks.stone, 0);
        this.setBlock(world, i + 13, j + 29, k + 35, Blocks.stone, 0);
        this.setBlock(world, i + 13, j + 29, k + 36, Blocks.stone, 0);
        this.setBlock(world, i + 13, j + 29, k + 37, Blocks.stone, 0);
        this.setBlock(world, i + 13, j + 29, k + 38, Blocks.stone, 0);
        this.setBlock(world, i + 13, j + 29, k + 39, Blocks.stone, 0);
        this.setBlock(world, i + 13, j + 29, k + 40, Blocks.stone, 0);
        this.setBlock(world, i + 13, j + 29, k + 41, Blocks.stone, 0);
        this.setBlock(world, i + 13, j + 29, k + 42, Blocks.stone, 0);
        this.setBlock(world, i + 13, j + 29, k + 43, Blocks.stone, 0);
        this.setBlock(world, i + 13, j + 29, k + 44, Blocks.stone, 0);
        this.setBlock(world, i + 13, j + 29, k + 45, Blocks.bedrock, 0);
        this.setBlock(world, i + 13, j + 29, k + 46, Blocks.stone, 0);
        this.setBlock(world, i + 13, j + 29, k + 47, Blocks.stone, 0);
        this.setBlock(world, i + 13, j + 29, k + 48, Blocks.stone, 0);
        this.setBlock(world, i + 13, j + 29, k + 49, Blocks.bedrock, 0);
        this.setBlock(world, i + 13, j + 29, k + 50, Blocks.stone, 0);
        this.setBlock(world, i + 13, j + 29, k + 51, Blocks.stone, 0);
        this.setBlock(world, i + 13, j + 29, k + 52, Blocks.cobblestone, 0);
        this.setBlock(world, i + 13, j + 29, k + 53, Blocks.bedrock, 0);
        this.setBlock(world, i + 13, j + 29, k + 54, Blocks.stone, 0);
        this.setBlock(world, i + 13, j + 29, k + 55, Blocks.bedrock, 0);
        this.setBlock(world, i + 13, j + 29, k + 56, Blocks.stone, 0);
        this.setBlock(world, i + 13, j + 29, k + 57, Blocks.cobblestone, 0);
        this.setBlock(world, i + 13, j + 29, k + 58, Blocks.stone, 0);
        this.setBlock(world, i + 13, j + 30, k + 32, Blocks.stonebrick, 0);
        this.setBlock(world, i + 13, j + 30, k + 33, Blocks.bedrock, 0);
        this.setBlock(world, i + 13, j + 30, k + 34, Blocks.stonebrick, 0);
        this.setBlock(world, i + 13, j + 30, k + 35, Blocks.bedrock, 0);
        this.setBlock(world, i + 13, j + 30, k + 36, Blocks.stonebrick, 0);
        this.setBlock(world, i + 13, j + 30, k + 39, Blocks.stone, 0);
        this.setBlock(world, i + 13, j + 30, k + 40, Blocks.cobblestone, 0);
        this.setBlock(world, i + 13, j + 30, k + 41, Blocks.stone, 0);
        this.setBlock(world, i + 13, j + 30, k + 42, Blocks.cobblestone, 0);
        this.setBlock(world, i + 13, j + 30, k + 43, Blocks.stone, 0);
        this.setBlock(world, i + 13, j + 30, k + 44, Blocks.stone, 0);
        this.setBlock(world, i + 13, j + 30, k + 45, Blocks.stone, 0);
        this.setBlock(world, i + 13, j + 30, k + 46, Blocks.stone, 0);
        this.setBlock(world, i + 13, j + 30, k + 47, Blocks.stone, 0);
        this.setBlock(world, i + 13, j + 30, k + 48, Blocks.stone, 0);
        this.setBlock(world, i + 13, j + 30, k + 49, Blocks.stone, 0);
        this.setBlock(world, i + 13, j + 30, k + 50, Blocks.stone, 0);
        this.setBlock(world, i + 13, j + 30, k + 51, Blocks.stone, 0);
        this.setBlock(world, i + 13, j + 30, k + 52, Blocks.stone, 0);
        this.setBlock(world, i + 13, j + 30, k + 53, Blocks.stone, 0);
        this.setBlock(world, i + 13, j + 30, k + 54, Blocks.bedrock, 0);
        this.setBlock(world, i + 13, j + 30, k + 55, Blocks.stone, 0);
        this.setBlock(world, i + 13, j + 30, k + 56, Blocks.stone, 0);
        this.setBlock(world, i + 13, j + 30, k + 57, Blocks.stone, 0);
        this.setBlock(world, i + 13, j + 30, k + 58, Blocks.stone, 0);
        this.setBlock(world, i + 13, j + 31, k + 32, Blocks.stonebrick, 0);
        this.setBlock(world, i + 13, j + 31, k + 33, Blocks.bedrock, 0);
        this.setBlock(world, i + 13, j + 31, k + 34, Blocks.stonebrick, 0);
        this.setBlock(world, i + 13, j + 31, k + 35, Blocks.bedrock, 0);
        this.setBlock(world, i + 13, j + 31, k + 36, Blocks.stonebrick, 0);
        this.setBlock(world, i + 13, j + 31, k + 40, Blocks.bedrock, 0);
        this.setBlock(world, i + 13, j + 31, k + 41, Blocks.stone, 0);
        this.setBlock(world, i + 13, j + 31, k + 42, Blocks.stone, 0);
        this.setBlock(world, i + 13, j + 31, k + 43, Blocks.stone, 0);
        this.setBlock(world, i + 13, j + 31, k + 44, Blocks.stone, 0);
        this.setBlock(world, i + 13, j + 31, k + 45, Blocks.bedrock, 0);
        this.setBlock(world, i + 13, j + 31, k + 46, Blocks.stone, 0);
        this.setBlock(world, i + 13, j + 31, k + 47, Blocks.stone, 0);
        this.setBlock(world, i + 13, j + 31, k + 48, Blocks.stone, 0);
        this.setBlock(world, i + 13, j + 31, k + 49, Blocks.bedrock, 0);
        this.setBlock(world, i + 13, j + 31, k + 50, Blocks.stone, 0);
        this.setBlock(world, i + 13, j + 31, k + 51, Blocks.stone, 0);
        this.setBlock(world, i + 13, j + 31, k + 52, Blocks.stone, 0);
        this.setBlock(world, i + 13, j + 31, k + 53, Blocks.stone, 0);
        this.setBlock(world, i + 13, j + 31, k + 54, Blocks.stone, 0);
        this.setBlock(world, i + 13, j + 31, k + 55, Blocks.stone, 0);
        this.setBlock(world, i + 13, j + 32, k + 32, Blocks.stonebrick, 0);
        this.setBlock(world, i + 13, j + 32, k + 33, Blocks.bedrock, 0);
        this.setBlock(world, i + 13, j + 32, k + 34, Blocks.stonebrick, 0);
        this.setBlock(world, i + 13, j + 32, k + 35, Blocks.bedrock, 0);
        this.setBlock(world, i + 13, j + 32, k + 36, Blocks.stonebrick, 0);
        this.setBlock(world, i + 13, j + 32, k + 41, Blocks.stone, 0);
        this.setBlock(world, i + 13, j + 32, k + 42, Blocks.stone, 0);
        this.setBlock(world, i + 13, j + 32, k + 43, Blocks.stone, 0);
        this.setBlock(world, i + 13, j + 32, k + 44, Blocks.bedrock, 0);
        this.setBlock(world, i + 13, j + 32, k + 45, Blocks.stone, 0);
        this.setBlock(world, i + 13, j + 32, k + 46, Blocks.stone, 0);
        this.setBlock(world, i + 13, j + 32, k + 47, Blocks.stone, 0);
        this.setBlock(world, i + 13, j + 32, k + 48, Blocks.stone, 0);
        this.setBlock(world, i + 13, j + 32, k + 49, Blocks.stone, 0);
        this.setBlock(world, i + 13, j + 32, k + 50, Blocks.stone, 0);
        this.setBlock(world, i + 13, j + 32, k + 51, Blocks.stone, 0);
        this.setBlock(world, i + 13, j + 32, k + 52, Blocks.bedrock, 0);
        this.setBlock(world, i + 13, j + 33, k + 32, Blocks.stonebrick, 0);
        this.setBlock(world, i + 13, j + 33, k + 33, Blocks.bedrock, 0);
        this.setBlock(world, i + 13, j + 33, k + 34, Blocks.stonebrick, 0);
        this.setBlock(world, i + 13, j + 33, k + 35, Blocks.bedrock, 0);
        this.setBlock(world, i + 13, j + 33, k + 36, Blocks.stonebrick, 0);
        this.setBlock(world, i + 13, j + 33, k + 43, Blocks.stone, 0);
        this.setBlock(world, i + 13, j + 33, k + 44, Blocks.mycelium, 0);
        this.setBlock(world, i + 13, j + 33, k + 45, Blocks.dirt, 0);
        this.setBlock(world, i + 13, j + 33, k + 46, Blocks.dirt, 0);
        this.setBlock(world, i + 13, j + 33, k + 47, Blocks.dirt, 0);
        this.setBlock(world, i + 13, j + 33, k + 48, Blocks.mycelium, 0);
        this.setBlock(world, i + 13, j + 33, k + 49, Blocks.mycelium, 0);
        this.setBlock(world, i + 13, j + 33, k + 50, Blocks.stone, 0);
        this.setBlock(world, i + 13, j + 33, k + 51, Blocks.stone, 0);
        this.setBlock(world, i + 13, j + 34, k + 32, Blocks.stonebrick, 0);
        this.setBlock(world, i + 13, j + 34, k + 33, Blocks.bedrock, 0);
        this.setBlock(world, i + 13, j + 34, k + 34, Blocks.stonebrick, 0);
        this.setBlock(world, i + 13, j + 34, k + 35, Blocks.bedrock, 0);
        this.setBlock(world, i + 13, j + 34, k + 36, Blocks.stonebrick, 0);
        this.setBlock(world, i + 13, j + 34, k + 45, Blocks.mycelium, 0);
        this.setBlock(world, i + 13, j + 34, k + 46, Blocks.mycelium, 0);
        this.setBlock(world, i + 13, j + 34, k + 47, Blocks.mycelium, 0);
        this.setBlock(world, i + 13, j + 35, k + 32, Blocks.stonebrick, 0);
        this.setBlock(world, i + 13, j + 35, k + 33, Blocks.bedrock, 0);
        this.setBlock(world, i + 13, j + 35, k + 34, Blocks.stonebrick, 0);
        this.setBlock(world, i + 13, j + 35, k + 35, Blocks.bedrock, 0);
        this.setBlock(world, i + 13, j + 35, k + 36, Blocks.stonebrick, 0);
        this.setBlock(world, i + 13, j + 36, k + 32, Blocks.stonebrick, 0);
        this.setBlock(world, i + 13, j + 36, k + 33, Blocks.bedrock, 0);
        this.setBlock(world, i + 13, j + 36, k + 34, Blocks.stonebrick, 0);
        this.setBlock(world, i + 13, j + 36, k + 35, Blocks.bedrock, 0);
        this.setBlock(world, i + 13, j + 36, k + 36, Blocks.stonebrick, 0);
        this.setBlock(world, i + 13, j + 37, k + 32, Blocks.stonebrick, 0);
        this.setBlock(world, i + 13, j + 37, k + 33, Blocks.bedrock, 0);
        this.setBlock(world, i + 13, j + 37, k + 35, Blocks.bedrock, 0);
        this.setBlock(world, i + 13, j + 37, k + 36, Blocks.stonebrick, 0);
        this.setBlock(world, i + 13, j + 38, k + 32, Blocks.stonebrick, 0);
        this.setBlock(world, i + 13, j + 38, k + 33, Blocks.bedrock, 0);
        this.setBlock(world, i + 13, j + 38, k + 35, Blocks.bedrock, 0);
        this.setBlock(world, i + 13, j + 38, k + 36, Blocks.stonebrick, 0);
        this.setBlock(world, i + 13, j + 39, k + 32, Blocks.stonebrick, 0);
        this.setBlock(world, i + 13, j + 39, k + 33, Blocks.bedrock, 0);
        this.setBlock(world, i + 13, j + 39, k + 34, Blocks.stonebrick, 0);
        this.setBlock(world, i + 13, j + 39, k + 35, Blocks.bedrock, 0);
        this.setBlock(world, i + 13, j + 39, k + 36, Blocks.stonebrick, 0);
        this.setBlock(world, i + 13, j + 40, k + 31, Blocks.cobblestone_wall, 0);
        this.setBlock(world, i + 13, j + 40, k + 32, Blocks.stonebrick, 0);
        this.setBlock(world, i + 13, j + 40, k + 33, Blocks.bedrock, 0);
        this.setBlock(world, i + 13, j + 40, k + 34, Blocks.stonebrick, 0);
        this.setBlock(world, i + 13, j + 40, k + 35, Blocks.bedrock, 0);
        this.setBlock(world, i + 13, j + 40, k + 36, Blocks.stonebrick, 0);
        this.setBlock(world, i + 13, j + 40, k + 37, Blocks.cobblestone_wall, 0);
        this.setBlock(world, i + 13, j + 41, k + 31, Blocks.stained_hardened_clay, 9);
        this.setBlock(world, i + 13, j + 41, k + 32, Blocks.stonebrick, 0);
        this.setBlock(world, i + 13, j + 41, k + 33, Blocks.bedrock, 0);
        this.setBlock(world, i + 13, j + 41, k + 34, Blocks.stonebrick, 0);
        this.setBlock(world, i + 13, j + 41, k + 35, Blocks.bedrock, 0);
        this.setBlock(world, i + 13, j + 41, k + 36, Blocks.stonebrick, 0);
        this.setBlock(world, i + 13, j + 41, k + 37, Blocks.stained_hardened_clay, 9);
        this.setBlock(world, i + 13, j + 42, k + 31, Blocks.stained_hardened_clay, 9);
        this.setBlock(world, i + 13, j + 42, k + 32, Blocks.stonebrick, 0);
        this.setBlock(world, i + 13, j + 42, k + 33, Blocks.bedrock, 0);
        this.setBlock(world, i + 13, j + 42, k + 34, Blocks.iron_bars, 0);
        this.setBlock(world, i + 13, j + 42, k + 35, Blocks.bedrock, 0);
        this.setBlock(world, i + 13, j + 42, k + 36, Blocks.stonebrick, 0);
        this.setBlock(world, i + 13, j + 42, k + 37, Blocks.stained_hardened_clay, 9);
        this.setBlock(world, i + 13, j + 43, k + 32, Blocks.stonebrick, 0);
        this.setBlock(world, i + 13, j + 43, k + 33, Blocks.bedrock, 0);
        this.setBlock(world, i + 13, j + 43, k + 34, Blocks.iron_bars, 0);
        this.setBlock(world, i + 13, j + 43, k + 35, Blocks.bedrock, 0);
        this.setBlock(world, i + 13, j + 43, k + 36, Blocks.stonebrick, 0);
        this.setBlock(world, i + 13, j + 44, k + 32, Blocks.stonebrick, 0);
        this.setBlock(world, i + 13, j + 44, k + 33, Blocks.bedrock, 0);
        this.setBlock(world, i + 13, j + 44, k + 34, Blocks.stonebrick, 0);
        this.setBlock(world, i + 13, j + 44, k + 35, Blocks.bedrock, 0);
        this.setBlock(world, i + 13, j + 44, k + 36, Blocks.stonebrick, 0);
        this.setBlock(world, i + 13, j + 45, k + 31, Blocks.cobblestone_wall, 0);
        this.setBlock(world, i + 13, j + 45, k + 32, Blocks.stonebrick, 0);
        this.setBlock(world, i + 13, j + 45, k + 33, Blocks.bedrock, 0);
        this.setBlock(world, i + 13, j + 45, k + 34, Blocks.stonebrick, 0);
        this.setBlock(world, i + 13, j + 45, k + 35, Blocks.bedrock, 0);
        this.setBlock(world, i + 13, j + 45, k + 36, Blocks.stonebrick, 0);
        this.setBlock(world, i + 13, j + 45, k + 37, Blocks.cobblestone_wall, 0);
        this.setBlock(world, i + 13, j + 46, k + 31, Blocks.stained_hardened_clay, 9);
        this.setBlock(world, i + 13, j + 46, k + 32, Blocks.stonebrick, 0);
        this.setBlock(world, i + 13, j + 46, k + 33, Blocks.bedrock, 0);
        this.setBlock(world, i + 13, j + 46, k + 34, Blocks.stonebrick, 0);
        this.setBlock(world, i + 13, j + 46, k + 35, Blocks.bedrock, 0);
        this.setBlock(world, i + 13, j + 46, k + 36, Blocks.stonebrick, 0);
        this.setBlock(world, i + 13, j + 46, k + 37, Blocks.stained_hardened_clay, 9);
        this.setBlock(world, i + 13, j + 47, k + 31, Blocks.stained_hardened_clay, 9);
        this.setBlock(world, i + 13, j + 47, k + 32, Blocks.stonebrick, 0);
        this.setBlock(world, i + 13, j + 47, k + 33, Blocks.bedrock, 0);
        this.setBlock(world, i + 13, j + 47, k + 34, Blocks.iron_bars, 0);
        this.setBlock(world, i + 13, j + 47, k + 35, Blocks.bedrock, 0);
        this.setBlock(world, i + 13, j + 47, k + 36, Blocks.stonebrick, 0);
        this.setBlock(world, i + 13, j + 47, k + 37, Blocks.stained_hardened_clay, 9);
        this.setBlock(world, i + 13, j + 48, k + 32, Blocks.stonebrick, 0);
        this.setBlock(world, i + 13, j + 48, k + 33, Blocks.bedrock, 0);
        this.setBlock(world, i + 13, j + 48, k + 34, Blocks.iron_bars, 0);
        this.setBlock(world, i + 13, j + 48, k + 35, Blocks.bedrock, 0);
        this.setBlock(world, i + 13, j + 48, k + 36, Blocks.stonebrick, 0);
        this.setBlock(world, i + 13, j + 49, k + 32, Blocks.stonebrick, 0);
        this.setBlock(world, i + 13, j + 49, k + 33, Blocks.bedrock, 0);
        this.setBlock(world, i + 13, j + 49, k + 34, Blocks.stonebrick, 0);
        this.setBlock(world, i + 13, j + 49, k + 35, Blocks.bedrock, 0);
        this.setBlock(world, i + 13, j + 49, k + 36, Blocks.stonebrick, 0);
        this.setBlock(world, i + 13, j + 50, k + 31, Blocks.cobblestone_wall, 0);
        this.setBlock(world, i + 13, j + 50, k + 32, Blocks.stonebrick, 0);
        this.setBlock(world, i + 13, j + 50, k + 33, Blocks.bedrock, 0);
        this.setBlock(world, i + 13, j + 50, k + 34, Blocks.stonebrick, 0);
        this.setBlock(world, i + 13, j + 50, k + 35, Blocks.bedrock, 0);
        this.setBlock(world, i + 13, j + 50, k + 36, Blocks.stonebrick, 0);
        this.setBlock(world, i + 13, j + 50, k + 37, Blocks.cobblestone_wall, 0);
        this.setBlock(world, i + 13, j + 51, k + 31, Blocks.stained_hardened_clay, 9);
        this.setBlock(world, i + 13, j + 51, k + 32, Blocks.stonebrick, 0);
        this.setBlock(world, i + 13, j + 51, k + 33, Blocks.bedrock, 0);
        this.setBlock(world, i + 13, j + 51, k + 34, Blocks.stonebrick, 0);
        this.setBlock(world, i + 13, j + 51, k + 35, Blocks.bedrock, 0);
        this.setBlock(world, i + 13, j + 51, k + 36, Blocks.stonebrick, 0);
        this.setBlock(world, i + 13, j + 51, k + 37, Blocks.stained_hardened_clay, 9);
        this.setBlock(world, i + 13, j + 52, k + 31, Blocks.stained_hardened_clay, 9);
        this.setBlock(world, i + 13, j + 52, k + 33, Blocks.bedrock, 0);
        this.setBlock(world, i + 13, j + 52, k + 35, Blocks.bedrock, 0);
        this.setBlock(world, i + 13, j + 52, k + 37, Blocks.stained_hardened_clay, 9);
        this.setBlock(world, i + 14, j + 23, k + 47, Blocks.stone, 0);
        this.setBlock(world, i + 14, j + 23, k + 48, Blocks.stone, 0);
        this.setBlock(world, i + 14, j + 24, k + 39, Blocks.stone, 0);
        this.setBlock(world, i + 14, j + 24, k + 44, Blocks.stone, 0);
        this.setBlock(world, i + 14, j + 24, k + 45, Blocks.stone, 0);
        this.setBlock(world, i + 14, j + 24, k + 46, Blocks.stone, 0);
        this.setBlock(world, i + 14, j + 24, k + 47, Blocks.cobblestone, 0);
        this.setBlock(world, i + 14, j + 24, k + 48, Blocks.stone, 0);
        this.setBlock(world, i + 14, j + 24, k + 49, Blocks.bedrock, 0);
        this.setBlock(world, i + 14, j + 24, k + 50, Blocks.stone, 0);
        this.setBlock(world, i + 14, j + 24, k + 51, Blocks.stone, 0);
        this.setBlock(world, i + 14, j + 25, k + 36, Blocks.stone, 0);
        this.setBlock(world, i + 14, j + 25, k + 37, Blocks.stone, 0);
        this.setBlock(world, i + 14, j + 25, k + 38, Blocks.bedrock, 0);
        this.setBlock(world, i + 14, j + 25, k + 39, Blocks.stone, 0);
        this.setBlock(world, i + 14, j + 25, k + 40, Blocks.stone, 0);
        this.setBlock(world, i + 14, j + 25, k + 41, Blocks.cobblestone, 0);
        this.setBlock(world, i + 14, j + 25, k + 42, Blocks.stone, 0);
        this.setBlock(world, i + 14, j + 25, k + 43, Blocks.stone, 0);
        this.setBlock(world, i + 14, j + 25, k + 44, Blocks.stone, 0);
        this.setBlock(world, i + 14, j + 25, k + 45, Blocks.stone, 0);
        this.setBlock(world, i + 14, j + 25, k + 46, Blocks.stone, 0);
        this.setBlock(world, i + 14, j + 25, k + 47, Blocks.stone, 0);
        this.setBlock(world, i + 14, j + 25, k + 48, Blocks.cobblestone, 0);
        this.setBlock(world, i + 14, j + 25, k + 49, Blocks.bedrock, 0);
        this.setBlock(world, i + 14, j + 25, k + 50, Blocks.stone, 0);
        this.setBlock(world, i + 14, j + 25, k + 51, Blocks.stone, 0);
        this.setBlock(world, i + 14, j + 25, k + 52, Blocks.stone, 0);
        this.setBlock(world, i + 14, j + 25, k + 53, Blocks.stone, 0);
        this.setBlock(world, i + 14, j + 25, k + 54, Blocks.stone, 0);
        this.setBlock(world, i + 14, j + 25, k + 56, Blocks.stone, 0);
        this.setBlock(world, i + 14, j + 25, k + 57, Blocks.stone, 0);
        this.setBlock(world, i + 14, j + 25, k + 58, Blocks.stone, 0);
        this.setBlock(world, i + 14, j + 26, k + 33, Blocks.stone, 0);
        this.setBlock(world, i + 14, j + 26, k + 34, Blocks.stone, 0);
        this.setBlock(world, i + 14, j + 26, k + 35, Blocks.stone, 0);
        this.setBlock(world, i + 14, j + 26, k + 36, Blocks.stone, 0);
        this.setBlock(world, i + 14, j + 26, k + 37, Blocks.stone, 0);
        this.setBlock(world, i + 14, j + 26, k + 38, Blocks.stone, 0);
        this.setBlock(world, i + 14, j + 26, k + 39, Blocks.stone, 0);
        this.setBlock(world, i + 14, j + 26, k + 40, Blocks.bedrock, 0);
        this.setBlock(world, i + 14, j + 26, k + 41, Blocks.stone, 0);
        this.setBlock(world, i + 14, j + 26, k + 42, Blocks.stone, 0);
        this.setBlock(world, i + 14, j + 26, k + 43, Blocks.stone, 0);
        this.setBlock(world, i + 14, j + 26, k + 44, Blocks.stone, 0);
        this.setBlock(world, i + 14, j + 26, k + 45, Blocks.stone, 0);
        this.setBlock(world, i + 14, j + 26, k + 46, Blocks.cobblestone, 0);
        this.setBlock(world, i + 14, j + 26, k + 47, Blocks.stone, 0);
        this.setBlock(world, i + 14, j + 26, k + 48, Blocks.stone, 0);
        this.setBlock(world, i + 14, j + 26, k + 49, Blocks.stone, 0);
        this.setBlock(world, i + 14, j + 26, k + 50, Blocks.stone, 0);
        this.setBlock(world, i + 14, j + 26, k + 51, Blocks.cobblestone, 0);
        this.setBlock(world, i + 14, j + 26, k + 52, Blocks.stone, 0);
        this.setBlock(world, i + 14, j + 26, k + 53, Blocks.stone, 0);
        this.setBlock(world, i + 14, j + 26, k + 54, Blocks.stone, 0);
        this.setBlock(world, i + 14, j + 26, k + 55, Blocks.bedrock, 0);
        this.setBlock(world, i + 14, j + 26, k + 56, Blocks.stone, 0);
        this.setBlock(world, i + 14, j + 26, k + 57, Blocks.stone, 0);
        this.setBlock(world, i + 14, j + 26, k + 58, Blocks.bedrock, 0);
        this.setBlock(world, i + 14, j + 26, k + 59, Blocks.stone, 0);
        this.setBlock(world, i + 14, j + 27, k + 32, Blocks.stone, 0);
        this.setBlock(world, i + 14, j + 27, k + 33, Blocks.stone, 0);
        this.setBlock(world, i + 14, j + 27, k + 34, Blocks.stone, 0);
        this.setBlock(world, i + 14, j + 27, k + 35, Blocks.stone, 0);
        this.setBlock(world, i + 14, j + 27, k + 36, Blocks.stone, 0);
        this.setBlock(world, i + 14, j + 27, k + 37, Blocks.stone, 0);
        this.setBlock(world, i + 14, j + 27, k + 38, Blocks.stone, 0);
        this.setBlock(world, i + 14, j + 27, k + 39, Blocks.stone, 0);
        this.setBlock(world, i + 14, j + 27, k + 40, Blocks.stone, 0);
        this.setBlock(world, i + 14, j + 27, k + 41, Blocks.stone, 0);
        this.setBlock(world, i + 14, j + 27, k + 42, Blocks.stone, 0);
        this.setBlock(world, i + 14, j + 27, k + 43, Blocks.bedrock, 0);
        this.setBlock(world, i + 14, j + 27, k + 44, Blocks.bedrock, 0);
        this.setBlock(world, i + 14, j + 27, k + 45, Blocks.stone, 0);
        this.setBlock(world, i + 14, j + 27, k + 46, Blocks.cobblestone, 0);
        this.setBlock(world, i + 14, j + 27, k + 47, Blocks.stone, 0);
        this.setBlock(world, i + 14, j + 27, k + 48, Blocks.bedrock, 0);
        this.setBlock(world, i + 14, j + 27, k + 49, Blocks.cobblestone, 0);
        this.setBlock(world, i + 14, j + 27, k + 50, Blocks.stone, 0);
        this.setBlock(world, i + 14, j + 27, k + 51, Blocks.stone, 0);
        this.setBlock(world, i + 14, j + 27, k + 52, Blocks.stone, 0);
        this.setBlock(world, i + 14, j + 27, k + 53, Blocks.stone, 0);
        this.setBlock(world, i + 14, j + 27, k + 54, Blocks.cobblestone, 0);
        this.setBlock(world, i + 14, j + 27, k + 55, Blocks.stone, 0);
        this.setBlock(world, i + 14, j + 27, k + 56, Blocks.stone, 0);
        this.setBlock(world, i + 14, j + 27, k + 57, Blocks.bedrock, 0);
        this.setBlock(world, i + 14, j + 27, k + 58, Blocks.stone, 0);
        this.setBlock(world, i + 14, j + 27, k + 59, Blocks.stone, 0);
        this.setBlock(world, i + 14, j + 27, k + 60, Blocks.stone, 0);
        this.setBlock(world, i + 14, j + 27, k + 61, Blocks.stone, 0);
        this.setBlock(world, i + 14, j + 27, k + 62, Blocks.stone, 0);
        this.setBlock(world, i + 14, j + 27, k + 63, Blocks.stone, 0);
        this.setBlock(world, i + 14, j + 28, k + 32, Blocks.stone, 0);
        this.setBlock(world, i + 14, j + 28, k + 33, Blocks.stone, 0);
        this.setBlock(world, i + 14, j + 28, k + 34, Blocks.stone, 0);
        this.setBlock(world, i + 14, j + 28, k + 35, Blocks.bedrock, 0);
        this.setBlock(world, i + 14, j + 28, k + 36, Blocks.stone, 0);
        this.setBlock(world, i + 14, j + 28, k + 37, Blocks.cobblestone, 0);
        this.setBlock(world, i + 14, j + 28, k + 38, Blocks.stone, 0);
        this.setBlock(world, i + 14, j + 28, k + 39, Blocks.stone, 0);
        this.setBlock(world, i + 14, j + 28, k + 40, Blocks.stone, 0);
        this.setBlock(world, i + 14, j + 28, k + 41, Blocks.stone, 0);
        this.setBlock(world, i + 14, j + 28, k + 42, Blocks.cobblestone, 0);
        this.setBlock(world, i + 14, j + 28, k + 43, Blocks.bedrock, 0);
        this.setBlock(world, i + 14, j + 28, k + 44, Blocks.cobblestone, 0);
        this.setBlock(world, i + 14, j + 28, k + 45, Blocks.stone, 0);
        this.setBlock(world, i + 14, j + 28, k + 46, Blocks.stone, 0);
        this.setBlock(world, i + 14, j + 28, k + 47, Blocks.stone, 0);
        this.setBlock(world, i + 14, j + 28, k + 48, Blocks.stone, 0);
        this.setBlock(world, i + 14, j + 28, k + 49, Blocks.stone, 0);
        this.setBlock(world, i + 14, j + 28, k + 50, Blocks.stone, 0);
        this.setBlock(world, i + 14, j + 28, k + 51, Blocks.stone, 0);
        this.setBlock(world, i + 14, j + 28, k + 52, Blocks.stone, 0);
        this.setBlock(world, i + 14, j + 28, k + 53, Blocks.stone, 0);
        this.setBlock(world, i + 14, j + 28, k + 54, Blocks.bedrock, 0);
        this.setBlock(world, i + 14, j + 28, k + 55, Blocks.stone, 0);
        this.setBlock(world, i + 14, j + 28, k + 56, Blocks.bedrock, 0);
        this.setBlock(world, i + 14, j + 28, k + 57, Blocks.stone, 0);
        this.setBlock(world, i + 14, j + 28, k + 58, Blocks.stone, 0);
        this.setBlock(world, i + 14, j + 28, k + 59, Blocks.stone, 0);
        this.setBlock(world, i + 14, j + 28, k + 60, Blocks.stone, 0);
        this.setBlock(world, i + 14, j + 28, k + 61, Blocks.stone, 0);
        this.setBlock(world, i + 14, j + 28, k + 62, Blocks.stone, 0);
        this.setBlock(world, i + 14, j + 28, k + 63, Blocks.bedrock, 0);
        this.setBlock(world, i + 14, j + 28, k + 64, Blocks.cobblestone, 0);
        this.setBlock(world, i + 14, j + 28, k + 65, Blocks.cobblestone, 0);
        this.setBlock(world, i + 14, j + 28, k + 66, Blocks.bedrock, 0);
        this.setBlock(world, i + 14, j + 29, k + 31, Blocks.bedrock, 0);
        this.setBlock(world, i + 14, j + 29, k + 32, Blocks.stone, 0);
        this.setBlock(world, i + 14, j + 29, k + 33, Blocks.stone, 0);
        this.setBlock(world, i + 14, j + 29, k + 34, Blocks.stone, 0);
        this.setBlock(world, i + 14, j + 29, k + 35, Blocks.cobblestone, 0);
        this.setBlock(world, i + 14, j + 29, k + 36, Blocks.stone, 0);
        this.setBlock(world, i + 14, j + 29, k + 37, Blocks.stone, 0);
        this.setBlock(world, i + 14, j + 29, k + 38, Blocks.stone, 0);
        this.setBlock(world, i + 14, j + 29, k + 39, Blocks.stone, 0);
        this.setBlock(world, i + 14, j + 29, k + 40, Blocks.stone, 0);
        this.setBlock(world, i + 14, j + 29, k + 41, Blocks.stone, 0);
        this.setBlock(world, i + 14, j + 29, k + 42, Blocks.stone, 0);
        this.setBlock(world, i + 14, j + 29, k + 43, Blocks.stone, 0);
        this.setBlock(world, i + 14, j + 29, k + 44, Blocks.stone, 0);
        this.setBlock(world, i + 14, j + 29, k + 45, Blocks.stone, 0);
        this.setBlock(world, i + 14, j + 29, k + 46, Blocks.stone, 0);
        this.setBlock(world, i + 14, j + 29, k + 47, Blocks.stone, 0);
        this.setBlock(world, i + 14, j + 29, k + 48, Blocks.bedrock, 0);
        this.setBlock(world, i + 14, j + 29, k + 49, Blocks.stone, 0);
        this.setBlock(world, i + 14, j + 29, k + 50, Blocks.cobblestone, 0);
        this.setBlock(world, i + 14, j + 29, k + 51, Blocks.stone, 0);
        this.setBlock(world, i + 14, j + 29, k + 52, Blocks.stone, 0);
        this.setBlock(world, i + 14, j + 29, k + 53, Blocks.bedrock, 0);
        this.setBlock(world, i + 14, j + 29, k + 54, Blocks.stone, 0);
        this.setBlock(world, i + 14, j + 29, k + 55, Blocks.bedrock, 0);
        this.setBlock(world, i + 14, j + 29, k + 56, Blocks.cobblestone, 0);
        this.setBlock(world, i + 14, j + 29, k + 57, Blocks.stone, 0);
        this.setBlock(world, i + 14, j + 29, k + 58, Blocks.stone, 0);
        this.setBlock(world, i + 14, j + 29, k + 59, Blocks.bedrock, 0);
        this.setBlock(world, i + 14, j + 29, k + 60, Blocks.cobblestone, 0);
        this.setBlock(world, i + 14, j + 30, k + 31, Blocks.stonebrick, 0);
        this.setBlock(world, i + 14, j + 30, k + 37, Blocks.stonebrick, 0);
        this.setBlock(world, i + 14, j + 30, k + 38, Blocks.stone, 0);
        this.setBlock(world, i + 14, j + 30, k + 39, Blocks.bedrock, 0);
        this.setBlock(world, i + 14, j + 30, k + 40, Blocks.bedrock, 0);
        this.setBlock(world, i + 14, j + 30, k + 41, Blocks.stone, 0);
        this.setBlock(world, i + 14, j + 30, k + 42, Blocks.cobblestone, 0);
        this.setBlock(world, i + 14, j + 30, k + 43, Blocks.stone, 0);
        this.setBlock(world, i + 14, j + 30, k + 44, Blocks.stone, 0);
        this.setBlock(world, i + 14, j + 30, k + 45, Blocks.stone, 0);
        this.setBlock(world, i + 14, j + 30, k + 46, Blocks.stone, 0);
        this.setBlock(world, i + 14, j + 30, k + 47, Blocks.stone, 0);
        this.setBlock(world, i + 14, j + 30, k + 48, Blocks.stone, 0);
        this.setBlock(world, i + 14, j + 30, k + 49, Blocks.cobblestone, 0);
        this.setBlock(world, i + 14, j + 30, k + 50, Blocks.stone, 0);
        this.setBlock(world, i + 14, j + 30, k + 51, Blocks.stone, 0);
        this.setBlock(world, i + 14, j + 30, k + 52, Blocks.stone, 0);
        this.setBlock(world, i + 14, j + 30, k + 53, Blocks.stone, 0);
        this.setBlock(world, i + 14, j + 30, k + 54, Blocks.stone, 0);
        this.setBlock(world, i + 14, j + 30, k + 55, Blocks.stone, 0);
        this.setBlock(world, i + 14, j + 30, k + 56, Blocks.stone, 0);
        this.setBlock(world, i + 14, j + 30, k + 57, Blocks.bedrock, 0);
        this.setBlock(world, i + 14, j + 30, k + 58, Blocks.stone, 0);
        this.setBlock(world, i + 14, j + 30, k + 59, Blocks.stone, 0);
        this.setBlock(world, i + 14, j + 31, k + 31, Blocks.stonebrick, 0);
        this.setBlock(world, i + 14, j + 31, k + 37, Blocks.stonebrick, 0);
        this.setBlock(world, i + 14, j + 31, k + 39, Blocks.stone, 0);
        this.setBlock(world, i + 14, j + 31, k + 40, Blocks.bedrock, 0);
        this.setBlock(world, i + 14, j + 31, k + 41, Blocks.stone, 0);
        this.setBlock(world, i + 14, j + 31, k + 42, Blocks.stone, 0);
        this.setBlock(world, i + 14, j + 31, k + 43, Blocks.stone, 0);
        this.setBlock(world, i + 14, j + 31, k + 44, Blocks.stone, 0);
        this.setBlock(world, i + 14, j + 31, k + 45, Blocks.stone, 0);
        this.setBlock(world, i + 14, j + 31, k + 46, Blocks.stone, 0);
        this.setBlock(world, i + 14, j + 31, k + 47, Blocks.stone, 0);
        this.setBlock(world, i + 14, j + 31, k + 48, Blocks.cobblestone, 0);
        this.setBlock(world, i + 14, j + 31, k + 49, Blocks.cobblestone, 0);
        this.setBlock(world, i + 14, j + 31, k + 50, Blocks.bedrock, 0);
        this.setBlock(world, i + 14, j + 31, k + 51, Blocks.cobblestone, 0);
        this.setBlock(world, i + 14, j + 31, k + 52, Blocks.cobblestone, 0);
        this.setBlock(world, i + 14, j + 31, k + 53, Blocks.bedrock, 0);
        this.setBlock(world, i + 14, j + 31, k + 54, Blocks.stone, 0);
        this.setBlock(world, i + 14, j + 31, k + 55, Blocks.bedrock, 0);
        this.setBlock(world, i + 14, j + 31, k + 56, Blocks.stone, 0);
        this.setBlock(world, i + 14, j + 31, k + 57, Blocks.cobblestone, 0);
        this.setBlock(world, i + 14, j + 31, k + 58, Blocks.stone, 0);
        this.setBlock(world, i + 14, j + 32, k + 31, Blocks.stonebrick, 0);
        this.setBlock(world, i + 14, j + 32, k + 37, Blocks.stonebrick, 0);
        this.setBlock(world, i + 14, j + 32, k + 39, Blocks.stone, 0);
        this.setBlock(world, i + 14, j + 32, k + 40, Blocks.bedrock, 0);
        this.setBlock(world, i + 14, j + 32, k + 41, Blocks.cobblestone, 0);
        this.setBlock(world, i + 14, j + 32, k + 42, Blocks.stone, 0);
        this.setBlock(world, i + 14, j + 32, k + 43, Blocks.stone, 0);
        this.setBlock(world, i + 14, j + 32, k + 44, Blocks.stone, 0);
        this.setBlock(world, i + 14, j + 32, k + 45, Blocks.stone, 0);
        this.setBlock(world, i + 14, j + 32, k + 46, Blocks.stone, 0);
        this.setBlock(world, i + 14, j + 32, k + 47, Blocks.cobblestone, 0);
        this.setBlock(world, i + 14, j + 32, k + 48, Blocks.stone, 0);
        this.setBlock(world, i + 14, j + 32, k + 49, Blocks.bedrock, 0);
        this.setBlock(world, i + 14, j + 32, k + 50, Blocks.cobblestone, 0);
        this.setBlock(world, i + 14, j + 32, k + 51, Blocks.stone, 0);
        this.setBlock(world, i + 14, j + 32, k + 52, Blocks.bedrock, 0);
        this.setBlock(world, i + 14, j + 32, k + 53, Blocks.cobblestone, 0);
        this.setBlock(world, i + 14, j + 32, k + 54, Blocks.stone, 0);
        this.setBlock(world, i + 14, j + 32, k + 55, Blocks.stone, 0);
        this.setBlock(world, i + 14, j + 33, k + 31, Blocks.stonebrick, 0);
        this.setBlock(world, i + 14, j + 33, k + 37, Blocks.stonebrick, 0);
        this.setBlock(world, i + 14, j + 33, k + 43, Blocks.mycelium, 0);
        this.setBlock(world, i + 14, j + 33, k + 44, Blocks.mycelium, 0);
        this.setBlock(world, i + 14, j + 33, k + 45, Blocks.dirt, 0);
        this.setBlock(world, i + 14, j + 33, k + 46, Blocks.dirt, 0);
        this.setBlock(world, i + 14, j + 33, k + 47, Blocks.dirt, 0);
        this.setBlock(world, i + 14, j + 33, k + 48, Blocks.dirt, 0);
        this.setBlock(world, i + 14, j + 33, k + 49, Blocks.mycelium, 0);
        this.setBlock(world, i + 14, j + 33, k + 50, Blocks.mycelium, 0);
        this.setBlock(world, i + 14, j + 33, k + 51, Blocks.stone, 0);
        this.setBlock(world, i + 14, j + 34, k + 31, Blocks.stonebrick, 0);
        this.setBlock(world, i + 14, j + 34, k + 37, Blocks.stonebrick, 0);
        this.setBlock(world, i + 14, j + 34, k + 45, Blocks.mycelium, 0);
        this.setBlock(world, i + 14, j + 34, k + 46, Blocks.mycelium, 0);
        this.setBlock(world, i + 14, j + 34, k + 47, Blocks.mycelium, 0);
        this.setBlock(world, i + 14, j + 34, k + 48, Blocks.mycelium, 0);
        this.setBlock(world, i + 14, j + 35, k + 31, Blocks.stonebrick, 0);
        this.setBlock(world, i + 14, j + 35, k + 32, Blocks.stonebrick, 0);
        this.setBlock(world, i + 14, j + 35, k + 33, Blocks.stonebrick, 0);
        this.setBlock(world, i + 14, j + 35, k + 34, Blocks.stonebrick, 0);
        this.setBlock(world, i + 14, j + 35, k + 35, Blocks.stonebrick, 0);
        this.setBlock(world, i + 14, j + 35, k + 36, Blocks.stonebrick, 0);
        this.setBlock(world, i + 14, j + 35, k + 37, Blocks.stonebrick, 0);
        this.setBlock(world, i + 14, j + 36, k + 31, Blocks.stonebrick, 0);
        this.setBlock(world, i + 14, j + 36, k + 37, Blocks.stonebrick, 0);
        this.setBlock(world, i + 14, j + 37, k + 31, Blocks.stonebrick, 0);
        this.setBlock(world, i + 14, j + 37, k + 37, Blocks.stonebrick, 0);
        this.setBlock(world, i + 14, j + 38, k + 31, Blocks.stonebrick, 0);
        this.setBlock(world, i + 14, j + 38, k + 37, Blocks.stonebrick, 0);
        this.setBlock(world, i + 14, j + 39, k + 31, Blocks.stonebrick, 0);
        this.setBlock(world, i + 14, j + 39, k + 37, Blocks.stonebrick, 0);
        this.setBlock(world, i + 14, j + 40, k + 30, Blocks.cobblestone_wall, 0);
        this.setBlock(world, i + 14, j + 40, k + 31, Blocks.stonebrick, 0);
        this.setBlock(world, i + 14, j + 40, k + 32, Blocks.stonebrick, 0);
        this.setBlock(world, i + 14, j + 40, k + 33, Blocks.stonebrick, 0);
        this.setBlock(world, i + 14, j + 40, k + 34, Blocks.stonebrick, 0);
        this.setBlock(world, i + 14, j + 40, k + 35, Blocks.stonebrick, 0);
        this.setBlock(world, i + 14, j + 40, k + 36, Blocks.stonebrick, 0);
        this.setBlock(world, i + 14, j + 40, k + 37, Blocks.stonebrick, 0);
        this.setBlock(world, i + 14, j + 40, k + 38, Blocks.cobblestone_wall, 0);
        this.setBlock(world, i + 14, j + 41, k + 30, Blocks.stained_hardened_clay, 9);
        this.setBlock(world, i + 14, j + 41, k + 31, Blocks.stonebrick, 0);
        this.setBlock(world, i + 14, j + 41, k + 37, Blocks.stonebrick, 0);
        this.setBlock(world, i + 14, j + 41, k + 38, Blocks.stained_hardened_clay, 9);
        this.setBlock(world, i + 14, j + 42, k + 31, Blocks.stonebrick, 0);
        this.setBlock(world, i + 14, j + 42, k + 37, Blocks.stonebrick, 0);
        this.setBlock(world, i + 14, j + 43, k + 31, Blocks.stonebrick, 0);
        this.setBlock(world, i + 14, j + 43, k + 37, Blocks.stonebrick, 0);
        this.setBlock(world, i + 14, j + 44, k + 31, Blocks.stonebrick, 0);
        this.setBlock(world, i + 14, j + 44, k + 37, Blocks.stonebrick, 0);
        this.setBlock(world, i + 14, j + 45, k + 30, Blocks.cobblestone_wall, 0);
        this.setBlock(world, i + 14, j + 45, k + 31, Blocks.stonebrick, 0);
        this.setBlock(world, i + 14, j + 45, k + 32, Blocks.stonebrick, 0);
        this.setBlock(world, i + 14, j + 45, k + 33, Blocks.stonebrick, 0);
        this.setBlock(world, i + 14, j + 45, k + 34, Blocks.stonebrick, 0);
        this.setBlock(world, i + 14, j + 45, k + 35, Blocks.stonebrick, 0);
        this.setBlock(world, i + 14, j + 45, k + 36, Blocks.stonebrick, 0);
        this.setBlock(world, i + 14, j + 45, k + 37, Blocks.stonebrick, 0);
        this.setBlock(world, i + 14, j + 45, k + 38, Blocks.cobblestone_wall, 0);
        this.setBlock(world, i + 14, j + 46, k + 30, Blocks.stained_hardened_clay, 9);
        this.setBlock(world, i + 14, j + 46, k + 31, Blocks.stonebrick, 0);
        this.setBlock(world, i + 14, j + 46, k + 37, Blocks.stonebrick, 0);
        this.setBlock(world, i + 14, j + 46, k + 38, Blocks.stained_hardened_clay, 9);
        this.setBlock(world, i + 14, j + 47, k + 31, Blocks.stonebrick, 0);
        this.setBlock(world, i + 14, j + 47, k + 37, Blocks.stonebrick, 0);
        this.setBlock(world, i + 14, j + 48, k + 31, Blocks.stonebrick, 0);
        this.setBlock(world, i + 14, j + 48, k + 37, Blocks.stonebrick, 0);
        this.setBlock(world, i + 14, j + 49, k + 31, Blocks.stonebrick, 0);
        this.setBlock(world, i + 14, j + 49, k + 37, Blocks.stonebrick, 0);
        this.setBlock(world, i + 14, j + 50, k + 30, Blocks.cobblestone_wall, 0);
        this.setBlock(world, i + 14, j + 50, k + 31, Blocks.stonebrick, 0);
        this.setBlock(world, i + 14, j + 50, k + 37, Blocks.stonebrick, 0);
        this.setBlock(world, i + 14, j + 50, k + 38, Blocks.cobblestone_wall, 0);
        this.setBlock(world, i + 14, j + 51, k + 30, Blocks.stained_hardened_clay, 9);
        this.setBlock(world, i + 14, j + 51, k + 31, Blocks.stonebrick, 0);
        this.setBlock(world, i + 14, j + 51, k + 33, Blocks.bedrock, 0);
        this.setBlock(world, i + 14, j + 51, k + 35, Blocks.bedrock, 0);
        this.setBlock(world, i + 14, j + 51, k + 37, Blocks.stonebrick, 0);
        this.setBlock(world, i + 14, j + 51, k + 38, Blocks.stained_hardened_clay, 9);
        this.setBlock(world, i + 14, j + 52, k + 32, Blocks.stonebrick, 0);
        this.setBlock(world, i + 14, j + 52, k + 33, Blocks.bedrock, 0);
        this.setBlock(world, i + 14, j + 52, k + 34, Blocks.stonebrick, 0);
        this.setBlock(world, i + 14, j + 52, k + 35, Blocks.bedrock, 0);
        this.setBlock(world, i + 14, j + 52, k + 36, Blocks.stonebrick, 0);
        this.setBlock(world, i + 14, j + 53, k + 33, Blocks.bedrock, 0);
        this.setBlock(world, i + 14, j + 53, k + 35, Blocks.bedrock, 0);
        this.setBlock(world, i + 15, j + 23, k + 46, Blocks.stone, 0);
        this.setBlock(world, i + 15, j + 23, k + 47, Blocks.cobblestone, 0);
        this.setBlock(world, i + 15, j + 23, k + 48, Blocks.stone, 0);
        this.setBlock(world, i + 15, j + 23, k + 49, Blocks.stone, 0);
        this.setBlock(world, i + 15, j + 24, k + 38, Blocks.stone, 0);
        this.setBlock(world, i + 15, j + 24, k + 39, Blocks.stone, 0);
        this.setBlock(world, i + 15, j + 24, k + 40, Blocks.cobblestone, 0);
        this.setBlock(world, i + 15, j + 24, k + 45, Blocks.bedrock, 0);
        this.setBlock(world, i + 15, j + 24, k + 46, Blocks.bedrock, 0);
        this.setBlock(world, i + 15, j + 24, k + 47, Blocks.stone, 0);
        this.setBlock(world, i + 15, j + 24, k + 48, Blocks.cobblestone, 0);
        this.setBlock(world, i + 15, j + 24, k + 49, Blocks.stone, 0);
        this.setBlock(world, i + 15, j + 24, k + 50, Blocks.stone, 0);
        this.setBlock(world, i + 15, j + 24, k + 51, Blocks.stone, 0);
        this.setBlock(world, i + 15, j + 24, k + 52, Blocks.stone, 0);
        this.setBlock(world, i + 15, j + 24, k + 53, Blocks.stone, 0);
        this.setBlock(world, i + 15, j + 24, k + 57, Blocks.stone, 0);
        this.setBlock(world, i + 15, j + 25, k + 32, Blocks.bedrock, 0);
        this.setBlock(world, i + 15, j + 25, k + 33, Blocks.cobblestone, 0);
        this.setBlock(world, i + 15, j + 25, k + 34, Blocks.stone, 0);
        this.setBlock(world, i + 15, j + 25, k + 35, Blocks.cobblestone, 0);
        this.setBlock(world, i + 15, j + 25, k + 36, Blocks.bedrock, 0);
        this.setBlock(world, i + 15, j + 25, k + 37, Blocks.stone, 0);
        this.setBlock(world, i + 15, j + 25, k + 38, Blocks.stone, 0);
        this.setBlock(world, i + 15, j + 25, k + 39, Blocks.stone, 0);
        this.setBlock(world, i + 15, j + 25, k + 40, Blocks.stone, 0);
        this.setBlock(world, i + 15, j + 25, k + 41, Blocks.cobblestone, 0);
        this.setBlock(world, i + 15, j + 25, k + 42, Blocks.stone, 0);
        this.setBlock(world, i + 15, j + 25, k + 43, Blocks.stone, 0);
        this.setBlock(world, i + 15, j + 25, k + 44, Blocks.stone, 0);
        this.setBlock(world, i + 15, j + 25, k + 45, Blocks.stone, 0);
        this.setBlock(world, i + 15, j + 25, k + 46, Blocks.cobblestone, 0);
        this.setBlock(world, i + 15, j + 25, k + 47, Blocks.stone, 0);
        this.setBlock(world, i + 15, j + 25, k + 48, Blocks.stone, 0);
        this.setBlock(world, i + 15, j + 25, k + 49, Blocks.stone, 0);
        this.setBlock(world, i + 15, j + 25, k + 50, Blocks.stone, 0);
        this.setBlock(world, i + 15, j + 25, k + 51, Blocks.stone, 0);
        this.setBlock(world, i + 15, j + 25, k + 52, Blocks.stone, 0);
        this.setBlock(world, i + 15, j + 25, k + 53, Blocks.stone, 0);
        this.setBlock(world, i + 15, j + 25, k + 54, Blocks.stone, 0);
        this.setBlock(world, i + 15, j + 25, k + 55, Blocks.stone, 0);
        this.setBlock(world, i + 15, j + 25, k + 56, Blocks.stone, 0);
        this.setBlock(world, i + 15, j + 25, k + 57, Blocks.stone, 0);
        this.setBlock(world, i + 15, j + 25, k + 58, Blocks.stone, 0);
        this.setBlock(world, i + 15, j + 25, k + 59, Blocks.stone, 0);
        this.setBlock(world, i + 15, j + 26, k + 31, Blocks.stone, 0);
        this.setBlock(world, i + 15, j + 26, k + 32, Blocks.stone, 0);
        this.setBlock(world, i + 15, j + 26, k + 33, Blocks.cobblestone, 0);
        this.setBlock(world, i + 15, j + 26, k + 34, Blocks.stone, 0);
        this.setBlock(world, i + 15, j + 26, k + 35, Blocks.cobblestone, 0);
        this.setBlock(world, i + 15, j + 26, k + 36, Blocks.stone, 0);
        this.setBlock(world, i + 15, j + 26, k + 37, Blocks.stone, 0);
        this.setBlock(world, i + 15, j + 26, k + 38, Blocks.stone, 0);
        this.setBlock(world, i + 15, j + 26, k + 39, Blocks.bedrock, 0);
        this.setBlock(world, i + 15, j + 26, k + 40, Blocks.bedrock, 0);
        this.setBlock(world, i + 15, j + 26, k + 41, Blocks.stone, 0);
        this.setBlock(world, i + 15, j + 26, k + 42, Blocks.stone, 0);
        this.setBlock(world, i + 15, j + 26, k + 43, Blocks.stone, 0);
        this.setBlock(world, i + 15, j + 26, k + 44, Blocks.stone, 0);
        this.setBlock(world, i + 15, j + 26, k + 45, Blocks.stone, 0);
        this.setBlock(world, i + 15, j + 26, k + 46, Blocks.stone, 0);
        this.setBlock(world, i + 15, j + 26, k + 47, Blocks.stone, 0);
        this.setBlock(world, i + 15, j + 26, k + 48, Blocks.stone, 0);
        this.setBlock(world, i + 15, j + 26, k + 49, Blocks.stone, 0);
        this.setBlock(world, i + 15, j + 26, k + 50, Blocks.stone, 0);
        this.setBlock(world, i + 15, j + 26, k + 51, Blocks.bedrock, 0);
        this.setBlock(world, i + 15, j + 26, k + 52, Blocks.stone, 0);
        this.setBlock(world, i + 15, j + 26, k + 53, Blocks.stone, 0);
        this.setBlock(world, i + 15, j + 26, k + 54, Blocks.stone, 0);
        this.setBlock(world, i + 15, j + 26, k + 55, Blocks.stone, 0);
        this.setBlock(world, i + 15, j + 26, k + 56, Blocks.stone, 0);
        this.setBlock(world, i + 15, j + 26, k + 57, Blocks.stone, 0);
        this.setBlock(world, i + 15, j + 26, k + 58, Blocks.stone, 0);
        this.setBlock(world, i + 15, j + 26, k + 59, Blocks.stone, 0);
        this.setBlock(world, i + 15, j + 26, k + 60, Blocks.bedrock, 0);
        this.setBlock(world, i + 15, j + 26, k + 61, Blocks.stone, 0);
        this.setBlock(world, i + 15, j + 26, k + 62, Blocks.stone, 0);
        this.setBlock(world, i + 15, j + 26, k + 63, Blocks.bedrock, 0);
        this.setBlock(world, i + 15, j + 26, k + 64, Blocks.stone, 0);
        this.setBlock(world, i + 15, j + 27, k + 30, Blocks.stone, 0);
        this.setBlock(world, i + 15, j + 27, k + 31, Blocks.stone, 0);
        this.setBlock(world, i + 15, j + 27, k + 32, Blocks.stone, 0);
        this.setBlock(world, i + 15, j + 27, k + 33, Blocks.stone, 0);
        this.setBlock(world, i + 15, j + 27, k + 34, Blocks.stone, 0);
        this.setBlock(world, i + 15, j + 27, k + 35, Blocks.cobblestone, 0);
        this.setBlock(world, i + 15, j + 27, k + 36, Blocks.stone, 0);
        this.setBlock(world, i + 15, j + 27, k + 37, Blocks.bedrock, 0);
        this.setBlock(world, i + 15, j + 27, k + 38, Blocks.stone, 0);
        this.setBlock(world, i + 15, j + 27, k + 39, Blocks.stone, 0);
        this.setBlock(world, i + 15, j + 27, k + 40, Blocks.bedrock, 0);
        this.setBlock(world, i + 15, j + 27, k + 41, Blocks.stone, 0);
        this.setBlock(world, i + 15, j + 27, k + 42, Blocks.stone, 0);
        this.setBlock(world, i + 15, j + 27, k + 43, Blocks.stone, 0);
        this.setBlock(world, i + 15, j + 27, k + 44, Blocks.stone, 0);
        this.setBlock(world, i + 15, j + 27, k + 45, Blocks.stone, 0);
        this.setBlock(world, i + 15, j + 27, k + 46, Blocks.stone, 0);
        this.setBlock(world, i + 15, j + 27, k + 47, Blocks.stone, 0);
        this.setBlock(world, i + 15, j + 27, k + 48, Blocks.stone, 0);
        this.setBlock(world, i + 15, j + 27, k + 49, Blocks.stone, 0);
        this.setBlock(world, i + 15, j + 27, k + 50, Blocks.stone, 0);
        this.setBlock(world, i + 15, j + 27, k + 51, Blocks.stone, 0);
        this.setBlock(world, i + 15, j + 27, k + 52, Blocks.stone, 0);
        this.setBlock(world, i + 15, j + 27, k + 53, Blocks.stone, 0);
        this.setBlock(world, i + 15, j + 27, k + 54, Blocks.stone, 0);
        this.setBlock(world, i + 15, j + 27, k + 55, Blocks.cobblestone, 0);
        this.setBlock(world, i + 15, j + 27, k + 56, Blocks.bedrock, 0);
        this.setBlock(world, i + 15, j + 27, k + 57, Blocks.cobblestone, 0);
        this.setBlock(world, i + 15, j + 27, k + 58, Blocks.stone, 0);
        this.setBlock(world, i + 15, j + 27, k + 59, Blocks.stone, 0);
        this.setBlock(world, i + 15, j + 27, k + 60, Blocks.stone, 0);
        this.setBlock(world, i + 15, j + 27, k + 61, Blocks.stone, 0);
        this.setBlock(world, i + 15, j + 27, k + 62, Blocks.stone, 0);
        this.setBlock(world, i + 15, j + 27, k + 63, Blocks.stone, 0);
        this.setBlock(world, i + 15, j + 27, k + 64, Blocks.stone, 0);
        this.setBlock(world, i + 15, j + 27, k + 65, Blocks.cobblestone, 0);
        this.setBlock(world, i + 15, j + 28, k + 30, Blocks.cobblestone, 0);
        this.setBlock(world, i + 15, j + 28, k + 31, Blocks.stone, 0);
        this.setBlock(world, i + 15, j + 28, k + 32, Blocks.bedrock, 0);
        this.setBlock(world, i + 15, j + 28, k + 33, Blocks.stone, 0);
        this.setBlock(world, i + 15, j + 28, k + 34, Blocks.cobblestone, 0);
        this.setBlock(world, i + 15, j + 28, k + 35, Blocks.stone, 0);
        this.setBlock(world, i + 15, j + 28, k + 36, Blocks.stone, 0);
        this.setBlock(world, i + 15, j + 28, k + 37, Blocks.stone, 0);
        this.setBlock(world, i + 15, j + 28, k + 38, Blocks.stone, 0);
        this.setBlock(world, i + 15, j + 28, k + 39, Blocks.stone, 0);
        this.setBlock(world, i + 15, j + 28, k + 40, Blocks.stone, 0);
        this.setBlock(world, i + 15, j + 28, k + 41, Blocks.stone, 0);
        this.setBlock(world, i + 15, j + 28, k + 42, Blocks.stone, 0);
        this.setBlock(world, i + 15, j + 28, k + 43, Blocks.stone, 0);
        this.setBlock(world, i + 15, j + 28, k + 44, Blocks.bedrock, 0);
        this.setBlock(world, i + 15, j + 28, k + 45, Blocks.stone, 0);
        this.setBlock(world, i + 15, j + 28, k + 46, Blocks.bedrock, 0);
        this.setBlock(world, i + 15, j + 28, k + 47, Blocks.stone, 0);
        this.setBlock(world, i + 15, j + 28, k + 48, Blocks.stone, 0);
        this.setBlock(world, i + 15, j + 28, k + 49, Blocks.bedrock, 0);
        this.setBlock(world, i + 15, j + 28, k + 50, Blocks.stone, 0);
        this.setBlock(world, i + 15, j + 28, k + 51, Blocks.stone, 0);
        this.setBlock(world, i + 15, j + 28, k + 52, Blocks.bedrock, 0);
        this.setBlock(world, i + 15, j + 28, k + 53, Blocks.cobblestone, 0);
        this.setBlock(world, i + 15, j + 28, k + 54, Blocks.stone, 0);
        this.setBlock(world, i + 15, j + 28, k + 55, Blocks.cobblestone, 0);
        this.setBlock(world, i + 15, j + 28, k + 56, Blocks.stone, 0);
        this.setBlock(world, i + 15, j + 28, k + 57, Blocks.stone, 0);
        this.setBlock(world, i + 15, j + 28, k + 58, Blocks.stone, 0);
        this.setBlock(world, i + 15, j + 28, k + 59, Blocks.stone, 0);
        this.setBlock(world, i + 15, j + 28, k + 60, Blocks.stone, 0);
        this.setBlock(world, i + 15, j + 28, k + 61, Blocks.stone, 0);
        this.setBlock(world, i + 15, j + 28, k + 62, Blocks.stone, 0);
        this.setBlock(world, i + 15, j + 28, k + 63, Blocks.stone, 0);
        this.setBlock(world, i + 15, j + 28, k + 64, Blocks.cobblestone, 0);
        this.setBlock(world, i + 15, j + 28, k + 65, Blocks.stone, 0);
        this.setBlock(world, i + 15, j + 28, k + 66, Blocks.stone, 0);
        this.setBlock(world, i + 15, j + 28, k + 67, Blocks.stone, 0);
        this.setBlock(world, i + 15, j + 29, k + 30, Blocks.stone, 0);
        this.setBlock(world, i + 15, j + 29, k + 31, Blocks.stone, 0);
