

package com.gibby.dungeon.gen;

import com.gibby.dungeon.Dungeons;
import com.gibby.dungeon.mobs.entityinstance.EntityAnchorTrader;
import cpw.mods.fml.common.IWorldGenerator;
import net.minecraft.block.Block;
import net.minecraft.init.Blocks;
import net.minecraft.world.World;
import net.minecraft.world.chunk.IChunkProvider;
import net.minecraft.world.gen.feature.WorldGenerator;

import java.util.Random;

public class WorldGenCrystalHouse extends WorldGenerator implements IWorldGenerator
{
    public void generate(final Random random, final int chunkX, final int chunkZ, final World world, final IChunkProvider chunkGenerator, final IChunkProvider chunkProvider) {
    }

    public void setBlock(final World world, final int x, final int y, final int z, final Block block, final int metadata) {
        final Block b1 = world.getBlock(x, y, z);
        world.setBlock(x, y, z, block, metadata, 2);
    }

    public boolean generate(final World world, final Random rand, final int i, final int j, final int k) {
        if (world.getBlock(i, j, k) != Blocks.air || world.getBlock(i + 13, j, k + 13) != Blocks.air || world.getBlock(i + 13, j - 1, k + 13) == Blocks.air || world.getBlock(i, j - 1, k) == Blocks.air) {
            return false;
        }
        this.setBlock(world, i, j + 1, k + 4, Blocks.obsidian, 0);
        this.setBlock(world, i, j + 1, k + 5, Blocks.obsidian, 0);
        this.setBlock(world, i, j + 1, k + 6, Blocks.obsidian, 0);
        this.setBlock(world, i, j + 1, k + 7, Blocks.obsidian, 0);
        this.setBlock(world, i, j + 1, k + 8, Blocks.obsidian, 0);
        this.setBlock(world, i, j + 2, k + 4, Blocks.obsidian, 0);
        this.setBlock(world, i, j + 2, k + 5, Blocks.obsidian, 0);
        this.setBlock(world, i, j + 2, k + 6, Blocks.obsidian, 0);
        this.setBlock(world, i, j + 2, k + 7, Blocks.obsidian, 0);
        this.setBlock(world, i, j + 2, k + 8, Blocks.obsidian, 0);
        this.setBlock(world, i, j + 3, k + 4, Blocks.obsidian, 0);
        this.setBlock(world, i, j + 3, k + 5, Blocks.obsidian, 0);
        this.setBlock(world, i, j + 3, k + 6, Blocks.obsidian, 0);
        this.setBlock(world, i, j + 3, k + 7, Blocks.obsidian, 0);
        this.setBlock(world, i, j + 3, k + 8, Blocks.obsidian, 0);
        this.setBlock(world, i, j + 4, k + 4, Blocks.obsidian, 0);
        this.setBlock(world, i, j + 4, k + 5, Blocks.obsidian, 0);
        this.setBlock(world, i, j + 4, k + 6, Blocks.obsidian, 0);
        this.setBlock(world, i, j + 4, k + 7, Blocks.obsidian, 0);
        this.setBlock(world, i, j + 4, k + 8, Blocks.obsidian, 0);
        this.setBlock(world, i, j + 5, k + 4, Blocks.obsidian, 0);
        this.setBlock(world, i, j + 5, k + 5, Blocks.obsidian, 0);
        this.setBlock(world, i, j + 5, k + 7, Blocks.obsidian, 0);
        this.setBlock(world, i, j + 5, k + 8, Blocks.obsidian, 0);
        this.setBlock(world, i, j + 6, k + 4, Blocks.obsidian, 0);
        this.setBlock(world, i, j + 6, k + 5, Blocks.obsidian, 0);
        this.setBlock(world, i, j + 6, k + 7, Blocks.obsidian, 0);
        this.setBlock(world, i, j + 7, k + 4, Blocks.obsidian, 0);
        this.setBlock(world, i, j + 7, k + 7, Blocks.obsidian, 0);
        this.setBlock(world, i, j + 8, k + 4, Blocks.obsidian, 0);
        this.setBlock(world, i, j + 8, k + 7, Blocks.obsidian, 0);
        this.setBlock(world, i + 1, j, k + 4, Blocks.obsidian, 0);
        this.setBlock(world, i + 1, j, k + 5, Blocks.obsidian, 0);
        this.setBlock(world, i + 1, j, k + 6, Blocks.obsidian, 0);
        this.setBlock(world, i + 1, j, k + 7, Blocks.obsidian, 0);
        this.setBlock(world, i + 1, j, k + 8, Blocks.obsidian, 0);
        this.setBlock(world, i + 1, j + 1, k + 3, Blocks.obsidian, 0);
        this.setBlock(world, i + 1, j + 1, k + 4, Blocks.wool, 10);
        this.setBlock(world, i + 1, j + 1, k + 5, Blocks.wool, 10);
        this.setBlock(world, i + 1, j + 1, k + 6, Blocks.wool, 10);
        this.setBlock(world, i + 1, j + 1, k + 7, Blocks.wool, 10);
        this.setBlock(world, i + 1, j + 1, k + 8, Blocks.wool, 10);
        this.setBlock(world, i + 1, j + 1, k + 9, Blocks.obsidian, 0);
        this.setBlock(world, i + 1, j + 2, k + 3, Blocks.obsidian, 0);
        this.setBlock(world, i + 1, j + 2, k + 4, Blocks.wool, 10);
        this.setBlock(world, i + 1, j + 2, k + 5, Blocks.wool, 10);
        this.setBlock(world, i + 1, j + 2, k + 6, Blocks.wool, 10);
        this.setBlock(world, i + 1, j + 2, k + 7, Blocks.wool, 10);
        this.setBlock(world, i + 1, j + 2, k + 8, Blocks.wool, 10);
        this.setBlock(world, i + 1, j + 2, k + 9, Blocks.obsidian, 0);
        this.setBlock(world, i + 1, j + 3, k + 3, Blocks.obsidian, 0);
        this.setBlock(world, i + 1, j + 3, k + 4, Blocks.wool, 10);
        this.setBlock(world, i + 1, j + 3, k + 5, Blocks.wool, 10);
        this.setBlock(world, i + 1, j + 3, k + 6, Blocks.wool, 10);
        this.setBlock(world, i + 1, j + 3, k + 7, Blocks.wool, 10);
        this.setBlock(world, i + 1, j + 3, k + 8, Blocks.wool, 10);
        this.setBlock(world, i + 1, j + 3, k + 9, Blocks.obsidian, 0);
        this.setBlock(world, i + 1, j + 4, k + 3, Blocks.obsidian, 0);
        this.setBlock(world, i + 1, j + 4, k + 4, Blocks.wool, 10);
        this.setBlock(world, i + 1, j + 4, k + 5, Blocks.wool, 10);
        this.setBlock(world, i + 1, j + 4, k + 6, Blocks.wool, 10);
        this.setBlock(world, i + 1, j + 4, k + 7, Blocks.wool, 10);
        this.setBlock(world, i + 1, j + 4, k + 8, Blocks.wool, 10);
        this.setBlock(world, i + 1, j + 4, k + 9, Blocks.obsidian, 0);
        this.setBlock(world, i + 1, j + 5, k + 3, Blocks.obsidian, 0);
        this.setBlock(world, i + 1, j + 5, k + 4, Blocks.wool, 10);
        this.setBlock(world, i + 1, j + 5, k + 5, Blocks.wool, 10);
        this.setBlock(world, i + 1, j + 5, k + 7, Blocks.wool, 10);
        this.setBlock(world, i + 1, j + 5, k + 8, Blocks.wool, 10);
        this.setBlock(world, i + 1, j + 5, k + 9, Blocks.obsidian, 0);
        this.setBlock(world, i + 1, j + 6, k + 3, Blocks.obsidian, 0);
        this.setBlock(world, i + 1, j + 6, k + 4, Blocks.wool, 10);
        this.setBlock(world, i + 1, j + 6, k + 5, Blocks.wool, 10);
        this.setBlock(world, i + 1, j + 6, k + 7, Blocks.wool, 10);
        this.setBlock(world, i + 1, j + 7, k + 4, Blocks.wool, 10);
        this.setBlock(world, i + 1, j + 7, k + 7, Blocks.wool, 10);
        this.setBlock(world, i + 1, j + 8, k + 4, Blocks.wool, 10);
        this.setBlock(world, i + 1, j + 8, k + 7, Blocks.wool, 10);
        this.setBlock(world, i + 1, j + 9, k + 4, Blocks.obsidian, 0);
        this.setBlock(world, i + 1, j + 9, k + 7, Blocks.obsidian, 0);
        this.setBlock(world, i + 2, j, k + 3, Blocks.obsidian, 0);
        this.setBlock(world, i + 2, j, k + 4, Blocks.wool, 10);
        this.setBlock(world, i + 2, j, k + 5, Blocks.wool, 10);
        this.setBlock(world, i + 2, j, k + 6, Blocks.wool, 10);
        this.setBlock(world, i + 2, j, k + 7, Blocks.wool, 10);
        this.setBlock(world, i + 2, j, k + 8, Blocks.wool, 10);
        this.setBlock(world, i + 2, j, k + 9, Blocks.obsidian, 0);
        this.setBlock(world, i + 2, j + 1, k + 2, Blocks.obsidian, 0);
        this.setBlock(world, i + 2, j + 1, k + 3, Blocks.wool, 10);
        this.setBlock(world, i + 2, j + 1, k + 6, Blocks.crafting_table, 0);
        this.setBlock(world, i + 2, j + 1, k + 9, Blocks.wool, 10);
        this.setBlock(world, i + 2, j + 1, k + 10, Blocks.obsidian, 0);
        this.setBlock(world, i + 2, j + 2, k + 2, Blocks.obsidian, 0);
        this.setBlock(world, i + 2, j + 2, k + 3, Blocks.wool, 10);
        this.setBlock(world, i + 2, j + 2, k + 9, Blocks.wool, 10);
        this.setBlock(world, i + 2, j + 2, k + 10, Blocks.obsidian, 0);
        this.setBlock(world, i + 2, j + 3, k + 2, Blocks.obsidian, 0);
        this.setBlock(world, i + 2, j + 3, k + 3, Blocks.wool, 10);
        this.setBlock(world, i + 2, j + 3, k + 9, Blocks.wool, 10);
        this.setBlock(world, i + 2, j + 3, k + 10, Blocks.obsidian, 0);
        this.setBlock(world, i + 2, j + 4, k + 2, Blocks.obsidian, 0);
        this.setBlock(world, i + 2, j + 4, k + 3, Blocks.wool, 10);
        this.setBlock(world, i + 2, j + 4, k + 9, Blocks.wool, 10);
        this.setBlock(world, i + 2, j + 4, k + 10, Blocks.obsidian, 0);
        this.setBlock(world, i + 2, j + 5, k + 2, Blocks.obsidian, 0);
        this.setBlock(world, i + 2, j + 5, k + 3, Blocks.wool, 10);
        this.setBlock(world, i + 2, j + 5, k + 9, Blocks.wool, 10);
        this.setBlock(world, i + 2, j + 5, k + 10, Blocks.obsidian, 0);
        this.setBlock(world, i + 2, j + 6, k + 2, Blocks.obsidian, 0);
        this.setBlock(world, i + 2, j + 6, k + 3, Blocks.wool, 10);
        this.setBlock(world, i + 2, j + 6, k + 10, Blocks.obsidian, 0);
        this.setBlock(world, i + 2, j + 7, k + 2, Blocks.obsidian, 0);
        this.setBlock(world, i + 2, j + 7, k + 10, Blocks.obsidian, 0);
        this.setBlock(world, i + 2, j + 8, k + 2, Blocks.obsidian, 0);
        this.setBlock(world, i + 2, j + 8, k + 4, Blocks.wool, 10);
        this.setBlock(world, i + 2, j + 8, k + 7, Blocks.wool, 10);
        this.setBlock(world, i + 2, j + 9, k + 2, Blocks.obsidian, 0);
        this.setBlock(world, i + 2, j + 9, k + 4, Blocks.obsidian, 0);
        this.setBlock(world, i + 2, j + 9, k + 5, Blocks.obsidian, 0);
        this.setBlock(world, i + 2, j + 9, k + 6, Blocks.obsidian, 0);
        this.setBlock(world, i + 2, j + 9, k + 7, Blocks.obsidian, 0);
        this.setBlock(world, i + 3, j, k + 2, Blocks.obsidian, 0);
        this.setBlock(world, i + 3, j, k + 3, Blocks.wool, 10);
        this.setBlock(world, i + 3, j, k + 4, Blocks.wool, 10);
        this.setBlock(world, i + 3, j, k + 5, Blocks.wool, 10);
        this.setBlock(world, i + 3, j, k + 6, Blocks.wool, 10);
        this.setBlock(world, i + 3, j, k + 7, Blocks.wool, 10);
        this.setBlock(world, i + 3, j, k + 8, Blocks.wool, 10);
        this.setBlock(world, i + 3, j, k + 9, Blocks.wool, 10);
        this.setBlock(world, i + 3, j, k + 10, Blocks.obsidian, 0);
        this.setBlock(world, i + 3, j + 1, k + 1, Blocks.obsidian, 0);
        this.setBlock(world, i + 3, j + 1, k + 2, Blocks.wool, 10);
        this.setBlock(world, i + 3, j + 1, k + 10, Blocks.wool, 10);
        this.setBlock(world, i + 3, j + 1, k + 11, Blocks.obsidian, 0);
        this.setBlock(world, i + 3, j + 2, k + 1, Blocks.obsidian, 0);
        this.setBlock(world, i + 3, j + 2, k + 2, Blocks.wool, 10);
        this.setBlock(world, i + 3, j + 2, k + 10, Blocks.wool, 10);
        this.setBlock(world, i + 3, j + 2, k + 11, Blocks.obsidian, 0);
        this.setBlock(world, i + 3, j + 3, k + 1, Blocks.obsidian, 0);
        this.setBlock(world, i + 3, j + 3, k + 2, Blocks.wool, 10);
        this.setBlock(world, i + 3, j + 3, k + 10, Blocks.wool, 10);
        this.setBlock(world, i + 3, j + 3, k + 11, Blocks.obsidian, 0);
        this.setBlock(world, i + 3, j + 4, k + 1, Blocks.obsidian, 0);
        this.setBlock(world, i + 3, j + 4, k + 2, Blocks.wool, 10);
        this.setBlock(world, i + 3, j + 4, k + 10, Blocks.wool, 10);
        this.setBlock(world, i + 3, j + 4, k + 11, Blocks.obsidian, 0);
        this.setBlock(world, i + 3, j + 5, k + 1, Blocks.obsidian, 0);
        this.setBlock(world, i + 3, j + 5, k + 2, Blocks.wool, 10);
        this.setBlock(world, i + 3, j + 6, k + 1, Blocks.obsidian, 0);
        this.setBlock(world, i + 3, j + 6, k + 2, Blocks.wool, 10);
        this.setBlock(world, i + 3, j + 7, k + 2, Blocks.wool, 10);
        this.setBlock(world, i + 3, j + 8, k + 2, Blocks.wool, 10);
        this.setBlock(world, i + 3, j + 8, k + 4, Blocks.wool, 10);
        this.setBlock(world, i + 3, j + 8, k + 7, Blocks.wool, 10);
        this.setBlock(world, i + 3, j + 9, k + 2, Blocks.wool, 10);
        this.setBlock(world, i + 3, j + 9, k + 4, Blocks.obsidian, 0);
        this.setBlock(world, i + 3, j + 9, k + 5, Blocks.obsidian, 0);
        this.setBlock(world, i + 3, j + 9, k + 6, Blocks.obsidian, 0);
        this.setBlock(world, i + 3, j + 9, k + 7, Blocks.obsidian, 0);
        this.setBlock(world, i + 3, j + 10, k + 2, Blocks.obsidian, 0);
        this.setBlock(world, i + 4, j, k + 2, Blocks.obsidian, 0);
        this.setBlock(world, i + 4, j, k + 3, Blocks.wool, 10);
        this.setBlock(world, i + 4, j, k + 4, Dungeons.purpleBrick, 0);
        this.setBlock(world, i + 4, j, k + 5, Dungeons.purpleBrick, 0);
        this.setBlock(world, i + 4, j, k + 6, Dungeons.purpleBrick, 0);
        this.setBlock(world, i + 4, j, k + 7, Dungeons.purpleBrick, 0);
        this.setBlock(world, i + 4, j, k + 8, Dungeons.purpleBrick, 0);
        this.setBlock(world, i + 4, j, k + 9, Blocks.wool, 10);
        this.setBlock(world, i + 4, j, k + 10, Blocks.wool, 10);
        this.setBlock(world, i + 4, j, k + 11, Blocks.obsidian, 0);
        this.setBlock(world, i + 4, j + 1, k + 1, Blocks.obsidian, 0);
        this.setBlock(world, i + 4, j + 1, k + 2, Blocks.wool, 10);
        this.setBlock(world, i + 4, j + 1, k + 4, Dungeons.purpleBrick, 0);
        this.setBlock(world, i + 4, j + 1, k + 8, Dungeons.purpleBrick, 0);
        this.setBlock(world, i + 4, j + 1, k + 11, Blocks.wool, 10);
        this.setBlock(world, i + 4, j + 1, k + 12, Blocks.obsidian, 0);
        this.setBlock(world, i + 4, j + 2, k + 1, Blocks.obsidian, 0);
        this.setBlock(world, i + 4, j + 2, k + 2, Blocks.wool, 10);
        this.setBlock(world, i + 4, j + 2, k + 4, Dungeons.purpleBrick, 0);
        this.setBlock(world, i + 4, j + 2, k + 8, Dungeons.purpleBrick, 0);
        this.setBlock(world, i + 4, j + 2, k + 11, Blocks.wool, 10);
        this.setBlock(world, i + 4, j + 2, k + 12, Blocks.obsidian, 0);
        this.setBlock(world, i + 4, j + 3, k + 1, Blocks.obsidian, 0);
        this.setBlock(world, i + 4, j + 3, k + 2, Blocks.wool, 10);
        this.setBlock(world, i + 4, j + 3, k + 4, Dungeons.purpleBrick, 0);
        this.setBlock(world, i + 4, j + 3, k + 5, Dungeons.purpleBrick, 0);
        this.setBlock(world, i + 4, j + 3, k + 7, Dungeons.purpleBrick, 0);
        this.setBlock(world, i + 4, j + 3, k + 8, Dungeons.purpleBrick, 0);
        this.setBlock(world, i + 4, j + 3, k + 11, Blocks.wool, 10);
        this.setBlock(world, i + 4, j + 3, k + 12, Blocks.obsidian, 0);
        this.setBlock(world, i + 4, j + 4, k + 1, Blocks.obsidian, 0);
        this.setBlock(world, i + 4, j + 4, k + 2, Blocks.wool, 10);
        this.setBlock(world, i + 4, j + 4, k + 4, Dungeons.purpleBrick, 0);
        this.setBlock(world, i + 4, j + 4, k + 5, Dungeons.purpleBrick, 0);
        this.setBlock(world, i + 4, j + 4, k + 6, Dungeons.purpleBrick, 0);
        this.setBlock(world, i + 4, j + 4, k + 7, Dungeons.purpleBrick, 0);
        this.setBlock(world, i + 4, j + 4, k + 8, Dungeons.purpleBrick, 0);
        this.setBlock(world, i + 4, j + 4, k + 11, Blocks.wool, 10);
        this.setBlock(world, i + 4, j + 4, k + 12, Blocks.obsidian, 0);
        this.setBlock(world, i + 4, j + 5, k + 1, Blocks.obsidian, 0);
        this.setBlock(world, i + 4, j + 5, k + 2, Blocks.wool, 10);
        this.setBlock(world, i + 4, j + 5, k + 5, Dungeons.purpleBrick, 0);
        this.setBlock(world, i + 4, j + 5, k + 6, Dungeons.purpleBrick, 0);
        this.setBlock(world, i + 4, j + 5, k + 7, Dungeons.purpleBrick, 0);
        this.setBlock(world, i + 4, j + 5, k + 11, Blocks.wool, 10);
        this.setBlock(world, i + 4, j + 5, k + 12, Blocks.obsidian, 0);
        this.setBlock(world, i + 4, j + 6, k + 1, Blocks.obsidian, 0);
        this.setBlock(world, i + 4, j + 6, k + 2, Blocks.wool, 10);
        this.setBlock(world, i + 4, j + 6, k + 6, Dungeons.purpleBrick, 0);
        this.setBlock(world, i + 4, j + 6, k + 11, Blocks.wool, 10);
        this.setBlock(world, i + 4, j + 6, k + 12, Blocks.obsidian, 0);
        this.setBlock(world, i + 4, j + 7, k + 1, Blocks.obsidian, 0);
        this.setBlock(world, i + 4, j + 7, k + 2, Blocks.wool, 10);
        this.setBlock(world, i + 4, j + 7, k + 6, Dungeons.purpleBrick, 0);
        this.setBlock(world, i + 4, j + 7, k + 10, Blocks.wool, 10);
        this.setBlock(world, i + 4, j + 7, k + 11, Blocks.wool, 10);
        this.setBlock(world, i + 4, j + 7, k + 12, Blocks.obsidian, 0);
        this.setBlock(world, i + 4, j + 8, k + 1, Blocks.obsidian, 0);
        this.setBlock(world, i + 4, j + 8, k + 2, Blocks.wool, 10);
        this.setBlock(world, i + 4, j + 8, k + 9, Blocks.wool, 10);
        this.setBlock(world, i + 4, j + 8, k + 10, Blocks.obsidian, 0);
        this.setBlock(world, i + 4, j + 8, k + 11, Blocks.obsidian, 0);
        this.setBlock(world, i + 4, j + 9, k + 1, Blocks.obsidian, 0);
        this.setBlock(world, i + 4, j + 9, k + 2, Blocks.wool, 10);
        this.setBlock(world, i + 4, j + 9, k + 3, Blocks.wool, 10);
        this.setBlock(world, i + 4, j + 9, k + 4, Blocks.wool, 10);
        this.setBlock(world, i + 4, j + 9, k + 5, Blocks.wool, 10);
        this.setBlock(world, i + 4, j + 9, k + 6, Blocks.wool, 10);
        this.setBlock(world, i + 4, j + 9, k + 7, Blocks.wool, 10);
        this.setBlock(world, i + 4, j + 9, k + 8, Blocks.wool, 10);
        this.setBlock(world, i + 4, j + 9, k + 9, Blocks.obsidian, 0);
        this.setBlock(world, i + 4, j + 9, k + 10, Blocks.obsidian, 0);
        this.setBlock(world, i + 4, j + 10, k + 1, Blocks.obsidian, 0);
        this.setBlock(world, i + 4, j + 10, k + 2, Blocks.obsidian, 0);
        this.setBlock(world, i + 4, j + 10, k + 3, Blocks.obsidian, 0);
        this.setBlock(world, i + 4, j + 10, k + 4, Blocks.obsidian, 0);
        this.setBlock(world, i + 4, j + 10, k + 5, Blocks.obsidian, 0);
        this.setBlock(world, i + 4, j + 10, k + 6, Blocks.obsidian, 0);
        this.setBlock(world, i + 4, j + 10, k + 7, Blocks.obsidian, 0);
        this.setBlock(world, i + 4, j + 10, k + 8, Blocks.obsidian, 0);
        this.setBlock(world, i + 5, j, k + 1, Blocks.obsidian, 0);
        this.setBlock(world, i + 5, j, k + 2, Blocks.wool, 10);
        this.setBlock(world, i + 5, j, k + 3, Blocks.wool, 10);
        this.setBlock(world, i + 5, j, k + 4, Dungeons.purpleBrick, 0);
        this.setBlock(world, i + 5, j, k + 5, Dungeons.purpleBrick, 0);
        this.setBlock(world, i + 5, j, k + 6, Dungeons.purpleBrick, 0);
        this.setBlock(world, i + 5, j, k + 7, Dungeons.purpleBrick, 0);
        this.setBlock(world, i + 5, j, k + 8, Dungeons.purpleBrick, 0);
        this.setBlock(world, i + 5, j, k + 9, Blocks.wool, 10);
        this.setBlock(world, i + 5, j, k + 10, Blocks.wool, 10);
        this.setBlock(world, i + 5, j, k + 11, Blocks.obsidian, 0);
        this.setBlock(world, i + 5, j + 1, k, Blocks.obsidian, 0);
        this.setBlock(world, i + 5, j + 1, k + 1, Blocks.wool, 10);
        this.setBlock(world, i + 5, j + 1, k + 11, Blocks.wool, 10);
        this.setBlock(world, i + 5, j + 1, k + 12, Blocks.obsidian, 0);
        this.setBlock(world, i + 5, j + 2, k, Blocks.obsidian, 0);
        this.setBlock(world, i + 5, j + 2, k + 1, Blocks.wool, 10);
        this.setBlock(world, i + 5, j + 2, k + 11, Blocks.wool, 10);
        this.setBlock(world, i + 5, j + 2, k + 12, Blocks.obsidian, 0);
        this.setBlock(world, i + 5, j + 3, k, Blocks.obsidian, 0);
        this.setBlock(world, i + 5, j + 3, k + 1, Blocks.wool, 10);
        this.setBlock(world, i + 5, j + 3, k + 4, Dungeons.purpleBrick, 0);
        this.setBlock(world, i + 5, j + 3, k + 8, Dungeons.purpleBrick, 0);
        this.setBlock(world, i + 5, j + 3, k + 11, Blocks.wool, 10);
        this.setBlock(world, i + 5, j + 3, k + 12, Blocks.obsidian, 0);
        this.setBlock(world, i + 5, j + 4, k, Blocks.obsidian, 0);
        this.setBlock(world, i + 5, j + 4, k + 1, Blocks.wool, 10);
        this.setBlock(world, i + 5, j + 4, k + 4, Dungeons.purpleBrick, 0);
        this.setBlock(world, i + 5, j + 4, k + 8, Dungeons.purpleBrick, 0);
        this.setBlock(world, i + 5, j + 5, k, Blocks.obsidian, 0);
        this.setBlock(world, i + 5, j + 5, k + 1, Blocks.wool, 10);
        this.setBlock(world, i + 5, j + 5, k + 4, Dungeons.purpleBrick, 0);
        this.setBlock(world, i + 5, j + 5, k + 8, Dungeons.purpleBrick, 0);
        this.setBlock(world, i + 5, j + 6, k, Blocks.obsidian, 0);
        this.setBlock(world, i + 5, j + 6, k + 1, Blocks.wool, 10);
        this.setBlock(world, i + 5, j + 7, k, Blocks.obsidian, 0);
        this.setBlock(world, i + 5, j + 7, k + 1, Blocks.wool, 10);
        this.setBlock(world, i + 5, j + 8, k, Blocks.obsidian, 0);
        this.setBlock(world, i + 5, j + 8, k + 1, Blocks.wool, 10);
        this.setBlock(world, i + 5, j + 9, k, Blocks.obsidian, 0);
        this.setBlock(world, i + 5, j + 9, k + 1, Blocks.wool, 10);
        this.setBlock(world, i + 5, j + 9, k + 5, Blocks.wool, 10);
        this.setBlock(world, i + 5, j + 9, k + 6, Blocks.wool, 10);
        this.setBlock(world, i + 5, j + 9, k + 7, Blocks.wool, 10);
        this.setBlock(world, i + 5, j + 9, k + 8, Blocks.wool, 10);
        this.setBlock(world, i + 5, j + 10, k, Blocks.obsidian, 0);
        this.setBlock(world, i + 5, j + 10, k + 1, Blocks.wool, 10);
        this.setBlock(world, i + 5, j + 10, k + 2, Blocks.wool, 10);
        this.setBlock(world, i + 5, j + 10, k + 3, Blocks.wool, 10);
        this.setBlock(world, i + 5, j + 10, k + 4, Blocks.wool, 10);
        this.setBlock(world, i + 5, j + 10, k + 5, Blocks.obsidian, 0);
        this.setBlock(world, i + 5, j + 10, k + 6, Blocks.obsidian, 0);
        this.setBlock(world, i + 5, j + 10, k + 7, Blocks.obsidian, 0);
        this.setBlock(world, i + 5, j + 10, k + 8, Blocks.obsidian, 0);
        this.setBlock(world, i + 5, j + 11, k, Blocks.obsidian, 0);
        this.setBlock(world, i + 5, j + 11, k + 1, Blocks.obsidian, 0);
        this.setBlock(world, i + 5, j + 11, k + 2, Blocks.obsidian, 0);
        this.setBlock(world, i + 5, j + 11, k + 3, Blocks.obsidian, 0);
        this.setBlock(world, i + 5, j + 11, k + 4, Blocks.obsidian, 0);
        this.setBlock(world, i + 5, j + 12, k + 2, Blocks.obsidian, 0);
        this.setBlock(world, i + 5, j + 12, k + 3, Blocks.obsidian, 0);
        this.setBlock(world, i + 6, j, k + 1, Blocks.obsidian, 0);
        this.setBlock(world, i + 6, j, k + 2, Blocks.wool, 10);
        this.setBlock(world, i + 6, j, k + 3, Blocks.wool, 10);
        this.setBlock(world, i + 6, j, k + 4, Dungeons.purpleBrick, 0);
        this.setBlock(world, i + 6, j, k + 5, Dungeons.purpleBrick, 0);
        this.setBlock(world, i + 6, j, k + 6, Blocks.glowstone, 0);
        final EntityAnchorTrader trader = new EntityAnchorTrader(world);
        trader.setPosition((i + 6), (j + 1), (k + 6));
        world.spawnEntityInWorld(trader);
        trader.onSpawnWithEgg(null);
        trader.setPosition((i + 6), (j + 1),(k + 6));
        this.setBlock(world, i + 6, j, k + 7, Dungeons.purpleBrick, 0);
        this.setBlock(world, i + 6, j, k + 8, Dungeons.purpleBrick, 0);
        this.setBlock(world, i + 6, j, k + 9, Blocks.wool, 10);
        this.setBlock(world, i + 6, j, k + 10, Blocks.wool, 10);
        this.setBlock(world, i + 6, j, k + 11, Blocks.obsidian, 0);
        this.setBlock(world, i + 6, j + 1, k, Blocks.obsidian, 0);
        this.setBlock(world, i + 6, j + 1, k + 1, Blocks.wool, 10);
        this.setBlock(world, i + 6, j + 1, k + 2, Blocks.furnace, 3);
        this.setBlock(world, i + 6, j + 1, k + 10, Blocks.noteblock, 0);
        this.setBlock(world, i + 6, j + 1, k + 11, Blocks.wool, 10);
        this.setBlock(world, i + 6, j + 1, k + 12, Blocks.obsidian, 0);
        this.setBlock(world, i + 6, j + 2, k, Blocks.obsidian, 0);
        this.setBlock(world, i + 6, j + 2, k + 1, Blocks.wool, 10);
        this.setBlock(world, i + 6, j + 2, k + 11, Blocks.wool, 10);
        this.setBlock(world, i + 6, j + 2, k + 12, Blocks.obsidian, 0);
        this.setBlock(world, i + 6, j + 3, k, Blocks.obsidian, 0);
        this.setBlock(world, i + 6, j + 3, k + 1, Blocks.wool, 10);
        this.setBlock(world, i + 6, j + 3, k + 11, Blocks.wool, 10);
        this.setBlock(world, i + 6, j + 3, k + 12, Blocks.obsidian, 0);
        this.setBlock(world, i + 6, j + 4, k, Blocks.obsidian, 0);
        this.setBlock(world, i + 6, j + 4, k + 1, Blocks.wool, 10);
        this.setBlock(world, i + 6, j + 4, k + 4, Dungeons.purpleBrick, 0);
        this.setBlock(world, i + 6, j + 4, k + 8, Dungeons.purpleBrick, 0);
        this.setBlock(world, i + 6, j + 4, k + 11, Blocks.wool, 10);
        this.setBlock(world, i + 6, j + 4, k + 12, Blocks.obsidian, 0);
        this.setBlock(world, i + 6, j + 5, k, Blocks.obsidian, 0);
        this.setBlock(world, i + 6, j + 5, k + 1, Blocks.wool, 10);
        this.setBlock(world, i + 6, j + 5, k + 4, Dungeons.purpleBrick, 0);
        this.setBlock(world, i + 6, j + 5, k + 8, Dungeons.purpleBrick, 0);
        this.setBlock(world, i + 6, j + 5, k + 11, Blocks.wool, 10);
        this.setBlock(world, i + 6, j + 5, k + 12, Blocks.obsidian, 0);
        this.setBlock(world, i + 6, j + 6, k + 4, Dungeons.purpleBrick, 0);
        this.setBlock(world, i + 6, j + 6, k + 8, Dungeons.purpleBrick, 0);
        this.setBlock(world, i + 6, j + 6, k + 11, Blocks.wool, 10);
        this.setBlock(world, i + 6, j + 6, k + 12, Blocks.obsidian, 0);
        this.setBlock(world, i + 6, j + 7, k + 4, Dungeons.purpleBrick, 0);
        this.setBlock(world, i + 6, j + 7, k + 8, Dungeons.purpleBrick, 0);
        this.setBlock(world, i + 6, j + 7, k + 11, Blocks.wool, 10);
        this.setBlock(world, i + 6, j + 7, k + 12, Blocks.obsidian, 0);
        this.setBlock(world, i + 6, j + 8, k + 10, Blocks.wool, 10);
        this.setBlock(world, i + 6, j + 8, k + 11, Blocks.wool, 10);
        this.setBlock(world, i + 6, j + 8, k + 12, Blocks.obsidian, 0);
        this.setBlock(world, i + 6, j + 9, k + 8, Blocks.wool, 10);
        this.setBlock(world, i + 6, j + 9, k + 9, Blocks.wool, 10);
        this.setBlock(world, i + 6, j + 9, k + 10, Blocks.obsidian, 0);
        this.setBlock(world, i + 6, j + 9, k + 11, Blocks.obsidian, 0);
        this.setBlock(world, i + 6, j + 10, k + 4, Blocks.wool, 10);
        this.setBlock(world, i + 6, j + 10, k + 5, Blocks.wool, 10);
        this.setBlock(world, i + 6, j + 10, k + 6, Blocks.wool, 10);
        this.setBlock(world, i + 6, j + 10, k + 7, Blocks.wool, 10);
        this.setBlock(world, i + 6, j + 10, k + 8, Blocks.obsidian, 0);
        this.setBlock(world, i + 6, j + 10, k + 9, Blocks.obsidian, 0);
        this.setBlock(world, i + 6, j + 11, k + 2, Blocks.wool, 10);
        this.setBlock(world, i + 6, j + 11, k + 3, Blocks.wool, 10);
        this.setBlock(world, i + 6, j + 11, k + 4, Blocks.obsidian, 0);
        this.setBlock(world, i + 6, j + 11, k + 5, Blocks.obsidian, 0);
        this.setBlock(world, i + 6, j + 11, k + 6, Blocks.obsidian, 0);
        this.setBlock(world, i + 6, j + 11, k + 7, Blocks.obsidian, 0);
        this.setBlock(world, i + 6, j + 11, k + 8, Blocks.obsidian, 0);
        this.setBlock(world, i + 6, j + 12, k + 2, Blocks.obsidian, 0);
        this.setBlock(world, i + 6, j + 12, k + 3, Blocks.obsidian, 0);
        this.setBlock(world, i + 6, j + 12, k + 4, Blocks.obsidian, 0);
        this.setBlock(world, i + 6, j + 12, k + 5, Blocks.obsidian, 0);
        this.setBlock(world, i + 6, j + 12, k + 6, Blocks.obsidian, 0);
        this.setBlock(world, i + 7, j, k + 1, Blocks.obsidian, 0);
        this.setBlock(world, i + 7, j, k + 2, Blocks.wool, 10);
        this.setBlock(world, i + 7, j, k + 3, Blocks.wool, 10);
        this.setBlock(world, i + 7, j, k + 4, Dungeons.purpleBrick, 0);
        this.setBlock(world, i + 7, j, k + 5, Dungeons.purpleBrick, 0);
        this.setBlock(world, i + 7, j, k + 6, Dungeons.purpleBrick, 0);
        this.setBlock(world, i + 7, j, k + 7, Dungeons.purpleBrick, 0);
        this.setBlock(world, i + 7, j, k + 8, Dungeons.purpleBrick, 0);
        this.setBlock(world, i + 7, j, k + 9, Blocks.wool, 10);
        this.setBlock(world, i + 7, j, k + 10, Blocks.wool, 10);
        this.setBlock(world, i + 7, j, k + 11, Blocks.obsidian, 0);
        this.setBlock(world, i + 7, j + 1, k, Blocks.obsidian, 0);
        this.setBlock(world, i + 7, j + 1, k + 1, Blocks.wool, 10);
        this.setBlock(world, i + 7, j + 1, k + 2, Blocks.furnace, 3);
        this.setBlock(world, i + 7, j + 1, k + 10, Blocks.noteblock, 0);
        this.setBlock(world, i + 7, j + 1, k + 11, Blocks.wool, 10);
        this.setBlock(world, i + 7, j + 1, k + 12, Blocks.obsidian, 0);
        this.setBlock(world, i + 7, j + 2, k, Blocks.obsidian, 0);
        this.setBlock(world, i + 7, j + 2, k + 1, Blocks.wool, 10);
        this.setBlock(world, i + 7, j + 2, k + 11, Blocks.wool, 10);
        this.setBlock(world, i + 7, j + 2, k + 12, Blocks.obsidian, 0);
        this.setBlock(world, i + 7, j + 3, k, Blocks.obsidian, 0);
        this.setBlock(world, i + 7, j + 3, k + 1, Blocks.wool, 10);
        this.setBlock(world, i + 7, j + 3, k + 4, Dungeons.purpleBrick, 0);
        this.setBlock(world, i + 7, j + 3, k + 8, Dungeons.purpleBrick, 0);
        this.setBlock(world, i + 7, j + 3, k + 11, Blocks.wool, 10);
        this.setBlock(world, i + 7, j + 3, k + 12, Blocks.obsidian, 0);
        this.setBlock(world, i + 7, j + 4, k, Blocks.obsidian, 0);
        this.setBlock(world, i + 7, j + 4, k + 1, Blocks.wool, 10);
        this.setBlock(world, i + 7, j + 4, k + 4, Dungeons.purpleBrick, 0);
        this.setBlock(world, i + 7, j + 4, k + 8, Dungeons.purpleBrick, 0);
        this.setBlock(world, i + 7, j + 5, k, Blocks.obsidian, 0);
        this.setBlock(world, i + 7, j + 5, k + 1, Blocks.wool, 10);
        this.setBlock(world, i + 7, j + 5, k + 4, Dungeons.purpleBrick, 0);
        this.setBlock(world, i + 7, j + 5, k + 8, Dungeons.purpleBrick, 0);
        this.setBlock(world, i + 7, j + 6, k, Blocks.obsidian, 0);
        this.setBlock(world, i + 7, j + 6, k + 1, Blocks.wool, 10);
        this.setBlock(world, i + 7, j + 7, k, Blocks.obsidian, 0);
        this.setBlock(world, i + 7, j + 7, k + 1, Blocks.wool, 10);
        this.setBlock(world, i + 7, j + 8, k, Blocks.obsidian, 0);
        this.setBlock(world, i + 7, j + 8, k + 1, Blocks.wool, 10);
        this.setBlock(world, i + 7, j + 8, k + 10, Blocks.wool, 10);
        this.setBlock(world, i + 7, j + 9, k, Blocks.obsidian, 0);
        this.setBlock(world, i + 7, j + 9, k + 1, Blocks.wool, 10);
        this.setBlock(world, i + 7, j + 9, k + 9, Blocks.wool, 10);
        this.setBlock(world, i + 7, j + 9, k + 10, Blocks.obsidian, 0);
        this.setBlock(world, i + 7, j + 10, k, Blocks.obsidian, 0);
        this.setBlock(world, i + 7, j + 10, k + 1, Blocks.wool, 10);
        this.setBlock(world, i + 7, j + 10, k + 8, Blocks.wool, 10);
        this.setBlock(world, i + 7, j + 10, k + 9, Blocks.obsidian, 0);
        this.setBlock(world, i + 7, j + 11, k, Blocks.obsidian, 0);
        this.setBlock(world, i + 7, j + 11, k + 1, Blocks.obsidian, 0);
        this.setBlock(world, i + 7, j + 11, k + 4, Blocks.wool, 10);
        this.setBlock(world, i + 7, j + 11, k + 5, Blocks.wool, 10);
        this.setBlock(world, i + 7, j + 11, k + 6, Blocks.wool, 10);
        this.setBlock(world, i + 7, j + 11, k + 7, Blocks.wool, 10);
        this.setBlock(world, i + 7, j + 11, k + 8, Blocks.obsidian, 0);
        this.setBlock(world, i + 7, j + 12, k + 4, Blocks.obsidian, 0);
        this.setBlock(world, i + 7, j + 12, k + 5, Blocks.obsidian, 0);
        this.setBlock(world, i + 7, j + 12, k + 6, Blocks.obsidian, 0);
        this.setBlock(world, i + 7, j + 12, k + 7, Blocks.obsidian, 0);
        this.setBlock(world, i + 8, j, k + 1, Blocks.obsidian, 0);
        this.setBlock(world, i + 8, j, k + 2, Blocks.wool, 10);
        this.setBlock(world, i + 8, j, k + 3, Blocks.wool, 10);
        this.setBlock(world, i + 8, j, k + 4, Dungeons.purpleBrick, 0);
        this.setBlock(world, i + 8, j, k + 5, Dungeons.purpleBrick, 0);
        this.setBlock(world, i + 8, j, k + 6, Dungeons.purpleBrick, 0);
        this.setBlock(world, i + 8, j, k + 7, Dungeons.purpleBrick, 0);
        this.setBlock(world, i + 8, j, k + 8, Dungeons.purpleBrick, 0);
        this.setBlock(world, i + 8, j, k + 9, Blocks.wool, 10);
        this.setBlock(world, i + 8, j, k + 10, Blocks.wool, 10);
        this.setBlock(world, i + 8, j, k + 11, Blocks.obsidian, 0);
        this.setBlock(world, i + 8, j + 1, k, Blocks.obsidian, 0);
        this.setBlock(world, i + 8, j + 1, k + 1, Blocks.wool, 10);
        this.setBlock(world, i + 8, j + 1, k + 4, Dungeons.purpleBrick, 0);
        this.setBlock(world, i + 8, j + 1, k + 8, Dungeons.purpleBrick, 0);
        this.setBlock(world, i + 8, j + 1, k + 11, Blocks.wool, 10);
        this.setBlock(world, i + 8, j + 1, k + 12, Blocks.obsidian, 0);
        this.setBlock(world, i + 8, j + 2, k, Blocks.obsidian, 0);
        this.setBlock(world, i + 8, j + 2, k + 1, Blocks.wool, 10);
        this.setBlock(world, i + 8, j + 2, k + 4, Dungeons.purpleBrick, 0);
        this.setBlock(world, i + 8, j + 2, k + 8, Dungeons.purpleBrick, 0);
        this.setBlock(world, i + 8, j + 2, k + 11, Blocks.wool, 10);
        this.setBlock(world, i + 8, j + 2, k + 12, Blocks.obsidian, 0);
        this.setBlock(world, i + 8, j + 3, k, Blocks.obsidian, 0);
        this.setBlock(world, i + 8, j + 3, k + 1, Blocks.wool, 10);
        this.setBlock(world, i + 8, j + 3, k + 4, Dungeons.purpleBrick, 0);
        this.setBlock(world, i + 8, j + 3, k + 5, Dungeons.purpleBrick, 0);
        this.setBlock(world, i + 8, j + 3, k + 7, Dungeons.purpleBrick, 0);
        this.setBlock(world, i + 8, j + 3, k + 8, Dungeons.purpleBrick, 0);
        this.setBlock(world, i + 8, j + 3, k + 11, Blocks.wool, 10);
        this.setBlock(world, i + 8, j + 3, k + 12, Blocks.obsidian, 0);
        this.setBlock(world, i + 8, j + 4, k, Blocks.obsidian, 0);
        this.setBlock(world, i + 8, j + 4, k + 1, Blocks.wool, 10);
        this.setBlock(world, i + 8, j + 4, k + 4, Dungeons.purpleBrick, 0);
        this.setBlock(world, i + 8, j + 4, k + 5, Dungeons.purpleBrick, 0);
        this.setBlock(world, i + 8, j + 4, k + 6, Dungeons.purpleBrick, 0);
        this.setBlock(world, i + 8, j + 4, k + 7, Dungeons.purpleBrick, 0);
        this.setBlock(world, i + 8, j + 4, k + 8, Dungeons.purpleBrick, 0);
        this.setBlock(world, i + 8, j + 4, k + 11, Blocks.wool, 10);
        this.setBlock(world, i + 8, j + 4, k + 12, Blocks.obsidian, 0);
        this.setBlock(world, i + 8, j + 5, k, Blocks.obsidian, 0);
        this.setBlock(world, i + 8, j + 5, k + 1, Blocks.wool, 10);
        this.setBlock(world, i + 8, j + 5, k + 5, Dungeons.purpleBrick, 0);
        this.setBlock(world, i + 8, j + 5, k + 6, Dungeons.purpleBrick, 0);
        this.setBlock(world, i + 8, j + 5, k + 7, Dungeons.purpleBrick, 0);
        this.setBlock(world, i + 8, j + 5, k + 11, Blocks.wool, 10);
        this.setBlock(world, i + 8, j + 5, k + 12, Blocks.obsidian, 0);
        this.setBlock(world, i + 8, j + 6, k + 6, Dungeons.purpleBrick, 0);
        this.setBlock(world, i + 8, j + 6, k + 11, Blocks.wool, 10);
        this.setBlock(world, i + 8, j + 6, k + 12, Blocks.obsidian, 0);
        this.setBlock(world, i + 8, j + 7, k + 6, Dungeons.purpleBrick, 0);
        this.setBlock(world, i + 8, j + 7, k + 11, Blocks.wool, 10);
        this.setBlock(world, i + 8, j + 7, k + 12, Blocks.obsidian, 0);
        this.setBlock(world, i + 8, j + 8, k + 11, Blocks.wool, 10);
        this.setBlock(world, i + 8, j + 8, k + 12, Blocks.obsidian, 0);
        this.setBlock(world, i + 8, j + 9, k + 9, Blocks.wool, 10);
        this.setBlock(world, i + 8, j + 9, k + 10, Blocks.wool, 10);
        this.setBlock(world, i + 8, j + 9, k + 11, Blocks.obsidian, 0);
        this.setBlock(world, i + 8, j + 9, k + 12, Blocks.obsidian, 0);
        this.setBlock(world, i + 8, j + 10, k + 2, Blocks.wool, 10);
        this.setBlock(world, i + 8, j + 10, k + 8, Blocks.wool, 10);
        this.setBlock(world, i + 8, j + 10, k + 9, Blocks.obsidian, 0);
        this.setBlock(world, i + 8, j + 10, k + 10, Blocks.obsidian, 0);
        this.setBlock(world, i + 8, j + 11, k + 1, Blocks.obsidian, 0);
        this.setBlock(world, i + 8, j + 11, k + 2, Blocks.obsidian, 0);
        this.setBlock(world, i + 8, j + 11, k + 3, Blocks.wool, 10);
        this.setBlock(world, i + 8, j + 11, k + 4, Blocks.wool, 10);
        this.setBlock(world, i + 8, j + 11, k + 5, Blocks.wool, 10);
        this.setBlock(world, i + 8, j + 11, k + 6, Blocks.wool, 10);
        this.setBlock(world, i + 8, j + 11, k + 7, Blocks.wool, 10);
        this.setBlock(world, i + 8, j + 11, k + 8, Blocks.obsidian, 0);
        this.setBlock(world, i + 8, j + 12, k + 1, Blocks.obsidian, 0);
        this.setBlock(world, i + 8, j + 12, k + 2, Blocks.obsidian, 0);
        this.setBlock(world, i + 8, j + 12, k + 3, Blocks.obsidian, 0);
        this.setBlock(world, i + 8, j + 12, k + 4, Blocks.obsidian, 0);
        this.setBlock(world, i + 8, j + 12, k + 5, Blocks.obsidian, 0);
        this.setBlock(world, i + 8, j + 12, k + 6, Blocks.obsidian, 0);
        this.setBlock(world, i + 8, j + 12, k + 7, Blocks.obsidian, 0);
        this.setBlock(world, i + 8, j + 12, k + 8, Blocks.obsidian, 0);
        this.setBlock(world, i + 9, j, k + 2, Blocks.obsidian, 0);
        this.setBlock(world, i + 9, j, k + 3, Blocks.wool, 10);
        this.setBlock(world, i + 9, j, k + 4, Blocks.wool, 10);
        this.setBlock(world, i + 9, j, k + 5, Blocks.wool, 10);
        this.setBlock(world, i + 9, j, k + 6, Blocks.wool, 10);
        this.setBlock(world, i + 9, j, k + 7, Blocks.wool, 10);
        this.setBlock(world, i + 9, j, k + 8, Blocks.wool, 10);
        this.setBlock(world, i + 9, j, k + 9, Blocks.wool, 10);
        this.setBlock(world, i + 9, j, k + 10, Blocks.obsidian, 0);
        this.setBlock(world, i + 9, j + 1, k + 1, Blocks.obsidian, 0);
        this.setBlock(world, i + 9, j + 1, k + 2, Blocks.wool, 10);
        this.setBlock(world, i + 9, j + 1, k + 10, Blocks.wool, 10);
        this.setBlock(world, i + 9, j + 1, k + 11, Blocks.obsidian, 0);
        this.setBlock(world, i + 9, j + 2, k + 1, Blocks.obsidian, 0);
        this.setBlock(world, i + 9, j + 2, k + 2, Blocks.wool, 10);
        this.setBlock(world, i + 9, j + 2, k + 10, Blocks.wool, 10);
        this.setBlock(world, i + 9, j + 2, k + 11, Blocks.obsidian, 0);
        this.setBlock(world, i + 9, j + 3, k, Blocks.obsidian, 0);
        this.setBlock(world, i + 9, j + 3, k + 1, Blocks.obsidian, 0);
        this.setBlock(world, i + 9, j + 3, k + 2, Blocks.wool, 10);
        this.setBlock(world, i + 9, j + 3, k + 10, Blocks.wool, 10);
        this.setBlock(world, i + 9, j + 3, k + 11, Blocks.obsidian, 0);
        this.setBlock(world, i + 9, j + 4, k, Blocks.obsidian, 0);
        this.setBlock(world, i + 9, j + 4, k + 1, Blocks.wool, 10);
        this.setBlock(world, i + 9, j + 4, k + 10, Blocks.wool, 10);
        this.setBlock(world, i + 9, j + 4, k + 11, Blocks.obsidian, 0);
        this.setBlock(world, i + 9, j + 5, k, Blocks.obsidian, 0);
        this.setBlock(world, i + 9, j + 5, k + 1, Blocks.wool, 10);
        this.setBlock(world, i + 9, j + 5, k + 10, Blocks.wool, 10);
        this.setBlock(world, i + 9, j + 5, k + 11, Blocks.obsidian, 0);
        this.setBlock(world, i + 9, j + 6, k, Blocks.obsidian, 0);
        this.setBlock(world, i + 9, j + 6, k + 1, Blocks.wool, 10);
        this.setBlock(world, i + 9, j + 6, k + 10, Blocks.wool, 10);
        this.setBlock(world, i + 9, j + 6, k + 11, Blocks.obsidian, 0);
        this.setBlock(world, i + 9, j + 7, k, Blocks.obsidian, 0);
        this.setBlock(world, i + 9, j + 7, k + 1, Blocks.wool, 10);
        this.setBlock(world, i + 9, j + 7, k + 10, Blocks.wool, 10);
        this.setBlock(world, i + 9, j + 7, k + 11, Blocks.obsidian, 0);
        this.setBlock(world, i + 9, j + 8, k, Blocks.obsidian, 0);
        this.setBlock(world, i + 9, j + 8, k + 1, Blocks.wool, 10);
        this.setBlock(world, i + 9, j + 8, k + 10, Blocks.wool, 10);
        this.setBlock(world, i + 9, j + 8, k + 11, Blocks.obsidian, 0);
        this.setBlock(world, i + 9, j + 9, k, Blocks.obsidian, 0);
        this.setBlock(world, i + 9, j + 9, k + 1, Blocks.wool, 10);
        this.setBlock(world, i + 9, j + 9, k + 9, Blocks.wool, 10);
        this.setBlock(world, i + 9, j + 9, k + 10, Blocks.wool, 10);
        this.setBlock(world, i + 9, j + 10, k, Blocks.obsidian, 0);
        this.setBlock(world, i + 9, j + 10, k + 5, Blocks.wool, 10);
        this.setBlock(world, i + 9, j + 10, k + 6, Blocks.wool, 10);
        this.setBlock(world, i + 9, j + 10, k + 7, Blocks.wool, 10);
        this.setBlock(world, i + 9, j + 10, k + 8, Blocks.wool, 10);
        this.setBlock(world, i + 9, j + 10, k + 9, Blocks.obsidian, 0);
        this.setBlock(world, i + 9, j + 10, k + 10, Blocks.obsidian, 0);
        this.setBlock(world, i + 9, j + 11, k, Blocks.obsidian, 0);
        this.setBlock(world, i + 9, j + 11, k + 1, Blocks.obsidian, 0);
        this.setBlock(world, i + 9, j + 11, k + 3, Blocks.wool, 10);
        this.setBlock(world, i + 9, j + 11, k + 4, Blocks.wool, 10);
        this.setBlock(world, i + 9, j + 11, k + 5, Blocks.obsidian, 0);
        this.setBlock(world, i + 9, j + 11, k + 6, Blocks.obsidian, 0);
        this.setBlock(world, i + 9, j + 11, k + 7, Blocks.obsidian, 0);
        this.setBlock(world, i + 9, j + 11, k + 8, Blocks.obsidian, 0);
        this.setBlock(world, i + 9, j + 12, k + 2, Blocks.obsidian, 0);
        this.setBlock(world, i + 9, j + 12, k + 3, Blocks.obsidian, 0);
        this.setBlock(world, i + 9, j + 12, k + 4, Blocks.obsidian, 0);
        this.setBlock(world, i + 10, j, k + 3, Blocks.obsidian, 0);
        this.setBlock(world, i + 10, j, k + 4, Blocks.wool, 10);
        this.setBlock(world, i + 10, j, k + 5, Blocks.wool, 10);
        this.setBlock(world, i + 10, j, k + 6, Blocks.wool, 10);
        this.setBlock(world, i + 10, j, k + 7, Blocks.wool, 10);
        this.setBlock(world, i + 10, j, k + 8, Blocks.obsidian, 0);
        this.setBlock(world, i + 10, j, k + 9, Blocks.obsidian, 0);
        this.setBlock(world, i + 10, j + 1, k + 2, Blocks.obsidian, 0);
        this.setBlock(world, i + 10, j + 1, k + 3, Blocks.wool, 10);
        this.setBlock(world, i + 10, j + 1, k + 8, Blocks.wool, 10);
        this.setBlock(world, i + 10, j + 1, k + 9, Blocks.wool, 10);
        this.setBlock(world, i + 10, j + 1, k + 10, Blocks.obsidian, 0);
        this.setBlock(world, i + 10, j + 2, k + 2, Blocks.obsidian, 0);
        this.setBlock(world, i + 10, j + 2, k + 3, Blocks.wool, 10);
        this.setBlock(world, i + 10, j + 2, k + 8, Blocks.wool, 10);
        this.setBlock(world, i + 10, j + 2, k + 9, Blocks.wool, 10);
        this.setBlock(world, i + 10, j + 2, k + 10, Blocks.obsidian, 0);
        this.setBlock(world, i + 10, j + 3, k + 1, Blocks.obsidian, 0);
        this.setBlock(world, i + 10, j + 3, k + 2, Blocks.obsidian, 0);
        this.setBlock(world, i + 10, j + 3, k + 3, Blocks.wool, 10);
        this.setBlock(world, i + 10, j + 3, k + 9, Blocks.wool, 10);
        this.setBlock(world, i + 10, j + 3, k + 10, Blocks.wool, 10);
        this.setBlock(world, i + 10, j + 4, k + 1, Blocks.obsidian, 0);
        this.setBlock(world, i + 10, j + 4, k + 2, Blocks.wool, 10);
        this.setBlock(world, i + 10, j + 4, k + 9, Blocks.wool, 10);
        this.setBlock(world, i + 10, j + 5, k + 1, Blocks.obsidian, 0);
        this.setBlock(world, i + 10, j + 5, k + 2, Blocks.wool, 10);
        this.setBlock(world, i + 10, j + 5, k + 9, Blocks.wool, 10);
        this.setBlock(world, i + 10, j + 6, k + 1, Blocks.obsidian, 0);
        this.setBlock(world, i + 10, j + 6, k + 2, Blocks.wool, 10);
        this.setBlock(world, i + 10, j + 6, k + 9, Blocks.wool, 10);
        this.setBlock(world, i + 10, j + 7, k + 1, Blocks.obsidian, 0);
        this.setBlock(world, i + 10, j + 7, k + 9, Blocks.wool, 10);
        this.setBlock(world, i + 10, j + 8, k + 1, Blocks.obsidian, 0);
        this.setBlock(world, i + 10, j + 8, k + 9, Blocks.wool, 10);
        this.setBlock(world, i + 10, j + 9, k + 1, Blocks.obsidian, 0);
        this.setBlock(world, i + 10, j + 9, k + 6, Blocks.wool, 10);
        this.setBlock(world, i + 10, j + 9, k + 7, Blocks.wool, 10);
        this.setBlock(world, i + 10, j + 9, k + 8, Blocks.wool, 10);
        this.setBlock(world, i + 10, j + 9, k + 9, Blocks.obsidian, 0);
        this.setBlock(world, i + 10, j + 10, k + 3, Blocks.wool, 10);
        this.setBlock(world, i + 10, j + 10, k + 4, Blocks.wool, 10);
        this.setBlock(world, i + 10, j + 10, k + 5, Blocks.wool, 10);
        this.setBlock(world, i + 10, j + 10, k + 6, Blocks.obsidian, 0);
        this.setBlock(world, i + 10, j + 10, k + 7, Blocks.obsidian, 0);
        this.setBlock(world, i + 10, j + 10, k + 8, Blocks.obsidian, 0);
        this.setBlock(world, i + 10, j + 11, k + 3, Blocks.wool, 10);
        this.setBlock(world, i + 10, j + 11, k + 4, Blocks.obsidian, 0);
        this.setBlock(world, i + 10, j + 11, k + 5, Blocks.obsidian, 0);
        this.setBlock(world, i + 10, j + 12, k + 3, Blocks.obsidian, 0);
        this.setBlock(world, i + 10, j + 12, k + 4, Blocks.obsidian, 0);
        this.setBlock(world, i + 11, j, k + 4, Blocks.obsidian, 0);
        this.setBlock(world, i + 11, j, k + 5, Blocks.obsidian, 0);
        this.setBlock(world, i + 11, j, k + 6, Blocks.obsidian, 0);
        this.setBlock(world, i + 11, j, k + 7, Blocks.obsidian, 0);
        this.setBlock(world, i + 11, j + 1, k + 3, Blocks.obsidian, 0);
        this.setBlock(world, i + 11, j + 1, k + 4, Blocks.wool, 10);
        this.setBlock(world, i + 11, j + 1, k + 5, Blocks.wool, 10);
        this.setBlock(world, i + 11, j + 1, k + 6, Blocks.wool, 10);
        this.setBlock(world, i + 11, j + 1, k + 7, Blocks.wool, 10);
        this.setBlock(world, i + 11, j + 1, k + 8, Blocks.obsidian, 0);
        this.setBlock(world, i + 11, j + 1, k + 9, Blocks.obsidian, 0);
        this.setBlock(world, i + 11, j + 2, k + 2, Blocks.obsidian, 0);
        this.setBlock(world, i + 11, j + 2, k + 3, Blocks.obsidian, 0);
        this.setBlock(world, i + 11, j + 2, k + 4, Blocks.wool, 10);
        this.setBlock(world, i + 11, j + 2, k + 5, Blocks.wool, 10);
        this.setBlock(world, i + 11, j + 2, k + 6, Blocks.wool, 10);
        this.setBlock(world, i + 11, j + 2, k + 7, Blocks.wool, 10);
        this.setBlock(world, i + 11, j + 2, k + 8, Blocks.obsidian, 0);
        this.setBlock(world, i + 11, j + 2, k + 9, Blocks.obsidian, 0);
        this.setBlock(world, i + 11, j + 3, k + 2, Blocks.obsidian, 0);
        this.setBlock(world, i + 11, j + 3, k + 3, Blocks.obsidian, 0);
        this.setBlock(world, i + 11, j + 3, k + 4, Blocks.wool, 10);
        this.setBlock(world, i + 11, j + 3, k + 6, Blocks.wool, 10);
        this.setBlock(world, i + 11, j + 3, k + 8, Blocks.wool, 10);
        this.setBlock(world, i + 11, j + 3, k + 9, Blocks.obsidian, 0);
        this.setBlock(world, i + 11, j + 4, k + 2, Blocks.obsidian, 0);
        this.setBlock(world, i + 11, j + 4, k + 3, Blocks.wool, 10);
        this.setBlock(world, i + 11, j + 4, k + 8, Blocks.wool, 10);
        this.setBlock(world, i + 11, j + 4, k + 9, Blocks.obsidian, 0);
        this.setBlock(world, i + 11, j + 5, k + 2, Blocks.obsidian, 0);
        this.setBlock(world, i + 11, j + 5, k + 3, Blocks.wool, 10);
        this.setBlock(world, i + 11, j + 5, k + 8, Blocks.wool, 10);
        this.setBlock(world, i + 11, j + 5, k + 9, Blocks.obsidian, 0);
        this.setBlock(world, i + 11, j + 6, k + 2, Blocks.obsidian, 0);
        this.setBlock(world, i + 11, j + 6, k + 3, Blocks.wool, 10);
        this.setBlock(world, i + 11, j + 6, k + 8, Blocks.wool, 10);
        this.setBlock(world, i + 11, j + 6, k + 9, Blocks.obsidian, 0);
        this.setBlock(world, i + 11, j + 7, k + 3, Blocks.wool, 10);
        this.setBlock(world, i + 11, j + 7, k + 8, Blocks.wool, 10);
        this.setBlock(world, i + 11, j + 7, k + 9, Blocks.obsidian, 0);
        this.setBlock(world, i + 11, j + 8, k + 3, Blocks.wool, 10);
        this.setBlock(world, i + 11, j + 8, k + 8, Blocks.wool, 10);
        this.setBlock(world, i + 11, j + 8, k + 9, Blocks.obsidian, 0);
        this.setBlock(world, i + 11, j + 9, k + 3, Blocks.wool, 10);
        this.setBlock(world, i + 11, j + 9, k + 5, Blocks.wool, 10);
        this.setBlock(world, i + 11, j + 9, k + 8, Blocks.obsidian, 0);
        this.setBlock(world, i + 11, j + 9, k + 9, Blocks.obsidian, 0);
        this.setBlock(world, i + 11, j + 10, k + 3, Blocks.obsidian, 0);
        this.setBlock(world, i + 11, j + 10, k + 5, Blocks.obsidian, 0);
        this.setBlock(world, i + 11, j + 10, k + 7, Blocks.obsidian, 0);
        this.setBlock(world, i + 11, j + 10, k + 8, Blocks.obsidian, 0);
        this.setBlock(world, i + 11, j + 11, k + 3, Blocks.obsidian, 0);
        this.setBlock(world, i + 11, j + 11, k + 4, Blocks.obsidian, 0);
        this.setBlock(world, i + 12, j + 1, k + 4, Blocks.obsidian, 0);
        this.setBlock(world, i + 12, j + 1, k + 5, Blocks.obsidian, 0);
        this.setBlock(world, i + 12, j + 1, k + 6, Blocks.obsidian, 0);
        this.setBlock(world, i + 12, j + 1, k + 7, Blocks.obsidian, 0);
        this.setBlock(world, i + 12, j + 2, k + 3, Blocks.obsidian, 0);
        this.setBlock(world, i + 12, j + 2, k + 4, Blocks.obsidian, 0);
        this.setBlock(world, i + 12, j + 2, k + 5, Blocks.obsidian, 0);
        this.setBlock(world, i + 12, j + 2, k + 6, Blocks.obsidian, 0);
        this.setBlock(world, i + 12, j + 2, k + 7, Blocks.obsidian, 0);
        this.setBlock(world, i + 12, j + 2, k + 8, Blocks.obsidian, 0);
        this.setBlock(world, i + 12, j + 3, k + 3, Blocks.obsidian, 0);
        this.setBlock(world, i + 12, j + 3, k + 4, Blocks.wool, 10);
        this.setBlock(world, i + 12, j + 3, k + 5, Blocks.wool, 10);
        this.setBlock(world, i + 12, j + 3, k + 6, Blocks.obsidian, 0);
        this.setBlock(world, i + 12, j + 3, k + 7, Blocks.wool, 10);
        this.setBlock(world, i + 12, j + 3, k + 8, Blocks.obsidian, 0);
        this.setBlock(world, i + 12, j + 4, k + 3, Blocks.obsidian, 0);
        this.setBlock(world, i + 12, j + 4, k + 4, Blocks.wool, 10);
        this.setBlock(world, i + 12, j + 4, k + 5, Blocks.wool, 10);
        this.setBlock(world, i + 12, j + 4, k + 6, Blocks.wool, 10);
        this.setBlock(world, i + 12, j + 4, k + 8, Blocks.obsidian, 0);
        this.setBlock(world, i + 12, j + 5, k + 3, Blocks.obsidian, 0);
        this.setBlock(world, i + 12, j + 5, k + 4, Blocks.wool, 10);
        this.setBlock(world, i + 12, j + 5, k + 5, Blocks.wool, 10);
        this.setBlock(world, i + 12, j + 5, k + 6, Blocks.wool, 10);
        this.setBlock(world, i + 12, j + 5, k + 8, Blocks.obsidian, 0);
        this.setBlock(world, i + 12, j + 6, k + 3, Blocks.obsidian, 0);
        this.setBlock(world, i + 12, j + 6, k + 5, Blocks.wool, 10);
        this.setBlock(world, i + 12, j + 6, k + 6, Blocks.wool, 10);
        this.setBlock(world, i + 12, j + 6, k + 8, Blocks.obsidian, 0);
        this.setBlock(world, i + 12, j + 7, k + 3, Blocks.obsidian, 0);
        this.setBlock(world, i + 12, j + 7, k + 5, Blocks.wool, 10);
        this.setBlock(world, i + 12, j + 7, k + 8, Blocks.obsidian, 0);
        this.setBlock(world, i + 12, j + 8, k + 3, Blocks.obsidian, 0);
        this.setBlock(world, i + 12, j + 8, k + 5, Blocks.wool, 10);
        this.setBlock(world, i + 12, j + 8, k + 8, Blocks.obsidian, 0);
        this.setBlock(world, i + 12, j + 9, k + 3, Blocks.obsidian, 0);
        this.setBlock(world, i + 12, j + 9, k + 5, Blocks.wool, 10);
        this.setBlock(world, i + 12, j + 10, k + 5, Blocks.obsidian, 0);
        this.setBlock(world, i + 13, j + 2, k + 4, Blocks.obsidian, 0);
        this.setBlock(world, i + 13, j + 2, k + 5, Blocks.obsidian, 0);
        this.setBlock(world, i + 13, j + 2, k + 6, Blocks.obsidian, 0);
        this.setBlock(world, i + 13, j + 3, k + 4, Blocks.obsidian, 0);
        this.setBlock(world, i + 13, j + 3, k + 5, Blocks.obsidian, 0);
        this.setBlock(world, i + 13, j + 3, k + 6, Blocks.obsidian, 0);
        this.setBlock(world, i + 13, j + 4, k + 4, Blocks.obsidian, 0);
        this.setBlock(world, i + 13, j + 4, k + 5, Blocks.obsidian, 0);
        this.setBlock(world, i + 13, j + 4, k + 6, Blocks.obsidian, 0);
        this.setBlock(world, i + 13, j + 5, k + 4, Blocks.obsidian, 0);
        this.setBlock(world, i + 13, j + 5, k + 5, Blocks.obsidian, 0);
        this.setBlock(world, i + 13, j + 5, k + 6, Blocks.obsidian, 0);
        this.setBlock(world, i + 13, j + 6, k + 5, Blocks.obsidian, 0);
        this.setBlock(world, i + 13, j + 6, k + 6, Blocks.obsidian, 0);
        this.setBlock(world, i + 13, j + 7, k + 5, Blocks.obsidian, 0);
        this.setBlock(world, i + 13, j + 7, k + 6, Blocks.obsidian, 0);
        this.setBlock(world, i + 13, j + 8, k + 5, Blocks.obsidian, 0);
        this.setBlock(world, i + 13, j + 9, k + 5, Blocks.obsidian, 0);
        this.setBlock(world, i + 13, j + 10, k + 5, Blocks.obsidian, 0);
        return true;
    }
}
