

package com.gibby.dungeon.gen;

import net.minecraft.world.gen.feature.*;
import net.minecraft.world.*;
import java.util.*;
import net.minecraft.init.*;
import com.gibby.dungeon.*;

public class WorldGenGhostWitherTower extends WorldGenerator
{
    public boolean generate(final World world, final Random rand, final int i, final int j, final int k) {
        if (world.getBlock(i, j + 6, k) == Blocks.air || world.getBlock(i + 40, j + 6, k + 40) == Blocks.air || world.getBlock(i, j + 50, k) != Blocks.air || world.getBlock(i + 40, j + 50, k + 40) != Blocks.air || world.getBlock(i, j + 10, k) != Blocks.air || world.getBlock(i + 40, j + 10, k + 40) != Blocks.air) {
            return false;
        }
        System.out.println("Wither Ruins Generating at " + i + " " + j + " " + k);
        world.setBlock(i + 0, j + 0, k + 0, Dungeons.purpleBrick);
        world.setBlock(i + 0, j + 0, k + 1, Dungeons.purpleBrick);
        world.setBlock(i + 0, j + 0, k + 2, Dungeons.purpleBrick);
        world.setBlock(i + 0, j + 0, k + 3, Dungeons.purpleBrick);
        world.setBlock(i + 0, j + 0, k + 4, Dungeons.purpleBrick);
        world.setBlock(i + 0, j + 0, k + 5, Dungeons.purpleBrick);
        world.setBlock(i + 0, j + 0, k + 6, Dungeons.purpleBrick);
        world.setBlock(i + 0, j + 0, k + 7, Dungeons.purpleBrick);
        world.setBlock(i + 0, j + 0, k + 8, Dungeons.purpleBrick);
        world.setBlock(i + 0, j + 0, k + 9, Dungeons.purpleBrick);
        world.setBlock(i + 0, j + 0, k + 10, Dungeons.purpleBrick);
        world.setBlock(i + 0, j + 0, k + 11, Dungeons.purpleBrick);
        world.setBlock(i + 0, j + 0, k + 12, Dungeons.purpleBrick);
        world.setBlock(i + 0, j + 0, k + 13, Dungeons.purpleBrick);
        world.setBlock(i + 0, j + 0, k + 14, Dungeons.purpleBrick);
        world.setBlock(i + 0, j + 0, k + 15, Dungeons.purpleBrick);
        world.setBlock(i + 0, j + 0, k + 16, Dungeons.purpleBrick);
        world.setBlock(i + 0, j + 0, k + 17, Dungeons.purpleBrick);
        world.setBlock(i + 0, j + 0, k + 18, Dungeons.purpleBrick);
        world.setBlock(i + 0, j + 0, k + 19, Dungeons.purpleBrick);
        world.setBlock(i + 0, j + 0, k + 20, Dungeons.purpleBrick);
        world.setBlock(i + 0, j + 0, k + 21, Dungeons.purpleBrick);
        world.setBlock(i + 0, j + 0, k + 22, Dungeons.purpleBrick);
        world.setBlock(i + 0, j + 0, k + 23, Dungeons.purpleBrick);
        world.setBlock(i + 0, j + 0, k + 24, Dungeons.purpleBrick);
        world.setBlock(i + 0, j + 0, k + 25, Dungeons.purpleBrick);
        world.setBlock(i + 0, j + 0, k + 26, Dungeons.purpleBrick);
        world.setBlock(i + 0, j + 0, k + 27, Dungeons.purpleBrick);
        world.setBlock(i + 0, j + 0, k + 28, Dungeons.purpleBrick);
        world.setBlock(i + 0, j + 0, k + 29, Dungeons.purpleBrick);
        world.setBlock(i + 0, j + 0, k + 30, Dungeons.purpleBrick);
        world.setBlock(i + 0, j + 0, k + 31, Dungeons.purpleBrick);
        world.setBlock(i + 0, j + 0, k + 32, Dungeons.purpleBrick);
        world.setBlock(i + 0, j + 0, k + 33, Dungeons.purpleBrick);
        world.setBlock(i + 0, j + 0, k + 34, Dungeons.purpleBrick);
        world.setBlock(i + 0, j + 0, k + 35, Dungeons.purpleBrick);
        world.setBlock(i + 0, j + 0, k + 36, Dungeons.purpleBrick);
        world.setBlock(i + 0, j + 0, k + 37, Dungeons.purpleBrick);
        world.setBlock(i + 0, j + 0, k + 38, Dungeons.purpleBrick);
        world.setBlock(i + 1, j + 0, k + 0, Dungeons.purpleBrick);
        world.setBlock(i + 1, j + 0, k + 1, Dungeons.purpleBrick);
        world.setBlock(i + 1, j + 0, k + 2, Dungeons.purpleBrick);
        world.setBlock(i + 1, j + 0, k + 3, Dungeons.purpleBrick);
        world.setBlock(i + 1, j + 0, k + 4, Dungeons.purpleBrick);
        world.setBlock(i + 1, j + 0, k + 5, Dungeons.purpleBrick);
        world.setBlock(i + 1, j + 0, k + 6, Dungeons.purpleBrick);
        world.setBlock(i + 1, j + 0, k + 7, Dungeons.purpleBrick);
        world.setBlock(i + 1, j + 0, k + 8, Dungeons.purpleBrick);
        world.setBlock(i + 1, j + 0, k + 9, Dungeons.purpleBrick);
        world.setBlock(i + 1, j + 0, k + 10, Dungeons.purpleBrick);
        world.setBlock(i + 1, j + 0, k + 11, Dungeons.purpleBrick);
        world.setBlock(i + 1, j + 0, k + 12, Dungeons.purpleBrick);
        world.setBlock(i + 1, j + 0, k + 13, Dungeons.purpleBrick);
        world.setBlock(i + 1, j + 0, k + 14, Dungeons.purpleBrick);
        world.setBlock(i + 1, j + 0, k + 15, Dungeons.purpleBrick);
        world.setBlock(i + 1, j + 0, k + 16, Dungeons.purpleBrick);
        world.setBlock(i + 1, j + 0, k + 17, Dungeons.purpleBrick);
        world.setBlock(i + 1, j + 0, k + 18, Dungeons.purpleBrick);
        world.setBlock(i + 1, j + 0, k + 19, Dungeons.purpleBrick);
        world.setBlock(i + 1, j + 0, k + 20, Dungeons.purpleBrick);
        world.setBlock(i + 1, j + 0, k + 21, Dungeons.purpleBrick);
        world.setBlock(i + 1, j + 0, k + 22, Dungeons.purpleBrick);
        world.setBlock(i + 1, j + 0, k + 23, Dungeons.purpleBrick);
        world.setBlock(i + 1, j + 0, k + 24, Dungeons.purpleBrick);
        world.setBlock(i + 1, j + 0, k + 25, Dungeons.purpleBrick);
        world.setBlock(i + 1, j + 0, k + 26, Dungeons.purpleBrick);
        world.setBlock(i + 1, j + 0, k + 27, Dungeons.purpleBrick);
        world.setBlock(i + 1, j + 0, k + 28, Dungeons.purpleBrick);
        world.setBlock(i + 1, j + 0, k + 29, Dungeons.purpleBrick);
        world.setBlock(i + 1, j + 0, k + 30, Dungeons.purpleBrick);
        world.setBlock(i + 1, j + 0, k + 31, Dungeons.purpleBrick);
        world.setBlock(i + 1, j + 0, k + 32, Dungeons.purpleBrick);
        world.setBlock(i + 1, j + 0, k + 33, Dungeons.purpleBrick);
        world.setBlock(i + 1, j + 0, k + 34, Dungeons.purpleBrick);
        world.setBlock(i + 1, j + 0, k + 35, Dungeons.purpleBrick);
        world.setBlock(i + 1, j + 0, k + 36, Dungeons.purpleBrick);
        world.setBlock(i + 1, j + 0, k + 37, Dungeons.purpleBrick);
        world.setBlock(i + 1, j + 0, k + 38, Dungeons.purpleBrick);
        world.setBlock(i + 2, j + 0, k + 0, Dungeons.purpleBrick);
        world.setBlock(i + 2, j + 0, k + 1, Dungeons.purpleBrick);
        world.setBlock(i + 2, j + 0, k + 2, Dungeons.purpleBrick);
        world.setBlock(i + 2, j + 0, k + 3, Dungeons.purpleBrick);
        world.setBlock(i + 2, j + 0, k + 4, Dungeons.purpleBrick);
        world.setBlock(i + 2, j + 0, k + 5, Dungeons.purpleBrick);
        world.setBlock(i + 2, j + 0, k + 6, Dungeons.purpleBrick);
        world.setBlock(i + 2, j + 0, k + 7, Dungeons.purpleBrick);
        world.setBlock(i + 2, j + 0, k + 8, Dungeons.purpleBrick);
        world.setBlock(i + 2, j + 0, k + 9, Dungeons.purpleBrick);
        world.setBlock(i + 2, j + 0, k + 10, Dungeons.purpleBrick);
        world.setBlock(i + 2, j + 0, k + 11, Dungeons.purpleBrick);
        world.setBlock(i + 2, j + 0, k + 12, Dungeons.purpleBrick);
        world.setBlock(i + 2, j + 0, k + 13, Dungeons.purpleBrick);
        world.setBlock(i + 2, j + 0, k + 14, Dungeons.purpleBrick);
        world.setBlock(i + 2, j + 0, k + 15, Dungeons.purpleBrick);
        world.setBlock(i + 2, j + 0, k + 16, Dungeons.purpleBrick);
        world.setBlock(i + 2, j + 0, k + 17, Dungeons.purpleBrick);
        world.setBlock(i + 2, j + 0, k + 18, Dungeons.purpleBrick);
        world.setBlock(i + 2, j + 0, k + 19, Dungeons.purpleBrick);
        world.setBlock(i + 2, j + 0, k + 20, Dungeons.purpleBrick);
        world.setBlock(i + 2, j + 0, k + 21, Dungeons.purpleBrick);
        world.setBlock(i + 2, j + 0, k + 22, Dungeons.purpleBrick);
        world.setBlock(i + 2, j + 0, k + 23, Dungeons.purpleBrick);
        world.setBlock(i + 2, j + 0, k + 24, Dungeons.purpleBrick);
        world.setBlock(i + 2, j + 0, k + 25, Dungeons.purpleBrick);
        world.setBlock(i + 2, j + 0, k + 26, Dungeons.purpleBrick);
        world.setBlock(i + 2, j + 0, k + 27, Dungeons.purpleBrick);
        world.setBlock(i + 2, j + 0, k + 28, Dungeons.purpleBrick);
        world.setBlock(i + 2, j + 0, k + 29, Dungeons.purpleBrick);
        world.setBlock(i + 2, j + 0, k + 30, Dungeons.purpleBrick);
        world.setBlock(i + 2, j + 0, k + 31, Dungeons.purpleBrick);
        world.setBlock(i + 2, j + 0, k + 32, Dungeons.purpleBrick);
        world.setBlock(i + 2, j + 0, k + 33, Dungeons.purpleBrick);
        world.setBlock(i + 2, j + 0, k + 34, Dungeons.purpleBrick);
        world.setBlock(i + 2, j + 0, k + 35, Dungeons.purpleBrick);
        world.setBlock(i + 2, j + 0, k + 36, Dungeons.purpleBrick);
        world.setBlock(i + 2, j + 0, k + 37, Dungeons.purpleBrick);
        world.setBlock(i + 2, j + 0, k + 38, Dungeons.purpleBrick);
        world.setBlock(i + 3, j + 0, k + 0, Dungeons.purpleBrick);
        world.setBlock(i + 3, j + 0, k + 1, Dungeons.purpleBrick);
        world.setBlock(i + 3, j + 0, k + 2, Dungeons.purpleBrick);
        world.setBlock(i + 3, j + 0, k + 3, Dungeons.purpleBrick);
        world.setBlock(i + 3, j + 0, k + 4, Dungeons.purpleBrick);
        world.setBlock(i + 3, j + 0, k + 5, Dungeons.purpleBrick);
        world.setBlock(i + 3, j + 0, k + 6, Dungeons.purpleBrick);
        world.setBlock(i + 3, j + 0, k + 7, Dungeons.purpleBrick);
        world.setBlock(i + 3, j + 0, k + 8, Dungeons.purpleBrick);
        world.setBlock(i + 3, j + 0, k + 9, Dungeons.purpleBrick);
        world.setBlock(i + 3, j + 0, k + 10, Dungeons.purpleBrick);
        world.setBlock(i + 3, j + 0, k + 11, Dungeons.purpleBrick);
        world.setBlock(i + 3, j + 0, k + 12, Dungeons.purpleBrick);
        world.setBlock(i + 3, j + 0, k + 13, Dungeons.purpleBrick);
        world.setBlock(i + 3, j + 0, k + 14, Dungeons.purpleBrick);
        world.setBlock(i + 3, j + 0, k + 15, Dungeons.purpleBrick);
        world.setBlock(i + 3, j + 0, k + 16, Dungeons.purpleBrick);
        world.setBlock(i + 3, j + 0, k + 17, Dungeons.purpleBrick);
        world.setBlock(i + 3, j + 0, k + 18, Dungeons.purpleBrick);
        world.setBlock(i + 3, j + 0, k + 19, Dungeons.purpleBrick);
        world.setBlock(i + 3, j + 0, k + 20, Dungeons.purpleBrick);
        world.setBlock(i + 3, j + 0, k + 21, Dungeons.purpleBrick);
        world.setBlock(i + 3, j + 0, k + 22, Dungeons.purpleBrick);
        world.setBlock(i + 3, j + 0, k + 23, Dungeons.purpleBrick);
        world.setBlock(i + 3, j + 0, k + 24, Dungeons.purpleBrick);
        world.setBlock(i + 3, j + 0, k + 25, Dungeons.purpleBrick);
        world.setBlock(i + 3, j + 0, k + 26, Dungeons.purpleBrick);
        world.setBlock(i + 3, j + 0, k + 27, Dungeons.purpleBrick);
        world.setBlock(i + 3, j + 0, k + 28, Dungeons.purpleBrick);
        world.setBlock(i + 3, j + 0, k + 29, Dungeons.purpleBrick);
        world.setBlock(i + 3, j + 0, k + 30, Dungeons.purpleBrick);
        world.setBlock(i + 3, j + 0, k + 31, Dungeons.purpleBrick);
        world.setBlock(i + 3, j + 0, k + 32, Dungeons.purpleBrick);
        world.setBlock(i + 3, j + 0, k + 33, Dungeons.purpleBrick);
        world.setBlock(i + 3, j + 0, k + 34, Dungeons.purpleBrick);
        world.setBlock(i + 3, j + 0, k + 35, Dungeons.purpleBrick);
        world.setBlock(i + 3, j + 0, k + 36, Dungeons.purpleBrick);
        world.setBlock(i + 3, j + 0, k + 37, Dungeons.purpleBrick);
        world.setBlock(i + 3, j + 0, k + 38, Dungeons.purpleBrick);
        world.setBlock(i + 4, j + 0, k + 0, Dungeons.purpleBrick);
        world.setBlock(i + 4, j + 0, k + 1, Dungeons.purpleBrick);
        world.setBlock(i + 4, j + 0, k + 2, Dungeons.purpleBrick);
        world.setBlock(i + 4, j + 0, k + 3, Dungeons.purpleBrick);
        world.setBlock(i + 4, j + 0, k + 4, Dungeons.purpleBrick);
        world.setBlock(i + 4, j + 0, k + 5, Dungeons.purpleBrick);
        world.setBlock(i + 4, j + 0, k + 6, Dungeons.purpleBrick);
        world.setBlock(i + 4, j + 0, k + 7, Dungeons.purpleBrick);
        world.setBlock(i + 4, j + 0, k + 8, Dungeons.purpleBrick);
        world.setBlock(i + 4, j + 0, k + 9, Dungeons.purpleBrick);
        world.setBlock(i + 4, j + 0, k + 10, Dungeons.purpleBrick);
        world.setBlock(i + 4, j + 0, k + 11, Dungeons.purpleBrick);
        world.setBlock(i + 4, j + 0, k + 12, Dungeons.purpleBrick);
        world.setBlock(i + 4, j + 0, k + 13, Dungeons.purpleBrick);
        world.setBlock(i + 4, j + 0, k + 14, Dungeons.purpleBrick);
        world.setBlock(i + 4, j + 0, k + 15, Dungeons.purpleBrick);
        world.setBlock(i + 4, j + 0, k + 16, Dungeons.purpleBrick);
        world.setBlock(i + 4, j + 0, k + 17, Dungeons.purpleBrick);
        world.setBlock(i + 4, j + 0, k + 18, Dungeons.purpleBrick);
        world.setBlock(i + 4, j + 0, k + 19, Dungeons.purpleBrick);
        world.setBlock(i + 4, j + 0, k + 20, Dungeons.purpleBrick);
        world.setBlock(i + 4, j + 0, k + 21, Dungeons.purpleBrick);
        world.setBlock(i + 4, j + 0, k + 22, Dungeons.purpleBrick);
        world.setBlock(i + 4, j + 0, k + 23, Dungeons.purpleBrick);
        world.setBlock(i + 4, j + 0, k + 24, Dungeons.purpleBrick);
        world.setBlock(i + 4, j + 0, k + 25, Dungeons.purpleBrick);
        world.setBlock(i + 4, j + 0, k + 26, Dungeons.purpleBrick);
        world.setBlock(i + 4, j + 0, k + 27, Dungeons.purpleBrick);
        world.setBlock(i + 4, j + 0, k + 28, Dungeons.purpleBrick);
        world.setBlock(i + 4, j + 0, k + 29, Dungeons.purpleBrick);
        world.setBlock(i + 4, j + 0, k + 30, Dungeons.purpleBrick);
        world.setBlock(i + 4, j + 0, k + 31, Dungeons.purpleBrick);
        world.setBlock(i + 4, j + 0, k + 32, Dungeons.purpleBrick);
        world.setBlock(i + 4, j + 0, k + 33, Dungeons.purpleBrick);
        world.setBlock(i + 4, j + 0, k + 34, Dungeons.purpleBrick);
        world.setBlock(i + 4, j + 0, k + 35, Dungeons.purpleBrick);
        world.setBlock(i + 4, j + 0, k + 36, Dungeons.purpleBrick);
        world.setBlock(i + 4, j + 0, k + 37, Dungeons.purpleBrick);
        world.setBlock(i + 4, j + 0, k + 38, Dungeons.purpleBrick);
        world.setBlock(i + 4, j + 1, k + 16, Dungeons.purpleBrick);
        world.setBlock(i + 4, j + 1, k + 17, Dungeons.purpleBrick);
        world.setBlock(i + 4, j + 1, k + 18, Dungeons.purpleBrick);
        world.setBlock(i + 4, j + 1, k + 19, Dungeons.purpleBrick);
        world.setBlock(i + 4, j + 1, k + 20, Dungeons.purpleBrick);
        world.setBlock(i + 4, j + 1, k + 21, Dungeons.purpleBrick);
        world.setBlock(i + 4, j + 1, k + 22, Dungeons.purpleBrick);
        world.setBlock(i + 4, j + 2, k + 16, Dungeons.purpleBrick);
        world.setBlock(i + 4, j + 2, k + 17, Dungeons.purpleBrick);
        world.setBlock(i + 4, j + 2, k + 18, Dungeons.purpleBrick);
        world.setBlock(i + 4, j + 2, k + 19, Dungeons.purpleBrick);
        world.setBlock(i + 4, j + 2, k + 20, Dungeons.purpleBrick);
        world.setBlock(i + 4, j + 2, k + 21, Dungeons.purpleBrick);
        world.setBlock(i + 4, j + 2, k + 22, Dungeons.purpleBrick);
        world.setBlock(i + 4, j + 3, k + 16, Dungeons.purpleBrick);
        world.setBlock(i + 4, j + 3, k + 17, Dungeons.purpleBrick);
        world.setBlock(i + 4, j + 3, k + 18, Dungeons.purpleBrick);
        world.setBlock(i + 4, j + 3, k + 19, Dungeons.purpleBrick);
        world.setBlock(i + 4, j + 3, k + 20, Dungeons.purpleBrick);
        world.setBlock(i + 4, j + 3, k + 21, Dungeons.purpleBrick);
        world.setBlock(i + 4, j + 3, k + 22, Dungeons.purpleBrick);
        world.setBlock(i + 4, j + 4, k + 16, Dungeons.purpleBrick);
        world.setBlock(i + 4, j + 4, k + 17, Dungeons.purpleBrick);
        world.setBlock(i + 4, j + 4, k + 18, Dungeons.purpleBrick);
        world.setBlock(i + 4, j + 4, k + 19, Dungeons.purpleBrick);
        world.setBlock(i + 4, j + 4, k + 20, Dungeons.purpleBrick);
        world.setBlock(i + 4, j + 4, k + 21, Dungeons.purpleBrick);
        world.setBlock(i + 4, j + 4, k + 22, Dungeons.purpleBrick);
        world.setBlock(i + 4, j + 5, k + 16, Dungeons.purpleBrick);
        world.setBlock(i + 4, j + 5, k + 17, Dungeons.purpleBrick);
        world.setBlock(i + 4, j + 5, k + 18, Dungeons.purpleBrick);
        world.setBlock(i + 4, j + 5, k + 19, Dungeons.purpleBrick);
        world.setBlock(i + 4, j + 5, k + 20, Dungeons.purpleBrick);
        world.setBlock(i + 4, j + 5, k + 21, Dungeons.purpleBrick);
        world.setBlock(i + 4, j + 5, k + 22, Dungeons.purpleBrick);
        world.setBlock(i + 4, j + 6, k + 16, Dungeons.purpleBrick);
        world.setBlock(i + 4, j + 6, k + 17, Dungeons.purpleBrick);
        world.setBlock(i + 4, j + 6, k + 18, Dungeons.purpleBrick);
        world.setBlock(i + 4, j + 6, k + 19, Dungeons.purpleBrick);
        world.setBlock(i + 4, j + 6, k + 20, Dungeons.purpleBrick);
        world.setBlock(i + 4, j + 6, k + 21, Dungeons.purpleBrick);
        world.setBlock(i + 4, j + 6, k + 22, Dungeons.purpleBrick);
        world.setBlock(i + 4, j + 7, k + 16, Dungeons.purpleBrick);
        world.setBlock(i + 4, j + 7, k + 17, Dungeons.purpleBrick);
        world.setBlock(i + 4, j + 7, k + 18, Dungeons.purpleBrick);
        world.setBlock(i + 4, j + 7, k + 19, Dungeons.purpleBrick);
        world.setBlock(i + 4, j + 7, k + 20, Dungeons.purpleBrick);
        world.setBlock(i + 4, j + 7, k + 21, Dungeons.purpleBrick);
        world.setBlock(i + 4, j + 7, k + 22, Dungeons.purpleBrick);
        world.setBlock(i + 4, j + 8, k + 16, Dungeons.purpleBrick);
        world.setBlock(i + 4, j + 8, k + 17, Dungeons.purpleBrick);
        world.setBlock(i + 4, j + 8, k + 18, Dungeons.purpleBrick);
        world.setBlock(i + 4, j + 8, k + 19, Dungeons.purpleBrick);
        world.setBlock(i + 4, j + 8, k + 20, Dungeons.purpleBrick);
        world.setBlock(i + 4, j + 8, k + 21, Dungeons.purpleBrick);
        world.setBlock(i + 4, j + 8, k + 22, Dungeons.purpleBrick);
        world.setBlock(i + 4, j + 9, k + 16, Dungeons.purpleBrick);
        world.setBlock(i + 4, j + 9, k + 17, Dungeons.purpleBrick);
        world.setBlock(i + 4, j + 9, k + 18, Dungeons.purpleBrick);
        world.setBlock(i + 4, j + 9, k + 19, Dungeons.purpleBrick);
        world.setBlock(i + 4, j + 9, k + 20, Dungeons.purpleBrick);
        world.setBlock(i + 4, j + 9, k + 21, Dungeons.purpleBrick);
        world.setBlock(i + 4, j + 9, k + 22, Dungeons.purpleBrick);
        world.setBlock(i + 4, j + 10, k + 16, Dungeons.purpleBrick);
        world.setBlock(i + 4, j + 10, k + 17, Dungeons.purpleBrick);
        world.setBlock(i + 4, j + 10, k + 18, Dungeons.purpleBrick);
        world.setBlock(i + 4, j + 10, k + 19, Dungeons.purpleBrick);
        world.setBlock(i + 4, j + 10, k + 20, Dungeons.purpleBrick);
        world.setBlock(i + 4, j + 10, k + 21, Dungeons.purpleBrick);
        world.setBlock(i + 4, j + 10, k + 22, Dungeons.purpleBrick);
        world.setBlock(i + 4, j + 11, k + 16, Dungeons.purpleBrick);
        world.setBlock(i + 4, j + 11, k + 17, Dungeons.purpleBrick);
        world.setBlock(i + 4, j + 11, k + 18, Dungeons.purpleBrick);
        world.setBlock(i + 4, j + 11, k + 19, Dungeons.purpleBrick);
        world.setBlock(i + 4, j + 11, k + 20, Dungeons.purpleBrick);
        world.setBlock(i + 4, j + 11, k + 21, Dungeons.purpleBrick);
        world.setBlock(i + 4, j + 11, k + 22, Dungeons.purpleBrick);
        world.setBlock(i + 4, j + 12, k + 16, Dungeons.purpleBrick);
        world.setBlock(i + 4, j + 12, k + 17, Dungeons.purpleBrick);
        world.setBlock(i + 4, j + 12, k + 18, Dungeons.purpleBrick);
        world.setBlock(i + 4, j + 12, k + 19, Dungeons.purpleBrick);
        world.setBlock(i + 4, j + 12, k + 20, Dungeons.purpleBrick);
        world.setBlock(i + 4, j + 12, k + 21, Dungeons.purpleBrick);
        world.setBlock(i + 4, j + 12, k + 22, Dungeons.purpleBrick);
        world.setBlock(i + 5, j + 0, k + 0, Dungeons.purpleBrick);
        world.setBlock(i + 5, j + 0, k + 1, Dungeons.purpleBrick);
        world.setBlock(i + 5, j + 0, k + 2, Dungeons.purpleBrick);
        world.setBlock(i + 5, j + 0, k + 3, Dungeons.purpleBrick);
        world.setBlock(i + 5, j + 0, k + 4, Dungeons.purpleBrick);
        world.setBlock(i + 5, j + 0, k + 5, Dungeons.purpleBrick);
        world.setBlock(i + 5, j + 0, k + 6, Dungeons.purpleBrick);
        world.setBlock(i + 5, j + 0, k + 7, Dungeons.purpleBrick);
        world.setBlock(i + 5, j + 0, k + 8, Dungeons.purpleBrick);
        world.setBlock(i + 5, j + 0, k + 9, Dungeons.purpleBrick);
        world.setBlock(i + 5, j + 0, k + 10, Dungeons.purpleBrick);
        world.setBlock(i + 5, j + 0, k + 11, Dungeons.purpleBrick);
        world.setBlock(i + 5, j + 0, k + 12, Dungeons.purpleBrick);
        world.setBlock(i + 5, j + 0, k + 13, Dungeons.purpleBrick);
        world.setBlock(i + 5, j + 0, k + 14, Dungeons.purpleBrick);
        world.setBlock(i + 5, j + 0, k + 15, Dungeons.purpleBrick);
        world.setBlock(i + 5, j + 0, k + 16, Dungeons.purpleBrick);
        world.setBlock(i + 5, j + 0, k + 17, Dungeons.purpleBrick);
        world.setBlock(i + 5, j + 0, k + 18, Dungeons.purpleBrick);
        world.setBlock(i + 5, j + 0, k + 19, Dungeons.purpleBrick);
        world.setBlock(i + 5, j + 0, k + 20, Dungeons.purpleBrick);
        world.setBlock(i + 5, j + 0, k + 21, Dungeons.purpleBrick);
        world.setBlock(i + 5, j + 0, k + 22, Dungeons.purpleBrick);
        world.setBlock(i + 5, j + 0, k + 23, Dungeons.purpleBrick);
        world.setBlock(i + 5, j + 0, k + 24, Dungeons.purpleBrick);
        world.setBlock(i + 5, j + 0, k + 25, Dungeons.purpleBrick);
        world.setBlock(i + 5, j + 0, k + 26, Dungeons.purpleBrick);
        world.setBlock(i + 5, j + 0, k + 27, Dungeons.purpleBrick);
        world.setBlock(i + 5, j + 0, k + 28, Dungeons.purpleBrick);
        world.setBlock(i + 5, j + 0, k + 29, Dungeons.purpleBrick);
        world.setBlock(i + 5, j + 0, k + 30, Dungeons.purpleBrick);
        world.setBlock(i + 5, j + 0, k + 31, Dungeons.purpleBrick);
        world.setBlock(i + 5, j + 0, k + 32, Dungeons.purpleBrick);
        world.setBlock(i + 5, j + 0, k + 33, Dungeons.purpleBrick);
        world.setBlock(i + 5, j + 0, k + 34, Dungeons.purpleBrick);
        world.setBlock(i + 5, j + 0, k + 35, Dungeons.purpleBrick);
        world.setBlock(i + 5, j + 0, k + 36, Dungeons.purpleBrick);
        world.setBlock(i + 5, j + 0, k + 37, Dungeons.purpleBrick);
        world.setBlock(i + 5, j + 0, k + 38, Dungeons.purpleBrick);
        world.setBlock(i + 5, j + 1, k + 13, Dungeons.purpleBrick);
        world.setBlock(i + 5, j + 1, k + 14, Dungeons.purpleBrick);
        world.setBlock(i + 5, j + 1, k + 15, Dungeons.purpleBrick);
        world.setBlock(i + 5, j + 1, k + 16, Dungeons.purpleBrick);
        world.setBlock(i + 5, j + 1, k + 17, Dungeons.purpleBrick);
        world.setBlock(i + 5, j + 1, k + 18, Dungeons.purpleBrick);
        world.setBlock(i + 5, j + 1, k + 19, Dungeons.purpleBrick);
        world.setBlock(i + 5, j + 1, k + 20, Dungeons.purpleBrick);
        world.setBlock(i + 5, j + 1, k + 21, Dungeons.purpleBrick);
        world.setBlock(i + 5, j + 1, k + 22, Dungeons.purpleBrick);
        world.setBlock(i + 5, j + 1, k + 23, Dungeons.purpleBrick);
        world.setBlock(i + 5, j + 1, k + 24, Dungeons.purpleBrick);
        world.setBlock(i + 5, j + 1, k + 25, Dungeons.purpleBrick);
        world.setBlock(i + 5, j + 2, k + 13, Dungeons.purpleBrick);
        world.setBlock(i + 5, j + 2, k + 14, Dungeons.purpleBrick);
        world.setBlock(i + 5, j + 2, k + 15, Dungeons.purpleBrick);
        world.setBlock(i + 5, j + 2, k + 16, Dungeons.purpleBrick);
        world.setBlock(i + 5, j + 2, k + 17, Dungeons.purpleBrick);
        world.setBlock(i + 5, j + 2, k + 18, Dungeons.purpleBrick);
        world.setBlock(i + 5, j + 2, k + 19, Dungeons.purpleBrick);
        world.setBlock(i + 5, j + 2, k + 20, Dungeons.purpleBrick);
        world.setBlock(i + 5, j + 2, k + 21, Dungeons.purpleBrick);
        world.setBlock(i + 5, j + 2, k + 22, Dungeons.purpleBrick);
        world.setBlock(i + 5, j + 2, k + 23, Dungeons.purpleBrick);
        world.setBlock(i + 5, j + 2, k + 24, Dungeons.purpleBrick);
        world.setBlock(i + 5, j + 2, k + 25, Dungeons.purpleBrick);
        world.setBlock(i + 5, j + 3, k + 13, Dungeons.purpleBrick);
        world.setBlock(i + 5, j + 3, k + 14, Dungeons.purpleBrick);
        world.setBlock(i + 5, j + 3, k + 15, Dungeons.purpleBrick);
        world.setBlock(i + 5, j + 3, k + 16, Dungeons.purpleBrick);
        world.setBlock(i + 5, j + 3, k + 17, Dungeons.purpleBrick);
        world.setBlock(i + 5, j + 3, k + 18, Dungeons.purpleBrick);
        world.setBlock(i + 5, j + 3, k + 19, Dungeons.purpleBrick);
        world.setBlock(i + 5, j + 3, k + 20, Dungeons.purpleBrick);
        world.setBlock(i + 5, j + 3, k + 21, Dungeons.purpleBrick);
        world.setBlock(i + 5, j + 3, k + 22, Dungeons.purpleBrick);
        world.setBlock(i + 5, j + 3, k + 23, Dungeons.purpleBrick);
        world.setBlock(i + 5, j + 3, k + 24, Dungeons.purpleBrick);
        world.setBlock(i + 5, j + 3, k + 25, Dungeons.purpleBrick);
        world.setBlock(i + 5, j + 4, k + 13, Dungeons.purpleBrick);
        world.setBlock(i + 5, j + 4, k + 14, Dungeons.purpleBrick);
        world.setBlock(i + 5, j + 4, k + 15, Dungeons.purpleBrick);
        world.setBlock(i + 5, j + 4, k + 16, Dungeons.purpleBrick);
        world.setBlock(i + 5, j + 4, k + 17, Dungeons.purpleBrick);
        world.setBlock(i + 5, j + 4, k + 18, Dungeons.purpleBrick);
        world.setBlock(i + 5, j + 4, k + 19, Dungeons.purpleBrick);
        world.setBlock(i + 5, j + 4, k + 20, Dungeons.purpleBrick);
        world.setBlock(i + 5, j + 4, k + 21, Dungeons.purpleBrick);
        world.setBlock(i + 5, j + 4, k + 22, Dungeons.purpleBrick);
        world.setBlock(i + 5, j + 4, k + 23, Dungeons.purpleBrick);
        world.setBlock(i + 5, j + 4, k + 24, Dungeons.purpleBrick);
        world.setBlock(i + 5, j + 4, k + 25, Dungeons.purpleBrick);
        world.setBlock(i + 5, j + 5, k + 13, Dungeons.purpleBrick);
        world.setBlock(i + 5, j + 5, k + 14, Dungeons.purpleBrick);
        world.setBlock(i + 5, j + 5, k + 15, Dungeons.purpleBrick);
        world.setBlock(i + 5, j + 5, k + 16, Dungeons.purpleBrick);
        world.setBlock(i + 5, j + 5, k + 17, Dungeons.purpleBrick);
        world.setBlock(i + 5, j + 5, k + 18, Dungeons.purpleBrick);
        world.setBlock(i + 5, j + 5, k + 19, Dungeons.purpleBrick);
        world.setBlock(i + 5, j + 5, k + 20, Dungeons.purpleBrick);
        world.setBlock(i + 5, j + 5, k + 21, Dungeons.purpleBrick);
        world.setBlock(i + 5, j + 5, k + 22, Dungeons.purpleBrick);
        world.setBlock(i + 5, j + 5, k + 23, Dungeons.purpleBrick);
        world.setBlock(i + 5, j + 5, k + 24, Dungeons.purpleBrick);
        world.setBlock(i + 5, j + 5, k + 25, Dungeons.purpleBrick);
        world.setBlock(i + 5, j + 6, k + 13, Dungeons.purpleBrick);
        world.setBlock(i + 5, j + 6, k + 14, Dungeons.purpleBrick);
        world.setBlock(i + 5, j + 6, k + 15, Dungeons.purpleBrick);
        world.setBlock(i + 5, j + 6, k + 16, Dungeons.purpleBrick);
        world.setBlock(i + 5, j + 6, k + 17, Dungeons.purpleBrick);
        world.setBlock(i + 5, j + 6, k + 18, Dungeons.purpleBrick);
        world.setBlock(i + 5, j + 6, k + 19, Dungeons.purpleBrick);
        world.setBlock(i + 5, j + 6, k + 20, Dungeons.purpleBrick);
        world.setBlock(i + 5, j + 6, k + 21, Dungeons.purpleBrick);
        world.setBlock(i + 5, j + 6, k + 22, Dungeons.purpleBrick);
        world.setBlock(i + 5, j + 6, k + 23, Dungeons.purpleBrick);
        world.setBlock(i + 5, j + 6, k + 24, Dungeons.purpleBrick);
        world.setBlock(i + 5, j + 6, k + 25, Dungeons.purpleBrick);
        world.setBlock(i + 5, j + 7, k + 13, Dungeons.purpleBrick);
        world.setBlock(i + 5, j + 7, k + 14, Dungeons.purpleBrick);
        world.setBlock(i + 5, j + 7, k + 15, Dungeons.purpleBrick);
        world.setBlock(i + 5, j + 7, k + 16, Dungeons.purpleBrick);
        world.setBlock(i + 5, j + 7, k + 17, Dungeons.purpleBrick);
        world.setBlock(i + 5, j + 7, k + 18, Dungeons.purpleBrick);
        world.setBlock(i + 5, j + 7, k + 19, Dungeons.purpleBrick);
        world.setBlock(i + 5, j + 7, k + 20, Dungeons.purpleBrick);
        world.setBlock(i + 5, j + 7, k + 21, Dungeons.purpleBrick);
        world.setBlock(i + 5, j + 7, k + 22, Dungeons.purpleBrick);
        world.setBlock(i + 5, j + 7, k + 23, Dungeons.purpleBrick);
        world.setBlock(i + 5, j + 7, k + 24, Dungeons.purpleBrick);
        world.setBlock(i + 5, j + 7, k + 25, Dungeons.purpleBrick);
        world.setBlock(i + 5, j + 8, k + 13, Dungeons.purpleBrick);
        world.setBlock(i + 5, j + 8, k + 14, Dungeons.purpleBrick);
        world.setBlock(i + 5, j + 8, k + 15, Dungeons.purpleBrick);
        world.setBlock(i + 5, j + 8, k + 17, Dungeons.purpleBrick);
        world.setBlock(i + 5, j + 8, k + 18, Dungeons.purpleBrick);
        world.setBlock(i + 5, j + 8, k + 19, Dungeons.purpleBrick);
        world.setBlock(i + 5, j + 8, k + 20, Dungeons.purpleBrick);
        world.setBlock(i + 5, j + 8, k + 21, Dungeons.purpleBrick);
        world.setBlock(i + 5, j + 8, k + 22, Dungeons.purpleBrick);
        world.setBlock(i + 5, j + 8, k + 23, Dungeons.purpleBrick);
        world.setBlock(i + 5, j + 8, k + 24, Dungeons.purpleBrick);
        world.setBlock(i + 5, j + 8, k + 25, Dungeons.purpleBrick);
        world.setBlock(i + 5, j + 9, k + 13, Dungeons.purpleBrick);
        world.setBlock(i + 5, j + 9, k + 14, Dungeons.purpleBrick);
        world.setBlock(i + 5, j + 9, k + 15, Dungeons.purpleBrick);
        world.setBlock(i + 5, j + 9, k + 19, Dungeons.purpleBrick);
        world.setBlock(i + 5, j + 9, k + 20, Dungeons.purpleBrick);
        world.setBlock(i + 5, j + 9, k + 21, Dungeons.purpleBrick);
        world.setBlock(i + 5, j + 9, k + 22, Dungeons.purpleBrick);
        world.setBlock(i + 5, j + 9, k + 23, Dungeons.purpleBrick);
        world.setBlock(i + 5, j + 9, k + 24, Dungeons.purpleBrick);
        world.setBlock(i + 5, j + 9, k + 25, Dungeons.purpleBrick);
        world.setBlock(i + 5, j + 10, k + 13, Dungeons.purpleBrick);
        world.setBlock(i + 5, j + 10, k + 14, Dungeons.purpleBrick);
        world.setBlock(i + 5, j + 10, k + 15, Dungeons.purpleBrick);
        world.setBlock(i + 5, j + 10, k + 21, Dungeons.purpleBrick);
        world.setBlock(i + 5, j + 10, k + 22, Dungeons.purpleBrick);
        world.setBlock(i + 5, j + 10, k + 23, Dungeons.purpleBrick);
        world.setBlock(i + 5, j + 10, k + 24, Dungeons.purpleBrick);
        world.setBlock(i + 5, j + 10, k + 25, Dungeons.purpleBrick);
        world.setBlock(i + 5, j + 11, k + 13, Dungeons.purpleBrick);
        world.setBlock(i + 5, j + 11, k + 14, Dungeons.purpleBrick);
        world.setBlock(i + 5, j + 11, k + 15, Dungeons.purpleBrick);
        world.setBlock(i + 5, j + 11, k + 22, Dungeons.purpleBrick);
        world.setBlock(i + 5, j + 11, k + 23, Dungeons.purpleBrick);
        world.setBlock(i + 5, j + 11, k + 24, Dungeons.purpleBrick);
        world.setBlock(i + 5, j + 11, k + 25, Dungeons.purpleBrick);
        world.setBlock(i + 5, j + 12, k + 13, Dungeons.purpleBrick);
        world.setBlock(i + 5, j + 12, k + 14, Dungeons.purpleBrick);
        world.setBlock(i + 5, j + 12, k + 15, Dungeons.purpleBrick);
        world.setBlock(i + 5, j + 12, k + 23, Dungeons.purpleBrick);
        world.setBlock(i + 5, j + 12, k + 24, Dungeons.purpleBrick);
        world.setBlock(i + 5, j + 12, k + 25, Dungeons.purpleBrick);
        world.setBlock(i + 6, j + 0, k + 0, Dungeons.purpleBrick);
        world.setBlock(i + 6, j + 0, k + 1, Dungeons.purpleBrick);
        world.setBlock(i + 6, j + 0, k + 2, Dungeons.purpleBrick);
        world.setBlock(i + 6, j + 0, k + 3, Dungeons.purpleBrick);
        world.setBlock(i + 6, j + 0, k + 4, Dungeons.purpleBrick);
        world.setBlock(i + 6, j + 0, k + 5, Dungeons.purpleBrick);
        world.setBlock(i + 6, j + 0, k + 6, Dungeons.purpleBrick);
        world.setBlock(i + 6, j + 0, k + 7, Dungeons.purpleBrick);
        world.setBlock(i + 6, j + 0, k + 8, Dungeons.purpleBrick);
        world.setBlock(i + 6, j + 0, k + 9, Dungeons.purpleBrick);
        world.setBlock(i + 6, j + 0, k + 10, Dungeons.purpleBrick);
        world.setBlock(i + 6, j + 0, k + 11, Dungeons.purpleBrick);
        world.setBlock(i + 6, j + 0, k + 12, Dungeons.purpleBrick);
        world.setBlock(i + 6, j + 0, k + 13, Dungeons.purpleBrick);
        world.setBlock(i + 6, j + 0, k + 14, Dungeons.purpleBrick);
        world.setBlock(i + 6, j + 0, k + 15, Dungeons.purpleBrick);
        world.setBlock(i + 6, j + 0, k + 16, Dungeons.purpleBrick);
        world.setBlock(i + 6, j + 0, k + 17, Dungeons.purpleBrick);
        world.setBlock(i + 6, j + 0, k + 18, Dungeons.purpleBrick);
        world.setBlock(i + 6, j + 0, k + 19, Dungeons.purpleBrick);
        world.setBlock(i + 6, j + 0, k + 20, Dungeons.purpleBrick);
        world.setBlock(i + 6, j + 0, k + 21, Dungeons.purpleBrick);
        world.setBlock(i + 6, j + 0, k + 22, Dungeons.purpleBrick);
        world.setBlock(i + 6, j + 0, k + 23, Dungeons.purpleBrick);
        world.setBlock(i + 6, j + 0, k + 24, Dungeons.purpleBrick);
        world.setBlock(i + 6, j + 0, k + 25, Dungeons.purpleBrick);
        world.setBlock(i + 6, j + 0, k + 26, Dungeons.purpleBrick);
        world.setBlock(i + 6, j + 0, k + 27, Dungeons.purpleBrick);
        world.setBlock(i + 6, j + 0, k + 28, Dungeons.purpleBrick);
        world.setBlock(i + 6, j + 0, k + 29, Dungeons.purpleBrick);
        world.setBlock(i + 6, j + 0, k + 30, Dungeons.purpleBrick);
        world.setBlock(i + 6, j + 0, k + 31, Dungeons.purpleBrick);
        world.setBlock(i + 6, j + 0, k + 32, Dungeons.purpleBrick);
        world.setBlock(i + 6, j + 0, k + 33, Dungeons.purpleBrick);
        world.setBlock(i + 6, j + 0, k + 34, Dungeons.purpleBrick);
        world.setBlock(i + 6, j + 0, k + 35, Dungeons.purpleBrick);
        world.setBlock(i + 6, j + 0, k + 36, Dungeons.purpleBrick);
        world.setBlock(i + 6, j + 0, k + 37, Dungeons.purpleBrick);
        world.setBlock(i + 6, j + 0, k + 38, Dungeons.purpleBrick);
        world.setBlock(i + 6, j + 1, k + 11, Dungeons.purpleBrick);
        world.setBlock(i + 6, j + 1, k + 12, Dungeons.purpleBrick);
        world.setBlock(i + 6, j + 1, k + 13, Dungeons.purpleBrick);
        world.setBlock(i + 6, j + 1, k + 14, Dungeons.purpleBrick);
        world.setBlock(i + 6, j + 1, k + 15, Dungeons.purpleBrick);
        world.setBlock(i + 6, j + 1, k + 16, Dungeons.purpleBrick);
        world.setBlock(i + 6, j + 1, k + 17, Dungeons.purpleBrick);
        world.setBlock(i + 6, j + 1, k + 18, Dungeons.purpleBrick);
        world.setBlock(i + 6, j + 1, k + 19, Dungeons.purpleBrick);
        world.setBlock(i + 6, j + 1, k + 20, Dungeons.purpleBrick);
        world.setBlock(i + 6, j + 1, k + 21, Dungeons.purpleBrick);
        world.setBlock(i + 6, j + 1, k + 22, Dungeons.purpleBrick);
        world.setBlock(i + 6, j + 1, k + 23, Dungeons.purpleBrick);
        world.setBlock(i + 6, j + 1, k + 24, Dungeons.purpleBrick);
        world.setBlock(i + 6, j + 1, k + 25, Dungeons.purpleBrick);
        world.setBlock(i + 6, j + 1, k + 26, Dungeons.purpleBrick);
        world.setBlock(i + 6, j + 1, k + 27, Dungeons.purpleBrick);
        world.setBlock(i + 6, j + 2, k + 11, Dungeons.purpleBrick);
        world.setBlock(i + 6, j + 2, k + 12, Dungeons.purpleBrick);
        world.setBlock(i + 6, j + 2, k + 13, Dungeons.purpleBrick);
        world.setBlock(i + 6, j + 2, k + 14, Dungeons.purpleBrick);
        world.setBlock(i + 6, j + 2, k + 15, Dungeons.purpleBrick);
        world.setBlock(i + 6, j + 2, k + 16, Dungeons.purpleBrick);
        world.setBlock(i + 6, j + 2, k + 17, Dungeons.purpleBrick);
        world.setBlock(i + 6, j + 2, k + 18, Dungeons.purpleBrick);
        world.setBlock(i + 6, j + 2, k + 19, Dungeons.purpleBrick);
        world.setBlock(i + 6, j + 2, k + 20, Dungeons.purpleBrick);
        world.setBlock(i + 6, j + 2, k + 21, Dungeons.purpleBrick);
        world.setBlock(i + 6, j + 2, k + 22, Dungeons.purpleBrick);
        world.setBlock(i + 6, j + 2, k + 23, Dungeons.purpleBrick);
        world.setBlock(i + 6, j + 2, k + 24, Dungeons.purpleBrick);
        world.setBlock(i + 6, j + 2, k + 25, Dungeons.purpleBrick);
        world.setBlock(i + 6, j + 2, k + 26, Dungeons.purpleBrick);
        world.setBlock(i + 6, j + 2, k + 27, Dungeons.purpleBrick);
        world.setBlock(i + 6, j + 3, k + 11, Dungeons.purpleBrick);
        world.setBlock(i + 6, j + 3, k + 12, Dungeons.purpleBrick);
        world.setBlock(i + 6, j + 3, k + 13, Dungeons.purpleBrick);
        world.setBlock(i + 6, j + 3, k + 14, Dungeons.purpleBrick);
        world.setBlock(i + 6, j + 3, k + 15, Dungeons.purpleBrick);
        world.setBlock(i + 6, j + 3, k + 16, Dungeons.purpleBrick);
        world.setBlock(i + 6, j + 3, k + 17, Dungeons.purpleBrick);
        world.setBlock(i + 6, j + 3, k + 18, Dungeons.purpleBrick);
        world.setBlock(i + 6, j + 3, k + 19, Dungeons.purpleBrick);
        world.setBlock(i + 6, j + 3, k + 20, Dungeons.purpleBrick);
        world.setBlock(i + 6, j + 3, k + 21, Dungeons.purpleBrick);
        world.setBlock(i + 6, j + 3, k + 22, Dungeons.purpleBrick);
        world.setBlock(i + 6, j + 3, k + 23, Dungeons.purpleBrick);
        world.setBlock(i + 6, j + 3, k + 24, Dungeons.purpleBrick);
        world.setBlock(i + 6, j + 3, k + 25, Dungeons.purpleBrick);
        world.setBlock(i + 6, j + 3, k + 26, Dungeons.purpleBrick);
        world.setBlock(i + 6, j + 3, k + 27, Dungeons.purpleBrick);
        world.setBlock(i + 6, j + 4, k + 11, Dungeons.purpleBrick);
        world.setBlock(i + 6, j + 4, k + 12, Dungeons.purpleBrick);
        world.setBlock(i + 6, j + 4, k + 13, Dungeons.purpleBrick);
        world.setBlock(i + 6, j + 4, k + 14, Dungeons.purpleBrick);
        world.setBlock(i + 6, j + 4, k + 15, Dungeons.purpleBrick);
        world.setBlock(i + 6, j + 4, k + 16, Dungeons.purpleBrick);
        world.setBlock(i + 6, j + 4, k + 17, Dungeons.purpleBrick);
        world.setBlock(i + 6, j + 4, k + 18, Dungeons.purpleBrick);
        world.setBlock(i + 6, j + 4, k + 19, Dungeons.purpleBrick);
        world.setBlock(i + 6, j + 4, k + 20, Dungeons.purpleBrick);
        world.setBlock(i + 6, j + 4, k + 21, Dungeons.purpleBrick);
        world.setBlock(i + 6, j + 4, k + 22, Dungeons.purpleBrick);
        world.setBlock(i + 6, j + 4, k + 23, Dungeons.purpleBrick);
        world.setBlock(i + 6, j + 4, k + 24, Dungeons.purpleBrick);
        world.setBlock(i + 6, j + 4, k + 25, Dungeons.purpleBrick);
        world.setBlock(i + 6, j + 4, k + 26, Dungeons.purpleBrick);
        world.setBlock(i + 6, j + 4, k + 27, Dungeons.purpleBrick);
        world.setBlock(i + 6, j + 5, k + 11, Dungeons.purpleBrick);
        world.setBlock(i + 6, j + 5, k + 12, Dungeons.purpleBrick);
        world.setBlock(i + 6, j + 5, k + 13, Dungeons.purpleBrick);
        world.setBlock(i + 6, j + 5, k + 14, Dungeons.purpleBrick);
        world.setBlock(i + 6, j + 5, k + 15, Dungeons.purpleBrick);
        world.setBlock(i + 6, j + 5, k + 16, Dungeons.purpleBrick);
        world.setBlock(i + 6, j + 5, k + 17, Dungeons.purpleBrick);
        world.setBlock(i + 6, j + 5, k + 18, Dungeons.purpleBrick);
        world.setBlock(i + 6, j + 5, k + 19, Dungeons.purpleBrick);
        world.setBlock(i + 6, j + 5, k + 20, Dungeons.purpleBrick);
        world.setBlock(i + 6, j + 5, k + 21, Dungeons.purpleBrick);
        world.setBlock(i + 6, j + 5, k + 22, Dungeons.purpleBrick);
        world.setBlock(i + 6, j + 5, k + 23, Dungeons.purpleBrick);
        world.setBlock(i + 6, j + 5, k + 24, Dungeons.purpleBrick);
        world.setBlock(i + 6, j + 5, k + 25, Dungeons.purpleBrick);
        world.setBlock(i + 6, j + 5, k + 26, Dungeons.purpleBrick);
        world.setBlock(i + 6, j + 5, k + 27, Dungeons.purpleBrick);
        world.setBlock(i + 6, j + 6, k + 11, Dungeons.purpleBrick);
        world.setBlock(i + 6, j + 6, k + 12, Dungeons.purpleBrick);
        world.setBlock(i + 6, j + 6, k + 13, Dungeons.purpleBrick);
        world.setBlock(i + 6, j + 6, k + 14, Dungeons.purpleBrick);
        world.setBlock(i + 6, j + 6, k + 15, Dungeons.purpleBrick);
        world.setBlock(i + 6, j + 6, k + 16, Dungeons.purpleBrick);
        world.setBlock(i + 6, j + 6, k + 17, Dungeons.purpleBrick);
        world.setBlock(i + 6, j + 6, k + 18, Dungeons.purpleBrick);
        world.setBlock(i + 6, j + 6, k + 19, Dungeons.purpleBrick);
        world.setBlock(i + 6, j + 6, k + 20, Dungeons.purpleBrick);
        world.setBlock(i + 6, j + 6, k + 21, Dungeons.purpleBrick);
        world.setBlock(i + 6, j + 6, k + 22, Dungeons.purpleBrick);
        world.setBlock(i + 6, j + 6, k + 23, Dungeons.purpleBrick);
        world.setBlock(i + 6, j + 6, k + 24, Dungeons.purpleBrick);
        world.setBlock(i + 6, j + 6, k + 25, Dungeons.purpleBrick);
        world.setBlock(i + 6, j + 6, k + 26, Dungeons.purpleBrick);
        world.setBlock(i + 6, j + 6, k + 27, Dungeons.purpleBrick);
        world.setBlock(i + 6, j + 7, k + 11, Dungeons.purpleBrick);
        world.setBlock(i + 6, j + 7, k + 12, Dungeons.purpleBrick);
        world.setBlock(i + 6, j + 7, k + 16, Dungeons.purpleBrick);
        world.setBlock(i + 6, j + 7, k + 17, Dungeons.purpleBrick);
        world.setBlock(i + 6, j + 7, k + 18, Dungeons.purpleBrick);
        world.setBlock(i + 6, j + 7, k + 19, Dungeons.purpleBrick);
        world.setBlock(i + 6, j + 7, k + 20, Dungeons.purpleBrick);
        world.setBlock(i + 6, j + 7, k + 21, Dungeons.purpleBrick);
        world.setBlock(i + 6, j + 7, k + 22, Dungeons.purpleBrick);
        world.setBlock(i + 6, j + 7, k + 23, Dungeons.purpleBrick);
        world.setBlock(i + 6, j + 7, k + 24, Dungeons.purpleBrick);
        world.setBlock(i + 6, j + 7, k + 25, Dungeons.purpleBrick);
        world.setBlock(i + 6, j + 7, k + 26, Dungeons.purpleBrick);
        world.setBlock(i + 6, j + 7, k + 27, Dungeons.purpleBrick);
        world.setBlock(i + 6, j + 8, k + 11, Dungeons.purpleBrick);
        world.setBlock(i + 6, j + 8, k + 12, Dungeons.purpleBrick);
        world.setBlock(i + 6, j + 8, k + 17, Dungeons.purpleBrick);
        world.setBlock(i + 6, j + 8, k + 18, Dungeons.purpleBrick);
        world.setBlock(i + 6, j + 8, k + 19, Dungeons.purpleBrick);
        world.setBlock(i + 6, j + 8, k + 20, Dungeons.purpleBrick);
        world.setBlock(i + 6, j + 8, k + 21, Dungeons.purpleBrick);
        world.setBlock(i + 6, j + 8, k + 22, Dungeons.purpleBrick);
        world.setBlock(i + 6, j + 8, k + 23, Dungeons.purpleBrick);
        world.setBlock(i + 6, j + 8, k + 24, Dungeons.purpleBrick);
        world.setBlock(i + 6, j + 8, k + 25, Dungeons.purpleBrick);
        world.setBlock(i + 6, j + 8, k + 26, Dungeons.purpleBrick);
        world.setBlock(i + 6, j + 8, k + 27, Dungeons.purpleBrick);
        world.setBlock(i + 6, j + 9, k + 11, Dungeons.purpleBrick);
        world.setBlock(i + 6, j + 9, k + 12, Dungeons.purpleBrick);
        world.setBlock(i + 6, j + 9, k + 19, Dungeons.purpleBrick);
        world.setBlock(i + 6, j + 9, k + 20, Dungeons.purpleBrick);
        world.setBlock(i + 6, j + 9, k + 21, Dungeons.purpleBrick);
        world.setBlock(i + 6, j + 9, k + 22, Dungeons.purpleBrick);
        world.setBlock(i + 6, j + 9, k + 23, Dungeons.purpleBrick);
        world.setBlock(i + 6, j + 9, k + 24, Dungeons.purpleBrick);
        world.setBlock(i + 6, j + 9, k + 25, Dungeons.purpleBrick);
        world.setBlock(i + 6, j + 9, k + 26, Dungeons.purpleBrick);
        world.setBlock(i + 6, j + 9, k + 27, Dungeons.purpleBrick);
        world.setBlock(i + 6, j + 10, k + 11, Dungeons.purpleBrick);
        world.setBlock(i + 6, j + 10, k + 12, Dungeons.purpleBrick);
        world.setBlock(i + 6, j + 10, k + 21, Dungeons.purpleBrick);
        world.setBlock(i + 6, j + 10, k + 22, Dungeons.purpleBrick);
        world.setBlock(i + 6, j + 10, k + 23, Dungeons.purpleBrick);
        world.setBlock(i + 6, j + 10, k + 24, Dungeons.purpleBrick);
        world.setBlock(i + 6, j + 10, k + 25, Dungeons.purpleBrick);
        world.setBlock(i + 6, j + 10, k + 26, Dungeons.purpleBrick);
        world.setBlock(i + 6, j + 10, k + 27, Dungeons.purpleBrick);
        world.setBlock(i + 6, j + 11, k + 11, Dungeons.purpleBrick);
        world.setBlock(i + 6, j + 11, k + 12, Dungeons.purpleBrick);
        world.setBlock(i + 6, j + 11, k + 22, Dungeons.purpleBrick);
        world.setBlock(i + 6, j + 11, k + 23, Dungeons.purpleBrick);
        world.setBlock(i + 6, j + 11, k + 24, Dungeons.purpleBrick);
        world.setBlock(i + 6, j + 11, k + 25, Dungeons.purpleBrick);
        world.setBlock(i + 6, j + 11, k + 26, Dungeons.purpleBrick);
        world.setBlock(i + 6, j + 11, k + 27, Dungeons.purpleBrick);
        world.setBlock(i + 6, j + 12, k + 11, Dungeons.purpleBrick);
        world.setBlock(i + 6, j + 12, k + 12, Dungeons.purpleBrick);
        world.setBlock(i + 6, j + 12, k + 26, Dungeons.purpleBrick);
        world.setBlock(i + 6, j + 12, k + 27, Dungeons.purpleBrick);
        world.setBlock(i + 7, j + 0, k + 0, Dungeons.purpleBrick);
        world.setBlock(i + 7, j + 0, k + 1, Dungeons.purpleBrick);
        world.setBlock(i + 7, j + 0, k + 2, Dungeons.purpleBrick);
        world.setBlock(i + 7, j + 0, k + 3, Dungeons.purpleBrick);
        world.setBlock(i + 7, j + 0, k + 4, Dungeons.purpleBrick);
        world.setBlock(i + 7, j + 0, k + 5, Dungeons.purpleBrick);
        world.setBlock(i + 7, j + 0, k + 6, Dungeons.purpleBrick);
        world.setBlock(i + 7, j + 0, k + 7, Dungeons.purpleBrick);
        world.setBlock(i + 7, j + 0, k + 8, Dungeons.purpleBrick);
        world.setBlock(i + 7, j + 0, k + 9, Dungeons.purpleBrick);
        world.setBlock(i + 7, j + 0, k + 10, Dungeons.purpleBrick);
        world.setBlock(i + 7, j + 0, k + 11, Dungeons.purpleBrick);
        world.setBlock(i + 7, j + 0, k + 12, Dungeons.purpleBrick);
        world.setBlock(i + 7, j + 0, k + 13, Dungeons.purpleBrick);
        world.setBlock(i + 7, j + 0, k + 14, Dungeons.purpleBrick);
        world.setBlock(i + 7, j + 0, k + 15, Dungeons.purpleBrick);
        world.setBlock(i + 7, j + 0, k + 16, Dungeons.purpleBrick);
        world.setBlock(i + 7, j + 0, k + 17, Dungeons.purpleBrick);
        world.setBlock(i + 7, j + 0, k + 18, Dungeons.purpleBrick);
        world.setBlock(i + 7, j + 0, k + 19, Dungeons.purpleBrick);
        world.setBlock(i + 7, j + 0, k + 20, Dungeons.purpleBrick);
        world.setBlock(i + 7, j + 0, k + 21, Dungeons.purpleBrick);
        world.setBlock(i + 7, j + 0, k + 22, Dungeons.purpleBrick);
        world.setBlock(i + 7, j + 0, k + 23, Dungeons.purpleBrick);
        world.setBlock(i + 7, j + 0, k + 24, Dungeons.purpleBrick);
        world.setBlock(i + 7, j + 0, k + 25, Dungeons.purpleBrick);
        world.setBlock(i + 7, j + 0, k + 26, Dungeons.purpleBrick);
        world.setBlock(i + 7, j + 0, k + 27, Dungeons.purpleBrick);
        world.setBlock(i + 7, j + 0, k + 28, Dungeons.purpleBrick);
        world.setBlock(i + 7, j + 0, k + 29, Dungeons.purpleBrick);
        world.setBlock(i + 7, j + 0, k + 30, Dungeons.purpleBrick);
        world.setBlock(i + 7, j + 0, k + 31, Dungeons.purpleBrick);
        world.setBlock(i + 7, j + 0, k + 32, Dungeons.purpleBrick);
        world.setBlock(i + 7, j + 0, k + 33, Dungeons.purpleBrick);
        world.setBlock(i + 7, j + 0, k + 34, Dungeons.purpleBrick);
        world.setBlock(i + 7, j + 0, k + 35, Dungeons.purpleBrick);
        world.setBlock(i + 7, j + 0, k + 36, Dungeons.purpleBrick);
        world.setBlock(i + 7, j + 0, k + 37, Dungeons.purpleBrick);
        world.setBlock(i + 7, j + 0, k + 38, Dungeons.purpleBrick);
        world.setBlock(i + 7, j + 1, k + 10, Dungeons.purpleBrick);
        world.setBlock(i + 7, j + 1, k + 11, Dungeons.purpleBrick);
        world.setBlock(i + 7, j + 1, k + 12, Dungeons.purpleBrick);
        world.setBlock(i + 7, j + 1, k + 13, Dungeons.purpleBrick);
        world.setBlock(i + 7, j + 1, k + 14, Dungeons.purpleBrick);
        world.setBlock(i + 7, j + 1, k + 15, Dungeons.purpleBrick);
        world.setBlock(i + 7, j + 1, k + 16, Dungeons.purpleBrick);
        world.setBlock(i + 7, j + 1, k + 17, Dungeons.purpleBrick);
        world.setBlock(i + 7, j + 1, k + 18, Dungeons.purpleBrick);
        world.setBlock(i + 7, j + 1, k + 19, Dungeons.purpleBrick);
        world.setBlock(i + 7, j + 1, k + 20, Dungeons.purpleBrick);
        world.setBlock(i + 7, j + 1, k + 21, Dungeons.purpleBrick);
        world.setBlock(i + 7, j + 1, k + 22, Dungeons.purpleBrick);
        world.setBlock(i + 7, j + 1, k + 23, Dungeons.purpleBrick);
        world.setBlock(i + 7, j + 1, k + 24, Dungeons.purpleBrick);
        world.setBlock(i + 7, j + 1, k + 25, Dungeons.purpleBrick);
        world.setBlock(i + 7, j + 1, k + 26, Dungeons.purpleBrick);
        world.setBlock(i + 7, j + 1, k + 27, Dungeons.purpleBrick);
        world.setBlock(i + 7, j + 1, k + 28, Dungeons.purpleBrick);
        world.setBlock(i + 7, j + 2, k + 10, Dungeons.purpleBrick);
        world.setBlock(i + 7, j + 2, k + 11, Dungeons.purpleBrick);
        world.setBlock(i + 7, j + 2, k + 12, Dungeons.purpleBrick);
        world.setBlock(i + 7, j + 2, k + 13, Dungeons.purpleBrick);
        world.setBlock(i + 7, j + 2, k + 14, Dungeons.purpleBrick);
        world.setBlock(i + 7, j + 2, k + 15, Dungeons.purpleBrick);
        world.setBlock(i + 7, j + 2, k + 16, Dungeons.purpleBrick);
        world.setBlock(i + 7, j + 2, k + 17, Dungeons.purpleBrick);
        world.setBlock(i + 7, j + 2, k + 18, Dungeons.purpleBrick);
        world.setBlock(i + 7, j + 2, k + 19, Dungeons.purpleBrick);
        world.setBlock(i + 7, j + 2, k + 20, Dungeons.purpleBrick);
        world.setBlock(i + 7, j + 2, k + 21, Dungeons.purpleBrick);
        world.setBlock(i + 7, j + 2, k + 22, Dungeons.purpleBrick);
        world.setBlock(i + 7, j + 2, k + 23, Dungeons.purpleBrick);
        world.setBlock(i + 7, j + 2, k + 24, Dungeons.purpleBrick);
        world.setBlock(i + 7, j + 2, k + 25, Dungeons.purpleBrick);
        world.setBlock(i + 7, j + 2, k + 26, Dungeons.purpleBrick);
        world.setBlock(i + 7, j + 2, k + 27, Dungeons.purpleBrick);
        world.setBlock(i + 7, j + 2, k + 28, Dungeons.purpleBrick);
        world.setBlock(i + 7, j + 3, k + 10, Dungeons.purpleBrick);
        world.setBlock(i + 7, j + 3, k + 11, Dungeons.purpleBrick);
        world.setBlock(i + 7, j + 3, k + 12, Dungeons.purpleBrick);
        world.setBlock(i + 7, j + 3, k + 13, Dungeons.purpleBrick);
        world.setBlock(i + 7, j + 3, k + 14, Dungeons.purpleBrick);
        world.setBlock(i + 7, j + 3, k + 15, Dungeons.purpleBrick);
        world.setBlock(i + 7, j + 3, k + 16, Dungeons.purpleBrick);
        world.setBlock(i + 7, j + 3, k + 17, Dungeons.purpleBrick);
        world.setBlock(i + 7, j + 3, k + 18, Dungeons.purpleBrick);
        world.setBlock(i + 7, j + 3, k + 19, Dungeons.purpleBrick);
        world.setBlock(i + 7, j + 3, k + 20, Dungeons.purpleBrick);
        world.setBlock(i + 7, j + 3, k + 21, Dungeons.purpleBrick);
        world.setBlock(i + 7, j + 3, k + 22, Dungeons.purpleBrick);
        world.setBlock(i + 7, j + 3, k + 23, Dungeons.purpleBrick);
        world.setBlock(i + 7, j + 3, k + 24, Dungeons.purpleBrick);
        world.setBlock(i + 7, j + 3, k + 25, Dungeons.purpleBrick);
        world.setBlock(i + 7, j + 3, k + 26, Dungeons.purpleBrick);
        world.setBlock(i + 7, j + 3, k + 27, Dungeons.purpleBrick);
        world.setBlock(i + 7, j + 3, k + 28, Dungeons.purpleBrick);
        world.setBlock(i + 7, j + 4, k + 10, Dungeons.purpleBrick);
        world.setBlock(i + 7, j + 4, k + 11, Dungeons.purpleBrick);
        world.setBlock(i + 7, j + 4, k + 12, Dungeons.purpleBrick);
        world.setBlock(i + 7, j + 4, k + 13, Dungeons.purpleBrick);
        world.setBlock(i + 7, j + 4, k + 14, Dungeons.purpleBrick);
        world.setBlock(i + 7, j + 4, k + 15, Dungeons.purpleBrick);
        world.setBlock(i + 7, j + 4, k + 16, Dungeons.purpleBrick);
        world.setBlock(i + 7, j + 4, k + 17, Dungeons.purpleBrick);
        world.setBlock(i + 7, j + 4, k + 18, Dungeons.purpleBrick);
        world.setBlock(i + 7, j + 4, k + 19, Dungeons.purpleBrick);
        world.setBlock(i + 7, j + 4, k + 20, Dungeons.purpleBrick);
        world.setBlock(i + 7, j + 4, k + 21, Dungeons.purpleBrick);
        world.setBlock(i + 7, j + 4, k + 22, Dungeons.purpleBrick);
        world.setBlock(i + 7, j + 4, k + 23, Dungeons.purpleBrick);
        world.setBlock(i + 7, j + 4, k + 24, Dungeons.purpleBrick);
        world.setBlock(i + 7, j + 4, k + 25, Dungeons.purpleBrick);
        world.setBlock(i + 7, j + 4, k + 26, Dungeons.purpleBrick);
        world.setBlock(i + 7, j + 4, k + 27, Dungeons.purpleBrick);
        world.setBlock(i + 7, j + 4, k + 28, Dungeons.purpleBrick);
        world.setBlock(i + 7, j + 5, k + 10, Dungeons.purpleBrick);
        world.setBlock(i + 7, j + 5, k + 11, Dungeons.purpleBrick);
        world.setBlock(i + 7, j + 5, k + 12, Dungeons.purpleBrick);
        world.setBlock(i + 7, j + 5, k + 13, Dungeons.purpleBrick);
        world.setBlock(i + 7, j + 5, k + 14, Dungeons.purpleBrick);
        world.setBlock(i + 7, j + 5, k + 15, Dungeons.purpleBrick);
        world.setBlock(i + 7, j + 5, k + 16, Dungeons.purpleBrick);
        world.setBlock(i + 7, j + 5, k + 17, Dungeons.purpleBrick);
        world.setBlock(i + 7, j + 5, k + 18, Dungeons.purpleBrick);
        world.setBlock(i + 7, j + 5, k + 19, Dungeons.purpleBrick);
        world.setBlock(i + 7, j + 5, k + 20, Dungeons.purpleBrick);
        world.setBlock(i + 7, j + 5, k + 21, Dungeons.purpleBrick);
        world.setBlock(i + 7, j + 5, k + 22, Dungeons.purpleBrick);
        world.setBlock(i + 7, j + 5, k + 23, Dungeons.purpleBrick);
        world.setBlock(i + 7, j + 5, k + 24, Dungeons.purpleBrick);
        world.setBlock(i + 7, j + 5, k + 25, Dungeons.purpleBrick);
        world.setBlock(i + 7, j + 5, k + 26, Dungeons.purpleBrick);
        world.setBlock(i + 7, j + 5, k + 27, Dungeons.purpleBrick);
        world.setBlock(i + 7, j + 5, k + 28, Dungeons.purpleBrick);
        world.setBlock(i + 7, j + 6, k + 10, Dungeons.purpleBrick);
        world.setBlock(i + 7, j + 6, k + 14, Dungeons.purpleBrick);
        world.setBlock(i + 7, j + 6, k + 15, Dungeons.purpleBrick);
        world.setBlock(i + 7, j + 6, k + 16, Dungeons.purpleBrick);
        world.setBlock(i + 7, j + 6, k + 17, Dungeons.purpleBrick);
        world.setBlock(i + 7, j + 6, k + 18, Dungeons.purpleBrick);
        world.setBlock(i + 7, j + 6, k + 19, Dungeons.purpleBrick);
        world.setBlock(i + 7, j + 6, k + 20, Dungeons.purpleBrick);
        world.setBlock(i + 7, j + 6, k + 21, Dungeons.purpleBrick);
        world.setBlock(i + 7, j + 6, k + 22, Dungeons.purpleBrick);
        world.setBlock(i + 7, j + 6, k + 23, Dungeons.purpleBrick);
        world.setBlock(i + 7, j + 6, k + 24, Dungeons.purpleBrick);
        world.setBlock(i + 7, j + 6, k + 25, Dungeons.purpleBrick);
        world.setBlock(i + 7, j + 6, k + 26, Dungeons.purpleBrick);
        world.setBlock(i + 7, j + 6, k + 27, Dungeons.purpleBrick);
        world.setBlock(i + 7, j + 6, k + 28, Dungeons.purpleBrick);
        world.setBlock(i + 7, j + 7, k + 10, Dungeons.purpleBrick);
        world.setBlock(i + 7, j + 7, k + 16, Dungeons.purpleBrick);
        world.setBlock(i + 7, j + 7, k + 17, Dungeons.purpleBrick);
        world.setBlock(i + 7, j + 7, k + 18, Dungeons.purpleBrick);
        world.setBlock(i + 7, j + 7, k + 19, Dungeons.purpleBrick);
        world.setBlock(i + 7, j + 7, k + 20, Dungeons.purpleBrick);
        world.setBlock(i + 7, j + 7, k + 21, Dungeons.purpleBrick);
        world.setBlock(i + 7, j + 7, k + 22, Dungeons.purpleBrick);
        world.setBlock(i + 7, j + 7, k + 23, Dungeons.purpleBrick);
        world.setBlock(i + 7, j + 7, k + 24, Dungeons.purpleBrick);
        world.setBlock(i + 7, j + 7, k + 25, Dungeons.purpleBrick);
        world.setBlock(i + 7, j + 7, k + 26, Dungeons.purpleBrick);
        world.setBlock(i + 7, j + 7, k + 27, Dungeons.purpleBrick);
        world.setBlock(i + 7, j + 7, k + 28, Dungeons.purpleBrick);
        world.setBlock(i + 7, j + 8, k + 10, Dungeons.purpleBrick);
        world.setBlock(i + 7, j + 8, k + 17, Dungeons.purpleBrick);
        world.setBlock(i + 7, j + 8, k + 18, Dungeons.purpleBrick);
        world.setBlock(i + 7, j + 8, k + 19, Dungeons.purpleBrick);
        world.setBlock(i + 7, j + 8, k + 20, Dungeons.purpleBrick);
        world.setBlock(i + 7, j + 8, k + 21, Dungeons.purpleBrick);
        world.setBlock(i + 7, j + 8, k + 22, Dungeons.purpleBrick);
        world.setBlock(i + 7, j + 8, k + 23, Dungeons.purpleBrick);
        world.setBlock(i + 7, j + 8, k + 24, Dungeons.purpleBrick);
        world.setBlock(i + 7, j + 8, k + 25, Dungeons.purpleBrick);
        world.setBlock(i + 7, j + 8, k + 26, Dungeons.purpleBrick);
        world.setBlock(i + 7, j + 8, k + 27, Dungeons.purpleBrick);
        world.setBlock(i + 7, j + 8, k + 28, Dungeons.purpleBrick);
        world.setBlock(i + 7, j + 9, k + 10, Dungeons.purpleBrick);
        world.setBlock(i + 7, j + 9, k + 19, Dungeons.purpleBrick);
        world.setBlock(i + 7, j + 9, k + 20, Dungeons.purpleBrick);
        world.setBlock(i + 7, j + 9, k + 21, Dungeons.purpleBrick);
        world.setBlock(i + 7, j + 9, k + 22, Dungeons.purpleBrick);
        world.setBlock(i + 7, j + 9, k + 23, Dungeons.purpleBrick);
        world.setBlock(i + 7, j + 9, k + 24, Dungeons.purpleBrick);
        world.setBlock(i + 7, j + 9, k + 25, Dungeons.purpleBrick);
        world.setBlock(i + 7, j + 9, k + 26, Dungeons.purpleBrick);
        world.setBlock(i + 7, j + 9, k + 27, Dungeons.purpleBrick);
        world.setBlock(i + 7, j + 9, k + 28, Dungeons.purpleBrick);
        world.setBlock(i + 7, j + 10, k + 10, Dungeons.purpleBrick);
        world.setBlock(i + 7, j + 10, k + 21, Dungeons.purpleBrick);
        world.setBlock(i + 7, j + 10, k + 22, Dungeons.purpleBrick);
        world.setBlock(i + 7, j + 10, k + 23, Dungeons.purpleBrick);
        world.setBlock(i + 7, j + 10, k + 24, Dungeons.purpleBrick);
        world.setBlock(i + 7, j + 10, k + 25, Dungeons.purpleBrick);
        world.setBlock(i + 7, j + 10, k + 26, Dungeons.purpleBrick);
        world.setBlock(i + 7, j + 10, k + 27, Dungeons.purpleBrick);
        world.setBlock(i + 7, j + 10, k + 28, Dungeons.purpleBrick);
        world.setBlock(i + 7, j + 11, k + 10, Dungeons.purpleBrick);
        world.setBlock(i + 7, j + 11, k + 22, Dungeons.purpleBrick);
        world.setBlock(i + 7, j + 11, k + 23, Dungeons.purpleBrick);
        world.setBlock(i + 7, j + 11, k + 24, Dungeons.purpleBrick);
        world.setBlock(i + 7, j + 11, k + 25, Dungeons.purpleBrick);
        world.setBlock(i + 7, j + 11, k + 26, Dungeons.purpleBrick);
        world.setBlock(i + 7, j + 11, k + 27, Dungeons.purpleBrick);
        world.setBlock(i + 7, j + 11, k + 28, Dungeons.purpleBrick);
        world.setBlock(i + 7, j + 12, k + 28, Dungeons.purpleBrick);
        world.setBlock(i + 8, j + 0, k + 0, Dungeons.purpleBrick);
        world.setBlock(i + 8, j + 0, k + 1, Dungeons.purpleBrick);
        world.setBlock(i + 8, j + 0, k + 2, Dungeons.purpleBrick);
        world.setBlock(i + 8, j + 0, k + 3, Dungeons.purpleBrick);
        world.setBlock(i + 8, j + 0, k + 4, Dungeons.purpleBrick);
        world.setBlock(i + 8, j + 0, k + 5, Dungeons.purpleBrick);
        world.setBlock(i + 8, j + 0, k + 6, Dungeons.purpleBrick);
        world.setBlock(i + 8, j + 0, k + 7, Dungeons.purpleBrick);
        world.setBlock(i + 8, j + 0, k + 8, Dungeons.purpleBrick);
        world.setBlock(i + 8, j + 0, k + 9, Dungeons.purpleBrick);
        world.setBlock(i + 8, j + 0, k + 10, Dungeons.purpleBrick);
        world.setBlock(i + 8, j + 0, k + 11, Dungeons.purpleBrick);
        world.setBlock(i + 8, j + 0, k + 12, Dungeons.purpleBrick);
        world.setBlock(i + 8, j + 0, k + 13, Dungeons.purpleBrick);
        world.setBlock(i + 8, j + 0, k + 14, Dungeons.purpleBrick);
        world.setBlock(i + 8, j + 0, k + 15, Dungeons.purpleBrick);
        world.setBlock(i + 8, j + 0, k + 16, Dungeons.purpleBrick);
        world.setBlock(i + 8, j + 0, k + 17, Dungeons.purpleBrick);
        world.setBlock(i + 8, j + 0, k + 18, Dungeons.purpleBrick);
        world.setBlock(i + 8, j + 0, k + 19, Dungeons.purpleBrick);
        world.setBlock(i + 8, j + 0, k + 20, Dungeons.purpleBrick);
        world.setBlock(i + 8, j + 0, k + 21, Dungeons.purpleBrick);
        world.setBlock(i + 8, j + 0, k + 22, Dungeons.purpleBrick);
        world.setBlock(i + 8, j + 0, k + 23, Dungeons.purpleBrick);
        world.setBlock(i + 8, j + 0, k + 24, Dungeons.purpleBrick);
        world.setBlock(i + 8, j + 0, k + 25, Dungeons.purpleBrick);
        world.setBlock(i + 8, j + 0, k + 26, Dungeons.purpleBrick);
        world.setBlock(i + 8, j + 0, k + 27, Dungeons.purpleBrick);
        world.setBlock(i + 8, j + 0, k + 28, Dungeons.purpleBrick);
        world.setBlock(i + 8, j + 0, k + 29, Dungeons.purpleBrick);
        world.setBlock(i + 8, j + 0, k + 30, Dungeons.purpleBrick);
        world.setBlock(i + 8, j + 0, k + 31, Dungeons.purpleBrick);
        world.setBlock(i + 8, j + 0, k + 32, Dungeons.purpleBrick);
        world.setBlock(i + 8, j + 0, k + 33, Dungeons.purpleBrick);
        world.setBlock(i + 8, j + 0, k + 34, Dungeons.purpleBrick);
        world.setBlock(i + 8, j + 0, k + 35, Dungeons.purpleBrick);
        world.setBlock(i + 8, j + 0, k + 36, Dungeons.purpleBrick);
        world.setBlock(i + 8, j + 0, k + 37, Dungeons.purpleBrick);
        world.setBlock(i + 8, j + 0, k + 38, Dungeons.purpleBrick);
        world.setBlock(i + 8, j + 1, k + 9, Dungeons.purpleBrick);
        world.setBlock(i + 8, j + 1, k + 10, Dungeons.purpleBrick);
        world.setBlock(i + 8, j + 1, k + 11, Dungeons.purpleBrick);
        world.setBlock(i + 8, j + 1, k + 12, Dungeons.purpleBrick);
        world.setBlock(i + 8, j + 1, k + 13, Dungeons.purpleBrick);
        world.setBlock(i + 8, j + 1, k + 14, Dungeons.purpleBrick);
        world.setBlock(i + 8, j + 1, k + 15, Dungeons.purpleBrick);
        world.setBlock(i + 8, j + 1, k + 16, Dungeons.purpleBrick);
        world.setBlock(i + 8, j + 1, k + 17, Dungeons.purpleBrick);
        world.setBlock(i + 8, j + 1, k + 18, Dungeons.purpleBrick);
        world.setBlock(i + 8, j + 1, k + 19, Dungeons.purpleBrick);
        world.setBlock(i + 8, j + 1, k + 20, Dungeons.purpleBrick);
        world.setBlock(i + 8, j + 1, k + 21, Dungeons.purpleBrick);
        world.setBlock(i + 8, j + 1, k + 22, Dungeons.purpleBrick);
        world.setBlock(i + 8, j + 1, k + 23, Dungeons.purpleBrick);
        world.setBlock(i + 8, j + 1, k + 24, Dungeons.purpleBrick);
        world.setBlock(i + 8, j + 1, k + 25, Dungeons.purpleBrick);
        world.setBlock(i + 8, j + 1, k + 26, Dungeons.purpleBrick);
        world.setBlock(i + 8, j + 1, k + 27, Dungeons.purpleBrick);
        world.setBlock(i + 8, j + 1, k + 28, Dungeons.purpleBrick);
        world.setBlock(i + 8, j + 1, k + 29, Dungeons.purpleBrick);
        world.setBlock(i + 8, j + 2, k + 9, Dungeons.purpleBrick);
        world.setBlock(i + 8, j + 2, k + 10, Dungeons.purpleBrick);
        world.setBlock(i + 8, j + 2, k + 11, Dungeons.purpleBrick);
        world.setBlock(i + 8, j + 2, k + 12, Dungeons.purpleBrick);
        world.setBlock(i + 8, j + 2, k + 13, Dungeons.purpleBrick);
        world.setBlock(i + 8, j + 2, k + 14, Dungeons.purpleBrick);
        world.setBlock(i + 8, j + 2, k + 15, Dungeons.purpleBrick);
        world.setBlock(i + 8, j + 2, k + 16, Dungeons.purpleBrick);
        world.setBlock(i + 8, j + 2, k + 17, Dungeons.purpleBrick);
        world.setBlock(i + 8, j + 2, k + 18, Dungeons.purpleBrick);
        world.setBlock(i + 8, j + 2, k + 19, Dungeons.purpleBrick);
        world.setBlock(i + 8, j + 2, k + 20, Dungeons.purpleBrick);
        world.setBlock(i + 8, j + 2, k + 21, Dungeons.purpleBrick);
        world.setBlock(i + 8, j + 2, k + 22, Dungeons.purpleBrick);
        world.setBlock(i + 8, j + 2, k + 23, Dungeons.purpleBrick);
        world.setBlock(i + 8, j + 2, k + 24, Dungeons.purpleBrick);
        world.setBlock(i + 8, j + 2, k + 25, Dungeons.purpleBrick);
        world.setBlock(i + 8, j + 2, k + 26, Dungeons.purpleBrick);
        world.setBlock(i + 8, j + 2, k + 27, Dungeons.purpleBrick);
        world.setBlock(i + 8, j + 2, k + 28, Dungeons.purpleBrick);
        world.setBlock(i + 8, j + 2, k + 29, Dungeons.purpleBrick);
        world.setBlock(i + 8, j + 3, k + 9, Dungeons.purpleBrick);
        world.setBlock(i + 8, j + 3, k + 10, Dungeons.purpleBrick);
        world.setBlock(i + 8, j + 3, k + 11, Dungeons.purpleBrick);
        world.setBlock(i + 8, j + 3, k + 12, Dungeons.purpleBrick);
        world.setBlock(i + 8, j + 3, k + 13, Dungeons.purpleBrick);
        world.setBlock(i + 8, j + 3, k + 14, Dungeons.purpleBrick);
        world.setBlock(i + 8, j + 3, k + 15, Dungeons.purpleBrick);
        world.setBlock(i + 8, j + 3, k + 16, Dungeons.purpleBrick);
        world.setBlock(i + 8, j + 3, k + 17, Dungeons.purpleBrick);
        world.setBlock(i + 8, j + 3, k + 18, Dungeons.purpleBrick);
        world.setBlock(i + 8, j + 3, k + 19, Dungeons.purpleBrick);
        world.setBlock(i + 8, j + 3, k + 20, Dungeons.purpleBrick);
        world.setBlock(i + 8, j + 3, k + 21, Dungeons.purpleBrick);
        world.setBlock(i + 8, j + 3, k + 22, Dungeons.purpleBrick);
        world.setBlock(i + 8, j + 3, k + 23, Dungeons.purpleBrick);
        world.setBlock(i + 8, j + 3, k + 24, Dungeons.purpleBrick);
        world.setBlock(i + 8, j + 3, k + 25, Dungeons.purpleBrick);
        world.setBlock(i + 8, j + 3, k + 26, Dungeons.purpleBrick);
        world.setBlock(i + 8, j + 3, k + 27, Dungeons.purpleBrick);
        world.setBlock(i + 8, j + 3, k + 28, Dungeons.purpleBrick);
        world.setBlock(i + 8, j + 3, k + 29, Dungeons.purpleBrick);
        world.setBlock(i + 8, j + 4, k + 9, Dungeons.purpleBrick);
        world.setBlock(i + 8, j + 4, k + 10, Dungeons.purpleBrick);
        world.setBlock(i + 8, j + 4, k + 11, Dungeons.purpleBrick);
        world.setBlock(i + 8, j + 4, k + 12, Dungeons.purpleBrick);
        world.setBlock(i + 8, j + 4, k + 13, Dungeons.purpleBrick);
        world.setBlock(i + 8, j + 4, k + 14, Dungeons.purpleBrick);
        world.setBlock(i + 8, j + 4, k + 15, Dungeons.purpleBrick);
        world.setBlock(i + 8, j + 4, k + 16, Dungeons.purpleBrick);
        world.setBlock(i + 8, j + 4, k + 17, Dungeons.purpleBrick);
        world.setBlock(i + 8, j + 4, k + 18, Dungeons.purpleBrick);
        world.setBlock(i + 8, j + 4, k + 19, Dungeons.purpleBrick);
        world.setBlock(i + 8, j + 4, k + 20, Dungeons.purpleBrick);
        world.setBlock(i + 8, j + 4, k + 21, Dungeons.purpleBrick);
        world.setBlock(i + 8, j + 4, k + 22, Dungeons.purpleBrick);
        world.setBlock(i + 8, j + 4, k + 23, Dungeons.purpleBrick);
        world.setBlock(i + 8, j + 4, k + 24, Dungeons.purpleBrick);
        world.setBlock(i + 8, j + 4, k + 25, Dungeons.purpleBrick);
        world.setBlock(i + 8, j + 4, k + 26, Dungeons.purpleBrick);
        world.setBlock(i + 8, j + 4, k + 27, Dungeons.purpleBrick);
        world.setBlock(i + 8, j + 4, k + 28, Dungeons.purpleBrick);
        world.setBlock(i + 8, j + 4, k + 29, Dungeons.purpleBrick);
        world.setBlock(i + 8, j + 5, k + 9, Dungeons.purpleBrick);
        world.setBlock(i + 8, j + 5, k + 13, Dungeons.purpleBrick);
        world.setBlock(i + 8, j + 5, k + 14, Dungeons.purpleBrick);
        world.setBlock(i + 8, j + 5, k + 15, Dungeons.purpleBrick);
        world.setBlock(i + 8, j + 5, k + 16, Dungeons.purpleBrick);
        world.setBlock(i + 8, j + 5, k + 17, Dungeons.purpleBrick);
        world.setBlock(i + 8, j + 5, k + 18, Dungeons.purpleBrick);
        world.setBlock(i + 8, j + 5, k + 19, Dungeons.purpleBrick);
        world.setBlock(i + 8, j + 5, k + 20, Dungeons.purpleBrick);
        world.setBlock(i + 8, j + 5, k + 21, Dungeons.purpleBrick);
        world.setBlock(i + 8, j + 5, k + 22, Dungeons.purpleBrick);
        world.setBlock(i + 8, j + 5, k + 23, Dungeons.purpleBrick);
        world.setBlock(i + 8, j + 5, k + 24, Dungeons.purpleBrick);
        world.setBlock(i + 8, j + 5, k + 25, Dungeons.purpleBrick);
        world.setBlock(i + 8, j + 5, k + 26, Dungeons.purpleBrick);
        world.setBlock(i + 8, j + 5, k + 27, Dungeons.purpleBrick);
        world.setBlock(i + 8, j + 5, k + 28, Dungeons.purpleBrick);
        world.setBlock(i + 8, j + 5, k + 29, Dungeons.purpleBrick);
        world.setBlock(i + 8, j + 6, k + 9, Dungeons.purpleBrick);
        world.setBlock(i + 8, j + 6, k + 15, Dungeons.purpleBrick);
        world.setBlock(i + 8, j + 6, k + 16, Dungeons.purpleBrick);
        world.setBlock(i + 8, j + 6, k + 17, Dungeons.purpleBrick);
        world.setBlock(i + 8, j + 6, k + 18, Dungeons.purpleBrick);
        world.setBlock(i + 8, j + 6, k + 19, Dungeons.purpleBrick);
        world.setBlock(i + 8, j + 6, k + 20, Dungeons.purpleBrick);
        world.setBlock(i + 8, j + 6, k + 21, Dungeons.purpleBrick);
        world.setBlock(i + 8, j + 6, k + 22, Dungeons.purpleBrick);
        world.setBlock(i + 8, j + 6, k + 23, Dungeons.purpleBrick);
        world.setBlock(i + 8, j + 6, k + 24, Dungeons.purpleBrick);
        world.setBlock(i + 8, j + 6, k + 25, Dungeons.purpleBrick);
        world.setBlock(i + 8, j + 6, k + 26, Dungeons.purpleBrick);
        world.setBlock(i + 8, j + 6, k + 27, Dungeons.purpleBrick);
        world.setBlock(i + 8, j + 6, k + 28, Dungeons.purpleBrick);
        world.setBlock(i + 8, j + 6, k + 29, Dungeons.purpleBrick);
        world.setBlock(i + 8, j + 7, k + 9, Dungeons.purpleBrick);
        world.setBlock(i + 8, j + 7, k + 16, Dungeons.purpleBrick);
        world.setBlock(i + 8, j + 7, k + 17, Dungeons.purpleBrick);
        world.setBlock(i + 8, j + 7, k + 18, Dungeons.purpleBrick);
        world.setBlock(i + 8, j + 7, k + 19, Dungeons.purpleBrick);
        world.setBlock(i + 8, j + 7, k + 20, Dungeons.purpleBrick);
        world.setBlock(i + 8, j + 7, k + 21, Dungeons.purpleBrick);
        world.setBlock(i + 8, j + 7, k + 22, Dungeons.purpleBrick);
        world.setBlock(i + 8, j + 7, k + 23, Dungeons.purpleBrick);
        world.setBlock(i + 8, j + 7, k + 24, Dungeons.purpleBrick);
        world.setBlock(i + 8, j + 7, k + 25, Dungeons.purpleBrick);
        world.setBlock(i + 8, j + 7, k + 26, Dungeons.purpleBrick);
        world.setBlock(i + 8, j + 7, k + 27, Dungeons.purpleBrick);
        world.setBlock(i + 8, j + 7, k + 28, Dungeons.purpleBrick);
        world.setBlock(i + 8, j + 7, k + 29, Dungeons.purpleBrick);
        world.setBlock(i + 8, j + 8, k + 9, Dungeons.purpleBrick);
        world.setBlock(i + 8, j + 8, k + 17, Dungeons.purpleBrick);
        world.setBlock(i + 8, j + 8, k + 18, Dungeons.purpleBrick);
        world.setBlock(i + 8, j + 8, k + 19, Dungeons.purpleBrick);
        world.setBlock(i + 8, j + 8, k + 20, Dungeons.purpleBrick);
        world.setBlock(i + 8, j + 8, k + 21, Dungeons.purpleBrick);
        world.setBlock(i + 8, j + 8, k + 22, Dungeons.purpleBrick);
        world.setBlock(i + 8, j + 8, k + 23, Dungeons.purpleBrick);
        world.setBlock(i + 8, j + 8, k + 24, Dungeons.purpleBrick);
        world.setBlock(i + 8, j + 8, k + 25, Dungeons.purpleBrick);
        world.setBlock(i + 8, j + 8, k + 26, Dungeons.purpleBrick);
        world.setBlock(i + 8, j + 8, k + 27, Dungeons.purpleBrick);
        world.setBlock(i + 8, j + 8, k + 28, Dungeons.purpleBrick);
        world.setBlock(i + 8, j + 8, k + 29, Dungeons.purpleBrick);
        world.setBlock(i + 8, j + 9, k + 9, Dungeons.purpleBrick);
        world.setBlock(i + 8, j + 9, k + 19, Dungeons.purpleBrick);
        world.setBlock(i + 8, j + 9, k + 20, Dungeons.purpleBrick);
        world.setBlock(i + 8, j + 9, k + 21, Dungeons.purpleBrick);
        world.setBlock(i + 8, j + 9, k + 22, Dungeons.purpleBrick);
        world.setBlock(i + 8, j + 9, k + 23, Dungeons.purpleBrick);
        world.setBlock(i + 8, j + 9, k + 24, Dungeons.purpleBrick);
        world.setBlock(i + 8, j + 9, k + 25, Dungeons.purpleBrick);
        world.setBlock(i + 8, j + 9, k + 26, Dungeons.purpleBrick);
        world.setBlock(i + 8, j + 9, k + 27, Dungeons.purpleBrick);
        world.setBlock(i + 8, j + 9, k + 28, Dungeons.purpleBrick);
        world.setBlock(i + 8, j + 9, k + 29, Dungeons.purpleBrick);
        world.setBlock(i + 8, j + 10, k + 9, Dungeons.purpleBrick);
        world.setBlock(i + 8, j + 10, k + 21, Dungeons.purpleBrick);
        world.setBlock(i + 8, j + 10, k + 22, Dungeons.purpleBrick);
        world.setBlock(i + 8, j + 10, k + 23, Dungeons.purpleBrick);
        world.setBlock(i + 8, j + 10, k + 24, Dungeons.purpleBrick);
        world.setBlock(i + 8, j + 10, k + 25, Dungeons.purpleBrick);
        world.setBlock(i + 8, j + 10, k + 26, Dungeons.purpleBrick);
        world.setBlock(i + 8, j + 10, k + 27, Dungeons.purpleBrick);
        world.setBlock(i + 8, j + 10, k + 28, Dungeons.purpleBrick);
        world.setBlock(i + 8, j + 10, k + 29, Dungeons.purpleBrick);
        world.setBlock(i + 8, j + 11, k + 22, Dungeons.purpleBrick);
        world.setBlock(i + 8, j + 11, k + 23, Dungeons.purpleBrick);
        world.setBlock(i + 8, j + 11, k + 24, Dungeons.purpleBrick);
        world.setBlock(i + 8, j + 11, k + 25, Dungeons.purpleBrick);
        world.setBlock(i + 8, j + 11, k + 26, Dungeons.purpleBrick);
        world.setBlock(i + 8, j + 11, k + 27, Dungeons.purpleBrick);
        world.setBlock(i + 8, j + 11, k + 28, Dungeons.purpleBrick);
        world.setBlock(i + 8, j + 11, k + 29, Dungeons.purpleBrick);
        Dungeons.spawner(world, i + 8, j + 12, k + 25, 14, 2);
        world.setBlock(i + 8, j + 12, k + 29, Dungeons.purpleBrick);
        world.setBlock(i + 9, j + 0, k + 0, Dungeons.purpleBrick);
        world.setBlock(i + 9, j + 0, k + 1, Dungeons.purpleBrick);
        world.setBlock(i + 9, j + 0, k + 2, Dungeons.purpleBrick);
        world.setBlock(i + 9, j + 0, k + 3, Dungeons.purpleBrick);
        world.setBlock(i + 9, j + 0, k + 4, Dungeons.purpleBrick);
        world.setBlock(i + 9, j + 0, k + 5, Dungeons.purpleBrick);
        world.setBlock(i + 9, j + 0, k + 6, Dungeons.purpleBrick);
        world.setBlock(i + 9, j + 0, k + 7, Dungeons.purpleBrick);
        world.setBlock(i + 9, j + 0, k + 8, Dungeons.purpleBrick);
        world.setBlock(i + 9, j + 0, k + 9, Dungeons.purpleBrick);
        world.setBlock(i + 9, j + 0, k + 10, Dungeons.purpleBrick);
        world.setBlock(i + 9, j + 0, k + 11, Dungeons.purpleBrick);
        world.setBlock(i + 9, j + 0, k + 12, Dungeons.purpleBrick);
        world.setBlock(i + 9, j + 0, k + 13, Dungeons.purpleBrick);
        world.setBlock(i + 9, j + 0, k + 14, Dungeons.purpleBrick);
        world.setBlock(i + 9, j + 0, k + 15, Dungeons.purpleBrick);
        world.setBlock(i + 9, j + 0, k + 16, Dungeons.purpleBrick);
        world.setBlock(i + 9, j + 0, k + 17, Dungeons.purpleBrick);
        world.setBlock(i + 9, j + 0, k + 18, Dungeons.purpleBrick);
        world.setBlock(i + 9, j + 0, k + 19, Dungeons.purpleBrick);
        world.setBlock(i + 9, j + 0, k + 20, Dungeons.purpleBrick);
        world.setBlock(i + 9, j + 0, k + 21, Dungeons.purpleBrick);
        world.setBlock(i + 9, j + 0, k + 22, Dungeons.purpleBrick);
        world.setBlock(i + 9, j + 0, k + 23, Dungeons.purpleBrick);
        world.setBlock(i + 9, j + 0, k + 24, Dungeons.purpleBrick);
        world.setBlock(i + 9, j + 0, k + 25, Dungeons.purpleBrick);
        world.setBlock(i + 9, j + 0, k + 26, Dungeons.purpleBrick);
        world.setBlock(i + 9, j + 0, k + 27, Dungeons.purpleBrick);
        world.setBlock(i + 9, j + 0, k + 28, Dungeons.purpleBrick);
        world.setBlock(i + 9, j + 0, k + 29, Dungeons.purpleBrick);
        world.setBlock(i + 9, j + 0, k + 30, Dungeons.purpleBrick);
        world.setBlock(i + 9, j + 0, k + 31, Dungeons.purpleBrick);
        world.setBlock(i + 9, j + 0, k + 32, Dungeons.purpleBrick);
        world.setBlock(i + 9, j + 0, k + 33, Dungeons.purpleBrick);
        world.setBlock(i + 9, j + 0, k + 34, Dungeons.purpleBrick);
        world.setBlock(i + 9, j + 0, k + 35, Dungeons.purpleBrick);
        world.setBlock(i + 9, j + 0, k + 36, Dungeons.purpleBrick);
        world.setBlock(i + 9, j + 0, k + 37, Dungeons.purpleBrick);
        world.setBlock(i + 9, j + 0, k + 38, Dungeons.purpleBrick);
        world.setBlock(i + 9, j + 1, k + 8, Dungeons.purpleBrick);
        world.setBlock(i + 9, j + 1, k + 9, Dungeons.purpleBrick);
        world.setBlock(i + 9, j + 1, k + 10, Dungeons.purpleBrick);
        world.setBlock(i + 9, j + 1, k + 11, Dungeons.purpleBrick);
        world.setBlock(i + 9, j + 1, k + 12, Dungeons.purpleBrick);
        world.setBlock(i + 9, j + 1, k + 13, Dungeons.purpleBrick);
        world.setBlock(i + 9, j + 1, k + 14, Dungeons.purpleBrick);
        world.setBlock(i + 9, j + 1, k + 15, Dungeons.purpleBrick);
        world.setBlock(i + 9, j + 1, k + 16, Dungeons.purpleBrick);
        world.setBlock(i + 9, j + 1, k + 17, Dungeons.purpleBrick);
        world.setBlock(i + 9, j + 1, k + 18, Dungeons.purpleBrick);
        world.setBlock(i + 9, j + 1, k + 19, Dungeons.purpleBrick);
        world.setBlock(i + 9, j + 1, k + 20, Dungeons.purpleBrick);
        world.setBlock(i + 9, j + 1, k + 21, Dungeons.purpleBrick);
        world.setBlock(i + 9, j + 1, k + 22, Dungeons.purpleBrick);
        world.setBlock(i + 9, j + 1, k + 23, Dungeons.purpleBrick);
        world.setBlock(i + 9, j + 1, k + 24, Dungeons.purpleBrick);
        world.setBlock(i + 9, j + 1, k + 25, Dungeons.purpleBrick);
        world.setBlock(i + 9, j + 1, k + 26, Dungeons.purpleBrick);
        world.setBlock(i + 9, j + 1, k + 27, Dungeons.purpleBrick);
        world.setBlock(i + 9, j + 1, k + 28, Dungeons.purpleBrick);
        world.setBlock(i + 9, j + 1, k + 29, Dungeons.purpleBrick);
        world.setBlock(i + 9, j + 1, k + 30, Dungeons.purpleBrick);
        world.setBlock(i + 9, j + 2, k + 8, Dungeons.purpleBrick);
        world.setBlock(i + 9, j + 2, k + 9, Dungeons.purpleBrick);
        world.setBlock(i + 9, j + 2, k + 10, Dungeons.purpleBrick);
        world.setBlock(i + 9, j + 2, k + 11, Dungeons.purpleBrick);
        world.setBlock(i + 9, j + 2, k + 12, Dungeons.purpleBrick);
        world.setBlock(i + 9, j + 2, k + 13, Dungeons.purpleBrick);
        world.setBlock(i + 9, j + 2, k + 14, Dungeons.purpleBrick);
        world.setBlock(i + 9, j + 2, k + 15, Dungeons.purpleBrick);
        world.setBlock(i + 9, j + 2, k + 16, Dungeons.purpleBrick);
        world.setBlock(i + 9, j + 2, k + 17, Dungeons.purpleBrick);
        world.setBlock(i + 9, j + 2, k + 18, Dungeons.purpleBrick);
        world.setBlock(i + 9, j + 2, k + 19, Dungeons.purpleBrick);
        world.setBlock(i + 9, j + 2, k + 20, Dungeons.purpleBrick);
        world.setBlock(i + 9, j + 2, k + 21, Dungeons.purpleBrick);
        world.setBlock(i + 9, j + 2, k + 22, Dungeons.purpleBrick);
        world.setBlock(i + 9, j + 2, k + 23, Dungeons.purpleBrick);
        world.setBlock(i + 9, j + 2, k + 24, Dungeons.purpleBrick);
        world.setBlock(i + 9, j + 2, k + 25, Dungeons.purpleBrick);
        world.setBlock(i + 9, j + 2, k + 26, Dungeons.purpleBrick);
        world.setBlock(i + 9, j + 2, k + 27, Dungeons.purpleBrick);
        world.setBlock(i + 9, j + 2, k + 28, Dungeons.purpleBrick);
        world.setBlock(i + 9, j + 2, k + 29, Dungeons.purpleBrick);
        world.setBlock(i + 9, j + 2, k + 30, Dungeons.purpleBrick);
        world.setBlock(i + 9, j + 3, k + 8, Dungeons.purpleBrick);
        world.setBlock(i + 9, j + 3, k + 9, Dungeons.purpleBrick);
        world.setBlock(i + 9, j + 3, k + 10, Dungeons.purpleBrick);
        world.setBlock(i + 9, j + 3, k + 11, Dungeons.purpleBrick);
        world.setBlock(i + 9, j + 3, k + 12, Dungeons.purpleBrick);
        world.setBlock(i + 9, j + 3, k + 13, Dungeons.purpleBrick);
        world.setBlock(i + 9, j + 3, k + 14, Dungeons.purpleBrick);
        world.setBlock(i + 9, j + 3, k + 15, Dungeons.purpleBrick);
        world.setBlock(i + 9, j + 3, k + 16, Dungeons.purpleBrick);
        world.setBlock(i + 9, j + 3, k + 17, Dungeons.purpleBrick);
        world.setBlock(i + 9, j + 3, k + 18, Dungeons.purpleBrick);
        world.setBlock(i + 9, j + 3, k + 19, Dungeons.purpleBrick);
        world.setBlock(i + 9, j + 3, k + 20, Dungeons.purpleBrick);
        world.setBlock(i + 9, j + 3, k + 21, Dungeons.purpleBrick);
        world.setBlock(i + 9, j + 3, k + 22, Dungeons.purpleBrick);
        world.setBlock(i + 9, j + 3, k + 23, Dungeons.purpleBrick);
        world.setBlock(i + 9, j + 3, k + 24, Dungeons.purpleBrick);
        world.setBlock(i + 9, j + 3, k + 25, Dungeons.purpleBrick);
        world.setBlock(i + 9, j + 3, k + 26, Dungeons.purpleBrick);
        world.setBlock(i + 9, j + 3, k + 27, Dungeons.purpleBrick);
        world.setBlock(i + 9, j + 3, k + 28, Dungeons.purpleBrick);
        world.setBlock(i + 9, j + 3, k + 29, Dungeons.purpleBrick);
        world.setBlock(i + 9, j + 3, k + 30, Dungeons.purpleBrick);
        world.setBlock(i + 9, j + 4, k + 8, Dungeons.purpleBrick);
        world.setBlock(i + 9, j + 4, k + 9, Dungeons.purpleBrick);
        world.setBlock(i + 9, j + 4, k + 10, Dungeons.purpleBrick);
        world.setBlock(i + 9, j + 4, k + 11, Dungeons.purpleBrick);
        world.setBlock(i + 9, j + 4, k + 12, Dungeons.purpleBrick);
        world.setBlock(i + 9, j + 4, k + 13, Dungeons.purpleBrick);
        world.setBlock(i + 9, j + 4, k + 14, Dungeons.purpleBrick);
        world.setBlock(i + 9, j + 4, k + 15, Dungeons.purpleBrick);
        world.setBlock(i + 9, j + 4, k + 16, Dungeons.purpleBrick);
        world.setBlock(i + 9, j + 4, k + 17, Dungeons.purpleBrick);
        world.setBlock(i + 9, j + 4, k + 18, Dungeons.purpleBrick);
        world.setBlock(i + 9, j + 4, k + 19, Dungeons.purpleBrick);
        world.setBlock(i + 9, j + 4, k + 20, Dungeons.purpleBrick);
        world.setBlock(i + 9, j + 4, k + 21, Dungeons.purpleBrick);
        world.setBlock(i + 9, j + 4, k + 22, Dungeons.purpleBrick);
        world.setBlock(i + 9, j + 4, k + 23, Dungeons.purpleBrick);
        world.setBlock(i + 9, j + 4, k + 24, Dungeons.purpleBrick);
        world.setBlock(i + 9, j + 4, k + 25, Dungeons.purpleBrick);
        world.setBlock(i + 9, j + 4, k + 26, Dungeons.purpleBrick);
        world.setBlock(i + 9, j + 4, k + 27, Dungeons.purpleBrick);
        world.setBlock(i + 9, j + 4, k + 28, Dungeons.purpleBrick);
        world.setBlock(i + 9, j + 4, k + 29, Dungeons.purpleBrick);
        world.setBlock(i + 9, j + 4, k + 30, Dungeons.purpleBrick);
        world.setBlock(i + 9, j + 5, k + 8, Dungeons.purpleBrick);
        world.setBlock(i + 9, j + 5, k + 14, Dungeons.purpleBrick);
        world.setBlock(i + 9, j + 5, k + 15, Dungeons.purpleBrick);
        world.setBlock(i + 9, j + 5, k + 16, Dungeons.purpleBrick);
        world.setBlock(i + 9, j + 5, k + 17, Dungeons.purpleBrick);
        world.setBlock(i + 9, j + 5, k + 18, Dungeons.purpleBrick);
        world.setBlock(i + 9, j + 5, k + 19, Dungeons.purpleBrick);
        world.setBlock(i + 9, j + 5, k + 20, Dungeons.purpleBrick);
        world.setBlock(i + 9, j + 5, k + 21, Dungeons.purpleBrick);
        world.setBlock(i + 9, j + 5, k + 22, Dungeons.purpleBrick);
        world.setBlock(i + 9, j + 5, k + 23, Dungeons.purpleBrick);
        world.setBlock(i + 9, j + 5, k + 24, Dungeons.purpleBrick);
        world.setBlock(i + 9, j + 5, k + 25, Dungeons.purpleBrick);
        world.setBlock(i + 9, j + 5, k + 26, Dungeons.purpleBrick);
        world.setBlock(i + 9, j + 5, k + 27, Dungeons.purpleBrick);
        world.setBlock(i + 9, j + 5, k + 28, Dungeons.purpleBrick);
        world.setBlock(i + 9, j + 5, k + 29, Dungeons.purpleBrick);
        world.setBlock(i + 9, j + 5, k + 30, Dungeons.purpleBrick);
        world.setBlock(i + 9, j + 6, k + 8, Dungeons.purpleBrick);
        world.setBlock(i + 9, j + 6, k + 15, Dungeons.purpleBrick);
        world.setBlock(i + 9, j + 6, k + 16, Dungeons.purpleBrick);
        world.setBlock(i + 9, j + 6, k + 17, Dungeons.purpleBrick);
        world.setBlock(i + 9, j + 6, k + 18, Dungeons.purpleBrick);
        world.setBlock(i + 9, j + 6, k + 19, Dungeons.purpleBrick);
        world.setBlock(i + 9, j + 6, k + 20, Dungeons.purpleBrick);
        world.setBlock(i + 9, j + 6, k + 21, Dungeons.purpleBrick);
        world.setBlock(i + 9, j + 6, k + 22, Dungeons.purpleBrick);
        world.setBlock(i + 9, j + 6, k + 23, Dungeons.purpleBrick);
        world.setBlock(i + 9, j + 6, k + 24, Dungeons.purpleBrick);
        world.setBlock(i + 9, j + 6, k + 25, Dungeons.purpleBrick);
        world.setBlock(i + 9, j + 6, k + 26, Dungeons.purpleBrick);
        world.setBlock(i + 9, j + 6, k + 27, Dungeons.purpleBrick);
        world.setBlock(i + 9, j + 6, k + 28, Dungeons.purpleBrick);
        world.setBlock(i + 9, j + 6, k + 29, Dungeons.purpleBrick);
        world.setBlock(i + 9, j + 6, k + 30, Dungeons.purpleBrick);
        world.setBlock(i + 9, j + 7, k + 8, Dungeons.purpleBrick);
        world.setBlock(i + 9, j + 7, k + 16, Dungeons.purpleBrick);
        world.setBlock(i + 9, j + 7, k + 17, Dungeons.purpleBrick);
        world.setBlock(i + 9, j + 7, k + 18, Dungeons.purpleBrick);
        world.setBlock(i + 9, j + 7, k + 19, Dungeons.purpleBrick);
        world.setBlock(i + 9, j + 7, k + 20, Dungeons.purpleBrick);
        world.setBlock(i + 9, j + 7, k + 21, Dungeons.purpleBrick);
        world.setBlock(i + 9, j + 7, k + 22, Dungeons.purpleBrick);
        world.setBlock(i + 9, j + 7, k + 23, Dungeons.purpleBrick);
        world.setBlock(i + 9, j + 7, k + 24, Dungeons.purpleBrick);
        world.setBlock(i + 9, j + 7, k + 25, Dungeons.purpleBrick);
        world.setBlock(i + 9, j + 7, k + 26, Dungeons.purpleBrick);
        world.setBlock(i + 9, j + 7, k + 27, Dungeons.purpleBrick);
        world.setBlock(i + 9, j + 7, k + 28, Dungeons.purpleBrick);
        world.setBlock(i + 9, j + 7, k + 29, Dungeons.purpleBrick);
        world.setBlock(i + 9, j + 7, k + 30, Dungeons.purpleBrick);
        world.setBlock(i + 9, j + 8, k + 8, Dungeons.purpleBrick);
        world.setBlock(i + 9, j + 8, k + 16, Dungeons.purpleBrick);
        world.setBlock(i + 9, j + 8, k + 17, Dungeons.purpleBrick);
        world.setBlock(i + 9, j + 8, k + 18, Dungeons.purpleBrick);
        world.setBlock(i + 9, j + 8, k + 19, Dungeons.purpleBrick);
        world.setBlock(i + 9, j + 8, k + 20, Dungeons.purpleBrick);
        world.setBlock(i + 9, j + 8, k + 21, Dungeons.purpleBrick);
        world.setBlock(i + 9, j + 8, k + 22, Dungeons.purpleBrick);
        world.setBlock(i + 9, j + 8, k + 23, Dungeons.purpleBrick);
        world.setBlock(i + 9, j + 8, k + 24, Dungeons.purpleBrick);
        world.setBlock(i + 9, j + 8, k + 25, Dungeons.purpleBrick);
        world.setBlock(i + 9, j + 8, k + 26, Dungeons.purpleBrick);
        world.setBlock(i + 9, j + 8, k + 27, Dungeons.purpleBrick);
        world.setBlock(i + 9, j + 8, k + 28, Dungeons.purpleBrick);
        world.setBlock(i + 9, j + 8, k + 29, Dungeons.purpleBrick);
        world.setBlock(i + 9, j + 8, k + 30, Dungeons.purpleBrick);
        world.setBlock(i + 9, j + 9, k + 8, Dungeons.purpleBrick);
        world.setBlock(i + 9, j + 9, k + 16, Dungeons.purpleBrick);
        world.setBlock(i + 9, j + 9, k + 17, Dungeons.purpleBrick);
        world.setBlock(i + 9, j + 9, k + 18, Dungeons.purpleBrick);
        world.setBlock(i + 9, j + 9, k + 19, Dungeons.purpleBrick);
        world.setBlock(i + 9, j + 9, k + 20, Dungeons.purpleBrick);
        world.setBlock(i + 9, j + 9, k + 21, Dungeons.purpleBrick);
        world.setBlock(i + 9, j + 9, k + 22, Dungeons.purpleBrick);
        world.setBlock(i + 9, j + 9, k + 23, Dungeons.purpleBrick);
        world.setBlock(i + 9, j + 9, k + 24, Dungeons.purpleBrick);
        world.setBlock(i + 9, j + 9, k + 25, Dungeons.purpleBrick);
        world.setBlock(i + 9, j + 9, k + 26, Dungeons.purpleBrick);
        world.setBlock(i + 9, j + 9, k + 27, Dungeons.purpleBrick);
        world.setBlock(i + 9, j + 9, k + 28, Dungeons.purpleBrick);
        world.setBlock(i + 9, j + 9, k + 29, Dungeons.purpleBrick);
        world.setBlock(i + 9, j + 9, k + 30, Dungeons.purpleBrick);
        world.setBlock(i + 9, j + 10, k + 16, Dungeons.purpleBrick);
        world.setBlock(i + 9, j + 10, k + 17, Dungeons.purpleBrick);
        world.setBlock(i + 9, j + 10, k + 18, Dungeons.purpleBrick);
        world.setBlock(i + 9, j + 10, k + 19, Dungeons.purpleBrick);
        world.setBlock(i + 9, j + 10, k + 20, Dungeons.purpleBrick);
        world.setBlock(i + 9, j + 10, k + 21, Dungeons.purpleBrick);
        world.setBlock(i + 9, j + 10, k + 22, Dungeons.purpleBrick);
        world.setBlock(i + 9, j + 10, k + 23, Dungeons.purpleBrick);
        world.setBlock(i + 9, j + 10, k + 24, Dungeons.purpleBrick);
        world.setBlock(i + 9, j + 10, k + 25, Dungeons.purpleBrick);
        world.setBlock(i + 9, j + 10, k + 26, Dungeons.purpleBrick);
        world.setBlock(i + 9, j + 10, k + 27, Dungeons.purpleBrick);
        world.setBlock(i + 9, j + 10, k + 28, Dungeons.purpleBrick);
        world.setBlock(i + 9, j + 10, k + 29, Dungeons.purpleBrick);
        world.setBlock(i + 9, j + 10, k + 30, Dungeons.purpleBrick);
        world.setBlock(i + 9, j + 11, k + 16, Dungeons.purpleBrick);
        world.setBlock(i + 9, j + 11, k + 17, Dungeons.purpleBrick);
        world.setBlock(i + 9, j + 11, k + 18, Dungeons.purpleBrick);
        world.setBlock(i + 9, j + 11, k + 19, Dungeons.purpleBrick);
        world.setBlock(i + 9, j + 11, k + 20, Dungeons.purpleBrick);
        world.setBlock(i + 9, j + 11, k + 21, Dungeons.purpleBrick);
        world.setBlock(i + 9, j + 11, k + 22, Dungeons.purpleBrick);
        world.setBlock(i + 9, j + 11, k + 23, Dungeons.purpleBrick);
        world.setBlock(i + 9, j + 11, k + 24, Dungeons.purpleBrick);
        world.setBlock(i + 9, j + 11, k + 25, Dungeons.purpleBrick);
        world.setBlock(i + 9, j + 11, k + 26, Dungeons.purpleBrick);
        world.setBlock(i + 9, j + 11, k + 27, Dungeons.purpleBrick);
        world.setBlock(i + 9, j + 11, k + 28, Dungeons.purpleBrick);
        world.setBlock(i + 9, j + 11, k + 29, Dungeons.purpleBrick);
        world.setBlock(i + 9, j + 11, k + 30, Dungeons.purpleBrick);
        world.setBlock(i + 9, j + 12, k + 16, Dungeons.purpleBrick);
        world.setBlock(i + 9, j + 12, k + 17, Dungeons.purpleBrick);
        world.setBlock(i + 9, j + 12, k + 18, Dungeons.purpleBrick);
        world.setBlock(i + 9, j + 12, k + 19, Dungeons.purpleBrick);
        world.setBlock(i + 9, j + 12, k + 20, Dungeons.purpleBrick);
        world.setBlock(i + 9, j + 12, k + 21, Dungeons.purpleBrick);
        world.setBlock(i + 9, j + 12, k + 22, Dungeons.purpleBrick);
        world.setBlock(i + 9, j + 12, k + 30, Dungeons.purpleBrick);
        world.setBlock(i + 9, j + 13, k + 16, Dungeons.purpleBrick);
        world.setBlock(i + 9, j + 13, k + 17, Dungeons.purpleBrick);
        world.setBlock(i + 9, j + 13, k + 18, Dungeons.purpleBrick);
        world.setBlock(i + 9, j + 13, k + 19, Dungeons.purpleBrick);
        world.setBlock(i + 9, j + 13, k + 20, Dungeons.purpleBrick);
        world.setBlock(i + 9, j + 13, k + 21, Dungeons.purpleBrick);
        world.setBlock(i + 9, j + 13, k + 22, Dungeons.purpleBrick);
        world.setBlock(i + 9, j + 14, k + 16, Dungeons.purpleBrick);
        world.setBlock(i + 9, j + 14, k + 17, Dungeons.purpleBrick);
        world.setBlock(i + 9, j + 14, k + 18, Dungeons.purpleBrick);
        world.setBlock(i + 9, j + 14, k + 19, Dungeons.purpleBrick);
        world.setBlock(i + 9, j + 14, k + 20, Dungeons.purpleBrick);
        world.setBlock(i + 9, j + 14, k + 21, Dungeons.purpleBrick);
        world.setBlock(i + 9, j + 14, k + 22, Dungeons.purpleBrick);
        world.setBlock(i + 9, j + 15, k + 16, Dungeons.purpleBrick);
        world.setBlock(i + 9, j + 15, k + 17, Dungeons.purpleBrick);
        world.setBlock(i + 9, j + 15, k + 18, Dungeons.purpleBrick);
        world.setBlock(i + 9, j + 15, k + 19, Dungeons.purpleBrick);
        world.setBlock(i + 9, j + 15, k + 20, Dungeons.purpleBrick);
        world.setBlock(i + 9, j + 15, k + 21, Dungeons.purpleBrick);
        world.setBlock(i + 9, j + 15, k + 22, Dungeons.purpleBrick);
        world.setBlock(i + 9, j + 16, k + 16, Dungeons.purpleBrick);
        world.setBlock(i + 9, j + 16, k + 17, Dungeons.purpleBrick);
        world.setBlock(i + 9, j + 16, k + 18, Dungeons.purpleBrick);
        world.setBlock(i + 9, j + 16, k + 19, Dungeons.purpleBrick);
        world.setBlock(i + 9, j + 16, k + 20, Dungeons.purpleBrick);
        world.setBlock(i + 9, j + 16, k + 21, Dungeons.purpleBrick);
        world.setBlock(i + 9, j + 16, k + 22, Dungeons.purpleBrick);
        world.setBlock(i + 9, j + 17, k + 16, Dungeons.purpleBrick);
        world.setBlock(i + 9, j + 17, k + 17, Dungeons.purpleBrick);
        world.setBlock(i + 9, j + 17, k + 18, Dungeons.purpleBrick);
        world.setBlock(i + 9, j + 17, k + 19, Dungeons.purpleBrick);
        world.setBlock(i + 9, j + 17, k + 20, Dungeons.purpleBrick);
        world.setBlock(i + 9, j + 17, k + 21, Dungeons.purpleBrick);
        world.setBlock(i + 9, j + 17, k + 22, Dungeons.purpleBrick);
        world.setBlock(i + 9, j + 18, k + 16, Dungeons.purpleBrick);
        world.setBlock(i + 9, j + 18, k + 17, Dungeons.purpleBrick);
        world.setBlock(i + 9, j + 18, k + 18, Dungeons.purpleBrick);
        world.setBlock(i + 9, j + 18, k + 19, Dungeons.purpleBrick);
        world.setBlock(i + 9, j + 18, k + 20, Dungeons.purpleBrick);
        world.setBlock(i + 9, j + 18, k + 21, Dungeons.purpleBrick);
        world.setBlock(i + 9, j + 18, k + 22, Dungeons.purpleBrick);
        world.setBlock(i + 9, j + 19, k + 16, Dungeons.purpleBrick);
        world.setBlock(i + 9, j + 19, k + 17, Dungeons.purpleBrick);
        world.setBlock(i + 9, j + 19, k + 18, Dungeons.purpleBrick);
        world.setBlock(i + 9, j + 19, k + 19, Dungeons.purpleBrick);
        world.setBlock(i + 9, j + 19, k + 20, Dungeons.purpleBrick);
        world.setBlock(i + 9, j + 19, k + 21, Dungeons.purpleBrick);
        world.setBlock(i + 9, j + 19, k + 22, Dungeons.purpleBrick);
        world.setBlock(i + 9, j + 20, k + 16, Dungeons.purpleBrick);
        world.setBlock(i + 9, j + 20, k + 17, Dungeons.purpleBrick);
        world.setBlock(i + 9, j + 20, k + 18, Dungeons.purpleBrick);
        world.setBlock(i + 9, j + 20, k + 19, Dungeons.purpleBrick);
        world.setBlock(i + 9, j + 20, k + 20, Dungeons.purpleBrick);
        world.setBlock(i + 9, j + 20, k + 21, Dungeons.purpleBrick);
        world.setBlock(i + 9, j + 20, k + 22, Dungeons.purpleBrick);
        world.setBlock(i + 9, j + 21, k + 16, Dungeons.purpleBrick);
        world.setBlock(i + 9, j + 21, k + 17, Dungeons.purpleBrick);
        world.setBlock(i + 9, j + 21, k + 18, Dungeons.purpleBrick);
        world.setBlock(i + 9, j + 21, k + 19, Dungeons.purpleBrick);
        world.setBlock(i + 9, j + 21, k + 20, Dungeons.purpleBrick);
        world.setBlock(i + 9, j + 21, k + 21, Dungeons.purpleBrick);
        world.setBlock(i + 9, j + 21, k + 22, Dungeons.purpleBrick);
        world.setBlock(i + 9, j + 22, k + 16, Dungeons.purpleBrick);
        world.setBlock(i + 9, j + 22, k + 17, Dungeons.purpleBrick);
        world.setBlock(i + 9, j + 22, k + 18, Dungeons.purpleBrick);
        world.setBlock(i + 9, j + 22, k + 19, Dungeons.purpleBrick);
        world.setBlock(i + 9, j + 22, k + 20, Dungeons.purpleBrick);
        world.setBlock(i + 9, j + 22, k + 21, Dungeons.purpleBrick);
        world.setBlock(i + 9, j + 22, k + 22, Dungeons.purpleBrick);
        world.setBlock(i + 10, j + 0, k + 0, Dungeons.purpleBrick);
        world.setBlock(i + 10, j + 0, k + 1, Dungeons.purpleBrick);
        world.setBlock(i + 10, j + 0, k + 2, Dungeons.purpleBrick);
        world.setBlock(i + 10, j + 0, k + 3, Dungeons.purpleBrick);
        world.setBlock(i + 10, j + 0, k + 4, Dungeons.purpleBrick);
        world.setBlock(i + 10, j + 0, k + 5, Dungeons.purpleBrick);
        world.setBlock(i + 10, j + 0, k + 6, Dungeons.purpleBrick);
        world.setBlock(i + 10, j + 0, k + 7, Dungeons.purpleBrick);
        world.setBlock(i + 10, j + 0, k + 8, Dungeons.purpleBrick);
        world.setBlock(i + 10, j + 0, k + 9, Dungeons.purpleBrick);
        world.setBlock(i + 10, j + 0, k + 10, Dungeons.purpleBrick);
        world.setBlock(i + 10, j + 0, k + 11, Dungeons.purpleBrick);
        world.setBlock(i + 10, j + 0, k + 12, Dungeons.purpleBrick);
        world.setBlock(i + 10, j + 0, k + 13, Dungeons.purpleBrick);
        world.setBlock(i + 10, j + 0, k + 14, Dungeons.purpleBrick);
        world.setBlock(i + 10, j + 0, k + 15, Dungeons.purpleBrick);
        world.setBlock(i + 10, j + 0, k + 16, Dungeons.purpleBrick);
        world.setBlock(i + 10, j + 0, k + 17, Dungeons.purpleBrick);
        world.setBlock(i + 10, j + 0, k + 18, Dungeons.purpleBrick);
        world.setBlock(i + 10, j + 0, k + 19, Dungeons.purpleBrick);
        world.setBlock(i + 10, j + 0, k + 20, Dungeons.purpleBrick);
        world.setBlock(i + 10, j + 0, k + 21, Dungeons.purpleBrick);
        world.setBlock(i + 10, j + 0, k + 22, Dungeons.purpleBrick);
        world.setBlock(i + 10, j + 0, k + 23, Dungeons.purpleBrick);
        world.setBlock(i + 10, j + 0, k + 24, Dungeons.purpleBrick);
        world.setBlock(i + 10, j + 0, k + 25, Dungeons.purpleBrick);
        world.setBlock(i + 10, j + 0, k + 26, Dungeons.purpleBrick);
        world.setBlock(i + 10, j + 0, k + 27, Dungeons.purpleBrick);
        world.setBlock(i + 10, j + 0, k + 28, Dungeons.purpleBrick);
        world.setBlock(i + 10, j + 0, k + 29, Dungeons.purpleBrick);
        world.setBlock(i + 10, j + 0, k + 30, Dungeons.purpleBrick);
        world.setBlock(i + 10, j + 0, k + 31, Dungeons.purpleBrick);
        world.setBlock(i + 10, j + 0, k + 32, Dungeons.purpleBrick);
        world.setBlock(i + 10, j + 0, k + 33, Dungeons.purpleBrick);
        world.setBlock(i + 10, j + 0, k + 34, Dungeons.purpleBrick);
        world.setBlock(i + 10, j + 0, k + 35, Dungeons.purpleBrick);
        world.setBlock(i + 10, j + 0, k + 36, Dungeons.purpleBrick);
        world.setBlock(i + 10, j + 0, k + 37, Dungeons.purpleBrick);
        world.setBlock(i + 10, j + 0, k + 38, Dungeons.purpleBrick);
        world.setBlock(i + 10, j + 1, k + 7, Dungeons.purpleBrick);
        world.setBlock(i + 10, j + 1, k + 8, Dungeons.purpleBrick);
        world.setBlock(i + 10, j + 1, k + 9, Dungeons.purpleBrick);
        world.setBlock(i + 10, j + 1, k + 10, Dungeons.purpleBrick);
        world.setBlock(i + 10, j + 1, k + 11, Dungeons.purpleBrick);
        world.setBlock(i + 10, j + 1, k + 12, Dungeons.purpleBrick);
        world.setBlock(i + 10, j + 1, k + 13, Dungeons.purpleBrick);
        world.setBlock(i + 10, j + 1, k + 14, Dungeons.purpleBrick);
        world.setBlock(i + 10, j + 1, k + 15, Dungeons.purpleBrick);
        world.setBlock(i + 10, j + 1, k + 16, Dungeons.purpleBrick);
        world.setBlock(i + 10, j + 1, k + 17, Dungeons.purpleBrick);
        world.setBlock(i + 10, j + 1, k + 18, Dungeons.purpleBrick);
        world.setBlock(i + 10, j + 1, k + 19, Dungeons.purpleBrick);
        world.setBlock(i + 10, j + 1, k + 20, Dungeons.purpleBrick);
        world.setBlock(i + 10, j + 1, k + 21, Dungeons.purpleBrick);
        world.setBlock(i + 10, j + 1, k + 22, Dungeons.purpleBrick);
        world.setBlock(i + 10, j + 1, k + 23, Dungeons.purpleBrick);
        world.setBlock(i + 10, j + 1, k + 24, Dungeons.purpleBrick);
        world.setBlock(i + 10, j + 1, k + 25, Dungeons.purpleBrick);
        world.setBlock(i + 10, j + 1, k + 26, Dungeons.purpleBrick);
