

package com.gibby.dungeon.gen;

import net.minecraft.world.gen.feature.*;
import net.minecraft.world.*;
import java.util.*;
import net.minecraft.init.*;
import com.gibby.dungeon.*;

public class WorldGenVampireCastle extends WorldGenerator
{
    public boolean generate(final World world, final Random rand, final int i, final int j, final int k) {
        world.setBlock(i + 4, j + 0, k + 4, Blocks.stonebrick);
        world.setBlock(i + 4, j + 0, k + 5, Blocks.stonebrick);
        world.setBlock(i + 4, j + 0, k + 6, Blocks.stonebrick);
        world.setBlock(i + 4, j + 0, k + 7, Blocks.stonebrick);
        world.setBlock(i + 4, j + 0, k + 10, Blocks.stonebrick);
        world.setBlock(i + 4, j + 0, k + 11, Blocks.stonebrick);
        world.setBlock(i + 4, j + 0, k + 12, Blocks.stonebrick);
        world.setBlock(i + 4, j + 0, k + 15, Blocks.stonebrick);
        world.setBlock(i + 4, j + 0, k + 16, Blocks.stonebrick);
        world.setBlock(i + 4, j + 0, k + 17, Blocks.stonebrick);
        world.setBlock(i + 4, j + 0, k + 18, Blocks.stonebrick);
        world.setBlock(i + 4, j + 1, k + 4, Blocks.stonebrick);
        world.setBlock(i + 4, j + 1, k + 5, Blocks.stonebrick);
        world.setBlock(i + 4, j + 1, k + 6, Blocks.stonebrick);
        world.setBlock(i + 4, j + 1, k + 7, Blocks.stonebrick);
        world.setBlock(i + 4, j + 1, k + 10, Blocks.stonebrick);
        world.setBlock(i + 4, j + 1, k + 11, Blocks.stonebrick);
        world.setBlock(i + 4, j + 1, k + 12, Blocks.stonebrick);
        world.setBlock(i + 4, j + 1, k + 15, Blocks.stonebrick);
        world.setBlock(i + 4, j + 1, k + 16, Blocks.stonebrick);
        world.setBlock(i + 4, j + 1, k + 17, Blocks.stonebrick);
        world.setBlock(i + 4, j + 1, k + 18, Blocks.stonebrick);
        world.setBlock(i + 4, j + 2, k + 4, Blocks.stonebrick);
        world.setBlock(i + 4, j + 2, k + 5, Blocks.stonebrick);
        world.setBlock(i + 4, j + 2, k + 6, Blocks.stonebrick);
        world.setBlock(i + 4, j + 2, k + 7, Blocks.stonebrick);
        world.setBlock(i + 4, j + 2, k + 10, Blocks.stonebrick);
        world.setBlock(i + 4, j + 2, k + 11, Blocks.stonebrick);
        world.setBlock(i + 4, j + 2, k + 12, Blocks.stonebrick);
        world.setBlock(i + 4, j + 2, k + 15, Blocks.stonebrick);
        world.setBlock(i + 4, j + 2, k + 16, Blocks.stonebrick);
        world.setBlock(i + 4, j + 2, k + 17, Blocks.stonebrick);
        world.setBlock(i + 4, j + 2, k + 18, Blocks.stonebrick);
        world.setBlock(i + 4, j + 3, k + 4, Blocks.nether_brick);
        world.setBlock(i + 4, j + 3, k + 5, Blocks.nether_brick);
        world.setBlock(i + 4, j + 3, k + 6, Blocks.nether_brick);
        world.setBlock(i + 4, j + 3, k + 7, Blocks.nether_brick);
        world.setBlock(i + 4, j + 3, k + 8, Blocks.stonebrick);
        world.setBlock(i + 4, j + 3, k + 9, Blocks.stonebrick);
        world.setBlock(i + 4, j + 3, k + 10, Blocks.nether_brick);
        world.setBlock(i + 4, j + 3, k + 11, Blocks.nether_brick);
        world.setBlock(i + 4, j + 3, k + 12, Blocks.nether_brick);
        world.setBlock(i + 4, j + 3, k + 13, Blocks.stonebrick);
        world.setBlock(i + 4, j + 3, k + 14, Blocks.stonebrick);
        world.setBlock(i + 4, j + 3, k + 15, Blocks.nether_brick);
        world.setBlock(i + 4, j + 3, k + 16, Blocks.nether_brick);
        world.setBlock(i + 4, j + 3, k + 17, Blocks.nether_brick);
        world.setBlock(i + 4, j + 3, k + 18, Blocks.nether_brick);
        world.setBlock(i + 4, j + 4, k + 4, Blocks.nether_brick);
        world.setBlock(i + 4, j + 4, k + 5, Blocks.glowstone);
        world.setBlock(i + 4, j + 4, k + 6, Blocks.nether_brick);
        world.setBlock(i + 4, j + 4, k + 7, Blocks.nether_brick);
        world.setBlock(i + 4, j + 4, k + 8, Blocks.nether_brick);
        world.setBlock(i + 4, j + 4, k + 9, Blocks.nether_brick);
        world.setBlock(i + 4, j + 4, k + 10, Blocks.nether_brick);
        world.setBlock(i + 4, j + 4, k + 11, Blocks.glowstone);
        world.setBlock(i + 4, j + 4, k + 12, Blocks.nether_brick);
        world.setBlock(i + 4, j + 4, k + 13, Blocks.nether_brick);
        world.setBlock(i + 4, j + 4, k + 14, Blocks.nether_brick);
        world.setBlock(i + 4, j + 4, k + 15, Blocks.nether_brick);
        world.setBlock(i + 4, j + 4, k + 16, Blocks.nether_brick);
        world.setBlock(i + 4, j + 4, k + 17, Blocks.glowstone);
        world.setBlock(i + 4, j + 4, k + 18, Blocks.nether_brick);
        world.setBlock(i + 4, j + 5, k + 4, Blocks.nether_brick);
        world.setBlock(i + 4, j + 5, k + 5, Blocks.nether_brick);
        world.setBlock(i + 4, j + 5, k + 6, Blocks.nether_brick);
        world.setBlock(i + 4, j + 5, k + 7, Blocks.nether_brick);
        world.setBlock(i + 4, j + 5, k + 8, Blocks.nether_brick);
        world.setBlock(i + 4, j + 5, k + 9, Blocks.nether_brick);
        world.setBlock(i + 4, j + 5, k + 10, Blocks.nether_brick);
        world.setBlock(i + 4, j + 5, k + 11, Blocks.nether_brick);
        world.setBlock(i + 4, j + 5, k + 12, Blocks.nether_brick);
        world.setBlock(i + 4, j + 5, k + 13, Blocks.nether_brick);
        world.setBlock(i + 4, j + 5, k + 14, Blocks.nether_brick);
        world.setBlock(i + 4, j + 5, k + 15, Blocks.nether_brick);
        world.setBlock(i + 4, j + 5, k + 16, Blocks.nether_brick);
        world.setBlock(i + 4, j + 5, k + 17, Blocks.nether_brick);
        world.setBlock(i + 4, j + 5, k + 18, Blocks.nether_brick);
        world.setBlock(i + 4, j + 6, k + 4, Blocks.nether_brick);
        world.setBlock(i + 4, j + 6, k + 5, Blocks.nether_brick);
        world.setBlock(i + 4, j + 6, k + 6, Blocks.nether_brick);
        world.setBlock(i + 4, j + 6, k + 7, Blocks.nether_brick);
        world.setBlock(i + 4, j + 6, k + 8, Blocks.nether_brick);
        world.setBlock(i + 4, j + 6, k + 9, Blocks.nether_brick);
        world.setBlock(i + 4, j + 6, k + 10, Blocks.nether_brick);
        world.setBlock(i + 4, j + 6, k + 11, Blocks.nether_brick);
        world.setBlock(i + 4, j + 6, k + 12, Blocks.nether_brick);
        world.setBlock(i + 4, j + 6, k + 13, Blocks.nether_brick);
        world.setBlock(i + 4, j + 6, k + 14, Blocks.nether_brick);
        world.setBlock(i + 4, j + 6, k + 15, Blocks.nether_brick);
        world.setBlock(i + 4, j + 6, k + 16, Blocks.nether_brick);
        world.setBlock(i + 4, j + 6, k + 17, Blocks.nether_brick);
        world.setBlock(i + 4, j + 6, k + 18, Blocks.nether_brick);
        world.setBlock(i + 4, j + 7, k + 4, Blocks.nether_brick);
        world.setBlock(i + 4, j + 7, k + 5, Blocks.nether_brick);
        world.setBlock(i + 4, j + 7, k + 6, Blocks.nether_brick);
        world.setBlock(i + 4, j + 7, k + 7, Blocks.nether_brick);
        world.setBlock(i + 4, j + 7, k + 8, Blocks.nether_brick);
        world.setBlock(i + 4, j + 7, k + 9, Blocks.nether_brick);
        world.setBlock(i + 4, j + 7, k + 10, Blocks.nether_brick);
        world.setBlock(i + 4, j + 7, k + 11, Blocks.nether_brick);
        world.setBlock(i + 4, j + 7, k + 12, Blocks.nether_brick);
        world.setBlock(i + 4, j + 7, k + 13, Blocks.nether_brick);
        world.setBlock(i + 4, j + 7, k + 14, Blocks.nether_brick);
        world.setBlock(i + 4, j + 7, k + 15, Blocks.nether_brick);
        world.setBlock(i + 4, j + 7, k + 16, Blocks.nether_brick);
        world.setBlock(i + 4, j + 7, k + 17, Blocks.nether_brick);
        world.setBlock(i + 4, j + 7, k + 18, Blocks.nether_brick);
        world.setBlock(i + 4, j + 8, k + 4, Blocks.nether_brick);
        world.setBlock(i + 4, j + 8, k + 5, Blocks.nether_brick);
        world.setBlock(i + 4, j + 8, k + 6, Blocks.nether_brick);
        world.setBlock(i + 4, j + 8, k + 7, Blocks.nether_brick);
        world.setBlock(i + 4, j + 8, k + 8, Blocks.nether_brick);
        world.setBlock(i + 4, j + 8, k + 9, Blocks.nether_brick);
        world.setBlock(i + 4, j + 8, k + 10, Blocks.nether_brick);
        world.setBlock(i + 4, j + 8, k + 11, Blocks.nether_brick);
        world.setBlock(i + 4, j + 8, k + 12, Blocks.nether_brick);
        world.setBlock(i + 4, j + 8, k + 13, Blocks.nether_brick);
        world.setBlock(i + 4, j + 8, k + 14, Blocks.nether_brick);
        world.setBlock(i + 4, j + 8, k + 15, Blocks.nether_brick);
        world.setBlock(i + 4, j + 8, k + 16, Blocks.nether_brick);
        world.setBlock(i + 4, j + 8, k + 17, Blocks.nether_brick);
        world.setBlock(i + 4, j + 8, k + 18, Blocks.nether_brick);
        world.setBlock(i + 4, j + 9, k + 4, Blocks.nether_brick);
        world.setBlock(i + 4, j + 9, k + 5, Blocks.nether_brick);
        world.setBlock(i + 4, j + 9, k + 6, Blocks.nether_brick);
        world.setBlock(i + 4, j + 9, k + 7, Blocks.nether_brick);
        world.setBlock(i + 4, j + 9, k + 8, Blocks.nether_brick);
        world.setBlock(i + 4, j + 9, k + 9, Blocks.nether_brick);
        world.setBlock(i + 4, j + 9, k + 10, Blocks.nether_brick);
        world.setBlock(i + 4, j + 9, k + 11, Blocks.nether_brick);
        world.setBlock(i + 4, j + 9, k + 12, Blocks.nether_brick);
        world.setBlock(i + 4, j + 9, k + 13, Blocks.nether_brick);
        world.setBlock(i + 4, j + 9, k + 14, Blocks.nether_brick);
        world.setBlock(i + 4, j + 9, k + 15, Blocks.nether_brick);
        world.setBlock(i + 4, j + 9, k + 16, Blocks.nether_brick);
        world.setBlock(i + 4, j + 9, k + 17, Blocks.nether_brick);
        world.setBlock(i + 4, j + 9, k + 18, Blocks.nether_brick);
        world.setBlock(i + 4, j + 10, k + 4, Blocks.nether_brick);
        world.setBlock(i + 4, j + 10, k + 5, Blocks.nether_brick);
        world.setBlock(i + 4, j + 10, k + 6, Blocks.nether_brick);
        world.setBlock(i + 4, j + 10, k + 7, Blocks.nether_brick);
        world.setBlock(i + 4, j + 10, k + 8, Blocks.nether_brick);
        world.setBlock(i + 4, j + 10, k + 9, Blocks.nether_brick);
        world.setBlock(i + 4, j + 10, k + 10, Blocks.nether_brick);
        world.setBlock(i + 4, j + 10, k + 11, Blocks.nether_brick);
        world.setBlock(i + 4, j + 10, k + 12, Blocks.nether_brick);
        world.setBlock(i + 4, j + 10, k + 13, Blocks.nether_brick);
        world.setBlock(i + 4, j + 10, k + 14, Blocks.nether_brick);
        world.setBlock(i + 4, j + 10, k + 15, Blocks.nether_brick);
        world.setBlock(i + 4, j + 10, k + 16, Blocks.nether_brick);
        world.setBlock(i + 4, j + 10, k + 17, Blocks.nether_brick);
        world.setBlock(i + 4, j + 10, k + 18, Blocks.nether_brick);
        world.setBlock(i + 4, j + 11, k + 4, Blocks.nether_brick);
        world.setBlock(i + 4, j + 11, k + 5, Blocks.nether_brick);
        world.setBlock(i + 4, j + 11, k + 6, Blocks.nether_brick);
        world.setBlock(i + 4, j + 11, k + 7, Blocks.nether_brick);
        world.setBlock(i + 4, j + 11, k + 8, Blocks.nether_brick);
        world.setBlock(i + 4, j + 11, k + 9, Blocks.nether_brick);
        world.setBlock(i + 4, j + 11, k + 10, Blocks.nether_brick);
        world.setBlock(i + 4, j + 11, k + 11, Blocks.nether_brick);
        world.setBlock(i + 4, j + 11, k + 12, Blocks.nether_brick);
        world.setBlock(i + 4, j + 11, k + 13, Blocks.nether_brick);
        world.setBlock(i + 4, j + 11, k + 14, Blocks.nether_brick);
        world.setBlock(i + 4, j + 11, k + 15, Blocks.nether_brick);
        world.setBlock(i + 4, j + 11, k + 16, Blocks.nether_brick);
        world.setBlock(i + 4, j + 11, k + 17, Blocks.nether_brick);
        world.setBlock(i + 4, j + 11, k + 18, Blocks.nether_brick);
        world.setBlock(i + 4, j + 12, k + 4, Blocks.nether_brick);
        world.setBlock(i + 4, j + 12, k + 5, Blocks.nether_brick);
        world.setBlock(i + 4, j + 12, k + 6, Blocks.nether_brick);
        world.setBlock(i + 4, j + 12, k + 7, Blocks.nether_brick);
        world.setBlock(i + 4, j + 12, k + 8, Blocks.nether_brick);
        world.setBlock(i + 4, j + 12, k + 9, Blocks.nether_brick);
        world.setBlock(i + 4, j + 12, k + 10, Blocks.nether_brick);
        world.setBlock(i + 4, j + 12, k + 11, Blocks.nether_brick);
        world.setBlock(i + 4, j + 12, k + 12, Blocks.nether_brick);
        world.setBlock(i + 4, j + 12, k + 13, Blocks.nether_brick);
        world.setBlock(i + 4, j + 12, k + 14, Blocks.nether_brick);
        world.setBlock(i + 4, j + 12, k + 15, Blocks.nether_brick);
        world.setBlock(i + 4, j + 12, k + 16, Blocks.nether_brick);
        world.setBlock(i + 4, j + 12, k + 17, Blocks.nether_brick);
        world.setBlock(i + 4, j + 12, k + 18, Blocks.nether_brick);
        world.setBlock(i + 4, j + 13, k + 4, Blocks.nether_brick);
        world.setBlock(i + 4, j + 13, k + 5, Blocks.nether_brick);
        world.setBlock(i + 4, j + 13, k + 6, Blocks.nether_brick);
        world.setBlock(i + 4, j + 13, k + 7, Blocks.nether_brick);
        world.setBlock(i + 4, j + 13, k + 8, Blocks.nether_brick);
        world.setBlock(i + 4, j + 13, k + 9, Blocks.nether_brick);
        world.setBlock(i + 4, j + 13, k + 10, Blocks.nether_brick);
        world.setBlock(i + 4, j + 13, k + 11, Blocks.nether_brick);
        world.setBlock(i + 4, j + 13, k + 12, Blocks.nether_brick);
        world.setBlock(i + 4, j + 13, k + 13, Blocks.nether_brick);
        world.setBlock(i + 4, j + 13, k + 14, Blocks.nether_brick);
        world.setBlock(i + 4, j + 13, k + 15, Blocks.nether_brick);
        world.setBlock(i + 4, j + 13, k + 16, Blocks.nether_brick);
        world.setBlock(i + 4, j + 13, k + 17, Blocks.nether_brick);
        world.setBlock(i + 4, j + 13, k + 18, Blocks.nether_brick);
        world.setBlock(i + 4, j + 14, k + 4, Blocks.nether_brick);
        world.setBlock(i + 4, j + 14, k + 5, Blocks.nether_brick);
        world.setBlock(i + 4, j + 14, k + 6, Blocks.nether_brick);
        world.setBlock(i + 4, j + 14, k + 7, Blocks.nether_brick);
        world.setBlock(i + 4, j + 14, k + 8, Blocks.nether_brick);
        world.setBlock(i + 4, j + 14, k + 9, Blocks.nether_brick);
        world.setBlock(i + 4, j + 14, k + 10, Blocks.nether_brick);
        world.setBlock(i + 4, j + 14, k + 11, Blocks.nether_brick);
        world.setBlock(i + 4, j + 14, k + 12, Blocks.nether_brick);
        world.setBlock(i + 4, j + 14, k + 13, Blocks.nether_brick);
        world.setBlock(i + 4, j + 14, k + 14, Blocks.nether_brick);
        world.setBlock(i + 4, j + 14, k + 15, Blocks.nether_brick);
        world.setBlock(i + 4, j + 14, k + 16, Blocks.nether_brick);
        world.setBlock(i + 4, j + 14, k + 17, Blocks.nether_brick);
        world.setBlock(i + 4, j + 14, k + 18, Blocks.nether_brick);
        world.setBlock(i + 4, j + 15, k + 4, Blocks.nether_brick);
        world.setBlock(i + 4, j + 15, k + 5, Blocks.nether_brick);
        world.setBlock(i + 4, j + 15, k + 6, Blocks.nether_brick);
        world.setBlock(i + 4, j + 15, k + 7, Blocks.nether_brick);
        world.setBlock(i + 4, j + 15, k + 8, Blocks.nether_brick);
        world.setBlock(i + 4, j + 15, k + 9, Blocks.nether_brick);
        world.setBlock(i + 4, j + 15, k + 10, Blocks.nether_brick);
        world.setBlock(i + 4, j + 15, k + 11, Blocks.nether_brick);
        world.setBlock(i + 4, j + 15, k + 12, Blocks.nether_brick);
        world.setBlock(i + 4, j + 15, k + 13, Blocks.nether_brick);
        world.setBlock(i + 4, j + 15, k + 14, Blocks.nether_brick);
        world.setBlock(i + 4, j + 15, k + 15, Blocks.nether_brick);
        world.setBlock(i + 4, j + 15, k + 16, Blocks.nether_brick);
        world.setBlock(i + 4, j + 15, k + 17, Blocks.nether_brick);
        world.setBlock(i + 4, j + 15, k + 18, Blocks.nether_brick);
        world.setBlock(i + 4, j + 16, k + 4, Blocks.nether_brick);
        world.setBlock(i + 4, j + 16, k + 5, Blocks.nether_brick);
        world.setBlock(i + 4, j + 16, k + 6, Blocks.nether_brick);
        world.setBlock(i + 4, j + 16, k + 7, Blocks.nether_brick);
        world.setBlock(i + 4, j + 16, k + 8, Blocks.nether_brick);
        world.setBlock(i + 4, j + 16, k + 9, Blocks.nether_brick);
        world.setBlock(i + 4, j + 16, k + 10, Blocks.nether_brick);
        world.setBlock(i + 4, j + 16, k + 11, Blocks.nether_brick);
        world.setBlock(i + 4, j + 16, k + 12, Blocks.nether_brick);
        world.setBlock(i + 4, j + 16, k + 13, Blocks.nether_brick);
        world.setBlock(i + 4, j + 16, k + 14, Blocks.nether_brick);
        world.setBlock(i + 4, j + 16, k + 15, Blocks.nether_brick);
        world.setBlock(i + 4, j + 16, k + 16, Blocks.nether_brick);
        world.setBlock(i + 4, j + 16, k + 17, Blocks.nether_brick);
        world.setBlock(i + 4, j + 16, k + 18, Blocks.nether_brick);
        world.setBlock(i + 4, j + 17, k + 4, Blocks.nether_brick_stairs, 1, 0);
        world.setBlock(i + 4, j + 17, k + 5, Blocks.nether_brick);
        world.setBlock(i + 4, j + 17, k + 6, Blocks.nether_brick);
        world.setBlock(i + 4, j + 17, k + 7, Blocks.nether_brick);
        world.setBlock(i + 4, j + 17, k + 8, Blocks.nether_brick);
        world.setBlock(i + 4, j + 17, k + 9, Blocks.nether_brick);
        world.setBlock(i + 4, j + 17, k + 10, Blocks.nether_brick);
        world.setBlock(i + 4, j + 17, k + 11, Blocks.nether_brick);
        world.setBlock(i + 4, j + 17, k + 12, Blocks.nether_brick);
        world.setBlock(i + 4, j + 17, k + 13, Blocks.nether_brick);
        world.setBlock(i + 4, j + 17, k + 14, Blocks.nether_brick);
        world.setBlock(i + 4, j + 17, k + 15, Blocks.nether_brick);
        world.setBlock(i + 4, j + 17, k + 16, Blocks.nether_brick);
        world.setBlock(i + 4, j + 17, k + 17, Blocks.nether_brick);
        world.setBlock(i + 4, j + 17, k + 18, Blocks.nether_brick_stairs, 1, 0);
        world.setBlock(i + 4, j + 18, k + 5, Blocks.nether_brick_stairs, 2, 0);
        world.setBlock(i + 4, j + 18, k + 6, Blocks.nether_brick);
        world.setBlock(i + 4, j + 18, k + 7, Blocks.nether_brick);
        world.setBlock(i + 4, j + 18, k + 8, Blocks.nether_brick);
        world.setBlock(i + 4, j + 18, k + 9, Blocks.nether_brick);
        world.setBlock(i + 4, j + 18, k + 10, Blocks.nether_brick);
        world.setBlock(i + 4, j + 18, k + 11, Blocks.nether_brick);
        world.setBlock(i + 4, j + 18, k + 12, Blocks.nether_brick);
        world.setBlock(i + 4, j + 18, k + 13, Blocks.nether_brick);
        world.setBlock(i + 4, j + 18, k + 14, Blocks.nether_brick);
        world.setBlock(i + 4, j + 18, k + 15, Blocks.nether_brick);
        world.setBlock(i + 4, j + 18, k + 16, Blocks.nether_brick);
        world.setBlock(i + 4, j + 18, k + 17, Blocks.nether_brick_stairs, 3, 0);
        world.setBlock(i + 4, j + 19, k + 6, Blocks.nether_brick_stairs, 2, 0);
        world.setBlock(i + 4, j + 19, k + 7, Blocks.nether_brick);
        world.setBlock(i + 4, j + 19, k + 8, Blocks.nether_brick);
        world.setBlock(i + 4, j + 19, k + 9, Blocks.nether_brick);
        world.setBlock(i + 4, j + 19, k + 10, Blocks.nether_brick);
        world.setBlock(i + 4, j + 19, k + 11, Blocks.nether_brick);
        world.setBlock(i + 4, j + 19, k + 12, Blocks.nether_brick);
        world.setBlock(i + 4, j + 19, k + 13, Blocks.nether_brick);
        world.setBlock(i + 4, j + 19, k + 14, Blocks.nether_brick);
        world.setBlock(i + 4, j + 19, k + 15, Blocks.nether_brick);
        world.setBlock(i + 4, j + 19, k + 16, Blocks.nether_brick_stairs, 3, 0);
        world.setBlock(i + 4, j + 20, k + 7, Blocks.nether_brick_stairs, 2, 0);
        world.setBlock(i + 4, j + 20, k + 8, Blocks.nether_brick);
        world.setBlock(i + 4, j + 20, k + 9, Blocks.nether_brick);
        world.setBlock(i + 4, j + 20, k + 10, Blocks.nether_brick);
        world.setBlock(i + 4, j + 20, k + 11, Blocks.nether_brick);
        world.setBlock(i + 4, j + 20, k + 12, Blocks.nether_brick);
        world.setBlock(i + 4, j + 20, k + 13, Blocks.nether_brick);
        world.setBlock(i + 4, j + 20, k + 14, Blocks.nether_brick);
        world.setBlock(i + 4, j + 20, k + 15, Blocks.nether_brick_stairs, 3, 0);
        world.setBlock(i + 4, j + 21, k + 8, Blocks.nether_brick_stairs, 2, 0);
        world.setBlock(i + 4, j + 21, k + 9, Blocks.nether_brick);
        world.setBlock(i + 4, j + 21, k + 10, Blocks.nether_brick);
        world.setBlock(i + 4, j + 21, k + 11, Blocks.glowstone);
        world.setBlock(i + 4, j + 21, k + 12, Blocks.nether_brick);
        world.setBlock(i + 4, j + 21, k + 13, Blocks.nether_brick);
        world.setBlock(i + 4, j + 21, k + 14, Blocks.nether_brick_stairs, 3, 0);
        world.setBlock(i + 4, j + 22, k + 9, Blocks.nether_brick_stairs, 2, 0);
        world.setBlock(i + 4, j + 22, k + 10, Blocks.nether_brick);
        world.setBlock(i + 4, j + 22, k + 11, Blocks.nether_brick);
        world.setBlock(i + 4, j + 22, k + 12, Blocks.nether_brick);
        world.setBlock(i + 4, j + 22, k + 13, Blocks.nether_brick_stairs, 3, 0);
        world.setBlock(i + 4, j + 23, k + 10, Blocks.nether_brick_stairs, 2, 0);
        world.setBlock(i + 4, j + 23, k + 11, Blocks.nether_brick);
        world.setBlock(i + 4, j + 23, k + 12, Blocks.nether_brick_stairs, 3, 0);
        world.setBlock(i + 5, j + 0, k + 4, Blocks.stonebrick);
        world.setBlock(i + 5, j + 0, k + 5, Blocks.stonebrick);
        world.setBlock(i + 5, j + 0, k + 6, Blocks.stonebrick);
        world.setBlock(i + 5, j + 0, k + 7, Blocks.stonebrick);
        world.setBlock(i + 5, j + 0, k + 10, Blocks.stonebrick);
        world.setBlock(i + 5, j + 0, k + 11, Blocks.stonebrick);
        world.setBlock(i + 5, j + 0, k + 12, Blocks.stonebrick);
        world.setBlock(i + 5, j + 0, k + 15, Blocks.stonebrick);
        world.setBlock(i + 5, j + 0, k + 16, Blocks.stonebrick);
        world.setBlock(i + 5, j + 0, k + 17, Blocks.stonebrick);
        world.setBlock(i + 5, j + 0, k + 18, Blocks.stonebrick);
        world.setBlock(i + 5, j + 1, k + 4, Blocks.stonebrick);
        world.setBlock(i + 5, j + 1, k + 5, Blocks.stonebrick);
        world.setBlock(i + 5, j + 1, k + 6, Blocks.stonebrick);
        world.setBlock(i + 5, j + 1, k + 7, Blocks.stonebrick);
        world.setBlock(i + 5, j + 1, k + 10, Blocks.stonebrick);
        world.setBlock(i + 5, j + 1, k + 11, Blocks.stonebrick);
        world.setBlock(i + 5, j + 1, k + 12, Blocks.stonebrick);
        world.setBlock(i + 5, j + 1, k + 15, Blocks.stonebrick);
        world.setBlock(i + 5, j + 1, k + 16, Blocks.stonebrick);
        world.setBlock(i + 5, j + 1, k + 17, Blocks.stonebrick);
        world.setBlock(i + 5, j + 1, k + 18, Blocks.stonebrick);
        world.setBlock(i + 5, j + 2, k + 4, Blocks.stonebrick);
        world.setBlock(i + 5, j + 2, k + 5, Blocks.stonebrick);
        world.setBlock(i + 5, j + 2, k + 6, Blocks.stonebrick);
        world.setBlock(i + 5, j + 2, k + 7, Blocks.stonebrick);
        world.setBlock(i + 5, j + 2, k + 10, Blocks.stonebrick);
        world.setBlock(i + 5, j + 2, k + 11, Blocks.stonebrick);
        world.setBlock(i + 5, j + 2, k + 12, Blocks.stonebrick);
        world.setBlock(i + 5, j + 2, k + 15, Blocks.stonebrick);
        world.setBlock(i + 5, j + 2, k + 16, Blocks.stonebrick);
        world.setBlock(i + 5, j + 2, k + 17, Blocks.stonebrick);
        world.setBlock(i + 5, j + 2, k + 18, Blocks.stonebrick);
        world.setBlock(i + 5, j + 3, k + 4, Blocks.nether_brick);
        world.setBlock(i + 5, j + 3, k + 5, Blocks.stonebrick);
        world.setBlock(i + 5, j + 3, k + 6, Blocks.stonebrick);
        world.setBlock(i + 5, j + 3, k + 7, Blocks.stonebrick);
        world.setBlock(i + 5, j + 3, k + 8, Blocks.stonebrick);
        world.setBlock(i + 5, j + 3, k + 9, Blocks.stonebrick);
        world.setBlock(i + 5, j + 3, k + 10, Blocks.stonebrick);
        world.setBlock(i + 5, j + 3, k + 11, Blocks.stonebrick);
        world.setBlock(i + 5, j + 3, k + 12, Blocks.stonebrick);
        world.setBlock(i + 5, j + 3, k + 13, Blocks.stonebrick);
        world.setBlock(i + 5, j + 3, k + 14, Blocks.stonebrick);
        world.setBlock(i + 5, j + 3, k + 15, Blocks.stonebrick);
        world.setBlock(i + 5, j + 3, k + 16, Blocks.stonebrick);
        world.setBlock(i + 5, j + 3, k + 17, Blocks.stonebrick);
        world.setBlock(i + 5, j + 3, k + 18, Blocks.nether_brick);
        world.setBlock(i + 5, j + 4, k + 4, Blocks.glowstone);
        world.setBlock(i + 5, j + 4, k + 5, Blocks.stonebrick);
        world.setBlock(i + 5, j + 4, k + 6, Blocks.stonebrick);
        world.setBlock(i + 5, j + 4, k + 7, Blocks.stonebrick);
        world.setBlock(i + 5, j + 4, k + 8, Blocks.stonebrick);
        world.setBlock(i + 5, j + 4, k + 9, Blocks.stonebrick);
        world.setBlock(i + 5, j + 4, k + 10, Blocks.stonebrick);
        world.setBlock(i + 5, j + 4, k + 11, Blocks.stonebrick);
        world.setBlock(i + 5, j + 4, k + 12, Blocks.stonebrick);
        world.setBlock(i + 5, j + 4, k + 13, Blocks.stonebrick);
        world.setBlock(i + 5, j + 4, k + 14, Blocks.stonebrick);
        world.setBlock(i + 5, j + 4, k + 15, Blocks.stonebrick);
        world.setBlock(i + 5, j + 4, k + 16, Blocks.stonebrick);
        world.setBlock(i + 5, j + 4, k + 17, Blocks.stonebrick);
        world.setBlock(i + 5, j + 4, k + 18, Blocks.glowstone);
        world.setBlock(i + 5, j + 5, k + 4, Blocks.nether_brick);
        world.setBlock(i + 5, j + 5, k + 5, Blocks.stonebrick);
        world.setBlock(i + 5, j + 5, k + 6, Blocks.stonebrick);
        world.setBlock(i + 5, j + 5, k + 7, Blocks.stonebrick);
        world.setBlock(i + 5, j + 5, k + 8, Blocks.stonebrick);
        world.setBlock(i + 5, j + 5, k + 9, Blocks.stonebrick);
        world.setBlock(i + 5, j + 5, k + 10, Blocks.stonebrick);
        world.setBlock(i + 5, j + 5, k + 11, Blocks.stonebrick);
        world.setBlock(i + 5, j + 5, k + 12, Blocks.stonebrick);
        world.setBlock(i + 5, j + 5, k + 13, Blocks.stonebrick);
        world.setBlock(i + 5, j + 5, k + 14, Blocks.stonebrick);
        world.setBlock(i + 5, j + 5, k + 15, Blocks.stonebrick);
        world.setBlock(i + 5, j + 5, k + 16, Blocks.stonebrick);
        world.setBlock(i + 5, j + 5, k + 17, Blocks.stonebrick);
        world.setBlock(i + 5, j + 5, k + 18, Blocks.nether_brick);
        world.setBlock(i + 5, j + 6, k + 4, Blocks.nether_brick);
        world.setBlock(i + 5, j + 6, k + 5, Blocks.stonebrick);
        world.setBlock(i + 5, j + 6, k + 6, Blocks.stonebrick);
        world.setBlock(i + 5, j + 6, k + 7, Blocks.stonebrick);
        world.setBlock(i + 5, j + 6, k + 8, Blocks.stonebrick);
        world.setBlock(i + 5, j + 6, k + 9, Blocks.stonebrick);
        world.setBlock(i + 5, j + 6, k + 10, Blocks.stonebrick);
        world.setBlock(i + 5, j + 6, k + 11, Blocks.stonebrick);
        world.setBlock(i + 5, j + 6, k + 12, Blocks.stonebrick);
        world.setBlock(i + 5, j + 6, k + 13, Blocks.stonebrick);
        world.setBlock(i + 5, j + 6, k + 14, Blocks.stonebrick);
        world.setBlock(i + 5, j + 6, k + 15, Blocks.stonebrick);
        world.setBlock(i + 5, j + 6, k + 16, Blocks.stonebrick);
        world.setBlock(i + 5, j + 6, k + 17, Blocks.stonebrick);
        world.setBlock(i + 5, j + 6, k + 18, Blocks.nether_brick);
        world.setBlock(i + 5, j + 7, k + 4, Blocks.nether_brick);
        world.setBlock(i + 5, j + 7, k + 5, Blocks.stonebrick);
        world.setBlock(i + 5, j + 7, k + 6, Blocks.stonebrick);
        world.setBlock(i + 5, j + 7, k + 7, Blocks.stonebrick);
        world.setBlock(i + 5, j + 7, k + 8, Blocks.stonebrick);
        world.setBlock(i + 5, j + 7, k + 9, Blocks.stonebrick);
        world.setBlock(i + 5, j + 7, k + 10, Blocks.stonebrick);
        world.setBlock(i + 5, j + 7, k + 11, Blocks.stonebrick);
        world.setBlock(i + 5, j + 7, k + 12, Blocks.stonebrick);
        world.setBlock(i + 5, j + 7, k + 13, Blocks.stonebrick);
        world.setBlock(i + 5, j + 7, k + 14, Blocks.stonebrick);
        world.setBlock(i + 5, j + 7, k + 15, Blocks.stonebrick);
        world.setBlock(i + 5, j + 7, k + 16, Blocks.stonebrick);
        world.setBlock(i + 5, j + 7, k + 17, Blocks.stonebrick);
        world.setBlock(i + 5, j + 7, k + 18, Blocks.nether_brick);
        world.setBlock(i + 5, j + 8, k + 4, Blocks.nether_brick);
        world.setBlock(i + 5, j + 8, k + 5, Blocks.stonebrick);
        world.setBlock(i + 5, j + 8, k + 6, Blocks.stonebrick);
        world.setBlock(i + 5, j + 8, k + 7, Blocks.stonebrick);
        world.setBlock(i + 5, j + 8, k + 8, Blocks.stonebrick);
        world.setBlock(i + 5, j + 8, k + 9, Blocks.stonebrick);
        world.setBlock(i + 5, j + 8, k + 10, Blocks.stonebrick);
        world.setBlock(i + 5, j + 8, k + 11, Blocks.stonebrick);
        world.setBlock(i + 5, j + 8, k + 12, Blocks.stonebrick);
        world.setBlock(i + 5, j + 8, k + 13, Blocks.stonebrick);
        world.setBlock(i + 5, j + 8, k + 14, Blocks.stonebrick);
        world.setBlock(i + 5, j + 8, k + 15, Blocks.stonebrick);
        world.setBlock(i + 5, j + 8, k + 16, Blocks.stonebrick);
        world.setBlock(i + 5, j + 8, k + 17, Blocks.stonebrick);
        world.setBlock(i + 5, j + 8, k + 18, Blocks.nether_brick);
        world.setBlock(i + 5, j + 9, k + 4, Blocks.nether_brick);
        world.setBlock(i + 5, j + 9, k + 5, Blocks.stonebrick);
        world.setBlock(i + 5, j + 9, k + 6, Blocks.stonebrick);
        world.setBlock(i + 5, j + 9, k + 7, Blocks.stonebrick);
        world.setBlock(i + 5, j + 9, k + 8, Blocks.stonebrick);
        world.setBlock(i + 5, j + 9, k + 9, Blocks.stonebrick);
        world.setBlock(i + 5, j + 9, k + 10, Blocks.stonebrick);
        world.setBlock(i + 5, j + 9, k + 11, Blocks.stonebrick);
        world.setBlock(i + 5, j + 9, k + 12, Blocks.stonebrick);
        world.setBlock(i + 5, j + 9, k + 13, Blocks.stonebrick);
        world.setBlock(i + 5, j + 9, k + 14, Blocks.stonebrick);
        world.setBlock(i + 5, j + 9, k + 15, Blocks.stonebrick);
        world.setBlock(i + 5, j + 9, k + 16, Blocks.stonebrick);
        world.setBlock(i + 5, j + 9, k + 17, Blocks.stonebrick);
        world.setBlock(i + 5, j + 9, k + 18, Blocks.nether_brick);
        world.setBlock(i + 5, j + 10, k + 4, Blocks.nether_brick);
        world.setBlock(i + 5, j + 10, k + 5, Blocks.stonebrick);
        world.setBlock(i + 5, j + 10, k + 6, Blocks.stonebrick);
        world.setBlock(i + 5, j + 10, k + 7, Blocks.stonebrick);
        world.setBlock(i + 5, j + 10, k + 8, Blocks.stonebrick);
        world.setBlock(i + 5, j + 10, k + 9, Blocks.stonebrick);
        world.setBlock(i + 5, j + 10, k + 10, Blocks.stonebrick);
        world.setBlock(i + 5, j + 10, k + 11, Blocks.stonebrick);
        world.setBlock(i + 5, j + 10, k + 12, Blocks.stonebrick);
        world.setBlock(i + 5, j + 10, k + 13, Blocks.stonebrick);
        world.setBlock(i + 5, j + 10, k + 14, Blocks.stonebrick);
        world.setBlock(i + 5, j + 10, k + 15, Blocks.stonebrick);
        world.setBlock(i + 5, j + 10, k + 16, Blocks.stonebrick);
        world.setBlock(i + 5, j + 10, k + 17, Blocks.stonebrick);
        world.setBlock(i + 5, j + 10, k + 18, Blocks.nether_brick);
        world.setBlock(i + 5, j + 11, k + 4, Blocks.nether_brick);
        world.setBlock(i + 5, j + 11, k + 5, Blocks.stonebrick);
        world.setBlock(i + 5, j + 11, k + 6, Blocks.stonebrick);
        world.setBlock(i + 5, j + 11, k + 7, Blocks.stonebrick);
        world.setBlock(i + 5, j + 11, k + 8, Blocks.stonebrick);
        world.setBlock(i + 5, j + 11, k + 9, Blocks.stonebrick);
        world.setBlock(i + 5, j + 11, k + 10, Blocks.stonebrick);
        world.setBlock(i + 5, j + 11, k + 11, Blocks.stonebrick);
        world.setBlock(i + 5, j + 11, k + 12, Blocks.stonebrick);
        world.setBlock(i + 5, j + 11, k + 13, Blocks.stonebrick);
        world.setBlock(i + 5, j + 11, k + 14, Blocks.stonebrick);
        world.setBlock(i + 5, j + 11, k + 15, Blocks.stonebrick);
        world.setBlock(i + 5, j + 11, k + 16, Blocks.stonebrick);
        world.setBlock(i + 5, j + 11, k + 17, Blocks.stonebrick);
        world.setBlock(i + 5, j + 11, k + 18, Blocks.nether_brick);
        world.setBlock(i + 5, j + 12, k + 4, Blocks.nether_brick);
        world.setBlock(i + 5, j + 12, k + 5, Blocks.stonebrick);
        world.setBlock(i + 5, j + 12, k + 6, Blocks.stonebrick);
        world.setBlock(i + 5, j + 12, k + 7, Blocks.stonebrick);
        world.setBlock(i + 5, j + 12, k + 8, Blocks.stonebrick);
        world.setBlock(i + 5, j + 12, k + 9, Blocks.stonebrick);
        world.setBlock(i + 5, j + 12, k + 10, Blocks.stonebrick);
        world.setBlock(i + 5, j + 12, k + 11, Blocks.stonebrick);
        world.setBlock(i + 5, j + 12, k + 12, Blocks.stonebrick);
        world.setBlock(i + 5, j + 12, k + 13, Blocks.stonebrick);
        world.setBlock(i + 5, j + 12, k + 14, Blocks.stonebrick);
        world.setBlock(i + 5, j + 12, k + 15, Blocks.stonebrick);
        world.setBlock(i + 5, j + 12, k + 16, Blocks.stonebrick);
        world.setBlock(i + 5, j + 12, k + 17, Blocks.stonebrick);
        world.setBlock(i + 5, j + 12, k + 18, Blocks.nether_brick);
        world.setBlock(i + 5, j + 13, k + 4, Blocks.nether_brick);
        world.setBlock(i + 5, j + 13, k + 5, Blocks.stonebrick);
        world.setBlock(i + 5, j + 13, k + 6, Blocks.stonebrick);
        world.setBlock(i + 5, j + 13, k + 7, Blocks.stonebrick);
        world.setBlock(i + 5, j + 13, k + 8, Blocks.stonebrick);
        world.setBlock(i + 5, j + 13, k + 9, Blocks.stonebrick);
        world.setBlock(i + 5, j + 13, k + 10, Blocks.stonebrick);
        world.setBlock(i + 5, j + 13, k + 11, Blocks.stonebrick);
        world.setBlock(i + 5, j + 13, k + 12, Blocks.stonebrick);
        world.setBlock(i + 5, j + 13, k + 13, Blocks.stonebrick);
        world.setBlock(i + 5, j + 13, k + 14, Blocks.stonebrick);
        world.setBlock(i + 5, j + 13, k + 15, Blocks.stonebrick);
        world.setBlock(i + 5, j + 13, k + 16, Blocks.stonebrick);
        world.setBlock(i + 5, j + 13, k + 17, Blocks.stonebrick);
        world.setBlock(i + 5, j + 13, k + 18, Blocks.nether_brick);
        world.setBlock(i + 5, j + 14, k + 4, Blocks.nether_brick);
        world.setBlock(i + 5, j + 14, k + 5, Blocks.stonebrick);
        world.setBlock(i + 5, j + 14, k + 6, Blocks.stonebrick);
        world.setBlock(i + 5, j + 14, k + 7, Blocks.stonebrick);
        world.setBlock(i + 5, j + 14, k + 8, Blocks.stonebrick);
        world.setBlock(i + 5, j + 14, k + 9, Blocks.stonebrick);
        world.setBlock(i + 5, j + 14, k + 10, Blocks.stonebrick);
        world.setBlock(i + 5, j + 14, k + 11, Blocks.stonebrick);
        world.setBlock(i + 5, j + 14, k + 12, Blocks.stonebrick);
        world.setBlock(i + 5, j + 14, k + 13, Blocks.stonebrick);
        world.setBlock(i + 5, j + 14, k + 14, Blocks.stonebrick);
        world.setBlock(i + 5, j + 14, k + 15, Blocks.stonebrick);
        world.setBlock(i + 5, j + 14, k + 16, Blocks.stonebrick);
        world.setBlock(i + 5, j + 14, k + 17, Blocks.stonebrick);
        world.setBlock(i + 5, j + 14, k + 18, Blocks.nether_brick);
        world.setBlock(i + 5, j + 15, k + 4, Blocks.nether_brick);
        world.setBlock(i + 5, j + 15, k + 5, Blocks.stonebrick);
        world.setBlock(i + 5, j + 15, k + 6, Blocks.stonebrick);
        world.setBlock(i + 5, j + 15, k + 7, Blocks.stonebrick);
        world.setBlock(i + 5, j + 15, k + 8, Blocks.stonebrick);
        world.setBlock(i + 5, j + 15, k + 9, Blocks.stonebrick);
        world.setBlock(i + 5, j + 15, k + 10, Blocks.stonebrick);
        world.setBlock(i + 5, j + 15, k + 11, Blocks.stonebrick);
        world.setBlock(i + 5, j + 15, k + 12, Blocks.stonebrick);
        world.setBlock(i + 5, j + 15, k + 13, Blocks.stonebrick);
        world.setBlock(i + 5, j + 15, k + 14, Blocks.stonebrick);
        world.setBlock(i + 5, j + 15, k + 15, Blocks.stonebrick);
        world.setBlock(i + 5, j + 15, k + 16, Blocks.stonebrick);
        world.setBlock(i + 5, j + 15, k + 17, Blocks.stonebrick);
        world.setBlock(i + 5, j + 15, k + 18, Blocks.nether_brick);
        world.setBlock(i + 5, j + 16, k + 4, Blocks.nether_brick_stairs, 1, 0);
        world.setBlock(i + 5, j + 16, k + 5, Blocks.stonebrick);
        world.setBlock(i + 5, j + 16, k + 6, Blocks.stonebrick);
        world.setBlock(i + 5, j + 16, k + 7, Blocks.stonebrick);
        world.setBlock(i + 5, j + 16, k + 8, Blocks.stonebrick);
        world.setBlock(i + 5, j + 16, k + 9, Blocks.stonebrick);
        world.setBlock(i + 5, j + 16, k + 10, Blocks.stonebrick);
        world.setBlock(i + 5, j + 16, k + 11, Blocks.stonebrick);
        world.setBlock(i + 5, j + 16, k + 12, Blocks.stonebrick);
        world.setBlock(i + 5, j + 16, k + 13, Blocks.stonebrick);
        world.setBlock(i + 5, j + 16, k + 14, Blocks.stonebrick);
        world.setBlock(i + 5, j + 16, k + 15, Blocks.stonebrick);
        world.setBlock(i + 5, j + 16, k + 16, Blocks.stonebrick);
        world.setBlock(i + 5, j + 16, k + 17, Blocks.stonebrick);
        world.setBlock(i + 5, j + 16, k + 18, Blocks.nether_brick_stairs, 1, 0);
        world.setBlock(i + 5, j + 17, k + 5, Blocks.stonebrick);
        world.setBlock(i + 5, j + 17, k + 6, Blocks.stonebrick);
        world.setBlock(i + 5, j + 17, k + 7, Blocks.stonebrick);
        world.setBlock(i + 5, j + 17, k + 8, Blocks.stonebrick);
        world.setBlock(i + 5, j + 17, k + 9, Blocks.stonebrick);
        world.setBlock(i + 5, j + 17, k + 10, Blocks.stonebrick);
        world.setBlock(i + 5, j + 17, k + 11, Blocks.stonebrick);
        world.setBlock(i + 5, j + 17, k + 12, Blocks.stonebrick);
        world.setBlock(i + 5, j + 17, k + 13, Blocks.stonebrick);
        world.setBlock(i + 5, j + 17, k + 14, Blocks.stonebrick);
        world.setBlock(i + 5, j + 17, k + 15, Blocks.stonebrick);
        world.setBlock(i + 5, j + 17, k + 16, Blocks.stonebrick);
        world.setBlock(i + 5, j + 17, k + 17, Blocks.stonebrick);
        world.setBlock(i + 5, j + 18, k + 5, Blocks.stonebrick);
        world.setBlock(i + 5, j + 18, k + 6, Blocks.stonebrick);
        world.setBlock(i + 5, j + 18, k + 7, Blocks.stonebrick);
        world.setBlock(i + 5, j + 18, k + 8, Blocks.stonebrick);
        world.setBlock(i + 5, j + 18, k + 9, Blocks.stonebrick);
        world.setBlock(i + 5, j + 18, k + 10, Blocks.stonebrick);
        world.setBlock(i + 5, j + 18, k + 11, Blocks.stonebrick);
        world.setBlock(i + 5, j + 18, k + 12, Blocks.stonebrick);
        world.setBlock(i + 5, j + 18, k + 13, Blocks.stonebrick);
        world.setBlock(i + 5, j + 18, k + 14, Blocks.stonebrick);
        world.setBlock(i + 5, j + 18, k + 15, Blocks.stonebrick);
        world.setBlock(i + 5, j + 18, k + 16, Blocks.stonebrick);
        world.setBlock(i + 5, j + 18, k + 17, Blocks.stonebrick);
        world.setBlock(i + 5, j + 19, k + 5, Blocks.stonebrick);
        world.setBlock(i + 5, j + 19, k + 6, Blocks.stonebrick);
        world.setBlock(i + 5, j + 19, k + 7, Blocks.stonebrick);
        world.setBlock(i + 5, j + 19, k + 8, Blocks.stonebrick);
        world.setBlock(i + 5, j + 19, k + 9, Blocks.stonebrick);
        world.setBlock(i + 5, j + 19, k + 10, Blocks.stonebrick);
        world.setBlock(i + 5, j + 19, k + 11, Blocks.stonebrick);
        world.setBlock(i + 5, j + 19, k + 12, Blocks.stonebrick);
        world.setBlock(i + 5, j + 19, k + 13, Blocks.stonebrick);
        world.setBlock(i + 5, j + 19, k + 14, Blocks.stonebrick);
        world.setBlock(i + 5, j + 19, k + 15, Blocks.stonebrick);
        world.setBlock(i + 5, j + 19, k + 16, Blocks.stonebrick);
        world.setBlock(i + 5, j + 19, k + 17, Blocks.stonebrick);
        world.setBlock(i + 5, j + 20, k + 5, Blocks.stonebrick);
        world.setBlock(i + 5, j + 20, k + 6, Blocks.stonebrick);
        world.setBlock(i + 5, j + 20, k + 7, Blocks.stonebrick);
        world.setBlock(i + 5, j + 20, k + 8, Blocks.stonebrick);
        world.setBlock(i + 5, j + 20, k + 9, Blocks.stonebrick);
        world.setBlock(i + 5, j + 20, k + 10, Blocks.stonebrick);
        world.setBlock(i + 5, j + 20, k + 11, Blocks.stonebrick);
        world.setBlock(i + 5, j + 20, k + 12, Blocks.stonebrick);
        world.setBlock(i + 5, j + 20, k + 13, Blocks.stonebrick);
        world.setBlock(i + 5, j + 20, k + 14, Blocks.stonebrick);
        world.setBlock(i + 5, j + 20, k + 15, Blocks.stonebrick);
        world.setBlock(i + 5, j + 20, k + 16, Blocks.stonebrick);
        world.setBlock(i + 5, j + 20, k + 17, Blocks.stonebrick);
        world.setBlock(i + 5, j + 21, k + 5, Blocks.nether_brick);
        world.setBlock(i + 5, j + 21, k + 6, Blocks.nether_brick);
        world.setBlock(i + 5, j + 21, k + 7, Blocks.nether_brick);
        world.setBlock(i + 5, j + 21, k + 8, Blocks.nether_brick_stairs, 3, 0);
        world.setBlock(i + 5, j + 21, k + 14, Blocks.nether_brick_stairs, 2, 0);
        world.setBlock(i + 5, j + 21, k + 15, Blocks.nether_brick);
        world.setBlock(i + 5, j + 21, k + 16, Blocks.nether_brick);
        world.setBlock(i + 5, j + 21, k + 17, Blocks.nether_brick);
        world.setBlock(i + 5, j + 22, k + 5, Blocks.nether_brick);
        world.setBlock(i + 5, j + 22, k + 6, Blocks.nether_brick);
        world.setBlock(i + 5, j + 22, k + 7, Blocks.nether_brick_stairs, 3, 0);
        world.setBlock(i + 5, j + 22, k + 15, Blocks.nether_brick_stairs, 2, 0);
        world.setBlock(i + 5, j + 22, k + 16, Blocks.nether_brick);
        world.setBlock(i + 5, j + 22, k + 17, Blocks.nether_brick);
        world.setBlock(i + 5, j + 23, k + 5, Blocks.nether_brick);
        world.setBlock(i + 5, j + 23, k + 6, Blocks.nether_brick_stairs, 3, 0);
        world.setBlock(i + 5, j + 23, k + 16, Blocks.nether_brick_stairs, 2, 0);
        world.setBlock(i + 5, j + 23, k + 17, Blocks.nether_brick);
        world.setBlock(i + 5, j + 24, k + 5, Blocks.nether_brick_stairs);
        world.setBlock(i + 5, j + 24, k + 17, Blocks.nether_brick_stairs, 2, 0);
        world.setBlock(i + 6, j + 0, k + 4, Blocks.stonebrick);
        world.setBlock(i + 6, j + 0, k + 5, Blocks.stonebrick);
        world.setBlock(i + 6, j + 0, k + 6, Blocks.stonebrick);
        world.setBlock(i + 6, j + 0, k + 7, Blocks.stonebrick);
        world.setBlock(i + 6, j + 0, k + 10, Blocks.stonebrick);
        world.setBlock(i + 6, j + 0, k + 11, Blocks.stonebrick);
        world.setBlock(i + 6, j + 0, k + 12, Blocks.stonebrick);
        world.setBlock(i + 6, j + 0, k + 15, Blocks.stonebrick);
        world.setBlock(i + 6, j + 0, k + 16, Blocks.stonebrick);
        world.setBlock(i + 6, j + 0, k + 17, Blocks.stonebrick);
        world.setBlock(i + 6, j + 0, k + 18, Blocks.stonebrick);
        world.setBlock(i + 6, j + 1, k + 4, Blocks.stonebrick);
        world.setBlock(i + 6, j + 1, k + 5, Blocks.stonebrick);
        world.setBlock(i + 6, j + 1, k + 6, Blocks.stonebrick);
        world.setBlock(i + 6, j + 1, k + 7, Blocks.stonebrick);
        world.setBlock(i + 6, j + 1, k + 10, Blocks.stonebrick);
        world.setBlock(i + 6, j + 1, k + 11, Blocks.stonebrick);
        world.setBlock(i + 6, j + 1, k + 12, Blocks.stonebrick);
        world.setBlock(i + 6, j + 1, k + 15, Blocks.stonebrick);
        world.setBlock(i + 6, j + 1, k + 16, Blocks.stonebrick);
        world.setBlock(i + 6, j + 1, k + 17, Blocks.stonebrick);
        world.setBlock(i + 6, j + 1, k + 18, Blocks.stonebrick);
        world.setBlock(i + 6, j + 2, k + 4, Blocks.stonebrick);
        world.setBlock(i + 6, j + 2, k + 5, Blocks.stonebrick);
        world.setBlock(i + 6, j + 2, k + 6, Blocks.stonebrick);
        world.setBlock(i + 6, j + 2, k + 7, Blocks.stonebrick);
        world.setBlock(i + 6, j + 2, k + 10, Blocks.stonebrick);
        world.setBlock(i + 6, j + 2, k + 11, Blocks.stonebrick);
        world.setBlock(i + 6, j + 2, k + 12, Blocks.stonebrick);
        world.setBlock(i + 6, j + 2, k + 15, Blocks.stonebrick);
        world.setBlock(i + 6, j + 2, k + 16, Blocks.stonebrick);
        world.setBlock(i + 6, j + 2, k + 17, Blocks.stonebrick);
        world.setBlock(i + 6, j + 2, k + 18, Blocks.stonebrick);
        world.setBlock(i + 6, j + 3, k + 4, Blocks.nether_brick);
        world.setBlock(i + 6, j + 3, k + 5, Blocks.stonebrick);
        world.setBlock(i + 6, j + 3, k + 6, Blocks.stonebrick);
        world.setBlock(i + 6, j + 3, k + 7, Blocks.stonebrick);
        world.setBlock(i + 6, j + 3, k + 8, Blocks.stonebrick);
        world.setBlock(i + 6, j + 3, k + 9, Blocks.stonebrick);
        world.setBlock(i + 6, j + 3, k + 10, Blocks.stonebrick);
        world.setBlock(i + 6, j + 3, k + 11, Blocks.stonebrick);
        world.setBlock(i + 6, j + 3, k + 12, Blocks.stonebrick);
        world.setBlock(i + 6, j + 3, k + 13, Blocks.stonebrick);
        world.setBlock(i + 6, j + 3, k + 14, Blocks.stonebrick);
        world.setBlock(i + 6, j + 3, k + 15, Blocks.stonebrick);
        world.setBlock(i + 6, j + 3, k + 16, Blocks.stonebrick);
        world.setBlock(i + 6, j + 3, k + 17, Blocks.stonebrick);
        world.setBlock(i + 6, j + 3, k + 18, Blocks.nether_brick);
        world.setBlock(i + 6, j + 4, k + 4, Blocks.nether_brick);
        world.setBlock(i + 6, j + 4, k + 5, Blocks.stonebrick);
        world.setBlock(i + 6, j + 4, k + 6, Blocks.nether_brick);
        world.setBlock(i + 6, j + 4, k + 16, Blocks.nether_brick);
        world.setBlock(i + 6, j + 4, k + 17, Blocks.stonebrick);
        world.setBlock(i + 6, j + 4, k + 18, Blocks.nether_brick);
        world.setBlock(i + 6, j + 5, k + 4, Blocks.nether_brick);
        world.setBlock(i + 6, j + 5, k + 5, Blocks.stonebrick);
        world.setBlock(i + 6, j + 5, k + 6, Blocks.nether_brick);
        world.setBlock(i + 6, j + 5, k + 16, Blocks.nether_brick);
        world.setBlock(i + 6, j + 5, k + 17, Blocks.stonebrick);
        world.setBlock(i + 6, j + 5, k + 18, Blocks.nether_brick);
        world.setBlock(i + 6, j + 6, k + 4, Blocks.nether_brick);
        world.setBlock(i + 6, j + 6, k + 5, Blocks.stonebrick);
        world.setBlock(i + 6, j + 6, k + 6, Blocks.nether_brick);
        world.setBlock(i + 6, j + 6, k + 16, Blocks.nether_brick);
        world.setBlock(i + 6, j + 6, k + 17, Blocks.stonebrick);
        world.setBlock(i + 6, j + 6, k + 18, Blocks.nether_brick);
        world.setBlock(i + 6, j + 7, k + 4, Blocks.nether_brick);
        world.setBlock(i + 6, j + 7, k + 5, Blocks.stonebrick);
        world.setBlock(i + 6, j + 7, k + 6, Blocks.glowstone);
        world.setBlock(i + 6, j + 7, k + 16, Blocks.glowstone);
        world.setBlock(i + 6, j + 7, k + 17, Blocks.stonebrick);
        world.setBlock(i + 6, j + 7, k + 18, Blocks.nether_brick);
        world.setBlock(i + 6, j + 8, k + 4, Blocks.nether_brick);
        world.setBlock(i + 6, j + 8, k + 5, Blocks.stonebrick);
        world.setBlock(i + 6, j + 8, k + 6, Blocks.stonebrick);
        world.setBlock(i + 6, j + 8, k + 7, Blocks.stonebrick);
        world.setBlock(i + 6, j + 8, k + 8, Blocks.stonebrick);
        world.setBlock(i + 6, j + 8, k + 9, Blocks.stonebrick);
        world.setBlock(i + 6, j + 8, k + 10, Blocks.stonebrick);
        world.setBlock(i + 6, j + 8, k + 11, Blocks.stonebrick);
        world.setBlock(i + 6, j + 8, k + 12, Blocks.stonebrick);
        world.setBlock(i + 6, j + 8, k + 13, Blocks.stonebrick);
        world.setBlock(i + 6, j + 8, k + 14, Blocks.stonebrick);
        world.setBlock(i + 6, j + 8, k + 15, Blocks.stonebrick);
        world.setBlock(i + 6, j + 8, k + 16, Blocks.stonebrick);
        world.setBlock(i + 6, j + 8, k + 17, Blocks.stonebrick);
        world.setBlock(i + 6, j + 8, k + 18, Blocks.nether_brick);
        world.setBlock(i + 6, j + 9, k + 4, Blocks.nether_brick);
        world.setBlock(i + 6, j + 9, k + 5, Blocks.stonebrick);
        world.setBlock(i + 6, j + 9, k + 8, Blocks.nether_brick_stairs, 2, 0);
        world.setBlock(i + 6, j + 9, k + 9, Blocks.nether_brick);
        world.setBlock(i + 6, j + 9, k + 10, Blocks.nether_brick);
        world.setBlock(i + 6, j + 9, k + 11, Blocks.jukebox);
        world.setBlock(i + 6, j + 9, k + 12, Blocks.nether_brick);
        world.setBlock(i + 6, j + 9, k + 13, Blocks.nether_brick);
        world.setBlock(i + 6, j + 9, k + 14, Blocks.nether_brick_stairs, 3, 0);
        world.setBlock(i + 6, j + 9, k + 17, Blocks.stonebrick);
        world.setBlock(i + 6, j + 9, k + 18, Blocks.nether_brick);
        world.setBlock(i + 6, j + 10, k + 4, Blocks.nether_brick);
        world.setBlock(i + 6, j + 10, k + 5, Blocks.stonebrick);
        world.setBlock(i + 6, j + 10, k + 9, Blocks.nether_brick_stairs, 2, 0);
        world.setBlock(i + 6, j + 10, k + 10, Blocks.nether_brick);
        world.setBlock(i + 6, j + 10, k + 12, Blocks.nether_brick);
        world.setBlock(i + 6, j + 10, k + 13, Blocks.nether_brick_stairs, 3, 0);
        world.setBlock(i + 6, j + 10, k + 17, Blocks.stonebrick);
        world.setBlock(i + 6, j + 10, k + 18, Blocks.nether_brick);
        world.setBlock(i + 6, j + 11, k + 4, Blocks.nether_brick);
        world.setBlock(i + 6, j + 11, k + 5, Blocks.stonebrick);
        world.setBlock(i + 6, j + 11, k + 10, Blocks.nether_brick_stairs, 2, 0);
        world.setBlock(i + 6, j + 11, k + 12, Blocks.nether_brick_stairs, 3, 0);
        world.setBlock(i + 6, j + 11, k + 17, Blocks.stonebrick);
        world.setBlock(i + 6, j + 11, k + 18, Blocks.nether_brick);
        world.setBlock(i + 6, j + 12, k + 4, Blocks.nether_brick);
        world.setBlock(i + 6, j + 12, k + 5, Blocks.stonebrick);
        world.setBlock(i + 6, j + 12, k + 17, Blocks.stonebrick);
        world.setBlock(i + 6, j + 12, k + 18, Blocks.nether_brick);
        world.setBlock(i + 6, j + 13, k + 4, Blocks.nether_brick);
        world.setBlock(i + 6, j + 13, k + 5, Blocks.stonebrick);
        world.setBlock(i + 6, j + 13, k + 17, Blocks.stonebrick);
        world.setBlock(i + 6, j + 13, k + 18, Blocks.nether_brick);
        world.setBlock(i + 6, j + 14, k + 4, Blocks.nether_brick);
        world.setBlock(i + 6, j + 14, k + 5, Blocks.stonebrick);
        world.setBlock(i + 6, j + 14, k + 6, Blocks.stonebrick);
        world.setBlock(i + 6, j + 14, k + 7, Blocks.stonebrick);
        world.setBlock(i + 6, j + 14, k + 8, Blocks.stonebrick);
        world.setBlock(i + 6, j + 14, k + 9, Blocks.stonebrick);
        world.setBlock(i + 6, j + 14, k + 10, Blocks.stonebrick);
        world.setBlock(i + 6, j + 14, k + 11, Blocks.stonebrick);
        world.setBlock(i + 6, j + 14, k + 12, Blocks.stonebrick);
        world.setBlock(i + 6, j + 14, k + 13, Blocks.stonebrick);
        world.setBlock(i + 6, j + 14, k + 14, Blocks.stonebrick);
        world.setBlock(i + 6, j + 14, k + 15, Blocks.stonebrick);
        world.setBlock(i + 6, j + 14, k + 16, Blocks.stonebrick);
        world.setBlock(i + 6, j + 14, k + 17, Blocks.stonebrick);
        world.setBlock(i + 6, j + 14, k + 18, Blocks.nether_brick);
        world.setBlock(i + 6, j + 15, k + 4, Blocks.nether_brick_stairs, 1, 0);
        world.setBlock(i + 6, j + 15, k + 5, Blocks.stonebrick);
        world.setBlock(i + 6, j + 15, k + 8, Blocks.nether_brick);
        world.setBlock(i + 6, j + 15, k + 9, Blocks.bookshelf);
        world.setBlock(i + 6, j + 15, k + 11, Blocks.enchanting_table);
        world.setBlock(i + 6, j + 15, k + 13, Blocks.bookshelf);
        world.setBlock(i + 6, j + 15, k + 14, Blocks.nether_brick);
        world.setBlock(i + 6, j + 15, k + 17, Blocks.stonebrick);
        world.setBlock(i + 6, j + 15, k + 18, Blocks.nether_brick_stairs, 1, 0);
        world.setBlock(i + 6, j + 16, k + 5, Blocks.stonebrick);
        world.setBlock(i + 6, j + 16, k + 8, Blocks.nether_brick);
        world.setBlock(i + 6, j + 16, k + 9, Blocks.bookshelf);
        world.setBlock(i + 6, j + 16, k + 13, Blocks.bookshelf);
        world.setBlock(i + 6, j + 16, k + 14, Blocks.nether_brick);
        world.setBlock(i + 6, j + 16, k + 17, Blocks.stonebrick);
        world.setBlock(i + 6, j + 17, k + 5, Blocks.stonebrick);
        world.setBlock(i + 6, j + 17, k + 8, Blocks.nether_brick);
        world.setBlock(i + 6, j + 17, k + 9, Blocks.bookshelf);
        world.setBlock(i + 6, j + 17, k + 13, Blocks.bookshelf);
        world.setBlock(i + 6, j + 17, k + 14, Blocks.nether_brick);
        world.setBlock(i + 6, j + 17, k + 17, Blocks.stonebrick);
        world.setBlock(i + 6, j + 18, k + 5, Blocks.stonebrick);
        world.setBlock(i + 6, j + 18, k + 8, Blocks.nether_brick);
        world.setBlock(i + 6, j + 18, k + 9, Blocks.bookshelf);
        world.setBlock(i + 6, j + 18, k + 13, Blocks.bookshelf);
        world.setBlock(i + 6, j + 18, k + 14, Blocks.nether_brick);
        world.setBlock(i + 6, j + 18, k + 17, Blocks.stonebrick);
        world.setBlock(i + 6, j + 19, k + 5, Blocks.stonebrick);
        world.setBlock(i + 6, j + 19, k + 8, Blocks.glowstone);
        world.setBlock(i + 6, j + 19, k + 9, Blocks.bookshelf);
        world.setBlock(i + 6, j + 19, k + 13, Blocks.bookshelf);
        world.setBlock(i + 6, j + 19, k + 14, Blocks.glowstone);
        world.setBlock(i + 6, j + 19, k + 17, Blocks.stonebrick);
        world.setBlock(i + 6, j + 20, k + 5, Blocks.stonebrick);
        world.setBlock(i + 6, j + 20, k + 6, Blocks.stonebrick);
        world.setBlock(i + 6, j + 20, k + 7, Blocks.stonebrick);
        world.setBlock(i + 6, j + 20, k + 8, Blocks.stonebrick);
        world.setBlock(i + 6, j + 20, k + 9, Blocks.stonebrick);
        world.setBlock(i + 6, j + 20, k + 10, Blocks.stonebrick);
        world.setBlock(i + 6, j + 20, k + 11, Blocks.stonebrick);
        world.setBlock(i + 6, j + 20, k + 12, Blocks.stonebrick);
        world.setBlock(i + 6, j + 20, k + 13, Blocks.stonebrick);
        world.setBlock(i + 6, j + 20, k + 14, Blocks.stonebrick);
        world.setBlock(i + 6, j + 20, k + 15, Blocks.stonebrick);
        world.setBlock(i + 6, j + 20, k + 16, Blocks.stonebrick);
        world.setBlock(i + 6, j + 20, k + 17, Blocks.stonebrick);
        world.setBlock(i + 6, j + 21, k + 5, Blocks.nether_brick);
        WorldGenWarlordDungeon.chest(world, rand, i + 6, j + 21, k + 6, "Vampire", 10);
        world.setBlock(i + 6, j + 21, k + 17, Blocks.nether_brick);
        world.setBlock(i + 6, j + 22, k + 5, Blocks.nether_brick);
        world.setBlock(i + 6, j + 22, k + 17, Blocks.nether_brick);
        world.setBlock(i + 6, j + 23, k + 5, Blocks.nether_brick);
        world.setBlock(i + 6, j + 23, k + 17, Blocks.nether_brick);
        world.setBlock(i + 6, j + 24, k + 5, Blocks.nether_brick);
        world.setBlock(i + 6, j + 24, k + 17, Blocks.nether_brick);
        world.setBlock(i + 6, j + 25, k + 5, Blocks.nether_brick_stairs);
        world.setBlock(i + 6, j + 25, k + 17, Blocks.nether_brick_stairs);
        world.setBlock(i + 7, j + 0, k + 4, Blocks.stonebrick);
        world.setBlock(i + 7, j + 0, k + 5, Blocks.stonebrick);
        world.setBlock(i + 7, j + 0, k + 6, Blocks.stonebrick);
        world.setBlock(i + 7, j + 0, k + 7, Blocks.stonebrick);
        world.setBlock(i + 7, j + 0, k + 10, Blocks.stonebrick);
        world.setBlock(i + 7, j + 0, k + 11, Blocks.stonebrick);
        world.setBlock(i + 7, j + 0, k + 12, Blocks.stonebrick);
        world.setBlock(i + 7, j + 0, k + 15, Blocks.stonebrick);
        world.setBlock(i + 7, j + 0, k + 16, Blocks.stonebrick);
        world.setBlock(i + 7, j + 0, k + 17, Blocks.stonebrick);
        world.setBlock(i + 7, j + 0, k + 18, Blocks.stonebrick);
        world.setBlock(i + 7, j + 1, k + 4, Blocks.stonebrick);
        world.setBlock(i + 7, j + 1, k + 5, Blocks.stonebrick);
        world.setBlock(i + 7, j + 1, k + 6, Blocks.stonebrick);
        world.setBlock(i + 7, j + 1, k + 7, Blocks.stonebrick);
        world.setBlock(i + 7, j + 1, k + 10, Blocks.stonebrick);
        world.setBlock(i + 7, j + 1, k + 11, Blocks.stonebrick);
        world.setBlock(i + 7, j + 1, k + 12, Blocks.stonebrick);
        world.setBlock(i + 7, j + 1, k + 15, Blocks.stonebrick);
        world.setBlock(i + 7, j + 1, k + 16, Blocks.stonebrick);
        world.setBlock(i + 7, j + 1, k + 17, Blocks.stonebrick);
        world.setBlock(i + 7, j + 1, k + 18, Blocks.stonebrick);
        world.setBlock(i + 7, j + 2, k + 4, Blocks.stonebrick);
        world.setBlock(i + 7, j + 2, k + 5, Blocks.stonebrick);
        world.setBlock(i + 7, j + 2, k + 6, Blocks.stonebrick);
        world.setBlock(i + 7, j + 2, k + 7, Blocks.stonebrick);
        world.setBlock(i + 7, j + 2, k + 10, Blocks.stonebrick);
        world.setBlock(i + 7, j + 2, k + 11, Blocks.stonebrick);
        world.setBlock(i + 7, j + 2, k + 12, Blocks.stonebrick);
        world.setBlock(i + 7, j + 2, k + 15, Blocks.stonebrick);
        world.setBlock(i + 7, j + 2, k + 16, Blocks.stonebrick);
        world.setBlock(i + 7, j + 2, k + 17, Blocks.stonebrick);
        world.setBlock(i + 7, j + 2, k + 18, Blocks.stonebrick);
        world.setBlock(i + 7, j + 3, k + 4, Blocks.nether_brick);
        world.setBlock(i + 7, j + 3, k + 5, Blocks.stonebrick);
        world.setBlock(i + 7, j + 3, k + 6, Blocks.stonebrick);
        world.setBlock(i + 7, j + 3, k + 7, Blocks.stonebrick);
        world.setBlock(i + 7, j + 3, k + 8, Blocks.stonebrick);
        world.setBlock(i + 7, j + 3, k + 9, Blocks.stonebrick);
        world.setBlock(i + 7, j + 3, k + 10, Blocks.stonebrick);
        world.setBlock(i + 7, j + 3, k + 11, Blocks.stonebrick);
        world.setBlock(i + 7, j + 3, k + 12, Blocks.stonebrick);
        world.setBlock(i + 7, j + 3, k + 13, Blocks.stonebrick);
        world.setBlock(i + 7, j + 3, k + 14, Blocks.stonebrick);
        world.setBlock(i + 7, j + 3, k + 15, Blocks.stonebrick);
        world.setBlock(i + 7, j + 3, k + 16, Blocks.stonebrick);
        world.setBlock(i + 7, j + 3, k + 17, Blocks.stonebrick);
        world.setBlock(i + 7, j + 3, k + 18, Blocks.nether_brick);
        world.setBlock(i + 7, j + 4, k + 4, Blocks.nether_brick);
        world.setBlock(i + 7, j + 4, k + 5, Blocks.stonebrick);
        world.setBlock(i + 7, j + 4, k + 17, Blocks.stonebrick);
        world.setBlock(i + 7, j + 4, k + 18, Blocks.nether_brick);
        world.setBlock(i + 7, j + 5, k + 4, Blocks.nether_brick);
        world.setBlock(i + 7, j + 5, k + 5, Blocks.stonebrick);
        world.setBlock(i + 7, j + 5, k + 17, Blocks.stonebrick);
        world.setBlock(i + 7, j + 5, k + 18, Blocks.nether_brick);
        world.setBlock(i + 7, j + 6, k + 4, Blocks.nether_brick);
        world.setBlock(i + 7, j + 6, k + 5, Blocks.stonebrick);
        world.setBlock(i + 7, j + 6, k + 17, Blocks.stonebrick);
        world.setBlock(i + 7, j + 6, k + 18, Blocks.nether_brick);
        world.setBlock(i + 7, j + 7, k + 4, Blocks.nether_brick);
        world.setBlock(i + 7, j + 7, k + 5, Blocks.stonebrick);
        world.setBlock(i + 7, j + 7, k + 17, Blocks.stonebrick);
        world.setBlock(i + 7, j + 7, k + 18, Blocks.nether_brick);
        world.setBlock(i + 7, j + 8, k + 4, Blocks.nether_brick);
        world.setBlock(i + 7, j + 8, k + 5, Blocks.stonebrick);
        world.setBlock(i + 7, j + 8, k + 6, Blocks.stonebrick);
        world.setBlock(i + 7, j + 8, k + 7, Blocks.stonebrick);
        world.setBlock(i + 7, j + 8, k + 8, Blocks.stonebrick);
        world.setBlock(i + 7, j + 8, k + 9, Blocks.stonebrick);
        world.setBlock(i + 7, j + 8, k + 10, Blocks.stonebrick);
        world.setBlock(i + 7, j + 8, k + 11, Blocks.stonebrick);
        world.setBlock(i + 7, j + 8, k + 12, Blocks.stonebrick);
        world.setBlock(i + 7, j + 8, k + 13, Blocks.stonebrick);
        world.setBlock(i + 7, j + 8, k + 14, Blocks.stonebrick);
        world.setBlock(i + 7, j + 8, k + 15, Blocks.stonebrick);
        world.setBlock(i + 7, j + 8, k + 16, Blocks.stonebrick);
        world.setBlock(i + 7, j + 8, k + 17, Blocks.stonebrick);
        world.setBlock(i + 7, j + 8, k + 18, Blocks.nether_brick);
        world.setBlock(i + 7, j + 9, k + 4, Blocks.nether_brick);
        world.setBlock(i + 7, j + 9, k + 5, Blocks.stonebrick);
        world.setBlock(i + 7, j + 9, k + 17, Blocks.stonebrick);
        world.setBlock(i + 7, j + 9, k + 18, Blocks.nether_brick);
        world.setBlock(i + 7, j + 10, k + 4, Blocks.nether_brick);
        world.setBlock(i + 7, j + 10, k + 5, Blocks.stonebrick);
        world.setBlock(i + 7, j + 10, k + 17, Blocks.stonebrick);
        world.setBlock(i + 7, j + 10, k + 18, Blocks.nether_brick);
        world.setBlock(i + 7, j + 11, k + 4, Blocks.nether_brick);
        world.setBlock(i + 7, j + 11, k + 5, Blocks.stonebrick);
        world.setBlock(i + 7, j + 11, k + 17, Blocks.stonebrick);
        world.setBlock(i + 7, j + 11, k + 18, Blocks.nether_brick);
        world.setBlock(i + 7, j + 12, k + 4, Blocks.nether_brick);
        world.setBlock(i + 7, j + 12, k + 5, Blocks.stonebrick);
        world.setBlock(i + 7, j + 12, k + 17, Blocks.stonebrick);
        world.setBlock(i + 7, j + 12, k + 18, Blocks.nether_brick);
        world.setBlock(i + 7, j + 13, k + 4, Blocks.nether_brick);
        world.setBlock(i + 7, j + 13, k + 5, Blocks.stonebrick);
        world.setBlock(i + 7, j + 13, k + 17, Blocks.stonebrick);
        world.setBlock(i + 7, j + 13, k + 18, Blocks.nether_brick);
        world.setBlock(i + 7, j + 14, k + 4, Blocks.nether_brick_stairs, 1, 0);
        world.setBlock(i + 7, j + 14, k + 5, Blocks.stonebrick);
        world.setBlock(i + 7, j + 14, k + 6, Blocks.stonebrick);
        world.setBlock(i + 7, j + 14, k + 7, Blocks.stonebrick);
        world.setBlock(i + 7, j + 14, k + 8, Blocks.stonebrick);
        world.setBlock(i + 7, j + 14, k + 9, Blocks.stonebrick);
        world.setBlock(i + 7, j + 14, k + 10, Blocks.stonebrick);
        world.setBlock(i + 7, j + 14, k + 11, Blocks.stonebrick);
        world.setBlock(i + 7, j + 14, k + 12, Blocks.stonebrick);
        world.setBlock(i + 7, j + 14, k + 13, Blocks.stonebrick);
        world.setBlock(i + 7, j + 14, k + 14, Blocks.stonebrick);
        world.setBlock(i + 7, j + 14, k + 15, Blocks.stonebrick);
        world.setBlock(i + 7, j + 14, k + 16, Blocks.stonebrick);
        world.setBlock(i + 7, j + 14, k + 17, Blocks.stonebrick);
        world.setBlock(i + 7, j + 14, k + 18, Blocks.nether_brick_stairs, 1, 0);
        world.setBlock(i + 7, j + 19, k + 5, Blocks.stonebrick);
        world.setBlock(i + 7, j + 19, k + 17, Blocks.stonebrick);
        world.setBlock(i + 7, j + 20, k + 5, Blocks.stonebrick);
        world.setBlock(i + 7, j + 20, k + 6, Blocks.stonebrick);
        world.setBlock(i + 7, j + 20, k + 7, Blocks.stonebrick);
        world.setBlock(i + 7, j + 20, k + 8, Blocks.stonebrick);
        world.setBlock(i + 7, j + 20, k + 9, Blocks.stonebrick);
        world.setBlock(i + 7, j + 20, k + 10, Blocks.stonebrick);
        world.setBlock(i + 7, j + 20, k + 11, Blocks.stonebrick);
        world.setBlock(i + 7, j + 20, k + 12, Blocks.stonebrick);
        world.setBlock(i + 7, j + 20, k + 13, Blocks.stonebrick);
        world.setBlock(i + 7, j + 20, k + 14, Blocks.stonebrick);
        world.setBlock(i + 7, j + 20, k + 15, Blocks.stonebrick);
        world.setBlock(i + 7, j + 20, k + 16, Blocks.stonebrick);
        world.setBlock(i + 7, j + 20, k + 17, Blocks.stonebrick);
        world.setBlock(i + 8, j + 3, k + 4, Blocks.stonebrick);
        world.setBlock(i + 8, j + 3, k + 5, Blocks.stonebrick);
        world.setBlock(i + 8, j + 3, k + 6, Blocks.stonebrick);
        world.setBlock(i + 8, j + 3, k + 7, Blocks.stonebrick);
        world.setBlock(i + 8, j + 3, k + 8, Blocks.stonebrick);
        world.setBlock(i + 8, j + 3, k + 9, Blocks.stonebrick);
        world.setBlock(i + 8, j + 3, k + 10, Blocks.stonebrick);
        world.setBlock(i + 8, j + 3, k + 11, Blocks.stonebrick);
        world.setBlock(i + 8, j + 3, k + 12, Blocks.stonebrick);
        world.setBlock(i + 8, j + 3, k + 13, Blocks.stonebrick);
        world.setBlock(i + 8, j + 3, k + 14, Blocks.stonebrick);
        world.setBlock(i + 8, j + 3, k + 15, Blocks.stonebrick);
        world.setBlock(i + 8, j + 3, k + 16, Blocks.stonebrick);
        world.setBlock(i + 8, j + 3, k + 17, Blocks.stonebrick);
        world.setBlock(i + 8, j + 3, k + 18, Blocks.stonebrick);
        world.setBlock(i + 8, j + 4, k + 4, Blocks.nether_brick);
        world.setBlock(i + 8, j + 4, k + 5, Blocks.stonebrick);
        world.setBlock(i + 8, j + 4, k + 17, Blocks.stonebrick);
        world.setBlock(i + 8, j + 4, k + 18, Blocks.nether_brick);
        world.setBlock(i + 8, j + 5, k + 4, Blocks.nether_brick);
        world.setBlock(i + 8, j + 5, k + 5, Blocks.stonebrick);
        world.setBlock(i + 8, j + 5, k + 17, Blocks.stonebrick);
        world.setBlock(i + 8, j + 5, k + 18, Blocks.nether_brick);
        world.setBlock(i + 8, j + 6, k + 4, Blocks.nether_brick);
        world.setBlock(i + 8, j + 6, k + 5, Blocks.stonebrick);
        world.setBlock(i + 8, j + 6, k + 17, Blocks.stonebrick);
        world.setBlock(i + 8, j + 6, k + 18, Blocks.nether_brick);
        world.setBlock(i + 8, j + 7, k + 4, Blocks.nether_brick);
        world.setBlock(i + 8, j + 7, k + 5, Blocks.stonebrick);
        world.setBlock(i + 8, j + 7, k + 17, Blocks.stonebrick);
        world.setBlock(i + 8, j + 7, k + 18, Blocks.nether_brick);
        world.setBlock(i + 8, j + 8, k + 4, Blocks.nether_brick);
        world.setBlock(i + 8, j + 8, k + 5, Blocks.stonebrick);
        world.setBlock(i + 8, j + 8, k + 6, Blocks.stonebrick);
        world.setBlock(i + 8, j + 8, k + 7, Blocks.stonebrick);
        world.setBlock(i + 8, j + 8, k + 8, Blocks.stonebrick);
        world.setBlock(i + 8, j + 8, k + 9, Blocks.stonebrick);
        world.setBlock(i + 8, j + 8, k + 10, Blocks.stonebrick);
        world.setBlock(i + 8, j + 8, k + 11, Blocks.stonebrick);
        world.setBlock(i + 8, j + 8, k + 12, Blocks.stonebrick);
        world.setBlock(i + 8, j + 8, k + 13, Blocks.stonebrick);
        world.setBlock(i + 8, j + 8, k + 14, Blocks.stonebrick);
        world.setBlock(i + 8, j + 8, k + 15, Blocks.stonebrick);
        world.setBlock(i + 8, j + 8, k + 16, Blocks.stonebrick);
        world.setBlock(i + 8, j + 8, k + 17, Blocks.stonebrick);
        world.setBlock(i + 8, j + 8, k + 18, Blocks.nether_brick);
        world.setBlock(i + 8, j + 9, k + 4, Blocks.nether_brick);
        world.setBlock(i + 8, j + 9, k + 5, Blocks.stonebrick);
        world.setBlock(i + 8, j + 9, k + 17, Blocks.stonebrick);
        world.setBlock(i + 8, j + 9, k + 18, Blocks.nether_brick);
        world.setBlock(i + 8, j + 10, k + 4, Blocks.nether_brick);
        world.setBlock(i + 8, j + 10, k + 5, Blocks.stonebrick);
        world.setBlock(i + 8, j + 10, k + 17, Blocks.stonebrick);
        world.setBlock(i + 8, j + 10, k + 18, Blocks.nether_brick);
        world.setBlock(i + 8, j + 11, k + 4, Blocks.nether_brick);
        world.setBlock(i + 8, j + 11, k + 5, Blocks.stonebrick);
        world.setBlock(i + 8, j + 11, k + 17, Blocks.stonebrick);
        world.setBlock(i + 8, j + 11, k + 18, Blocks.nether_brick);
        world.setBlock(i + 8, j + 12, k + 4, Blocks.nether_brick);
        world.setBlock(i + 8, j + 12, k + 5, Blocks.stonebrick);
        world.setBlock(i + 8, j + 12, k + 17, Blocks.stonebrick);
        world.setBlock(i + 8, j + 12, k + 18, Blocks.nether_brick);
        world.setBlock(i + 8, j + 13, k + 4, Blocks.nether_brick_stairs, 1, 0);
        world.setBlock(i + 8, j + 13, k + 5, Blocks.stonebrick);
        world.setBlock(i + 8, j + 13, k + 17, Blocks.stonebrick);
        world.setBlock(i + 8, j + 13, k + 18, Blocks.nether_brick_stairs, 1, 0);
        world.setBlock(i + 8, j + 14, k + 5, Blocks.stonebrick);
        world.setBlock(i + 8, j + 14, k + 6, Blocks.stonebrick);
        world.setBlock(i + 8, j + 14, k + 7, Blocks.stonebrick);
        world.setBlock(i + 8, j + 14, k + 8, Blocks.stonebrick);
        world.setBlock(i + 8, j + 14, k + 9, Blocks.stonebrick);
        world.setBlock(i + 8, j + 14, k + 10, Blocks.stonebrick);
        world.setBlock(i + 8, j + 14, k + 11, Blocks.stonebrick);
        world.setBlock(i + 8, j + 14, k + 12, Blocks.stonebrick);
        world.setBlock(i + 8, j + 14, k + 13, Blocks.stonebrick);
        world.setBlock(i + 8, j + 14, k + 14, Blocks.stonebrick);
        world.setBlock(i + 8, j + 14, k + 15, Blocks.stonebrick);
        world.setBlock(i + 8, j + 14, k + 16, Blocks.stonebrick);
        world.setBlock(i + 8, j + 14, k + 17, Blocks.stonebrick);
        world.setBlock(i + 8, j + 15, k + 5, Blocks.stonebrick);
        world.setBlock(i + 8, j + 15, k + 8, Blocks.nether_brick);
        world.setBlock(i + 8, j + 15, k + 9, Blocks.bookshelf);
        world.setBlock(i + 8, j + 15, k + 13, Blocks.bookshelf);
        world.setBlock(i + 8, j + 15, k + 14, Blocks.nether_brick);
        world.setBlock(i + 8, j + 15, k + 17, Blocks.stonebrick);
        world.setBlock(i + 8, j + 16, k + 5, Blocks.stonebrick);
        world.setBlock(i + 8, j + 16, k + 8, Blocks.nether_brick);
        world.setBlock(i + 8, j + 16, k + 9, Blocks.bookshelf);
        world.setBlock(i + 8, j + 16, k + 13, Blocks.bookshelf);
        world.setBlock(i + 8, j + 16, k + 14, Blocks.nether_brick);
        world.setBlock(i + 8, j + 16, k + 17, Blocks.stonebrick);
        world.setBlock(i + 8, j + 17, k + 5, Blocks.stonebrick);
        world.setBlock(i + 8, j + 17, k + 8, Blocks.nether_brick);
        world.setBlock(i + 8, j + 17, k + 9, Blocks.bookshelf);
        world.setBlock(i + 8, j + 17, k + 13, Blocks.bookshelf);
        world.setBlock(i + 8, j + 17, k + 14, Blocks.nether_brick);
        world.setBlock(i + 8, j + 17, k + 17, Blocks.stonebrick);
        world.setBlock(i + 8, j + 18, k + 5, Blocks.stonebrick);
        world.setBlock(i + 8, j + 18, k + 8, Blocks.nether_brick);
        world.setBlock(i + 8, j + 18, k + 9, Blocks.bookshelf);
        world.setBlock(i + 8, j + 18, k + 13, Blocks.bookshelf);
        world.setBlock(i + 8, j + 18, k + 14, Blocks.nether_brick);
        world.setBlock(i + 8, j + 18, k + 17, Blocks.stonebrick);
        world.setBlock(i + 8, j + 19, k + 5, Blocks.stonebrick);
        world.setBlock(i + 8, j + 19, k + 8, Blocks.glowstone);
        world.setBlock(i + 8, j + 19, k + 9, Blocks.bookshelf);
        world.setBlock(i + 8, j + 19, k + 13, Blocks.bookshelf);
        world.setBlock(i + 8, j + 19, k + 14, Blocks.glowstone);
        world.setBlock(i + 8, j + 19, k + 17, Blocks.stonebrick);
        world.setBlock(i + 8, j + 20, k + 5, Blocks.stonebrick);
        world.setBlock(i + 8, j + 20, k + 6, Blocks.stonebrick);
        world.setBlock(i + 8, j + 20, k + 7, Blocks.stonebrick);
        world.setBlock(i + 8, j + 20, k + 8, Blocks.stonebrick);
        world.setBlock(i + 8, j + 20, k + 9, Blocks.stonebrick);
        world.setBlock(i + 8, j + 20, k + 10, Blocks.stonebrick);
        world.setBlock(i + 8, j + 20, k + 11, Blocks.stonebrick);
        world.setBlock(i + 8, j + 20, k + 12, Blocks.stonebrick);
        world.setBlock(i + 8, j + 20, k + 13, Blocks.stonebrick);
        world.setBlock(i + 8, j + 20, k + 14, Blocks.stonebrick);
        world.setBlock(i + 8, j + 20, k + 15, Blocks.stonebrick);
        world.setBlock(i + 8, j + 20, k + 16, Blocks.stonebrick);
        world.setBlock(i + 8, j + 20, k + 17, Blocks.stonebrick);
        world.setBlock(i + 8, j + 21, k + 5, Blocks.nether_brick);
        world.setBlock(i + 8, j + 21, k + 17, Blocks.nether_brick);
        world.setBlock(i + 8, j + 22, k + 5, Blocks.nether_brick);
        world.setBlock(i + 8, j + 22, k + 17, Blocks.nether_brick);
        world.setBlock(i + 8, j + 23, k + 5, Blocks.nether_brick);
        world.setBlock(i + 8, j + 23, k + 17, Blocks.nether_brick);
        world.setBlock(i + 8, j + 24, k + 5, Blocks.nether_brick);
        world.setBlock(i + 8, j + 24, k + 17, Blocks.nether_brick);
        world.setBlock(i + 8, j + 25, k + 5, Blocks.nether_brick_stairs, 1, 0);
        world.setBlock(i + 8, j + 25, k + 17, Blocks.nether_brick_stairs, 1, 0);
        world.setBlock(i + 9, j + 3, k + 4, Blocks.stonebrick);
        world.setBlock(i + 9, j + 3, k + 5, Blocks.stonebrick);
        world.setBlock(i + 9, j + 3, k + 6, Blocks.stonebrick);
        world.setBlock(i + 9, j + 3, k + 7, Blocks.stonebrick);
        world.setBlock(i + 9, j + 3, k + 8, Blocks.stonebrick);
        world.setBlock(i + 9, j + 3, k + 9, Blocks.stonebrick);
        world.setBlock(i + 9, j + 3, k + 10, Blocks.stonebrick);
        world.setBlock(i + 9, j + 3, k + 11, Blocks.stonebrick);
        world.setBlock(i + 9, j + 3, k + 12, Blocks.stonebrick);
        world.setBlock(i + 9, j + 3, k + 13, Blocks.stonebrick);
        world.setBlock(i + 9, j + 3, k + 14, Blocks.stonebrick);
        world.setBlock(i + 9, j + 3, k + 15, Blocks.stonebrick);
        world.setBlock(i + 9, j + 3, k + 16, Blocks.stonebrick);
        world.setBlock(i + 9, j + 3, k + 17, Blocks.stonebrick);
        world.setBlock(i + 9, j + 3, k + 18, Blocks.stonebrick);
        world.setBlock(i + 9, j + 4, k + 4, Blocks.nether_brick);
        world.setBlock(i + 9, j + 4, k + 5, Blocks.stonebrick);
        world.setBlock(i + 9, j + 4, k + 17, Blocks.stonebrick);
        world.setBlock(i + 9, j + 4, k + 18, Blocks.nether_brick);
        world.setBlock(i + 9, j + 5, k + 4, Blocks.nether_brick);
        world.setBlock(i + 9, j + 5, k + 5, Blocks.stonebrick);
        world.setBlock(i + 9, j + 5, k + 17, Blocks.stonebrick);
        world.setBlock(i + 9, j + 5, k + 18, Blocks.nether_brick);
        world.setBlock(i + 9, j + 6, k + 4, Blocks.nether_brick);
        world.setBlock(i + 9, j + 6, k + 5, Blocks.stonebrick);
        world.setBlock(i + 9, j + 6, k + 17, Blocks.stonebrick);
        world.setBlock(i + 9, j + 6, k + 18, Blocks.nether_brick);
        world.setBlock(i + 9, j + 7, k + 4, Blocks.nether_brick);
        world.setBlock(i + 9, j + 7, k + 5, Blocks.stonebrick);
        world.setBlock(i + 9, j + 7, k + 17, Blocks.stonebrick);
        world.setBlock(i + 9, j + 7, k + 18, Blocks.nether_brick);
        world.setBlock(i + 9, j + 8, k + 4, Blocks.nether_brick);
        world.setBlock(i + 9, j + 8, k + 5, Blocks.stonebrick);
        world.setBlock(i + 9, j + 8, k + 6, Blocks.stonebrick);
        world.setBlock(i + 9, j + 8, k + 7, Blocks.stonebrick);
        world.setBlock(i + 9, j + 8, k + 8, Blocks.stonebrick);
        world.setBlock(i + 9, j + 8, k + 9, Blocks.stonebrick);
        world.setBlock(i + 9, j + 8, k + 10, Blocks.stonebrick);
        world.setBlock(i + 9, j + 8, k + 11, Blocks.stonebrick);
        world.setBlock(i + 9, j + 8, k + 12, Blocks.stonebrick);
        world.setBlock(i + 9, j + 8, k + 13, Blocks.stonebrick);
        world.setBlock(i + 9, j + 8, k + 14, Blocks.stonebrick);
        world.setBlock(i + 9, j + 8, k + 15, Blocks.stonebrick);
        world.setBlock(i + 9, j + 8, k + 16, Blocks.stonebrick);
        world.setBlock(i + 9, j + 8, k + 17, Blocks.stonebrick);
        world.setBlock(i + 9, j + 8, k + 18, Blocks.nether_brick);
        world.setBlock(i + 9, j + 9, k + 4, Blocks.nether_brick);
        world.setBlock(i + 9, j + 9, k + 5, Blocks.stonebrick);
        Dungeons.spawner(world, i + 9, j + 9, k + 11, 15, 2);
        world.setBlock(i + 9, j + 9, k + 17, Blocks.stonebrick);
        world.setBlock(i + 9, j + 9, k + 18, Blocks.nether_brick);
        world.setBlock(i + 9, j + 10, k + 4, Blocks.nether_brick);
        world.setBlock(i + 9, j + 10, k + 5, Blocks.stonebrick);
        world.setBlock(i + 9, j + 10, k + 17, Blocks.stonebrick);
        world.setBlock(i + 9, j + 10, k + 18, Blocks.nether_brick);
        world.setBlock(i + 9, j + 11, k + 4, Blocks.nether_brick);
        world.setBlock(i + 9, j + 11, k + 5, Blocks.stonebrick);
        world.setBlock(i + 9, j + 11, k + 17, Blocks.stonebrick);
        world.setBlock(i + 9, j + 11, k + 18, Blocks.nether_brick);
        world.setBlock(i + 9, j + 12, k + 4, Blocks.nether_brick_stairs, 1, 0);
        world.setBlock(i + 9, j + 12, k + 5, Blocks.stonebrick);
        world.setBlock(i + 9, j + 12, k + 17, Blocks.stonebrick);
        world.setBlock(i + 9, j + 12, k + 18, Blocks.nether_brick_stairs, 1, 0);
        world.setBlock(i + 9, j + 13, k + 5, Blocks.stonebrick);
        world.setBlock(i + 9, j + 13, k + 17, Blocks.stonebrick);
        world.setBlock(i + 9, j + 14, k + 5, Blocks.stonebrick);
        world.setBlock(i + 9, j + 14, k + 6, Blocks.stonebrick);
        world.setBlock(i + 9, j + 14, k + 7, Blocks.stonebrick);
        world.setBlock(i + 9, j + 14, k + 8, Blocks.stonebrick);
        world.setBlock(i + 9, j + 14, k + 9, Blocks.stonebrick);
        world.setBlock(i + 9, j + 14, k + 10, Blocks.stonebrick);
        world.setBlock(i + 9, j + 14, k + 11, Blocks.stonebrick);
        world.setBlock(i + 9, j + 14, k + 12, Blocks.stonebrick);
        world.setBlock(i + 9, j + 14, k + 13, Blocks.stonebrick);
        world.setBlock(i + 9, j + 14, k + 14, Blocks.stonebrick);
        world.setBlock(i + 9, j + 14, k + 15, Blocks.stonebrick);
        world.setBlock(i + 9, j + 14, k + 16, Blocks.stonebrick);
        world.setBlock(i + 9, j + 14, k + 17, Blocks.stonebrick);
        world.setBlock(i + 9, j + 15, k + 5, Blocks.stonebrick);
        world.setBlock(i + 9, j + 15, k + 6, Blocks.stonebrick);
        world.setBlock(i + 9, j + 15, k + 7, Blocks.stonebrick);
        world.setBlock(i + 9, j + 15, k + 8, Blocks.stonebrick);
        world.setBlock(i + 9, j + 15, k + 9, Blocks.stonebrick);
        world.setBlock(i + 9, j + 15, k + 10, Blocks.stonebrick);
        world.setBlock(i + 9, j + 15, k + 11, Blocks.stonebrick);
        world.setBlock(i + 9, j + 15, k + 12, Blocks.stonebrick);
        world.setBlock(i + 9, j + 15, k + 13, Blocks.stonebrick);
        world.setBlock(i + 9, j + 15, k + 14, Blocks.stonebrick);
        world.setBlock(i + 9, j + 15, k + 15, Blocks.stonebrick);
        world.setBlock(i + 9, j + 15, k + 16, Blocks.stonebrick);
        world.setBlock(i + 9, j + 15, k + 17, Blocks.stonebrick);
        world.setBlock(i + 9, j + 16, k + 5, Blocks.stonebrick);
        world.setBlock(i + 9, j + 16, k + 6, Blocks.stonebrick);
        world.setBlock(i + 9, j + 16, k + 7, Blocks.stonebrick);
        world.setBlock(i + 9, j + 16, k + 8, Blocks.stonebrick);
        world.setBlock(i + 9, j + 16, k + 9, Blocks.stonebrick);
        world.setBlock(i + 9, j + 16, k + 10, Blocks.stonebrick);
        world.setBlock(i + 9, j + 16, k + 11, Blocks.stonebrick);
        world.setBlock(i + 9, j + 16, k + 12, Blocks.stonebrick);
        world.setBlock(i + 9, j + 16, k + 13, Blocks.stonebrick);
        world.setBlock(i + 9, j + 16, k + 14, Blocks.stonebrick);
        world.setBlock(i + 9, j + 16, k + 15, Blocks.stonebrick);
        world.setBlock(i + 9, j + 16, k + 16, Blocks.stonebrick);
        world.setBlock(i + 9, j + 16, k + 17, Blocks.stonebrick);
        world.setBlock(i + 9, j + 17, k + 5, Blocks.stonebrick);
        world.setBlock(i + 9, j + 17, k + 6, Blocks.stonebrick);
        world.setBlock(i + 9, j + 17, k + 7, Blocks.stonebrick);
        world.setBlock(i + 9, j + 17, k + 8, Blocks.stonebrick);
        world.setBlock(i + 9, j + 17, k + 9, Blocks.stonebrick);
        world.setBlock(i + 9, j + 17, k + 10, Blocks.stonebrick);
        world.setBlock(i + 9, j + 17, k + 11, Blocks.stonebrick);
        world.setBlock(i + 9, j + 17, k + 12, Blocks.stonebrick);
        world.setBlock(i + 9, j + 17, k + 13, Blocks.stonebrick);
        world.setBlock(i + 9, j + 17, k + 14, Blocks.stonebrick);
        world.setBlock(i + 9, j + 17, k + 15, Blocks.stonebrick);
        world.setBlock(i + 9, j + 17, k + 16, Blocks.stonebrick);
        world.setBlock(i + 9, j + 17, k + 17, Blocks.stonebrick);
        world.setBlock(i + 9, j + 18, k + 5, Blocks.stonebrick);
        world.setBlock(i + 9, j + 18, k + 6, Blocks.stonebrick);
        world.setBlock(i + 9, j + 18, k + 7, Blocks.stonebrick);
        world.setBlock(i + 9, j + 18, k + 8, Blocks.stonebrick);
        world.setBlock(i + 9, j + 18, k + 9, Blocks.stonebrick);
        world.setBlock(i + 9, j + 18, k + 10, Blocks.stonebrick);
        world.setBlock(i + 9, j + 18, k + 11, Blocks.stonebrick);
        world.setBlock(i + 9, j + 18, k + 12, Blocks.stonebrick);
        world.setBlock(i + 9, j + 18, k + 13, Blocks.stonebrick);
        world.setBlock(i + 9, j + 18, k + 14, Blocks.stonebrick);
        world.setBlock(i + 9, j + 18, k + 15, Blocks.stonebrick);
        world.setBlock(i + 9, j + 18, k + 16, Blocks.stonebrick);
        world.setBlock(i + 9, j + 18, k + 17, Blocks.stonebrick);
        world.setBlock(i + 9, j + 19, k + 5, Blocks.stonebrick);
        world.setBlock(i + 9, j + 19, k + 6, Blocks.stonebrick);
        world.setBlock(i + 9, j + 19, k + 7, Blocks.stonebrick);
        world.setBlock(i + 9, j + 19, k + 8, Blocks.stonebrick);
        world.setBlock(i + 9, j + 19, k + 9, Blocks.stonebrick);
        world.setBlock(i + 9, j + 19, k + 10, Blocks.stonebrick);
        world.setBlock(i + 9, j + 19, k + 11, Blocks.stonebrick);
        world.setBlock(i + 9, j + 19, k + 12, Blocks.stonebrick);
        world.setBlock(i + 9, j + 19, k + 13, Blocks.stonebrick);
        world.setBlock(i + 9, j + 19, k + 14, Blocks.stonebrick);
        world.setBlock(i + 9, j + 19, k + 15, Blocks.stonebrick);
        world.setBlock(i + 9, j + 19, k + 16, Blocks.stonebrick);
        world.setBlock(i + 9, j + 19, k + 17, Blocks.stonebrick);
        world.setBlock(i + 9, j + 20, k + 5, Blocks.stonebrick);
        world.setBlock(i + 9, j + 20, k + 6, Blocks.stonebrick);
        world.setBlock(i + 9, j + 20, k + 7, Blocks.stonebrick);
        world.setBlock(i + 9, j + 20, k + 8, Blocks.stonebrick);
        world.setBlock(i + 9, j + 20, k + 9, Blocks.stonebrick);
        world.setBlock(i + 9, j + 20, k + 10, Blocks.stonebrick);
        world.setBlock(i + 9, j + 20, k + 11, Blocks.stonebrick);
        world.setBlock(i + 9, j + 20, k + 12, Blocks.stonebrick);
        world.setBlock(i + 9, j + 20, k + 13, Blocks.stonebrick);
        world.setBlock(i + 9, j + 20, k + 14, Blocks.stonebrick);
        world.setBlock(i + 9, j + 20, k + 15, Blocks.stonebrick);
        world.setBlock(i + 9, j + 20, k + 16, Blocks.stonebrick);
        world.setBlock(i + 9, j + 20, k + 17, Blocks.stonebrick);
        world.setBlock(i + 9, j + 21, k + 5, Blocks.nether_brick);
        world.setBlock(i + 9, j + 21, k + 6, Blocks.nether_brick);
        world.setBlock(i + 9, j + 21, k + 7, Blocks.nether_brick);
        world.setBlock(i + 9, j + 21, k + 8, Blocks.nether_brick_stairs, 3, 0);
        world.setBlock(i + 9, j + 21, k + 14, Blocks.nether_brick_stairs, 2, 0);
        world.setBlock(i + 9, j + 21, k + 15, Blocks.nether_brick);
        world.setBlock(i + 9, j + 21, k + 16, Blocks.nether_brick);
        world.setBlock(i + 9, j + 21, k + 17, Blocks.nether_brick);
        world.setBlock(i + 9, j + 22, k + 5, Blocks.nether_brick);
        world.setBlock(i + 9, j + 22, k + 6, Blocks.nether_brick);
        world.setBlock(i + 9, j + 22, k + 7, Blocks.nether_brick_stairs, 3, 0);
        world.setBlock(i + 9, j + 22, k + 15, Blocks.nether_brick_stairs, 2, 0);
        world.setBlock(i + 9, j + 22, k + 16, Blocks.nether_brick);
        world.setBlock(i + 9, j + 22, k + 17, Blocks.nether_brick);
        world.setBlock(i + 9, j + 23, k + 5, Blocks.nether_brick);
        world.setBlock(i + 9, j + 23, k + 6, Blocks.nether_brick_stairs, 3, 0);
        world.setBlock(i + 9, j + 23, k + 16, Blocks.nether_brick_stairs, 2, 0);
        world.setBlock(i + 9, j + 23, k + 17, Blocks.nether_brick);
        world.setBlock(i + 9, j + 24, k + 5, Blocks.nether_brick_stairs, 3, 0);
        world.setBlock(i + 9, j + 24, k + 17, Blocks.nether_brick_stairs, 2, 0);
        world.setBlock(i + 10, j + 0, k + 4, Blocks.stonebrick);
        world.setBlock(i + 10, j + 0, k + 5, Blocks.stonebrick);
        world.setBlock(i + 10, j + 0, k + 6, Blocks.stonebrick);
        world.setBlock(i + 10, j + 0, k + 7, Blocks.stonebrick);
        world.setBlock(i + 10, j + 0, k + 10, Blocks.stonebrick);
        world.setBlock(i + 10, j + 0, k + 11, Blocks.stonebrick);
        world.setBlock(i + 10, j + 0, k + 12, Blocks.stonebrick);
        world.setBlock(i + 10, j + 0, k + 15, Blocks.stonebrick);
        world.setBlock(i + 10, j + 0, k + 16, Blocks.stonebrick);
        world.setBlock(i + 10, j + 0, k + 17, Blocks.stonebrick);
        world.setBlock(i + 10, j + 0, k + 18, Blocks.stonebrick);
        world.setBlock(i + 10, j + 1, k + 4, Blocks.stonebrick);
        world.setBlock(i + 10, j + 1, k + 5, Blocks.stonebrick);
        world.setBlock(i + 10, j + 1, k + 6, Blocks.stonebrick);
        world.setBlock(i + 10, j + 1, k + 7, Blocks.stonebrick);
        world.setBlock(i + 10, j + 1, k + 10, Blocks.stonebrick);
        world.setBlock(i + 10, j + 1, k + 11, Blocks.stonebrick);
        world.setBlock(i + 10, j + 1, k + 12, Blocks.stonebrick);
        world.setBlock(i + 10, j + 1, k + 15, Blocks.stonebrick);
        world.setBlock(i + 10, j + 1, k + 16, Blocks.stonebrick);
        world.setBlock(i + 10, j + 1, k + 17, Blocks.stonebrick);
        world.setBlock(i + 10, j + 1, k + 18, Blocks.stonebrick);
        world.setBlock(i + 10, j + 2, k + 4, Blocks.stonebrick);
        world.setBlock(i + 10, j + 2, k + 5, Blocks.stonebrick);
        world.setBlock(i + 10, j + 2, k + 6, Blocks.stonebrick);
        world.setBlock(i + 10, j + 2, k + 7, Blocks.stonebrick);
        world.setBlock(i + 10, j + 2, k + 10, Blocks.stonebrick);
        world.setBlock(i + 10, j + 2, k + 11, Blocks.stonebrick);
        world.setBlock(i + 10, j + 2, k + 12, Blocks.stonebrick);
        world.setBlock(i + 10, j + 2, k + 15, Blocks.stonebrick);
        world.setBlock(i + 10, j + 2, k + 16, Blocks.stonebrick);
        world.setBlock(i + 10, j + 2, k + 17, Blocks.stonebrick);
        world.setBlock(i + 10, j + 2, k + 18, Blocks.stonebrick);
        world.setBlock(i + 10, j + 3, k + 4, Blocks.nether_brick);
        world.setBlock(i + 10, j + 3, k + 5, Blocks.stonebrick);
        world.setBlock(i + 10, j + 3, k + 6, Blocks.stonebrick);
        world.setBlock(i + 10, j + 3, k + 7, Blocks.stonebrick);
        world.setBlock(i + 10, j + 3, k + 8, Blocks.stonebrick);
        world.setBlock(i + 10, j + 3, k + 9, Blocks.stonebrick);
        world.setBlock(i + 10, j + 3, k + 10, Blocks.stonebrick);
        world.setBlock(i + 10, j + 3, k + 11, Blocks.stonebrick);
        world.setBlock(i + 10, j + 3, k + 12, Blocks.stonebrick);
        world.setBlock(i + 10, j + 3, k + 13, Blocks.stonebrick);
        world.setBlock(i + 10, j + 3, k + 14, Blocks.stonebrick);
        world.setBlock(i + 10, j + 3, k + 15, Blocks.stonebrick);
        world.setBlock(i + 10, j + 3, k + 16, Blocks.stonebrick);
        world.setBlock(i + 10, j + 3, k + 17, Blocks.stonebrick);
        world.setBlock(i + 10, j + 3, k + 18, Blocks.nether_brick);
        world.setBlock(i + 10, j + 4, k + 4, Blocks.nether_brick);
        world.setBlock(i + 10, j + 4, k + 5, Blocks.stonebrick);
        world.setBlock(i + 10, j + 4, k + 6, Blocks.lapis_ore);
        world.setBlock(i + 10, j + 4, k + 7, Blocks.enchanting_table);
        world.setBlock(i + 10, j + 4, k + 15, Blocks.enchanting_table);
        world.setBlock(i + 10, j + 4, k + 16, Blocks.lapis_ore);
        world.setBlock(i + 10, j + 4, k + 17, Blocks.stonebrick);
        world.setBlock(i + 10, j + 4, k + 18, Blocks.nether_brick);
        world.setBlock(i + 10, j + 5, k + 4, Blocks.nether_brick);
        world.setBlock(i + 10, j + 5, k + 5, Blocks.stonebrick);
        world.setBlock(i + 10, j + 5, k + 17, Blocks.stonebrick);
        world.setBlock(i + 10, j + 5, k + 18, Blocks.nether_brick);
        world.setBlock(i + 10, j + 6, k + 4, Blocks.nether_brick);
        world.setBlock(i + 10, j + 6, k + 5, Blocks.stonebrick);
        world.setBlock(i + 10, j + 6, k + 17, Blocks.stonebrick);
        world.setBlock(i + 10, j + 6, k + 18, Blocks.nether_brick);
        world.setBlock(i + 10, j + 7, k + 4, Blocks.nether_brick);
        world.setBlock(i + 10, j + 7, k + 5, Blocks.stonebrick);
        world.setBlock(i + 10, j + 7, k + 17, Blocks.stonebrick);
        world.setBlock(i + 10, j + 7, k + 18, Blocks.nether_brick);
        world.setBlock(i + 10, j + 8, k + 4, Blocks.nether_brick);
        world.setBlock(i + 10, j + 8, k + 5, Blocks.stonebrick);
        world.setBlock(i + 10, j + 8, k + 6, Blocks.stonebrick);
        world.setBlock(i + 10, j + 8, k + 7, Blocks.stonebrick);
        world.setBlock(i + 10, j + 8, k + 8, Blocks.stonebrick);
        world.setBlock(i + 10, j + 8, k + 9, Blocks.stonebrick);
        world.setBlock(i + 10, j + 8, k + 10, Blocks.stonebrick);
        world.setBlock(i + 10, j + 8, k + 11, Blocks.stonebrick);
        world.setBlock(i + 10, j + 8, k + 12, Blocks.stonebrick);
        world.setBlock(i + 10, j + 8, k + 13, Blocks.stonebrick);
        world.setBlock(i + 10, j + 8, k + 14, Blocks.stonebrick);
        world.setBlock(i + 10, j + 8, k + 15, Blocks.stonebrick);
        world.setBlock(i + 10, j + 8, k + 16, Blocks.stonebrick);
        world.setBlock(i + 10, j + 8, k + 17, Blocks.stonebrick);
        world.setBlock(i + 10, j + 8, k + 18, Blocks.nether_brick);
        world.setBlock(i + 10, j + 9, k + 4, Blocks.nether_brick);
        world.setBlock(i + 10, j + 9, k + 5, Blocks.stonebrick);
        world.setBlock(i + 10, j + 9, k + 17, Blocks.stonebrick);
        world.setBlock(i + 10, j + 9, k + 18, Blocks.nether_brick);
        world.setBlock(i + 10, j + 10, k + 4, Blocks.nether_brick);
        world.setBlock(i + 10, j + 10, k + 5, Blocks.stonebrick);
        world.setBlock(i + 10, j + 10, k + 17, Blocks.stonebrick);
        world.setBlock(i + 10, j + 10, k + 18, Blocks.nether_brick);
        world.setBlock(i + 10, j + 11, k + 4, Blocks.nether_brick_stairs, 1, 0);
        world.setBlock(i + 10, j + 11, k + 5, Blocks.stonebrick);
        world.setBlock(i + 10, j + 11, k + 17, Blocks.stonebrick);
        world.setBlock(i + 10, j + 11, k + 18, Blocks.nether_brick_stairs, 1, 0);
        world.setBlock(i + 10, j + 12, k + 5, Blocks.stonebrick);
        world.setBlock(i + 10, j + 12, k + 17, Blocks.stonebrick);
        world.setBlock(i + 10, j + 13, k + 5, Blocks.stonebrick);
        world.setBlock(i + 10, j + 13, k + 17, Blocks.stonebrick);
        world.setBlock(i + 10, j + 14, k + 5, Blocks.stonebrick);
        world.setBlock(i + 10, j + 14, k + 6, Blocks.stonebrick);
        world.setBlock(i + 10, j + 14, k + 7, Blocks.stonebrick);
        world.setBlock(i + 10, j + 14, k + 8, Blocks.stonebrick);
        world.setBlock(i + 10, j + 14, k + 9, Blocks.stonebrick);
        world.setBlock(i + 10, j + 14, k + 10, Blocks.stonebrick);
        world.setBlock(i + 10, j + 14, k + 11, Blocks.stonebrick);
        world.setBlock(i + 10, j + 14, k + 12, Blocks.stonebrick);
        world.setBlock(i + 10, j + 14, k + 13, Blocks.stonebrick);
        world.setBlock(i + 10, j + 14, k + 14, Blocks.stonebrick);
        world.setBlock(i + 10, j + 14, k + 15, Blocks.stonebrick);
        world.setBlock(i + 10, j + 14, k + 16, Blocks.stonebrick);
        world.setBlock(i + 10, j + 14, k + 17, Blocks.stonebrick);
        world.setBlock(i + 10, j + 15, k + 5, Blocks.nether_brick);
        world.setBlock(i + 10, j + 15, k + 17, Blocks.nether_brick);
        world.setBlock(i + 10, j + 16, k + 5, Blocks.nether_brick_stairs);
        world.setBlock(i + 10, j + 16, k + 17, Blocks.nether_brick_stairs);
        world.setBlock(i + 11, j + 0, k + 5, Blocks.stonebrick);
        world.setBlock(i + 11, j + 0, k + 6, Blocks.stonebrick);
        world.setBlock(i + 11, j + 0, k + 7, Blocks.stonebrick);
        world.setBlock(i + 11, j + 0, k + 10, Blocks.stonebrick);
        world.setBlock(i + 11, j + 0, k + 11, Blocks.stonebrick);
        world.setBlock(i + 11, j + 0, k + 12, Blocks.stonebrick);
        world.setBlock(i + 11, j + 0, k + 15, Blocks.stonebrick);
        world.setBlock(i + 11, j + 0, k + 16, Blocks.stonebrick);
        world.setBlock(i + 11, j + 0, k + 17, Blocks.stonebrick);
        world.setBlock(i + 11, j + 1, k + 5, Blocks.stonebrick);
        world.setBlock(i + 11, j + 1, k + 6, Blocks.stonebrick);
        world.setBlock(i + 11, j + 1, k + 7, Blocks.stonebrick);
        world.setBlock(i + 11, j + 1, k + 10, Blocks.stonebrick);
        world.setBlock(i + 11, j + 1, k + 11, Blocks.stonebrick);
        world.setBlock(i + 11, j + 1, k + 12, Blocks.stonebrick);
        world.setBlock(i + 11, j + 1, k + 15, Blocks.stonebrick);
        world.setBlock(i + 11, j + 1, k + 16, Blocks.stonebrick);
        world.setBlock(i + 11, j + 1, k + 17, Blocks.stonebrick);
        world.setBlock(i + 11, j + 2, k + 5, Blocks.stonebrick);
        world.setBlock(i + 11, j + 2, k + 6, Blocks.stonebrick);
        world.setBlock(i + 11, j + 2, k + 7, Blocks.stonebrick);
        world.setBlock(i + 11, j + 2, k + 10, Blocks.stonebrick);
        world.setBlock(i + 11, j + 2, k + 11, Blocks.stonebrick);
        world.setBlock(i + 11, j + 2, k + 12, Blocks.stonebrick);
        world.setBlock(i + 11, j + 2, k + 15, Blocks.stonebrick);
        world.setBlock(i + 11, j + 2, k + 16, Blocks.stonebrick);
        world.setBlock(i + 11, j + 2, k + 17, Blocks.stonebrick);
        world.setBlock(i + 11, j + 3, k + 4, Blocks.nether_brick);
        world.setBlock(i + 11, j + 3, k + 5, Blocks.stonebrick);
        world.setBlock(i + 11, j + 3, k + 6, Blocks.stonebrick);
        world.setBlock(i + 11, j + 3, k + 7, Blocks.stonebrick);
        world.setBlock(i + 11, j + 3, k + 8, Blocks.stonebrick);
        world.setBlock(i + 11, j + 3, k + 9, Blocks.stonebrick);
        world.setBlock(i + 11, j + 3, k + 10, Blocks.stonebrick);
        world.setBlock(i + 11, j + 3, k + 11, Blocks.stonebrick);
        world.setBlock(i + 11, j + 3, k + 12, Blocks.stonebrick);
        world.setBlock(i + 11, j + 3, k + 13, Blocks.stonebrick);
        world.setBlock(i + 11, j + 3, k + 14, Blocks.stonebrick);
        world.setBlock(i + 11, j + 3, k + 15, Blocks.stonebrick);
        world.setBlock(i + 11, j + 3, k + 16, Blocks.stonebrick);
        world.setBlock(i + 11, j + 3, k + 17, Blocks.stonebrick);
        world.setBlock(i + 11, j + 3, k + 18, Blocks.nether_brick);
        world.setBlock(i + 11, j + 4, k + 4, Blocks.glowstone);
        world.setBlock(i + 11, j + 4, k + 5, Blocks.stonebrick);
        world.setBlock(i + 11, j + 4, k + 6, Blocks.lapis_ore);
        world.setBlock(i + 11, j + 4, k + 7, Blocks.lapis_ore);
        world.setBlock(i + 11, j + 4, k + 15, Blocks.lapis_ore);
        world.setBlock(i + 11, j + 4, k + 16, Blocks.lapis_ore);
        world.setBlock(i + 11, j + 4, k + 17, Blocks.stonebrick);
        world.setBlock(i + 11, j + 4, k + 18, Blocks.glowstone);
        world.setBlock(i + 11, j + 5, k + 4, Blocks.nether_brick);
        world.setBlock(i + 11, j + 5, k + 5, Blocks.stonebrick);
        world.setBlock(i + 11, j + 5, k + 6, Blocks.lapis_ore);
        world.setBlock(i + 11, j + 5, k + 16, Blocks.lapis_ore);
        world.setBlock(i + 11, j + 5, k + 17, Blocks.stonebrick);
        world.setBlock(i + 11, j + 5, k + 18, Blocks.nether_brick);
        world.setBlock(i + 11, j + 6, k + 4, Blocks.nether_brick);
        world.setBlock(i + 11, j + 6, k + 5, Blocks.stonebrick);
        world.setBlock(i + 11, j + 6, k + 17, Blocks.stonebrick);
        world.setBlock(i + 11, j + 6, k + 18, Blocks.nether_brick);
        world.setBlock(i + 11, j + 7, k + 4, Blocks.nether_brick);
        world.setBlock(i + 11, j + 7, k + 5, Blocks.stonebrick);
        world.setBlock(i + 11, j + 7, k + 17, Blocks.stonebrick);
        world.setBlock(i + 11, j + 7, k + 18, Blocks.nether_brick);
        world.setBlock(i + 11, j + 8, k + 4, Blocks.nether_brick);
        world.setBlock(i + 11, j + 8, k + 5, Blocks.stonebrick);
        world.setBlock(i + 11, j + 8, k + 6, Blocks.stonebrick);
        world.setBlock(i + 11, j + 8, k + 7, Blocks.stonebrick);
        world.setBlock(i + 11, j + 8, k + 8, Blocks.stonebrick);
        world.setBlock(i + 11, j + 8, k + 9, Blocks.stonebrick);
        world.setBlock(i + 11, j + 8, k + 10, Blocks.stonebrick);
        world.setBlock(i + 11, j + 8, k + 11, Blocks.stonebrick);
        world.setBlock(i + 11, j + 8, k + 12, Blocks.stonebrick);
        world.setBlock(i + 11, j + 8, k + 13, Blocks.stonebrick);
        world.setBlock(i + 11, j + 8, k + 14, Blocks.stonebrick);
        world.setBlock(i + 11, j + 8, k + 15, Blocks.stonebrick);
        world.setBlock(i + 11, j + 8, k + 16, Blocks.stonebrick);
        world.setBlock(i + 11, j + 8, k + 17, Blocks.stonebrick);
        world.setBlock(i + 11, j + 8, k + 18, Blocks.nether_brick);
        world.setBlock(i + 11, j + 9, k + 4, Blocks.nether_brick);
        world.setBlock(i + 11, j + 9, k + 5, Blocks.stonebrick);
        world.setBlock(i + 11, j + 9, k + 9, Blocks.stonebrick);
        world.setBlock(i + 11, j + 9, k + 10, Blocks.stonebrick);
        world.setBlock(i + 11, j + 9, k + 11, Blocks.stonebrick);
        world.setBlock(i + 11, j + 9, k + 12, Blocks.stonebrick);
        world.setBlock(i + 11, j + 9, k + 13, Blocks.stonebrick);
        world.setBlock(i + 11, j + 9, k + 17, Blocks.stonebrick);
        world.setBlock(i + 11, j + 9, k + 18, Blocks.nether_brick);
        world.setBlock(i + 11, j + 10, k + 4, Blocks.nether_brick_stairs, 1, 0);
        world.setBlock(i + 11, j + 10, k + 18, Blocks.nether_brick_stairs, 1, 0);
        world.setBlock(i + 11, j + 13, k + 5, Blocks.stonebrick);
        world.setBlock(i + 11, j + 13, k + 17, Blocks.stonebrick);
        world.setBlock(i + 11, j + 14, k + 5, Blocks.stonebrick);
        world.setBlock(i + 11, j + 14, k + 6, Blocks.stonebrick);
        world.setBlock(i + 11, j + 14, k + 7, Blocks.stonebrick);
        world.setBlock(i + 11, j + 14, k + 8, Blocks.stonebrick);
        world.setBlock(i + 11, j + 14, k + 9, Blocks.stonebrick);
        world.setBlock(i + 11, j + 14, k + 10, Blocks.stonebrick);
        world.setBlock(i + 11, j + 14, k + 11, Blocks.stonebrick);
        world.setBlock(i + 11, j + 14, k + 12, Blocks.stonebrick);
        world.setBlock(i + 11, j + 14, k + 13, Blocks.stonebrick);
        world.setBlock(i + 11, j + 14, k + 14, Blocks.stonebrick);
        world.setBlock(i + 11, j + 14, k + 15, Blocks.stonebrick);
        world.setBlock(i + 11, j + 14, k + 16, Blocks.stonebrick);
        world.setBlock(i + 11, j + 14, k + 17, Blocks.stonebrick);
        world.setBlock(i + 11, j + 15, k + 5, Blocks.nether_brick);
        Dungeons.spawner(world, i + 11, j + 15, k + 11, 15, 2);
        WorldGenWarlordDungeon.chest(world, rand, i + 11, j + 15, k + 16, "strongholdCorridor", 10);
        world.setBlock(i + 11, j + 15, k + 17, Blocks.nether_brick);
        world.setBlock(i + 11, j + 16, k + 5, Blocks.nether_brick);
        world.setBlock(i + 11, j + 16, k + 17, Blocks.nether_brick);
        world.setBlock(i + 11, j + 17, k + 5, Blocks.nether_brick_stairs);
        world.setBlock(i + 11, j + 17, k + 17, Blocks.nether_brick_stairs);
        world.setBlock(i + 12, j + 0, k + 4, Blocks.stonebrick);
        world.setBlock(i + 12, j + 0, k + 5, Blocks.stonebrick);
        world.setBlock(i + 12, j + 0, k + 6, Blocks.stonebrick);
        world.setBlock(i + 12, j + 0, k + 7, Blocks.stonebrick);
        world.setBlock(i + 12, j + 0, k + 10, Blocks.stonebrick);
        world.setBlock(i + 12, j + 0, k + 11, Blocks.stonebrick);
        world.setBlock(i + 12, j + 0, k + 12, Blocks.stonebrick);
        world.setBlock(i + 12, j + 0, k + 15, Blocks.stonebrick);
        world.setBlock(i + 12, j + 0, k + 16, Blocks.stonebrick);
        world.setBlock(i + 12, j + 0, k + 17, Blocks.stonebrick);
        world.setBlock(i + 12, j + 0, k + 18, Blocks.stonebrick);
        world.setBlock(i + 12, j + 1, k + 4, Blocks.stonebrick);
        world.setBlock(i + 12, j + 1, k + 5, Blocks.stonebrick);
        world.setBlock(i + 12, j + 1, k + 6, Blocks.stonebrick);
        world.setBlock(i + 12, j + 1, k + 7, Blocks.stonebrick);
        world.setBlock(i + 12, j + 1, k + 10, Blocks.stonebrick);
        world.setBlock(i + 12, j + 1, k + 11, Blocks.stonebrick);
        world.setBlock(i + 12, j + 1, k + 12, Blocks.stonebrick);
        world.setBlock(i + 12, j + 1, k + 15, Blocks.stonebrick);
        world.setBlock(i + 12, j + 1, k + 16, Blocks.stonebrick);
        world.setBlock(i + 12, j + 1, k + 17, Blocks.stonebrick);
