

package com.gibby.dungeon.gen;

import net.minecraft.world.gen.feature.*;
import net.minecraft.world.*;
import java.util.*;
import net.minecraft.init.*;
import net.minecraft.block.*;
import com.gibby.dungeon.*;
import com.gibby.dungeon.mobs.*;
import net.minecraft.entity.*;
import net.minecraft.entity.passive.*;

public class WorldGenAnchorVillage extends WorldGenerator
{
    public boolean generate(final World world, final Random rand, final int i, final int j, final int k) {
        if (world.getBlock(i, j + 40, k) != Blocks.air && world.getBlock(i + 30, j + 40, k + 50) != Blocks.air && world.getBlock(i, j + 38, k) == Blocks.air && world.getBlock(i + 30, j + 38, k + 50) == Blocks.air) {
            world.setBlock(i + 6, j + 23, k + 27, Blocks.dirt);
        }
        world.setBlock(i + 6, j + 23, k + 28, Blocks.dirt);
        world.setBlock(i + 6, j + 24, k + 25, Blocks.glowstone);
        world.setBlock(i + 6, j + 24, k + 26, Blocks.dirt);
        world.setBlock(i + 6, j + 24, k + 27, Blocks.dirt);
        world.setBlock(i + 6, j + 24, k + 28, Blocks.dirt);
        world.setBlock(i + 6, j + 24, k + 29, Blocks.dirt);
        world.setBlock(i + 6, j + 25, k + 25, Blocks.grass);
        world.setBlock(i + 6, j + 25, k + 26, Blocks.grass);
        world.setBlock(i + 6, j + 25, k + 27, Blocks.grass);
        world.setBlock(i + 6, j + 25, k + 28, Blocks.grass);
        world.setBlock(i + 6, j + 25, k + 29, Blocks.grass);
        world.setBlock(i + 7, j + 22, k + 26, Dungeons.amethystCrystalized);
        world.setBlock(i + 7, j + 22, k + 27, Dungeons.amethystCrystalized);
        world.setBlock(i + 7, j + 22, k + 28, Dungeons.amethystCrystalized);
        world.setBlock(i + 7, j + 22, k + 29, Dungeons.amethystCrystalized);
        world.setBlock(i + 7, j + 22, k + 30, Dungeons.amethystCrystalized);
        world.setBlock(i + 7, j + 22, k + 31, Dungeons.amethystCrystalized);
        world.setBlock(i + 7, j + 23, k + 25, Blocks.dirt);
        world.setBlock(i + 7, j + 23, k + 26, Blocks.dirt);
        world.setBlock(i + 7, j + 23, k + 27, Blocks.dirt);
        world.setBlock(i + 7, j + 23, k + 28, Blocks.dirt);
        world.setBlock(i + 7, j + 23, k + 29, Blocks.dirt);
        world.setBlock(i + 7, j + 23, k + 30, Blocks.dirt);
        world.setBlock(i + 7, j + 23, k + 31, Blocks.dirt);
        world.setBlock(i + 7, j + 23, k + 32, Blocks.dirt);
        world.setBlock(i + 7, j + 24, k + 24, Blocks.dirt);
        world.setBlock(i + 7, j + 24, k + 25, Blocks.dirt);
        world.setBlock(i + 7, j + 24, k + 26, Blocks.dirt);
        world.setBlock(i + 7, j + 24, k + 27, Blocks.obsidian);
        world.setBlock(i + 7, j + 24, k + 28, Blocks.dirt);
        world.setBlock(i + 7, j + 24, k + 29, Blocks.dirt);
        world.setBlock(i + 7, j + 24, k + 30, Blocks.dirt);
        world.setBlock(i + 7, j + 24, k + 31, Blocks.dirt);
        world.setBlock(i + 7, j + 24, k + 32, Blocks.dirt);
        world.setBlock(i + 7, j + 24, k + 33, Blocks.dirt);
        world.setBlock(i + 7, j + 25, k + 23, Blocks.grass);
        world.setBlock(i + 7, j + 25, k + 24, Blocks.grass);
        world.setBlock(i + 7, j + 25, k + 25, Blocks.grass);
        world.setBlock(i + 7, j + 25, k + 26, Blocks.grass);
        world.setBlock(i + 7, j + 25, k + 27, Blocks.obsidian);
        world.setBlock(i + 7, j + 25, k + 28, Blocks.grass);
        world.setBlock(i + 7, j + 25, k + 29, Blocks.grass);
        world.setBlock(i + 7, j + 25, k + 30, Blocks.grass);
        world.setBlock(i + 7, j + 25, k + 31, Blocks.grass);
        world.setBlock(i + 7, j + 25, k + 32, Blocks.grass);
        world.setBlock(i + 7, j + 25, k + 33, Blocks.grass);
        world.setBlock(i + 7, j + 25, k + 34, Blocks.grass);
        world.setBlock(i + 7, j + 26, k + 27, Blocks.obsidian);
        world.setBlock(i + 7, j + 27, k + 27, Blocks.obsidian);
        world.setBlock(i + 7, j + 28, k + 27, Blocks.obsidian);
        world.setBlock(i + 7, j + 29, k + 27, Blocks.obsidian);
        world.setBlock(i + 7, j + 34, k + 27, Blocks.obsidian);
        world.setBlock(i + 7, j + 35, k + 27, Blocks.obsidian);
        world.setBlock(i + 7, j + 36, k + 27, Blocks.obsidian);
        world.setBlock(i + 7, j + 37, k + 27, Blocks.obsidian);
        world.setBlock(i + 7, j + 38, k + 27, Blocks.obsidian);
        world.setBlock(i + 7, j + 39, k + 27, Blocks.obsidian);
        world.setBlock(i + 8, j + 21, k + 26, Dungeons.amethystCrystalized);
        world.setBlock(i + 8, j + 21, k + 27, Dungeons.amethystCrystalized);
        world.setBlock(i + 8, j + 21, k + 28, Dungeons.amethystCrystalized);
        world.setBlock(i + 8, j + 21, k + 29, Dungeons.amethystCrystalized);
        world.setBlock(i + 8, j + 21, k + 30, Dungeons.amethystCrystalized);
        world.setBlock(i + 8, j + 21, k + 31, Dungeons.amethystCrystalized);
        world.setBlock(i + 8, j + 22, k + 23, Dungeons.amethystCrystalized);
        world.setBlock(i + 8, j + 22, k + 24, Dungeons.amethystCrystalized);
        world.setBlock(i + 8, j + 22, k + 25, Dungeons.amethystCrystalized);
        world.setBlock(i + 8, j + 22, k + 26, Dungeons.amethystCrystalized);
        world.setBlock(i + 8, j + 22, k + 27, Dungeons.amethystCrystalized);
        world.setBlock(i + 8, j + 22, k + 28, Dungeons.amethystCrystalized);
        world.setBlock(i + 8, j + 22, k + 29, Dungeons.amethystCrystalized);
        world.setBlock(i + 8, j + 22, k + 30, Dungeons.amethystCrystalized);
        world.setBlock(i + 8, j + 22, k + 31, Dungeons.amethystCrystalized);
        world.setBlock(i + 8, j + 22, k + 32, Dungeons.amethystCrystalized);
        world.setBlock(i + 8, j + 22, k + 33, Dungeons.amethystCrystalized);
        world.setBlock(i + 8, j + 23, k + 22, Blocks.dirt);
        world.setBlock(i + 8, j + 23, k + 23, Blocks.dirt);
        world.setBlock(i + 8, j + 23, k + 24, Blocks.dirt);
        world.setBlock(i + 8, j + 23, k + 25, Blocks.dirt);
        world.setBlock(i + 8, j + 23, k + 26, Blocks.dirt);
        world.setBlock(i + 8, j + 23, k + 27, Blocks.dirt);
        world.setBlock(i + 8, j + 23, k + 28, Blocks.dirt);
        world.setBlock(i + 8, j + 23, k + 29, Blocks.dirt);
        world.setBlock(i + 8, j + 23, k + 30, Blocks.dirt);
        world.setBlock(i + 8, j + 23, k + 31, Blocks.dirt);
        world.setBlock(i + 8, j + 23, k + 32, Blocks.dirt);
        world.setBlock(i + 8, j + 23, k + 33, Blocks.dirt);
        world.setBlock(i + 8, j + 23, k + 34, Blocks.dirt);
        world.setBlock(i + 8, j + 24, k + 22, Blocks.dirt);
        world.setBlock(i + 8, j + 24, k + 23, Blocks.dirt);
        world.setBlock(i + 8, j + 24, k + 24, Blocks.dirt);
        world.setBlock(i + 8, j + 24, k + 25, Blocks.dirt);
        world.setBlock(i + 8, j + 24, k + 26, Blocks.dirt);
        world.setBlock(i + 8, j + 24, k + 27, Blocks.obsidian);
        world.setBlock(i + 8, j + 24, k + 28, Blocks.dirt);
        world.setBlock(i + 8, j + 24, k + 29, Blocks.dirt);
        world.setBlock(i + 8, j + 24, k + 30, Blocks.dirt);
        world.setBlock(i + 8, j + 24, k + 31, Blocks.dirt);
        world.setBlock(i + 8, j + 24, k + 32, Blocks.dirt);
        world.setBlock(i + 8, j + 24, k + 33, Blocks.dirt);
        world.setBlock(i + 8, j + 24, k + 34, Blocks.dirt);
        world.setBlock(i + 8, j + 24, k + 35, Blocks.dirt);
        world.setBlock(i + 8, j + 25, k + 21, Blocks.grass);
        world.setBlock(i + 8, j + 25, k + 22, Blocks.grass);
        world.setBlock(i + 8, j + 25, k + 23, Blocks.grass);
        world.setBlock(i + 8, j + 25, k + 24, Blocks.grass);
        world.setBlock(i + 8, j + 25, k + 25, Blocks.grass);
        world.setBlock(i + 8, j + 25, k + 26, Blocks.grass);
        world.setBlock(i + 8, j + 25, k + 27, Blocks.grass);
        world.setBlock(i + 8, j + 25, k + 28, Blocks.grass);
        world.setBlock(i + 8, j + 25, k + 29, Blocks.grass);
        world.setBlock(i + 8, j + 25, k + 30, Blocks.grass);
        world.setBlock(i + 8, j + 25, k + 31, Blocks.grass);
        world.setBlock(i + 8, j + 25, k + 32, Blocks.grass);
        world.setBlock(i + 8, j + 25, k + 33, Blocks.grass);
        world.setBlock(i + 8, j + 25, k + 34, Blocks.grass);
        world.setBlock(i + 8, j + 25, k + 35, Blocks.grass);
        world.setBlock(i + 8, j + 25, k + 36, Blocks.grass);
        world.setBlock(i + 8, j + 29, k + 26, Blocks.obsidian);
        world.setBlock(i + 8, j + 29, k + 27, Blocks.obsidian);
        world.setBlock(i + 8, j + 29, k + 28, Blocks.obsidian);
        world.setBlock(i + 8, j + 30, k + 26, Blocks.obsidian);
        world.setBlock(i + 8, j + 30, k + 28, Blocks.obsidian);
        world.setBlock(i + 8, j + 31, k + 26, Blocks.obsidian);
        world.setBlock(i + 8, j + 31, k + 28, Blocks.obsidian);
        world.setBlock(i + 8, j + 32, k + 26, Blocks.obsidian);
        world.setBlock(i + 8, j + 32, k + 28, Blocks.obsidian);
        world.setBlock(i + 8, j + 33, k + 26, Blocks.obsidian);
        world.setBlock(i + 8, j + 33, k + 28, Blocks.obsidian);
        world.setBlock(i + 8, j + 34, k + 26, Blocks.obsidian);
        world.setBlock(i + 8, j + 34, k + 27, Blocks.obsidian);
        world.setBlock(i + 8, j + 34, k + 28, Blocks.obsidian);
        world.setBlock(i + 8, j + 39, k + 26, Blocks.obsidian);
        world.setBlock(i + 8, j + 39, k + 27, Blocks.obsidian);
        world.setBlock(i + 8, j + 39, k + 28, Blocks.obsidian);
        world.setBlock(i + 8, j + 40, k + 26, Blocks.obsidian);
        world.setBlock(i + 8, j + 40, k + 28, Blocks.obsidian);
        world.setBlock(i + 8, j + 41, k + 26, Blocks.obsidian);
        world.setBlock(i + 8, j + 41, k + 28, Blocks.obsidian);
        world.setBlock(i + 8, j + 42, k + 26, Blocks.obsidian);
        world.setBlock(i + 8, j + 42, k + 28, Blocks.obsidian);
        world.setBlock(i + 8, j + 43, k + 26, Blocks.obsidian);
        world.setBlock(i + 8, j + 43, k + 28, Blocks.obsidian);
        world.setBlock(i + 8, j + 44, k + 26, Blocks.obsidian);
        world.setBlock(i + 8, j + 44, k + 27, Blocks.obsidian);
        world.setBlock(i + 8, j + 44, k + 28, Blocks.obsidian);
        world.setBlock(i + 9, j + 21, k + 25, Dungeons.amethystCrystalized);
        world.setBlock(i + 9, j + 21, k + 26, Dungeons.amethystCrystalized);
        world.setBlock(i + 9, j + 21, k + 27, Dungeons.amethystCrystalized);
        world.setBlock(i + 9, j + 21, k + 28, Dungeons.amethystCrystalized);
        world.setBlock(i + 9, j + 21, k + 29, Dungeons.amethystCrystalized);
        world.setBlock(i + 9, j + 21, k + 30, Dungeons.amethystCrystalized);
        world.setBlock(i + 9, j + 21, k + 31, Dungeons.amethystCrystalized);
        world.setBlock(i + 9, j + 21, k + 32, Dungeons.amethystCrystalized);
        world.setBlock(i + 9, j + 21, k + 33, Dungeons.amethystCrystalized);
        world.setBlock(i + 9, j + 22, k + 20, Dungeons.amethystCrystalized);
        world.setBlock(i + 9, j + 22, k + 21, Dungeons.amethystCrystalized);
        world.setBlock(i + 9, j + 22, k + 22, Dungeons.amethystCrystalized);
        world.setBlock(i + 9, j + 22, k + 23, Dungeons.amethystCrystalized);
        world.setBlock(i + 9, j + 22, k + 24, Dungeons.amethystCrystalized);
        world.setBlock(i + 9, j + 22, k + 25, Dungeons.amethystCrystalized);
        world.setBlock(i + 9, j + 22, k + 26, Dungeons.amethystCrystalized);
        world.setBlock(i + 9, j + 22, k + 27, Dungeons.amethystCrystalized);
        world.setBlock(i + 9, j + 22, k + 28, Dungeons.amethystCrystalized);
        world.setBlock(i + 9, j + 22, k + 29, Dungeons.amethystCrystalized);
        world.setBlock(i + 9, j + 22, k + 30, Dungeons.amethystCrystalized);
        world.setBlock(i + 9, j + 22, k + 31, Dungeons.amethystCrystalized);
        world.setBlock(i + 9, j + 22, k + 32, Dungeons.amethystCrystalized);
        world.setBlock(i + 9, j + 22, k + 33, Dungeons.amethystCrystalized);
        world.setBlock(i + 9, j + 22, k + 34, Dungeons.amethystCrystalized);
        world.setBlock(i + 9, j + 22, k + 35, Dungeons.amethystCrystalized);
        world.setBlock(i + 9, j + 22, k + 36, Dungeons.amethystCrystalized);
        world.setBlock(i + 9, j + 22, k + 37, Dungeons.amethystCrystalized);
        world.setBlock(i + 9, j + 22, k + 38, Dungeons.amethystCrystalized);
        world.setBlock(i + 9, j + 23, k + 18, Blocks.glowstone);
        world.setBlock(i + 9, j + 23, k + 19, Blocks.dirt);
        world.setBlock(i + 9, j + 23, k + 20, Blocks.dirt);
        world.setBlock(i + 9, j + 23, k + 21, Blocks.dirt);
        world.setBlock(i + 9, j + 23, k + 22, Blocks.dirt);
        world.setBlock(i + 9, j + 23, k + 23, Blocks.dirt);
        world.setBlock(i + 9, j + 23, k + 24, Blocks.dirt);
        world.setBlock(i + 9, j + 23, k + 25, Blocks.dirt);
        world.setBlock(i + 9, j + 23, k + 26, Blocks.dirt);
        world.setBlock(i + 9, j + 23, k + 27, Blocks.dirt);
        world.setBlock(i + 9, j + 23, k + 28, Blocks.dirt);
        world.setBlock(i + 9, j + 23, k + 29, Blocks.dirt);
        world.setBlock(i + 9, j + 23, k + 30, Blocks.dirt);
        world.setBlock(i + 9, j + 23, k + 31, Blocks.dirt);
        world.setBlock(i + 9, j + 23, k + 32, Blocks.dirt);
        world.setBlock(i + 9, j + 23, k + 33, Blocks.dirt);
        world.setBlock(i + 9, j + 23, k + 34, Blocks.dirt);
        world.setBlock(i + 9, j + 23, k + 35, Blocks.dirt);
        world.setBlock(i + 9, j + 23, k + 36, Blocks.dirt);
        world.setBlock(i + 9, j + 23, k + 37, Blocks.dirt);
        world.setBlock(i + 9, j + 23, k + 38, Blocks.dirt);
        world.setBlock(i + 9, j + 24, k + 18, Blocks.dirt);
        world.setBlock(i + 9, j + 24, k + 19, Blocks.dirt);
        world.setBlock(i + 9, j + 24, k + 20, Blocks.dirt);
        world.setBlock(i + 9, j + 24, k + 21, Blocks.dirt);
        world.setBlock(i + 9, j + 24, k + 22, Blocks.dirt);
        world.setBlock(i + 9, j + 24, k + 23, Blocks.dirt);
        world.setBlock(i + 9, j + 24, k + 24, Blocks.dirt);
        world.setBlock(i + 9, j + 24, k + 25, Blocks.dirt);
        world.setBlock(i + 9, j + 24, k + 26, Blocks.dirt);
        world.setBlock(i + 9, j + 24, k + 27, Blocks.obsidian);
        world.setBlock(i + 9, j + 24, k + 28, Blocks.dirt);
        world.setBlock(i + 9, j + 24, k + 29, Blocks.dirt);
        world.setBlock(i + 9, j + 24, k + 30, Blocks.dirt);
        world.setBlock(i + 9, j + 24, k + 31, Blocks.dirt);
        world.setBlock(i + 9, j + 24, k + 32, Blocks.dirt);
        world.setBlock(i + 9, j + 24, k + 33, Blocks.dirt);
        world.setBlock(i + 9, j + 24, k + 34, Blocks.dirt);
        world.setBlock(i + 9, j + 24, k + 35, Blocks.dirt);
        world.setBlock(i + 9, j + 24, k + 36, Blocks.dirt);
        world.setBlock(i + 9, j + 24, k + 37, Blocks.dirt);
        world.setBlock(i + 9, j + 24, k + 38, Blocks.dirt);
        world.setBlock(i + 9, j + 25, k + 18, Blocks.grass);
        world.setBlock(i + 9, j + 25, k + 19, Blocks.grass);
        world.setBlock(i + 9, j + 25, k + 20, Blocks.grass);
        world.setBlock(i + 9, j + 25, k + 21, Blocks.grass);
        world.setBlock(i + 9, j + 25, k + 22, Blocks.grass);
        world.setBlock(i + 9, j + 25, k + 23, Blocks.grass);
        world.setBlock(i + 9, j + 25, k + 24, Blocks.grass);
        world.setBlock(i + 9, j + 25, k + 25, Blocks.grass);
        world.setBlock(i + 9, j + 25, k + 26, Blocks.grass);
        world.setBlock(i + 9, j + 25, k + 27, Blocks.obsidian);
        world.setBlock(i + 9, j + 25, k + 28, Blocks.grass);
        world.setBlock(i + 9, j + 25, k + 29, Blocks.grass);
        world.setBlock(i + 9, j + 25, k + 30, Blocks.grass);
        world.setBlock(i + 9, j + 25, k + 31, Blocks.grass);
        world.setBlock(i + 9, j + 25, k + 32, Blocks.grass);
        world.setBlock(i + 9, j + 25, k + 33, Blocks.grass);
        world.setBlock(i + 9, j + 25, k + 34, Blocks.grass);
        world.setBlock(i + 9, j + 25, k + 35, Blocks.grass);
        world.setBlock(i + 9, j + 25, k + 36, Blocks.grass);
        world.setBlock(i + 9, j + 25, k + 37, Blocks.grass);
        world.setBlock(i + 9, j + 25, k + 38, Blocks.grass);
        world.setBlock(i + 9, j + 26, k + 27, Blocks.obsidian);
        world.setBlock(i + 9, j + 27, k + 27, Blocks.obsidian);
        world.setBlock(i + 9, j + 28, k + 27, Blocks.obsidian);
        world.setBlock(i + 9, j + 29, k + 27, Blocks.obsidian);
        world.setBlock(i + 9, j + 34, k + 27, Blocks.obsidian);
        world.setBlock(i + 9, j + 35, k + 27, Blocks.obsidian);
        world.setBlock(i + 9, j + 36, k + 27, Blocks.obsidian);
        world.setBlock(i + 9, j + 37, k + 27, Blocks.obsidian);
        world.setBlock(i + 9, j + 38, k + 27, Blocks.obsidian);
        world.setBlock(i + 9, j + 39, k + 27, Blocks.obsidian);
        world.setBlock(i + 10, j + 20, k + 27, Dungeons.amethystCrystalized);
        world.setBlock(i + 10, j + 20, k + 28, Dungeons.amethystCrystalized);
        world.setBlock(i + 10, j + 20, k + 29, Dungeons.amethystCrystalized);
        world.setBlock(i + 10, j + 20, k + 30, Dungeons.amethystCrystalized);
        world.setBlock(i + 10, j + 21, k + 23, Dungeons.amethystCrystalized);
        world.setBlock(i + 10, j + 21, k + 24, Dungeons.amethystCrystalized);
        world.setBlock(i + 10, j + 21, k + 25, Dungeons.amethystCrystalized);
        world.setBlock(i + 10, j + 21, k + 26, Dungeons.amethystCrystalized);
        world.setBlock(i + 10, j + 21, k + 27, Dungeons.amethystCrystalized);
        world.setBlock(i + 10, j + 21, k + 28, Dungeons.amethystCrystalized);
        world.setBlock(i + 10, j + 21, k + 29, Dungeons.amethystCrystalized);
        world.setBlock(i + 10, j + 21, k + 30, Dungeons.amethystCrystalized);
        world.setBlock(i + 10, j + 21, k + 31, Dungeons.amethystCrystalized);
        world.setBlock(i + 10, j + 21, k + 32, Dungeons.amethystCrystalized);
        world.setBlock(i + 10, j + 21, k + 33, Dungeons.amethystCrystalized);
        world.setBlock(i + 10, j + 21, k + 34, Dungeons.amethystCrystalized);
        world.setBlock(i + 10, j + 21, k + 35, Dungeons.amethystCrystalized);
        world.setBlock(i + 10, j + 22, k + 17, Dungeons.amethystCrystalized);
        world.setBlock(i + 10, j + 22, k + 18, Dungeons.amethystCrystalized);
        world.setBlock(i + 10, j + 22, k + 19, Dungeons.amethystCrystalized);
        world.setBlock(i + 10, j + 22, k + 20, Dungeons.amethystCrystalized);
        world.setBlock(i + 10, j + 22, k + 21, Dungeons.amethystCrystalized);
        world.setBlock(i + 10, j + 22, k + 22, Dungeons.amethystCrystalized);
        world.setBlock(i + 10, j + 22, k + 23, Dungeons.amethystCrystalized);
        world.setBlock(i + 10, j + 22, k + 24, Dungeons.amethystCrystalized);
        world.setBlock(i + 10, j + 22, k + 25, Dungeons.amethystCrystalized);
        world.setBlock(i + 10, j + 22, k + 26, Dungeons.amethystCrystalized);
        world.setBlock(i + 10, j + 22, k + 27, Dungeons.amethystCrystalized);
        world.setBlock(i + 10, j + 22, k + 28, Dungeons.amethystCrystalized);
        world.setBlock(i + 10, j + 22, k + 29, Dungeons.amethystCrystalized);
        world.setBlock(i + 10, j + 22, k + 30, Dungeons.amethystCrystalized);
        world.setBlock(i + 10, j + 22, k + 31, Dungeons.amethystCrystalized);
        world.setBlock(i + 10, j + 22, k + 32, Dungeons.amethystCrystalized);
        world.setBlock(i + 10, j + 22, k + 33, Dungeons.amethystCrystalized);
        world.setBlock(i + 10, j + 22, k + 34, Dungeons.amethystCrystalized);
        world.setBlock(i + 10, j + 22, k + 35, Dungeons.amethystCrystalized);
        world.setBlock(i + 10, j + 22, k + 36, Dungeons.amethystCrystalized);
        world.setBlock(i + 10, j + 22, k + 37, Dungeons.amethystCrystalized);
        world.setBlock(i + 10, j + 22, k + 38, Dungeons.amethystCrystalized);
        world.setBlock(i + 10, j + 23, k + 17, Blocks.dirt);
        world.setBlock(i + 10, j + 23, k + 18, Blocks.dirt);
        world.setBlock(i + 10, j + 23, k + 19, Blocks.dirt);
        world.setBlock(i + 10, j + 23, k + 20, Blocks.dirt);
        world.setBlock(i + 10, j + 23, k + 21, Blocks.dirt);
        world.setBlock(i + 10, j + 23, k + 22, Blocks.dirt);
        world.setBlock(i + 10, j + 23, k + 23, Blocks.dirt);
        world.setBlock(i + 10, j + 23, k + 24, Blocks.dirt);
        world.setBlock(i + 10, j + 23, k + 25, Blocks.dirt);
        world.setBlock(i + 10, j + 23, k + 26, Blocks.dirt);
        world.setBlock(i + 10, j + 23, k + 27, Blocks.dirt);
        world.setBlock(i + 10, j + 23, k + 28, Blocks.dirt);
        world.setBlock(i + 10, j + 23, k + 29, Blocks.dirt);
        world.setBlock(i + 10, j + 23, k + 30, Blocks.dirt);
        world.setBlock(i + 10, j + 23, k + 31, Blocks.dirt);
        world.setBlock(i + 10, j + 23, k + 32, Blocks.dirt);
        world.setBlock(i + 10, j + 23, k + 33, Blocks.dirt);
        world.setBlock(i + 10, j + 23, k + 34, Blocks.dirt);
        world.setBlock(i + 10, j + 23, k + 35, Blocks.dirt);
        world.setBlock(i + 10, j + 23, k + 36, Blocks.dirt);
        world.setBlock(i + 10, j + 23, k + 37, Blocks.dirt);
        world.setBlock(i + 10, j + 23, k + 38, Blocks.dirt);
        world.setBlock(i + 10, j + 24, k + 16, Blocks.dirt);
        world.setBlock(i + 10, j + 24, k + 17, Blocks.dirt);
        world.setBlock(i + 10, j + 24, k + 18, Blocks.dirt);
        world.setBlock(i + 10, j + 24, k + 19, Blocks.dirt);
        world.setBlock(i + 10, j + 24, k + 20, Blocks.dirt);
        world.setBlock(i + 10, j + 24, k + 21, Blocks.dirt);
        world.setBlock(i + 10, j + 24, k + 22, Blocks.dirt);
        world.setBlock(i + 10, j + 24, k + 23, Blocks.dirt);
        world.setBlock(i + 10, j + 24, k + 24, Blocks.dirt);
        world.setBlock(i + 10, j + 24, k + 25, Blocks.dirt);
        world.setBlock(i + 10, j + 24, k + 26, Blocks.dirt);
        world.setBlock(i + 10, j + 24, k + 27, Blocks.dirt);
        world.setBlock(i + 10, j + 24, k + 28, Blocks.dirt);
        world.setBlock(i + 10, j + 24, k + 29, Blocks.dirt);
        world.setBlock(i + 10, j + 24, k + 30, Blocks.dirt);
        world.setBlock(i + 10, j + 24, k + 31, Blocks.dirt);
        world.setBlock(i + 10, j + 24, k + 32, Blocks.dirt);
        world.setBlock(i + 10, j + 24, k + 33, Blocks.dirt);
        world.setBlock(i + 10, j + 24, k + 34, Blocks.dirt);
        world.setBlock(i + 10, j + 24, k + 35, Blocks.dirt);
        world.setBlock(i + 10, j + 24, k + 36, Blocks.dirt);
        world.setBlock(i + 10, j + 24, k + 37, Blocks.dirt);
        world.setBlock(i + 10, j + 24, k + 38, Blocks.dirt);
        world.setBlock(i + 10, j + 24, k + 39, Blocks.dirt);
        world.setBlock(i + 10, j + 24, k + 40, Blocks.dirt);
        world.setBlock(i + 10, j + 25, k + 16, Blocks.grass);
        world.setBlock(i + 10, j + 25, k + 17, Blocks.grass);
        world.setBlock(i + 10, j + 25, k + 18, Blocks.grass);
        world.setBlock(i + 10, j + 25, k + 19, Blocks.grass);
        world.setBlock(i + 10, j + 25, k + 20, Blocks.grass);
        world.setBlock(i + 10, j + 25, k + 21, Blocks.grass);
        world.setBlock(i + 10, j + 25, k + 22, Blocks.grass);
        world.setBlock(i + 10, j + 25, k + 23, Blocks.grass);
        world.setBlock(i + 10, j + 25, k + 24, Blocks.grass);
        world.setBlock(i + 10, j + 25, k + 25, Blocks.grass);
        world.setBlock(i + 10, j + 25, k + 26, Blocks.grass);
        world.setBlock(i + 10, j + 25, k + 27, Blocks.grass);
        world.setBlock(i + 10, j + 25, k + 28, Blocks.grass);
        world.setBlock(i + 10, j + 25, k + 29, Blocks.grass);
        world.setBlock(i + 10, j + 25, k + 30, Blocks.grass);
        world.setBlock(i + 10, j + 25, k + 31, Blocks.grass);
        world.setBlock(i + 10, j + 25, k + 32, Blocks.grass);
        world.setBlock(i + 10, j + 25, k + 33, Blocks.grass);
        world.setBlock(i + 10, j + 25, k + 34, Blocks.grass);
        world.setBlock(i + 10, j + 25, k + 35, Blocks.grass);
        world.setBlock(i + 10, j + 25, k + 36, Blocks.grass);
        world.setBlock(i + 10, j + 25, k + 37, Blocks.grass);
        world.setBlock(i + 10, j + 25, k + 38, Blocks.grass);
        world.setBlock(i + 10, j + 25, k + 39, Blocks.grass);
        world.setBlock(i + 10, j + 25, k + 40, Blocks.grass);
        world.setBlock(i + 10, j + 25, k + 41, Blocks.grass);
        world.setBlock(i + 11, j + 19, k + 27, Dungeons.amethystCrystalized);
        world.setBlock(i + 11, j + 19, k + 28, Dungeons.amethystCrystalized);
        world.setBlock(i + 11, j + 19, k + 29, Dungeons.amethystCrystalized);
        world.setBlock(i + 11, j + 20, k + 25, Dungeons.amethystCrystalized);
        world.setBlock(i + 11, j + 20, k + 26, Dungeons.amethystCrystalized);
        world.setBlock(i + 11, j + 20, k + 27, Dungeons.amethystCrystalized);
        world.setBlock(i + 11, j + 20, k + 28, Dungeons.amethystCrystalized);
        world.setBlock(i + 11, j + 20, k + 29, Dungeons.amethystCrystalized);
        world.setBlock(i + 11, j + 20, k + 30, Dungeons.amethystCrystalized);
        world.setBlock(i + 11, j + 20, k + 31, Dungeons.amethystCrystalized);
        world.setBlock(i + 11, j + 20, k + 32, Dungeons.amethystCrystalized);
        world.setBlock(i + 11, j + 21, k + 21, Dungeons.amethystCrystalized);
        world.setBlock(i + 11, j + 21, k + 22, Dungeons.amethystCrystalized);
        world.setBlock(i + 11, j + 21, k + 23, Dungeons.amethystCrystalized);
        world.setBlock(i + 11, j + 21, k + 24, Dungeons.amethystCrystalized);
        world.setBlock(i + 11, j + 21, k + 25, Dungeons.amethystCrystalized);
        world.setBlock(i + 11, j + 21, k + 26, Dungeons.amethystCrystalized);
        world.setBlock(i + 11, j + 21, k + 27, Dungeons.amethystCrystalized);
        world.setBlock(i + 11, j + 21, k + 28, Dungeons.amethystCrystalized);
        world.setBlock(i + 11, j + 21, k + 29, Dungeons.amethystCrystalized);
        world.setBlock(i + 11, j + 21, k + 30, Dungeons.amethystCrystalized);
        world.setBlock(i + 11, j + 21, k + 31, Dungeons.amethystCrystalized);
        world.setBlock(i + 11, j + 21, k + 32, Dungeons.amethystCrystalized);
        world.setBlock(i + 11, j + 21, k + 33, Dungeons.amethystCrystalized);
        world.setBlock(i + 11, j + 21, k + 34, Dungeons.amethystCrystalized);
        world.setBlock(i + 11, j + 21, k + 35, Dungeons.amethystCrystalized);
        world.setBlock(i + 11, j + 21, k + 36, Dungeons.amethystCrystalized);
        world.setBlock(i + 11, j + 21, k + 37, Dungeons.amethystCrystalized);
        world.setBlock(i + 11, j + 22, k + 16, Dungeons.amethystCrystalized);
        world.setBlock(i + 11, j + 22, k + 17, Dungeons.amethystCrystalized);
        world.setBlock(i + 11, j + 22, k + 18, Dungeons.amethystCrystalized);
        world.setBlock(i + 11, j + 22, k + 19, Dungeons.amethystCrystalized);
        world.setBlock(i + 11, j + 22, k + 20, Dungeons.amethystCrystalized);
        world.setBlock(i + 11, j + 22, k + 21, Dungeons.amethystCrystalized);
        world.setBlock(i + 11, j + 22, k + 22, Dungeons.amethystCrystalized);
        world.setBlock(i + 11, j + 22, k + 23, Dungeons.amethystCrystalized);
        world.setBlock(i + 11, j + 22, k + 24, Dungeons.amethystCrystalized);
        world.setBlock(i + 11, j + 22, k + 25, Dungeons.amethystCrystalized);
        world.setBlock(i + 11, j + 22, k + 26, Dungeons.amethystCrystalized);
        world.setBlock(i + 11, j + 22, k + 27, Dungeons.amethystCrystalized);
        world.setBlock(i + 11, j + 22, k + 28, Dungeons.amethystCrystalized);
        world.setBlock(i + 11, j + 22, k + 29, Dungeons.amethystCrystalized);
        world.setBlock(i + 11, j + 22, k + 30, Dungeons.amethystCrystalized);
        world.setBlock(i + 11, j + 22, k + 31, Dungeons.amethystCrystalized);
        world.setBlock(i + 11, j + 22, k + 32, Dungeons.amethystCrystalized);
        world.setBlock(i + 11, j + 22, k + 33, Dungeons.amethystCrystalized);
        world.setBlock(i + 11, j + 22, k + 34, Dungeons.amethystCrystalized);
        world.setBlock(i + 11, j + 22, k + 35, Dungeons.amethystCrystalized);
        world.setBlock(i + 11, j + 22, k + 36, Dungeons.amethystCrystalized);
        world.setBlock(i + 11, j + 22, k + 37, Dungeons.amethystCrystalized);
        world.setBlock(i + 11, j + 22, k + 38, Dungeons.amethystCrystalized);
        world.setBlock(i + 11, j + 23, k + 16, Blocks.dirt);
        world.setBlock(i + 11, j + 23, k + 17, Blocks.dirt);
        world.setBlock(i + 11, j + 23, k + 18, Blocks.dirt);
        world.setBlock(i + 11, j + 23, k + 19, Blocks.dirt);
        world.setBlock(i + 11, j + 23, k + 20, Blocks.dirt);
        world.setBlock(i + 11, j + 23, k + 21, Blocks.dirt);
        world.setBlock(i + 11, j + 23, k + 22, Blocks.dirt);
        world.setBlock(i + 11, j + 23, k + 23, Blocks.dirt);
        world.setBlock(i + 11, j + 23, k + 24, Blocks.dirt);
        world.setBlock(i + 11, j + 23, k + 25, Blocks.dirt);
        world.setBlock(i + 11, j + 23, k + 26, Blocks.dirt);
        world.setBlock(i + 11, j + 23, k + 27, Blocks.dirt);
        world.setBlock(i + 11, j + 23, k + 28, Blocks.dirt);
        world.setBlock(i + 11, j + 23, k + 29, Blocks.dirt);
        world.setBlock(i + 11, j + 23, k + 30, Blocks.dirt);
        world.setBlock(i + 11, j + 23, k + 31, Blocks.dirt);
        world.setBlock(i + 11, j + 23, k + 32, Blocks.dirt);
        world.setBlock(i + 11, j + 23, k + 33, Blocks.dirt);
        world.setBlock(i + 11, j + 23, k + 34, Blocks.dirt);
        world.setBlock(i + 11, j + 23, k + 35, Blocks.dirt);
        world.setBlock(i + 11, j + 23, k + 36, Blocks.dirt);
        world.setBlock(i + 11, j + 23, k + 37, Blocks.dirt);
        world.setBlock(i + 11, j + 23, k + 38, Blocks.dirt);
        world.setBlock(i + 11, j + 24, k + 15, Blocks.dirt);
        world.setBlock(i + 11, j + 24, k + 16, Blocks.dirt);
        world.setBlock(i + 11, j + 24, k + 17, Blocks.dirt);
        world.setBlock(i + 11, j + 24, k + 18, Blocks.dirt);
        world.setBlock(i + 11, j + 24, k + 19, Blocks.dirt);
        world.setBlock(i + 11, j + 24, k + 20, Blocks.dirt);
        world.setBlock(i + 11, j + 24, k + 21, Blocks.dirt);
        world.setBlock(i + 11, j + 24, k + 22, Blocks.dirt);
        world.setBlock(i + 11, j + 24, k + 23, Blocks.dirt);
        world.setBlock(i + 11, j + 24, k + 24, Blocks.dirt);
        world.setBlock(i + 11, j + 24, k + 25, Blocks.dirt);
        world.setBlock(i + 11, j + 24, k + 26, Blocks.dirt);
        world.setBlock(i + 11, j + 24, k + 27, Blocks.dirt);
        world.setBlock(i + 11, j + 24, k + 28, Blocks.dirt);
        world.setBlock(i + 11, j + 24, k + 29, Blocks.dirt);
        world.setBlock(i + 11, j + 24, k + 30, Blocks.dirt);
        world.setBlock(i + 11, j + 24, k + 31, Blocks.dirt);
        world.setBlock(i + 11, j + 24, k + 32, Blocks.dirt);
        world.setBlock(i + 11, j + 24, k + 33, Blocks.dirt);
        world.setBlock(i + 11, j + 24, k + 34, Blocks.dirt);
        world.setBlock(i + 11, j + 24, k + 35, Blocks.dirt);
        world.setBlock(i + 11, j + 24, k + 36, Blocks.dirt);
        world.setBlock(i + 11, j + 24, k + 37, Blocks.dirt);
        world.setBlock(i + 11, j + 24, k + 38, Blocks.dirt);
        world.setBlock(i + 11, j + 24, k + 39, Blocks.dirt);
        world.setBlock(i + 11, j + 24, k + 40, Blocks.dirt);
        world.setBlock(i + 11, j + 24, k + 41, Blocks.dirt);
        world.setBlock(i + 11, j + 24, k + 42, Blocks.dirt);
        world.setBlock(i + 11, j + 24, k + 43, Blocks.dirt);
        world.setBlock(i + 11, j + 25, k + 14, Blocks.grass);
        world.setBlock(i + 11, j + 25, k + 15, Blocks.grass);
        world.setBlock(i + 11, j + 25, k + 16, Blocks.grass);
        world.setBlock(i + 11, j + 25, k + 17, Blocks.grass);
        world.setBlock(i + 11, j + 25, k + 18, Blocks.grass);
        world.setBlock(i + 11, j + 25, k + 19, Blocks.grass);
        world.setBlock(i + 11, j + 25, k + 20, Blocks.grass);
        world.setBlock(i + 11, j + 25, k + 21, Blocks.grass);
        world.setBlock(i + 11, j + 25, k + 22, Blocks.grass);
        world.setBlock(i + 11, j + 25, k + 23, Blocks.grass);
        world.setBlock(i + 11, j + 25, k + 24, Blocks.grass);
        world.setBlock(i + 11, j + 25, k + 25, Blocks.grass);
        world.setBlock(i + 11, j + 25, k + 26, Blocks.grass);
        world.setBlock(i + 11, j + 25, k + 27, Blocks.grass);
        world.setBlock(i + 11, j + 25, k + 28, Blocks.grass);
        world.setBlock(i + 11, j + 25, k + 29, Blocks.grass);
        world.setBlock(i + 11, j + 25, k + 30, Blocks.grass);
        world.setBlock(i + 11, j + 25, k + 31, Blocks.grass);
        world.setBlock(i + 11, j + 25, k + 32, Blocks.grass);
        world.setBlock(i + 11, j + 25, k + 33, Blocks.grass);
        world.setBlock(i + 11, j + 25, k + 34, Blocks.grass);
        world.setBlock(i + 11, j + 25, k + 35, Blocks.grass);
        world.setBlock(i + 11, j + 25, k + 36, Blocks.grass);
        world.setBlock(i + 11, j + 25, k + 37, Blocks.grass);
        world.setBlock(i + 11, j + 25, k + 38, Blocks.grass);
        world.setBlock(i + 11, j + 25, k + 39, Blocks.grass);
        world.setBlock(i + 11, j + 25, k + 40, Blocks.grass);
        world.setBlock(i + 11, j + 25, k + 41, Blocks.grass);
        world.setBlock(i + 11, j + 25, k + 42, Blocks.grass);
        world.setBlock(i + 11, j + 25, k + 43, Blocks.grass);
        world.setBlock(i + 11, j + 25, k + 44, Blocks.grass);
        world.setBlock(i + 12, j + 18, k + 28, Dungeons.amethystCrystalized);
        world.setBlock(i + 12, j + 19, k + 26, Dungeons.amethystCrystalized);
        world.setBlock(i + 12, j + 19, k + 27, Dungeons.amethystCrystalized);
        world.setBlock(i + 12, j + 19, k + 28, Dungeons.amethystCrystalized);
        world.setBlock(i + 12, j + 19, k + 29, Dungeons.amethystCrystalized);
        world.setBlock(i + 12, j + 19, k + 30, Dungeons.amethystCrystalized);
        world.setBlock(i + 12, j + 19, k + 31, Dungeons.amethystCrystalized);
        world.setBlock(i + 12, j + 20, k + 24, Dungeons.amethystCrystalized);
        world.setBlock(i + 12, j + 20, k + 25, Dungeons.amethystCrystalized);
        world.setBlock(i + 12, j + 20, k + 26, Dungeons.amethystCrystalized);
        world.setBlock(i + 12, j + 20, k + 27, Dungeons.amethystCrystalized);
        world.setBlock(i + 12, j + 20, k + 28, Dungeons.amethystCrystalized);
        world.setBlock(i + 12, j + 20, k + 29, Dungeons.amethystCrystalized);
        world.setBlock(i + 12, j + 20, k + 30, Dungeons.amethystCrystalized);
        world.setBlock(i + 12, j + 20, k + 31, Dungeons.amethystCrystalized);
        world.setBlock(i + 12, j + 20, k + 32, Dungeons.amethystCrystalized);
        world.setBlock(i + 12, j + 20, k + 33, Dungeons.amethystCrystalized);
        world.setBlock(i + 12, j + 21, k + 18, Dungeons.amethystCrystalized);
        world.setBlock(i + 12, j + 21, k + 19, Dungeons.amethystCrystalized);
        world.setBlock(i + 12, j + 21, k + 20, Dungeons.amethystCrystalized);
        world.setBlock(i + 12, j + 21, k + 21, Dungeons.amethystCrystalized);
        world.setBlock(i + 12, j + 21, k + 22, Dungeons.amethystCrystalized);
        world.setBlock(i + 12, j + 21, k + 23, Dungeons.amethystCrystalized);
        world.setBlock(i + 12, j + 21, k + 24, Dungeons.amethystCrystalized);
        world.setBlock(i + 12, j + 21, k + 25, Dungeons.amethystCrystalized);
        world.setBlock(i + 12, j + 21, k + 26, Dungeons.amethystCrystalized);
        world.setBlock(i + 12, j + 21, k + 27, Dungeons.amethystCrystalized);
        world.setBlock(i + 12, j + 21, k + 28, Dungeons.amethystCrystalized);
        world.setBlock(i + 12, j + 21, k + 29, Dungeons.amethystCrystalized);
        world.setBlock(i + 12, j + 21, k + 30, Dungeons.amethystCrystalized);
        world.setBlock(i + 12, j + 21, k + 31, Dungeons.amethystCrystalized);
        world.setBlock(i + 12, j + 21, k + 32, Dungeons.amethystCrystalized);
        world.setBlock(i + 12, j + 21, k + 33, Dungeons.amethystCrystalized);
        world.setBlock(i + 12, j + 21, k + 34, Dungeons.amethystCrystalized);
        world.setBlock(i + 12, j + 21, k + 35, Dungeons.amethystCrystalized);
        world.setBlock(i + 12, j + 21, k + 36, Dungeons.amethystCrystalized);
        world.setBlock(i + 12, j + 21, k + 37, Dungeons.amethystCrystalized);
        world.setBlock(i + 12, j + 21, k + 38, Dungeons.amethystCrystalized);
        world.setBlock(i + 12, j + 21, k + 39, Dungeons.amethystCrystalized);
        world.setBlock(i + 12, j + 22, k + 13, Dungeons.amethystCrystalized);
        world.setBlock(i + 12, j + 22, k + 14, Dungeons.amethystCrystalized);
        world.setBlock(i + 12, j + 22, k + 15, Dungeons.amethystCrystalized);
        world.setBlock(i + 12, j + 22, k + 16, Dungeons.amethystCrystalized);
        world.setBlock(i + 12, j + 22, k + 17, Dungeons.amethystCrystalized);
        world.setBlock(i + 12, j + 22, k + 18, Dungeons.amethystCrystalized);
        world.setBlock(i + 12, j + 22, k + 19, Dungeons.amethystCrystalized);
        world.setBlock(i + 12, j + 22, k + 20, Dungeons.amethystCrystalized);
        world.setBlock(i + 12, j + 22, k + 21, Dungeons.amethystCrystalized);
        world.setBlock(i + 12, j + 22, k + 22, Dungeons.amethystCrystalized);
        world.setBlock(i + 12, j + 22, k + 23, Dungeons.amethystCrystalized);
        world.setBlock(i + 12, j + 22, k + 24, Dungeons.amethystCrystalized);
        world.setBlock(i + 12, j + 22, k + 25, Dungeons.amethystCrystalized);
        world.setBlock(i + 12, j + 22, k + 26, Dungeons.amethystCrystalized);
        world.setBlock(i + 12, j + 22, k + 27, Dungeons.amethystCrystalized);
        world.setBlock(i + 12, j + 22, k + 28, Dungeons.amethystCrystalized);
        world.setBlock(i + 12, j + 22, k + 29, Dungeons.amethystCrystalized);
        world.setBlock(i + 12, j + 22, k + 30, Dungeons.amethystCrystalized);
        world.setBlock(i + 12, j + 22, k + 31, Dungeons.amethystCrystalized);
        world.setBlock(i + 12, j + 22, k + 32, Dungeons.amethystCrystalized);
        world.setBlock(i + 12, j + 22, k + 33, Dungeons.amethystCrystalized);
        world.setBlock(i + 12, j + 22, k + 34, Dungeons.amethystCrystalized);
        world.setBlock(i + 12, j + 22, k + 35, Dungeons.amethystCrystalized);
        world.setBlock(i + 12, j + 22, k + 36, Dungeons.amethystCrystalized);
        world.setBlock(i + 12, j + 22, k + 37, Dungeons.amethystCrystalized);
        world.setBlock(i + 12, j + 22, k + 38, Dungeons.amethystCrystalized);
        world.setBlock(i + 12, j + 22, k + 39, Dungeons.amethystCrystalized);
        world.setBlock(i + 12, j + 22, k + 40, Dungeons.amethystCrystalized);
        world.setBlock(i + 12, j + 22, k + 41, Dungeons.amethystCrystalized);
        world.setBlock(i + 12, j + 22, k + 42, Dungeons.amethystCrystalized);
        world.setBlock(i + 12, j + 22, k + 43, Dungeons.amethystCrystalized);
        world.setBlock(i + 12, j + 22, k + 44, Dungeons.amethystCrystalized);
        world.setBlock(i + 12, j + 23, k + 13, Blocks.dirt);
        world.setBlock(i + 12, j + 23, k + 14, Blocks.dirt);
        world.setBlock(i + 12, j + 23, k + 15, Blocks.dirt);
        world.setBlock(i + 12, j + 23, k + 16, Blocks.dirt);
        world.setBlock(i + 12, j + 23, k + 17, Blocks.dirt);
        world.setBlock(i + 12, j + 23, k + 18, Blocks.dirt);
        world.setBlock(i + 12, j + 23, k + 19, Blocks.dirt);
        world.setBlock(i + 12, j + 23, k + 20, Blocks.dirt);
        world.setBlock(i + 12, j + 23, k + 21, Blocks.dirt);
        world.setBlock(i + 12, j + 23, k + 22, Blocks.dirt);
        world.setBlock(i + 12, j + 23, k + 23, Blocks.dirt);
        world.setBlock(i + 12, j + 23, k + 24, Blocks.dirt);
        world.setBlock(i + 12, j + 23, k + 25, Blocks.dirt);
        world.setBlock(i + 12, j + 23, k + 26, Blocks.dirt);
        world.setBlock(i + 12, j + 23, k + 27, Blocks.dirt);
        world.setBlock(i + 12, j + 23, k + 28, Blocks.dirt);
        world.setBlock(i + 12, j + 23, k + 29, Blocks.dirt);
        world.setBlock(i + 12, j + 23, k + 30, Blocks.dirt);
        world.setBlock(i + 12, j + 23, k + 31, Blocks.dirt);
        world.setBlock(i + 12, j + 23, k + 32, Blocks.dirt);
        world.setBlock(i + 12, j + 23, k + 33, Blocks.dirt);
        world.setBlock(i + 12, j + 23, k + 34, Blocks.dirt);
        world.setBlock(i + 12, j + 23, k + 35, Blocks.dirt);
        world.setBlock(i + 12, j + 23, k + 36, Blocks.dirt);
        world.setBlock(i + 12, j + 23, k + 37, Blocks.dirt);
        world.setBlock(i + 12, j + 23, k + 38, Blocks.dirt);
        world.setBlock(i + 12, j + 23, k + 39, Blocks.dirt);
        world.setBlock(i + 12, j + 23, k + 40, Blocks.dirt);
        world.setBlock(i + 12, j + 23, k + 41, Blocks.dirt);
        world.setBlock(i + 12, j + 23, k + 42, Blocks.dirt);
        world.setBlock(i + 12, j + 23, k + 43, Blocks.dirt);
        world.setBlock(i + 12, j + 23, k + 44, Blocks.dirt);
        world.setBlock(i + 12, j + 24, k + 12, Blocks.dirt);
        world.setBlock(i + 12, j + 24, k + 13, Blocks.dirt);
        world.setBlock(i + 12, j + 24, k + 14, Blocks.dirt);
        world.setBlock(i + 12, j + 24, k + 15, Blocks.dirt);
        world.setBlock(i + 12, j + 24, k + 16, Blocks.dirt);
        world.setBlock(i + 12, j + 24, k + 17, Blocks.dirt);
        world.setBlock(i + 12, j + 24, k + 18, Blocks.dirt);
        world.setBlock(i + 12, j + 24, k + 19, Blocks.dirt);
        world.setBlock(i + 12, j + 24, k + 20, Blocks.dirt);
        world.setBlock(i + 12, j + 24, k + 21, Blocks.dirt);
        world.setBlock(i + 12, j + 24, k + 22, Blocks.dirt);
        world.setBlock(i + 12, j + 24, k + 23, Blocks.dirt);
        world.setBlock(i + 12, j + 24, k + 24, Blocks.dirt);
        world.setBlock(i + 12, j + 24, k + 25, Blocks.dirt);
        world.setBlock(i + 12, j + 24, k + 26, Blocks.dirt);
        world.setBlock(i + 12, j + 24, k + 27, Blocks.dirt);
        world.setBlock(i + 12, j + 24, k + 28, Blocks.dirt);
        world.setBlock(i + 12, j + 24, k + 29, Blocks.dirt);
        world.setBlock(i + 12, j + 24, k + 30, Blocks.dirt);
        world.setBlock(i + 12, j + 24, k + 31, Blocks.dirt);
        world.setBlock(i + 12, j + 24, k + 32, Blocks.dirt);
        world.setBlock(i + 12, j + 24, k + 33, Blocks.dirt);
        world.setBlock(i + 12, j + 24, k + 34, Blocks.dirt);
        world.setBlock(i + 12, j + 24, k + 35, Blocks.dirt);
        world.setBlock(i + 12, j + 24, k + 36, Blocks.dirt);
        world.setBlock(i + 12, j + 24, k + 37, Blocks.dirt);
        world.setBlock(i + 12, j + 24, k + 38, Blocks.dirt);
        world.setBlock(i + 12, j + 24, k + 39, Blocks.dirt);
        world.setBlock(i + 12, j + 24, k + 40, Blocks.dirt);
        world.setBlock(i + 12, j + 24, k + 41, Blocks.dirt);
        world.setBlock(i + 12, j + 24, k + 42, Blocks.dirt);
        world.setBlock(i + 12, j + 24, k + 43, Blocks.dirt);
        world.setBlock(i + 12, j + 24, k + 44, Blocks.dirt);
        world.setBlock(i + 12, j + 25, k + 12, Blocks.grass);
        world.setBlock(i + 12, j + 25, k + 13, Blocks.grass);
        world.setBlock(i + 12, j + 25, k + 14, Blocks.grass);
        world.setBlock(i + 12, j + 25, k + 15, Blocks.grass);
        world.setBlock(i + 12, j + 25, k + 16, Blocks.grass);
        world.setBlock(i + 12, j + 25, k + 17, Blocks.grass);
        world.setBlock(i + 12, j + 25, k + 18, Blocks.grass);
        world.setBlock(i + 12, j + 25, k + 19, Blocks.grass);
        world.setBlock(i + 12, j + 25, k + 20, Blocks.grass);
        world.setBlock(i + 12, j + 25, k + 21, Blocks.grass);
        world.setBlock(i + 12, j + 25, k + 22, Blocks.grass);
        world.setBlock(i + 12, j + 25, k + 23, Blocks.grass);
        world.setBlock(i + 12, j + 25, k + 24, Blocks.grass);
        world.setBlock(i + 12, j + 25, k + 25, Blocks.grass);
        world.setBlock(i + 12, j + 25, k + 26, Blocks.grass);
        world.setBlock(i + 12, j + 25, k + 27, Blocks.grass);
        world.setBlock(i + 12, j + 25, k + 28, Blocks.grass);
        world.setBlock(i + 12, j + 25, k + 29, Blocks.grass);
        world.setBlock(i + 12, j + 25, k + 30, Blocks.grass);
        world.setBlock(i + 12, j + 25, k + 31, Blocks.grass);
        world.setBlock(i + 12, j + 25, k + 32, Blocks.grass);
        world.setBlock(i + 12, j + 25, k + 33, Blocks.grass);
        world.setBlock(i + 12, j + 25, k + 34, Blocks.grass);
        world.setBlock(i + 12, j + 25, k + 35, Blocks.grass);
        world.setBlock(i + 12, j + 25, k + 36, Blocks.grass);
        world.setBlock(i + 12, j + 25, k + 37, Blocks.grass);
        world.setBlock(i + 12, j + 25, k + 38, Blocks.grass);
        world.setBlock(i + 12, j + 25, k + 39, Blocks.grass);
        world.setBlock(i + 12, j + 25, k + 40, Blocks.grass);
        world.setBlock(i + 12, j + 25, k + 41, Blocks.grass);
        world.setBlock(i + 12, j + 25, k + 42, Blocks.grass);
        world.setBlock(i + 12, j + 25, k + 43, Blocks.grass);
        world.setBlock(i + 12, j + 25, k + 44, Blocks.grass);
        world.setBlock(i + 12, j + 25, k + 45, Blocks.grass);
        world.setBlock(i + 12, j + 26, k + 12, Blocks.fence);
        world.setBlock(i + 12, j + 26, k + 44, Blocks.fence);
        world.setBlock(i + 12, j + 27, k + 12, Blocks.fence);
        world.setBlock(i + 12, j + 27, k + 26, Blocks.glowstone);
        world.setBlock(i + 12, j + 27, k + 30, Blocks.glowstone);
        world.setBlock(i + 12, j + 27, k + 44, Blocks.fence);
        world.setBlock(i + 12, j + 28, k + 12, Blocks.glowstone);
        world.setBlock(i + 12, j + 28, k + 26, Blocks.fence);
        world.setBlock(i + 12, j + 28, k + 30, Blocks.fence);
        world.setBlock(i + 12, j + 28, k + 44, Blocks.glowstone);
        world.setBlock(i + 13, j + 18, k + 25, Dungeons.amethystCrystalized);
        world.setBlock(i + 13, j + 18, k + 26, Dungeons.amethystCrystalized);
        world.setBlock(i + 13, j + 18, k + 27, Dungeons.amethystCrystalized);
        world.setBlock(i + 13, j + 18, k + 28, Dungeons.amethystCrystalized);
        world.setBlock(i + 13, j + 18, k + 29, Dungeons.amethystCrystalized);
        world.setBlock(i + 13, j + 18, k + 30, Dungeons.amethystCrystalized);
        world.setBlock(i + 13, j + 18, k + 31, Dungeons.amethystCrystalized);
        world.setBlock(i + 13, j + 19, k + 23, Blocks.glowstone);
        world.setBlock(i + 13, j + 19, k + 24, Dungeons.amethystCrystalized);
        world.setBlock(i + 13, j + 19, k + 25, Dungeons.amethystCrystalized);
        world.setBlock(i + 13, j + 19, k + 26, Dungeons.amethystCrystalized);
        world.setBlock(i + 13, j + 19, k + 27, Dungeons.amethystCrystalized);
        world.setBlock(i + 13, j + 19, k + 28, Dungeons.amethystCrystalized);
        world.setBlock(i + 13, j + 19, k + 29, Dungeons.amethystCrystalized);
        world.setBlock(i + 13, j + 19, k + 30, Dungeons.amethystCrystalized);
        world.setBlock(i + 13, j + 19, k + 31, Dungeons.amethystCrystalized);
        world.setBlock(i + 13, j + 19, k + 32, Dungeons.amethystCrystalized);
        world.setBlock(i + 13, j + 19, k + 33, Dungeons.amethystCrystalized);
        world.setBlock(i + 13, j + 20, k + 21, Dungeons.amethystCrystalized);
        world.setBlock(i + 13, j + 20, k + 22, Dungeons.amethystCrystalized);
        world.setBlock(i + 13, j + 20, k + 23, Dungeons.amethystCrystalized);
        world.setBlock(i + 13, j + 20, k + 24, Dungeons.amethystCrystalized);
        world.setBlock(i + 13, j + 20, k + 25, Dungeons.amethystCrystalized);
        world.setBlock(i + 13, j + 20, k + 26, Dungeons.amethystCrystalized);
        world.setBlock(i + 13, j + 20, k + 27, Dungeons.amethystCrystalized);
        world.setBlock(i + 13, j + 20, k + 28, Dungeons.amethystCrystalized);
        world.setBlock(i + 13, j + 20, k + 29, Dungeons.amethystCrystalized);
        world.setBlock(i + 13, j + 20, k + 30, Dungeons.amethystCrystalized);
        world.setBlock(i + 13, j + 20, k + 31, Dungeons.amethystCrystalized);
        world.setBlock(i + 13, j + 20, k + 32, Dungeons.amethystCrystalized);
        world.setBlock(i + 13, j + 20, k + 33, Dungeons.amethystCrystalized);
        world.setBlock(i + 13, j + 20, k + 34, Dungeons.amethystCrystalized);
        world.setBlock(i + 13, j + 20, k + 35, Dungeons.amethystCrystalized);
        world.setBlock(i + 13, j + 20, k + 36, Blocks.glowstone);
        world.setBlock(i + 13, j + 21, k + 15, Dungeons.amethystCrystalized);
        world.setBlock(i + 13, j + 21, k + 16, Dungeons.amethystCrystalized);
        world.setBlock(i + 13, j + 21, k + 17, Dungeons.amethystCrystalized);
        world.setBlock(i + 13, j + 21, k + 18, Dungeons.amethystCrystalized);
        world.setBlock(i + 13, j + 21, k + 19, Dungeons.amethystCrystalized);
        world.setBlock(i + 13, j + 21, k + 20, Dungeons.amethystCrystalized);
        world.setBlock(i + 13, j + 21, k + 21, Dungeons.amethystCrystalized);
        world.setBlock(i + 13, j + 21, k + 22, Dungeons.amethystCrystalized);
        world.setBlock(i + 13, j + 21, k + 23, Dungeons.amethystCrystalized);
        world.setBlock(i + 13, j + 21, k + 24, Dungeons.amethystCrystalized);
        world.setBlock(i + 13, j + 21, k + 25, Dungeons.amethystCrystalized);
        world.setBlock(i + 13, j + 21, k + 26, Dungeons.amethystCrystalized);
        world.setBlock(i + 13, j + 21, k + 27, Dungeons.amethystCrystalized);
        world.setBlock(i + 13, j + 21, k + 28, Dungeons.amethystCrystalized);
        world.setBlock(i + 13, j + 21, k + 29, Dungeons.amethystCrystalized);
        world.setBlock(i + 13, j + 21, k + 30, Dungeons.amethystCrystalized);
        world.setBlock(i + 13, j + 21, k + 31, Dungeons.amethystCrystalized);
        world.setBlock(i + 13, j + 21, k + 32, Dungeons.amethystCrystalized);
        world.setBlock(i + 13, j + 21, k + 33, Dungeons.amethystCrystalized);
        world.setBlock(i + 13, j + 21, k + 34, Dungeons.amethystCrystalized);
        world.setBlock(i + 13, j + 21, k + 35, Dungeons.amethystCrystalized);
        world.setBlock(i + 13, j + 21, k + 36, Dungeons.amethystCrystalized);
        world.setBlock(i + 13, j + 21, k + 37, Dungeons.amethystCrystalized);
        world.setBlock(i + 13, j + 21, k + 38, Dungeons.amethystCrystalized);
        world.setBlock(i + 13, j + 21, k + 39, Dungeons.amethystCrystalized);
        world.setBlock(i + 13, j + 21, k + 40, Dungeons.amethystCrystalized);
        world.setBlock(i + 13, j + 21, k + 41, Dungeons.amethystCrystalized);
        world.setBlock(i + 13, j + 22, k + 13, Dungeons.amethystCrystalized);
        world.setBlock(i + 13, j + 22, k + 14, Dungeons.amethystCrystalized);
        world.setBlock(i + 13, j + 22, k + 15, Dungeons.amethystCrystalized);
        world.setBlock(i + 13, j + 22, k + 16, Dungeons.amethystCrystalized);
        world.setBlock(i + 13, j + 22, k + 17, Dungeons.amethystCrystalized);
        world.setBlock(i + 13, j + 22, k + 18, Dungeons.amethystCrystalized);
        world.setBlock(i + 13, j + 22, k + 19, Dungeons.amethystCrystalized);
        world.setBlock(i + 13, j + 22, k + 20, Dungeons.amethystCrystalized);
        world.setBlock(i + 13, j + 22, k + 21, Dungeons.amethystCrystalized);
        world.setBlock(i + 13, j + 22, k + 22, Dungeons.amethystCrystalized);
        world.setBlock(i + 13, j + 22, k + 23, Dungeons.amethystCrystalized);
        world.setBlock(i + 13, j + 22, k + 24, Dungeons.amethystCrystalized);
        world.setBlock(i + 13, j + 22, k + 25, Dungeons.amethystCrystalized);
        world.setBlock(i + 13, j + 22, k + 26, Dungeons.amethystCrystalized);
        world.setBlock(i + 13, j + 22, k + 27, Dungeons.amethystCrystalized);
        world.setBlock(i + 13, j + 22, k + 28, Dungeons.amethystCrystalized);
        world.setBlock(i + 13, j + 22, k + 29, Dungeons.amethystCrystalized);
        world.setBlock(i + 13, j + 22, k + 30, Dungeons.amethystCrystalized);
        world.setBlock(i + 13, j + 22, k + 31, Dungeons.amethystCrystalized);
        world.setBlock(i + 13, j + 22, k + 32, Dungeons.amethystCrystalized);
        world.setBlock(i + 13, j + 22, k + 33, Dungeons.amethystCrystalized);
        world.setBlock(i + 13, j + 22, k + 34, Dungeons.amethystCrystalized);
        world.setBlock(i + 13, j + 22, k + 35, Dungeons.amethystCrystalized);
        world.setBlock(i + 13, j + 22, k + 36, Dungeons.amethystCrystalized);
        world.setBlock(i + 13, j + 22, k + 37, Dungeons.amethystCrystalized);
        world.setBlock(i + 13, j + 22, k + 38, Dungeons.amethystCrystalized);
        world.setBlock(i + 13, j + 22, k + 39, Dungeons.amethystCrystalized);
        world.setBlock(i + 13, j + 22, k + 40, Dungeons.amethystCrystalized);
        world.setBlock(i + 13, j + 22, k + 41, Dungeons.amethystCrystalized);
        world.setBlock(i + 13, j + 22, k + 42, Dungeons.amethystCrystalized);
        world.setBlock(i + 13, j + 22, k + 43, Dungeons.amethystCrystalized);
        world.setBlock(i + 13, j + 22, k + 44, Dungeons.amethystCrystalized);
        world.setBlock(i + 13, j + 23, k + 12, Blocks.dirt);
        world.setBlock(i + 13, j + 23, k + 13, Blocks.dirt);
        world.setBlock(i + 13, j + 23, k + 14, Blocks.dirt);
        world.setBlock(i + 13, j + 23, k + 15, Blocks.dirt);
        world.setBlock(i + 13, j + 23, k + 16, Blocks.dirt);
        world.setBlock(i + 13, j + 23, k + 17, Blocks.dirt);
        world.setBlock(i + 13, j + 23, k + 18, Blocks.dirt);
        world.setBlock(i + 13, j + 23, k + 19, Blocks.dirt);
        world.setBlock(i + 13, j + 23, k + 20, Blocks.dirt);
        world.setBlock(i + 13, j + 23, k + 21, Blocks.dirt);
        world.setBlock(i + 13, j + 23, k + 22, Blocks.dirt);
        world.setBlock(i + 13, j + 23, k + 23, Blocks.dirt);
        world.setBlock(i + 13, j + 23, k + 24, Blocks.dirt);
        world.setBlock(i + 13, j + 23, k + 25, Blocks.dirt);
        world.setBlock(i + 13, j + 23, k + 26, Blocks.dirt);
        world.setBlock(i + 13, j + 23, k + 27, Blocks.dirt);
        world.setBlock(i + 13, j + 23, k + 28, Blocks.dirt);
        world.setBlock(i + 13, j + 23, k + 29, Blocks.dirt);
        world.setBlock(i + 13, j + 23, k + 30, Blocks.dirt);
        world.setBlock(i + 13, j + 23, k + 31, Blocks.dirt);
        world.setBlock(i + 13, j + 23, k + 32, Blocks.dirt);
        world.setBlock(i + 13, j + 23, k + 33, Blocks.dirt);
        world.setBlock(i + 13, j + 23, k + 34, Blocks.dirt);
        world.setBlock(i + 13, j + 23, k + 35, Blocks.dirt);
        world.setBlock(i + 13, j + 23, k + 36, Blocks.dirt);
        world.setBlock(i + 13, j + 23, k + 37, Blocks.dirt);
        world.setBlock(i + 13, j + 23, k + 38, Blocks.dirt);
        world.setBlock(i + 13, j + 23, k + 39, Blocks.dirt);
        world.setBlock(i + 13, j + 23, k + 40, Blocks.dirt);
        world.setBlock(i + 13, j + 23, k + 41, Blocks.dirt);
        world.setBlock(i + 13, j + 23, k + 42, Blocks.dirt);
        world.setBlock(i + 13, j + 23, k + 43, Blocks.dirt);
        world.setBlock(i + 13, j + 23, k + 44, Blocks.dirt);
        world.setBlock(i + 13, j + 24, k + 12, Blocks.dirt);
        world.setBlock(i + 13, j + 24, k + 13, Blocks.dirt);
        world.setBlock(i + 13, j + 24, k + 14, Blocks.dirt);
        world.setBlock(i + 13, j + 24, k + 15, Blocks.dirt);
        world.setBlock(i + 13, j + 24, k + 16, Blocks.dirt);
        world.setBlock(i + 13, j + 24, k + 17, Blocks.dirt);
        world.setBlock(i + 13, j + 24, k + 18, Blocks.dirt);
        world.setBlock(i + 13, j + 24, k + 19, Blocks.dirt);
        world.setBlock(i + 13, j + 24, k + 20, Blocks.dirt);
        world.setBlock(i + 13, j + 24, k + 21, Blocks.dirt);
        world.setBlock(i + 13, j + 24, k + 22, Blocks.dirt);
        world.setBlock(i + 13, j + 24, k + 23, Blocks.dirt);
        world.setBlock(i + 13, j + 24, k + 24, Blocks.dirt);
        world.setBlock(i + 13, j + 24, k + 25, Blocks.dirt);
        world.setBlock(i + 13, j + 24, k + 26, Blocks.dirt);
        world.setBlock(i + 13, j + 24, k + 27, Blocks.dirt);
        world.setBlock(i + 13, j + 24, k + 28, Blocks.dirt);
        world.setBlock(i + 13, j + 24, k + 29, Blocks.dirt);
        world.setBlock(i + 13, j + 24, k + 30, Blocks.dirt);
        world.setBlock(i + 13, j + 24, k + 31, Blocks.dirt);
        world.setBlock(i + 13, j + 24, k + 32, Blocks.dirt);
        world.setBlock(i + 13, j + 24, k + 33, Blocks.dirt);
        world.setBlock(i + 13, j + 24, k + 34, Blocks.dirt);
        world.setBlock(i + 13, j + 24, k + 35, Blocks.dirt);
        world.setBlock(i + 13, j + 24, k + 36, Blocks.dirt);
        world.setBlock(i + 13, j + 24, k + 37, Blocks.dirt);
        world.setBlock(i + 13, j + 24, k + 38, Blocks.dirt);
        world.setBlock(i + 13, j + 24, k + 39, Blocks.dirt);
        world.setBlock(i + 13, j + 24, k + 40, Blocks.dirt);
        world.setBlock(i + 13, j + 24, k + 41, Blocks.dirt);
        world.setBlock(i + 13, j + 24, k + 42, Blocks.dirt);
        world.setBlock(i + 13, j + 24, k + 43, Blocks.dirt);
        world.setBlock(i + 13, j + 24, k + 44, Blocks.dirt);
        world.setBlock(i + 13, j + 24, k + 45, Blocks.dirt);
        world.setBlock(i + 13, j + 25, k + 12, Blocks.grass);
        world.setBlock(i + 13, j + 25, k + 13, Blocks.dirt);
        world.setBlock(i + 13, j + 25, k + 14, Blocks.dirt);
        world.setBlock(i + 13, j + 25, k + 15, Blocks.dirt);
        world.setBlock(i + 13, j + 25, k + 16, Blocks.dirt);
        world.setBlock(i + 13, j + 25, k + 17, Blocks.dirt);
        world.setBlock(i + 13, j + 25, k + 18, Blocks.dirt);
        world.setBlock(i + 13, j + 25, k + 19, Blocks.dirt);
        world.setBlock(i + 13, j + 25, k + 20, Blocks.dirt);
        world.setBlock(i + 13, j + 25, k + 21, Blocks.dirt);
        world.setBlock(i + 13, j + 25, k + 22, Blocks.dirt);
        world.setBlock(i + 13, j + 25, k + 23, Blocks.dirt);
        world.setBlock(i + 13, j + 25, k + 24, Blocks.dirt);
        world.setBlock(i + 13, j + 25, k + 25, Blocks.dirt);
        world.setBlock(i + 13, j + 25, k + 26, Blocks.dirt);
        world.setBlock(i + 13, j + 25, k + 30, Blocks.dirt);
        world.setBlock(i + 13, j + 25, k + 31, Blocks.dirt);
        world.setBlock(i + 13, j + 25, k + 32, Blocks.dirt);
        world.setBlock(i + 13, j + 25, k + 33, Blocks.dirt);
        world.setBlock(i + 13, j + 25, k + 34, Blocks.dirt);
        world.setBlock(i + 13, j + 25, k + 35, Blocks.dirt);
        world.setBlock(i + 13, j + 25, k + 36, Blocks.dirt);
        world.setBlock(i + 13, j + 25, k + 37, Blocks.dirt);
        world.setBlock(i + 13, j + 25, k + 38, Blocks.dirt);
        world.setBlock(i + 13, j + 25, k + 39, Blocks.dirt);
        world.setBlock(i + 13, j + 25, k + 40, Blocks.dirt);
        world.setBlock(i + 13, j + 25, k + 41, Blocks.dirt);
        world.setBlock(i + 13, j + 25, k + 42, Blocks.dirt);
        world.setBlock(i + 13, j + 25, k + 43, Blocks.dirt);
        world.setBlock(i + 13, j + 25, k + 44, Blocks.grass);
        world.setBlock(i + 13, j + 25, k + 45, Blocks.grass);
        world.setBlock(i + 13, j + 25, k + 46, Blocks.grass);
        world.setBlock(i + 13, j + 26, k + 13, Blocks.stonebrick);
        world.setBlock(i + 13, j + 26, k + 14, Blocks.stonebrick);
        world.setBlock(i + 13, j + 26, k + 15, Blocks.stonebrick);
        world.setBlock(i + 13, j + 26, k + 16, Blocks.stonebrick);
        world.setBlock(i + 13, j + 26, k + 17, Blocks.stonebrick);
        world.setBlock(i + 13, j + 26, k + 18, Blocks.stonebrick);
        world.setBlock(i + 13, j + 26, k + 19, Blocks.stonebrick);
        world.setBlock(i + 13, j + 26, k + 20, Blocks.stonebrick);
        world.setBlock(i + 13, j + 26, k + 21, Blocks.stonebrick);
        world.setBlock(i + 13, j + 26, k + 22, Blocks.stonebrick);
        world.setBlock(i + 13, j + 26, k + 23, Blocks.stonebrick);
        world.setBlock(i + 13, j + 26, k + 24, Blocks.stonebrick);
        world.setBlock(i + 13, j + 26, k + 25, Blocks.stonebrick);
        world.setBlock(i + 13, j + 26, k + 26, Blocks.stonebrick);
        world.setBlock(i + 13, j + 26, k + 27, Blocks.fence);
        world.setBlock(i + 13, j + 26, k + 28, Blocks.fence);
        world.setBlock(i + 13, j + 26, k + 29, Blocks.fence);
        world.setBlock(i + 13, j + 26, k + 30, Blocks.stonebrick);
        world.setBlock(i + 13, j + 26, k + 31, Blocks.stonebrick);
        world.setBlock(i + 13, j + 26, k + 32, Blocks.stonebrick);
        world.setBlock(i + 13, j + 26, k + 33, Blocks.stonebrick);
        world.setBlock(i + 13, j + 26, k + 34, Blocks.stonebrick);
        world.setBlock(i + 13, j + 26, k + 35, Blocks.stonebrick);
        world.setBlock(i + 13, j + 26, k + 36, Blocks.stonebrick);
        world.setBlock(i + 13, j + 26, k + 37, Blocks.stonebrick);
        world.setBlock(i + 13, j + 26, k + 38, Blocks.stonebrick);
        world.setBlock(i + 13, j + 26, k + 39, Blocks.stonebrick);
        world.setBlock(i + 13, j + 26, k + 40, Blocks.stonebrick);
        world.setBlock(i + 13, j + 26, k + 41, Blocks.stonebrick);
        world.setBlock(i + 13, j + 26, k + 42, Blocks.stonebrick);
        world.setBlock(i + 13, j + 26, k + 43, Blocks.stonebrick);
        world.setBlock(i + 13, j + 27, k + 13, Blocks.stonebrick);
        world.setBlock(i + 13, j + 27, k + 14, Blocks.stonebrick);
        world.setBlock(i + 13, j + 27, k + 15, Blocks.stonebrick);
        world.setBlock(i + 13, j + 27, k + 16, Blocks.stonebrick);
        world.setBlock(i + 13, j + 27, k + 17, Blocks.stonebrick);
        world.setBlock(i + 13, j + 27, k + 18, Blocks.stonebrick);
        world.setBlock(i + 13, j + 27, k + 19, Blocks.stonebrick);
        world.setBlock(i + 13, j + 27, k + 20, Blocks.stonebrick);
        world.setBlock(i + 13, j + 27, k + 21, Blocks.stonebrick);
        world.setBlock(i + 13, j + 27, k + 22, Blocks.stonebrick);
        world.setBlock(i + 13, j + 27, k + 23, Blocks.stonebrick);
        world.setBlock(i + 13, j + 27, k + 24, Blocks.stonebrick);
        world.setBlock(i + 13, j + 27, k + 25, Blocks.stonebrick);
        world.setBlock(i + 13, j + 27, k + 26, Blocks.stonebrick);
        world.setBlock(i + 13, j + 27, k + 27, Blocks.fence);
        world.setBlock(i + 13, j + 27, k + 28, Blocks.fence);
        world.setBlock(i + 13, j + 27, k + 29, Blocks.fence);
        world.setBlock(i + 13, j + 27, k + 30, Blocks.stonebrick);
        world.setBlock(i + 13, j + 27, k + 31, Blocks.stonebrick);
        world.setBlock(i + 13, j + 27, k + 32, Blocks.stonebrick);
        world.setBlock(i + 13, j + 27, k + 33, Blocks.stonebrick);
        world.setBlock(i + 13, j + 27, k + 34, Blocks.stonebrick);
        world.setBlock(i + 13, j + 27, k + 35, Blocks.stonebrick);
        world.setBlock(i + 13, j + 27, k + 36, Blocks.stonebrick);
        world.setBlock(i + 13, j + 27, k + 37, Blocks.stonebrick);
        world.setBlock(i + 13, j + 27, k + 38, Blocks.stonebrick);
        world.setBlock(i + 13, j + 27, k + 39, Blocks.stonebrick);
        world.setBlock(i + 13, j + 27, k + 40, Blocks.stonebrick);
        world.setBlock(i + 13, j + 27, k + 41, Blocks.stonebrick);
        world.setBlock(i + 13, j + 27, k + 42, Blocks.stonebrick);
        world.setBlock(i + 13, j + 27, k + 43, Blocks.stonebrick);
        world.setBlock(i + 13, j + 28, k + 13, Blocks.stonebrick);
        world.setBlock(i + 13, j + 28, k + 15, Blocks.stonebrick);
        world.setBlock(i + 13, j + 28, k + 17, Blocks.stonebrick);
        world.setBlock(i + 13, j + 28, k + 19, Blocks.stonebrick);
        world.setBlock(i + 13, j + 28, k + 21, Blocks.stonebrick);
        world.setBlock(i + 13, j + 28, k + 23, Blocks.stonebrick);
        world.setBlock(i + 13, j + 28, k + 25, Blocks.stonebrick);
        world.setBlock(i + 13, j + 28, k + 26, Blocks.stonebrick);
        world.setBlock(i + 13, j + 28, k + 27, Blocks.fence);
        world.setBlock(i + 13, j + 28, k + 28, Blocks.fence);
        world.setBlock(i + 13, j + 28, k + 29, Blocks.fence);
        world.setBlock(i + 13, j + 28, k + 30, Blocks.stonebrick);
        world.setBlock(i + 13, j + 28, k + 31, Blocks.stonebrick);
        world.setBlock(i + 13, j + 28, k + 33, Blocks.stonebrick);
        world.setBlock(i + 13, j + 28, k + 35, Blocks.stonebrick);
        world.setBlock(i + 13, j + 28, k + 37, Blocks.stonebrick);
        world.setBlock(i + 13, j + 28, k + 39, Blocks.stonebrick);
        world.setBlock(i + 13, j + 28, k + 40, Blocks.stonebrick);
        world.setBlock(i + 13, j + 28, k + 41, Blocks.stonebrick);
        world.setBlock(i + 13, j + 28, k + 42, Blocks.stonebrick);
        world.setBlock(i + 13, j + 28, k + 43, Blocks.stonebrick);
        world.setBlock(i + 13, j + 29, k + 26, Blocks.stonebrick);
        world.setBlock(i + 13, j + 29, k + 27, Blocks.stonebrick);
        world.setBlock(i + 13, j + 29, k + 28, Blocks.fence);
        world.setBlock(i + 13, j + 29, k + 29, Blocks.stonebrick);
        world.setBlock(i + 13, j + 29, k + 30, Blocks.stonebrick);
        world.setBlock(i + 13, j + 29, k + 39, Blocks.stonebrick);
        world.setBlock(i + 13, j + 29, k + 40, Blocks.stonebrick);
        world.setBlock(i + 13, j + 29, k + 41, Blocks.stonebrick);
        world.setBlock(i + 13, j + 29, k + 42, Blocks.stonebrick);
        world.setBlock(i + 13, j + 29, k + 43, Blocks.stonebrick);
        world.setBlock(i + 13, j + 30, k + 27, Blocks.stonebrick);
        world.setBlock(i + 13, j + 30, k + 28, Blocks.stonebrick);
        world.setBlock(i + 13, j + 30, k + 29, Blocks.stonebrick);
        world.setBlock(i + 13, j + 30, k + 39, Blocks.stonebrick);
        world.setBlock(i + 13, j + 30, k + 40, Blocks.stonebrick);
        world.setBlock(i + 13, j + 30, k + 41, Blocks.stonebrick);
        world.setBlock(i + 13, j + 30, k + 42, Blocks.stonebrick);
        world.setBlock(i + 13, j + 30, k + 43, Blocks.stonebrick);
        world.setBlock(i + 13, j + 31, k + 39, Blocks.stonebrick);
        world.setBlock(i + 13, j + 31, k + 41, Blocks.stonebrick);
        world.setBlock(i + 13, j + 31, k + 43, Blocks.stonebrick);
        world.setBlock(i + 14, j + 17, k + 25, Dungeons.amethystCrystalized);
        world.setBlock(i + 14, j + 17, k + 26, Dungeons.amethystCrystalized);
        world.setBlock(i + 14, j + 17, k + 27, Dungeons.amethystCrystalized);
        world.setBlock(i + 14, j + 17, k + 28, Dungeons.amethystCrystalized);
        world.setBlock(i + 14, j + 17, k + 29, Dungeons.amethystCrystalized);
        world.setBlock(i + 14, j + 17, k + 30, Dungeons.amethystCrystalized);
        world.setBlock(i + 14, j + 17, k + 31, Dungeons.amethystCrystalized);
        world.setBlock(i + 14, j + 18, k + 24, Dungeons.amethystCrystalized);
        world.setBlock(i + 14, j + 18, k + 25, Dungeons.amethystCrystalized);
        world.setBlock(i + 14, j + 18, k + 26, Dungeons.amethystCrystalized);
        world.setBlock(i + 14, j + 18, k + 27, Dungeons.amethystCrystalized);
        world.setBlock(i + 14, j + 18, k + 28, Dungeons.amethystCrystalized);
        world.setBlock(i + 14, j + 18, k + 29, Dungeons.amethystCrystalized);
        world.setBlock(i + 14, j + 18, k + 30, Dungeons.amethystCrystalized);
        world.setBlock(i + 14, j + 18, k + 31, Dungeons.amethystCrystalized);
        world.setBlock(i + 14, j + 18, k + 32, Dungeons.amethystCrystalized);
        world.setBlock(i + 14, j + 19, k + 21, Dungeons.amethystCrystalized);
        world.setBlock(i + 14, j + 19, k + 22, Dungeons.amethystCrystalized);
        world.setBlock(i + 14, j + 19, k + 23, Dungeons.amethystCrystalized);
        world.setBlock(i + 14, j + 19, k + 24, Dungeons.amethystCrystalized);
        world.setBlock(i + 14, j + 19, k + 25, Dungeons.amethystCrystalized);
        world.setBlock(i + 14, j + 19, k + 26, Dungeons.amethystCrystalized);
        world.setBlock(i + 14, j + 19, k + 27, Dungeons.amethystCrystalized);
        world.setBlock(i + 14, j + 19, k + 28, Dungeons.amethystCrystalized);
        world.setBlock(i + 14, j + 19, k + 29, Dungeons.amethystCrystalized);
        world.setBlock(i + 14, j + 19, k + 30, Dungeons.amethystCrystalized);
        world.setBlock(i + 14, j + 19, k + 31, Dungeons.amethystCrystalized);
        world.setBlock(i + 14, j + 19, k + 32, Dungeons.amethystCrystalized);
        world.setBlock(i + 14, j + 19, k + 33, Dungeons.amethystCrystalized);
        world.setBlock(i + 14, j + 19, k + 34, Dungeons.amethystCrystalized);
        world.setBlock(i + 14, j + 20, k + 18, Dungeons.amethystCrystalized);
        world.setBlock(i + 14, j + 20, k + 19, Dungeons.amethystCrystalized);
        world.setBlock(i + 14, j + 20, k + 20, Dungeons.amethystCrystalized);
        world.setBlock(i + 14, j + 20, k + 21, Dungeons.amethystCrystalized);
        world.setBlock(i + 14, j + 20, k + 22, Dungeons.amethystCrystalized);
        world.setBlock(i + 14, j + 20, k + 23, Dungeons.amethystCrystalized);
        world.setBlock(i + 14, j + 20, k + 24, Dungeons.amethystCrystalized);
        world.setBlock(i + 14, j + 20, k + 25, Dungeons.amethystCrystalized);
        world.setBlock(i + 14, j + 20, k + 26, Dungeons.amethystCrystalized);
        world.setBlock(i + 14, j + 20, k + 27, Dungeons.amethystCrystalized);
        world.setBlock(i + 14, j + 20, k + 28, Dungeons.amethystCrystalized);
        world.setBlock(i + 14, j + 20, k + 29, Dungeons.amethystCrystalized);
        world.setBlock(i + 14, j + 20, k + 30, Dungeons.amethystCrystalized);
        world.setBlock(i + 14, j + 20, k + 31, Dungeons.amethystCrystalized);
        world.setBlock(i + 14, j + 20, k + 32, Dungeons.amethystCrystalized);
        world.setBlock(i + 14, j + 20, k + 33, Dungeons.amethystCrystalized);
        world.setBlock(i + 14, j + 20, k + 34, Dungeons.amethystCrystalized);
        world.setBlock(i + 14, j + 20, k + 35, Dungeons.amethystCrystalized);
        world.setBlock(i + 14, j + 20, k + 36, Dungeons.amethystCrystalized);
        world.setBlock(i + 14, j + 20, k + 37, Dungeons.amethystCrystalized);
        world.setBlock(i + 14, j + 21, k + 14, Dungeons.amethystCrystalized);
        world.setBlock(i + 14, j + 21, k + 15, Dungeons.amethystCrystalized);
        world.setBlock(i + 14, j + 21, k + 16, Dungeons.amethystCrystalized);
        world.setBlock(i + 14, j + 21, k + 17, Dungeons.amethystCrystalized);
        world.setBlock(i + 14, j + 21, k + 18, Dungeons.amethystCrystalized);
        world.setBlock(i + 14, j + 21, k + 19, Dungeons.amethystCrystalized);
        world.setBlock(i + 14, j + 21, k + 20, Dungeons.amethystCrystalized);
        world.setBlock(i + 14, j + 21, k + 21, Dungeons.amethystCrystalized);
        world.setBlock(i + 14, j + 21, k + 22, Dungeons.amethystCrystalized);
        world.setBlock(i + 14, j + 21, k + 23, Dungeons.amethystCrystalized);
        world.setBlock(i + 14, j + 21, k + 24, Dungeons.amethystCrystalized);
        world.setBlock(i + 14, j + 21, k + 25, Dungeons.amethystCrystalized);
        world.setBlock(i + 14, j + 21, k + 26, Dungeons.amethystCrystalized);
        world.setBlock(i + 14, j + 21, k + 27, Dungeons.amethystCrystalized);
        world.setBlock(i + 14, j + 21, k + 28, Dungeons.amethystCrystalized);
        world.setBlock(i + 14, j + 21, k + 29, Dungeons.amethystCrystalized);
        world.setBlock(i + 14, j + 21, k + 30, Dungeons.amethystCrystalized);
        world.setBlock(i + 14, j + 21, k + 31, Dungeons.amethystCrystalized);
        world.setBlock(i + 14, j + 21, k + 32, Dungeons.amethystCrystalized);
        world.setBlock(i + 14, j + 21, k + 33, Dungeons.amethystCrystalized);
        world.setBlock(i + 14, j + 21, k + 34, Dungeons.amethystCrystalized);
        world.setBlock(i + 14, j + 21, k + 35, Dungeons.amethystCrystalized);
        world.setBlock(i + 14, j + 21, k + 36, Dungeons.amethystCrystalized);
        world.setBlock(i + 14, j + 21, k + 37, Dungeons.amethystCrystalized);
        world.setBlock(i + 14, j + 21, k + 38, Dungeons.amethystCrystalized);
        world.setBlock(i + 14, j + 21, k + 39, Dungeons.amethystCrystalized);
        world.setBlock(i + 14, j + 21, k + 40, Dungeons.amethystCrystalized);
        world.setBlock(i + 14, j + 21, k + 41, Dungeons.amethystCrystalized);
        world.setBlock(i + 14, j + 21, k + 42, Dungeons.amethystCrystalized);
        world.setBlock(i + 14, j + 21, k + 43, Dungeons.amethystCrystalized);
        world.setBlock(i + 14, j + 22, k + 12, Dungeons.amethystCrystalized);
        world.setBlock(i + 14, j + 22, k + 13, Dungeons.amethystCrystalized);
        world.setBlock(i + 14, j + 22, k + 14, Dungeons.amethystCrystalized);
        world.setBlock(i + 14, j + 22, k + 15, Dungeons.amethystCrystalized);
        world.setBlock(i + 14, j + 22, k + 16, Dungeons.amethystCrystalized);
        world.setBlock(i + 14, j + 22, k + 17, Dungeons.amethystCrystalized);
        world.setBlock(i + 14, j + 22, k + 18, Dungeons.amethystCrystalized);
        world.setBlock(i + 14, j + 22, k + 19, Dungeons.amethystCrystalized);
        world.setBlock(i + 14, j + 22, k + 20, Dungeons.amethystCrystalized);
        world.setBlock(i + 14, j + 22, k + 21, Dungeons.amethystCrystalized);
        world.setBlock(i + 14, j + 22, k + 22, Dungeons.amethystCrystalized);
        world.setBlock(i + 14, j + 22, k + 23, Dungeons.amethystCrystalized);
        world.setBlock(i + 14, j + 22, k + 24, Dungeons.amethystCrystalized);
        world.setBlock(i + 14, j + 22, k + 25, Dungeons.amethystCrystalized);
        world.setBlock(i + 14, j + 22, k + 26, Dungeons.amethystCrystalized);
        world.setBlock(i + 14, j + 22, k + 27, Dungeons.amethystCrystalized);
        world.setBlock(i + 14, j + 22, k + 28, Dungeons.amethystCrystalized);
        world.setBlock(i + 14, j + 22, k + 29, Dungeons.amethystCrystalized);
        world.setBlock(i + 14, j + 22, k + 30, Dungeons.amethystCrystalized);
        world.setBlock(i + 14, j + 22, k + 31, Dungeons.amethystCrystalized);
        world.setBlock(i + 14, j + 22, k + 32, Dungeons.amethystCrystalized);
        world.setBlock(i + 14, j + 22, k + 33, Dungeons.amethystCrystalized);
        world.setBlock(i + 14, j + 22, k + 34, Dungeons.amethystCrystalized);
        world.setBlock(i + 14, j + 22, k + 35, Dungeons.amethystCrystalized);
        world.setBlock(i + 14, j + 22, k + 36, Dungeons.amethystCrystalized);
        world.setBlock(i + 14, j + 22, k + 37, Dungeons.amethystCrystalized);
        world.setBlock(i + 14, j + 22, k + 38, Dungeons.amethystCrystalized);
        world.setBlock(i + 14, j + 22, k + 39, Dungeons.amethystCrystalized);
        world.setBlock(i + 14, j + 22, k + 40, Dungeons.amethystCrystalized);
        world.setBlock(i + 14, j + 22, k + 41, Dungeons.amethystCrystalized);
        world.setBlock(i + 14, j + 22, k + 42, Dungeons.amethystCrystalized);
        world.setBlock(i + 14, j + 22, k + 43, Dungeons.amethystCrystalized);
        world.setBlock(i + 14, j + 22, k + 44, Dungeons.amethystCrystalized);
        world.setBlock(i + 14, j + 23, k + 11, Blocks.dirt);
        world.setBlock(i + 14, j + 23, k + 12, Blocks.dirt);
        world.setBlock(i + 14, j + 23, k + 13, Blocks.dirt);
        world.setBlock(i + 14, j + 23, k + 14, Blocks.dirt);
        world.setBlock(i + 14, j + 23, k + 15, Blocks.dirt);
        world.setBlock(i + 14, j + 23, k + 16, Blocks.dirt);
        world.setBlock(i + 14, j + 23, k + 17, Blocks.dirt);
        world.setBlock(i + 14, j + 23, k + 18, Blocks.dirt);
        world.setBlock(i + 14, j + 23, k + 19, Blocks.dirt);
        world.setBlock(i + 14, j + 23, k + 20, Blocks.dirt);
        world.setBlock(i + 14, j + 23, k + 21, Blocks.dirt);
        world.setBlock(i + 14, j + 23, k + 22, Blocks.dirt);
        world.setBlock(i + 14, j + 23, k + 23, Blocks.dirt);
        world.setBlock(i + 14, j + 23, k + 24, Blocks.dirt);
        world.setBlock(i + 14, j + 23, k + 25, Blocks.dirt);
        world.setBlock(i + 14, j + 23, k + 26, Blocks.dirt);
        world.setBlock(i + 14, j + 23, k + 27, Blocks.dirt);
        world.setBlock(i + 14, j + 23, k + 28, Blocks.dirt);
        world.setBlock(i + 14, j + 23, k + 29, Blocks.dirt);
        world.setBlock(i + 14, j + 23, k + 30, Blocks.dirt);
        world.setBlock(i + 14, j + 23, k + 31, Blocks.dirt);
        world.setBlock(i + 14, j + 23, k + 32, Blocks.dirt);
        world.setBlock(i + 14, j + 23, k + 33, Blocks.dirt);
        world.setBlock(i + 14, j + 23, k + 34, Blocks.dirt);
        world.setBlock(i + 14, j + 23, k + 35, Blocks.dirt);
        world.setBlock(i + 14, j + 23, k + 36, Blocks.dirt);
        world.setBlock(i + 14, j + 23, k + 37, Blocks.dirt);
        world.setBlock(i + 14, j + 23, k + 38, Blocks.dirt);
        world.setBlock(i + 14, j + 23, k + 39, Blocks.dirt);
        world.setBlock(i + 14, j + 23, k + 40, Blocks.dirt);
        world.setBlock(i + 14, j + 23, k + 41, Blocks.dirt);
        world.setBlock(i + 14, j + 23, k + 42, Blocks.dirt);
        world.setBlock(i + 14, j + 23, k + 43, Blocks.dirt);
        world.setBlock(i + 14, j + 23, k + 44, Blocks.dirt);
        world.setBlock(i + 14, j + 23, k + 45, Blocks.dirt);
        world.setBlock(i + 14, j + 24, k + 11, Blocks.dirt);
        world.setBlock(i + 14, j + 24, k + 12, Blocks.dirt);
        world.setBlock(i + 14, j + 24, k + 13, Blocks.dirt);
        world.setBlock(i + 14, j + 24, k + 14, Blocks.dirt);
        world.setBlock(i + 14, j + 24, k + 15, Blocks.dirt);
        world.setBlock(i + 14, j + 24, k + 16, Blocks.dirt);
        world.setBlock(i + 14, j + 24, k + 17, Blocks.dirt);
        world.setBlock(i + 14, j + 24, k + 18, Blocks.dirt);
        world.setBlock(i + 14, j + 24, k + 19, Blocks.dirt);
        world.setBlock(i + 14, j + 24, k + 20, Blocks.dirt);
        world.setBlock(i + 14, j + 24, k + 21, Blocks.dirt);
        world.setBlock(i + 14, j + 24, k + 22, Blocks.dirt);
        world.setBlock(i + 14, j + 24, k + 23, Blocks.dirt);
        world.setBlock(i + 14, j + 24, k + 24, Blocks.dirt);
        world.setBlock(i + 14, j + 24, k + 25, Blocks.dirt);
        world.setBlock(i + 14, j + 24, k + 26, Blocks.dirt);
        world.setBlock(i + 14, j + 24, k + 27, Blocks.dirt);
        world.setBlock(i + 14, j + 24, k + 28, Blocks.dirt);
        world.setBlock(i + 14, j + 24, k + 29, Blocks.dirt);
        world.setBlock(i + 14, j + 24, k + 30, Blocks.dirt);
        world.setBlock(i + 14, j + 24, k + 31, Blocks.dirt);
        world.setBlock(i + 14, j + 24, k + 32, Blocks.dirt);
        world.setBlock(i + 14, j + 24, k + 33, Blocks.dirt);
        world.setBlock(i + 14, j + 24, k + 34, Blocks.dirt);
        world.setBlock(i + 14, j + 24, k + 35, Blocks.dirt);
        world.setBlock(i + 14, j + 24, k + 36, Blocks.dirt);
        world.setBlock(i + 14, j + 24, k + 37, Blocks.dirt);
        world.setBlock(i + 14, j + 24, k + 38, Blocks.dirt);
        world.setBlock(i + 14, j + 24, k + 39, Blocks.dirt);
        world.setBlock(i + 14, j + 24, k + 40, Blocks.dirt);
        world.setBlock(i + 14, j + 24, k + 41, Blocks.dirt);
        world.setBlock(i + 14, j + 24, k + 42, Blocks.dirt);
        world.setBlock(i + 14, j + 24, k + 43, Blocks.dirt);
        world.setBlock(i + 14, j + 24, k + 44, Blocks.dirt);
        world.setBlock(i + 14, j + 24, k + 45, Blocks.dirt);
        world.setBlock(i + 14, j + 24, k + 46, Blocks.dirt);
        world.setBlock(i + 14, j + 25, k + 11, Blocks.grass);
        world.setBlock(i + 14, j + 25, k + 12, Blocks.grass);
        world.setBlock(i + 14, j + 25, k + 13, Blocks.dirt);
        world.setBlock(i + 14, j + 25, k + 14, Blocks.dirt);
        world.setBlock(i + 14, j + 25, k + 15, Blocks.dirt);
        world.setBlock(i + 14, j + 25, k + 16, Blocks.dirt);
        world.setBlock(i + 14, j + 25, k + 17, Blocks.dirt);
        world.setBlock(i + 14, j + 25, k + 18, Blocks.dirt);
        world.setBlock(i + 14, j + 25, k + 19, Blocks.grass);
        world.setBlock(i + 14, j + 25, k + 20, Blocks.grass);
        world.setBlock(i + 14, j + 25, k + 21, Blocks.grass);
        world.setBlock(i + 14, j + 25, k + 22, Blocks.dirt);
        world.setBlock(i + 14, j + 25, k + 23, Blocks.dirt);
        world.setBlock(i + 14, j + 25, k + 24, Blocks.dirt);
        world.setBlock(i + 14, j + 25, k + 25, Blocks.dirt);
        world.setBlock(i + 14, j + 25, k + 26, Blocks.dirt);
        world.setBlock(i + 14, j + 25, k + 30, Blocks.dirt);
        world.setBlock(i + 14, j + 25, k + 31, Blocks.dirt);
        world.setBlock(i + 14, j + 25, k + 32, Blocks.dirt);
        world.setBlock(i + 14, j + 25, k + 33, Blocks.dirt);
        world.setBlock(i + 14, j + 25, k + 34, Blocks.dirt);
        world.setBlock(i + 14, j + 25, k + 35, Blocks.grass);
        world.setBlock(i + 14, j + 25, k + 36, Blocks.grass);
        world.setBlock(i + 14, j + 25, k + 37, Blocks.grass);
        world.setBlock(i + 14, j + 25, k + 38, Blocks.grass);
        world.setBlock(i + 14, j + 25, k + 39, Blocks.dirt);
        world.setBlock(i + 14, j + 25, k + 40, Blocks.dirt);
        world.setBlock(i + 14, j + 25, k + 41, Blocks.dirt);
        world.setBlock(i + 14, j + 25, k + 42, Blocks.dirt);
        world.setBlock(i + 14, j + 25, k + 43, Blocks.dirt);
        world.setBlock(i + 14, j + 25, k + 44, Blocks.grass);
        world.setBlock(i + 14, j + 25, k + 45, Blocks.grass);
        world.setBlock(i + 14, j + 25, k + 46, Blocks.grass);
        world.setBlock(i + 14, j + 26, k + 13, Blocks.stonebrick);
        world.setBlock(i + 14, j + 26, k + 14, Blocks.cobblestone);
        world.setBlock(i + 14, j + 26, k + 15, Blocks.cobblestone);
        world.setBlock(i + 14, j + 26, k + 16, Blocks.cobblestone);
        world.setBlock(i + 14, j + 26, k + 17, Blocks.cobblestone);
        world.setBlock(i + 14, j + 26, k + 18, Blocks.cobblestone);
        world.setBlock(i + 14, j + 26, k + 22, Blocks.cobblestone);
        world.setBlock(i + 14, j + 26, k + 23, Blocks.cobblestone);
        world.setBlock(i + 14, j + 26, k + 24, Blocks.cobblestone);
        world.setBlock(i + 14, j + 26, k + 25, Blocks.cobblestone);
        world.setBlock(i + 14, j + 26, k + 26, Blocks.cobblestone);
        world.setBlock(i + 14, j + 26, k + 30, Blocks.cobblestone);
        world.setBlock(i + 14, j + 26, k + 31, Blocks.cobblestone);
        world.setBlock(i + 14, j + 26, k + 32, Blocks.cobblestone);
        world.setBlock(i + 14, j + 26, k + 33, Blocks.cobblestone);
        world.setBlock(i + 14, j + 26, k + 34, Blocks.cobblestone);
        world.setBlock(i + 14, j + 26, k + 39, Blocks.cobblestone);
        world.setBlock(i + 14, j + 26, k + 40, Blocks.cobblestone);
        world.setBlock(i + 14, j + 26, k + 41, Blocks.cobblestone);
        world.setBlock(i + 14, j + 26, k + 42, Blocks.cobblestone);
        world.setBlock(i + 14, j + 26, k + 43, Blocks.stonebrick);
        world.setBlock(i + 14, j + 27, k + 13, Blocks.stonebrick);
        world.setBlock(i + 14, j + 27, k + 14, Blocks.log);
        world.setBlock(i + 14, j + 27, k + 15, Blocks.planks);
        world.setBlock(i + 14, j + 27, k + 16, Blocks.planks);
        world.setBlock(i + 14, j + 27, k + 17, Blocks.planks);
        world.setBlock(i + 14, j + 27, k + 18, Blocks.log);
        world.setBlock(i + 14, j + 27, k + 22, Blocks.log);
        world.setBlock(i + 14, j + 27, k + 23, Blocks.planks);
        world.setBlock(i + 14, j + 27, k + 24, Blocks.planks);
        world.setBlock(i + 14, j + 27, k + 25, Blocks.planks);
        world.setBlock(i + 14, j + 27, k + 26, Blocks.log);
        world.setBlock(i + 14, j + 27, k + 30, Blocks.log);
        world.setBlock(i + 14, j + 27, k + 31, Blocks.planks);
        world.setBlock(i + 14, j + 27, k + 32, Blocks.planks);
        world.setBlock(i + 14, j + 27, k + 33, Blocks.planks);
        world.setBlock(i + 14, j + 27, k + 34, Blocks.log);
        world.setBlock(i + 14, j + 27, k + 39, Blocks.stonebrick);
        world.setBlock(i + 14, j + 27, k + 43, Blocks.stonebrick);
        world.setBlock(i + 14, j + 28, k + 14, Blocks.log);
        world.setBlock(i + 14, j + 28, k + 15, Blocks.planks);
        world.setBlock(i + 14, j + 28, k + 16, Blocks.glass_pane);
        world.setBlock(i + 14, j + 28, k + 17, Blocks.planks);
        world.setBlock(i + 14, j + 28, k + 18, Blocks.log);
        world.setBlock(i + 14, j + 28, k + 22, Blocks.log);
        world.setBlock(i + 14, j + 28, k + 23, Blocks.planks);
        world.setBlock(i + 14, j + 28, k + 24, Blocks.glass_pane);
        world.setBlock(i + 14, j + 28, k + 25, Blocks.planks);
        world.setBlock(i + 14, j + 28, k + 26, Blocks.log);
        world.setBlock(i + 14, j + 28, k + 30, Blocks.log);
        world.setBlock(i + 14, j + 28, k + 31, Blocks.planks);
        world.setBlock(i + 14, j + 28, k + 32, Blocks.glass_pane);
        world.setBlock(i + 14, j + 28, k + 33, Blocks.planks);
        world.setBlock(i + 14, j + 28, k + 34, Blocks.log);
        world.setBlock(i + 14, j + 28, k + 39, Blocks.stonebrick);
        world.setBlock(i + 14, j + 28, k + 43, Blocks.stonebrick);
        world.setBlock(i + 14, j + 29, k + 14, Blocks.log);
        world.setBlock(i + 14, j + 29, k + 15, Blocks.planks);
        world.setBlock(i + 14, j + 29, k + 16, Blocks.planks);
        world.setBlock(i + 14, j + 29, k + 17, Blocks.planks);
        world.setBlock(i + 14, j + 29, k + 18, Blocks.log);
        world.setBlock(i + 14, j + 29, k + 22, Blocks.log);
        world.setBlock(i + 14, j + 29, k + 23, Blocks.planks);
        world.setBlock(i + 14, j + 29, k + 24, Blocks.planks);
        world.setBlock(i + 14, j + 29, k + 25, Blocks.planks);
        world.setBlock(i + 14, j + 29, k + 26, Blocks.log);
        world.setBlock(i + 14, j + 29, k + 30, Blocks.log);
        world.setBlock(i + 14, j + 29, k + 31, Blocks.planks);
        world.setBlock(i + 14, j + 29, k + 32, Blocks.planks);
        world.setBlock(i + 14, j + 29, k + 33, Blocks.planks);
        world.setBlock(i + 14, j + 29, k + 34, Blocks.log);
        world.setBlock(i + 14, j + 29, k + 39, Blocks.stonebrick);
        world.setBlock(i + 14, j + 29, k + 40, Blocks.stonebrick);
        world.setBlock(i + 14, j + 29, k + 41, Blocks.stonebrick);
        world.setBlock(i + 14, j + 29, k + 42, Blocks.stonebrick);
        world.setBlock(i + 14, j + 29, k + 43, Blocks.stonebrick);
        world.setBlock(i + 14, j + 30, k + 15, Blocks.log);
        world.setBlock(i + 14, j + 30, k + 16, Blocks.log);
        world.setBlock(i + 14, j + 30, k + 17, Blocks.log);
        world.setBlock(i + 14, j + 30, k + 23, Blocks.log);
        world.setBlock(i + 14, j + 30, k + 24, Blocks.log);
        world.setBlock(i + 14, j + 30, k + 25, Blocks.log);
        world.setBlock(i + 14, j + 30, k + 31, Blocks.log);
        world.setBlock(i + 14, j + 30, k + 32, Blocks.log);
        world.setBlock(i + 14, j + 30, k + 33, Blocks.log);
        world.setBlock(i + 14, j + 30, k + 39, Blocks.stonebrick);
        world.setBlock(i + 14, j + 30, k + 43, Blocks.stonebrick);
        world.setBlock(i + 15, j + 16, k + 26, Dungeons.amethystCrystalized);
        world.setBlock(i + 15, j + 16, k + 27, Dungeons.amethystCrystalized);
        world.setBlock(i + 15, j + 16, k + 28, Dungeons.amethystCrystalized);
        world.setBlock(i + 15, j + 16, k + 29, Dungeons.amethystCrystalized);
        world.setBlock(i + 15, j + 17, k + 24, Dungeons.amethystCrystalized);
        world.setBlock(i + 15, j + 17, k + 25, Dungeons.amethystCrystalized);
        world.setBlock(i + 15, j + 17, k + 26, Dungeons.amethystCrystalized);
        world.setBlock(i + 15, j + 17, k + 27, Dungeons.amethystCrystalized);
        world.setBlock(i + 15, j + 17, k + 28, Dungeons.amethystCrystalized);
        world.setBlock(i + 15, j + 17, k + 29, Dungeons.amethystCrystalized);
        world.setBlock(i + 15, j + 17, k + 30, Dungeons.amethystCrystalized);
        world.setBlock(i + 15, j + 17, k + 31, Dungeons.amethystCrystalized);
        world.setBlock(i + 15, j + 17, k + 32, Dungeons.amethystCrystalized);
        world.setBlock(i + 15, j + 17, k + 33, Dungeons.amethystCrystalized);
        world.setBlock(i + 15, j + 18, k + 23, Dungeons.amethystCrystalized);
        world.setBlock(i + 15, j + 18, k + 24, Dungeons.amethystCrystalized);
        world.setBlock(i + 15, j + 18, k + 25, Dungeons.amethystCrystalized);
        world.setBlock(i + 15, j + 18, k + 26, Dungeons.amethystCrystalized);
        world.setBlock(i + 15, j + 18, k + 27, Dungeons.amethystCrystalized);
        world.setBlock(i + 15, j + 18, k + 28, Dungeons.amethystCrystalized);
        world.setBlock(i + 15, j + 18, k + 29, Dungeons.amethystCrystalized);
        world.setBlock(i + 15, j + 18, k + 30, Dungeons.amethystCrystalized);
        world.setBlock(i + 15, j + 18, k + 31, Dungeons.amethystCrystalized);
        world.setBlock(i + 15, j + 18, k + 32, Dungeons.amethystCrystalized);
        world.setBlock(i + 15, j + 18, k + 33, Dungeons.amethystCrystalized);
        world.setBlock(i + 15, j + 18, k + 34, Dungeons.amethystCrystalized);
        world.setBlock(i + 15, j + 19, k + 19, Dungeons.amethystCrystalized);
        world.setBlock(i + 15, j + 19, k + 20, Dungeons.amethystCrystalized);
        world.setBlock(i + 15, j + 19, k + 21, Dungeons.amethystCrystalized);
        world.setBlock(i + 15, j + 19, k + 22, Dungeons.amethystCrystalized);
        world.setBlock(i + 15, j + 19, k + 23, Dungeons.amethystCrystalized);
        world.setBlock(i + 15, j + 19, k + 24, Dungeons.amethystCrystalized);
        world.setBlock(i + 15, j + 19, k + 25, Dungeons.amethystCrystalized);
        world.setBlock(i + 15, j + 19, k + 26, Dungeons.amethystCrystalized);
        world.setBlock(i + 15, j + 19, k + 27, Dungeons.amethystCrystalized);
        world.setBlock(i + 15, j + 19, k + 28, Dungeons.amethystCrystalized);
        world.setBlock(i + 15, j + 19, k + 29, Dungeons.amethystCrystalized);
        world.setBlock(i + 15, j + 19, k + 30, Dungeons.amethystCrystalized);
        world.setBlock(i + 15, j + 19, k + 31, Dungeons.amethystCrystalized);
        world.setBlock(i + 15, j + 19, k + 32, Dungeons.amethystCrystalized);
        world.setBlock(i + 15, j + 19, k + 33, Dungeons.amethystCrystalized);
        world.setBlock(i + 15, j + 19, k + 34, Dungeons.amethystCrystalized);
        world.setBlock(i + 15, j + 19, k + 35, Dungeons.amethystCrystalized);
        world.setBlock(i + 15, j + 19, k + 36, Dungeons.amethystCrystalized);
        world.setBlock(i + 15, j + 20, k + 17, Dungeons.amethystCrystalized);
        world.setBlock(i + 15, j + 20, k + 18, Dungeons.amethystCrystalized);
        world.setBlock(i + 15, j + 20, k + 19, Dungeons.amethystCrystalized);
        world.setBlock(i + 15, j + 20, k + 20, Dungeons.amethystCrystalized);
        world.setBlock(i + 15, j + 20, k + 21, Dungeons.amethystCrystalized);
        world.setBlock(i + 15, j + 20, k + 22, Dungeons.amethystCrystalized);
        world.setBlock(i + 15, j + 20, k + 23, Dungeons.amethystCrystalized);
        world.setBlock(i + 15, j + 20, k + 24, Dungeons.amethystCrystalized);
        world.setBlock(i + 15, j + 20, k + 25, Dungeons.amethystCrystalized);
        world.setBlock(i + 15, j + 20, k + 26, Dungeons.amethystCrystalized);
        world.setBlock(i + 15, j + 20, k + 27, Dungeons.amethystCrystalized);
        world.setBlock(i + 15, j + 20, k + 28, Dungeons.amethystCrystalized);
        world.setBlock(i + 15, j + 20, k + 29, Dungeons.amethystCrystalized);
        world.setBlock(i + 15, j + 20, k + 30, Dungeons.amethystCrystalized);
        world.setBlock(i + 15, j + 20, k + 31, Dungeons.amethystCrystalized);
        world.setBlock(i + 15, j + 20, k + 32, Dungeons.amethystCrystalized);
        world.setBlock(i + 15, j + 20, k + 33, Dungeons.amethystCrystalized);
        world.setBlock(i + 15, j + 20, k + 34, Dungeons.amethystCrystalized);
        world.setBlock(i + 15, j + 20, k + 35, Dungeons.amethystCrystalized);
        world.setBlock(i + 15, j + 20, k + 36, Dungeons.amethystCrystalized);
        world.setBlock(i + 15, j + 20, k + 37, Dungeons.amethystCrystalized);
        world.setBlock(i + 15, j + 20, k + 38, Dungeons.amethystCrystalized);
        world.setBlock(i + 15, j + 21, k + 13, Dungeons.amethystCrystalized);
        world.setBlock(i + 15, j + 21, k + 14, Dungeons.amethystCrystalized);
        world.setBlock(i + 15, j + 21, k + 15, Dungeons.amethystCrystalized);
        world.setBlock(i + 15, j + 21, k + 16, Dungeons.amethystCrystalized);
        world.setBlock(i + 15, j + 21, k + 17, Dungeons.amethystCrystalized);
        world.setBlock(i + 15, j + 21, k + 18, Dungeons.amethystCrystalized);
        world.setBlock(i + 15, j + 21, k + 19, Dungeons.amethystCrystalized);
        world.setBlock(i + 15, j + 21, k + 20, Dungeons.amethystCrystalized);
        world.setBlock(i + 15, j + 21, k + 21, Dungeons.amethystCrystalized);
        world.setBlock(i + 15, j + 21, k + 22, Dungeons.amethystCrystalized);
        world.setBlock(i + 15, j + 21, k + 23, Dungeons.amethystCrystalized);
        world.setBlock(i + 15, j + 21, k + 24, Dungeons.amethystCrystalized);
        world.setBlock(i + 15, j + 21, k + 25, Dungeons.amethystCrystalized);
        world.setBlock(i + 15, j + 21, k + 26, Dungeons.amethystCrystalized);
        world.setBlock(i + 15, j + 21, k + 27, Dungeons.amethystCrystalized);
        world.setBlock(i + 15, j + 21, k + 28, Dungeons.amethystCrystalized);
        world.setBlock(i + 15, j + 21, k + 29, Dungeons.amethystCrystalized);
        world.setBlock(i + 15, j + 21, k + 30, Dungeons.amethystCrystalized);
        world.setBlock(i + 15, j + 21, k + 31, Dungeons.amethystCrystalized);
        world.setBlock(i + 15, j + 21, k + 32, Dungeons.amethystCrystalized);
        world.setBlock(i + 15, j + 21, k + 33, Dungeons.amethystCrystalized);
        world.setBlock(i + 15, j + 21, k + 34, Dungeons.amethystCrystalized);
        world.setBlock(i + 15, j + 21, k + 35, Dungeons.amethystCrystalized);
        world.setBlock(i + 15, j + 21, k + 36, Dungeons.amethystCrystalized);
        world.setBlock(i + 15, j + 21, k + 37, Dungeons.amethystCrystalized);
        world.setBlock(i + 15, j + 21, k + 38, Dungeons.amethystCrystalized);
        world.setBlock(i + 15, j + 21, k + 39, Dungeons.amethystCrystalized);
        world.setBlock(i + 15, j + 21, k + 40, Dungeons.amethystCrystalized);
        world.setBlock(i + 15, j + 21, k + 41, Dungeons.amethystCrystalized);
        world.setBlock(i + 15, j + 21, k + 42, Dungeons.amethystCrystalized);
        world.setBlock(i + 15, j + 21, k + 43, Dungeons.amethystCrystalized);
        world.setBlock(i + 15, j + 22, k + 11, Dungeons.amethystCrystalized);
        world.setBlock(i + 15, j + 22, k + 12, Dungeons.amethystCrystalized);
        world.setBlock(i + 15, j + 22, k + 13, Dungeons.amethystCrystalized);
        world.setBlock(i + 15, j + 22, k + 14, Dungeons.amethystCrystalized);
        world.setBlock(i + 15, j + 22, k + 15, Dungeons.amethystCrystalized);
        world.setBlock(i + 15, j + 22, k + 16, Dungeons.amethystCrystalized);
        world.setBlock(i + 15, j + 22, k + 17, Dungeons.amethystCrystalized);
        world.setBlock(i + 15, j + 22, k + 18, Dungeons.amethystCrystalized);
        world.setBlock(i + 15, j + 22, k + 19, Dungeons.amethystCrystalized);
        world.setBlock(i + 15, j + 22, k + 20, Dungeons.amethystCrystalized);
        world.setBlock(i + 15, j + 22, k + 21, Dungeons.amethystCrystalized);
        world.setBlock(i + 15, j + 22, k + 22, Dungeons.amethystCrystalized);
        world.setBlock(i + 15, j + 22, k + 23, Dungeons.amethystCrystalized);
        world.setBlock(i + 15, j + 22, k + 24, Dungeons.amethystCrystalized);
        world.setBlock(i + 15, j + 22, k + 25, Dungeons.amethystCrystalized);
        world.setBlock(i + 15, j + 22, k + 26, Dungeons.amethystCrystalized);
        world.setBlock(i + 15, j + 22, k + 27, Dungeons.amethystCrystalized);
        world.setBlock(i + 15, j + 22, k + 28, Dungeons.amethystCrystalized);
        world.setBlock(i + 15, j + 22, k + 29, Dungeons.amethystCrystalized);
        world.setBlock(i + 15, j + 22, k + 30, Dungeons.amethystCrystalized);
        world.setBlock(i + 15, j + 22, k + 31, Dungeons.amethystCrystalized);
        world.setBlock(i + 15, j + 22, k + 32, Dungeons.amethystCrystalized);
        world.setBlock(i + 15, j + 22, k + 33, Dungeons.amethystCrystalized);
        world.setBlock(i + 15, j + 22, k + 34, Dungeons.amethystCrystalized);
        world.setBlock(i + 15, j + 22, k + 35, Dungeons.amethystCrystalized);
        world.setBlock(i + 15, j + 22, k + 36, Dungeons.amethystCrystalized);
        world.setBlock(i + 15, j + 22, k + 37, Dungeons.amethystCrystalized);
        world.setBlock(i + 15, j + 22, k + 38, Dungeons.amethystCrystalized);
        world.setBlock(i + 15, j + 22, k + 39, Dungeons.amethystCrystalized);
        world.setBlock(i + 15, j + 22, k + 40, Dungeons.amethystCrystalized);
        world.setBlock(i + 15, j + 22, k + 41, Dungeons.amethystCrystalized);
        world.setBlock(i + 15, j + 22, k + 42, Dungeons.amethystCrystalized);
        world.setBlock(i + 15, j + 22, k + 43, Dungeons.amethystCrystalized);
        world.setBlock(i + 15, j + 22, k + 44, Dungeons.amethystCrystalized);
        world.setBlock(i + 15, j + 22, k + 45, Dungeons.amethystCrystalized);
        world.setBlock(i + 15, j + 23, k + 11, Blocks.dirt);
        world.setBlock(i + 15, j + 23, k + 12, Blocks.dirt);
        world.setBlock(i + 15, j + 23, k + 13, Blocks.dirt);
        world.setBlock(i + 15, j + 23, k + 14, Blocks.dirt);
        world.setBlock(i + 15, j + 23, k + 15, Blocks.dirt);
        world.setBlock(i + 15, j + 23, k + 16, Blocks.dirt);
        world.setBlock(i + 15, j + 23, k + 17, Blocks.dirt);
        world.setBlock(i + 15, j + 23, k + 18, Blocks.dirt);
        world.setBlock(i + 15, j + 23, k + 19, Blocks.dirt);
        world.setBlock(i + 15, j + 23, k + 20, Blocks.dirt);
        world.setBlock(i + 15, j + 23, k + 21, Blocks.dirt);
        world.setBlock(i + 15, j + 23, k + 22, Blocks.dirt);
        world.setBlock(i + 15, j + 23, k + 23, Blocks.dirt);
        world.setBlock(i + 15, j + 23, k + 24, Blocks.dirt);
        world.setBlock(i + 15, j + 23, k + 25, Blocks.dirt);
        world.setBlock(i + 15, j + 23, k + 26, Blocks.dirt);
        world.setBlock(i + 15, j + 23, k + 27, Blocks.dirt);
        world.setBlock(i + 15, j + 23, k + 28, Blocks.dirt);
        world.setBlock(i + 15, j + 23, k + 29, Blocks.dirt);
        world.setBlock(i + 15, j + 23, k + 30, Blocks.dirt);
        world.setBlock(i + 15, j + 23, k + 31, Blocks.dirt);
        world.setBlock(i + 15, j + 23, k + 32, Blocks.dirt);
        world.setBlock(i + 15, j + 23, k + 33, Blocks.dirt);
        world.setBlock(i + 15, j + 23, k + 34, Blocks.dirt);
        world.setBlock(i + 15, j + 23, k + 35, Blocks.dirt);
        world.setBlock(i + 15, j + 23, k + 36, Blocks.dirt);
        world.setBlock(i + 15, j + 23, k + 37, Blocks.dirt);
        world.setBlock(i + 15, j + 23, k + 38, Blocks.dirt);
        world.setBlock(i + 15, j + 23, k + 39, Blocks.dirt);
        world.setBlock(i + 15, j + 23, k + 40, Blocks.dirt);
        world.setBlock(i + 15, j + 23, k + 41, Blocks.dirt);
        world.setBlock(i + 15, j + 23, k + 42, Blocks.dirt);
        world.setBlock(i + 15, j + 23, k + 43, Blocks.dirt);
        world.setBlock(i + 15, j + 23, k + 44, Blocks.dirt);
        world.setBlock(i + 15, j + 23, k + 45, Blocks.dirt);
        world.setBlock(i + 15, j + 23, k + 46, Blocks.dirt);
        world.setBlock(i + 15, j + 24, k + 11, Blocks.dirt);
        world.setBlock(i + 15, j + 24, k + 12, Blocks.dirt);
        world.setBlock(i + 15, j + 24, k + 13, Blocks.dirt);
        world.setBlock(i + 15, j + 24, k + 14, Blocks.dirt);
        world.setBlock(i + 15, j + 24, k + 15, Blocks.dirt);
        world.setBlock(i + 15, j + 24, k + 16, Blocks.dirt);
        world.setBlock(i + 15, j + 24, k + 17, Blocks.dirt);
        world.setBlock(i + 15, j + 24, k + 18, Blocks.dirt);
        world.setBlock(i + 15, j + 24, k + 19, Blocks.dirt);
        world.setBlock(i + 15, j + 24, k + 20, Blocks.dirt);
        world.setBlock(i + 15, j + 24, k + 21, Blocks.dirt);
        world.setBlock(i + 15, j + 24, k + 22, Blocks.dirt);
        world.setBlock(i + 15, j + 24, k + 23, Blocks.dirt);
        world.setBlock(i + 15, j + 24, k + 24, Blocks.dirt);
        world.setBlock(i + 15, j + 24, k + 25, Blocks.dirt);
        world.setBlock(i + 15, j + 24, k + 26, Blocks.dirt);
        world.setBlock(i + 15, j + 24, k + 27, Blocks.dirt);
