

package com.gibby.dungeon.gen;

import net.minecraft.world.gen.feature.*;
import cpw.mods.fml.common.*;
import java.util.*;
import net.minecraft.world.chunk.*;
import net.minecraft.block.*;
import net.minecraft.world.*;
import net.minecraft.init.*;
import com.gibby.dungeon.*;

public class WorldGenNetherTower extends WorldGenerator implements IWorldGenerator
{
    public void generate(final Random random, final int chunkX, final int chunkZ, final World world, final IChunkProvider chunkGenerator, final IChunkProvider chunkProvider) {
    }
    
    public void setBlock(final World world, final int x, final int y, final int z, final Block block, final int metadata) {
        final Block b1 = world.getBlock(x, y, z);
        if (b1.isAir((IBlockAccess)world, x, y, z) || b1.isLeaves((IBlockAccess)world, x, y, z)) {
            world.setBlock(x, y, z, block, metadata, 2);
        }
    }
    
    public boolean generate(final World world, final Random rand, final int i, final int j, final int k) {
        if (world.getBlock(i, j, k) != Blocks.netherrack || world.getBlock(i + 20, j, k + 2) != Blocks.netherrack || world.getBlock(i, j + 1, k) != Blocks.air || world.getBlock(i + 20, j + 1, k + 20) != Blocks.air || world.getBlock(i, j + 25, k) != Blocks.air || world.getBlock(i + 20, j + 25, k + 20) != Blocks.air) {
            return false;
        }
        this.setBlock(world, i + 3, j + 0, k + 10, Blocks.nether_brick, 0);
        this.setBlock(world, i + 3, j + 0, k + 11, Blocks.nether_brick, 0);
        this.setBlock(world, i + 3, j + 0, k + 12, Blocks.nether_brick, 0);
        this.setBlock(world, i + 3, j + 0, k + 13, Blocks.nether_brick, 0);
        this.setBlock(world, i + 3, j + 0, k + 14, Blocks.nether_brick, 0);
        this.setBlock(world, i + 3, j + 0, k + 15, Blocks.nether_brick, 0);
        this.setBlock(world, i + 3, j + 0, k + 16, Blocks.nether_brick, 0);
        this.setBlock(world, i + 4, j + 0, k + 8, Blocks.nether_brick, 0);
        this.setBlock(world, i + 4, j + 0, k + 9, Blocks.nether_brick, 0);
        this.setBlock(world, i + 4, j + 0, k + 10, Blocks.nether_brick, 0);
        this.setBlock(world, i + 4, j + 0, k + 11, Blocks.nether_brick, 0);
        this.setBlock(world, i + 4, j + 0, k + 12, Blocks.nether_brick, 0);
        this.setBlock(world, i + 4, j + 0, k + 13, Blocks.nether_brick, 0);
        this.setBlock(world, i + 4, j + 0, k + 14, Blocks.nether_brick, 0);
        this.setBlock(world, i + 4, j + 0, k + 15, Blocks.nether_brick, 0);
        this.setBlock(world, i + 4, j + 0, k + 16, Blocks.nether_brick, 0);
        this.setBlock(world, i + 4, j + 0, k + 17, Blocks.nether_brick, 0);
        this.setBlock(world, i + 4, j + 0, k + 18, Blocks.nether_brick, 0);
        this.setBlock(world, i + 4, j + 1, k + 10, Blocks.nether_brick, 0);
        this.setBlock(world, i + 4, j + 1, k + 11, Blocks.nether_brick, 0);
        this.setBlock(world, i + 4, j + 1, k + 12, Blocks.nether_brick, 0);
        this.setBlock(world, i + 4, j + 1, k + 13, Blocks.nether_brick, 0);
        this.setBlock(world, i + 4, j + 1, k + 14, Blocks.nether_brick, 0);
        this.setBlock(world, i + 4, j + 1, k + 15, Blocks.nether_brick, 0);
        this.setBlock(world, i + 4, j + 1, k + 16, Blocks.nether_brick, 0);
        this.setBlock(world, i + 5, j + 0, k + 7, Blocks.nether_brick, 0);
        this.setBlock(world, i + 5, j + 0, k + 8, Blocks.nether_brick, 0);
        this.setBlock(world, i + 5, j + 0, k + 9, Blocks.nether_brick, 0);
        this.setBlock(world, i + 5, j + 0, k + 10, Blocks.nether_brick, 0);
        this.setBlock(world, i + 5, j + 0, k + 11, Blocks.nether_brick, 0);
        this.setBlock(world, i + 5, j + 0, k + 12, Blocks.nether_brick, 0);
        this.setBlock(world, i + 5, j + 0, k + 13, Blocks.nether_brick, 0);
        this.setBlock(world, i + 5, j + 0, k + 14, Blocks.nether_brick, 0);
        this.setBlock(world, i + 5, j + 0, k + 15, Blocks.nether_brick, 0);
        this.setBlock(world, i + 5, j + 0, k + 16, Blocks.nether_brick, 0);
        this.setBlock(world, i + 5, j + 0, k + 17, Blocks.nether_brick, 0);
        this.setBlock(world, i + 5, j + 0, k + 18, Blocks.nether_brick, 0);
        this.setBlock(world, i + 5, j + 0, k + 19, Blocks.nether_brick, 0);
        this.setBlock(world, i + 5, j + 1, k + 8, Blocks.nether_brick, 0);
        this.setBlock(world, i + 5, j + 1, k + 9, Blocks.nether_brick, 0);
        this.setBlock(world, i + 5, j + 1, k + 10, Blocks.nether_brick, 0);
        this.setBlock(world, i + 5, j + 1, k + 11, Blocks.nether_brick, 0);
        this.setBlock(world, i + 5, j + 1, k + 12, Blocks.nether_brick, 0);
        this.setBlock(world, i + 5, j + 1, k + 13, Blocks.nether_brick, 0);
        this.setBlock(world, i + 5, j + 1, k + 14, Blocks.nether_brick, 0);
        this.setBlock(world, i + 5, j + 1, k + 15, Blocks.nether_brick, 0);
        this.setBlock(world, i + 5, j + 1, k + 16, Blocks.nether_brick, 0);
        this.setBlock(world, i + 5, j + 1, k + 17, Blocks.nether_brick, 0);
        this.setBlock(world, i + 5, j + 1, k + 18, Blocks.nether_brick, 0);
        this.setBlock(world, i + 5, j + 2, k + 11, Blocks.nether_brick, 0);
        this.setBlock(world, i + 5, j + 2, k + 12, Blocks.nether_brick, 0);
        this.setBlock(world, i + 5, j + 2, k + 13, Blocks.nether_brick, 0);
        this.setBlock(world, i + 5, j + 2, k + 14, Blocks.nether_brick, 0);
        this.setBlock(world, i + 5, j + 2, k + 15, Blocks.nether_brick, 0);
        this.setBlock(world, i + 5, j + 3, k + 11, Blocks.nether_brick, 0);
        this.setBlock(world, i + 5, j + 3, k + 12, Blocks.nether_brick, 0);
        this.setBlock(world, i + 5, j + 3, k + 13, Blocks.nether_brick, 0);
        this.setBlock(world, i + 5, j + 3, k + 14, Blocks.nether_brick, 0);
        this.setBlock(world, i + 5, j + 3, k + 15, Blocks.nether_brick, 0);
        this.setBlock(world, i + 5, j + 4, k + 11, Blocks.nether_brick, 0);
        this.setBlock(world, i + 5, j + 4, k + 12, Blocks.nether_brick, 0);
        this.setBlock(world, i + 5, j + 4, k + 13, Blocks.nether_brick, 0);
        this.setBlock(world, i + 5, j + 4, k + 14, Blocks.nether_brick, 0);
        this.setBlock(world, i + 5, j + 4, k + 15, Blocks.nether_brick, 0);
        this.setBlock(world, i + 6, j + 0, k + 6, Blocks.nether_brick, 0);
        this.setBlock(world, i + 6, j + 0, k + 7, Blocks.nether_brick, 0);
        this.setBlock(world, i + 6, j + 0, k + 8, Blocks.nether_brick, 0);
        this.setBlock(world, i + 6, j + 0, k + 9, Blocks.nether_brick, 0);
        this.setBlock(world, i + 6, j + 0, k + 10, Blocks.nether_brick, 0);
        this.setBlock(world, i + 6, j + 0, k + 11, Blocks.nether_brick, 0);
        this.setBlock(world, i + 6, j + 0, k + 12, Blocks.nether_brick, 0);
        this.setBlock(world, i + 6, j + 0, k + 13, Blocks.nether_brick, 0);
        this.setBlock(world, i + 6, j + 0, k + 14, Blocks.nether_brick, 0);
        this.setBlock(world, i + 6, j + 0, k + 15, Blocks.nether_brick, 0);
        this.setBlock(world, i + 6, j + 0, k + 16, Blocks.nether_brick, 0);
        this.setBlock(world, i + 6, j + 0, k + 17, Blocks.nether_brick, 0);
        this.setBlock(world, i + 6, j + 0, k + 18, Blocks.nether_brick, 0);
        this.setBlock(world, i + 6, j + 0, k + 19, Blocks.nether_brick, 0);
        this.setBlock(world, i + 6, j + 0, k + 20, Blocks.nether_brick, 0);
        this.setBlock(world, i + 6, j + 1, k + 7, Blocks.nether_brick, 0);
        this.setBlock(world, i + 6, j + 1, k + 8, Blocks.nether_brick, 0);
        this.setBlock(world, i + 6, j + 1, k + 9, Blocks.nether_brick, 0);
        this.setBlock(world, i + 6, j + 1, k + 10, Blocks.nether_brick, 0);
        this.setBlock(world, i + 6, j + 1, k + 11, Blocks.obsidian, 0);
        this.setBlock(world, i + 6, j + 1, k + 12, Blocks.obsidian, 0);
        this.setBlock(world, i + 6, j + 1, k + 14, Blocks.chest, 5);
        WorldGenWarlordDungeon.chest(world, rand, i + 6, j + 1, k + 14, "NetherStructure", 10);
        this.setBlock(world, i + 6, j + 1, k + 16, Blocks.nether_brick, 0);
        this.setBlock(world, i + 6, j + 1, k + 17, Blocks.nether_brick, 0);
        this.setBlock(world, i + 6, j + 1, k + 18, Blocks.nether_brick, 0);
        this.setBlock(world, i + 6, j + 1, k + 19, Blocks.nether_brick, 0);
        this.setBlock(world, i + 6, j + 2, k + 9, Blocks.nether_brick, 0);
        this.setBlock(world, i + 6, j + 2, k + 10, Blocks.nether_brick, 0);
        this.setBlock(world, i + 6, j + 2, k + 11, Blocks.obsidian, 0);
        this.setBlock(world, i + 6, j + 2, k + 12, Blocks.obsidian, 0);
        this.setBlock(world, i + 6, j + 2, k + 16, Blocks.nether_brick, 0);
        this.setBlock(world, i + 6, j + 2, k + 17, Blocks.nether_brick, 0);
        this.setBlock(world, i + 6, j + 3, k + 9, Blocks.nether_brick, 0);
        this.setBlock(world, i + 6, j + 3, k + 10, Blocks.nether_brick, 0);
        this.setBlock(world, i + 6, j + 3, k + 11, Blocks.obsidian, 0);
        this.setBlock(world, i + 6, j + 3, k + 12, Blocks.obsidian, 0);
        this.setBlock(world, i + 6, j + 3, k + 16, Blocks.nether_brick, 0);
        this.setBlock(world, i + 6, j + 3, k + 17, Blocks.nether_brick, 0);
        this.setBlock(world, i + 6, j + 4, k + 9, Blocks.nether_brick, 0);
        this.setBlock(world, i + 6, j + 4, k + 10, Blocks.nether_brick, 0);
        this.setBlock(world, i + 6, j + 4, k + 11, Blocks.obsidian, 0);
        this.setBlock(world, i + 6, j + 4, k + 12, Blocks.obsidian, 0);
        this.setBlock(world, i + 6, j + 4, k + 16, Blocks.nether_brick, 0);
        this.setBlock(world, i + 6, j + 4, k + 17, Blocks.nether_brick, 0);
        this.setBlock(world, i + 6, j + 5, k + 11, Blocks.obsidian, 0);
        this.setBlock(world, i + 6, j + 5, k + 12, Blocks.obsidian, 0);
        this.setBlock(world, i + 6, j + 5, k + 13, Blocks.nether_brick, 0);
        this.setBlock(world, i + 6, j + 5, k + 14, Blocks.nether_brick, 0);
        this.setBlock(world, i + 6, j + 5, k + 15, Blocks.nether_brick, 0);
        this.setBlock(world, i + 6, j + 6, k + 11, Blocks.obsidian, 0);
        this.setBlock(world, i + 6, j + 6, k + 12, Blocks.obsidian, 0);
        this.setBlock(world, i + 6, j + 6, k + 13, Blocks.nether_brick, 0);
        this.setBlock(world, i + 6, j + 6, k + 14, Blocks.nether_brick, 0);
        this.setBlock(world, i + 6, j + 6, k + 15, Blocks.nether_brick, 0);
        this.setBlock(world, i + 6, j + 7, k + 11, Blocks.obsidian, 0);
        this.setBlock(world, i + 6, j + 7, k + 12, Blocks.obsidian, 0);
        this.setBlock(world, i + 6, j + 7, k + 13, Blocks.nether_brick, 0);
        this.setBlock(world, i + 6, j + 7, k + 14, Blocks.nether_brick, 0);
        this.setBlock(world, i + 6, j + 7, k + 15, Blocks.nether_brick, 0);
        this.setBlock(world, i + 7, j + 0, k + 5, Blocks.nether_brick, 0);
        this.setBlock(world, i + 7, j + 0, k + 6, Blocks.nether_brick, 0);
        this.setBlock(world, i + 7, j + 0, k + 7, Blocks.nether_brick, 0);
        this.setBlock(world, i + 7, j + 0, k + 8, Blocks.nether_brick, 0);
        this.setBlock(world, i + 7, j + 0, k + 9, Blocks.nether_brick, 0);
        this.setBlock(world, i + 7, j + 0, k + 10, Blocks.nether_brick, 0);
        this.setBlock(world, i + 7, j + 0, k + 11, Blocks.nether_brick, 0);
        this.setBlock(world, i + 7, j + 0, k + 12, Blocks.nether_brick, 0);
        this.setBlock(world, i + 7, j + 0, k + 13, Blocks.nether_brick, 0);
        this.setBlock(world, i + 7, j + 0, k + 14, Blocks.nether_brick, 0);
        this.setBlock(world, i + 7, j + 0, k + 15, Blocks.nether_brick, 0);
        this.setBlock(world, i + 7, j + 0, k + 16, Blocks.nether_brick, 0);
        this.setBlock(world, i + 7, j + 0, k + 17, Blocks.nether_brick, 0);
        this.setBlock(world, i + 7, j + 0, k + 18, Blocks.nether_brick, 0);
        this.setBlock(world, i + 7, j + 0, k + 19, Blocks.nether_brick, 0);
        this.setBlock(world, i + 7, j + 0, k + 20, Blocks.nether_brick, 0);
        this.setBlock(world, i + 7, j + 0, k + 21, Blocks.nether_brick, 0);
        this.setBlock(world, i + 7, j + 1, k + 6, Blocks.nether_brick, 0);
        this.setBlock(world, i + 7, j + 1, k + 7, Blocks.nether_brick, 0);
        this.setBlock(world, i + 7, j + 1, k + 8, Blocks.nether_brick, 0);
        this.setBlock(world, i + 7, j + 1, k + 10, Blocks.obsidian, 0);
        this.setBlock(world, i + 7, j + 1, k + 11, Blocks.obsidian, 0);
        this.setBlock(world, i + 7, j + 1, k + 18, Blocks.nether_brick, 0);
        this.setBlock(world, i + 7, j + 1, k + 19, Blocks.nether_brick, 0);
        this.setBlock(world, i + 7, j + 1, k + 20, Blocks.nether_brick, 0);
        this.setBlock(world, i + 7, j + 2, k + 7, Blocks.nether_brick, 0);
        this.setBlock(world, i + 7, j + 2, k + 8, Blocks.nether_brick, 0);
        this.setBlock(world, i + 7, j + 2, k + 10, Blocks.obsidian, 0);
        this.setBlock(world, i + 7, j + 2, k + 11, Blocks.obsidian, 0);
        this.setBlock(world, i + 7, j + 2, k + 18, Blocks.nether_brick, 0);
        this.setBlock(world, i + 7, j + 2, k + 19, Blocks.nether_brick, 0);
        this.setBlock(world, i + 7, j + 3, k + 7, Blocks.nether_brick, 0);
        this.setBlock(world, i + 7, j + 3, k + 8, Blocks.nether_brick, 0);
        this.setBlock(world, i + 7, j + 3, k + 10, Blocks.obsidian, 0);
        this.setBlock(world, i + 7, j + 3, k + 11, Blocks.obsidian, 0);
        this.setBlock(world, i + 7, j + 3, k + 18, Blocks.nether_brick, 0);
        this.setBlock(world, i + 7, j + 3, k + 19, Blocks.nether_brick, 0);
        this.setBlock(world, i + 7, j + 4, k + 7, Blocks.nether_brick, 0);
        this.setBlock(world, i + 7, j + 4, k + 8, Blocks.nether_brick, 0);
        this.setBlock(world, i + 7, j + 4, k + 10, Blocks.obsidian, 0);
        this.setBlock(world, i + 7, j + 4, k + 11, Blocks.obsidian, 0);
        this.setBlock(world, i + 7, j + 4, k + 18, Blocks.nether_brick, 0);
        this.setBlock(world, i + 7, j + 4, k + 19, Blocks.nether_brick, 0);
        this.setBlock(world, i + 7, j + 5, k + 9, Blocks.nether_brick, 0);
        this.setBlock(world, i + 7, j + 5, k + 10, Blocks.obsidian, 0);
        this.setBlock(world, i + 7, j + 5, k + 11, Blocks.obsidian, 0);
        this.setBlock(world, i + 7, j + 5, k + 15, Blocks.nether_brick, 0);
        this.setBlock(world, i + 7, j + 5, k + 16, Blocks.nether_brick, 0);
        this.setBlock(world, i + 7, j + 5, k + 17, Blocks.nether_brick, 0);
        this.setBlock(world, i + 7, j + 6, k + 9, Blocks.nether_brick, 0);
        this.setBlock(world, i + 7, j + 6, k + 10, Blocks.obsidian, 0);
        this.setBlock(world, i + 7, j + 6, k + 11, Blocks.obsidian, 0);
        this.setBlock(world, i + 7, j + 6, k + 15, Blocks.nether_brick, 0);
        this.setBlock(world, i + 7, j + 6, k + 16, Blocks.nether_brick, 0);
        this.setBlock(world, i + 7, j + 6, k + 17, Blocks.nether_brick, 0);
        this.setBlock(world, i + 7, j + 7, k + 9, Blocks.nether_brick, 0);
        this.setBlock(world, i + 7, j + 7, k + 10, Blocks.obsidian, 0);
        this.setBlock(world, i + 7, j + 7, k + 11, Blocks.obsidian, 0);
        this.setBlock(world, i + 7, j + 7, k + 12, Blocks.obsidian, 0);
        this.setBlock(world, i + 7, j + 7, k + 15, Blocks.nether_brick, 0);
        this.setBlock(world, i + 7, j + 7, k + 16, Blocks.nether_brick, 0);
        this.setBlock(world, i + 7, j + 7, k + 17, Blocks.nether_brick, 0);
        this.setBlock(world, i + 7, j + 8, k + 10, Blocks.nether_brick, 0);
        this.setBlock(world, i + 7, j + 8, k + 11, Blocks.obsidian, 0);
        this.setBlock(world, i + 7, j + 8, k + 12, Blocks.obsidian, 0);
        this.setBlock(world, i + 7, j + 8, k + 13, Blocks.nether_brick, 0);
        this.setBlock(world, i + 7, j + 8, k + 14, Blocks.nether_brick, 0);
        this.setBlock(world, i + 7, j + 9, k + 10, Blocks.nether_brick, 0);
        this.setBlock(world, i + 7, j + 9, k + 11, Blocks.obsidian, 0);
        this.setBlock(world, i + 7, j + 9, k + 12, Blocks.obsidian, 0);
        this.setBlock(world, i + 7, j + 9, k + 13, Blocks.nether_brick, 0);
        this.setBlock(world, i + 7, j + 9, k + 14, Blocks.nether_brick, 0);
        this.setBlock(world, i + 7, j + 10, k + 10, Blocks.nether_brick, 0);
        this.setBlock(world, i + 7, j + 10, k + 11, Blocks.obsidian, 0);
        this.setBlock(world, i + 7, j + 10, k + 12, Blocks.obsidian, 0);
        this.setBlock(world, i + 7, j + 10, k + 13, Blocks.nether_brick, 0);
        this.setBlock(world, i + 7, j + 10, k + 14, Blocks.nether_brick, 0);
        this.setBlock(world, i + 8, j + 0, k + 4, Blocks.nether_brick, 0);
        this.setBlock(world, i + 8, j + 0, k + 5, Blocks.nether_brick, 0);
        this.setBlock(world, i + 8, j + 0, k + 6, Blocks.nether_brick, 0);
        this.setBlock(world, i + 8, j + 0, k + 7, Blocks.nether_brick, 0);
        this.setBlock(world, i + 8, j + 0, k + 8, Blocks.nether_brick, 0);
        this.setBlock(world, i + 8, j + 0, k + 9, Blocks.nether_brick, 0);
        this.setBlock(world, i + 8, j + 0, k + 10, Blocks.nether_brick, 0);
        this.setBlock(world, i + 8, j + 0, k + 11, Blocks.nether_brick, 0);
        this.setBlock(world, i + 8, j + 0, k + 12, Blocks.nether_brick, 0);
        this.setBlock(world, i + 8, j + 0, k + 13, Blocks.nether_brick, 0);
        this.setBlock(world, i + 8, j + 0, k + 14, Blocks.nether_brick, 0);
        this.setBlock(world, i + 8, j + 0, k + 15, Blocks.nether_brick, 0);
        this.setBlock(world, i + 8, j + 0, k + 16, Blocks.nether_brick, 0);
        this.setBlock(world, i + 8, j + 0, k + 17, Blocks.nether_brick, 0);
        this.setBlock(world, i + 8, j + 0, k + 18, Blocks.nether_brick, 0);
        this.setBlock(world, i + 8, j + 0, k + 19, Blocks.nether_brick, 0);
        this.setBlock(world, i + 8, j + 0, k + 20, Blocks.nether_brick, 0);
        this.setBlock(world, i + 8, j + 0, k + 21, Blocks.nether_brick, 0);
        this.setBlock(world, i + 8, j + 0, k + 22, Blocks.nether_brick, 0);
        this.setBlock(world, i + 8, j + 1, k + 5, Blocks.nether_brick, 0);
        this.setBlock(world, i + 8, j + 1, k + 6, Blocks.nether_brick, 0);
        this.setBlock(world, i + 8, j + 1, k + 7, Blocks.nether_brick, 0);
        this.setBlock(world, i + 8, j + 1, k + 19, Blocks.nether_brick, 0);
        this.setBlock(world, i + 8, j + 1, k + 20, Blocks.nether_brick, 0);
        this.setBlock(world, i + 8, j + 1, k + 21, Blocks.nether_brick, 0);
        this.setBlock(world, i + 8, j + 2, k + 7, Blocks.nether_brick, 0);
        this.setBlock(world, i + 8, j + 2, k + 19, Blocks.nether_brick, 0);
        this.setBlock(world, i + 8, j + 3, k + 7, Blocks.nether_brick, 0);
        this.setBlock(world, i + 8, j + 3, k + 19, Blocks.nether_brick, 0);
        this.setBlock(world, i + 8, j + 4, k + 7, Blocks.nether_brick, 0);
        this.setBlock(world, i + 8, j + 4, k + 19, Blocks.nether_brick, 0);
        this.setBlock(world, i + 8, j + 5, k + 8, Blocks.nether_brick, 0);
        this.setBlock(world, i + 8, j + 5, k + 9, Blocks.nether_brick, 0);
        this.setBlock(world, i + 8, j + 5, k + 17, Blocks.nether_brick, 0);
        this.setBlock(world, i + 8, j + 5, k + 18, Blocks.nether_brick, 0);
        this.setBlock(world, i + 8, j + 6, k + 8, Blocks.nether_brick, 0);
        this.setBlock(world, i + 8, j + 6, k + 9, Blocks.nether_brick, 0);
        this.setBlock(world, i + 8, j + 6, k + 17, Blocks.nether_brick, 0);
        this.setBlock(world, i + 8, j + 6, k + 18, Blocks.nether_brick, 0);
        this.setBlock(world, i + 8, j + 7, k + 8, Blocks.nether_brick, 0);
        this.setBlock(world, i + 8, j + 7, k + 9, Blocks.nether_brick, 0);
        this.setBlock(world, i + 8, j + 7, k + 17, Blocks.nether_brick, 0);
        this.setBlock(world, i + 8, j + 7, k + 18, Blocks.nether_brick, 0);
        this.setBlock(world, i + 8, j + 8, k + 10, Blocks.nether_brick, 0);
        this.setBlock(world, i + 8, j + 8, k + 14, Blocks.nether_brick, 0);
        this.setBlock(world, i + 8, j + 8, k + 15, Blocks.nether_brick, 0);
        this.setBlock(world, i + 8, j + 8, k + 16, Blocks.nether_brick, 0);
        this.setBlock(world, i + 8, j + 9, k + 10, Blocks.nether_brick, 0);
        this.setBlock(world, i + 8, j + 9, k + 14, Blocks.nether_brick, 0);
        this.setBlock(world, i + 8, j + 9, k + 15, Blocks.nether_brick, 0);
        this.setBlock(world, i + 8, j + 9, k + 16, Blocks.nether_brick, 0);
        this.setBlock(world, i + 8, j + 10, k + 10, Blocks.nether_brick, 0);
        this.setBlock(world, i + 8, j + 10, k + 12, Blocks.obsidian, 0);
        this.setBlock(world, i + 8, j + 10, k + 14, Blocks.nether_brick, 0);
        this.setBlock(world, i + 8, j + 10, k + 15, Blocks.nether_brick, 0);
        this.setBlock(world, i + 8, j + 10, k + 16, Blocks.nether_brick, 0);
        this.setBlock(world, i + 8, j + 11, k + 11, Blocks.nether_brick, 0);
        this.setBlock(world, i + 8, j + 11, k + 12, Blocks.obsidian, 0);
        this.setBlock(world, i + 8, j + 11, k + 13, Blocks.nether_brick, 0);
        this.setBlock(world, i + 8, j + 12, k + 11, Blocks.nether_brick, 0);
        this.setBlock(world, i + 8, j + 12, k + 12, Blocks.obsidian, 0);
        this.setBlock(world, i + 8, j + 12, k + 13, Blocks.nether_brick, 0);
        this.setBlock(world, i + 8, j + 13, k + 11, Blocks.nether_brick, 0);
        this.setBlock(world, i + 8, j + 13, k + 12, Blocks.obsidian, 0);
        this.setBlock(world, i + 8, j + 13, k + 13, Blocks.nether_brick, 0);
        this.setBlock(world, i + 8, j + 14, k + 11, Blocks.nether_brick, 0);
        this.setBlock(world, i + 8, j + 14, k + 12, Blocks.obsidian, 0);
        this.setBlock(world, i + 8, j + 14, k + 13, Blocks.nether_brick, 0);
        this.setBlock(world, i + 8, j + 15, k + 12, Blocks.nether_brick, 0);
        this.setBlock(world, i + 8, j + 16, k + 12, Blocks.nether_brick, 0);
        this.setBlock(world, i + 8, j + 17, k + 12, Blocks.nether_brick, 0);
        this.setBlock(world, i + 8, j + 18, k + 12, Blocks.nether_brick, 0);
        this.setBlock(world, i + 8, j + 19, k + 12, Blocks.nether_brick, 0);
        this.setBlock(world, i + 8, j + 20, k + 12, Blocks.nether_brick, 0);
        this.setBlock(world, i + 8, j + 21, k + 12, Blocks.nether_brick, 0);
        this.setBlock(world, i + 9, j + 0, k + 4, Blocks.nether_brick, 0);
        this.setBlock(world, i + 9, j + 0, k + 5, Blocks.nether_brick, 0);
        this.setBlock(world, i + 9, j + 0, k + 6, Blocks.nether_brick, 0);
        this.setBlock(world, i + 9, j + 0, k + 7, Blocks.nether_brick, 0);
        this.setBlock(world, i + 9, j + 0, k + 8, Blocks.nether_brick, 0);
        this.setBlock(world, i + 9, j + 0, k + 9, Blocks.nether_brick, 0);
        this.setBlock(world, i + 9, j + 0, k + 10, Blocks.nether_brick, 0);
        this.setBlock(world, i + 9, j + 0, k + 11, Blocks.nether_brick, 0);
        this.setBlock(world, i + 9, j + 0, k + 12, Blocks.nether_brick, 0);
        this.setBlock(world, i + 9, j + 0, k + 13, Blocks.nether_brick, 0);
        this.setBlock(world, i + 9, j + 0, k + 14, Blocks.nether_brick, 0);
        this.setBlock(world, i + 9, j + 0, k + 15, Blocks.nether_brick, 0);
        this.setBlock(world, i + 9, j + 0, k + 16, Blocks.nether_brick, 0);
        this.setBlock(world, i + 9, j + 0, k + 17, Blocks.nether_brick, 0);
        this.setBlock(world, i + 9, j + 0, k + 18, Blocks.nether_brick, 0);
        this.setBlock(world, i + 9, j + 0, k + 19, Blocks.nether_brick, 0);
        this.setBlock(world, i + 9, j + 0, k + 20, Blocks.nether_brick, 0);
        this.setBlock(world, i + 9, j + 0, k + 21, Blocks.nether_brick, 0);
        this.setBlock(world, i + 9, j + 0, k + 22, Blocks.nether_brick, 0);
        this.setBlock(world, i + 9, j + 1, k + 5, Blocks.nether_brick, 0);
        this.setBlock(world, i + 9, j + 1, k + 6, Blocks.nether_brick, 0);
        this.setBlock(world, i + 9, j + 1, k + 20, Blocks.nether_brick, 0);
        this.setBlock(world, i + 9, j + 1, k + 21, Blocks.nether_brick, 0);
        this.setBlock(world, i + 9, j + 2, k + 6, Blocks.nether_brick, 0);
        this.setBlock(world, i + 9, j + 2, k + 20, Blocks.nether_brick, 0);
        this.setBlock(world, i + 9, j + 3, k + 6, Blocks.nether_brick, 0);
        this.setBlock(world, i + 9, j + 3, k + 20, Blocks.nether_brick, 0);
        this.setBlock(world, i + 9, j + 4, k + 6, Blocks.nether_brick, 0);
        this.setBlock(world, i + 9, j + 4, k + 20, Blocks.nether_brick, 0);
        this.setBlock(world, i + 9, j + 5, k + 7, Blocks.nether_brick, 0);
        this.setBlock(world, i + 9, j + 5, k + 8, Blocks.nether_brick, 0);
        this.setBlock(world, i + 9, j + 5, k + 18, Blocks.nether_brick, 0);
        this.setBlock(world, i + 9, j + 5, k + 19, Blocks.nether_brick, 0);
        this.setBlock(world, i + 9, j + 6, k + 7, Blocks.nether_brick, 0);
        this.setBlock(world, i + 9, j + 6, k + 8, Blocks.nether_brick, 0);
        this.setBlock(world, i + 9, j + 6, k + 18, Blocks.nether_brick, 0);
        this.setBlock(world, i + 9, j + 6, k + 19, Blocks.nether_brick, 0);
        this.setBlock(world, i + 9, j + 7, k + 7, Blocks.nether_brick, 0);
        this.setBlock(world, i + 9, j + 7, k + 8, Blocks.nether_brick, 0);
        this.setBlock(world, i + 9, j + 7, k + 18, Blocks.nether_brick, 0);
        this.setBlock(world, i + 9, j + 7, k + 19, Blocks.nether_brick, 0);
        this.setBlock(world, i + 9, j + 8, k + 9, Blocks.nether_brick, 0);
        this.setBlock(world, i + 9, j + 8, k + 10, Blocks.nether_brick, 0);
        this.setBlock(world, i + 9, j + 8, k + 16, Blocks.nether_brick, 0);
        this.setBlock(world, i + 9, j + 8, k + 17, Blocks.nether_brick, 0);
        this.setBlock(world, i + 9, j + 9, k + 9, Blocks.nether_brick, 0);
        this.setBlock(world, i + 9, j + 9, k + 10, Blocks.nether_brick, 0);
        this.setBlock(world, i + 9, j + 9, k + 16, Blocks.nether_brick, 0);
        this.setBlock(world, i + 9, j + 9, k + 17, Blocks.nether_brick, 0);
        this.setBlock(world, i + 9, j + 10, k + 9, Blocks.nether_brick, 0);
        this.setBlock(world, i + 9, j + 10, k + 10, Blocks.nether_brick, 0);
        this.setBlock(world, i + 9, j + 10, k + 16, Blocks.nether_brick, 0);
        this.setBlock(world, i + 9, j + 10, k + 17, Blocks.nether_brick, 0);
        this.setBlock(world, i + 9, j + 11, k + 11, Blocks.nether_brick, 0);
        this.setBlock(world, i + 9, j + 11, k + 13, Blocks.nether_brick, 0);
        this.setBlock(world, i + 9, j + 11, k + 14, Blocks.nether_brick, 0);
        this.setBlock(world, i + 9, j + 11, k + 15, Blocks.nether_brick, 0);
        this.setBlock(world, i + 9, j + 12, k + 11, Blocks.nether_brick, 0);
        this.setBlock(world, i + 9, j + 12, k + 13, Blocks.nether_brick, 0);
        this.setBlock(world, i + 9, j + 12, k + 14, Blocks.nether_brick, 0);
        this.setBlock(world, i + 9, j + 12, k + 15, Blocks.nether_brick, 0);
        this.setBlock(world, i + 9, j + 13, k + 11, Blocks.nether_brick, 0);
        this.setBlock(world, i + 9, j + 13, k + 13, Blocks.nether_brick, 0);
        this.setBlock(world, i + 9, j + 13, k + 14, Blocks.nether_brick, 0);
        this.setBlock(world, i + 9, j + 13, k + 15, Blocks.nether_brick, 0);
        this.setBlock(world, i + 9, j + 14, k + 11, Blocks.nether_brick, 0);
        this.setBlock(world, i + 9, j + 14, k + 13, Blocks.nether_brick, 0);
        this.setBlock(world, i + 9, j + 14, k + 14, Blocks.nether_brick, 0);
        this.setBlock(world, i + 9, j + 14, k + 15, Blocks.nether_brick, 0);
        this.setBlock(world, i + 9, j + 15, k + 12, Blocks.nether_brick, 0);
        this.setBlock(world, i + 9, j + 16, k + 12, Blocks.nether_brick, 0);
        this.setBlock(world, i + 9, j + 17, k + 12, Blocks.nether_brick, 0);
        this.setBlock(world, i + 9, j + 18, k + 12, Blocks.nether_brick, 0);
        this.setBlock(world, i + 9, j + 19, k + 12, Blocks.nether_brick, 0);
        this.setBlock(world, i + 9, j + 20, k + 12, Blocks.nether_brick, 0);
        this.setBlock(world, i + 10, j + 0, k + 3, Blocks.nether_brick, 0);
        this.setBlock(world, i + 10, j + 0, k + 4, Blocks.nether_brick, 0);
        this.setBlock(world, i + 10, j + 0, k + 5, Blocks.nether_brick, 0);
        this.setBlock(world, i + 10, j + 0, k + 6, Blocks.nether_brick, 0);
        this.setBlock(world, i + 10, j + 0, k + 7, Blocks.nether_brick, 0);
        this.setBlock(world, i + 10, j + 0, k + 8, Blocks.nether_brick, 0);
        this.setBlock(world, i + 10, j + 0, k + 9, Blocks.nether_brick, 0);
        this.setBlock(world, i + 10, j + 0, k + 10, Blocks.nether_brick, 0);
        this.setBlock(world, i + 10, j + 0, k + 11, Blocks.nether_brick, 0);
        this.setBlock(world, i + 10, j + 0, k + 12, Blocks.nether_brick, 0);
        this.setBlock(world, i + 10, j + 0, k + 13, Blocks.nether_brick, 0);
        this.setBlock(world, i + 10, j + 0, k + 14, Blocks.nether_brick, 0);
        this.setBlock(world, i + 10, j + 0, k + 15, Blocks.nether_brick, 0);
        this.setBlock(world, i + 10, j + 0, k + 16, Blocks.nether_brick, 0);
        this.setBlock(world, i + 10, j + 0, k + 17, Blocks.nether_brick, 0);
        this.setBlock(world, i + 10, j + 0, k + 18, Blocks.nether_brick, 0);
        this.setBlock(world, i + 10, j + 0, k + 19, Blocks.nether_brick, 0);
        this.setBlock(world, i + 10, j + 0, k + 20, Blocks.nether_brick, 0);
        this.setBlock(world, i + 10, j + 0, k + 21, Blocks.nether_brick, 0);
        this.setBlock(world, i + 10, j + 0, k + 22, Blocks.nether_brick, 0);
        this.setBlock(world, i + 10, j + 0, k + 23, Blocks.nether_brick, 0);
        this.setBlock(world, i + 10, j + 1, k + 4, Blocks.nether_brick, 0);
        this.setBlock(world, i + 10, j + 1, k + 5, Blocks.nether_brick, 0);
        this.setBlock(world, i + 10, j + 1, k + 6, Blocks.nether_brick, 0);
        this.setBlock(world, i + 10, j + 1, k + 19, Blocks.obsidian, 0);
        this.setBlock(world, i + 10, j + 1, k + 20, Blocks.nether_brick, 0);
        this.setBlock(world, i + 10, j + 1, k + 21, Blocks.nether_brick, 0);
        this.setBlock(world, i + 10, j + 1, k + 22, Blocks.nether_brick, 0);
        this.setBlock(world, i + 10, j + 2, k + 6, Blocks.nether_brick, 0);
        this.setBlock(world, i + 10, j + 2, k + 19, Blocks.obsidian, 0);
        this.setBlock(world, i + 10, j + 2, k + 20, Blocks.nether_brick, 0);
        this.setBlock(world, i + 10, j + 3, k + 6, Blocks.nether_brick, 0);
        this.setBlock(world, i + 10, j + 3, k + 19, Blocks.obsidian, 0);
        this.setBlock(world, i + 10, j + 3, k + 20, Blocks.nether_brick, 0);
        this.setBlock(world, i + 10, j + 4, k + 6, Blocks.nether_brick, 0);
        this.setBlock(world, i + 10, j + 4, k + 19, Blocks.obsidian, 0);
        this.setBlock(world, i + 10, j + 4, k + 20, Blocks.nether_brick, 0);
        this.setBlock(world, i + 10, j + 5, k + 7, Blocks.nether_brick, 0);
        this.setBlock(world, i + 10, j + 5, k + 19, Blocks.obsidian, 0);
        this.setBlock(world, i + 10, j + 6, k + 7, Blocks.nether_brick, 0);
        this.setBlock(world, i + 10, j + 6, k + 19, Blocks.obsidian, 0);
        this.setBlock(world, i + 10, j + 7, k + 7, Blocks.nether_brick, 0);
        this.setBlock(world, i + 10, j + 7, k + 19, Blocks.obsidian, 0);
        this.setBlock(world, i + 10, j + 8, k + 8, Blocks.nether_brick, 0);
        this.setBlock(world, i + 10, j + 8, k + 9, Blocks.nether_brick, 0);
        this.setBlock(world, i + 10, j + 8, k + 17, Blocks.nether_brick, 0);
        this.setBlock(world, i + 10, j + 8, k + 18, Blocks.nether_brick, 0);
        this.setBlock(world, i + 10, j + 8, k + 19, Blocks.nether_brick, 0);
        this.setBlock(world, i + 10, j + 9, k + 8, Blocks.nether_brick, 0);
        this.setBlock(world, i + 10, j + 9, k + 9, Blocks.nether_brick, 0);
        this.setBlock(world, i + 10, j + 9, k + 17, Blocks.nether_brick, 0);
        this.setBlock(world, i + 10, j + 9, k + 18, Blocks.nether_brick, 0);
        this.setBlock(world, i + 10, j + 9, k + 19, Blocks.nether_brick, 0);
        this.setBlock(world, i + 10, j + 10, k + 8, Blocks.nether_brick, 0);
        this.setBlock(world, i + 10, j + 10, k + 9, Blocks.nether_brick, 0);
        this.setBlock(world, i + 10, j + 10, k + 17, Blocks.nether_brick, 0);
        this.setBlock(world, i + 10, j + 10, k + 18, Blocks.nether_brick, 0);
        this.setBlock(world, i + 10, j + 10, k + 19, Blocks.nether_brick, 0);
        this.setBlock(world, i + 10, j + 11, k + 10, Blocks.nether_brick, 0);
        this.setBlock(world, i + 10, j + 11, k + 11, Blocks.nether_brick, 0);
        this.setBlock(world, i + 10, j + 11, k + 15, Blocks.nether_brick, 0);
        this.setBlock(world, i + 10, j + 11, k + 16, Blocks.nether_brick, 0);
        this.setBlock(world, i + 10, j + 12, k + 10, Blocks.nether_brick, 0);
        this.setBlock(world, i + 10, j + 12, k + 11, Blocks.nether_brick, 0);
        this.setBlock(world, i + 10, j + 12, k + 15, Blocks.nether_brick, 0);
        this.setBlock(world, i + 10, j + 12, k + 16, Blocks.nether_brick, 0);
        this.setBlock(world, i + 10, j + 13, k + 10, Blocks.nether_brick, 0);
        this.setBlock(world, i + 10, j + 13, k + 11, Blocks.nether_brick, 0);
        this.setBlock(world, i + 10, j + 13, k + 15, Blocks.nether_brick, 0);
        this.setBlock(world, i + 10, j + 13, k + 16, Blocks.nether_brick, 0);
        this.setBlock(world, i + 10, j + 14, k + 10, Blocks.nether_brick, 0);
        this.setBlock(world, i + 10, j + 14, k + 11, Blocks.nether_brick, 0);
        this.setBlock(world, i + 10, j + 14, k + 15, Blocks.nether_brick, 0);
        this.setBlock(world, i + 10, j + 14, k + 16, Blocks.nether_brick, 0);
        this.setBlock(world, i + 10, j + 15, k + 12, Blocks.nether_brick, 0);
        this.setBlock(world, i + 10, j + 15, k + 13, Blocks.nether_brick, 0);
        this.setBlock(world, i + 10, j + 15, k + 14, Blocks.nether_brick, 0);
        this.setBlock(world, i + 10, j + 16, k + 12, Blocks.nether_brick, 0);
        this.setBlock(world, i + 10, j + 16, k + 13, Blocks.nether_brick, 0);
        this.setBlock(world, i + 10, j + 16, k + 14, Blocks.nether_brick, 0);
        this.setBlock(world, i + 10, j + 17, k + 12, Blocks.nether_brick, 0);
        this.setBlock(world, i + 10, j + 17, k + 13, Blocks.nether_brick, 0);
        this.setBlock(world, i + 10, j + 17, k + 14, Blocks.nether_brick, 0);
        this.setBlock(world, i + 10, j + 18, k + 12, Blocks.nether_brick, 0);
        this.setBlock(world, i + 10, j + 18, k + 13, Blocks.nether_brick, 0);
        this.setBlock(world, i + 10, j + 18, k + 14, Blocks.nether_brick, 0);
        this.setBlock(world, i + 10, j + 19, k + 12, Blocks.nether_brick, 0);
        this.setBlock(world, i + 11, j + 0, k + 3, Blocks.nether_brick, 0);
        this.setBlock(world, i + 11, j + 0, k + 4, Blocks.nether_brick, 0);
        this.setBlock(world, i + 11, j + 0, k + 5, Blocks.nether_brick, 0);
        this.setBlock(world, i + 11, j + 0, k + 6, Blocks.nether_brick, 0);
        this.setBlock(world, i + 11, j + 0, k + 7, Blocks.nether_brick, 0);
        this.setBlock(world, i + 11, j + 0, k + 8, Blocks.nether_brick, 0);
        this.setBlock(world, i + 11, j + 0, k + 9, Blocks.nether_brick, 0);
        this.setBlock(world, i + 11, j + 0, k + 10, Blocks.nether_brick, 0);
        this.setBlock(world, i + 11, j + 0, k + 11, Blocks.nether_brick, 0);
        this.setBlock(world, i + 11, j + 0, k + 12, Blocks.nether_brick, 0);
        this.setBlock(world, i + 11, j + 0, k + 13, Blocks.glowstone, 0);
        this.setBlock(world, i + 11, j + 0, k + 14, Blocks.nether_brick, 0);
        this.setBlock(world, i + 11, j + 0, k + 15, Blocks.nether_brick, 0);
        this.setBlock(world, i + 11, j + 0, k + 16, Blocks.nether_brick, 0);
        this.setBlock(world, i + 11, j + 0, k + 17, Blocks.nether_brick, 0);
        this.setBlock(world, i + 11, j + 0, k + 18, Blocks.nether_brick, 0);
        this.setBlock(world, i + 11, j + 0, k + 19, Blocks.nether_brick, 0);
        this.setBlock(world, i + 11, j + 0, k + 20, Blocks.nether_brick, 0);
        this.setBlock(world, i + 11, j + 0, k + 21, Blocks.nether_brick, 0);
        this.setBlock(world, i + 11, j + 0, k + 22, Blocks.nether_brick, 0);
        this.setBlock(world, i + 11, j + 0, k + 23, Blocks.nether_brick, 0);
        this.setBlock(world, i + 11, j + 1, k + 4, Blocks.nether_brick, 0);
        this.setBlock(world, i + 11, j + 1, k + 5, Blocks.nether_brick, 0);
        this.setBlock(world, i + 11, j + 1, k + 19, Blocks.obsidian, 0);
        this.setBlock(world, i + 11, j + 1, k + 20, Blocks.obsidian, 0);
        this.setBlock(world, i + 11, j + 1, k + 21, Blocks.nether_brick, 0);
        this.setBlock(world, i + 11, j + 1, k + 22, Blocks.nether_brick, 0);
        this.setBlock(world, i + 11, j + 2, k + 5, Blocks.nether_brick, 0);
        this.setBlock(world, i + 11, j + 2, k + 19, Blocks.obsidian, 0);
        this.setBlock(world, i + 11, j + 2, k + 20, Blocks.obsidian, 0);
        this.setBlock(world, i + 11, j + 2, k + 21, Blocks.nether_brick, 0);
        this.setBlock(world, i + 11, j + 3, k + 5, Blocks.nether_brick, 0);
        this.setBlock(world, i + 11, j + 3, k + 19, Blocks.obsidian, 0);
        this.setBlock(world, i + 11, j + 3, k + 20, Blocks.obsidian, 0);
        this.setBlock(world, i + 11, j + 3, k + 21, Blocks.nether_brick, 0);
        this.setBlock(world, i + 11, j + 4, k + 5, Blocks.nether_brick, 0);
        this.setBlock(world, i + 11, j + 4, k + 19, Blocks.obsidian, 0);
        this.setBlock(world, i + 11, j + 4, k + 20, Blocks.obsidian, 0);
        this.setBlock(world, i + 11, j + 4, k + 21, Blocks.nether_brick, 0);
        this.setBlock(world, i + 11, j + 5, k + 6, Blocks.nether_brick, 0);
        this.setBlock(world, i + 11, j + 5, k + 7, Blocks.nether_brick, 0);
        this.setBlock(world, i + 11, j + 5, k + 19, Blocks.obsidian, 0);
        this.setBlock(world, i + 11, j + 5, k + 20, Blocks.obsidian, 0);
        this.setBlock(world, i + 11, j + 6, k + 6, Blocks.nether_brick, 0);
        this.setBlock(world, i + 11, j + 6, k + 7, Blocks.nether_brick, 0);
        this.setBlock(world, i + 11, j + 6, k + 19, Blocks.obsidian, 0);
        this.setBlock(world, i + 11, j + 6, k + 20, Blocks.obsidian, 0);
        this.setBlock(world, i + 11, j + 7, k + 6, Blocks.nether_brick, 0);
        this.setBlock(world, i + 11, j + 7, k + 7, Blocks.nether_brick, 0);
        this.setBlock(world, i + 11, j + 7, k + 19, Blocks.obsidian, 0);
        this.setBlock(world, i + 11, j + 7, k + 20, Blocks.obsidian, 0);
        this.setBlock(world, i + 11, j + 8, k + 8, Blocks.nether_brick, 0);
        this.setBlock(world, i + 11, j + 8, k + 19, Blocks.obsidian, 0);
        this.setBlock(world, i + 11, j + 9, k + 8, Blocks.nether_brick, 0);
        this.setBlock(world, i + 11, j + 9, k + 19, Blocks.obsidian, 0);
        this.setBlock(world, i + 11, j + 10, k + 8, Blocks.nether_brick, 0);
        this.setBlock(world, i + 11, j + 10, k + 19, Blocks.obsidian, 0);
        this.setBlock(world, i + 11, j + 11, k + 9, Blocks.nether_brick, 0);
        this.setBlock(world, i + 11, j + 11, k + 10, Blocks.nether_brick, 0);
        this.setBlock(world, i + 11, j + 11, k + 16, Blocks.nether_brick, 0);
        this.setBlock(world, i + 11, j + 11, k + 17, Blocks.nether_brick, 0);
        this.setBlock(world, i + 11, j + 11, k + 18, Blocks.nether_brick, 0);
        this.setBlock(world, i + 11, j + 12, k + 9, Blocks.nether_brick, 0);
        this.setBlock(world, i + 11, j + 12, k + 10, Blocks.nether_brick, 0);
        this.setBlock(world, i + 11, j + 12, k + 16, Blocks.nether_brick, 0);
        this.setBlock(world, i + 11, j + 12, k + 17, Blocks.nether_brick, 0);
        this.setBlock(world, i + 11, j + 12, k + 18, Blocks.nether_brick, 0);
        this.setBlock(world, i + 11, j + 13, k + 9, Blocks.nether_brick, 0);
        this.setBlock(world, i + 11, j + 13, k + 10, Blocks.nether_brick, 0);
        this.setBlock(world, i + 11, j + 13, k + 16, Blocks.nether_brick, 0);
        this.setBlock(world, i + 11, j + 13, k + 17, Blocks.nether_brick, 0);
        this.setBlock(world, i + 11, j + 13, k + 18, Blocks.nether_brick, 0);
        this.setBlock(world, i + 11, j + 14, k + 9, Blocks.nether_brick, 0);
        this.setBlock(world, i + 11, j + 14, k + 10, Blocks.nether_brick, 0);
        this.setBlock(world, i + 11, j + 14, k + 13, Blocks.obsidian, 0);
        this.setBlock(world, i + 11, j + 14, k + 16, Blocks.nether_brick, 0);
        this.setBlock(world, i + 11, j + 14, k + 17, Blocks.nether_brick, 0);
        this.setBlock(world, i + 11, j + 14, k + 18, Blocks.nether_brick, 0);
        this.setBlock(world, i + 11, j + 15, k + 9, Blocks.soul_sand, 0);
        this.setBlock(world, i + 11, j + 15, k + 10, Blocks.soul_sand, 0);
        this.setBlock(world, i + 11, j + 15, k + 11, Blocks.nether_brick, 0);
        this.setBlock(world, i + 11, j + 15, k + 12, Blocks.nether_brick, 0);
        this.setBlock(world, i + 11, j + 15, k + 13, Blocks.obsidian, 0);
        this.setBlock(world, i + 11, j + 15, k + 14, Blocks.nether_brick, 0);
        this.setBlock(world, i + 11, j + 15, k + 15, Blocks.nether_brick, 0);
        this.setBlock(world, i + 11, j + 16, k + 9, Blocks.soul_sand, 0);
        this.setBlock(world, i + 11, j + 16, k + 10, Blocks.soul_sand, 0);
        this.setBlock(world, i + 11, j + 16, k + 11, Blocks.nether_brick, 0);
        this.setBlock(world, i + 11, j + 16, k + 12, Blocks.nether_brick, 0);
        this.setBlock(world, i + 11, j + 16, k + 13, Blocks.obsidian, 0);
        this.setBlock(world, i + 11, j + 16, k + 14, Blocks.nether_brick, 0);
        this.setBlock(world, i + 11, j + 16, k + 15, Blocks.nether_brick, 0);
        this.setBlock(world, i + 11, j + 17, k + 9, Blocks.nether_brick, 0);
        this.setBlock(world, i + 11, j + 17, k + 10, Blocks.nether_brick, 0);
        this.setBlock(world, i + 11, j + 17, k + 11, Blocks.nether_brick, 0);
        this.setBlock(world, i + 11, j + 17, k + 12, Blocks.nether_brick, 0);
        this.setBlock(world, i + 11, j + 17, k + 13, Blocks.obsidian, 0);
        this.setBlock(world, i + 11, j + 17, k + 14, Blocks.nether_brick, 0);
        this.setBlock(world, i + 11, j + 17, k + 15, Blocks.nether_brick, 0);
        this.setBlock(world, i + 11, j + 18, k + 11, Blocks.nether_brick, 0);
        this.setBlock(world, i + 11, j + 18, k + 12, Blocks.nether_brick, 0);
        this.setBlock(world, i + 11, j + 18, k + 14, Blocks.nether_brick, 0);
        this.setBlock(world, i + 11, j + 18, k + 15, Blocks.nether_brick, 0);
        this.setBlock(world, i + 12, j + 0, k + 3, Blocks.nether_brick, 0);
        this.setBlock(world, i + 12, j + 0, k + 4, Blocks.nether_brick, 0);
        this.setBlock(world, i + 12, j + 0, k + 5, Blocks.nether_brick, 0);
        this.setBlock(world, i + 12, j + 0, k + 6, Blocks.nether_brick, 0);
        this.setBlock(world, i + 12, j + 0, k + 7, Blocks.nether_brick, 0);
        this.setBlock(world, i + 12, j + 0, k + 8, Blocks.nether_brick, 0);
        this.setBlock(world, i + 12, j + 0, k + 9, Blocks.nether_brick, 0);
        this.setBlock(world, i + 12, j + 0, k + 10, Blocks.nether_brick, 0);
        this.setBlock(world, i + 12, j + 0, k + 11, Blocks.nether_brick, 0);
        this.setBlock(world, i + 12, j + 0, k + 12, Blocks.glowstone, 0);
        this.setBlock(world, i + 12, j + 0, k + 13, Blocks.nether_brick, 0);
        this.setBlock(world, i + 12, j + 0, k + 14, Blocks.glowstone, 0);
        this.setBlock(world, i + 12, j + 0, k + 15, Blocks.nether_brick, 0);
        this.setBlock(world, i + 12, j + 0, k + 16, Blocks.nether_brick, 0);
        this.setBlock(world, i + 12, j + 0, k + 17, Blocks.nether_brick, 0);
        this.setBlock(world, i + 12, j + 0, k + 18, Blocks.nether_brick, 0);
        this.setBlock(world, i + 12, j + 0, k + 19, Blocks.nether_brick, 0);
        this.setBlock(world, i + 12, j + 0, k + 20, Blocks.nether_brick, 0);
        this.setBlock(world, i + 12, j + 0, k + 21, Blocks.nether_brick, 0);
        this.setBlock(world, i + 12, j + 0, k + 22, Blocks.nether_brick, 0);
        this.setBlock(world, i + 12, j + 0, k + 23, Blocks.nether_brick, 0);
        this.setBlock(world, i + 12, j + 1, k + 4, Blocks.nether_brick, 0);
        this.setBlock(world, i + 12, j + 1, k + 5, Blocks.nether_brick, 0);
        Dungeons.spawner(world, i + 12, j + 1, k + 6, 27, 1);
        this.setBlock(world, i + 12, j + 1, k + 13, Blocks.nether_brick, 0);
        this.setBlock(world, i + 12, j + 1, k + 20, Blocks.obsidian, 0);
        this.setBlock(world, i + 12, j + 1, k + 21, Blocks.nether_brick, 0);
        this.setBlock(world, i + 12, j + 1, k + 22, Blocks.nether_brick, 0);
        this.setBlock(world, i + 12, j + 2, k + 5, Blocks.nether_brick, 0);
        this.setBlock(world, i + 12, j + 2, k + 20, Blocks.obsidian, 0);
        this.setBlock(world, i + 12, j + 2, k + 21, Blocks.nether_brick, 0);
        this.setBlock(world, i + 12, j + 3, k + 5, Blocks.nether_brick, 0);
        this.setBlock(world, i + 12, j + 3, k + 20, Blocks.obsidian, 0);
        this.setBlock(world, i + 12, j + 3, k + 21, Blocks.nether_brick, 0);
        this.setBlock(world, i + 12, j + 4, k + 5, Blocks.nether_brick, 0);
        this.setBlock(world, i + 12, j + 4, k + 20, Blocks.obsidian, 0);
        this.setBlock(world, i + 12, j + 4, k + 21, Blocks.nether_brick, 0);
        this.setBlock(world, i + 12, j + 5, k + 6, Blocks.nether_brick, 0);
        this.setBlock(world, i + 12, j + 5, k + 20, Blocks.obsidian, 0);
        this.setBlock(world, i + 12, j + 6, k + 6, Blocks.nether_brick, 0);
        this.setBlock(world, i + 12, j + 6, k + 20, Blocks.obsidian, 0);
        this.setBlock(world, i + 12, j + 7, k + 6, Blocks.nether_brick, 0);
        this.setBlock(world, i + 12, j + 7, k + 19, Blocks.obsidian, 0);
        this.setBlock(world, i + 12, j + 7, k + 20, Blocks.obsidian, 0);
        this.setBlock(world, i + 12, j + 8, k + 7, Blocks.nether_brick, 0);
        this.setBlock(world, i + 12, j + 8, k + 8, Blocks.nether_brick, 0);
        this.setBlock(world, i + 12, j + 8, k + 19, Blocks.obsidian, 0);
        this.setBlock(world, i + 12, j + 9, k + 7, Blocks.nether_brick, 0);
        this.setBlock(world, i + 12, j + 9, k + 8, Blocks.nether_brick, 0);
        this.setBlock(world, i + 12, j + 9, k + 19, Blocks.obsidian, 0);
        this.setBlock(world, i + 12, j + 10, k + 7, Blocks.nether_brick, 0);
        this.setBlock(world, i + 12, j + 10, k + 8, Blocks.nether_brick, 0);
        this.setBlock(world, i + 12, j + 10, k + 18, Blocks.obsidian, 0);
        this.setBlock(world, i + 12, j + 10, k + 19, Blocks.obsidian, 0);
        this.setBlock(world, i + 12, j + 11, k + 8, Blocks.soul_sand, 0);
        this.setBlock(world, i + 12, j + 11, k + 9, Blocks.nether_brick, 0);
        this.setBlock(world, i + 12, j + 11, k + 18, Blocks.obsidian, 0);
        this.setBlock(world, i + 12, j + 12, k + 8, Blocks.soul_sand, 0);
        this.setBlock(world, i + 12, j + 12, k + 9, Blocks.nether_brick, 0);
        this.setBlock(world, i + 12, j + 12, k + 18, Blocks.obsidian, 0);
        this.setBlock(world, i + 12, j + 13, k + 8, Blocks.soul_sand, 0);
        this.setBlock(world, i + 12, j + 13, k + 9, Blocks.nether_brick, 0);
        this.setBlock(world, i + 12, j + 13, k + 13, Blocks.obsidian, 0);
        this.setBlock(world, i + 12, j + 13, k + 18, Blocks.obsidian, 0);
        this.setBlock(world, i + 12, j + 14, k + 8, Blocks.soul_sand, 0);
        this.setBlock(world, i + 12, j + 14, k + 9, Blocks.nether_brick, 0);
        this.setBlock(world, i + 12, j + 14, k + 12, Blocks.obsidian, 0);
        this.setBlock(world, i + 12, j + 14, k + 13, Blocks.obsidian, 0);
        this.setBlock(world, i + 12, j + 14, k + 14, Blocks.obsidian, 0);
        this.setBlock(world, i + 12, j + 14, k + 18, Blocks.obsidian, 0);
        this.setBlock(world, i + 12, j + 15, k + 8, Blocks.soul_sand, 0);
        this.setBlock(world, i + 12, j + 15, k + 9, Blocks.soul_sand, 0);
        this.setBlock(world, i + 12, j + 15, k + 10, Blocks.nether_brick, 0);
        this.setBlock(world, i + 12, j + 15, k + 11, Blocks.nether_brick, 0);
        this.setBlock(world, i + 12, j + 15, k + 12, Blocks.obsidian, 0);
        this.setBlock(world, i + 12, j + 15, k + 13, Blocks.obsidian, 0);
        this.setBlock(world, i + 12, j + 15, k + 14, Blocks.obsidian, 0);
        this.setBlock(world, i + 12, j + 15, k + 15, Blocks.nether_brick, 0);
        this.setBlock(world, i + 12, j + 15, k + 16, Blocks.nether_brick, 0);
        this.setBlock(world, i + 12, j + 15, k + 17, Blocks.nether_brick, 0);
        this.setBlock(world, i + 12, j + 15, k + 18, Blocks.nether_brick, 0);
        this.setBlock(world, i + 12, j + 16, k + 8, Blocks.soul_sand, 0);
        this.setBlock(world, i + 12, j + 16, k + 9, Blocks.soul_sand, 0);
        this.setBlock(world, i + 12, j + 16, k + 10, Blocks.nether_brick, 0);
        this.setBlock(world, i + 12, j + 16, k + 11, Blocks.nether_brick, 0);
        this.setBlock(world, i + 12, j + 16, k + 12, Blocks.obsidian, 0);
        this.setBlock(world, i + 12, j + 16, k + 14, Blocks.obsidian, 0);
        this.setBlock(world, i + 12, j + 16, k + 15, Blocks.nether_brick, 0);
        this.setBlock(world, i + 12, j + 16, k + 16, Blocks.nether_brick, 0);
        this.setBlock(world, i + 12, j + 16, k + 17, Blocks.nether_brick, 0);
        this.setBlock(world, i + 12, j + 16, k + 18, Blocks.nether_brick, 0);
        this.setBlock(world, i + 12, j + 17, k + 8, Blocks.nether_brick, 0);
        this.setBlock(world, i + 12, j + 17, k + 9, Blocks.nether_brick, 0);
        this.setBlock(world, i + 12, j + 17, k + 10, Blocks.nether_brick, 0);
        this.setBlock(world, i + 12, j + 17, k + 11, Blocks.nether_brick, 0);
        this.setBlock(world, i + 12, j + 17, k + 12, Blocks.obsidian, 0);
        this.setBlock(world, i + 12, j + 17, k + 14, Blocks.obsidian, 0);
        this.setBlock(world, i + 12, j + 17, k + 15, Blocks.nether_brick, 0);
        this.setBlock(world, i + 12, j + 17, k + 16, Blocks.nether_brick, 0);
        this.setBlock(world, i + 12, j + 17, k + 17, Blocks.nether_brick, 0);
        this.setBlock(world, i + 12, j + 17, k + 18, Blocks.nether_brick, 0);
        this.setBlock(world, i + 12, j + 18, k + 10, Blocks.nether_brick, 0);
        this.setBlock(world, i + 12, j + 18, k + 11, Blocks.nether_brick, 0);
        this.setBlock(world, i + 12, j + 18, k + 15, Blocks.nether_brick, 0);
        this.setBlock(world, i + 12, j + 18, k + 16, Blocks.nether_brick, 0);
        this.setBlock(world, i + 12, j + 18, k + 17, Blocks.nether_brick, 0);
        this.setBlock(world, i + 12, j + 18, k + 18, Blocks.nether_brick, 0);
        this.setBlock(world, i + 12, j + 19, k + 16, Blocks.nether_brick, 0);
        this.setBlock(world, i + 12, j + 19, k + 17, Blocks.nether_brick, 0);
        this.setBlock(world, i + 12, j + 19, k + 18, Blocks.nether_brick, 0);
        this.setBlock(world, i + 12, j + 20, k + 17, Blocks.nether_brick, 0);
        this.setBlock(world, i + 12, j + 20, k + 18, Blocks.nether_brick, 0);
        this.setBlock(world, i + 12, j + 21, k + 18, Blocks.nether_brick, 0);
        this.setBlock(world, i + 13, j + 0, k + 3, Blocks.nether_brick, 0);
        this.setBlock(world, i + 13, j + 0, k + 4, Blocks.nether_brick, 0);
        this.setBlock(world, i + 13, j + 0, k + 5, Blocks.nether_brick, 0);
        this.setBlock(world, i + 13, j + 0, k + 6, Blocks.nether_brick, 0);
        this.setBlock(world, i + 13, j + 0, k + 7, Blocks.nether_brick, 0);
        this.setBlock(world, i + 13, j + 0, k + 8, Blocks.nether_brick, 0);
        this.setBlock(world, i + 13, j + 0, k + 9, Blocks.nether_brick, 0);
        this.setBlock(world, i + 13, j + 0, k + 10, Blocks.nether_brick, 0);
        this.setBlock(world, i + 13, j + 0, k + 11, Blocks.glowstone, 0);
        this.setBlock(world, i + 13, j + 0, k + 12, Blocks.nether_brick, 0);
        this.setBlock(world, i + 13, j + 0, k + 13, Blocks.nether_brick, 0);
        this.setBlock(world, i + 13, j + 0, k + 14, Blocks.nether_brick, 0);
        this.setBlock(world, i + 13, j + 0, k + 15, Blocks.glowstone, 0);
        this.setBlock(world, i + 13, j + 0, k + 16, Blocks.nether_brick, 0);
        this.setBlock(world, i + 13, j + 0, k + 17, Blocks.nether_brick, 0);
        this.setBlock(world, i + 13, j + 0, k + 18, Blocks.nether_brick, 0);
        this.setBlock(world, i + 13, j + 0, k + 19, Blocks.nether_brick, 0);
        this.setBlock(world, i + 13, j + 0, k + 20, Blocks.nether_brick, 0);
        this.setBlock(world, i + 13, j + 0, k + 21, Blocks.nether_brick, 0);
        this.setBlock(world, i + 13, j + 0, k + 22, Blocks.nether_brick, 0);
        this.setBlock(world, i + 13, j + 0, k + 23, Blocks.nether_brick, 0);
        this.setBlock(world, i + 13, j + 0, k + 24, Blocks.nether_brick, 0);
        this.setBlock(world, i + 13, j + 0, k + 25, Blocks.nether_brick, 0);
        this.setBlock(world, i + 13, j + 1, k + 4, Blocks.nether_brick, 0);
        this.setBlock(world, i + 13, j + 1, k + 5, Blocks.nether_brick, 0);
        this.setBlock(world, i + 13, j + 1, k + 12, Blocks.nether_brick, 0);
        this.setBlock(world, i + 13, j + 1, k + 13, Blocks.tnt, 0);
        this.setBlock(world, i + 13, j + 1, k + 14, Blocks.nether_brick, 0);
        this.setBlock(world, i + 13, j + 1, k + 21, Blocks.nether_brick, 0);
        this.setBlock(world, i + 13, j + 1, k + 22, Blocks.nether_brick, 0);
        this.setBlock(world, i + 13, j + 2, k + 5, Blocks.nether_brick, 0);
        this.setBlock(world, i + 13, j + 2, k + 21, Blocks.nether_brick, 0);
        this.setBlock(world, i + 13, j + 3, k + 5, Blocks.nether_brick, 0);
        this.setBlock(world, i + 13, j + 3, k + 21, Blocks.nether_brick, 0);
        this.setBlock(world, i + 13, j + 4, k + 5, Blocks.nether_brick, 0);
        this.setBlock(world, i + 13, j + 4, k + 21, Blocks.nether_brick, 0);
        this.setBlock(world, i + 13, j + 5, k + 6, Blocks.nether_brick, 0);
        this.setBlock(world, i + 13, j + 5, k + 20, Blocks.nether_brick, 0);
        this.setBlock(world, i + 13, j + 6, k + 6, Blocks.nether_brick, 0);
        this.setBlock(world, i + 13, j + 6, k + 20, Blocks.nether_brick, 0);
        this.setBlock(world, i + 13, j + 7, k + 6, Blocks.nether_brick, 0);
        this.setBlock(world, i + 13, j + 7, k + 20, Blocks.nether_brick, 0);
        this.setBlock(world, i + 13, j + 8, k + 7, Blocks.nether_brick, 0);
        this.setBlock(world, i + 13, j + 8, k + 19, Blocks.nether_brick, 0);
        this.setBlock(world, i + 13, j + 9, k + 7, Blocks.nether_brick, 0);
        this.setBlock(world, i + 13, j + 9, k + 19, Blocks.nether_brick, 0);
        this.setBlock(world, i + 13, j + 10, k + 7, Blocks.nether_brick, 0);
        this.setBlock(world, i + 13, j + 10, k + 19, Blocks.nether_brick, 0);
        this.setBlock(world, i + 13, j + 11, k + 7, Blocks.soul_sand, 0);
        this.setBlock(world, i + 13, j + 11, k + 8, Blocks.nether_brick, 0);
        this.setBlock(world, i + 13, j + 11, k + 9, Blocks.nether_brick, 0);
        this.setBlock(world, i + 13, j + 11, k + 17, Blocks.nether_brick, 0);
        this.setBlock(world, i + 13, j + 11, k + 18, Blocks.nether_brick, 0);
        this.setBlock(world, i + 13, j + 12, k + 7, Blocks.soul_sand, 0);
        this.setBlock(world, i + 13, j + 12, k + 8, Blocks.nether_brick, 0);
        this.setBlock(world, i + 13, j + 12, k + 9, Blocks.nether_brick, 0);
        this.setBlock(world, i + 13, j + 12, k + 17, Blocks.nether_brick, 0);
        this.setBlock(world, i + 13, j + 12, k + 18, Blocks.nether_brick, 0);
        this.setBlock(world, i + 13, j + 13, k + 7, Blocks.soul_sand, 0);
        this.setBlock(world, i + 13, j + 13, k + 8, Blocks.nether_brick, 0);
        this.setBlock(world, i + 13, j + 13, k + 9, Blocks.nether_brick, 0);
        this.setBlock(world, i + 13, j + 13, k + 12, Blocks.obsidian, 0);
        this.setBlock(world, i + 13, j + 13, k + 14, Blocks.obsidian, 0);
        this.setBlock(world, i + 13, j + 13, k + 17, Blocks.nether_brick, 0);
        this.setBlock(world, i + 13, j + 13, k + 18, Blocks.nether_brick, 0);
        this.setBlock(world, i + 13, j + 14, k + 7, Blocks.soul_sand, 0);
        this.setBlock(world, i + 13, j + 14, k + 8, Blocks.nether_brick, 0);
        this.setBlock(world, i + 13, j + 14, k + 9, Blocks.nether_brick, 0);
        this.setBlock(world, i + 13, j + 14, k + 11, Blocks.obsidian, 0);
        this.setBlock(world, i + 13, j + 14, k + 12, Blocks.obsidian, 0);
        this.setBlock(world, i + 13, j + 14, k + 14, Blocks.obsidian, 0);
        this.setBlock(world, i + 13, j + 14, k + 15, Blocks.obsidian, 0);
        this.setBlock(world, i + 13, j + 14, k + 17, Blocks.nether_brick, 0);
        this.setBlock(world, i + 13, j + 14, k + 18, Blocks.nether_brick, 0);
        this.setBlock(world, i + 13, j + 15, k + 7, Blocks.soul_sand, 0);
        this.setBlock(world, i + 13, j + 15, k + 8, Blocks.soul_sand, 0);
        this.setBlock(world, i + 13, j + 15, k + 9, Blocks.soul_sand, 0);
        this.setBlock(world, i + 13, j + 15, k + 10, Blocks.nether_brick, 0);
        this.setBlock(world, i + 13, j + 15, k + 11, Blocks.obsidian, 0);
        this.setBlock(world, i + 13, j + 15, k + 12, Blocks.obsidian, 0);
        this.setBlock(world, i + 13, j + 15, k + 14, Blocks.obsidian, 0);
        this.setBlock(world, i + 13, j + 15, k + 15, Blocks.obsidian, 0);
        this.setBlock(world, i + 13, j + 15, k + 16, Blocks.nether_brick, 0);
        this.setBlock(world, i + 13, j + 16, k + 7, Blocks.nether_brick, 0);
        this.setBlock(world, i + 13, j + 16, k + 8, Blocks.nether_brick, 0);
        this.setBlock(world, i + 13, j + 16, k + 9, Blocks.nether_brick, 0);
        this.setBlock(world, i + 13, j + 16, k + 10, Blocks.nether_brick, 0);
        this.setBlock(world, i + 13, j + 16, k + 11, Blocks.obsidian, 0);
        this.setBlock(world, i + 13, j + 16, k + 15, Blocks.obsidian, 0);
        this.setBlock(world, i + 13, j + 16, k + 16, Blocks.nether_brick, 0);
        this.setBlock(world, i + 13, j + 17, k + 10, Blocks.nether_brick, 0);
        this.setBlock(world, i + 13, j + 17, k + 11, Blocks.obsidian, 0);
        this.setBlock(world, i + 13, j + 17, k + 15, Blocks.obsidian, 0);
        this.setBlock(world, i + 13, j + 17, k + 16, Blocks.nether_brick, 0);
        this.setBlock(world, i + 13, j + 18, k + 10, Blocks.nether_brick, 0);
        this.setBlock(world, i + 13, j + 18, k + 16, Blocks.nether_brick, 0);
        this.setBlock(world, i + 14, j + 0, k + 3, Blocks.nether_brick, 0);
        this.setBlock(world, i + 14, j + 0, k + 4, Blocks.nether_brick, 0);
        this.setBlock(world, i + 14, j + 0, k + 5, Blocks.nether_brick, 0);
        this.setBlock(world, i + 14, j + 0, k + 6, Blocks.nether_brick, 0);
        this.setBlock(world, i + 14, j + 0, k + 7, Blocks.nether_brick, 0);
        this.setBlock(world, i + 14, j + 0, k + 8, Blocks.nether_brick, 0);
        this.setBlock(world, i + 14, j + 0, k + 9, Blocks.nether_brick, 0);
        this.setBlock(world, i + 14, j + 0, k + 10, Blocks.nether_brick, 0);
        this.setBlock(world, i + 14, j + 0, k + 11, Blocks.nether_brick, 0);
        this.setBlock(world, i + 14, j + 0, k + 12, Blocks.glowstone, 0);
        this.setBlock(world, i + 14, j + 0, k + 13, Blocks.nether_brick, 0);
        this.setBlock(world, i + 14, j + 0, k + 14, Blocks.glowstone, 0);
        this.setBlock(world, i + 14, j + 0, k + 15, Blocks.nether_brick, 0);
        this.setBlock(world, i + 14, j + 0, k + 16, Blocks.nether_brick, 0);
        this.setBlock(world, i + 14, j + 0, k + 17, Blocks.nether_brick, 0);
        this.setBlock(world, i + 14, j + 0, k + 18, Blocks.nether_brick, 0);
        this.setBlock(world, i + 14, j + 0, k + 19, Blocks.nether_brick, 0);
        this.setBlock(world, i + 14, j + 0, k + 20, Blocks.nether_brick, 0);
        this.setBlock(world, i + 14, j + 0, k + 21, Blocks.nether_brick, 0);
        this.setBlock(world, i + 14, j + 0, k + 22, Blocks.nether_brick, 0);
        this.setBlock(world, i + 14, j + 0, k + 23, Blocks.nether_brick, 0);
        this.setBlock(world, i + 14, j + 0, k + 24, Blocks.soul_sand, 0);
        this.setBlock(world, i + 14, j + 1, k + 4, Blocks.nether_brick, 0);
        this.setBlock(world, i + 14, j + 1, k + 5, Blocks.nether_brick, 0);
        this.setBlock(world, i + 14, j + 1, k + 6, Blocks.obsidian, 0);
        this.setBlock(world, i + 14, j + 1, k + 13, Blocks.nether_brick, 0);
        WorldGenWarlordDungeon.chest(world, rand, i + 14, j + 1, k + 20, "NetherStructure", 10);
        this.setBlock(world, i + 14, j + 1, k + 21, Blocks.nether_brick, 0);
        this.setBlock(world, i + 14, j + 1, k + 22, Blocks.nether_brick, 0);
        this.setBlock(world, i + 14, j + 1, k + 23, Blocks.nether_brick, 0);
        this.setBlock(world, i + 14, j + 1, k + 24, Blocks.nether_brick, 0);
        this.setBlock(world, i + 14, j + 2, k + 5, Blocks.nether_brick, 0);
        this.setBlock(world, i + 14, j + 2, k + 6, Blocks.obsidian, 0);
        this.setBlock(world, i + 14, j + 2, k + 21, Blocks.nether_brick, 0);
        this.setBlock(world, i + 14, j + 3, k + 5, Blocks.nether_brick, 0);
        this.setBlock(world, i + 14, j + 3, k + 6, Blocks.obsidian, 0);
        this.setBlock(world, i + 14, j + 3, k + 21, Blocks.nether_brick, 0);
        this.setBlock(world, i + 14, j + 4, k + 5, Blocks.nether_brick, 0);
        this.setBlock(world, i + 14, j + 4, k + 6, Blocks.obsidian, 0);
        this.setBlock(world, i + 14, j + 4, k + 21, Blocks.nether_brick, 0);
        this.setBlock(world, i + 14, j + 5, k + 6, Blocks.obsidian, 0);
        this.setBlock(world, i + 14, j + 5, k + 20, Blocks.nether_brick, 0);
        this.setBlock(world, i + 14, j + 6, k + 6, Blocks.obsidian, 0);
        this.setBlock(world, i + 14, j + 6, k + 20, Blocks.nether_brick, 0);
        this.setBlock(world, i + 14, j + 7, k + 6, Blocks.obsidian, 0);
        this.setBlock(world, i + 14, j + 7, k + 7, Blocks.obsidian, 0);
        this.setBlock(world, i + 14, j + 7, k + 20, Blocks.nether_brick, 0);
        this.setBlock(world, i + 14, j + 8, k + 6, Blocks.soul_sand, 0);
        this.setBlock(world, i + 14, j + 8, k + 7, Blocks.obsidian, 0);
        this.setBlock(world, i + 14, j + 8, k + 18, Blocks.nether_brick, 0);
        this.setBlock(world, i + 14, j + 8, k + 19, Blocks.nether_brick, 0);
        this.setBlock(world, i + 14, j + 9, k + 6, Blocks.soul_sand, 0);
        this.setBlock(world, i + 14, j + 9, k + 7, Blocks.obsidian, 0);
        this.setBlock(world, i + 14, j + 9, k + 18, Blocks.nether_brick, 0);
        this.setBlock(world, i + 14, j + 9, k + 19, Blocks.nether_brick, 0);
        this.setBlock(world, i + 14, j + 10, k + 6, Blocks.soul_sand, 0);
        this.setBlock(world, i + 14, j + 10, k + 7, Blocks.obsidian, 0);
        this.setBlock(world, i + 14, j + 10, k + 8, Blocks.obsidian, 0);
        this.setBlock(world, i + 14, j + 10, k + 18, Blocks.nether_brick, 0);
        this.setBlock(world, i + 14, j + 10, k + 19, Blocks.nether_brick, 0);
        this.setBlock(world, i + 14, j + 11, k + 6, Blocks.soul_sand, 0);
        this.setBlock(world, i + 14, j + 11, k + 7, Blocks.soul_sand, 0);
        this.setBlock(world, i + 14, j + 11, k + 8, Blocks.obsidian, 0);
        this.setBlock(world, i + 14, j + 11, k + 17, Blocks.nether_brick, 0);
        this.setBlock(world, i + 14, j + 12, k + 6, Blocks.soul_sand, 0);
        this.setBlock(world, i + 14, j + 12, k + 7, Blocks.soul_sand, 0);
        this.setBlock(world, i + 14, j + 12, k + 8, Blocks.obsidian, 0);
        this.setBlock(world, i + 14, j + 12, k + 17, Blocks.nether_brick, 0);
        this.setBlock(world, i + 14, j + 13, k + 6, Blocks.soul_sand, 0);
        this.setBlock(world, i + 14, j + 13, k + 7, Blocks.soul_sand, 0);
        this.setBlock(world, i + 14, j + 13, k + 8, Blocks.obsidian, 0);
        this.setBlock(world, i + 14, j + 13, k + 13, Blocks.obsidian, 0);
        this.setBlock(world, i + 14, j + 13, k + 17, Blocks.nether_brick, 0);
        this.setBlock(world, i + 14, j + 14, k + 6, Blocks.soul_sand, 0);
        this.setBlock(world, i + 14, j + 14, k + 7, Blocks.soul_sand, 0);
        this.setBlock(world, i + 14, j + 14, k + 8, Blocks.obsidian, 0);
        this.setBlock(world, i + 14, j + 14, k + 12, Blocks.obsidian, 0);
        this.setBlock(world, i + 14, j + 14, k + 13, Blocks.obsidian, 0);
        this.setBlock(world, i + 14, j + 14, k + 14, Blocks.obsidian, 0);
        this.setBlock(world, i + 14, j + 14, k + 17, Blocks.nether_brick, 0);
        this.setBlock(world, i + 14, j + 15, k + 6, Blocks.nether_brick, 0);
        this.setBlock(world, i + 14, j + 15, k + 7, Blocks.nether_brick, 0);
        this.setBlock(world, i + 14, j + 15, k + 8, Blocks.nether_brick, 0);
        this.setBlock(world, i + 14, j + 15, k + 9, Blocks.nether_brick, 0);
        this.setBlock(world, i + 14, j + 15, k + 10, Blocks.nether_brick, 0);
        this.setBlock(world, i + 14, j + 15, k + 11, Blocks.nether_brick, 0);
        this.setBlock(world, i + 14, j + 15, k + 12, Blocks.obsidian, 0);
        this.setBlock(world, i + 14, j + 15, k + 13, Blocks.obsidian, 0);
        this.setBlock(world, i + 14, j + 15, k + 14, Blocks.obsidian, 0);
        this.setBlock(world, i + 14, j + 15, k + 15, Blocks.nether_brick, 0);
        this.setBlock(world, i + 14, j + 15, k + 16, Blocks.nether_brick, 0);
        this.setBlock(world, i + 14, j + 16, k + 8, Blocks.nether_brick, 0);
        this.setBlock(world, i + 14, j + 16, k + 9, Blocks.nether_brick, 0);
        this.setBlock(world, i + 14, j + 16, k + 10, Blocks.nether_brick, 0);
        this.setBlock(world, i + 14, j + 16, k + 11, Blocks.nether_brick, 0);
        this.setBlock(world, i + 14, j + 16, k + 12, Blocks.obsidian, 0);
        this.setBlock(world, i + 14, j + 16, k + 14, Blocks.obsidian, 0);
        this.setBlock(world, i + 14, j + 16, k + 15, Blocks.nether_brick, 0);
        this.setBlock(world, i + 14, j + 16, k + 16, Blocks.nether_brick, 0);
        this.setBlock(world, i + 14, j + 17, k + 8, Blocks.nether_brick, 0);
        this.setBlock(world, i + 14, j + 17, k + 9, Blocks.nether_brick, 0);
        this.setBlock(world, i + 14, j + 17, k + 10, Blocks.nether_brick, 0);
        this.setBlock(world, i + 14, j + 17, k + 11, Blocks.nether_brick, 0);
        this.setBlock(world, i + 14, j + 17, k + 12, Blocks.obsidian, 0);
        this.setBlock(world, i + 14, j + 17, k + 14, Blocks.obsidian, 0);
        this.setBlock(world, i + 14, j + 17, k + 15, Blocks.nether_brick, 0);
        this.setBlock(world, i + 14, j + 17, k + 16, Blocks.nether_brick, 0);
        this.setBlock(world, i + 14, j + 18, k + 8, Blocks.nether_brick, 0);
        this.setBlock(world, i + 14, j + 18, k + 9, Blocks.nether_brick, 0);
        this.setBlock(world, i + 14, j + 18, k + 10, Blocks.nether_brick, 0);
        this.setBlock(world, i + 14, j + 18, k + 11, Blocks.nether_brick, 0);
        this.setBlock(world, i + 14, j + 18, k + 15, Blocks.nether_brick, 0);
        this.setBlock(world, i + 14, j + 18, k + 16, Blocks.nether_brick, 0);
        this.setBlock(world, i + 14, j + 19, k + 8, Blocks.nether_brick, 0);
        this.setBlock(world, i + 14, j + 19, k + 9, Blocks.nether_brick, 0);
        this.setBlock(world, i + 14, j + 19, k + 10, Blocks.nether_brick, 0);
        this.setBlock(world, i + 14, j + 20, k + 8, Blocks.nether_brick, 0);
        this.setBlock(world, i + 14, j + 20, k + 9, Blocks.nether_brick, 0);
        this.setBlock(world, i + 14, j + 21, k + 8, Blocks.nether_brick, 0);
        this.setBlock(world, i + 15, j + 0, k + 3, Blocks.nether_brick, 0);
        this.setBlock(world, i + 15, j + 0, k + 4, Blocks.nether_brick, 0);
        this.setBlock(world, i + 15, j + 0, k + 5, Blocks.nether_brick, 0);
        this.setBlock(world, i + 15, j + 0, k + 6, Blocks.nether_brick, 0);
        this.setBlock(world, i + 15, j + 0, k + 7, Blocks.nether_brick, 0);
        this.setBlock(world, i + 15, j + 0, k + 8, Blocks.nether_brick, 0);
        this.setBlock(world, i + 15, j + 0, k + 9, Blocks.nether_brick, 0);
        this.setBlock(world, i + 15, j + 0, k + 10, Blocks.nether_brick, 0);
        this.setBlock(world, i + 15, j + 0, k + 11, Blocks.nether_brick, 0);
        this.setBlock(world, i + 15, j + 0, k + 12, Blocks.nether_brick, 0);
        this.setBlock(world, i + 15, j + 0, k + 13, Blocks.glowstone, 0);
        this.setBlock(world, i + 15, j + 0, k + 14, Blocks.nether_brick, 0);
        this.setBlock(world, i + 15, j + 0, k + 15, Blocks.nether_brick, 0);
        this.setBlock(world, i + 15, j + 0, k + 16, Blocks.nether_brick, 0);
        this.setBlock(world, i + 15, j + 0, k + 17, Blocks.nether_brick, 0);
        this.setBlock(world, i + 15, j + 0, k + 18, Blocks.nether_brick, 0);
        this.setBlock(world, i + 15, j + 0, k + 19, Blocks.nether_brick, 0);
        this.setBlock(world, i + 15, j + 0, k + 20, Blocks.nether_brick, 0);
        this.setBlock(world, i + 15, j + 0, k + 21, Blocks.nether_brick, 0);
        this.setBlock(world, i + 15, j + 0, k + 22, Blocks.nether_brick, 0);
        this.setBlock(world, i + 15, j + 0, k + 23, Blocks.nether_brick, 0);
        this.setBlock(world, i + 15, j + 1, k + 4, Blocks.nether_brick, 0);
        this.setBlock(world, i + 15, j + 1, k + 5, Blocks.nether_brick, 0);
        this.setBlock(world, i + 15, j + 1, k + 6, Blocks.obsidian, 0);
        this.setBlock(world, i + 15, j + 1, k + 7, Blocks.obsidian, 0);
        this.setBlock(world, i + 15, j + 1, k + 21, Blocks.nether_brick, 0);
        this.setBlock(world, i + 15, j + 1, k + 22, Blocks.nether_brick, 0);
        this.setBlock(world, i + 15, j + 1, k + 23, Blocks.soul_sand, 0);
        this.setBlock(world, i + 15, j + 2, k + 5, Blocks.nether_brick, 0);
        this.setBlock(world, i + 15, j + 2, k + 6, Blocks.obsidian, 0);
        this.setBlock(world, i + 15, j + 2, k + 7, Blocks.obsidian, 0);
        this.setBlock(world, i + 15, j + 2, k + 21, Blocks.nether_brick, 0);
        this.setBlock(world, i + 15, j + 2, k + 22, Blocks.nether_brick, 0);
        this.setBlock(world, i + 15, j + 2, k + 23, Blocks.nether_brick, 0);
        this.setBlock(world, i + 15, j + 3, k + 5, Blocks.nether_brick, 0);
        this.setBlock(world, i + 15, j + 3, k + 6, Blocks.obsidian, 0);
        this.setBlock(world, i + 15, j + 3, k + 7, Blocks.obsidian, 0);
        this.setBlock(world, i + 15, j + 3, k + 21, Blocks.nether_brick, 0);
        this.setBlock(world, i + 15, j + 4, k + 5, Blocks.nether_brick, 0);
        this.setBlock(world, i + 15, j + 4, k + 6, Blocks.obsidian, 0);
        this.setBlock(world, i + 15, j + 4, k + 7, Blocks.obsidian, 0);
        this.setBlock(world, i + 15, j + 4, k + 21, Blocks.nether_brick, 0);
        this.setBlock(world, i + 15, j + 5, k + 6, Blocks.obsidian, 0);
        this.setBlock(world, i + 15, j + 5, k + 7, Blocks.obsidian, 0);
        this.setBlock(world, i + 15, j + 5, k + 19, Blocks.nether_brick, 0);
        this.setBlock(world, i + 15, j + 5, k + 20, Blocks.nether_brick, 0);
        this.setBlock(world, i + 15, j + 6, k + 6, Blocks.obsidian, 0);
        this.setBlock(world, i + 15, j + 6, k + 7, Blocks.obsidian, 0);
        this.setBlock(world, i + 15, j + 6, k + 19, Blocks.nether_brick, 0);
        this.setBlock(world, i + 15, j + 6, k + 20, Blocks.nether_brick, 0);
        this.setBlock(world, i + 15, j + 7, k + 6, Blocks.obsidian, 0);
        this.setBlock(world, i + 15, j + 7, k + 7, Blocks.obsidian, 0);
        this.setBlock(world, i + 15, j + 7, k + 19, Blocks.nether_brick, 0);
        this.setBlock(world, i + 15, j + 7, k + 20, Blocks.nether_brick, 0);
        this.setBlock(world, i + 15, j + 8, k + 6, Blocks.soul_sand, 0);
        this.setBlock(world, i + 15, j + 8, k + 7, Blocks.obsidian, 0);
        this.setBlock(world, i + 15, j + 8, k + 18, Blocks.nether_brick, 0);
        this.setBlock(world, i + 15, j + 9, k + 6, Blocks.soul_sand, 0);
        this.setBlock(world, i + 15, j + 9, k + 7, Blocks.obsidian, 0);
        this.setBlock(world, i + 15, j + 9, k + 18, Blocks.nether_brick, 0);
        this.setBlock(world, i + 15, j + 10, k + 6, Blocks.soul_sand, 0);
        this.setBlock(world, i + 15, j + 10, k + 7, Blocks.obsidian, 0);
        this.setBlock(world, i + 15, j + 10, k + 18, Blocks.nether_brick, 0);
        this.setBlock(world, i + 15, j + 11, k + 6, Blocks.soul_sand, 0);
        this.setBlock(world, i + 15, j + 11, k + 7, Blocks.soul_sand, 0);
        this.setBlock(world, i + 15, j + 11, k + 8, Blocks.nether_brick, 0);
        this.setBlock(world, i + 15, j + 11, k + 9, Blocks.nether_brick, 0);
        this.setBlock(world, i + 15, j + 11, k + 10, Blocks.nether_brick, 0);
        this.setBlock(world, i + 15, j + 11, k + 16, Blocks.nether_brick, 0);
        this.setBlock(world, i + 15, j + 11, k + 17, Blocks.nether_brick, 0);
        this.setBlock(world, i + 15, j + 12, k + 6, Blocks.soul_sand, 0);
        this.setBlock(world, i + 15, j + 12, k + 7, Blocks.soul_sand, 0);
        this.setBlock(world, i + 15, j + 12, k + 8, Blocks.nether_brick, 0);
        this.setBlock(world, i + 15, j + 12, k + 9, Blocks.nether_brick, 0);
        this.setBlock(world, i + 15, j + 12, k + 10, Blocks.nether_brick, 0);
        this.setBlock(world, i + 15, j + 12, k + 16, Blocks.nether_brick, 0);
        this.setBlock(world, i + 15, j + 12, k + 17, Blocks.nether_brick, 0);
        this.setBlock(world, i + 15, j + 13, k + 6, Blocks.soul_sand, 0);
        this.setBlock(world, i + 15, j + 13, k + 7, Blocks.soul_sand, 0);
        this.setBlock(world, i + 15, j + 13, k + 8, Blocks.nether_brick, 0);
        this.setBlock(world, i + 15, j + 13, k + 9, Blocks.nether_brick, 0);
        this.setBlock(world, i + 15, j + 13, k + 10, Blocks.nether_brick, 0);
        this.setBlock(world, i + 15, j + 13, k + 16, Blocks.nether_brick, 0);
        this.setBlock(world, i + 15, j + 13, k + 17, Blocks.nether_brick, 0);
        this.setBlock(world, i + 15, j + 14, k + 6, Blocks.nether_brick, 0);
        this.setBlock(world, i + 15, j + 14, k + 7, Blocks.nether_brick, 0);
        this.setBlock(world, i + 15, j + 14, k + 8, Blocks.nether_brick, 0);
        this.setBlock(world, i + 15, j + 14, k + 9, Blocks.nether_brick, 0);
        this.setBlock(world, i + 15, j + 14, k + 10, Blocks.nether_brick, 0);
        this.setBlock(world, i + 15, j + 14, k + 13, Blocks.obsidian, 0);
        this.setBlock(world, i + 15, j + 14, k + 16, Blocks.nether_brick, 0);
        this.setBlock(world, i + 15, j + 14, k + 17, Blocks.nether_brick, 0);
        this.setBlock(world, i + 15, j + 15, k + 11, Blocks.nether_brick, 0);
        this.setBlock(world, i + 15, j + 15, k + 12, Blocks.nether_brick, 0);
        this.setBlock(world, i + 15, j + 15, k + 13, Blocks.obsidian, 0);
        this.setBlock(world, i + 15, j + 15, k + 14, Blocks.nether_brick, 0);
        this.setBlock(world, i + 15, j + 15, k + 15, Blocks.nether_brick, 0);
        this.setBlock(world, i + 15, j + 16, k + 11, Blocks.nether_brick, 0);
        this.setBlock(world, i + 15, j + 16, k + 12, Blocks.nether_brick, 0);
        this.setBlock(world, i + 15, j + 16, k + 13, Blocks.obsidian, 0);
        this.setBlock(world, i + 15, j + 16, k + 14, Blocks.nether_brick, 0);
        this.setBlock(world, i + 15, j + 16, k + 15, Blocks.nether_brick, 0);
        this.setBlock(world, i + 15, j + 17, k + 11, Blocks.nether_brick, 0);
        this.setBlock(world, i + 15, j + 17, k + 12, Blocks.nether_brick, 0);
        this.setBlock(world, i + 15, j + 17, k + 13, Blocks.obsidian, 0);
        this.setBlock(world, i + 15, j + 17, k + 14, Blocks.nether_brick, 0);
        this.setBlock(world, i + 15, j + 17, k + 15, Blocks.nether_brick, 0);
        this.setBlock(world, i + 15, j + 18, k + 11, Blocks.nether_brick, 0);
        this.setBlock(world, i + 15, j + 18, k + 12, Blocks.nether_brick, 0);
        this.setBlock(world, i + 15, j + 18, k + 14, Blocks.nether_brick, 0);
        this.setBlock(world, i + 15, j + 18, k + 15, Blocks.nether_brick, 0);
        this.setBlock(world, i + 16, j + 0, k + 3, Blocks.nether_brick, 0);
        this.setBlock(world, i + 16, j + 0, k + 4, Blocks.nether_brick, 0);
        this.setBlock(world, i + 16, j + 0, k + 5, Blocks.nether_brick, 0);
        this.setBlock(world, i + 16, j + 0, k + 6, Blocks.nether_brick, 0);
        this.setBlock(world, i + 16, j + 0, k + 7, Blocks.nether_brick, 0);
        this.setBlock(world, i + 16, j + 0, k + 8, Blocks.nether_brick, 0);
        this.setBlock(world, i + 16, j + 0, k + 9, Blocks.nether_brick, 0);
        this.setBlock(world, i + 16, j + 0, k + 10, Blocks.nether_brick, 0);
        this.setBlock(world, i + 16, j + 0, k + 11, Blocks.nether_brick, 0);
        this.setBlock(world, i + 16, j + 0, k + 12, Blocks.nether_brick, 0);
        this.setBlock(world, i + 16, j + 0, k + 13, Blocks.nether_brick, 0);
        this.setBlock(world, i + 16, j + 0, k + 14, Blocks.nether_brick, 0);
        this.setBlock(world, i + 16, j + 0, k + 15, Blocks.nether_brick, 0);
        this.setBlock(world, i + 16, j + 0, k + 16, Blocks.nether_brick, 0);
        this.setBlock(world, i + 16, j + 0, k + 17, Blocks.nether_brick, 0);
        this.setBlock(world, i + 16, j + 0, k + 18, Blocks.nether_brick, 0);
        this.setBlock(world, i + 16, j + 0, k + 19, Blocks.nether_brick, 0);
        this.setBlock(world, i + 16, j + 0, k + 20, Blocks.nether_brick, 0);
        this.setBlock(world, i + 16, j + 0, k + 21, Blocks.nether_brick, 0);
        this.setBlock(world, i + 16, j + 0, k + 22, Blocks.nether_brick, 0);
        this.setBlock(world, i + 16, j + 0, k + 23, Blocks.nether_brick, 0);
        this.setBlock(world, i + 16, j + 1, k + 4, Blocks.nether_brick, 0);
        this.setBlock(world, i + 16, j + 1, k + 5, Blocks.nether_brick, 0);
        this.setBlock(world, i + 16, j + 1, k + 6, Blocks.nether_brick, 0);
        this.setBlock(world, i + 16, j + 1, k + 7, Blocks.obsidian, 0);
        this.setBlock(world, i + 16, j + 1, k + 20, Blocks.nether_brick, 0);
        this.setBlock(world, i + 16, j + 1, k + 21, Blocks.nether_brick, 0);
        this.setBlock(world, i + 16, j + 1, k + 22, Blocks.nether_brick, 0);
        this.setBlock(world, i + 16, j + 1, k + 23, Blocks.soul_sand, 0);
        this.setBlock(world, i + 16, j + 2, k + 6, Blocks.nether_brick, 0);
        this.setBlock(world, i + 16, j + 2, k + 7, Blocks.obsidian, 0);
        this.setBlock(world, i + 16, j + 2, k + 20, Blocks.nether_brick, 0);
        this.setBlock(world, i + 16, j + 2, k + 21, Blocks.soul_sand, 0);
        this.setBlock(world, i + 16, j + 2, k + 22, Blocks.soul_sand, 0);
        this.setBlock(world, i + 16, j + 2, k + 23, Blocks.soul_sand, 0);
        this.setBlock(world, i + 16, j + 3, k + 6, Blocks.nether_brick, 0);
        this.setBlock(world, i + 16, j + 3, k + 7, Blocks.obsidian, 0);
        this.setBlock(world, i + 16, j + 3, k + 20, Blocks.nether_brick, 0);
        this.setBlock(world, i + 16, j + 3, k + 21, Blocks.nether_brick, 0);
        this.setBlock(world, i + 16, j + 3, k + 22, Blocks.nether_brick, 0);
        this.setBlock(world, i + 16, j + 3, k + 23, Blocks.nether_brick, 0);
        this.setBlock(world, i + 16, j + 4, k + 6, Blocks.nether_brick, 0);
        this.setBlock(world, i + 16, j + 4, k + 7, Blocks.obsidian, 0);
        this.setBlock(world, i + 16, j + 4, k + 20, Blocks.nether_brick, 0);
        this.setBlock(world, i + 16, j + 5, k + 6, Blocks.soul_sand, 0);
        this.setBlock(world, i + 16, j + 5, k + 7, Blocks.obsidian, 0);
        this.setBlock(world, i + 16, j + 5, k + 19, Blocks.nether_brick, 0);
        this.setBlock(world, i + 16, j + 6, k + 6, Blocks.soul_sand, 0);
        this.setBlock(world, i + 16, j + 6, k + 7, Blocks.obsidian, 0);
        this.setBlock(world, i + 16, j + 6, k + 19, Blocks.nether_brick, 0);
        this.setBlock(world, i + 16, j + 7, k + 6, Blocks.soul_sand, 0);
        this.setBlock(world, i + 16, j + 7, k + 7, Blocks.obsidian, 0);
        this.setBlock(world, i + 16, j + 7, k + 19, Blocks.nether_brick, 0);
        this.setBlock(world, i + 16, j + 8, k + 6, Blocks.soul_sand, 0);
        this.setBlock(world, i + 16, j + 8, k + 7, Blocks.nether_brick, 0);
        this.setBlock(world, i + 16, j + 8, k + 8, Blocks.nether_brick, 0);
        this.setBlock(world, i + 16, j + 8, k + 9, Blocks.nether_brick, 0);
        this.setBlock(world, i + 16, j + 8, k + 17, Blocks.nether_brick, 0);
        this.setBlock(world, i + 16, j + 8, k + 18, Blocks.nether_brick, 0);
        this.setBlock(world, i + 16, j + 9, k + 6, Blocks.soul_sand, 0);
        this.setBlock(world, i + 16, j + 9, k + 7, Blocks.nether_brick, 0);
        this.setBlock(world, i + 16, j + 9, k + 8, Blocks.nether_brick, 0);
        this.setBlock(world, i + 16, j + 9, k + 9, Blocks.nether_brick, 0);
        this.setBlock(world, i + 16, j + 9, k + 17, Blocks.nether_brick, 0);
        this.setBlock(world, i + 16, j + 9, k + 18, Blocks.nether_brick, 0);
        this.setBlock(world, i + 16, j + 10, k + 6, Blocks.soul_sand, 0);
        this.setBlock(world, i + 16, j + 10, k + 7, Blocks.nether_brick, 0);
        this.setBlock(world, i + 16, j + 10, k + 8, Blocks.nether_brick, 0);
        this.setBlock(world, i + 16, j + 10, k + 9, Blocks.nether_brick, 0);
        this.setBlock(world, i + 16, j + 10, k + 17, Blocks.nether_brick, 0);
        this.setBlock(world, i + 16, j + 10, k + 18, Blocks.nether_brick, 0);
        this.setBlock(world, i + 16, j + 11, k + 6, Blocks.soul_sand, 0);
        this.setBlock(world, i + 16, j + 11, k + 7, Blocks.soul_sand, 0);
        this.setBlock(world, i + 16, j + 11, k + 8, Blocks.soul_sand, 0);
        this.setBlock(world, i + 16, j + 11, k + 9, Blocks.soul_sand, 0);
        this.setBlock(world, i + 16, j + 11, k + 10, Blocks.nether_brick, 0);
        this.setBlock(world, i + 16, j + 11, k + 11, Blocks.nether_brick, 0);
        this.setBlock(world, i + 16, j + 11, k + 15, Blocks.nether_brick, 0);
        this.setBlock(world, i + 16, j + 11, k + 16, Blocks.nether_brick, 0);
        this.setBlock(world, i + 16, j + 12, k + 6, Blocks.soul_sand, 0);
        this.setBlock(world, i + 16, j + 12, k + 7, Blocks.soul_sand, 0);
        this.setBlock(world, i + 16, j + 12, k + 8, Blocks.soul_sand, 0);
        this.setBlock(world, i + 16, j + 12, k + 9, Blocks.nether_brick, 0);
        this.setBlock(world, i + 16, j + 12, k + 10, Blocks.nether_brick, 0);
        this.setBlock(world, i + 16, j + 12, k + 11, Blocks.nether_brick, 0);
        this.setBlock(world, i + 16, j + 12, k + 15, Blocks.nether_brick, 0);
        this.setBlock(world, i + 16, j + 12, k + 16, Blocks.nether_brick, 0);
        this.setBlock(world, i + 16, j + 13, k + 6, Blocks.nether_brick, 0);
        this.setBlock(world, i + 16, j + 13, k + 7, Blocks.nether_brick, 0);
        this.setBlock(world, i + 16, j + 13, k + 8, Blocks.nether_brick, 0);
        this.setBlock(world, i + 16, j + 13, k + 10, Blocks.nether_brick, 0);
        this.setBlock(world, i + 16, j + 13, k + 11, Blocks.nether_brick, 0);
        this.setBlock(world, i + 16, j + 13, k + 15, Blocks.nether_brick, 0);
        this.setBlock(world, i + 16, j + 13, k + 16, Blocks.nether_brick, 0);
        this.setBlock(world, i + 16, j + 14, k + 10, Blocks.nether_brick, 0);
        this.setBlock(world, i + 16, j + 14, k + 11, Blocks.nether_brick, 0);
        this.setBlock(world, i + 16, j + 14, k + 15, Blocks.nether_brick, 0);
        this.setBlock(world, i + 16, j + 14, k + 16, Blocks.nether_brick, 0);
        this.setBlock(world, i + 16, j + 15, k + 12, Blocks.nether_brick, 0);
        this.setBlock(world, i + 16, j + 15, k + 13, Blocks.nether_brick, 0);
        this.setBlock(world, i + 16, j + 15, k + 14, Blocks.nether_brick, 0);
        this.setBlock(world, i + 16, j + 16, k + 12, Blocks.nether_brick, 0);
        this.setBlock(world, i + 16, j + 16, k + 13, Blocks.nether_brick, 0);
        this.setBlock(world, i + 16, j + 16, k + 14, Blocks.nether_brick, 0);
        this.setBlock(world, i + 16, j + 17, k + 12, Blocks.nether_brick, 0);
        this.setBlock(world, i + 16, j + 17, k + 13, Blocks.nether_brick, 0);
        this.setBlock(world, i + 16, j + 17, k + 14, Blocks.nether_brick, 0);
        this.setBlock(world, i + 16, j + 18, k + 12, Blocks.nether_brick, 0);
        this.setBlock(world, i + 16, j + 18, k + 13, Blocks.nether_brick, 0);
        this.setBlock(world, i + 16, j + 18, k + 14, Blocks.nether_brick, 0);
        this.setBlock(world, i + 16, j + 19, k + 14, Blocks.nether_brick, 0);
        this.setBlock(world, i + 17, j + 0, k + 4, Blocks.nether_brick, 0);
        this.setBlock(world, i + 17, j + 0, k + 5, Blocks.nether_brick, 0);
        this.setBlock(world, i + 17, j + 0, k + 6, Blocks.nether_brick, 0);
        this.setBlock(world, i + 17, j + 0, k + 7, Blocks.nether_brick, 0);
        this.setBlock(world, i + 17, j + 0, k + 8, Blocks.nether_brick, 0);
        this.setBlock(world, i + 17, j + 0, k + 9, Blocks.nether_brick, 0);
        this.setBlock(world, i + 17, j + 0, k + 10, Blocks.nether_brick, 0);
        this.setBlock(world, i + 17, j + 0, k + 11, Blocks.nether_brick, 0);
        this.setBlock(world, i + 17, j + 0, k + 12, Blocks.nether_brick, 0);
        this.setBlock(world, i + 17, j + 0, k + 13, Blocks.nether_brick, 0);
        this.setBlock(world, i + 17, j + 0, k + 14, Blocks.nether_brick, 0);
        this.setBlock(world, i + 17, j + 0, k + 15, Blocks.nether_brick, 0);
        this.setBlock(world, i + 17, j + 0, k + 16, Blocks.nether_brick, 0);
        this.setBlock(world, i + 17, j + 0, k + 17, Blocks.nether_brick, 0);
        this.setBlock(world, i + 17, j + 0, k + 18, Blocks.nether_brick, 0);
        this.setBlock(world, i + 17, j + 0, k + 19, Blocks.nether_brick, 0);
        this.setBlock(world, i + 17, j + 0, k + 20, Blocks.nether_brick, 0);
        this.setBlock(world, i + 17, j + 0, k + 21, Blocks.nether_brick, 0);
        this.setBlock(world, i + 17, j + 0, k + 22, Blocks.nether_brick, 0);
        this.setBlock(world, i + 17, j + 1, k + 5, Blocks.nether_brick, 0);
        this.setBlock(world, i + 17, j + 1, k + 6, Blocks.nether_brick, 0);
        this.setBlock(world, i + 17, j + 1, k + 20, Blocks.nether_brick, 0);
        this.setBlock(world, i + 17, j + 1, k + 21, Blocks.nether_brick, 0);
        this.setBlock(world, i + 17, j + 1, k + 22, Blocks.soul_sand, 0);
        this.setBlock(world, i + 17, j + 2, k + 6, Blocks.nether_brick, 0);
        this.setBlock(world, i + 17, j + 2, k + 20, Blocks.nether_brick, 0);
        this.setBlock(world, i + 17, j + 2, k + 21, Blocks.soul_sand, 0);
        this.setBlock(world, i + 17, j + 2, k + 22, Blocks.soul_sand, 0);
        this.setBlock(world, i + 17, j + 3, k + 6, Blocks.nether_brick, 0);
        this.setBlock(world, i + 17, j + 3, k + 20, Blocks.nether_brick, 0);
        this.setBlock(world, i + 17, j + 3, k + 21, Blocks.soul_sand, 0);
        this.setBlock(world, i + 17, j + 3, k + 22, Blocks.soul_sand, 0);
        this.setBlock(world, i + 17, j + 4, k + 6, Blocks.nether_brick, 0);
        this.setBlock(world, i + 17, j + 4, k + 20, Blocks.nether_brick, 0);
        this.setBlock(world, i + 17, j + 4, k + 21, Blocks.nether_brick, 0);
        this.setBlock(world, i + 17, j + 4, k + 22, Blocks.nether_brick, 0);
        this.setBlock(world, i + 17, j + 5, k + 7, Blocks.nether_brick, 0);
        this.setBlock(world, i + 17, j + 5, k + 8, Blocks.nether_brick, 0);
        this.setBlock(world, i + 17, j + 5, k + 18, Blocks.nether_brick, 0);
        this.setBlock(world, i + 17, j + 5, k + 19, Blocks.nether_brick, 0);
        this.setBlock(world, i + 17, j + 6, k + 7, Blocks.nether_brick, 0);
        this.setBlock(world, i + 17, j + 6, k + 8, Blocks.nether_brick, 0);
        this.setBlock(world, i + 17, j + 6, k + 18, Blocks.nether_brick, 0);
        this.setBlock(world, i + 17, j + 6, k + 19, Blocks.nether_brick, 0);
        this.setBlock(world, i + 17, j + 7, k + 7, Blocks.nether_brick, 0);
        this.setBlock(world, i + 17, j + 7, k + 8, Blocks.nether_brick, 0);
        this.setBlock(world, i + 17, j + 7, k + 18, Blocks.nether_brick, 0);
        this.setBlock(world, i + 17, j + 7, k + 19, Blocks.nether_brick, 0);
        this.setBlock(world, i + 17, j + 8, k + 7, Blocks.soul_sand, 0);
        this.setBlock(world, i + 17, j + 8, k + 8, Blocks.soul_sand, 0);
        this.setBlock(world, i + 17, j + 8, k + 9, Blocks.nether_brick, 0);
        this.setBlock(world, i + 17, j + 8, k + 10, Blocks.nether_brick, 0);
        this.setBlock(world, i + 17, j + 8, k + 16, Blocks.nether_brick, 0);
        this.setBlock(world, i + 17, j + 8, k + 17, Blocks.nether_brick, 0);
        this.setBlock(world, i + 17, j + 9, k + 7, Blocks.soul_sand, 0);
        this.setBlock(world, i + 17, j + 9, k + 8, Blocks.soul_sand, 0);
        this.setBlock(world, i + 17, j + 9, k + 9, Blocks.nether_brick, 0);
        this.setBlock(world, i + 17, j + 9, k + 10, Blocks.nether_brick, 0);
        this.setBlock(world, i + 17, j + 9, k + 16, Blocks.nether_brick, 0);
        this.setBlock(world, i + 17, j + 9, k + 17, Blocks.nether_brick, 0);
        this.setBlock(world, i + 17, j + 10, k + 7, Blocks.soul_sand, 0);
        this.setBlock(world, i + 17, j + 10, k + 8, Blocks.soul_sand, 0);
        this.setBlock(world, i + 17, j + 10, k + 9, Blocks.nether_brick, 0);
        this.setBlock(world, i + 17, j + 10, k + 10, Blocks.nether_brick, 0);
        this.setBlock(world, i + 17, j + 10, k + 16, Blocks.nether_brick, 0);
        this.setBlock(world, i + 17, j + 10, k + 17, Blocks.nether_brick, 0);
        this.setBlock(world, i + 17, j + 11, k + 7, Blocks.soul_sand, 0);
        this.setBlock(world, i + 17, j + 11, k + 8, Blocks.soul_sand, 0);
        this.setBlock(world, i + 17, j + 11, k + 9, Blocks.soul_sand, 0);
        this.setBlock(world, i + 17, j + 11, k + 10, Blocks.soul_sand, 0);
        this.setBlock(world, i + 17, j + 11, k + 11, Blocks.nether_brick, 0);
        this.setBlock(world, i + 17, j + 11, k + 12, Blocks.nether_brick, 0);
        this.setBlock(world, i + 17, j + 11, k + 13, Blocks.nether_brick, 0);
        this.setBlock(world, i + 17, j + 11, k + 15, Blocks.nether_brick, 0);
        this.setBlock(world, i + 17, j + 12, k + 7, Blocks.soul_sand, 0);
        this.setBlock(world, i + 17, j + 12, k + 8, Blocks.soul_sand, 0);
        this.setBlock(world, i + 17, j + 12, k + 9, Blocks.nether_brick, 0);
        this.setBlock(world, i + 17, j + 12, k + 10, Blocks.nether_brick, 0);
        this.setBlock(world, i + 17, j + 12, k + 11, Blocks.nether_brick, 0);
        this.setBlock(world, i + 17, j + 12, k + 12, Blocks.nether_brick, 0);
        this.setBlock(world, i + 17, j + 12, k + 13, Blocks.nether_brick, 0);
        this.setBlock(world, i + 17, j + 12, k + 15, Blocks.nether_brick, 0);
        this.setBlock(world, i + 17, j + 13, k + 7, Blocks.nether_brick, 0);
        this.setBlock(world, i + 17, j + 13, k + 8, Blocks.nether_brick, 0);
        this.setBlock(world, i + 17, j + 13, k + 11, Blocks.nether_brick, 0);
        this.setBlock(world, i + 17, j + 13, k + 12, Blocks.nether_brick, 0);
        this.setBlock(world, i + 17, j + 13, k + 13, Blocks.nether_brick, 0);
        this.setBlock(world, i + 17, j + 13, k + 15, Blocks.nether_brick, 0);
        this.setBlock(world, i + 17, j + 14, k + 11, Blocks.nether_brick, 0);
        this.setBlock(world, i + 17, j + 14, k + 12, Blocks.nether_brick, 0);
        this.setBlock(world, i + 17, j + 14, k + 13, Blocks.nether_brick, 0);
        this.setBlock(world, i + 17, j + 14, k + 15, Blocks.nether_brick, 0);
        this.setBlock(world, i + 17, j + 15, k + 14, Blocks.nether_brick, 0);
        this.setBlock(world, i + 17, j + 16, k + 14, Blocks.nether_brick, 0);
        this.setBlock(world, i + 17, j + 17, k + 14, Blocks.nether_brick, 0);
        this.setBlock(world, i + 17, j + 18, k + 14, Blocks.nether_brick, 0);
        this.setBlock(world, i + 17, j + 19, k + 14, Blocks.nether_brick, 0);
        this.setBlock(world, i + 17, j + 20, k + 14, Blocks.nether_brick, 0);
        this.setBlock(world, i + 18, j + 0, k + 4, Blocks.nether_brick, 0);
        this.setBlock(world, i + 18, j + 0, k + 5, Blocks.nether_brick, 0);
        this.setBlock(world, i + 18, j + 0, k + 6, Blocks.nether_brick, 0);
        this.setBlock(world, i + 18, j + 0, k + 7, Blocks.nether_brick, 0);
        this.setBlock(world, i + 18, j + 0, k + 8, Blocks.nether_brick, 0);
        this.setBlock(world, i + 18, j + 0, k + 9, Blocks.nether_brick, 0);
        this.setBlock(world, i + 18, j + 0, k + 10, Blocks.nether_brick, 0);
        this.setBlock(world, i + 18, j + 0, k + 11, Blocks.nether_brick, 0);
        this.setBlock(world, i + 18, j + 0, k + 12, Blocks.nether_brick, 0);
        this.setBlock(world, i + 18, j + 0, k + 13, Blocks.nether_brick, 0);
        this.setBlock(world, i + 18, j + 0, k + 14, Blocks.nether_brick, 0);
        this.setBlock(world, i + 18, j + 0, k + 15, Blocks.nether_brick, 0);
        this.setBlock(world, i + 18, j + 0, k + 16, Blocks.nether_brick, 0);
        this.setBlock(world, i + 18, j + 0, k + 17, Blocks.nether_brick, 0);
        this.setBlock(world, i + 18, j + 0, k + 18, Blocks.nether_brick, 0);
        this.setBlock(world, i + 18, j + 0, k + 19, Blocks.nether_brick, 0);
        this.setBlock(world, i + 18, j + 0, k + 20, Blocks.nether_brick, 0);
        this.setBlock(world, i + 18, j + 0, k + 21, Blocks.nether_brick, 0);
        this.setBlock(world, i + 18, j + 0, k + 22, Blocks.nether_brick, 0);
        this.setBlock(world, i + 18, j + 1, k + 5, Blocks.nether_brick, 0);
        this.setBlock(world, i + 18, j + 1, k + 6, Blocks.nether_brick, 0);
        this.setBlock(world, i + 18, j + 1, k + 7, Blocks.nether_brick, 0);
        this.setBlock(world, i + 18, j + 1, k + 19, Blocks.nether_brick, 0);
        this.setBlock(world, i + 18, j + 1, k + 20, Blocks.nether_brick, 0);
        this.setBlock(world, i + 18, j + 1, k + 21, Blocks.nether_brick, 0);
        this.setBlock(world, i + 18, j + 1, k + 22, Blocks.soul_sand, 0);
        this.setBlock(world, i + 18, j + 2, k + 7, Blocks.nether_brick, 0);
        this.setBlock(world, i + 18, j + 2, k + 19, Blocks.nether_brick, 0);
        this.setBlock(world, i + 18, j + 2, k + 20, Blocks.soul_sand, 0);
        this.setBlock(world, i + 18, j + 2, k + 21, Blocks.soul_sand, 0);
        this.setBlock(world, i + 18, j + 2, k + 22, Blocks.soul_sand, 0);
        this.setBlock(world, i + 18, j + 3, k + 7, Blocks.nether_brick, 0);
        this.setBlock(world, i + 18, j + 3, k + 19, Blocks.nether_brick, 0);
        this.setBlock(world, i + 18, j + 3, k + 20, Blocks.soul_sand, 0);
        this.setBlock(world, i + 18, j + 3, k + 21, Blocks.soul_sand, 0);
        this.setBlock(world, i + 18, j + 3, k + 22, Blocks.soul_sand, 0);
        this.setBlock(world, i + 18, j + 4, k + 7, Blocks.nether_brick, 0);
        this.setBlock(world, i + 18, j + 4, k + 19, Blocks.nether_brick, 0);
        this.setBlock(world, i + 18, j + 4, k + 20, Blocks.soul_sand, 0);
        this.setBlock(world, i + 18, j + 4, k + 21, Blocks.nether_brick, 0);
        this.setBlock(world, i + 18, j + 4, k + 22, Blocks.nether_brick, 0);
        this.setBlock(world, i + 18, j + 5, k + 8, Blocks.nether_brick, 0);
        this.setBlock(world, i + 18, j + 5, k + 9, Blocks.nether_brick, 0);
        this.setBlock(world, i + 18, j + 5, k + 17, Blocks.nether_brick, 0);
        this.setBlock(world, i + 18, j + 5, k + 18, Blocks.nether_brick, 0);
        this.setBlock(world, i + 18, j + 5, k + 19, Blocks.nether_brick, 0);
        this.setBlock(world, i + 18, j + 5, k + 20, Blocks.nether_brick, 0);
        this.setBlock(world, i + 18, j + 6, k + 8, Blocks.nether_brick, 0);
        this.setBlock(world, i + 18, j + 6, k + 9, Blocks.nether_brick, 0);
        this.setBlock(world, i + 18, j + 6, k + 17, Blocks.nether_brick, 0);
        this.setBlock(world, i + 18, j + 6, k + 18, Blocks.nether_brick, 0);
        this.setBlock(world, i + 18, j + 7, k + 8, Blocks.nether_brick, 0);
        this.setBlock(world, i + 18, j + 7, k + 9, Blocks.nether_brick, 0);
        this.setBlock(world, i + 18, j + 7, k + 17, Blocks.nether_brick, 0);
        this.setBlock(world, i + 18, j + 7, k + 18, Blocks.nether_brick, 0);
        this.setBlock(world, i + 18, j + 8, k + 8, Blocks.soul_sand, 0);
        this.setBlock(world, i + 18, j + 8, k + 9, Blocks.soul_sand, 0);
        this.setBlock(world, i + 18, j + 8, k + 10, Blocks.nether_brick, 0);
        this.setBlock(world, i + 18, j + 8, k + 11, Blocks.nether_brick, 0);
        this.setBlock(world, i + 18, j + 8, k + 12, Blocks.nether_brick, 0);
        this.setBlock(world, i + 18, j + 8, k + 16, Blocks.nether_brick, 0);
        this.setBlock(world, i + 18, j + 9, k + 8, Blocks.soul_sand, 0);
        this.setBlock(world, i + 18, j + 9, k + 9, Blocks.soul_sand, 0);
        this.setBlock(world, i + 18, j + 9, k + 10, Blocks.nether_brick, 0);
        this.setBlock(world, i + 18, j + 9, k + 11, Blocks.nether_brick, 0);
        this.setBlock(world, i + 18, j + 9, k + 12, Blocks.nether_brick, 0);
        this.setBlock(world, i + 18, j + 9, k + 16, Blocks.nether_brick, 0);
        this.setBlock(world, i + 18, j + 10, k + 8, Blocks.soul_sand, 0);
        this.setBlock(world, i + 18, j + 10, k + 9, Blocks.soul_sand, 0);
        this.setBlock(world, i + 18, j + 10, k + 10, Blocks.nether_brick, 0);
        this.setBlock(world, i + 18, j + 10, k + 11, Blocks.nether_brick, 0);
        this.setBlock(world, i + 18, j + 10, k + 12, Blocks.nether_brick, 0);
        this.setBlock(world, i + 18, j + 10, k + 14, Blocks.obsidian, 0);
        this.setBlock(world, i + 18, j + 10, k + 16, Blocks.nether_brick, 0);
        this.setBlock(world, i + 18, j + 11, k + 8, Blocks.soul_sand, 0);
        this.setBlock(world, i + 18, j + 11, k + 9, Blocks.soul_sand, 0);
        this.setBlock(world, i + 18, j + 11, k + 10, Blocks.soul_sand, 0);
        this.setBlock(world, i + 18, j + 11, k + 11, Blocks.nether_brick, 0);
        this.setBlock(world, i + 18, j + 11, k + 12, Blocks.nether_brick, 0);
        this.setBlock(world, i + 18, j + 11, k + 13, Blocks.nether_brick, 0);
        this.setBlock(world, i + 18, j + 11, k + 14, Blocks.obsidian, 0);
        this.setBlock(world, i + 18, j + 11, k + 15, Blocks.nether_brick, 0);
        this.setBlock(world, i + 18, j + 12, k + 8, Blocks.nether_brick, 0);
        this.setBlock(world, i + 18, j + 12, k + 9, Blocks.nether_brick, 0);
        this.setBlock(world, i + 18, j + 12, k + 10, Blocks.nether_brick, 0);
        this.setBlock(world, i + 18, j + 12, k + 13, Blocks.nether_brick, 0);
        this.setBlock(world, i + 18, j + 12, k + 14, Blocks.obsidian, 0);
        this.setBlock(world, i + 18, j + 12, k + 15, Blocks.nether_brick, 0);
        this.setBlock(world, i + 18, j + 13, k + 13, Blocks.nether_brick, 0);
        this.setBlock(world, i + 18, j + 13, k + 14, Blocks.obsidian, 0);
        this.setBlock(world, i + 18, j + 13, k + 15, Blocks.nether_brick, 0);
        this.setBlock(world, i + 18, j + 14, k + 13, Blocks.nether_brick, 0);
        this.setBlock(world, i + 18, j + 14, k + 14, Blocks.obsidian, 0);
        this.setBlock(world, i + 18, j + 14, k + 15, Blocks.nether_brick, 0);
        this.setBlock(world, i + 18, j + 15, k + 14, Blocks.nether_brick, 0);
        this.setBlock(world, i + 18, j + 16, k + 14, Blocks.nether_brick, 0);
        this.setBlock(world, i + 18, j + 17, k + 14, Blocks.nether_brick, 0);
        this.setBlock(world, i + 18, j + 18, k + 14, Blocks.nether_brick, 0);
        this.setBlock(world, i + 18, j + 19, k + 14, Blocks.nether_brick, 0);
        this.setBlock(world, i + 18, j + 20, k + 14, Blocks.nether_brick, 0);
        this.setBlock(world, i + 18, j + 21, k + 14, Blocks.nether_brick, 0);
        this.setBlock(world, i + 19, j + 0, k + 5, Blocks.nether_brick, 0);
        this.setBlock(world, i + 19, j + 0, k + 6, Blocks.nether_brick, 0);
        this.setBlock(world, i + 19, j + 0, k + 7, Blocks.nether_brick, 0);
        this.setBlock(world, i + 19, j + 0, k + 8, Blocks.nether_brick, 0);
        this.setBlock(world, i + 19, j + 0, k + 9, Blocks.nether_brick, 0);
        this.setBlock(world, i + 19, j + 0, k + 10, Blocks.nether_brick, 0);
        this.setBlock(world, i + 19, j + 0, k + 11, Blocks.nether_brick, 0);
