

package com.gibby.dungeon.gen;

import net.minecraft.world.gen.feature.*;
import net.minecraft.world.*;
import java.util.*;
import net.minecraft.init.*;
import net.minecraft.block.*;
import com.gibby.dungeon.mobs.*;
import net.minecraft.entity.*;
import net.minecraft.entity.passive.*;

public class WorldGenMoundVillage extends WorldGenerator
{
    public boolean generate(final World world, final Random rand, final int i, final int j, final int k) {
        if (world.getBlock(i, j, k) != Blocks.grass || world.getBlock(i + 66, j, k) != Blocks.grass || world.getBlock(i + 66, j, k + 42) != Blocks.grass || world.getBlock(i, j, k + 42) != Blocks.grass || world.getBlock(i, j + 1, k) != Blocks.air || world.getBlock(i + 66, j + 1, k) != Blocks.air || world.getBlock(i + 66, j + 1, k + 42) != Blocks.air || world.getBlock(i, j + 1, k + 42) != Blocks.air) {
            return false;
        }
        world.setBlock(i, j, k, Blocks.grass);
        world.setBlock(i, j, k + 1, Blocks.grass);
        world.setBlock(i, j, k + 2, Blocks.grass);
        world.setBlock(i, j, k + 3, Blocks.grass);
        world.setBlock(i, j, k + 4, Blocks.grass);
        world.setBlock(i, j, k + 5, Blocks.grass);
        world.setBlock(i, j, k + 6, Blocks.grass);
        world.setBlock(i, j, k + 7, Blocks.grass);
        world.setBlock(i, j, k + 8, Blocks.grass);
        world.setBlock(i, j, k + 9, Blocks.grass);
        world.setBlock(i, j, k + 10, Blocks.grass);
        world.setBlock(i, j, k + 11, Blocks.grass);
        world.setBlock(i, j, k + 12, Blocks.grass);
        world.setBlock(i, j, k + 13, Blocks.grass);
        world.setBlock(i, j, k + 14, Blocks.grass);
        world.setBlock(i, j, k + 15, Blocks.grass);
        world.setBlock(i, j, k + 16, Blocks.grass);
        world.setBlock(i, j, k + 17, Blocks.grass);
        world.setBlock(i, j, k + 18, Blocks.grass);
        world.setBlock(i, j, k + 19, Blocks.grass);
        world.setBlock(i, j, k + 20, Blocks.grass);
        world.setBlock(i, j, k + 21, Blocks.grass);
        world.setBlock(i, j, k + 22, Blocks.grass);
        world.setBlock(i, j, k + 23, Blocks.grass);
        world.setBlock(i, j, k + 24, Blocks.grass);
        world.setBlock(i, j, k + 25, Blocks.grass);
        world.setBlock(i, j, k + 26, Blocks.grass);
        world.setBlock(i, j, k + 27, Blocks.grass);
        world.setBlock(i, j, k + 28, Blocks.grass);
        world.setBlock(i, j, k + 29, Blocks.grass);
        world.setBlock(i, j, k + 30, Blocks.grass);
        world.setBlock(i, j, k + 31, Blocks.grass);
        world.setBlock(i, j, k + 32, Blocks.grass);
        world.setBlock(i, j, k + 33, Blocks.grass);
        world.setBlock(i, j, k + 34, Blocks.grass);
        world.setBlock(i, j, k + 35, Blocks.grass);
        world.setBlock(i, j, k + 36, Blocks.grass);
        world.setBlock(i, j, k + 37, Blocks.grass);
        world.setBlock(i, j, k + 38, Blocks.grass);
        world.setBlock(i, j, k + 39, Blocks.grass);
        world.setBlock(i, j, k + 40, Blocks.grass);
        world.setBlock(i, j, k + 41, Blocks.grass);
        world.setBlock(i, j, k + 42, Blocks.grass);
        world.setBlock(i + 1, j, k, Blocks.grass);
        world.setBlock(i + 1, j, k + 1, Blocks.grass);
        world.setBlock(i + 1, j, k + 2, Blocks.grass);
        world.setBlock(i + 1, j, k + 3, Blocks.grass);
        world.setBlock(i + 1, j, k + 4, Blocks.grass);
        world.setBlock(i + 1, j, k + 5, Blocks.grass);
        world.setBlock(i + 1, j, k + 6, Blocks.grass);
        world.setBlock(i + 1, j, k + 7, Blocks.grass);
        world.setBlock(i + 1, j, k + 8, Blocks.grass);
        world.setBlock(i + 1, j, k + 9, Blocks.grass);
        world.setBlock(i + 1, j, k + 10, Blocks.grass);
        world.setBlock(i + 1, j, k + 11, Blocks.grass);
        world.setBlock(i + 1, j, k + 12, Blocks.grass);
        world.setBlock(i + 1, j, k + 13, Blocks.grass);
        world.setBlock(i + 1, j, k + 14, Blocks.grass);
        world.setBlock(i + 1, j, k + 15, Blocks.grass);
        world.setBlock(i + 1, j, k + 16, Blocks.grass);
        world.setBlock(i + 1, j, k + 17, Blocks.grass);
        world.setBlock(i + 1, j, k + 18, Blocks.grass);
        world.setBlock(i + 1, j, k + 19, Blocks.grass);
        world.setBlock(i + 1, j, k + 20, Blocks.grass);
        world.setBlock(i + 1, j, k + 21, Blocks.grass);
        world.setBlock(i + 1, j, k + 22, Blocks.grass);
        world.setBlock(i + 1, j, k + 23, Blocks.grass);
        world.setBlock(i + 1, j, k + 24, Blocks.grass);
        world.setBlock(i + 1, j, k + 25, Blocks.grass);
        world.setBlock(i + 1, j, k + 26, Blocks.grass);
        world.setBlock(i + 1, j, k + 27, Blocks.grass);
        world.setBlock(i + 1, j, k + 28, Blocks.grass);
        world.setBlock(i + 1, j, k + 29, Blocks.grass);
        world.setBlock(i + 1, j, k + 30, Blocks.grass);
        world.setBlock(i + 1, j, k + 31, Blocks.grass);
        world.setBlock(i + 1, j, k + 32, Blocks.grass);
        world.setBlock(i + 1, j, k + 33, Blocks.grass);
        world.setBlock(i + 1, j, k + 34, Blocks.grass);
        world.setBlock(i + 1, j, k + 35, Blocks.grass);
        world.setBlock(i + 1, j, k + 36, Blocks.grass);
        world.setBlock(i + 1, j, k + 37, Blocks.grass);
        world.setBlock(i + 1, j, k + 38, Blocks.grass);
        world.setBlock(i + 1, j, k + 39, Blocks.grass);
        world.setBlock(i + 1, j, k + 40, Blocks.grass);
        world.setBlock(i + 1, j, k + 41, Blocks.grass);
        world.setBlock(i + 1, j, k + 42, Blocks.grass);
        world.setBlock(i + 2, j, k, Blocks.grass);
        world.setBlock(i + 2, j, k + 1, Blocks.grass);
        world.setBlock(i + 2, j, k + 2, Blocks.grass);
        world.setBlock(i + 2, j, k + 3, Blocks.grass);
        world.setBlock(i + 2, j, k + 4, Blocks.grass);
        world.setBlock(i + 2, j, k + 5, Blocks.grass);
        world.setBlock(i + 2, j, k + 6, Blocks.grass);
        world.setBlock(i + 2, j, k + 7, Blocks.grass);
        world.setBlock(i + 2, j, k + 8, Blocks.grass);
        world.setBlock(i + 2, j, k + 9, Blocks.grass);
        world.setBlock(i + 2, j, k + 10, Blocks.grass);
        world.setBlock(i + 2, j, k + 11, Blocks.grass);
        world.setBlock(i + 2, j, k + 12, Blocks.grass);
        world.setBlock(i + 2, j, k + 13, Blocks.grass);
        world.setBlock(i + 2, j, k + 14, Blocks.grass);
        world.setBlock(i + 2, j, k + 15, Blocks.grass);
        world.setBlock(i + 2, j, k + 16, Blocks.grass);
        world.setBlock(i + 2, j, k + 17, Blocks.grass);
        world.setBlock(i + 2, j, k + 18, Blocks.grass);
        world.setBlock(i + 2, j, k + 19, Blocks.grass);
        world.setBlock(i + 2, j, k + 20, Blocks.grass);
        world.setBlock(i + 2, j, k + 21, Blocks.grass);
        world.setBlock(i + 2, j, k + 22, Blocks.grass);
        world.setBlock(i + 2, j, k + 23, Blocks.grass);
        world.setBlock(i + 2, j, k + 24, Blocks.grass);
        world.setBlock(i + 2, j, k + 25, Blocks.grass);
        world.setBlock(i + 2, j, k + 26, Blocks.grass);
        world.setBlock(i + 2, j, k + 27, Blocks.grass);
        world.setBlock(i + 2, j, k + 28, Blocks.grass);
        world.setBlock(i + 2, j, k + 29, Blocks.grass);
        world.setBlock(i + 2, j, k + 30, Blocks.dirt);
        world.setBlock(i + 2, j, k + 31, Blocks.dirt);
        world.setBlock(i + 2, j, k + 32, Blocks.dirt);
        world.setBlock(i + 2, j, k + 33, Blocks.dirt);
        world.setBlock(i + 2, j, k + 34, Blocks.dirt);
        world.setBlock(i + 2, j, k + 35, Blocks.dirt);
        world.setBlock(i + 2, j, k + 36, Blocks.dirt);
        world.setBlock(i + 2, j, k + 37, Blocks.dirt);
        world.setBlock(i + 2, j, k + 38, Blocks.dirt);
        world.setBlock(i + 2, j, k + 39, Blocks.dirt);
        world.setBlock(i + 2, j, k + 40, Blocks.dirt);
        world.setBlock(i + 2, j, k + 41, Blocks.dirt);
        world.setBlock(i + 2, j, k + 42, Blocks.grass);
        world.setBlock(i + 2, j + 1, k + 30, Blocks.dirt);
        world.setBlock(i + 2, j + 1, k + 31, Blocks.dirt);
        world.setBlock(i + 2, j + 1, k + 32, Blocks.dirt);
        world.setBlock(i + 2, j + 1, k + 33, Blocks.dirt);
        world.setBlock(i + 2, j + 1, k + 34, Blocks.dirt);
        world.setBlock(i + 2, j + 1, k + 35, Blocks.dirt);
        world.setBlock(i + 2, j + 1, k + 36, Blocks.dirt);
        world.setBlock(i + 2, j + 1, k + 37, Blocks.dirt);
        world.setBlock(i + 2, j + 1, k + 38, Blocks.dirt);
        world.setBlock(i + 2, j + 1, k + 39, Blocks.dirt);
        world.setBlock(i + 2, j + 1, k + 40, Blocks.dirt);
        world.setBlock(i + 2, j + 1, k + 41, Blocks.dirt);
        world.setBlock(i + 2, j + 2, k + 30, Blocks.grass);
        world.setBlock(i + 2, j + 2, k + 31, Blocks.grass);
        world.setBlock(i + 2, j + 2, k + 32, Blocks.grass);
        world.setBlock(i + 2, j + 2, k + 33, Blocks.grass);
        world.setBlock(i + 2, j + 2, k + 34, Blocks.grass);
        world.setBlock(i + 2, j + 2, k + 35, Blocks.grass);
        world.setBlock(i + 2, j + 2, k + 36, Blocks.grass);
        world.setBlock(i + 2, j + 2, k + 37, Blocks.grass);
        world.setBlock(i + 2, j + 2, k + 38, Blocks.grass);
        world.setBlock(i + 2, j + 2, k + 39, Blocks.grass);
        world.setBlock(i + 2, j + 2, k + 40, Blocks.grass);
        world.setBlock(i + 2, j + 2, k + 41, Blocks.grass);
        world.setBlock(i + 3, j, k, Blocks.grass);
        world.setBlock(i + 3, j, k + 1, Blocks.grass);
        world.setBlock(i + 3, j, k + 2, Blocks.grass);
        world.setBlock(i + 3, j, k + 3, Blocks.grass);
        world.setBlock(i + 3, j, k + 4, Blocks.grass);
        world.setBlock(i + 3, j, k + 5, Blocks.grass);
        world.setBlock(i + 3, j, k + 6, Blocks.grass);
        world.setBlock(i + 3, j, k + 7, Blocks.grass);
        world.setBlock(i + 3, j, k + 8, Blocks.grass);
        world.setBlock(i + 3, j, k + 9, Blocks.grass);
        world.setBlock(i + 3, j, k + 10, Blocks.grass);
        world.setBlock(i + 3, j, k + 11, Blocks.grass);
        world.setBlock(i + 3, j, k + 12, Blocks.grass);
        world.setBlock(i + 3, j, k + 13, Blocks.grass);
        world.setBlock(i + 3, j, k + 14, Blocks.grass);
        world.setBlock(i + 3, j, k + 25, Blocks.grass);
        world.setBlock(i + 3, j, k + 26, Blocks.grass);
        world.setBlock(i + 3, j, k + 27, Blocks.grass);
        world.setBlock(i + 3, j, k + 28, Blocks.grass);
        world.setBlock(i + 3, j, k + 29, Blocks.grass);
        world.setBlock(i + 3, j, k + 30, Blocks.dirt);
        world.setBlock(i + 3, j, k + 31, Blocks.dirt);
        world.setBlock(i + 3, j, k + 32, Blocks.dirt);
        world.setBlock(i + 3, j, k + 33, Blocks.dirt);
        world.setBlock(i + 3, j, k + 34, Blocks.dirt);
        world.setBlock(i + 3, j, k + 35, Blocks.dirt);
        world.setBlock(i + 3, j, k + 36, Blocks.dirt);
        world.setBlock(i + 3, j, k + 37, Blocks.dirt);
        world.setBlock(i + 3, j, k + 38, Blocks.dirt);
        world.setBlock(i + 3, j, k + 39, Blocks.dirt);
        world.setBlock(i + 3, j, k + 40, Blocks.dirt);
        world.setBlock(i + 3, j, k + 41, Blocks.dirt);
        world.setBlock(i + 3, j, k + 42, Blocks.grass);
        world.setBlock(i + 3, j + 1, k + 30, Blocks.dirt);
        world.setBlock(i + 3, j + 1, k + 31, Blocks.dirt);
        world.setBlock(i + 3, j + 1, k + 32, Blocks.dirt);
        world.setBlock(i + 3, j + 1, k + 33, Blocks.dirt);
        world.setBlock(i + 3, j + 1, k + 34, Blocks.dirt);
        world.setBlock(i + 3, j + 1, k + 35, Blocks.dirt);
        world.setBlock(i + 3, j + 1, k + 36, Blocks.dirt);
        world.setBlock(i + 3, j + 1, k + 37, Blocks.dirt);
        world.setBlock(i + 3, j + 1, k + 38, Blocks.dirt);
        world.setBlock(i + 3, j + 1, k + 39, Blocks.dirt);
        world.setBlock(i + 3, j + 1, k + 40, Blocks.dirt);
        world.setBlock(i + 3, j + 1, k + 41, Blocks.dirt);
        world.setBlock(i + 3, j + 2, k + 30, Blocks.grass);
        world.setBlock(i + 3, j + 2, k + 31, Blocks.dirt);
        world.setBlock(i + 3, j + 2, k + 32, Blocks.dirt);
        world.setBlock(i + 3, j + 2, k + 33, Blocks.dirt);
        world.setBlock(i + 3, j + 2, k + 34, Blocks.dirt);
        world.setBlock(i + 3, j + 2, k + 35, Blocks.dirt);
        world.setBlock(i + 3, j + 2, k + 36, Blocks.dirt);
        world.setBlock(i + 3, j + 2, k + 37, Blocks.dirt);
        world.setBlock(i + 3, j + 2, k + 38, Blocks.dirt);
        world.setBlock(i + 3, j + 2, k + 39, Blocks.dirt);
        world.setBlock(i + 3, j + 2, k + 40, Blocks.dirt);
        world.setBlock(i + 3, j + 2, k + 41, Blocks.grass);
        world.setBlock(i + 3, j + 3, k + 31, Blocks.dirt);
        world.setBlock(i + 3, j + 3, k + 32, Blocks.dirt);
        world.setBlock(i + 3, j + 3, k + 33, Blocks.dirt);
        world.setBlock(i + 3, j + 3, k + 34, Blocks.dirt);
        world.setBlock(i + 3, j + 3, k + 35, Blocks.dirt);
        world.setBlock(i + 3, j + 3, k + 36, Blocks.dirt);
        world.setBlock(i + 3, j + 3, k + 37, Blocks.dirt);
        world.setBlock(i + 3, j + 3, k + 38, Blocks.dirt);
        world.setBlock(i + 3, j + 3, k + 39, Blocks.dirt);
        world.setBlock(i + 3, j + 3, k + 40, Blocks.dirt);
        world.setBlock(i + 3, j + 4, k + 31, Blocks.grass);
        world.setBlock(i + 3, j + 4, k + 32, Blocks.grass);
        world.setBlock(i + 3, j + 4, k + 33, Blocks.grass);
        world.setBlock(i + 3, j + 4, k + 34, Blocks.grass);
        world.setBlock(i + 3, j + 4, k + 35, Blocks.grass);
        world.setBlock(i + 3, j + 4, k + 36, Blocks.grass);
        world.setBlock(i + 3, j + 4, k + 37, Blocks.grass);
        world.setBlock(i + 3, j + 4, k + 38, Blocks.grass);
        world.setBlock(i + 3, j + 4, k + 39, Blocks.grass);
        world.setBlock(i + 3, j + 4, k + 40, Blocks.grass);
        world.setBlock(i + 4, j, k, Blocks.grass);
        world.setBlock(i + 4, j, k + 1, Blocks.grass);
        world.setBlock(i + 4, j, k + 2, Blocks.grass);
        world.setBlock(i + 4, j, k + 3, Blocks.grass);
        world.setBlock(i + 4, j, k + 4, Blocks.grass);
        world.setBlock(i + 4, j, k + 5, Blocks.grass);
        world.setBlock(i + 4, j, k + 6, Blocks.grass);
        world.setBlock(i + 4, j, k + 7, Blocks.grass);
        world.setBlock(i + 4, j, k + 8, Blocks.grass);
        world.setBlock(i + 4, j, k + 9, Blocks.grass);
        world.setBlock(i + 4, j, k + 10, Blocks.grass);
        world.setBlock(i + 4, j, k + 11, Blocks.grass);
        world.setBlock(i + 4, j, k + 12, Blocks.grass);
        world.setBlock(i + 4, j, k + 13, Blocks.grass);
        world.setBlock(i + 4, j, k + 14, Blocks.grass);
        world.setBlock(i + 4, j, k + 25, Blocks.grass);
        world.setBlock(i + 4, j, k + 26, Blocks.grass);
        world.setBlock(i + 4, j, k + 27, Blocks.grass);
        world.setBlock(i + 4, j, k + 28, Blocks.grass);
        world.setBlock(i + 4, j, k + 29, Blocks.grass);
        world.setBlock(i + 4, j, k + 30, Blocks.dirt);
        world.setBlock(i + 4, j, k + 31, Blocks.dirt);
        world.setBlock(i + 4, j, k + 32, Blocks.dirt);
        world.setBlock(i + 4, j, k + 33, Blocks.dirt);
        world.setBlock(i + 4, j, k + 34, Blocks.dirt);
        world.setBlock(i + 4, j, k + 35, Blocks.dirt);
        world.setBlock(i + 4, j, k + 36, Blocks.dirt);
        world.setBlock(i + 4, j, k + 37, Blocks.dirt);
        world.setBlock(i + 4, j, k + 38, Blocks.dirt);
        world.setBlock(i + 4, j, k + 39, Blocks.dirt);
        world.setBlock(i + 4, j, k + 40, Blocks.dirt);
        world.setBlock(i + 4, j, k + 41, Blocks.dirt);
        world.setBlock(i + 4, j, k + 42, Blocks.grass);
        world.setBlock(i + 4, j + 1, k + 30, Blocks.dirt);
        world.setBlock(i + 4, j + 1, k + 31, Blocks.dirt);
        world.setBlock(i + 4, j + 1, k + 32, Blocks.dirt);
        world.setBlock(i + 4, j + 1, k + 33, Blocks.dirt);
        world.setBlock(i + 4, j + 1, k + 34, Blocks.dirt);
        world.setBlock(i + 4, j + 1, k + 35, Blocks.dirt);
        world.setBlock(i + 4, j + 1, k + 36, Blocks.dirt);
        world.setBlock(i + 4, j + 1, k + 37, Blocks.dirt);
        world.setBlock(i + 4, j + 1, k + 38, Blocks.dirt);
        world.setBlock(i + 4, j + 1, k + 39, Blocks.dirt);
        world.setBlock(i + 4, j + 1, k + 40, Blocks.dirt);
        world.setBlock(i + 4, j + 1, k + 41, Blocks.dirt);
        world.setBlock(i + 4, j + 2, k + 30, Blocks.grass);
        world.setBlock(i + 4, j + 2, k + 31, Blocks.dirt);
        world.setBlock(i + 4, j + 2, k + 32, Blocks.dirt);
        world.setBlock(i + 4, j + 2, k + 33, Blocks.dirt);
        world.setBlock(i + 4, j + 2, k + 34, Blocks.dirt);
        world.setBlock(i + 4, j + 2, k + 35, Blocks.dirt);
        world.setBlock(i + 4, j + 2, k + 36, Blocks.dirt);
        world.setBlock(i + 4, j + 2, k + 37, Blocks.dirt);
        world.setBlock(i + 4, j + 2, k + 38, Blocks.dirt);
        world.setBlock(i + 4, j + 2, k + 39, Blocks.dirt);
        world.setBlock(i + 4, j + 2, k + 40, Blocks.dirt);
        world.setBlock(i + 4, j + 2, k + 41, Blocks.grass);
        world.setBlock(i + 4, j + 3, k + 31, Blocks.dirt);
        world.setBlock(i + 4, j + 3, k + 32, Blocks.dirt);
        world.setBlock(i + 4, j + 3, k + 33, Blocks.dirt);
        world.setBlock(i + 4, j + 3, k + 34, Blocks.dirt);
        world.setBlock(i + 4, j + 3, k + 35, Blocks.dirt);
        world.setBlock(i + 4, j + 3, k + 36, Blocks.dirt);
        world.setBlock(i + 4, j + 3, k + 37, Blocks.dirt);
        world.setBlock(i + 4, j + 3, k + 38, Blocks.dirt);
        world.setBlock(i + 4, j + 3, k + 39, Blocks.dirt);
        world.setBlock(i + 4, j + 3, k + 40, Blocks.dirt);
        world.setBlock(i + 4, j + 4, k + 31, Blocks.grass);
        world.setBlock(i + 4, j + 4, k + 32, Blocks.dirt);
        world.setBlock(i + 4, j + 4, k + 33, Blocks.dirt);
        world.setBlock(i + 4, j + 4, k + 34, Blocks.dirt);
        world.setBlock(i + 4, j + 4, k + 35, Blocks.dirt);
        world.setBlock(i + 4, j + 4, k + 36, Blocks.dirt);
        world.setBlock(i + 4, j + 4, k + 37, Blocks.dirt);
        world.setBlock(i + 4, j + 4, k + 38, Blocks.dirt);
        world.setBlock(i + 4, j + 4, k + 39, Blocks.dirt);
        world.setBlock(i + 4, j + 4, k + 40, Blocks.grass);
        world.setBlock(i + 4, j + 5, k + 32, Blocks.dirt);
        world.setBlock(i + 4, j + 5, k + 33, Blocks.dirt);
        world.setBlock(i + 4, j + 5, k + 34, Blocks.dirt);
        world.setBlock(i + 4, j + 5, k + 35, Blocks.dirt);
        world.setBlock(i + 4, j + 5, k + 36, Blocks.dirt);
        world.setBlock(i + 4, j + 5, k + 37, Blocks.dirt);
        world.setBlock(i + 4, j + 5, k + 38, Blocks.dirt);
        world.setBlock(i + 4, j + 5, k + 39, Blocks.dirt);
        world.setBlock(i + 4, j + 6, k + 32, Blocks.grass);
        world.setBlock(i + 4, j + 6, k + 33, Blocks.grass);
        world.setBlock(i + 4, j + 6, k + 34, Blocks.grass);
        world.setBlock(i + 4, j + 6, k + 35, Blocks.grass);
        world.setBlock(i + 4, j + 6, k + 36, Blocks.grass);
        world.setBlock(i + 4, j + 6, k + 37, Blocks.grass);
        world.setBlock(i + 4, j + 6, k + 38, Blocks.grass);
        world.setBlock(i + 4, j + 6, k + 39, Blocks.grass);
        world.setBlock(i + 5, j, k, Blocks.grass);
        world.setBlock(i + 5, j, k + 1, Blocks.grass);
        world.setBlock(i + 5, j, k + 2, Blocks.grass);
        world.setBlock(i + 5, j, k + 3, Blocks.grass);
        world.setBlock(i + 5, j, k + 4, Blocks.grass);
        world.setBlock(i + 5, j, k + 5, Blocks.grass);
        world.setBlock(i + 5, j, k + 6, Blocks.grass);
        world.setBlock(i + 5, j, k + 7, Blocks.grass);
        world.setBlock(i + 5, j, k + 8, Blocks.grass);
        world.setBlock(i + 5, j, k + 9, Blocks.grass);
        world.setBlock(i + 5, j, k + 10, Blocks.grass);
        world.setBlock(i + 5, j, k + 11, Blocks.grass);
        world.setBlock(i + 5, j, k + 12, Blocks.grass);
        world.setBlock(i + 5, j, k + 13, Blocks.grass);
        world.setBlock(i + 5, j, k + 14, Blocks.grass);
        world.setBlock(i + 5, j, k + 25, Blocks.grass);
        world.setBlock(i + 5, j, k + 26, Blocks.grass);
        world.setBlock(i + 5, j, k + 27, Blocks.grass);
        world.setBlock(i + 5, j, k + 28, Blocks.grass);
        world.setBlock(i + 5, j, k + 29, Blocks.grass);
        world.setBlock(i + 5, j, k + 30, Blocks.dirt);
        world.setBlock(i + 5, j, k + 31, Blocks.dirt);
        world.setBlock(i + 5, j, k + 32, Blocks.dirt);
        world.setBlock(i + 5, j, k + 33, Blocks.dirt);
        world.setBlock(i + 5, j, k + 34, Blocks.dirt);
        world.setBlock(i + 5, j, k + 35, Blocks.dirt);
        world.setBlock(i + 5, j, k + 36, Blocks.dirt);
        world.setBlock(i + 5, j, k + 37, Blocks.dirt);
        world.setBlock(i + 5, j, k + 38, Blocks.dirt);
        world.setBlock(i + 5, j, k + 39, Blocks.dirt);
        world.setBlock(i + 5, j, k + 40, Blocks.dirt);
        world.setBlock(i + 5, j, k + 41, Blocks.dirt);
        world.setBlock(i + 5, j, k + 42, Blocks.grass);
        world.setBlock(i + 5, j + 1, k + 30, Blocks.dirt);
        world.setBlock(i + 5, j + 1, k + 31, Blocks.dirt);
        world.setBlock(i + 5, j + 1, k + 32, Blocks.dirt);
        world.setBlock(i + 5, j + 1, k + 33, Blocks.dirt);
        world.setBlock(i + 5, j + 1, k + 34, Blocks.dirt);
        world.setBlock(i + 5, j + 1, k + 35, Blocks.dirt);
        world.setBlock(i + 5, j + 1, k + 36, Blocks.dirt);
        world.setBlock(i + 5, j + 1, k + 37, Blocks.dirt);
        world.setBlock(i + 5, j + 1, k + 38, Blocks.dirt);
        world.setBlock(i + 5, j + 1, k + 39, Blocks.dirt);
        world.setBlock(i + 5, j + 1, k + 40, Blocks.dirt);
        world.setBlock(i + 5, j + 1, k + 41, Blocks.dirt);
        world.setBlock(i + 5, j + 2, k + 30, Blocks.grass);
        world.setBlock(i + 5, j + 2, k + 31, Blocks.dirt);
        world.setBlock(i + 5, j + 2, k + 32, Blocks.dirt);
        world.setBlock(i + 5, j + 2, k + 33, Blocks.dirt);
        world.setBlock(i + 5, j + 2, k + 34, Blocks.dirt);
        world.setBlock(i + 5, j + 2, k + 35, Blocks.dirt);
        world.setBlock(i + 5, j + 2, k + 36, Blocks.dirt);
        world.setBlock(i + 5, j + 2, k + 37, Blocks.dirt);
        world.setBlock(i + 5, j + 2, k + 38, Blocks.dirt);
        world.setBlock(i + 5, j + 2, k + 39, Blocks.dirt);
        world.setBlock(i + 5, j + 2, k + 40, Blocks.dirt);
        world.setBlock(i + 5, j + 2, k + 41, Blocks.grass);
        world.setBlock(i + 5, j + 3, k + 31, Blocks.dirt);
        world.setBlock(i + 5, j + 3, k + 32, Blocks.dirt);
        world.setBlock(i + 5, j + 3, k + 33, Blocks.dirt);
        world.setBlock(i + 5, j + 3, k + 34, Blocks.dirt);
        world.setBlock(i + 5, j + 3, k + 35, Blocks.dirt);
        world.setBlock(i + 5, j + 3, k + 36, Blocks.dirt);
        world.setBlock(i + 5, j + 3, k + 37, Blocks.dirt);
        world.setBlock(i + 5, j + 3, k + 38, Blocks.dirt);
        world.setBlock(i + 5, j + 3, k + 39, Blocks.dirt);
        world.setBlock(i + 5, j + 3, k + 40, Blocks.dirt);
        world.setBlock(i + 5, j + 4, k + 31, Blocks.grass);
        world.setBlock(i + 5, j + 4, k + 32, Blocks.dirt);
        world.setBlock(i + 5, j + 4, k + 33, Blocks.dirt);
        world.setBlock(i + 5, j + 4, k + 34, Blocks.dirt);
        world.setBlock(i + 5, j + 4, k + 35, Blocks.dirt);
        world.setBlock(i + 5, j + 4, k + 36, Blocks.dirt);
        world.setBlock(i + 5, j + 4, k + 37, Blocks.dirt);
        world.setBlock(i + 5, j + 4, k + 38, Blocks.dirt);
        world.setBlock(i + 5, j + 4, k + 39, Blocks.dirt);
        world.setBlock(i + 5, j + 4, k + 40, Blocks.grass);
        world.setBlock(i + 5, j + 5, k + 32, Blocks.dirt);
        world.setBlock(i + 5, j + 5, k + 33, Blocks.dirt);
        world.setBlock(i + 5, j + 5, k + 34, Blocks.dirt);
        world.setBlock(i + 5, j + 5, k + 35, Blocks.dirt);
        world.setBlock(i + 5, j + 5, k + 36, Blocks.dirt);
        world.setBlock(i + 5, j + 5, k + 37, Blocks.dirt);
        world.setBlock(i + 5, j + 5, k + 38, Blocks.dirt);
        world.setBlock(i + 5, j + 5, k + 39, Blocks.dirt);
        world.setBlock(i + 5, j + 6, k + 32, Blocks.grass);
        world.setBlock(i + 5, j + 6, k + 33, Blocks.dirt);
        world.setBlock(i + 5, j + 6, k + 34, Blocks.dirt);
        world.setBlock(i + 5, j + 6, k + 35, Blocks.dirt);
        world.setBlock(i + 5, j + 6, k + 36, Blocks.dirt);
        world.setBlock(i + 5, j + 6, k + 37, Blocks.dirt);
        world.setBlock(i + 5, j + 6, k + 38, Blocks.dirt);
        world.setBlock(i + 5, j + 6, k + 39, Blocks.grass);
        world.setBlock(i + 5, j + 7, k + 33, Blocks.dirt);
        world.setBlock(i + 5, j + 7, k + 34, Blocks.dirt);
        world.setBlock(i + 5, j + 7, k + 35, Blocks.dirt);
        world.setBlock(i + 5, j + 7, k + 36, Blocks.dirt);
        world.setBlock(i + 5, j + 7, k + 37, Blocks.dirt);
        world.setBlock(i + 5, j + 7, k + 38, Blocks.dirt);
        world.setBlock(i + 5, j + 8, k + 33, Blocks.grass);
        world.setBlock(i + 5, j + 8, k + 34, Blocks.grass);
        world.setBlock(i + 5, j + 8, k + 35, Blocks.grass);
        world.setBlock(i + 5, j + 8, k + 36, Blocks.grass);
        world.setBlock(i + 5, j + 8, k + 37, Blocks.grass);
        world.setBlock(i + 5, j + 8, k + 38, Blocks.grass);
        world.setBlock(i + 6, j, k, Blocks.grass);
        world.setBlock(i + 6, j, k + 1, Blocks.grass);
        world.setBlock(i + 6, j, k + 2, Blocks.grass);
        world.setBlock(i + 6, j, k + 3, Blocks.grass);
        world.setBlock(i + 6, j, k + 4, Blocks.grass);
        world.setBlock(i + 6, j, k + 5, Blocks.grass);
        world.setBlock(i + 6, j, k + 6, Blocks.grass);
        world.setBlock(i + 6, j, k + 7, Blocks.grass);
        world.setBlock(i + 6, j, k + 8, Blocks.grass);
        world.setBlock(i + 6, j, k + 9, Blocks.grass);
        world.setBlock(i + 6, j, k + 10, Blocks.grass);
        world.setBlock(i + 6, j, k + 11, Blocks.grass);
        world.setBlock(i + 6, j, k + 12, Blocks.grass);
        world.setBlock(i + 6, j, k + 13, Blocks.grass);
        world.setBlock(i + 6, j, k + 14, Blocks.grass);
        world.setBlock(i + 6, j, k + 25, Blocks.grass);
        world.setBlock(i + 6, j, k + 26, Blocks.grass);
        world.setBlock(i + 6, j, k + 27, Blocks.grass);
        world.setBlock(i + 6, j, k + 28, Blocks.grass);
        world.setBlock(i + 6, j, k + 29, Blocks.grass);
        world.setBlock(i + 6, j, k + 30, Blocks.dirt);
        world.setBlock(i + 6, j, k + 31, Blocks.dirt);
        world.setBlock(i + 6, j, k + 32, Blocks.dirt);
        world.setBlock(i + 6, j, k + 33, Blocks.dirt);
        world.setBlock(i + 6, j, k + 34, Blocks.dirt);
        world.setBlock(i + 6, j, k + 35, Blocks.dirt);
        world.setBlock(i + 6, j, k + 36, Blocks.dirt);
        world.setBlock(i + 6, j, k + 37, Blocks.dirt);
        world.setBlock(i + 6, j, k + 38, Blocks.dirt);
        world.setBlock(i + 6, j, k + 39, Blocks.dirt);
        world.setBlock(i + 6, j, k + 40, Blocks.dirt);
        world.setBlock(i + 6, j, k + 41, Blocks.dirt);
        world.setBlock(i + 6, j, k + 42, Blocks.grass);
        world.setBlock(i + 6, j + 1, k + 30, Blocks.dirt);
        world.setBlock(i + 6, j + 1, k + 31, Blocks.dirt);
        world.setBlock(i + 6, j + 1, k + 32, Blocks.dirt);
        world.setBlock(i + 6, j + 1, k + 33, Blocks.dirt);
        world.setBlock(i + 6, j + 1, k + 34, Blocks.dirt);
        world.setBlock(i + 6, j + 1, k + 35, Blocks.dirt);
        world.setBlock(i + 6, j + 1, k + 36, Blocks.dirt);
        world.setBlock(i + 6, j + 1, k + 37, Blocks.dirt);
        world.setBlock(i + 6, j + 1, k + 38, Blocks.dirt);
        world.setBlock(i + 6, j + 1, k + 39, Blocks.dirt);
        world.setBlock(i + 6, j + 1, k + 40, Blocks.dirt);
        world.setBlock(i + 6, j + 1, k + 41, Blocks.dirt);
        world.setBlock(i + 6, j + 2, k + 30, Blocks.grass);
        world.setBlock(i + 6, j + 2, k + 31, Blocks.dirt);
        world.setBlock(i + 6, j + 2, k + 32, Blocks.dirt);
        world.setBlock(i + 6, j + 2, k + 33, Blocks.dirt);
        world.setBlock(i + 6, j + 2, k + 34, Blocks.dirt);
        world.setBlock(i + 6, j + 2, k + 35, Blocks.dirt);
        world.setBlock(i + 6, j + 2, k + 36, Blocks.dirt);
        world.setBlock(i + 6, j + 2, k + 37, Blocks.dirt);
        world.setBlock(i + 6, j + 2, k + 38, Blocks.dirt);
        world.setBlock(i + 6, j + 2, k + 39, Blocks.dirt);
        world.setBlock(i + 6, j + 2, k + 40, Blocks.dirt);
        world.setBlock(i + 6, j + 2, k + 41, Blocks.grass);
        world.setBlock(i + 6, j + 3, k + 31, Blocks.dirt);
        world.setBlock(i + 6, j + 3, k + 32, Blocks.dirt);
        world.setBlock(i + 6, j + 3, k + 33, Blocks.dirt);
        world.setBlock(i + 6, j + 3, k + 34, Blocks.dirt);
        world.setBlock(i + 6, j + 3, k + 35, Blocks.dirt);
        world.setBlock(i + 6, j + 3, k + 36, Blocks.dirt);
        world.setBlock(i + 6, j + 3, k + 37, Blocks.dirt);
        world.setBlock(i + 6, j + 3, k + 38, Blocks.dirt);
        world.setBlock(i + 6, j + 3, k + 39, Blocks.dirt);
        world.setBlock(i + 6, j + 3, k + 40, Blocks.dirt);
        world.setBlock(i + 6, j + 4, k + 31, Blocks.grass);
        world.setBlock(i + 6, j + 4, k + 32, Blocks.dirt);
        world.setBlock(i + 6, j + 4, k + 33, Blocks.dirt);
        world.setBlock(i + 6, j + 4, k + 34, Blocks.dirt);
        world.setBlock(i + 6, j + 4, k + 35, Blocks.dirt);
        world.setBlock(i + 6, j + 4, k + 36, Blocks.dirt);
        world.setBlock(i + 6, j + 4, k + 37, Blocks.dirt);
        world.setBlock(i + 6, j + 4, k + 38, Blocks.dirt);
        world.setBlock(i + 6, j + 4, k + 39, Blocks.dirt);
        world.setBlock(i + 6, j + 4, k + 40, Blocks.grass);
        world.setBlock(i + 6, j + 5, k + 32, Blocks.dirt);
        world.setBlock(i + 6, j + 5, k + 33, Blocks.dirt);
        world.setBlock(i + 6, j + 5, k + 34, Blocks.dirt);
        world.setBlock(i + 6, j + 5, k + 35, Blocks.dirt);
        world.setBlock(i + 6, j + 5, k + 36, Blocks.dirt);
        world.setBlock(i + 6, j + 5, k + 37, Blocks.dirt);
        world.setBlock(i + 6, j + 5, k + 38, Blocks.dirt);
        world.setBlock(i + 6, j + 5, k + 39, Blocks.dirt);
        world.setBlock(i + 6, j + 6, k + 32, Blocks.grass);
        world.setBlock(i + 6, j + 6, k + 33, Blocks.dirt);
        world.setBlock(i + 6, j + 6, k + 34, Blocks.dirt);
        world.setBlock(i + 6, j + 6, k + 35, Blocks.dirt);
        world.setBlock(i + 6, j + 6, k + 36, Blocks.dirt);
        world.setBlock(i + 6, j + 6, k + 37, Blocks.dirt);
        world.setBlock(i + 6, j + 6, k + 38, Blocks.dirt);
        world.setBlock(i + 6, j + 6, k + 39, Blocks.grass);
        world.setBlock(i + 6, j + 7, k + 33, Blocks.dirt);
        world.setBlock(i + 6, j + 7, k + 34, Blocks.dirt);
        world.setBlock(i + 6, j + 7, k + 35, Blocks.dirt);
        world.setBlock(i + 6, j + 7, k + 36, Blocks.dirt);
        world.setBlock(i + 6, j + 7, k + 37, Blocks.dirt);
        world.setBlock(i + 6, j + 7, k + 38, Blocks.dirt);
        world.setBlock(i + 6, j + 8, k + 33, Blocks.dirt);
        world.setBlock(i + 6, j + 8, k + 34, Blocks.dirt);
        world.setBlock(i + 6, j + 8, k + 35, Blocks.dirt);
        world.setBlock(i + 6, j + 8, k + 36, Blocks.dirt);
        world.setBlock(i + 6, j + 8, k + 37, Blocks.dirt);
        world.setBlock(i + 6, j + 8, k + 38, Blocks.dirt);
        world.setBlock(i + 6, j + 9, k + 33, Blocks.cobblestone);
        world.setBlock(i + 6, j + 9, k + 34, Blocks.cobblestone);
        world.setBlock(i + 6, j + 9, k + 35, Blocks.cobblestone);
        world.setBlock(i + 6, j + 9, k + 36, Blocks.cobblestone);
        world.setBlock(i + 6, j + 9, k + 37, Blocks.cobblestone);
        world.setBlock(i + 6, j + 9, k + 38, Blocks.cobblestone);
        world.setBlock(i + 6, j + 10, k + 33, Blocks.log);
        world.setBlock(i + 6, j + 10, k + 34, Blocks.planks);
        world.setBlock(i + 6, j + 10, k + 35, Blocks.planks);
        world.setBlock(i + 6, j + 10, k + 36, Blocks.planks);
        world.setBlock(i + 6, j + 10, k + 37, Blocks.planks);
        world.setBlock(i + 6, j + 10, k + 38, Blocks.log);
        world.setBlock(i + 6, j + 11, k + 33, Blocks.log);
        world.setBlock(i + 6, j + 11, k + 34, Blocks.planks);
        world.setBlock(i + 6, j + 11, k + 35, Blocks.glass_pane);
        world.setBlock(i + 6, j + 11, k + 36, Blocks.glass_pane);
        world.setBlock(i + 6, j + 11, k + 37, Blocks.planks);
        world.setBlock(i + 6, j + 11, k + 38, Blocks.log);
        world.setBlock(i + 6, j + 12, k + 33, Blocks.log);
        world.setBlock(i + 6, j + 12, k + 34, Blocks.planks);
        world.setBlock(i + 6, j + 12, k + 35, Blocks.glass_pane);
        world.setBlock(i + 6, j + 12, k + 36, Blocks.glass_pane);
        world.setBlock(i + 6, j + 12, k + 37, Blocks.planks);
        world.setBlock(i + 6, j + 12, k + 38, Blocks.log);
        world.setBlock(i + 6, j + 13, k + 33, Blocks.log);
        world.setBlock(i + 6, j + 13, k + 34, Blocks.planks);
        world.setBlock(i + 6, j + 13, k + 35, Blocks.planks);
        world.setBlock(i + 6, j + 13, k + 36, Blocks.planks);
        world.setBlock(i + 6, j + 13, k + 37, Blocks.planks);
        world.setBlock(i + 6, j + 13, k + 38, Blocks.log);
        world.setBlock(i + 7, j, k, Blocks.grass);
        world.setBlock(i + 7, j, k + 1, Blocks.grass);
        world.setBlock(i + 7, j, k + 2, Blocks.grass);
        world.setBlock(i + 7, j, k + 3, Blocks.grass);
        world.setBlock(i + 7, j, k + 4, Blocks.grass);
        world.setBlock(i + 7, j, k + 5, Blocks.grass);
        world.setBlock(i + 7, j, k + 6, Blocks.grass);
        world.setBlock(i + 7, j, k + 7, Blocks.grass);
        world.setBlock(i + 7, j, k + 8, Blocks.grass);
        world.setBlock(i + 7, j, k + 9, Blocks.grass);
        world.setBlock(i + 7, j, k + 10, Blocks.grass);
        world.setBlock(i + 7, j, k + 11, Blocks.grass);
        world.setBlock(i + 7, j, k + 12, Blocks.grass);
        world.setBlock(i + 7, j, k + 13, Blocks.grass);
        world.setBlock(i + 7, j, k + 14, Blocks.grass);
        world.setBlock(i + 7, j, k + 25, Blocks.grass);
        world.setBlock(i + 7, j, k + 26, Blocks.grass);
        world.setBlock(i + 7, j, k + 27, Blocks.grass);
        world.setBlock(i + 7, j, k + 28, Blocks.grass);
        world.setBlock(i + 7, j, k + 29, Blocks.grass);
        world.setBlock(i + 7, j, k + 30, Blocks.dirt);
        world.setBlock(i + 7, j, k + 31, Blocks.dirt);
        world.setBlock(i + 7, j, k + 32, Blocks.dirt);
        world.setBlock(i + 7, j, k + 33, Blocks.dirt);
        world.setBlock(i + 7, j, k + 34, Blocks.dirt);
        world.setBlock(i + 7, j, k + 35, Blocks.dirt);
        world.setBlock(i + 7, j, k + 36, Blocks.dirt);
        world.setBlock(i + 7, j, k + 37, Blocks.dirt);
        world.setBlock(i + 7, j, k + 38, Blocks.dirt);
        world.setBlock(i + 7, j, k + 39, Blocks.dirt);
        world.setBlock(i + 7, j, k + 40, Blocks.dirt);
        world.setBlock(i + 7, j, k + 41, Blocks.dirt);
        world.setBlock(i + 7, j, k + 42, Blocks.grass);
        world.setBlock(i + 7, j + 1, k + 30, Blocks.dirt);
        world.setBlock(i + 7, j + 1, k + 31, Blocks.dirt);
        world.setBlock(i + 7, j + 1, k + 32, Blocks.dirt);
        world.setBlock(i + 7, j + 1, k + 33, Blocks.dirt);
        world.setBlock(i + 7, j + 1, k + 34, Blocks.dirt);
        world.setBlock(i + 7, j + 1, k + 35, Blocks.dirt);
        world.setBlock(i + 7, j + 1, k + 36, Blocks.dirt);
        world.setBlock(i + 7, j + 1, k + 37, Blocks.dirt);
        world.setBlock(i + 7, j + 1, k + 38, Blocks.dirt);
        world.setBlock(i + 7, j + 1, k + 39, Blocks.dirt);
        world.setBlock(i + 7, j + 1, k + 40, Blocks.dirt);
        world.setBlock(i + 7, j + 1, k + 41, Blocks.dirt);
        world.setBlock(i + 7, j + 2, k + 30, Blocks.grass);
        world.setBlock(i + 7, j + 2, k + 31, Blocks.dirt);
        world.setBlock(i + 7, j + 2, k + 32, Blocks.dirt);
        world.setBlock(i + 7, j + 2, k + 33, Blocks.dirt);
        world.setBlock(i + 7, j + 2, k + 34, Blocks.dirt);
        world.setBlock(i + 7, j + 2, k + 35, Blocks.dirt);
        world.setBlock(i + 7, j + 2, k + 36, Blocks.dirt);
        world.setBlock(i + 7, j + 2, k + 37, Blocks.dirt);
        world.setBlock(i + 7, j + 2, k + 38, Blocks.dirt);
        world.setBlock(i + 7, j + 2, k + 39, Blocks.dirt);
        world.setBlock(i + 7, j + 2, k + 40, Blocks.dirt);
        world.setBlock(i + 7, j + 2, k + 41, Blocks.grass);
        world.setBlock(i + 7, j + 3, k + 31, Blocks.dirt);
        world.setBlock(i + 7, j + 3, k + 32, Blocks.dirt);
        world.setBlock(i + 7, j + 3, k + 33, Blocks.dirt);
        world.setBlock(i + 7, j + 3, k + 34, Blocks.dirt);
        world.setBlock(i + 7, j + 3, k + 35, Blocks.dirt);
        world.setBlock(i + 7, j + 3, k + 36, Blocks.dirt);
        world.setBlock(i + 7, j + 3, k + 37, Blocks.dirt);
        world.setBlock(i + 7, j + 3, k + 38, Blocks.dirt);
        world.setBlock(i + 7, j + 3, k + 39, Blocks.dirt);
        world.setBlock(i + 7, j + 3, k + 40, Blocks.dirt);
        world.setBlock(i + 7, j + 4, k + 31, Blocks.grass);
        world.setBlock(i + 7, j + 4, k + 32, Blocks.dirt);
        world.setBlock(i + 7, j + 4, k + 33, Blocks.dirt);
        world.setBlock(i + 7, j + 4, k + 34, Blocks.dirt);
        world.setBlock(i + 7, j + 4, k + 35, Blocks.dirt);
        world.setBlock(i + 7, j + 4, k + 36, Blocks.dirt);
        world.setBlock(i + 7, j + 4, k + 37, Blocks.dirt);
        world.setBlock(i + 7, j + 4, k + 38, Blocks.dirt);
        world.setBlock(i + 7, j + 4, k + 39, Blocks.dirt);
        world.setBlock(i + 7, j + 4, k + 40, Blocks.grass);
        world.setBlock(i + 7, j + 5, k + 32, Blocks.dirt);
        world.setBlock(i + 7, j + 5, k + 33, Blocks.dirt);
        world.setBlock(i + 7, j + 5, k + 34, Blocks.dirt);
        world.setBlock(i + 7, j + 5, k + 35, Blocks.dirt);
        world.setBlock(i + 7, j + 5, k + 36, Blocks.dirt);
        world.setBlock(i + 7, j + 5, k + 37, Blocks.dirt);
        world.setBlock(i + 7, j + 5, k + 38, Blocks.dirt);
        world.setBlock(i + 7, j + 5, k + 39, Blocks.dirt);
        world.setBlock(i + 7, j + 6, k + 32, Blocks.grass);
        world.setBlock(i + 7, j + 6, k + 33, Blocks.dirt);
        world.setBlock(i + 7, j + 6, k + 34, Blocks.dirt);
        world.setBlock(i + 7, j + 6, k + 35, Blocks.dirt);
        world.setBlock(i + 7, j + 6, k + 36, Blocks.dirt);
        world.setBlock(i + 7, j + 6, k + 37, Blocks.dirt);
        world.setBlock(i + 7, j + 6, k + 38, Blocks.dirt);
        world.setBlock(i + 7, j + 6, k + 39, Blocks.grass);
        world.setBlock(i + 7, j + 7, k + 33, Blocks.dirt);
        world.setBlock(i + 7, j + 7, k + 34, Blocks.dirt);
        world.setBlock(i + 7, j + 7, k + 35, Blocks.dirt);
        world.setBlock(i + 7, j + 7, k + 36, Blocks.dirt);
        world.setBlock(i + 7, j + 7, k + 37, Blocks.dirt);
        world.setBlock(i + 7, j + 7, k + 38, Blocks.dirt);
        world.setBlock(i + 7, j + 8, k + 33, Blocks.dirt);
        world.setBlock(i + 7, j + 8, k + 34, Blocks.dirt);
        world.setBlock(i + 7, j + 8, k + 35, Blocks.dirt);
        world.setBlock(i + 7, j + 8, k + 36, Blocks.dirt);
        world.setBlock(i + 7, j + 8, k + 37, Blocks.dirt);
        world.setBlock(i + 7, j + 8, k + 38, Blocks.dirt);
        world.setBlock(i + 7, j + 9, k + 33, Blocks.cobblestone);
        world.setBlock(i + 7, j + 9, k + 34, Blocks.cobblestone);
        world.setBlock(i + 7, j + 9, k + 35, Blocks.cobblestone);
        world.setBlock(i + 7, j + 9, k + 36, Blocks.cobblestone);
        world.setBlock(i + 7, j + 9, k + 37, Blocks.cobblestone);
        world.setBlock(i + 7, j + 9, k + 38, Blocks.cobblestone);
        world.setBlock(i + 7, j + 10, k + 33, Blocks.planks);
        world.setBlock(i + 7, j + 10, k + 34, Blocks.crafting_table);
        world.setBlock(i + 7, j + 10, k + 37, Blocks.bookshelf);
        world.setBlock(i + 7, j + 10, k + 38, Blocks.planks);
        world.setBlock(i + 7, j + 11, k + 33, Blocks.glass_pane);
        world.setBlock(i + 7, j + 11, k + 37, Blocks.bookshelf);
        world.setBlock(i + 7, j + 11, k + 38, Blocks.planks);
        world.setBlock(i + 7, j + 12, k + 33, Blocks.glass_pane);
        world.setBlock(i + 7, j + 12, k + 37, Blocks.bookshelf);
        world.setBlock(i + 7, j + 12, k + 38, Blocks.planks);
        world.setBlock(i + 7, j + 13, k + 33, Blocks.planks);
        world.setBlock(i + 7, j + 13, k + 37, Blocks.bookshelf);
        world.setBlock(i + 7, j + 13, k + 38, Blocks.planks);
        world.setBlock(i + 7, j + 14, k + 34, Blocks.log);
        world.setBlock(i + 7, j + 14, k + 35, Blocks.log);
        world.setBlock(i + 7, j + 14, k + 36, Blocks.log);
        world.setBlock(i + 7, j + 14, k + 37, Blocks.log);
        world.setBlock(i + 8, j, k, Blocks.grass);
        world.setBlock(i + 8, j, k + 1, Blocks.grass);
        world.setBlock(i + 8, j, k + 2, Blocks.grass);
        world.setBlock(i + 8, j, k + 3, Blocks.grass);
        world.setBlock(i + 8, j, k + 4, Blocks.grass);
        world.setBlock(i + 8, j, k + 5, Blocks.grass);
        world.setBlock(i + 8, j, k + 6, Blocks.grass);
        world.setBlock(i + 8, j, k + 7, Blocks.grass);
        world.setBlock(i + 8, j, k + 8, Blocks.grass);
        world.setBlock(i + 8, j, k + 9, Blocks.grass);
        world.setBlock(i + 8, j, k + 10, Blocks.grass);
        world.setBlock(i + 8, j, k + 11, Blocks.grass);
        world.setBlock(i + 8, j, k + 12, Blocks.grass);
        world.setBlock(i + 8, j, k + 13, Blocks.grass);
        world.setBlock(i + 8, j, k + 14, Blocks.grass);
        world.setBlock(i + 8, j, k + 25, Blocks.grass);
        world.setBlock(i + 8, j, k + 26, Blocks.grass);
        world.setBlock(i + 8, j, k + 27, Blocks.grass);
        world.setBlock(i + 8, j, k + 28, Blocks.grass);
        world.setBlock(i + 8, j, k + 29, Blocks.grass);
        world.setBlock(i + 8, j, k + 30, Blocks.dirt);
        world.setBlock(i + 8, j, k + 31, Blocks.dirt);
        world.setBlock(i + 8, j, k + 32, Blocks.dirt);
        world.setBlock(i + 8, j, k + 33, Blocks.dirt);
        world.setBlock(i + 8, j, k + 34, Blocks.dirt);
        world.setBlock(i + 8, j, k + 35, Blocks.dirt);
        world.setBlock(i + 8, j, k + 36, Blocks.dirt);
        world.setBlock(i + 8, j, k + 37, Blocks.dirt);
        world.setBlock(i + 8, j, k + 38, Blocks.dirt);
        world.setBlock(i + 8, j, k + 39, Blocks.dirt);
        world.setBlock(i + 8, j, k + 40, Blocks.dirt);
        world.setBlock(i + 8, j, k + 41, Blocks.dirt);
        world.setBlock(i + 8, j, k + 42, Blocks.grass);
        world.setBlock(i + 8, j + 1, k + 24, Blocks.fence);
        world.setBlock(i + 8, j + 1, k + 30, Blocks.dirt);
        world.setBlock(i + 8, j + 1, k + 31, Blocks.dirt);
        world.setBlock(i + 8, j + 1, k + 32, Blocks.dirt);
        world.setBlock(i + 8, j + 1, k + 33, Blocks.dirt);
        world.setBlock(i + 8, j + 1, k + 34, Blocks.dirt);
        world.setBlock(i + 8, j + 1, k + 35, Blocks.dirt);
        world.setBlock(i + 8, j + 1, k + 36, Blocks.dirt);
        world.setBlock(i + 8, j + 1, k + 37, Blocks.dirt);
        world.setBlock(i + 8, j + 1, k + 38, Blocks.dirt);
        world.setBlock(i + 8, j + 1, k + 39, Blocks.dirt);
        world.setBlock(i + 8, j + 1, k + 40, Blocks.dirt);
        world.setBlock(i + 8, j + 1, k + 41, Blocks.dirt);
        world.setBlock(i + 8, j + 2, k + 24, Blocks.fence);
        world.setBlock(i + 8, j + 2, k + 30, Blocks.grass);
        world.setBlock(i + 8, j + 2, k + 31, Blocks.dirt);
        world.setBlock(i + 8, j + 2, k + 32, Blocks.dirt);
        world.setBlock(i + 8, j + 2, k + 33, Blocks.dirt);
        world.setBlock(i + 8, j + 2, k + 34, Blocks.dirt);
        world.setBlock(i + 8, j + 2, k + 35, Blocks.dirt);
        world.setBlock(i + 8, j + 2, k + 36, Blocks.dirt);
        world.setBlock(i + 8, j + 2, k + 37, Blocks.dirt);
        world.setBlock(i + 8, j + 2, k + 38, Blocks.dirt);
        world.setBlock(i + 8, j + 2, k + 39, Blocks.dirt);
        world.setBlock(i + 8, j + 2, k + 40, Blocks.dirt);
        world.setBlock(i + 8, j + 2, k + 41, Blocks.grass);
        world.setBlock(i + 8, j + 3, k + 24, Blocks.glowstone);
        final EntityMoundTrader trader = new EntityMoundTrader(world);
        trader.setPosition((double)(i + 8), (double)(j + 3), (double)(k + 24));
        world.spawnEntityInWorld((Entity)trader);
        trader.onSpawnWithEgg((IEntityLivingData)null);
        trader.setPosition((double)(i + 8), (double)(j + 3), (double)(k + 24));
        world.setBlock(i + 8, j + 3, k + 31, Blocks.dirt);
        world.setBlock(i + 8, j + 3, k + 32, Blocks.dirt);
        world.setBlock(i + 8, j + 3, k + 33, Blocks.dirt);
        world.setBlock(i + 8, j + 3, k + 34, Blocks.dirt);
        world.setBlock(i + 8, j + 3, k + 35, Blocks.dirt);
        world.setBlock(i + 8, j + 3, k + 36, Blocks.dirt);
        world.setBlock(i + 8, j + 3, k + 37, Blocks.dirt);
        world.setBlock(i + 8, j + 3, k + 38, Blocks.dirt);
        world.setBlock(i + 8, j + 3, k + 39, Blocks.dirt);
        world.setBlock(i + 8, j + 3, k + 40, Blocks.dirt);
        world.setBlock(i + 8, j + 4, k + 31, Blocks.grass);
        world.setBlock(i + 8, j + 4, k + 32, Blocks.dirt);
        world.setBlock(i + 8, j + 4, k + 33, Blocks.dirt);
        world.setBlock(i + 8, j + 4, k + 34, Blocks.dirt);
        world.setBlock(i + 8, j + 4, k + 35, Blocks.dirt);
        world.setBlock(i + 8, j + 4, k + 36, Blocks.dirt);
        world.setBlock(i + 8, j + 4, k + 37, Blocks.dirt);
        world.setBlock(i + 8, j + 4, k + 38, Blocks.dirt);
        world.setBlock(i + 8, j + 4, k + 39, Blocks.dirt);
        world.setBlock(i + 8, j + 4, k + 40, Blocks.grass);
        world.setBlock(i + 8, j + 5, k + 32, Blocks.dirt);
        world.setBlock(i + 8, j + 5, k + 33, Blocks.dirt);
        world.setBlock(i + 8, j + 5, k + 34, Blocks.dirt);
        world.setBlock(i + 8, j + 5, k + 35, Blocks.dirt);
        world.setBlock(i + 8, j + 5, k + 36, Blocks.dirt);
        world.setBlock(i + 8, j + 5, k + 37, Blocks.dirt);
        world.setBlock(i + 8, j + 5, k + 38, Blocks.dirt);
        world.setBlock(i + 8, j + 5, k + 39, Blocks.dirt);
        world.setBlock(i + 8, j + 6, k + 32, Blocks.grass);
        world.setBlock(i + 8, j + 6, k + 33, Blocks.dirt);
        world.setBlock(i + 8, j + 6, k + 34, Blocks.dirt);
        world.setBlock(i + 8, j + 6, k + 35, Blocks.dirt);
        world.setBlock(i + 8, j + 6, k + 36, Blocks.dirt);
        world.setBlock(i + 8, j + 6, k + 37, Blocks.dirt);
        world.setBlock(i + 8, j + 6, k + 38, Blocks.dirt);
        world.setBlock(i + 8, j + 6, k + 39, Blocks.grass);
        world.setBlock(i + 8, j + 7, k + 33, Blocks.dirt);
        world.setBlock(i + 8, j + 7, k + 34, Blocks.dirt);
        world.setBlock(i + 8, j + 7, k + 35, Blocks.dirt);
        world.setBlock(i + 8, j + 7, k + 36, Blocks.dirt);
        world.setBlock(i + 8, j + 7, k + 37, Blocks.dirt);
        world.setBlock(i + 8, j + 7, k + 38, Blocks.dirt);
        world.setBlock(i + 8, j + 8, k + 33, Blocks.dirt);
        world.setBlock(i + 8, j + 8, k + 34, Blocks.dirt);
        world.setBlock(i + 8, j + 8, k + 35, Blocks.dirt);
        world.setBlock(i + 8, j + 8, k + 36, Blocks.dirt);
        world.setBlock(i + 8, j + 8, k + 37, Blocks.dirt);
        world.setBlock(i + 8, j + 8, k + 38, Blocks.dirt);
        world.setBlock(i + 8, j + 9, k + 33, Blocks.cobblestone);
        world.setBlock(i + 8, j + 9, k + 34, Blocks.cobblestone);
        world.setBlock(i + 8, j + 9, k + 35, Blocks.cobblestone);
        world.setBlock(i + 8, j + 9, k + 36, Blocks.cobblestone);
        world.setBlock(i + 8, j + 9, k + 37, Blocks.cobblestone);
        world.setBlock(i + 8, j + 9, k + 38, Blocks.cobblestone);
        world.setBlock(i + 8, j + 10, k + 33, Blocks.planks);
        world.setBlock(i + 8, j + 10, k + 38, Blocks.planks);
        world.setBlock(i + 8, j + 11, k + 33, Blocks.glass_pane);
        world.setBlock(i + 8, j + 11, k + 38, Blocks.glass_pane);
        world.setBlock(i + 8, j + 12, k + 33, Blocks.glass_pane);
        world.setBlock(i + 8, j + 12, k + 38, Blocks.glass_pane);
        world.setBlock(i + 8, j + 13, k + 33, Blocks.planks);
        world.setBlock(i + 8, j + 13, k + 38, Blocks.planks);
        world.setBlock(i + 8, j + 14, k + 34, Blocks.log);
        world.setBlock(i + 8, j + 14, k + 35, Blocks.log);
        world.setBlock(i + 8, j + 14, k + 36, Blocks.log);
        world.setBlock(i + 8, j + 14, k + 37, Blocks.log);
        world.setBlock(i + 9, j, k, Blocks.grass);
        world.setBlock(i + 9, j, k + 1, Blocks.grass);
        world.setBlock(i + 9, j, k + 2, Blocks.grass);
        world.setBlock(i + 9, j, k + 3, Blocks.grass);
        world.setBlock(i + 9, j, k + 4, Blocks.grass);
        world.setBlock(i + 9, j, k + 5, Blocks.grass);
        world.setBlock(i + 9, j, k + 6, Blocks.grass);
        world.setBlock(i + 9, j, k + 7, Blocks.grass);
        world.setBlock(i + 9, j, k + 8, Blocks.grass);
        world.setBlock(i + 9, j, k + 9, Blocks.grass);
        world.setBlock(i + 9, j, k + 10, Blocks.grass);
        world.setBlock(i + 9, j, k + 11, Blocks.grass);
        world.setBlock(i + 9, j, k + 12, Blocks.grass);
        world.setBlock(i + 9, j, k + 13, Blocks.grass);
        world.setBlock(i + 9, j, k + 14, Blocks.grass);
        world.setBlock(i + 9, j, k + 25, Blocks.dirt);
        world.setBlock(i + 9, j, k + 26, Blocks.dirt);
        world.setBlock(i + 9, j, k + 27, Blocks.dirt);
        world.setBlock(i + 9, j, k + 28, Blocks.dirt);
        world.setBlock(i + 9, j, k + 29, Blocks.dirt);
        world.setBlock(i + 9, j, k + 30, Blocks.dirt);
        world.setBlock(i + 9, j, k + 31, Blocks.dirt);
        world.setBlock(i + 9, j, k + 32, Blocks.dirt);
        world.setBlock(i + 9, j, k + 33, Blocks.dirt);
        world.setBlock(i + 9, j, k + 34, Blocks.dirt);
        world.setBlock(i + 9, j, k + 35, Blocks.dirt);
        world.setBlock(i + 9, j, k + 36, Blocks.dirt);
        world.setBlock(i + 9, j, k + 37, Blocks.dirt);
        world.setBlock(i + 9, j, k + 38, Blocks.dirt);
        world.setBlock(i + 9, j, k + 39, Blocks.dirt);
        world.setBlock(i + 9, j, k + 40, Blocks.dirt);
        world.setBlock(i + 9, j, k + 41, Blocks.dirt);
        world.setBlock(i + 9, j, k + 42, Blocks.grass);
        world.setBlock(i + 9, j + 1, k + 30, Blocks.dirt);
        world.setBlock(i + 9, j + 1, k + 31, Blocks.dirt);
        world.setBlock(i + 9, j + 1, k + 32, Blocks.dirt);
        world.setBlock(i + 9, j + 1, k + 33, Blocks.dirt);
        world.setBlock(i + 9, j + 1, k + 34, Blocks.dirt);
        world.setBlock(i + 9, j + 1, k + 35, Blocks.dirt);
        world.setBlock(i + 9, j + 1, k + 36, Blocks.dirt);
        world.setBlock(i + 9, j + 1, k + 37, Blocks.dirt);
        world.setBlock(i + 9, j + 1, k + 38, Blocks.dirt);
        world.setBlock(i + 9, j + 1, k + 39, Blocks.dirt);
        world.setBlock(i + 9, j + 1, k + 40, Blocks.dirt);
        world.setBlock(i + 9, j + 1, k + 41, Blocks.dirt);
        world.setBlock(i + 9, j + 2, k + 30, Blocks.dirt);
        world.setBlock(i + 9, j + 2, k + 31, Blocks.dirt);
        world.setBlock(i + 9, j + 2, k + 32, Blocks.dirt);
        world.setBlock(i + 9, j + 2, k + 33, Blocks.dirt);
        world.setBlock(i + 9, j + 2, k + 34, Blocks.dirt);
        world.setBlock(i + 9, j + 2, k + 35, Blocks.dirt);
        world.setBlock(i + 9, j + 2, k + 36, Blocks.dirt);
        world.setBlock(i + 9, j + 2, k + 37, Blocks.dirt);
        world.setBlock(i + 9, j + 2, k + 38, Blocks.dirt);
        world.setBlock(i + 9, j + 2, k + 39, Blocks.dirt);
        world.setBlock(i + 9, j + 2, k + 40, Blocks.dirt);
        world.setBlock(i + 9, j + 2, k + 41, Blocks.grass);
        world.setBlock(i + 9, j + 3, k + 31, Blocks.dirt);
        world.setBlock(i + 9, j + 3, k + 32, Blocks.dirt);
        world.setBlock(i + 9, j + 3, k + 33, Blocks.dirt);
        world.setBlock(i + 9, j + 3, k + 34, Blocks.dirt);
        world.setBlock(i + 9, j + 3, k + 35, Blocks.dirt);
        world.setBlock(i + 9, j + 3, k + 36, Blocks.dirt);
        world.setBlock(i + 9, j + 3, k + 37, Blocks.dirt);
        world.setBlock(i + 9, j + 3, k + 38, Blocks.dirt);
        world.setBlock(i + 9, j + 3, k + 39, Blocks.dirt);
        world.setBlock(i + 9, j + 3, k + 40, Blocks.dirt);
        world.setBlock(i + 9, j + 4, k + 31, Blocks.dirt);
        world.setBlock(i + 9, j + 4, k + 32, Blocks.dirt);
        world.setBlock(i + 9, j + 4, k + 33, Blocks.dirt);
        world.setBlock(i + 9, j + 4, k + 34, Blocks.dirt);
        world.setBlock(i + 9, j + 4, k + 35, Blocks.dirt);
        world.setBlock(i + 9, j + 4, k + 36, Blocks.dirt);
        world.setBlock(i + 9, j + 4, k + 37, Blocks.dirt);
        world.setBlock(i + 9, j + 4, k + 38, Blocks.dirt);
        world.setBlock(i + 9, j + 4, k + 39, Blocks.dirt);
        world.setBlock(i + 9, j + 4, k + 40, Blocks.grass);
        world.setBlock(i + 9, j + 5, k + 32, Blocks.dirt);
        world.setBlock(i + 9, j + 5, k + 33, Blocks.dirt);
        world.setBlock(i + 9, j + 5, k + 34, Blocks.dirt);
        world.setBlock(i + 9, j + 5, k + 35, Blocks.dirt);
        world.setBlock(i + 9, j + 5, k + 36, Blocks.dirt);
        world.setBlock(i + 9, j + 5, k + 37, Blocks.dirt);
        world.setBlock(i + 9, j + 5, k + 38, Blocks.dirt);
        world.setBlock(i + 9, j + 5, k + 39, Blocks.dirt);
        world.setBlock(i + 9, j + 6, k + 32, Blocks.dirt);
        world.setBlock(i + 9, j + 6, k + 33, Blocks.dirt);
        world.setBlock(i + 9, j + 6, k + 34, Blocks.dirt);
        world.setBlock(i + 9, j + 6, k + 35, Blocks.dirt);
        world.setBlock(i + 9, j + 6, k + 36, Blocks.dirt);
        world.setBlock(i + 9, j + 6, k + 37, Blocks.dirt);
        world.setBlock(i + 9, j + 6, k + 38, Blocks.dirt);
        world.setBlock(i + 9, j + 6, k + 39, Blocks.grass);
        world.setBlock(i + 9, j + 7, k + 33, Blocks.dirt);
        world.setBlock(i + 9, j + 7, k + 34, Blocks.dirt);
        world.setBlock(i + 9, j + 7, k + 35, Blocks.dirt);
        world.setBlock(i + 9, j + 7, k + 36, Blocks.dirt);
        world.setBlock(i + 9, j + 7, k + 37, Blocks.dirt);
        world.setBlock(i + 9, j + 7, k + 38, Blocks.dirt);
        world.setBlock(i + 9, j + 8, k + 33, Blocks.dirt);
        world.setBlock(i + 9, j + 8, k + 34, Blocks.dirt);
        world.setBlock(i + 9, j + 8, k + 35, Blocks.dirt);
        world.setBlock(i + 9, j + 8, k + 36, Blocks.dirt);
        world.setBlock(i + 9, j + 8, k + 37, Blocks.dirt);
        world.setBlock(i + 9, j + 8, k + 38, Blocks.dirt);
        world.setBlock(i + 9, j + 9, k + 33, Blocks.cobblestone);
        world.setBlock(i + 9, j + 9, k + 34, Blocks.cobblestone);
        world.setBlock(i + 9, j + 9, k + 35, Blocks.cobblestone);
        world.setBlock(i + 9, j + 9, k + 36, Blocks.cobblestone);
        world.setBlock(i + 9, j + 9, k + 37, Blocks.cobblestone);
        world.setBlock(i + 9, j + 9, k + 38, Blocks.cobblestone);
        world.setBlock(i + 9, j + 10, k + 33, Blocks.log);
        world.setBlock(i + 9, j + 10, k + 38, Blocks.planks);
        world.setBlock(i + 9, j + 11, k + 33, Blocks.log);
        world.setBlock(i + 9, j + 11, k + 38, Blocks.glass_pane);
        world.setBlock(i + 9, j + 12, k + 33, Blocks.log);
        world.setBlock(i + 9, j + 12, k + 38, Blocks.glass_pane);
        world.setBlock(i + 9, j + 13, k + 33, Blocks.log);
        world.setBlock(i + 9, j + 13, k + 38, Blocks.planks);
        world.setBlock(i + 9, j + 14, k + 34, Blocks.log);
        world.setBlock(i + 9, j + 14, k + 35, Blocks.log);
        world.setBlock(i + 9, j + 14, k + 36, Blocks.log);
        world.setBlock(i + 9, j + 14, k + 37, Blocks.log);
        world.setBlock(i + 10, j, k, Blocks.grass);
        world.setBlock(i + 10, j, k + 1, Blocks.grass);
        world.setBlock(i + 10, j, k + 2, Blocks.grass);
        world.setBlock(i + 10, j, k + 3, Blocks.grass);
        world.setBlock(i + 10, j, k + 4, Blocks.grass);
        world.setBlock(i + 10, j, k + 5, Blocks.grass);
        world.setBlock(i + 10, j, k + 6, Blocks.grass);
        world.setBlock(i + 10, j, k + 7, Blocks.grass);
        world.setBlock(i + 10, j, k + 8, Blocks.grass);
        world.setBlock(i + 10, j, k + 9, Blocks.grass);
        world.setBlock(i + 10, j, k + 10, Blocks.grass);
        world.setBlock(i + 10, j, k + 11, Blocks.grass);
        world.setBlock(i + 10, j, k + 12, Blocks.grass);
        world.setBlock(i + 10, j, k + 13, Blocks.grass);
        world.setBlock(i + 10, j, k + 14, Blocks.grass);
        world.setBlock(i + 10, j, k + 25, Blocks.dirt);
        world.setBlock(i + 10, j, k + 26, Blocks.dirt);
        world.setBlock(i + 10, j, k + 27, Blocks.dirt);
        world.setBlock(i + 10, j, k + 28, Blocks.dirt);
        world.setBlock(i + 10, j, k + 29, Blocks.dirt);
        world.setBlock(i + 10, j, k + 30, Blocks.dirt);
        world.setBlock(i + 10, j, k + 31, Blocks.dirt);
        world.setBlock(i + 10, j, k + 32, Blocks.dirt);
        world.setBlock(i + 10, j, k + 33, Blocks.dirt);
        world.setBlock(i + 10, j, k + 34, Blocks.dirt);
        world.setBlock(i + 10, j, k + 35, Blocks.dirt);
        world.setBlock(i + 10, j, k + 36, Blocks.dirt);
        world.setBlock(i + 10, j, k + 37, Blocks.dirt);
        world.setBlock(i + 10, j, k + 38, Blocks.dirt);
        world.setBlock(i + 10, j, k + 39, Blocks.dirt);
        world.setBlock(i + 10, j, k + 40, Blocks.dirt);
        world.setBlock(i + 10, j, k + 41, Blocks.dirt);
        world.setBlock(i + 10, j, k + 42, Blocks.grass);
        world.setBlock(i + 10, j + 1, k + 24, Blocks.stone_brick_stairs, 2, 0);
        world.setBlock(i + 10, j + 1, k + 30, Blocks.dirt);
        world.setBlock(i + 10, j + 1, k + 31, Blocks.dirt);
        world.setBlock(i + 10, j + 1, k + 32, Blocks.dirt);
        world.setBlock(i + 10, j + 1, k + 33, Blocks.dirt);
        world.setBlock(i + 10, j + 1, k + 34, Blocks.dirt);
        world.setBlock(i + 10, j + 1, k + 35, Blocks.dirt);
        world.setBlock(i + 10, j + 1, k + 36, Blocks.dirt);
        world.setBlock(i + 10, j + 1, k + 37, Blocks.dirt);
        world.setBlock(i + 10, j + 1, k + 38, Blocks.dirt);
        world.setBlock(i + 10, j + 1, k + 39, Blocks.dirt);
        world.setBlock(i + 10, j + 1, k + 40, Blocks.dirt);
        world.setBlock(i + 10, j + 1, k + 41, Blocks.dirt);
        world.setBlock(i + 10, j + 2, k + 25, Blocks.stone_brick_stairs, 2, 0);
        world.setBlock(i + 10, j + 2, k + 30, Blocks.dirt);
        world.setBlock(i + 10, j + 2, k + 31, Blocks.dirt);
        world.setBlock(i + 10, j + 2, k + 32, Blocks.dirt);
        world.setBlock(i + 10, j + 2, k + 33, Blocks.dirt);
        world.setBlock(i + 10, j + 2, k + 34, Blocks.dirt);
        world.setBlock(i + 10, j + 2, k + 35, Blocks.dirt);
        world.setBlock(i + 10, j + 2, k + 36, Blocks.dirt);
        world.setBlock(i + 10, j + 2, k + 37, Blocks.dirt);
        world.setBlock(i + 10, j + 2, k + 38, Blocks.dirt);
        world.setBlock(i + 10, j + 2, k + 39, Blocks.dirt);
        world.setBlock(i + 10, j + 2, k + 40, Blocks.dirt);
        world.setBlock(i + 10, j + 2, k + 41, Blocks.grass);
        world.setBlock(i + 10, j + 3, k + 26, Blocks.stone_brick_stairs, 2, 0);
        world.setBlock(i + 10, j + 3, k + 31, Blocks.dirt);
        world.setBlock(i + 10, j + 3, k + 32, Blocks.dirt);
        world.setBlock(i + 10, j + 3, k + 33, Blocks.dirt);
        world.setBlock(i + 10, j + 3, k + 34, Blocks.dirt);
        world.setBlock(i + 10, j + 3, k + 35, Blocks.dirt);
        world.setBlock(i + 10, j + 3, k + 36, Blocks.dirt);
        world.setBlock(i + 10, j + 3, k + 37, Blocks.dirt);
        world.setBlock(i + 10, j + 3, k + 38, Blocks.dirt);
        world.setBlock(i + 10, j + 3, k + 39, Blocks.dirt);
        world.setBlock(i + 10, j + 3, k + 40, Blocks.dirt);
        world.setBlock(i + 10, j + 4, k + 27, Blocks.stone_brick_stairs, 2, 0);
        world.setBlock(i + 10, j + 4, k + 31, Blocks.dirt);
        world.setBlock(i + 10, j + 4, k + 32, Blocks.dirt);
        world.setBlock(i + 10, j + 4, k + 33, Blocks.dirt);
        world.setBlock(i + 10, j + 4, k + 34, Blocks.dirt);
        world.setBlock(i + 10, j + 4, k + 35, Blocks.dirt);
        world.setBlock(i + 10, j + 4, k + 36, Blocks.dirt);
        world.setBlock(i + 10, j + 4, k + 37, Blocks.dirt);
        world.setBlock(i + 10, j + 4, k + 38, Blocks.dirt);
        world.setBlock(i + 10, j + 4, k + 39, Blocks.dirt);
        world.setBlock(i + 10, j + 4, k + 40, Blocks.grass);
        world.setBlock(i + 10, j + 5, k + 28, Blocks.stone_brick_stairs, 2, 0);
        world.setBlock(i + 10, j + 5, k + 32, Blocks.dirt);
        world.setBlock(i + 10, j + 5, k + 33, Blocks.dirt);
        world.setBlock(i + 10, j + 5, k + 34, Blocks.dirt);
        world.setBlock(i + 10, j + 5, k + 35, Blocks.dirt);
        world.setBlock(i + 10, j + 5, k + 36, Blocks.dirt);
        world.setBlock(i + 10, j + 5, k + 37, Blocks.dirt);
        world.setBlock(i + 10, j + 5, k + 38, Blocks.dirt);
        world.setBlock(i + 10, j + 5, k + 39, Blocks.dirt);
        world.setBlock(i + 10, j + 6, k + 29, Blocks.stone_brick_stairs, 2, 0);
        world.setBlock(i + 10, j + 6, k + 32, Blocks.dirt);
        world.setBlock(i + 10, j + 6, k + 33, Blocks.dirt);
        world.setBlock(i + 10, j + 6, k + 34, Blocks.dirt);
        world.setBlock(i + 10, j + 6, k + 35, Blocks.dirt);
        world.setBlock(i + 10, j + 6, k + 36, Blocks.dirt);
        world.setBlock(i + 10, j + 6, k + 37, Blocks.dirt);
        world.setBlock(i + 10, j + 6, k + 38, Blocks.dirt);
        world.setBlock(i + 10, j + 6, k + 39, Blocks.grass);
        world.setBlock(i + 10, j + 7, k + 30, Blocks.stone_brick_stairs, 2, 0);
        world.setBlock(i + 10, j + 7, k + 33, Blocks.dirt);
        world.setBlock(i + 10, j + 7, k + 34, Blocks.dirt);
        world.setBlock(i + 10, j + 7, k + 35, Blocks.dirt);
        world.setBlock(i + 10, j + 7, k + 36, Blocks.dirt);
        world.setBlock(i + 10, j + 7, k + 37, Blocks.dirt);
        world.setBlock(i + 10, j + 7, k + 38, Blocks.dirt);
        world.setBlock(i + 10, j + 8, k + 31, Blocks.stone_brick_stairs, 2, 0);
        world.setBlock(i + 10, j + 8, k + 33, Blocks.dirt);
        world.setBlock(i + 10, j + 8, k + 34, Blocks.dirt);
        world.setBlock(i + 10, j + 8, k + 35, Blocks.dirt);
        world.setBlock(i + 10, j + 8, k + 36, Blocks.dirt);
        world.setBlock(i + 10, j + 8, k + 37, Blocks.dirt);
        world.setBlock(i + 10, j + 8, k + 38, Blocks.dirt);
        world.setBlock(i + 10, j + 9, k + 32, Blocks.stone_brick_stairs, 2, 0);
        world.setBlock(i + 10, j + 9, k + 33, Blocks.cobblestone);
        world.setBlock(i + 10, j + 9, k + 34, Blocks.cobblestone);
        world.setBlock(i + 10, j + 9, k + 35, Blocks.cobblestone);
        world.setBlock(i + 10, j + 9, k + 36, Blocks.cobblestone);
        world.setBlock(i + 10, j + 9, k + 37, Blocks.cobblestone);
        world.setBlock(i + 10, j + 9, k + 38, Blocks.cobblestone);
        world.setBlock(i + 10, j + 10, k + 37, Blocks.fence);
        world.setBlock(i + 10, j + 10, k + 38, Blocks.planks);
        world.setBlock(i + 10, j + 11, k + 38, Blocks.planks);
        world.setBlock(i + 10, j + 12, k + 33, Blocks.planks);
        world.setBlock(i + 10, j + 12, k + 38, Blocks.planks);
        world.setBlock(i + 10, j + 13, k + 33, Blocks.planks);
        world.setBlock(i + 10, j + 13, k + 38, Blocks.planks);
        world.setBlock(i + 10, j + 14, k + 34, Blocks.log);
        world.setBlock(i + 10, j + 14, k + 35, Blocks.log);
        world.setBlock(i + 10, j + 14, k + 36, Blocks.log);
        world.setBlock(i + 10, j + 14, k + 37, Blocks.log);
        world.setBlock(i + 11, j, k, Blocks.grass);
        world.setBlock(i + 11, j, k + 1, Blocks.grass);
        world.setBlock(i + 11, j, k + 2, Blocks.grass);
        world.setBlock(i + 11, j, k + 3, Blocks.grass);
        world.setBlock(i + 11, j, k + 4, Blocks.grass);
        world.setBlock(i + 11, j, k + 5, Blocks.grass);
        world.setBlock(i + 11, j, k + 6, Blocks.grass);
        world.setBlock(i + 11, j, k + 7, Blocks.grass);
        world.setBlock(i + 11, j, k + 8, Blocks.grass);
        world.setBlock(i + 11, j, k + 9, Blocks.grass);
        world.setBlock(i + 11, j, k + 10, Blocks.grass);
        world.setBlock(i + 11, j, k + 11, Blocks.grass);
        world.setBlock(i + 11, j, k + 12, Blocks.grass);
        world.setBlock(i + 11, j, k + 13, Blocks.grass);
        world.setBlock(i + 11, j, k + 14, Blocks.grass);
        world.setBlock(i + 11, j, k + 25, Blocks.dirt);
        world.setBlock(i + 11, j, k + 26, Blocks.dirt);
        world.setBlock(i + 11, j, k + 27, Blocks.dirt);
        world.setBlock(i + 11, j, k + 28, Blocks.dirt);
        world.setBlock(i + 11, j, k + 29, Blocks.dirt);
        world.setBlock(i + 11, j, k + 30, Blocks.dirt);
        world.setBlock(i + 11, j, k + 31, Blocks.dirt);
        world.setBlock(i + 11, j, k + 32, Blocks.dirt);
        world.setBlock(i + 11, j, k + 33, Blocks.dirt);
        world.setBlock(i + 11, j, k + 34, Blocks.dirt);
        world.setBlock(i + 11, j, k + 35, Blocks.dirt);
        world.setBlock(i + 11, j, k + 36, Blocks.dirt);
        world.setBlock(i + 11, j, k + 37, Blocks.dirt);
        world.setBlock(i + 11, j, k + 38, Blocks.dirt);
        world.setBlock(i + 11, j, k + 39, Blocks.dirt);
        world.setBlock(i + 11, j, k + 40, Blocks.dirt);
        world.setBlock(i + 11, j, k + 41, Blocks.dirt);
        world.setBlock(i + 11, j, k + 42, Blocks.grass);
        world.setBlock(i + 11, j + 1, k + 24, Blocks.stone_brick_stairs, 2, 0);
        world.setBlock(i + 11, j + 1, k + 30, Blocks.dirt);
        world.setBlock(i + 11, j + 1, k + 31, Blocks.dirt);
        world.setBlock(i + 11, j + 1, k + 32, Blocks.dirt);
        world.setBlock(i + 11, j + 1, k + 33, Blocks.dirt);
        world.setBlock(i + 11, j + 1, k + 34, Blocks.dirt);
        world.setBlock(i + 11, j + 1, k + 35, Blocks.dirt);
        world.setBlock(i + 11, j + 1, k + 36, Blocks.dirt);
        world.setBlock(i + 11, j + 1, k + 37, Blocks.dirt);
        world.setBlock(i + 11, j + 1, k + 38, Blocks.dirt);
        world.setBlock(i + 11, j + 1, k + 39, Blocks.dirt);
        world.setBlock(i + 11, j + 1, k + 40, Blocks.dirt);
        world.setBlock(i + 11, j + 1, k + 41, Blocks.dirt);
        world.setBlock(i + 11, j + 2, k + 25, Blocks.stone_brick_stairs, 2, 0);
        world.setBlock(i + 11, j + 2, k + 30, Blocks.dirt);
        world.setBlock(i + 11, j + 2, k + 31, Blocks.dirt);
        world.setBlock(i + 11, j + 2, k + 32, Blocks.dirt);
        world.setBlock(i + 11, j + 2, k + 33, Blocks.dirt);
        world.setBlock(i + 11, j + 2, k + 34, Blocks.dirt);
        world.setBlock(i + 11, j + 2, k + 35, Blocks.dirt);
        world.setBlock(i + 11, j + 2, k + 36, Blocks.dirt);
        world.setBlock(i + 11, j + 2, k + 37, Blocks.dirt);
        world.setBlock(i + 11, j + 2, k + 38, Blocks.dirt);
        world.setBlock(i + 11, j + 2, k + 39, Blocks.dirt);
        world.setBlock(i + 11, j + 2, k + 40, Blocks.dirt);
        world.setBlock(i + 11, j + 2, k + 41, Blocks.grass);
        world.setBlock(i + 11, j + 3, k + 26, Blocks.stone_brick_stairs, 2, 0);
        world.setBlock(i + 11, j + 3, k + 31, Blocks.dirt);
        world.setBlock(i + 11, j + 3, k + 32, Blocks.dirt);
        world.setBlock(i + 11, j + 3, k + 33, Blocks.dirt);
        world.setBlock(i + 11, j + 3, k + 34, Blocks.dirt);
        world.setBlock(i + 11, j + 3, k + 35, Blocks.dirt);
        world.setBlock(i + 11, j + 3, k + 36, Blocks.dirt);
        world.setBlock(i + 11, j + 3, k + 37, Blocks.dirt);
        world.setBlock(i + 11, j + 3, k + 38, Blocks.dirt);
        world.setBlock(i + 11, j + 3, k + 39, Blocks.dirt);
        world.setBlock(i + 11, j + 3, k + 40, Blocks.dirt);
        world.setBlock(i + 11, j + 4, k + 27, Blocks.stone_brick_stairs, 2, 0);
        world.setBlock(i + 11, j + 4, k + 31, Blocks.dirt);
        world.setBlock(i + 11, j + 4, k + 32, Blocks.dirt);
        world.setBlock(i + 11, j + 4, k + 33, Blocks.dirt);
        world.setBlock(i + 11, j + 4, k + 34, Blocks.dirt);
        world.setBlock(i + 11, j + 4, k + 35, Blocks.dirt);
        world.setBlock(i + 11, j + 4, k + 36, Blocks.dirt);
        world.setBlock(i + 11, j + 4, k + 37, Blocks.dirt);
        world.setBlock(i + 11, j + 4, k + 38, Blocks.dirt);
        world.setBlock(i + 11, j + 4, k + 39, Blocks.dirt);
        world.setBlock(i + 11, j + 4, k + 40, Blocks.grass);
        world.setBlock(i + 11, j + 5, k + 28, Blocks.stone_brick_stairs, 2, 0);
        world.setBlock(i + 11, j + 5, k + 32, Blocks.dirt);
        world.setBlock(i + 11, j + 5, k + 33, Blocks.dirt);
        world.setBlock(i + 11, j + 5, k + 34, Blocks.dirt);
        world.setBlock(i + 11, j + 5, k + 35, Blocks.dirt);
        world.setBlock(i + 11, j + 5, k + 36, Blocks.dirt);
        world.setBlock(i + 11, j + 5, k + 37, Blocks.dirt);
        world.setBlock(i + 11, j + 5, k + 38, Blocks.dirt);
        world.setBlock(i + 11, j + 5, k + 39, Blocks.dirt);
        world.setBlock(i + 11, j + 6, k + 29, Blocks.stone_brick_stairs, 2, 0);
        world.setBlock(i + 11, j + 6, k + 32, Blocks.dirt);
        world.setBlock(i + 11, j + 6, k + 33, Blocks.dirt);
        world.setBlock(i + 11, j + 6, k + 34, Blocks.dirt);
        world.setBlock(i + 11, j + 6, k + 35, Blocks.dirt);
        world.setBlock(i + 11, j + 6, k + 36, Blocks.dirt);
        world.setBlock(i + 11, j + 6, k + 37, Blocks.dirt);
        world.setBlock(i + 11, j + 6, k + 38, Blocks.dirt);
        world.setBlock(i + 11, j + 6, k + 39, Blocks.grass);
        world.setBlock(i + 11, j + 7, k + 30, Blocks.stone_brick_stairs, 2, 0);
        world.setBlock(i + 11, j + 7, k + 33, Blocks.dirt);
        world.setBlock(i + 11, j + 7, k + 34, Blocks.dirt);
        world.setBlock(i + 11, j + 7, k + 35, Blocks.dirt);
        world.setBlock(i + 11, j + 7, k + 36, Blocks.dirt);
        world.setBlock(i + 11, j + 7, k + 37, Blocks.dirt);
        world.setBlock(i + 11, j + 7, k + 38, Blocks.dirt);
        world.setBlock(i + 11, j + 8, k + 31, Blocks.stone_brick_stairs, 2, 0);
        world.setBlock(i + 11, j + 8, k + 33, Blocks.dirt);
        world.setBlock(i + 11, j + 8, k + 34, Blocks.dirt);
        world.setBlock(i + 11, j + 8, k + 35, Blocks.dirt);
        world.setBlock(i + 11, j + 8, k + 36, Blocks.dirt);
        world.setBlock(i + 11, j + 8, k + 37, Blocks.dirt);
        world.setBlock(i + 11, j + 8, k + 38, Blocks.dirt);
        world.setBlock(i + 11, j + 9, k + 32, Blocks.stone_brick_stairs, 2, 0);
        world.setBlock(i + 11, j + 9, k + 33, Blocks.cobblestone);
        world.setBlock(i + 11, j + 9, k + 34, Blocks.cobblestone);
        world.setBlock(i + 11, j + 9, k + 35, Blocks.cobblestone);
        world.setBlock(i + 11, j + 9, k + 36, Blocks.cobblestone);
        world.setBlock(i + 11, j + 9, k + 37, Blocks.cobblestone);
        world.setBlock(i + 11, j + 9, k + 38, Blocks.cobblestone);
        world.setBlock(i + 11, j + 10, k + 37, Blocks.fence);
        world.setBlock(i + 11, j + 10, k + 38, Blocks.planks);
        world.setBlock(i + 11, j + 11, k + 38, Blocks.planks);
        world.setBlock(i + 11, j + 12, k + 33, Blocks.planks);
        world.setBlock(i + 11, j + 12, k + 38, Blocks.planks);
        world.setBlock(i + 11, j + 13, k + 33, Blocks.planks);
        world.setBlock(i + 11, j + 13, k + 38, Blocks.planks);
        world.setBlock(i + 11, j + 14, k + 34, Blocks.log);
        world.setBlock(i + 11, j + 14, k + 35, Blocks.log);
        world.setBlock(i + 11, j + 14, k + 36, Blocks.log);
        world.setBlock(i + 11, j + 14, k + 37, Blocks.log);
        world.setBlock(i + 12, j, k, Blocks.grass);
        world.setBlock(i + 12, j, k + 1, Blocks.grass);
        world.setBlock(i + 12, j, k + 2, Blocks.grass);
        world.setBlock(i + 12, j, k + 3, Blocks.grass);
        world.setBlock(i + 12, j, k + 4, Blocks.grass);
        world.setBlock(i + 12, j, k + 5, Blocks.grass);
        world.setBlock(i + 12, j, k + 6, Blocks.grass);
        world.setBlock(i + 12, j, k + 7, Blocks.grass);
        world.setBlock(i + 12, j, k + 8, Blocks.grass);
        world.setBlock(i + 12, j, k + 9, Blocks.grass);
        world.setBlock(i + 12, j, k + 10, Blocks.grass);
        world.setBlock(i + 12, j, k + 11, Blocks.grass);
        world.setBlock(i + 12, j, k + 12, Blocks.grass);
        world.setBlock(i + 12, j, k + 13, Blocks.grass);
        world.setBlock(i + 12, j, k + 14, Blocks.grass);
        world.setBlock(i + 12, j, k + 25, Blocks.dirt);
        world.setBlock(i + 12, j, k + 26, Blocks.dirt);
        world.setBlock(i + 12, j, k + 27, Blocks.dirt);
        world.setBlock(i + 12, j, k + 28, Blocks.dirt);
        world.setBlock(i + 12, j, k + 29, Blocks.dirt);
        world.setBlock(i + 12, j, k + 30, Blocks.dirt);
        world.setBlock(i + 12, j, k + 31, Blocks.dirt);
        world.setBlock(i + 12, j, k + 32, Blocks.dirt);
        world.setBlock(i + 12, j, k + 33, Blocks.dirt);
        world.setBlock(i + 12, j, k + 34, Blocks.dirt);
        world.setBlock(i + 12, j, k + 35, Blocks.dirt);
        world.setBlock(i + 12, j, k + 36, Blocks.dirt);
        world.setBlock(i + 12, j, k + 37, Blocks.dirt);
        world.setBlock(i + 12, j, k + 38, Blocks.dirt);
        world.setBlock(i + 12, j, k + 39, Blocks.dirt);
        world.setBlock(i + 12, j, k + 40, Blocks.dirt);
        world.setBlock(i + 12, j, k + 41, Blocks.dirt);
        world.setBlock(i + 12, j, k + 42, Blocks.grass);
        world.setBlock(i + 12, j + 1, k + 30, Blocks.dirt);
        world.setBlock(i + 12, j + 1, k + 31, Blocks.dirt);
        world.setBlock(i + 12, j + 1, k + 32, Blocks.dirt);
        world.setBlock(i + 12, j + 1, k + 33, Blocks.dirt);
        world.setBlock(i + 12, j + 1, k + 34, Blocks.dirt);
        world.setBlock(i + 12, j + 1, k + 35, Blocks.dirt);
        world.setBlock(i + 12, j + 1, k + 36, Blocks.dirt);
        world.setBlock(i + 12, j + 1, k + 37, Blocks.dirt);
        world.setBlock(i + 12, j + 1, k + 38, Blocks.dirt);
        world.setBlock(i + 12, j + 1, k + 39, Blocks.dirt);
        world.setBlock(i + 12, j + 1, k + 40, Blocks.dirt);
        world.setBlock(i + 12, j + 1, k + 41, Blocks.dirt);
        world.setBlock(i + 12, j + 2, k + 30, Blocks.dirt);
        world.setBlock(i + 12, j + 2, k + 31, Blocks.dirt);
        world.setBlock(i + 12, j + 2, k + 32, Blocks.dirt);
        world.setBlock(i + 12, j + 2, k + 33, Blocks.dirt);
        world.setBlock(i + 12, j + 2, k + 34, Blocks.dirt);
        world.setBlock(i + 12, j + 2, k + 35, Blocks.dirt);
        world.setBlock(i + 12, j + 2, k + 36, Blocks.dirt);
        world.setBlock(i + 12, j + 2, k + 37, Blocks.dirt);
        world.setBlock(i + 12, j + 2, k + 38, Blocks.dirt);
        world.setBlock(i + 12, j + 2, k + 39, Blocks.dirt);
        world.setBlock(i + 12, j + 2, k + 40, Blocks.dirt);
        world.setBlock(i + 12, j + 2, k + 41, Blocks.grass);
        world.setBlock(i + 12, j + 3, k + 31, Blocks.dirt);
        world.setBlock(i + 12, j + 3, k + 32, Blocks.dirt);
        world.setBlock(i + 12, j + 3, k + 33, Blocks.dirt);
        world.setBlock(i + 12, j + 3, k + 34, Blocks.dirt);
        world.setBlock(i + 12, j + 3, k + 35, Blocks.dirt);
        world.setBlock(i + 12, j + 3, k + 36, Blocks.dirt);
        world.setBlock(i + 12, j + 3, k + 37, Blocks.dirt);
        world.setBlock(i + 12, j + 3, k + 38, Blocks.dirt);
        world.setBlock(i + 12, j + 3, k + 39, Blocks.dirt);
        world.setBlock(i + 12, j + 3, k + 40, Blocks.dirt);
        world.setBlock(i + 12, j + 4, k + 31, Blocks.dirt);
        world.setBlock(i + 12, j + 4, k + 32, Blocks.dirt);
        world.setBlock(i + 12, j + 4, k + 33, Blocks.dirt);
        world.setBlock(i + 12, j + 4, k + 34, Blocks.dirt);
        world.setBlock(i + 12, j + 4, k + 35, Blocks.dirt);
        world.setBlock(i + 12, j + 4, k + 36, Blocks.dirt);
        world.setBlock(i + 12, j + 4, k + 37, Blocks.dirt);
        world.setBlock(i + 12, j + 4, k + 38, Blocks.dirt);
        world.setBlock(i + 12, j + 4, k + 39, Blocks.dirt);
        world.setBlock(i + 12, j + 4, k + 40, Blocks.grass);
        world.setBlock(i + 12, j + 5, k + 32, Blocks.dirt);
        world.setBlock(i + 12, j + 5, k + 33, Blocks.dirt);
        world.setBlock(i + 12, j + 5, k + 34, Blocks.dirt);
        world.setBlock(i + 12, j + 5, k + 35, Blocks.dirt);
        world.setBlock(i + 12, j + 5, k + 36, Blocks.dirt);
        world.setBlock(i + 12, j + 5, k + 37, Blocks.dirt);
        world.setBlock(i + 12, j + 5, k + 38, Blocks.dirt);
        world.setBlock(i + 12, j + 5, k + 39, Blocks.dirt);
        world.setBlock(i + 12, j + 6, k + 32, Blocks.dirt);
        world.setBlock(i + 12, j + 6, k + 33, Blocks.dirt);
        world.setBlock(i + 12, j + 6, k + 34, Blocks.dirt);
        world.setBlock(i + 12, j + 6, k + 35, Blocks.dirt);
        world.setBlock(i + 12, j + 6, k + 36, Blocks.dirt);
        world.setBlock(i + 12, j + 6, k + 37, Blocks.dirt);
        world.setBlock(i + 12, j + 6, k + 38, Blocks.dirt);
        world.setBlock(i + 12, j + 6, k + 39, Blocks.grass);
        world.setBlock(i + 12, j + 7, k + 33, Blocks.dirt);
        world.setBlock(i + 12, j + 7, k + 34, Blocks.dirt);
        world.setBlock(i + 12, j + 7, k + 35, Blocks.dirt);
        world.setBlock(i + 12, j + 7, k + 36, Blocks.dirt);
        world.setBlock(i + 12, j + 7, k + 37, Blocks.dirt);
        world.setBlock(i + 12, j + 7, k + 38, Blocks.dirt);
        world.setBlock(i + 12, j + 8, k + 33, Blocks.dirt);
        world.setBlock(i + 12, j + 8, k + 34, Blocks.dirt);
        world.setBlock(i + 12, j + 8, k + 35, Blocks.dirt);
        world.setBlock(i + 12, j + 8, k + 36, Blocks.dirt);
        world.setBlock(i + 12, j + 8, k + 37, Blocks.dirt);
        world.setBlock(i + 12, j + 8, k + 38, Blocks.dirt);
        world.setBlock(i + 12, j + 9, k + 33, Blocks.cobblestone);
        world.setBlock(i + 12, j + 9, k + 34, Blocks.cobblestone);
        world.setBlock(i + 12, j + 9, k + 35, Blocks.cobblestone);
        world.setBlock(i + 12, j + 9, k + 36, Blocks.cobblestone);
        world.setBlock(i + 12, j + 9, k + 37, Blocks.cobblestone);
        world.setBlock(i + 12, j + 9, k + 38, Blocks.cobblestone);
        world.setBlock(i + 12, j + 10, k + 33, Blocks.log);
        world.setBlock(i + 12, j + 10, k + 38, Blocks.planks);
        world.setBlock(i + 12, j + 11, k + 33, Blocks.log);
        world.setBlock(i + 12, j + 11, k + 38, Blocks.glass_pane);
        world.setBlock(i + 12, j + 12, k + 33, Blocks.log);
        world.setBlock(i + 12, j + 12, k + 38, Blocks.glass_pane);
        world.setBlock(i + 12, j + 13, k + 33, Blocks.log);
        world.setBlock(i + 12, j + 13, k + 38, Blocks.planks);
        world.setBlock(i + 12, j + 14, k + 34, Blocks.log);
        world.setBlock(i + 12, j + 14, k + 35, Blocks.log);
        world.setBlock(i + 12, j + 14, k + 36, Blocks.log);
        world.setBlock(i + 12, j + 14, k + 37, Blocks.log);
        world.setBlock(i + 13, j, k, Blocks.grass);
        world.setBlock(i + 13, j, k + 1, Blocks.grass);
        world.setBlock(i + 13, j, k + 2, Blocks.grass);
        world.setBlock(i + 13, j, k + 3, Blocks.dirt);
        world.setBlock(i + 13, j, k + 4, Blocks.dirt);
        world.setBlock(i + 13, j, k + 5, Blocks.dirt);
        world.setBlock(i + 13, j, k + 6, Blocks.dirt);
        world.setBlock(i + 13, j, k + 7, Blocks.dirt);
        world.setBlock(i + 13, j, k + 8, Blocks.dirt);
        world.setBlock(i + 13, j, k + 9, Blocks.dirt);
        world.setBlock(i + 13, j, k + 10, Blocks.dirt);
        world.setBlock(i + 13, j, k + 11, Blocks.dirt);
        world.setBlock(i + 13, j, k + 12, Blocks.grass);
        world.setBlock(i + 13, j, k + 13, Blocks.grass);
        world.setBlock(i + 13, j, k + 14, Blocks.grass);
        world.setBlock(i + 13, j, k + 25, Blocks.grass);
        world.setBlock(i + 13, j, k + 26, Blocks.grass);
        world.setBlock(i + 13, j, k + 27, Blocks.grass);
        world.setBlock(i + 13, j, k + 28, Blocks.grass);
        world.setBlock(i + 13, j, k + 29, Blocks.grass);
        world.setBlock(i + 13, j, k + 30, Blocks.dirt);
        world.setBlock(i + 13, j, k + 31, Blocks.dirt);
        world.setBlock(i + 13, j, k + 32, Blocks.dirt);
        world.setBlock(i + 13, j, k + 33, Blocks.dirt);
        world.setBlock(i + 13, j, k + 34, Blocks.dirt);
        world.setBlock(i + 13, j, k + 35, Blocks.dirt);
        world.setBlock(i + 13, j, k + 36, Blocks.dirt);
        world.setBlock(i + 13, j, k + 37, Blocks.dirt);
        world.setBlock(i + 13, j, k + 38, Blocks.dirt);
        world.setBlock(i + 13, j, k + 39, Blocks.dirt);
        world.setBlock(i + 13, j, k + 40, Blocks.dirt);
        world.setBlock(i + 13, j, k + 41, Blocks.dirt);
        world.setBlock(i + 13, j, k + 42, Blocks.grass);
        world.setBlock(i + 13, j + 1, k + 3, Blocks.dirt);
        world.setBlock(i + 13, j + 1, k + 4, Blocks.dirt);
        world.setBlock(i + 13, j + 1, k + 5, Blocks.dirt);
        world.setBlock(i + 13, j + 1, k + 6, Blocks.dirt);
        world.setBlock(i + 13, j + 1, k + 7, Blocks.dirt);
        world.setBlock(i + 13, j + 1, k + 8, Blocks.dirt);
        world.setBlock(i + 13, j + 1, k + 9, Blocks.dirt);
        world.setBlock(i + 13, j + 1, k + 10, Blocks.dirt);
        world.setBlock(i + 13, j + 1, k + 11, Blocks.dirt);
        world.setBlock(i + 13, j + 1, k + 24, Blocks.fence);
        world.setBlock(i + 13, j + 1, k + 30, Blocks.dirt);
        world.setBlock(i + 13, j + 1, k + 31, Blocks.dirt);
        world.setBlock(i + 13, j + 1, k + 32, Blocks.dirt);
        world.setBlock(i + 13, j + 1, k + 33, Blocks.dirt);
        world.setBlock(i + 13, j + 1, k + 34, Blocks.dirt);
        world.setBlock(i + 13, j + 1, k + 35, Blocks.dirt);
        world.setBlock(i + 13, j + 1, k + 36, Blocks.dirt);
        world.setBlock(i + 13, j + 1, k + 37, Blocks.dirt);
        world.setBlock(i + 13, j + 1, k + 38, Blocks.dirt);
        world.setBlock(i + 13, j + 1, k + 39, Blocks.dirt);
        world.setBlock(i + 13, j + 1, k + 40, Blocks.dirt);
        world.setBlock(i + 13, j + 1, k + 41, Blocks.dirt);
        world.setBlock(i + 13, j + 2, k + 3, Blocks.grass);
        world.setBlock(i + 13, j + 2, k + 4, Blocks.grass);
        world.setBlock(i + 13, j + 2, k + 5, Blocks.grass);
        world.setBlock(i + 13, j + 2, k + 6, Blocks.grass);
        world.setBlock(i + 13, j + 2, k + 7, Blocks.grass);
        world.setBlock(i + 13, j + 2, k + 8, Blocks.grass);
        world.setBlock(i + 13, j + 2, k + 9, Blocks.grass);
        world.setBlock(i + 13, j + 2, k + 10, Blocks.grass);
        world.setBlock(i + 13, j + 2, k + 11, Blocks.grass);
        world.setBlock(i + 13, j + 2, k + 24, Blocks.fence);
        world.setBlock(i + 13, j + 2, k + 30, Blocks.grass);
        world.setBlock(i + 13, j + 2, k + 31, Blocks.dirt);
        world.setBlock(i + 13, j + 2, k + 32, Blocks.dirt);
        world.setBlock(i + 13, j + 2, k + 33, Blocks.dirt);
        world.setBlock(i + 13, j + 2, k + 34, Blocks.dirt);
        world.setBlock(i + 13, j + 2, k + 35, Blocks.dirt);
        world.setBlock(i + 13, j + 2, k + 36, Blocks.dirt);
        world.setBlock(i + 13, j + 2, k + 37, Blocks.dirt);
        world.setBlock(i + 13, j + 2, k + 38, Blocks.dirt);
        world.setBlock(i + 13, j + 2, k + 39, Blocks.dirt);
        world.setBlock(i + 13, j + 2, k + 40, Blocks.dirt);
        world.setBlock(i + 13, j + 2, k + 41, Blocks.grass);
        world.setBlock(i + 13, j + 3, k + 24, Blocks.glowstone);
        final EntityVillager entity = new EntityVillager(world);
        entity.setPosition((double)(i + 13), (double)(j + 3), (double)(k + 24));
        world.spawnEntityInWorld((Entity)entity);
        entity.onSpawnWithEgg((IEntityLivingData)null);
        entity.setPosition((double)(i + 13), (double)(j + 3), (double)(k + 24));
        world.setBlock(i + 13, j + 3, k + 31, Blocks.dirt);
        world.setBlock(i + 13, j + 3, k + 32, Blocks.dirt);
        world.setBlock(i + 13, j + 3, k + 33, Blocks.dirt);
        world.setBlock(i + 13, j + 3, k + 34, Blocks.dirt);
        world.setBlock(i + 13, j + 3, k + 35, Blocks.dirt);
        world.setBlock(i + 13, j + 3, k + 36, Blocks.dirt);
        world.setBlock(i + 13, j + 3, k + 37, Blocks.dirt);
        world.setBlock(i + 13, j + 3, k + 38, Blocks.dirt);
        world.setBlock(i + 13, j + 3, k + 39, Blocks.dirt);
        world.setBlock(i + 13, j + 3, k + 40, Blocks.dirt);
        world.setBlock(i + 13, j + 4, k + 31, Blocks.grass);
        world.setBlock(i + 13, j + 4, k + 32, Blocks.dirt);
        world.setBlock(i + 13, j + 4, k + 33, Blocks.dirt);
        world.setBlock(i + 13, j + 4, k + 34, Blocks.dirt);
        world.setBlock(i + 13, j + 4, k + 35, Blocks.dirt);
        world.setBlock(i + 13, j + 4, k + 36, Blocks.dirt);
        world.setBlock(i + 13, j + 4, k + 37, Blocks.dirt);
        world.setBlock(i + 13, j + 4, k + 38, Blocks.dirt);
        world.setBlock(i + 13, j + 4, k + 39, Blocks.dirt);
        world.setBlock(i + 13, j + 4, k + 40, Blocks.grass);
        world.setBlock(i + 13, j + 5, k + 32, Blocks.dirt);
        world.setBlock(i + 13, j + 5, k + 33, Blocks.dirt);
        world.setBlock(i + 13, j + 5, k + 34, Blocks.dirt);
        world.setBlock(i + 13, j + 5, k + 35, Blocks.dirt);
        world.setBlock(i + 13, j + 5, k + 36, Blocks.dirt);
        world.setBlock(i + 13, j + 5, k + 37, Blocks.dirt);
        world.setBlock(i + 13, j + 5, k + 38, Blocks.dirt);
        world.setBlock(i + 13, j + 5, k + 39, Blocks.dirt);
        world.setBlock(i + 13, j + 6, k + 32, Blocks.grass);
        world.setBlock(i + 13, j + 6, k + 33, Blocks.dirt);
        world.setBlock(i + 13, j + 6, k + 34, Blocks.dirt);
        world.setBlock(i + 13, j + 6, k + 35, Blocks.dirt);
        world.setBlock(i + 13, j + 6, k + 36, Blocks.dirt);
        world.setBlock(i + 13, j + 6, k + 37, Blocks.dirt);
        world.setBlock(i + 13, j + 6, k + 38, Blocks.dirt);
        world.setBlock(i + 13, j + 6, k + 39, Blocks.grass);
        world.setBlock(i + 13, j + 7, k + 33, Blocks.dirt);
        world.setBlock(i + 13, j + 7, k + 34, Blocks.dirt);
        world.setBlock(i + 13, j + 7, k + 35, Blocks.dirt);
        world.setBlock(i + 13, j + 7, k + 36, Blocks.dirt);
        world.setBlock(i + 13, j + 7, k + 37, Blocks.dirt);
        world.setBlock(i + 13, j + 7, k + 38, Blocks.dirt);
        world.setBlock(i + 13, j + 8, k + 33, Blocks.dirt);
        world.setBlock(i + 13, j + 8, k + 34, Blocks.dirt);
        world.setBlock(i + 13, j + 8, k + 35, Blocks.dirt);
        world.setBlock(i + 13, j + 8, k + 36, Blocks.dirt);
        world.setBlock(i + 13, j + 8, k + 37, Blocks.dirt);
        world.setBlock(i + 13, j + 8, k + 38, Blocks.dirt);
        world.setBlock(i + 13, j + 9, k + 33, Blocks.cobblestone);
        world.setBlock(i + 13, j + 9, k + 34, Blocks.cobblestone);
        world.setBlock(i + 13, j + 9, k + 35, Blocks.cobblestone);
        world.setBlock(i + 13, j + 9, k + 36, Blocks.cobblestone);
        world.setBlock(i + 13, j + 9, k + 37, Blocks.cobblestone);
        world.setBlock(i + 13, j + 9, k + 38, Blocks.cobblestone);
        world.setBlock(i + 13, j + 10, k + 33, Blocks.planks);
        world.setBlock(i + 13, j + 10, k + 38, Blocks.planks);
        world.setBlock(i + 13, j + 11, k + 33, Blocks.glass_pane);
        world.setBlock(i + 13, j + 11, k + 38, Blocks.glass_pane);
        world.setBlock(i + 13, j + 12, k + 33, Blocks.glass_pane);
        world.setBlock(i + 13, j + 12, k + 38, Blocks.glass_pane);
        world.setBlock(i + 13, j + 13, k + 33, Blocks.planks);
        world.setBlock(i + 13, j + 13, k + 38, Blocks.planks);
        world.setBlock(i + 13, j + 14, k + 34, Blocks.log);
        world.setBlock(i + 13, j + 14, k + 35, Blocks.log);
        world.setBlock(i + 13, j + 14, k + 36, Blocks.log);
        world.setBlock(i + 13, j + 14, k + 37, Blocks.log);
        world.setBlock(i + 14, j, k, Blocks.grass);
        world.setBlock(i + 14, j, k + 1, Blocks.grass);
        world.setBlock(i + 14, j, k + 2, Blocks.grass);
        world.setBlock(i + 14, j, k + 3, Blocks.dirt);
        world.setBlock(i + 14, j, k + 4, Blocks.dirt);
        world.setBlock(i + 14, j, k + 5, Blocks.dirt);
        world.setBlock(i + 14, j, k + 6, Blocks.dirt);
        world.setBlock(i + 14, j, k + 7, Blocks.dirt);
        world.setBlock(i + 14, j, k + 8, Blocks.dirt);
        world.setBlock(i + 14, j, k + 9, Blocks.dirt);
        world.setBlock(i + 14, j, k + 10, Blocks.dirt);
        world.setBlock(i + 14, j, k + 11, Blocks.dirt);
        world.setBlock(i + 14, j, k + 12, Blocks.grass);
        world.setBlock(i + 14, j, k + 13, Blocks.grass);
        world.setBlock(i + 14, j, k + 14, Blocks.grass);
        world.setBlock(i + 14, j, k + 25, Blocks.grass);
        world.setBlock(i + 14, j, k + 26, Blocks.grass);
        world.setBlock(i + 14, j, k + 27, Blocks.grass);
        world.setBlock(i + 14, j, k + 28, Blocks.grass);
        world.setBlock(i + 14, j, k + 29, Blocks.grass);
        world.setBlock(i + 14, j, k + 30, Blocks.dirt);
        world.setBlock(i + 14, j, k + 31, Blocks.dirt);
        world.setBlock(i + 14, j, k + 32, Blocks.dirt);
        world.setBlock(i + 14, j, k + 33, Blocks.dirt);
        world.setBlock(i + 14, j, k + 34, Blocks.dirt);
        world.setBlock(i + 14, j, k + 35, Blocks.dirt);
        world.setBlock(i + 14, j, k + 36, Blocks.dirt);
        world.setBlock(i + 14, j, k + 37, Blocks.dirt);
        world.setBlock(i + 14, j, k + 38, Blocks.dirt);
        world.setBlock(i + 14, j, k + 39, Blocks.dirt);
        world.setBlock(i + 14, j, k + 40, Blocks.dirt);
        this.generate2(world, rand, i, j, k);
        return true;
    }
    
    public boolean generate2(final World world, final Random rand, final int i, final int j, final int k) {
        world.setBlock(i + 14, j, k + 41, Blocks.dirt);
        world.setBlock(i + 14, j, k + 42, Blocks.grass);
        world.setBlock(i + 14, j + 1, k + 3, Blocks.dirt);
        world.setBlock(i + 14, j + 1, k + 4, Blocks.dirt);
        world.setBlock(i + 14, j + 1, k + 5, Blocks.dirt);
        world.setBlock(i + 14, j + 1, k + 6, Blocks.dirt);
        world.setBlock(i + 14, j + 1, k + 7, Blocks.dirt);
        world.setBlock(i + 14, j + 1, k + 8, Blocks.dirt);
        world.setBlock(i + 14, j + 1, k + 9, Blocks.dirt);
        world.setBlock(i + 14, j + 1, k + 10, Blocks.dirt);
        world.setBlock(i + 14, j + 1, k + 11, Blocks.dirt);
        world.setBlock(i + 14, j + 1, k + 30, Blocks.dirt);
        world.setBlock(i + 14, j + 1, k + 31, Blocks.dirt);
        world.setBlock(i + 14, j + 1, k + 32, Blocks.dirt);
        world.setBlock(i + 14, j + 1, k + 33, Blocks.dirt);
        world.setBlock(i + 14, j + 1, k + 34, Blocks.dirt);
        world.setBlock(i + 14, j + 1, k + 35, Blocks.dirt);
        world.setBlock(i + 14, j + 1, k + 36, Blocks.dirt);
        world.setBlock(i + 14, j + 1, k + 37, Blocks.dirt);
        world.setBlock(i + 14, j + 1, k + 38, Blocks.dirt);
        world.setBlock(i + 14, j + 1, k + 39, Blocks.dirt);
        world.setBlock(i + 14, j + 1, k + 40, Blocks.dirt);
        world.setBlock(i + 14, j + 1, k + 41, Blocks.dirt);
        world.setBlock(i + 14, j + 2, k + 3, Blocks.grass);
        world.setBlock(i + 14, j + 2, k + 4, Blocks.dirt);
        world.setBlock(i + 14, j + 2, k + 5, Blocks.dirt);
        world.setBlock(i + 14, j + 2, k + 6, Blocks.dirt);
        world.setBlock(i + 14, j + 2, k + 7, Blocks.dirt);
        world.setBlock(i + 14, j + 2, k + 8, Blocks.dirt);
        world.setBlock(i + 14, j + 2, k + 9, Blocks.dirt);
        world.setBlock(i + 14, j + 2, k + 10, Blocks.dirt);
        world.setBlock(i + 14, j + 2, k + 11, Blocks.grass);
        world.setBlock(i + 14, j + 2, k + 30, Blocks.grass);
        world.setBlock(i + 14, j + 2, k + 31, Blocks.dirt);
        world.setBlock(i + 14, j + 2, k + 32, Blocks.dirt);
        world.setBlock(i + 14, j + 2, k + 33, Blocks.dirt);
        world.setBlock(i + 14, j + 2, k + 34, Blocks.dirt);
        world.setBlock(i + 14, j + 2, k + 35, Blocks.dirt);
        world.setBlock(i + 14, j + 2, k + 36, Blocks.dirt);
        world.setBlock(i + 14, j + 2, k + 37, Blocks.dirt);
        world.setBlock(i + 14, j + 2, k + 38, Blocks.dirt);
        world.setBlock(i + 14, j + 2, k + 39, Blocks.dirt);
        world.setBlock(i + 14, j + 2, k + 40, Blocks.dirt);
        world.setBlock(i + 14, j + 2, k + 41, Blocks.grass);
        world.setBlock(i + 14, j + 3, k + 4, Blocks.dirt);
        world.setBlock(i + 14, j + 3, k + 5, Blocks.dirt);
        world.setBlock(i + 14, j + 3, k + 6, Blocks.dirt);
        world.setBlock(i + 14, j + 3, k + 7, Blocks.dirt);
        world.setBlock(i + 14, j + 3, k + 8, Blocks.dirt);
        world.setBlock(i + 14, j + 3, k + 9, Blocks.dirt);
        world.setBlock(i + 14, j + 3, k + 10, Blocks.dirt);
        world.setBlock(i + 14, j + 3, k + 31, Blocks.dirt);
        world.setBlock(i + 14, j + 3, k + 32, Blocks.dirt);
        world.setBlock(i + 14, j + 3, k + 33, Blocks.dirt);
        world.setBlock(i + 14, j + 3, k + 34, Blocks.dirt);
        world.setBlock(i + 14, j + 3, k + 35, Blocks.dirt);
        world.setBlock(i + 14, j + 3, k + 36, Blocks.dirt);
        world.setBlock(i + 14, j + 3, k + 37, Blocks.dirt);
        world.setBlock(i + 14, j + 3, k + 38, Blocks.dirt);
        world.setBlock(i + 14, j + 3, k + 39, Blocks.dirt);
        world.setBlock(i + 14, j + 3, k + 40, Blocks.dirt);
        world.setBlock(i + 14, j + 4, k + 4, Blocks.grass);
        world.setBlock(i + 14, j + 4, k + 5, Blocks.grass);
        world.setBlock(i + 14, j + 4, k + 6, Blocks.grass);
        world.setBlock(i + 14, j + 4, k + 7, Blocks.grass);
        world.setBlock(i + 14, j + 4, k + 8, Blocks.grass);
        world.setBlock(i + 14, j + 4, k + 9, Blocks.grass);
        world.setBlock(i + 14, j + 4, k + 10, Blocks.grass);
        world.setBlock(i + 14, j + 4, k + 31, Blocks.grass);
        world.setBlock(i + 14, j + 4, k + 32, Blocks.dirt);
        world.setBlock(i + 14, j + 4, k + 33, Blocks.dirt);
        world.setBlock(i + 14, j + 4, k + 34, Blocks.dirt);
        world.setBlock(i + 14, j + 4, k + 35, Blocks.dirt);
        world.setBlock(i + 14, j + 4, k + 36, Blocks.dirt);
        world.setBlock(i + 14, j + 4, k + 37, Blocks.dirt);
        world.setBlock(i + 14, j + 4, k + 38, Blocks.dirt);
        world.setBlock(i + 14, j + 4, k + 39, Blocks.dirt);
        world.setBlock(i + 14, j + 4, k + 40, Blocks.grass);
        world.setBlock(i + 14, j + 5, k + 32, Blocks.dirt);
        world.setBlock(i + 14, j + 5, k + 33, Blocks.dirt);
        world.setBlock(i + 14, j + 5, k + 34, Blocks.dirt);
        world.setBlock(i + 14, j + 5, k + 35, Blocks.dirt);
        world.setBlock(i + 14, j + 5, k + 36, Blocks.dirt);
        world.setBlock(i + 14, j + 5, k + 37, Blocks.dirt);
        world.setBlock(i + 14, j + 5, k + 38, Blocks.dirt);
        world.setBlock(i + 14, j + 5, k + 39, Blocks.dirt);
        world.setBlock(i + 14, j + 6, k + 32, Blocks.grass);
        world.setBlock(i + 14, j + 6, k + 33, Blocks.dirt);
        world.setBlock(i + 14, j + 6, k + 34, Blocks.dirt);
        world.setBlock(i + 14, j + 6, k + 35, Blocks.dirt);
        world.setBlock(i + 14, j + 6, k + 36, Blocks.dirt);
        world.setBlock(i + 14, j + 6, k + 37, Blocks.dirt);
        world.setBlock(i + 14, j + 6, k + 38, Blocks.dirt);
        world.setBlock(i + 14, j + 6, k + 39, Blocks.grass);
        world.setBlock(i + 14, j + 7, k + 33, Blocks.dirt);
        world.setBlock(i + 14, j + 7, k + 34, Blocks.dirt);
        world.setBlock(i + 14, j + 7, k + 35, Blocks.dirt);
        world.setBlock(i + 14, j + 7, k + 36, Blocks.dirt);
        world.setBlock(i + 14, j + 7, k + 37, Blocks.dirt);
        world.setBlock(i + 14, j + 7, k + 38, Blocks.dirt);
        world.setBlock(i + 14, j + 8, k + 33, Blocks.dirt);
        world.setBlock(i + 14, j + 8, k + 34, Blocks.dirt);
        world.setBlock(i + 14, j + 8, k + 35, Blocks.dirt);
        world.setBlock(i + 14, j + 8, k + 36, Blocks.dirt);
        world.setBlock(i + 14, j + 8, k + 37, Blocks.dirt);
        world.setBlock(i + 14, j + 8, k + 38, Blocks.dirt);
        world.setBlock(i + 14, j + 9, k + 33, Blocks.cobblestone);
        world.setBlock(i + 14, j + 9, k + 34, Blocks.cobblestone);
        world.setBlock(i + 14, j + 9, k + 35, Blocks.cobblestone);
        world.setBlock(i + 14, j + 9, k + 36, Blocks.cobblestone);
        world.setBlock(i + 14, j + 9, k + 37, Blocks.cobblestone);
        world.setBlock(i + 14, j + 9, k + 38, Blocks.cobblestone);
        world.setBlock(i + 14, j + 10, k + 33, Blocks.planks);
        world.setBlock(i + 14, j + 10, k + 34, Blocks.crafting_table);
        world.setBlock(i + 14, j + 10, k + 37, Blocks.bookshelf);
        world.setBlock(i + 14, j + 10, k + 38, Blocks.planks);
        world.setBlock(i + 14, j + 11, k + 33, Blocks.glass_pane);
        world.setBlock(i + 14, j + 11, k + 37, Blocks.bookshelf);
        world.setBlock(i + 14, j + 11, k + 38, Blocks.planks);
        world.setBlock(i + 14, j + 12, k + 33, Blocks.glass_pane);
        world.setBlock(i + 14, j + 12, k + 37, Blocks.bookshelf);
        world.setBlock(i + 14, j + 12, k + 38, Blocks.planks);
        world.setBlock(i + 14, j + 13, k + 33, Blocks.planks);
        world.setBlock(i + 14, j + 13, k + 37, Blocks.bookshelf);
        world.setBlock(i + 14, j + 13, k + 38, Blocks.planks);
        world.setBlock(i + 14, j + 14, k + 34, Blocks.log);
        world.setBlock(i + 14, j + 14, k + 35, Blocks.log);
        world.setBlock(i + 14, j + 14, k + 36, Blocks.log);
        world.setBlock(i + 14, j + 14, k + 37, Blocks.log);
        world.setBlock(i + 15, j, k, Blocks.grass);
        world.setBlock(i + 15, j, k + 1, Blocks.grass);
        world.setBlock(i + 15, j, k + 2, Blocks.grass);
        world.setBlock(i + 15, j, k + 3, Blocks.dirt);
        world.setBlock(i + 15, j, k + 4, Blocks.dirt);
        world.setBlock(i + 15, j, k + 5, Blocks.dirt);
        world.setBlock(i + 15, j, k + 6, Blocks.dirt);
        world.setBlock(i + 15, j, k + 7, Blocks.dirt);
        world.setBlock(i + 15, j, k + 8, Blocks.dirt);
        world.setBlock(i + 15, j, k + 9, Blocks.dirt);
        world.setBlock(i + 15, j, k + 10, Blocks.dirt);
        world.setBlock(i + 15, j, k + 11, Blocks.dirt);
        world.setBlock(i + 15, j, k + 12, Blocks.grass);
        world.setBlock(i + 15, j, k + 13, Blocks.grass);
        world.setBlock(i + 15, j, k + 14, Blocks.grass);
        world.setBlock(i + 15, j, k + 25, Blocks.grass);
        world.setBlock(i + 15, j, k + 26, Blocks.grass);
        world.setBlock(i + 15, j, k + 27, Blocks.grass);
        world.setBlock(i + 15, j, k + 28, Blocks.grass);
        world.setBlock(i + 15, j, k + 29, Blocks.grass);
        world.setBlock(i + 15, j, k + 30, Blocks.dirt);
        world.setBlock(i + 15, j, k + 31, Blocks.dirt);
        world.setBlock(i + 15, j, k + 32, Blocks.dirt);
        world.setBlock(i + 15, j, k + 33, Blocks.dirt);
        world.setBlock(i + 15, j, k + 34, Blocks.dirt);
        world.setBlock(i + 15, j, k + 35, Blocks.dirt);
        world.setBlock(i + 15, j, k + 36, Blocks.dirt);
        world.setBlock(i + 15, j, k + 37, Blocks.dirt);
        world.setBlock(i + 15, j, k + 38, Blocks.dirt);
        world.setBlock(i + 15, j, k + 39, Blocks.dirt);
        world.setBlock(i + 15, j, k + 40, Blocks.dirt);
        world.setBlock(i + 15, j, k + 41, Blocks.dirt);
        world.setBlock(i + 15, j, k + 42, Blocks.grass);
        world.setBlock(i + 15, j + 1, k + 3, Blocks.dirt);
        world.setBlock(i + 15, j + 1, k + 4, Blocks.dirt);
        world.setBlock(i + 15, j + 1, k + 5, Blocks.dirt);
        world.setBlock(i + 15, j + 1, k + 6, Blocks.dirt);
        world.setBlock(i + 15, j + 1, k + 7, Blocks.dirt);
        world.setBlock(i + 15, j + 1, k + 8, Blocks.dirt);
        world.setBlock(i + 15, j + 1, k + 9, Blocks.dirt);
        world.setBlock(i + 15, j + 1, k + 10, Blocks.dirt);
        world.setBlock(i + 15, j + 1, k + 11, Blocks.dirt);
